File: data/A344/A344_GdN_MH_055K_160905.rso.dat
[Header]
TITLE,MPMS RSO Measurement
BYAPP,MPMS Measurement,1.1,Summary
FILEOPENTIME, 1473171799.163000 9/7/2016, 2:23:19 AM

INFO, APPNAME, MPMS MultiVu Application, Revision 1.61,  Build 082

INFO, NAME, A344
INFO, WEIGHT, 10.500
INFO, AREA, 1.000
INFO, LENGTH, 1.000
INFO, SHAPE, 0
INFO, COMMENT, m = 0.0105g
INFO, SEQUENCE FILE: 7T_hysteresis_sweep_hi_res_zero_n4.seq


INFO, BACKGROUND DATA FILE:, None


STARTUPAXIS,X,4,LINEAR,AUTO,0.000000,0.000000
STARTUPAXIS,Y1,5,LINEAR,AUTO,0.000000,0.000000


STARTUPGROUP,Longitudinal
FIELDGROUP,Longitudinal,1,2,3,4,5,6,7,8,9,10,11,19,20,21,22,23,35
FIELDGROUP,Transverse,1,2,3,4,12,13,14,15,16,17,18,24,25,26,27,28,35

PLOT_APPEARANCE,ALL,HORZ_GRID_ON,VERT_GRID_ON,MARKERS_AND_LINES

[Data]
Time,Comment,Field (Oe),Temperature (K),Long Moment (emu),Long Scan Std Dev,Long Offset (cm),Long Offset Std Dev,Long Algorithm,Long Reg Fit,Long Reg Factor,Trans Moment (emu),Trans Scan Std Dev,Trans Offset (cm),Trans Offset Std Dev,Trans Algorithm,Trans Reg Fit,Trans Reg Factor,Long Moment [w/o ABS] (emu),Long Scan Std Dev [w/o ABS],Long Offset [w/o ABS] (cm),Long Offset Std Dev [w/o ABS],Long Reg Fit [w/o ABS],Trans Moment [w/o ABS] (emu),Trans Scan Std Dev [w/o ABS],Trans Offset [w/o ABS] (cm),Trans Offset Std Dev [w/o ABS],Trans Reg Fit [w/o ABS],RSO Position (deg),Amplitude (cm),Frequency,Cycles to Average,Scans per Measurement,Delta Temp (K),Error,EC Comp. Running,Using ABS,
1473171799.147,,7.000000e+004,5.508592e+001,9.198815e-004,0.000000e+000,1.378087e-002,0.000000e+000,3,9.392318e-001,1.825000e+000,,,,,,,,,,,,,,,,,,0,5.000000e+000,5.000000e-001,2,1,1.045990e-002,0,0,0,
1473171825.760,,7.000000e+004,5.504639e+001,9.202059e-004,0.000000e+000,1.372216e-002,0.000000e+000,3,9.394285e-001,1.825000e+000,,,,,,,,,,,,,,,,,,0,5.000000e+000,5.000000e-001,2,1,8.953094e-003,0,0,0,
1473172009.554,,6.000000e+004,5.500243e+001,9.094191e-004,0.000000e+000,1.233294e-002,0.000000e+000,3,9.395818e-001,1.825000e+000,,,,,,,,,,,,,,,,,,0,5.000000e+000,5.000000e-001,2,1,4.478455e-003,0,0,0,
1473172036.641,,6.000000e+004,5.499871e+001,9.090337e-004,0.000000e+000,1.307093e-002,0.000000e+000,3,9.392626e-001,1.825000e+000,,,,,,,,,,,,,,,,,,0,5.000000e+000,5.000000e-001,2,1,0.000000e+000,0,1,0,
1473172212.029,,5.000000e+004,5.500317e+001,8.951320e-004,0.000000e+000,1.182837e-002,0.000000e+000,3,9.391518e-001,1.825000e+000,,,,,,,,,,,,,,,,,,0,5.000000e+000,5.000000e-001,2,1,2.990723e-003,0,1,0,
1473172237.574,,5.000000e+004,5.499796e+001,8.947878e-004,0.000000e+000,1.182292e-002,0.000000e+000,3,9.391030e-001,1.825000e+000,,,,,,,,,,,,,,,,,,0,5.000000e+000,5.000000e-001,2,1,1.042175e-002,0,1,0,
1473172415.875,,4.000000e+004,5.500690e+001,8.775830e-004,0.000000e+000,9.847758e-003,0.000000e+000,3,9.410245e-001,1.825000e+000,,,,,,,,,,,,,,,,,,0,5.000000e+000,5.000000e-001,2,1,4.459381e-003,0,1,0,
1473172440.554,,4.000000e+004,5.500466e+001,8.770235e-004,0.000000e+000,1.032424e-002,0.000000e+000,3,9.370900e-001,1.825000e+000,,,,,,,,,,,,,,,,,,0,5.000000e+000,5.000000e-001,2,1,2.979279e-003,0,1,0,
1473172615.251,,3.000000e+004,5.500168e+001,8.526266e-004,0.000000e+000,8.009219e-003,0.000000e+000,3,9.379758e-001,1.825000e+000,,,,,,,,,,,,,,,,,,0,5.000000e+000,5.000000e-001,2,1,0.000000e+000,0,1,0,
1473172640.516,,3.000000e+004,5.500093e+001,8.532436e-004,0.000000e+000,8.502805e-003,0.000000e+000,3,9.383057e-001,1.825000e+000,,,,,,,,,,,,,,,,,,0,5.000000e+000,5.000000e-001,2,1,1.487732e-003,0,1,0,
1473172814.644,,2.000000e+004,5.499722e+001,8.179464e-004,0.000000e+000,8.859633e-003,0.000000e+000,3,9.363905e-001,1.825000e+000,,,,,,,,,,,,,,,,,,0,5.000000e+000,5.000000e-001,2,1,0.000000e+000,0,0,0,
1473172842.095,,2.000000e+004,5.499796e+001,8.179638e-004,0.000000e+000,8.525900e-003,0.000000e+000,3,9.370558e-001,1.825000e+000,,,,,,,,,,,,,,,,,,0,5.000000e+000,5.000000e-001,2,1,4.459381e-003,0,0,0,
1473173014.047,,1.000000e+004,5.499350e+001,7.674693e-004,0.000000e+000,7.226495e-003,0.000000e+000,3,9.337792e-001,1.825000e+000,,,,,,,,,,,,,,,,,,0,5.000000e+000,5.000000e-001,2,1,7.438660e-003,0,0,0,
1473173037.693,,1.000000e+004,5.499424e+001,7.641577e-004,0.000000e+000,6.421445e-003,0.000000e+000,3,9.318483e-001,1.825000e+000,,,,,,,,,,,,,,,,,,0,5.000000e+000,5.000000e-001,2,1,0.000000e+000,0,0,0,
1473173170.550,,9.000000e+003,5.499870e+001,7.602851e-004,0.000000e+000,7.741857e-003,0.000000e+000,3,9.339042e-001,1.825000e+000,,,,,,,,,,,,,,,,,,0,5.000000e+000,5.000000e-001,2,1,2.971649e-003,0,0,0,
1473173195.466,,9.000000e+003,5.499648e+001,7.603179e-004,0.000000e+000,7.418341e-003,0.000000e+000,3,9.334047e-001,1.825000e+000,,,,,,,,,,,,,,,,,,0,5.000000e+000,5.000000e-001,2,1,4.470825e-003,0,0,0,
1473173332.337,,7.000000e+003,5.498904e+001,7.441978e-004,0.000000e+000,7.332294e-003,0.000000e+000,3,9.326471e-001,1.825000e+000,,,,,,,,,,,,,,,,,,0,5.000000e+000,5.000000e-001,2,1,1.636887e-002,0,0,0,
1473173358.003,,7.000000e+003,5.499796e+001,7.445014e-004,0.000000e+000,7.198091e-003,0.000000e+000,3,9.325362e-001,1.825000e+000,,,,,,,,,,,,,,,,,,0,5.000000e+000,5.000000e-001,2,1,1.491547e-003,0,0,0,
1473173493.918,,5.000000e+003,5.500019e+001,7.247038e-004,0.000000e+000,7.203233e-003,0.000000e+000,3,9.316059e-001,1.825000e+000,,,,,,,,,,,,,,,,,,0,5.000000e+000,5.000000e-001,2,1,2.967834e-003,0,0,0,
1473173519.342,,5.000000e+003,5.499722e+001,7.246763e-004,0.000000e+000,7.213333e-003,0.000000e+000,3,9.315141e-001,1.825000e+000,,,,,,,,,,,,,,,,,,0,5.000000e+000,5.000000e-001,2,1,0.000000e+000,0,1,0,
1473173655.313,,3.000000e+003,5.500019e+001,6.992558e-004,0.000000e+000,7.458693e-003,0.000000e+000,3,9.324772e-001,1.825000e+000,,,,,,,,,,,,,,,,,,0,5.000000e+000,5.000000e-001,2,1,2.967834e-003,0,1,0,
1473173679.295,,3.000000e+003,5.500466e+001,6.995182e-004,0.000000e+000,7.295403e-003,0.000000e+000,3,9.319320e-001,1.825000e+000,,,,,,,,,,,,,,,,,,0,5.000000e+000,5.000000e-001,2,1,8.937836e-003,0,1,0,
1473173806.225,,1.000000e+003,5.500168e+001,6.589182e-004,0.000000e+000,9.875563e-003,0.000000e+000,3,9.423540e-001,1.825000e+000,,,,,,,,,,,,,,,,,,0,5.000000e+000,5.000000e-001,2,1,0.000000e+000,0,1,0,
1473173832.456,,1.000000e+003,5.500467e+001,6.584341e-004,0.000000e+000,9.425543e-003,0.000000e+000,3,9.424570e-001,1.825000e+000,,,,,,,,,,,,,,,,,,0,5.000000e+000,5.000000e-001,2,1,0.000000e+000,0,1,0,
1473173972.882,,7.000000e+002,5.500020e+001,6.458141e-004,0.000000e+000,1.056945e-002,0.000000e+000,3,9.491558e-001,1.825000e+000,,,,,,,,,,,,,,,,,,0,5.000000e+000,5.000000e-001,2,1,8.937836e-003,0,1,0,
1473173995.825,,7.000000e+002,5.499870e+001,6.461613e-004,0.000000e+000,1.034543e-002,0.000000e+000,3,9.485562e-001,1.825000e+000,,,,,,,,,,,,,,,,,,0,5.000000e+000,5.000000e-001,2,1,2.971649e-003,0,1,0,
1473174130.303,,6.000000e+002,5.499722e+001,6.407381e-004,0.000000e+000,1.128279e-002,0.000000e+000,3,9.518626e-001,1.825000e+000,,,,,,,,,,,,,,,,,,0,5.000000e+000,5.000000e-001,2,1,2.979279e-003,0,1,0,
1473174153.479,,6.000000e+002,5.499647e+001,6.407951e-004,0.000000e+000,1.091149e-002,0.000000e+000,3,9.517977e-001,1.825000e+000,,,,,,,,,,,,,,,,,,0,5.000000e+000,5.000000e-001,2,1,1.041794e-002,0,1,0,
1473174288.908,,5.000000e+002,5.500317e+001,6.335148e-004,0.000000e+000,1.145845e-002,0.000000e+000,3,9.548404e-001,1.825000e+000,,,,,,,,,,,,,,,,,,0,5.000000e+000,5.000000e-001,2,1,8.930206e-003,0,0,0,
1473174314.336,,5.000000e+002,5.499722e+001,6.334415e-004,0.000000e+000,1.148188e-002,0.000000e+000,3,9.548008e-001,1.825000e+000,,,,,,,,,,,,,,,,,,0,5.000000e+000,5.000000e-001,2,1,2.979279e-003,0,0,0,
1473174448.063,,4.000000e+002,5.500019e+001,6.250148e-004,0.000000e+000,1.144817e-002,0.000000e+000,3,9.598110e-001,1.825000e+000,,,,,,,,,,,,,,,,,,0,5.000000e+000,5.000000e-001,2,1,2.967834e-003,0,0,0,
1473174473.994,,4.000000e+002,5.499870e+001,6.252279e-004,0.000000e+000,1.127166e-002,0.000000e+000,3,9.594165e-001,1.825000e+000,,,,,,,,,,,,,,,,,,0,5.000000e+000,5.000000e-001,2,1,2.971649e-003,0,0,0,
1473174606.196,,3.000000e+002,5.499275e+001,6.111667e-004,0.000000e+000,1.272780e-002,0.000000e+000,3,9.648738e-001,1.825000e+000,,,,,,,,,,,,,,,,,,0,5.000000e+000,5.000000e-001,2,1,1.192093e-002,0,0,0,
1473174633.874,,3.000000e+002,5.500243e+001,6.109937e-004,0.000000e+000,1.232690e-002,0.000000e+000,3,9.636953e-001,1.825000e+000,,,,,,,,,,,,,,,,,,0,5.000000e+000,5.000000e-001,2,1,1.491547e-003,0,0,0,
1473174767.107,,2.000000e+002,5.499870e+001,5.872725e-004,0.000000e+000,1.281339e-002,0.000000e+000,3,9.687310e-001,1.825000e+000,,,,,,,,,,,,,,,,,,0,5.000000e+000,5.000000e-001,2,1,5.947113e-003,0,0,0,
1473174792.285,,2.000000e+002,5.500317e+001,5.878555e-004,0.000000e+000,1.308493e-002,0.000000e+000,3,9.695047e-001,1.825000e+000,,,,,,,,,,,,,,,,,,0,5.000000e+000,5.000000e-001,2,1,2.990723e-003,0,0,0,
1473174911.726,,1.800000e+002,5.499648e+001,5.799140e-004,0.000000e+000,1.294265e-002,0.000000e+000,3,9.720320e-001,1.825000e+000,,,,,,,,,,,,,,,,,,0,5.000000e+000,5.000000e-001,2,1,4.470825e-003,0,0,0,
1473174936.405,,1.800000e+002,5.499648e+001,5.804158e-004,0.000000e+000,1.275544e-002,0.000000e+000,3,9.709139e-001,1.825000e+000,,,,,,,,,,,,,,,,,,0,5.000000e+000,5.000000e-001,2,1,1.487732e-003,0,0,0,
1473175066.075,,1.600000e+002,5.499945e+001,5.717363e-004,0.000000e+000,1.303720e-002,0.000000e+000,3,9.728581e-001,1.825000e+000,,,,,,,,,,,,,,,,,,0,5.000000e+000,5.000000e-001,2,1,1.480103e-003,0,0,0,
1473175093.361,,1.600000e+002,5.499871e+001,5.717080e-004,0.000000e+000,1.360183e-002,0.000000e+000,3,9.720184e-001,1.825000e+000,,,,,,,,,,,,,,,,,,0,5.000000e+000,5.000000e-001,2,1,0.000000e+000,0,0,0,
1473175211.622,,1.400000e+002,5.500615e+001,5.623357e-004,0.000000e+000,1.356280e-002,0.000000e+000,3,9.738581e-001,1.825000e+000,,,,,,,,,,,,,,,,,,0,5.000000e+000,5.000000e-001,2,1,1.190948e-002,0,1,0,
1473175233.840,,1.400000e+002,5.499945e+001,5.624452e-004,0.000000e+000,1.390587e-002,0.000000e+000,3,9.723231e-001,1.825000e+000,,,,,,,,,,,,,,,,,,0,5.000000e+000,5.000000e-001,2,1,1.480103e-003,0,1,0,
1473175354.528,,1.200000e+002,5.500466e+001,5.504003e-004,0.000000e+000,1.364676e-002,0.000000e+000,3,9.748719e-001,1.825000e+000,,,,,,,,,,,,,,,,,,0,5.000000e+000,5.000000e-001,2,1,8.937836e-003,0,1,0,
1473175379.144,,1.200000e+002,5.500093e+001,5.505005e-004,0.000000e+000,1.337320e-002,0.000000e+000,3,9.751433e-001,1.825000e+000,,,,,,,,,,,,,,,,,,0,5.000000e+000,5.000000e-001,2,1,1.487732e-003,0,1,0,
1473175505.728,,1.000000e+002,5.500764e+001,5.350362e-004,0.000000e+000,1.358092e-002,0.000000e+000,3,9.765591e-001,1.825000e+000,,,,,,,,,,,,,,,,,,0,5.000000e+000,5.000000e-001,2,1,1.786804e-002,0,1,0,
1473175530.156,,1.000000e+002,5.500093e+001,5.362756e-004,0.000000e+000,1.346834e-002,0.000000e+000,3,9.761109e-001,1.825000e+000,,,,,,,,,,,,,,,,,,0,5.000000e+000,5.000000e-001,2,1,1.487732e-003,0,1,0,
1473175657.095,,8.000000e+001,5.500094e+001,5.177565e-004,0.000000e+000,1.380581e-002,0.000000e+000,3,9.771421e-001,1.825000e+000,,,,,,,,,,,,,,,,,,0,5.000000e+000,5.000000e-001,2,1,4.459381e-003,0,1,0,
1473175682.816,,8.000000e+001,5.499870e+001,5.174004e-004,0.000000e+000,1.251291e-002,0.000000e+000,3,9.788949e-001,1.825000e+000,,,,,,,,,,,,,,,,,,0,5.000000e+000,5.000000e-001,2,1,2.971649e-003,0,1,0,
1473175801.948,,6.000000e+001,5.499945e+001,4.953006e-004,0.000000e+000,1.365928e-002,0.000000e+000,3,9.800618e-001,1.825000e+000,,,,,,,,,,,,,,,,,,0,5.000000e+000,5.000000e-001,2,1,1.480103e-003,0,0,0,
1473175827.260,,6.000000e+001,5.500019e+001,4.973924e-004,0.000000e+000,1.365728e-002,0.000000e+000,3,9.785107e-001,1.825000e+000,,,,,,,,,,,,,,,,,,0,5.000000e+000,5.000000e-001,2,1,0.000000e+000,0,0,0,
1473175955.470,,4.000000e+001,5.499499e+001,4.641413e-004,0.000000e+000,1.348697e-002,0.000000e+000,3,9.813933e-001,1.825000e+000,,,,,,,,,,,,,,,,,,0,5.000000e+000,5.000000e-001,2,1,1.491547e-003,0,0,0,
1473175979.399,,4.000000e+001,5.499871e+001,4.642640e-004,0.000000e+000,1.414555e-002,0.000000e+000,3,9.802921e-001,1.825000e+000,,,,,,,,,,,,,,,,,,0,5.000000e+000,5.000000e-001,2,1,0.000000e+000,0,0,0,
1473176104.589,,2.000000e+001,5.499870e+001,4.161462e-004,0.000000e+000,1.399365e-002,0.000000e+000,3,9.823775e-001,1.825000e+000,,,,,,,,,,,,,,,,,,0,5.000000e+000,5.000000e-001,2,1,2.971649e-003,0,0,0,
1473176140.170,,2.000000e+001,5.499796e+001,4.151577e-004,0.000000e+000,1.487901e-002,0.000000e+000,3,9.816517e-001,1.825000e+000,,,,,,,,,,,,,,,,,,0,5.000000e+000,5.000000e-001,2,1,7.438660e-003,0,0,0,
1473176261.108,,0.000000e+000,5.499796e+001,3.153348e-004,0.000000e+000,1.463072e-002,0.000000e+000,3,9.848935e-001,1.825000e+000,,,,,,,,,,,,,,,,,,0,5.000000e+000,5.000000e-001,2,1,7.438660e-003,0,0,0,
1473176285.036,,0.000000e+000,5.499647e+001,3.138377e-004,0.000000e+000,1.421732e-002,0.000000e+000,3,9.844714e-001,1.825000e+000,,,,,,,,,,,,,,,,,,0,5.000000e+000,5.000000e-001,2,1,7.442474e-003,0,0,0,
1473176404.032,,-2.000000e+001,5.499647e+001,-3.759951e-004,0.000000e+000,1.506149e-002,0.000000e+000,3,9.814736e-001,1.825000e+000,,,,,,,,,,,,,,,,,,0,5.000000e+000,5.000000e-001,2,1,7.442474e-003,0,0,0,
1473176430.505,,-2.000000e+001,5.499648e+001,-3.795529e-004,0.000000e+000,1.403857e-002,0.000000e+000,3,9.815926e-001,1.825000e+000,,,,,,,,,,,,,,,,,,0,5.000000e+000,5.000000e-001,2,1,4.470825e-003,0,0,0,
1473176554.992,,-4.000000e+001,5.500169e+001,-4.712248e-004,0.000000e+000,1.531256e-002,0.000000e+000,3,9.794783e-001,1.825000e+000,,,,,,,,,,,,,,,,,,0,5.000000e+000,5.000000e-001,2,1,5.958557e-003,0,0,0,
1473176583.219,,-4.000000e+001,5.499648e+001,-4.717670e-004,0.000000e+000,1.444369e-002,0.000000e+000,3,9.797481e-001,1.825000e+000,,,,,,,,,,,,,,,,,,0,5.000000e+000,5.000000e-001,2,1,4.470825e-003,0,0,0,
1473176703.963,,-6.000000e+001,5.499722e+001,-5.093738e-004,0.000000e+000,1.530264e-002,0.000000e+000,3,9.784246e-001,1.825000e+000,,,,,,,,,,,,,,,,,,0,5.000000e+000,5.000000e-001,2,1,2.979279e-003,0,1,0,
1473176727.392,,-6.000000e+001,5.500094e+001,-5.082649e-004,0.000000e+000,1.486967e-002,0.000000e+000,3,9.796656e-001,1.825000e+000,,,,,,,,,,,,,,,,,,0,5.000000e+000,5.000000e-001,2,1,4.459381e-003,0,1,0,
1473176853.830,,-8.000000e+001,5.499722e+001,-5.327698e-004,0.000000e+000,1.403318e-002,0.000000e+000,3,9.780095e-001,1.825000e+000,,,,,,,,,,,,,,,,,,0,5.000000e+000,5.000000e-001,2,1,5.950928e-003,0,1,0,
1473176879.009,,-8.000000e+001,5.500095e+001,-5.322049e-004,0.000000e+000,1.379165e-002,0.000000e+000,3,9.788342e-001,1.825000e+000,,,,,,,,,,,,,,,,,,0,5.000000e+000,5.000000e-001,2,1,7.450104e-003,0,1,0,
1473177006.212,,-1.000000e+002,5.500391e+001,-5.488643e-004,0.000000e+000,1.569005e-002,0.000000e+000,3,9.718683e-001,1.825000e+000,,,,,,,,,,,,,,,,,,0,5.000000e+000,5.000000e-001,2,1,4.470825e-003,0,1,0,
1473177030.390,,-1.000000e+002,5.500168e+001,-5.486657e-004,0.000000e+000,1.421689e-002,0.000000e+000,3,9.759292e-001,1.825000e+000,,,,,,,,,,,,,,,,,,0,5.000000e+000,5.000000e-001,2,1,2.979279e-003,0,1,0,
1473177152.328,,-1.200000e+002,5.499870e+001,-5.616674e-004,0.000000e+000,1.336283e-002,0.000000e+000,3,9.765307e-001,1.825000e+000,,,,,,,,,,,,,,,,,,0,5.000000e+000,5.000000e-001,2,1,2.971649e-003,0,1,0,
1473177175.782,,-1.200000e+002,5.499870e+001,-5.615432e-004,0.000000e+000,1.413820e-002,0.000000e+000,3,9.745823e-001,1.825000e+000,,,,,,,,,,,,,,,,,,0,5.000000e+000,5.000000e-001,2,1,2.971649e-003,0,1,0,
1473177296.474,,-1.400000e+002,5.500169e+001,-5.712202e-004,0.000000e+000,1.416381e-002,0.000000e+000,3,9.740985e-001,1.825000e+000,,,,,,,,,,,,,,,,,,0,5.000000e+000,5.000000e-001,2,1,1.488876e-002,0,0,0,
1473177320.917,,-1.400000e+002,5.501211e+001,-5.720343e-004,0.000000e+000,1.333454e-002,0.000000e+000,3,9.742224e-001,1.825000e+000,,,,,,,,,,,,,,,,,,0,5.000000e+000,5.000000e-001,2,1,2.679825e-002,0,0,0,
1473177447.418,,-1.600000e+002,5.500019e+001,-5.810512e-004,0.000000e+000,1.284417e-002,0.000000e+000,3,9.720349e-001,1.825000e+000,,,,,,,,,,,,,,,,,,0,5.000000e+000,5.000000e-001,2,1,5.950928e-003,0,0,0,
1473177472.864,,-1.600000e+002,5.500541e+001,-5.805449e-004,0.000000e+000,1.314230e-002,0.000000e+000,3,9.728698e-001,1.825000e+000,,,,,,,,,,,,,,,,,,0,5.000000e+000,5.000000e-001,2,1,1.338959e-002,0,0,0,
1473177597.522,,-1.800000e+002,5.500019e+001,-5.869780e-004,0.000000e+000,1.187628e-002,0.000000e+000,3,9.730518e-001,1.825000e+000,,,,,,,,,,,,,,,,,,0,5.000000e+000,5.000000e-001,2,1,0.000000e+000,0,0,0,
1473177623.077,,-1.800000e+002,5.500019e+001,-5.884834e-004,0.000000e+000,1.259827e-002,0.000000e+000,3,9.717820e-001,1.825000e+000,,,,,,,,,,,,,,,,,,0,5.000000e+000,5.000000e-001,2,1,2.967834e-003,0,0,0,
1473177744.515,,-2.000000e+002,5.499870e+001,-5.944708e-004,0.000000e+000,1.281555e-002,0.000000e+000,3,9.715233e-001,1.825000e+000,,,,,,,,,,,,,,,,,,0,5.000000e+000,5.000000e-001,2,1,5.947113e-003,0,0,0,
1473177769.988,,-2.000000e+002,5.499573e+001,-5.944457e-004,0.000000e+000,1.336567e-002,0.000000e+000,3,9.702728e-001,1.825000e+000,,,,,,,,,,,,,,,,,,0,5.000000e+000,5.000000e-001,2,1,5.962372e-003,0,0,0,
1473177900.980,,-3.000000e+002,5.499648e+001,-6.157346e-004,0.000000e+000,1.255209e-002,0.000000e+000,3,9.646049e-001,1.825000e+000,,,,,,,,,,,,,,,,,,0,5.000000e+000,5.000000e-001,2,1,1.487732e-003,0,0,0,
1473177924.096,,-3.000000e+002,5.499870e+001,-6.158277e-004,0.000000e+000,1.269213e-002,0.000000e+000,3,9.648662e-001,1.825000e+000,,,,,,,,,,,,,,,,,,0,5.000000e+000,5.000000e-001,2,1,2.971649e-003,0,0,0,
1473178056.416,,-4.000000e+002,5.499424e+001,-6.280238e-004,0.000000e+000,1.213555e-002,0.000000e+000,3,9.602395e-001,1.825000e+000,,,,,,,,,,,,,,,,,,0,5.000000e+000,5.000000e-001,2,1,1.190186e-002,0,0,0,
1473178084.400,,-4.000000e+002,5.499796e+001,-6.282086e-004,0.000000e+000,1.225055e-002,0.000000e+000,3,9.596713e-001,1.825000e+000,,,,,,,,,,,,,,,,,,0,5.000000e+000,5.000000e-001,2,1,1.491547e-003,0,0,0,
1473178217.094,,-5.000000e+002,5.499945e+001,-6.368295e-004,0.000000e+000,1.116939e-002,0.000000e+000,3,9.562114e-001,1.825000e+000,,,,,,,,,,,,,,,,,,0,5.000000e+000,5.000000e-001,2,1,4.459381e-003,0,1,0,
1473178241.022,,-5.000000e+002,5.500243e+001,-6.361635e-004,0.000000e+000,1.179364e-002,0.000000e+000,3,9.556909e-001,1.825000e+000,,,,,,,,,,,,,,,,,,0,5.000000e+000,5.000000e-001,2,1,4.478455e-003,0,1,0,
1473178371.643,,-6.000000e+002,5.499499e+001,-6.425863e-004,0.000000e+000,1.069878e-002,0.000000e+000,3,9.527155e-001,1.825000e+000,,,,,,,,,,,,,,,,,,0,5.000000e+000,5.000000e-001,2,1,1.041031e-002,0,1,0,
1473178395.930,,-6.000000e+002,5.500168e+001,-6.426543e-004,0.000000e+000,1.163062e-002,0.000000e+000,3,9.522787e-001,1.825000e+000,,,,,,,,,,,,,,,,,,0,5.000000e+000,5.000000e-001,2,1,0.000000e+000,0,1,0,
1473178527.181,,-7.000000e+002,5.499349e+001,-6.476864e-004,0.000000e+000,1.090636e-002,0.000000e+000,3,9.505527e-001,1.825000e+000,,,,,,,,,,,,,,,,,,0,5.000000e+000,5.000000e-001,2,1,1.340103e-002,0,1,0,
1473178551.859,,-7.000000e+002,5.500093e+001,-6.475270e-004,0.000000e+000,1.084103e-002,0.000000e+000,3,9.490175e-001,1.825000e+000,,,,,,,,,,,,,,,,,,0,5.000000e+000,5.000000e-001,2,1,1.487732e-003,0,1,0,
1473178677.048,,-1.000000e+003,5.499870e+001,-6.587303e-004,0.000000e+000,1.005443e-002,0.000000e+000,3,9.432607e-001,1.825000e+000,,,,,,,,,,,,,,,,,,0,5.000000e+000,5.000000e-001,2,1,2.971649e-003,0,1,0,
1473178701.785,,-1.000000e+003,5.499870e+001,-6.586241e-004,0.000000e+000,1.018421e-002,0.000000e+000,3,9.432716e-001,1.825000e+000,,,,,,,,,,,,,,,,,,0,5.000000e+000,5.000000e-001,2,1,2.971649e-003,0,1,0,
1473178837.478,,-3.000000e+003,5.498978e+001,-6.986387e-004,0.000000e+000,7.699124e-003,0.000000e+000,3,9.340245e-001,1.825000e+000,,,,,,,,,,,,,,,,,,0,5.000000e+000,5.000000e-001,2,1,1.786041e-002,0,0,0,
1473178862.960,,-3.000000e+003,5.499796e+001,-6.992545e-004,0.000000e+000,8.027904e-003,0.000000e+000,3,9.315283e-001,1.825000e+000,,,,,,,,,,,,,,,,,,0,5.000000e+000,5.000000e-001,2,1,7.438660e-003,0,0,0,
1473178997.400,,-5.000000e+003,5.500019e+001,-7.242475e-004,0.000000e+000,8.122210e-003,0.000000e+000,3,9.315006e-001,1.825000e+000,,,,,,,,,,,,,,,,,,0,5.000000e+000,5.000000e-001,2,1,2.967834e-003,0,0,0,
1473179021.258,,-5.000000e+003,5.499499e+001,-7.247203e-004,0.000000e+000,7.866492e-003,0.000000e+000,3,9.315640e-001,1.825000e+000,,,,,,,,,,,,,,,,,,0,5.000000e+000,5.000000e-001,2,1,1.041031e-002,0,0,0,
1473179156.060,,-7.000000e+003,5.499945e+001,-7.441726e-004,0.000000e+000,8.081284e-003,0.000000e+000,3,9.323872e-001,1.825000e+000,,,,,,,,,,,,,,,,,,0,5.000000e+000,5.000000e-001,2,1,1.480103e-003,0,0,0,
1473179207.024,,-7.000000e+003,5.499945e+001,-7.441917e-004,0.000000e+000,7.969341e-003,0.000000e+000,3,9.324052e-001,1.825000e+000,,,,,,,,,,,,,,,,,,0,5.000000e+000,5.000000e-001,2,1,4.459381e-003,0,0,0,
1473179339.013,,-9.000000e+003,5.500093e+001,-7.600804e-004,0.000000e+000,8.269714e-003,0.000000e+000,3,9.333456e-001,1.825000e+000,,,,,,,,,,,,,,,,,,0,5.000000e+000,5.000000e-001,2,1,1.487732e-003,0,0,0,
1473179364.192,,-9.000000e+003,5.499722e+001,-7.602784e-004,0.000000e+000,8.198323e-003,0.000000e+000,3,9.332936e-001,1.825000e+000,,,,,,,,,,,,,,,,,,0,5.000000e+000,5.000000e-001,2,1,2.979279e-003,0,0,0,
1473179500.134,,-1.000000e+004,5.499573e+001,-7.672628e-004,0.000000e+000,8.394492e-003,0.000000e+000,3,9.337209e-001,1.825000e+000,,,,,,,,,,,,,,,,,,0,5.000000e+000,5.000000e-001,2,1,2.979279e-003,0,0,0,
1473179524.312,,-1.000000e+004,5.499499e+001,-7.672575e-004,0.000000e+000,8.355197e-003,0.000000e+000,3,9.336634e-001,1.825000e+000,,,,,,,,,,,,,,,,,,0,5.000000e+000,5.000000e-001,2,1,7.450104e-003,0,0,0,
1473179699.010,,-2.000000e+004,5.499796e+001,-8.185966e-004,0.000000e+000,9.659056e-003,0.000000e+000,3,9.364140e-001,1.825000e+000,,,,,,,,,,,,,,,,,,0,5.000000e+000,5.000000e-001,2,1,1.491547e-003,0,0,0,
1473179725.690,,-2.000000e+004,5.499945e+001,-8.183768e-004,0.000000e+000,9.870676e-003,0.000000e+000,3,9.362254e-001,1.825000e+000,,,,,,,,,,,,,,,,,,0,5.000000e+000,5.000000e-001,2,1,1.480103e-003,0,1,0,
1473179892.658,,-3.000000e+004,5.500095e+001,-8.515735e-004,0.000000e+000,1.095587e-002,0.000000e+000,3,9.376819e-001,1.825000e+000,,,,,,,,,,,,,,,,,,0,5.000000e+000,5.000000e-001,2,1,7.450104e-003,0,1,0,
1473179918.141,,-3.000000e+004,5.500317e+001,-8.519770e-004,0.000000e+000,1.102094e-002,0.000000e+000,3,9.378281e-001,1.825000e+000,,,,,,,,,,,,,,,,,,0,5.000000e+000,5.000000e-001,2,1,0.000000e+000,0,1,0,
1473180096.339,,-4.000000e+004,5.500317e+001,-8.759772e-004,0.000000e+000,1.185862e-002,0.000000e+000,3,9.390069e-001,1.825000e+000,,,,,,,,,,,,,,,,,,0,5.000000e+000,5.000000e-001,2,1,0.000000e+000,0,1,0,
1473180120.517,,-4.000000e+004,5.500168e+001,-8.732999e-004,0.000000e+000,9.550869e-003,0.000000e+000,3,9.381359e-001,1.825000e+000,,,,,,,,,,,,,,,,,,0,5.000000e+000,5.000000e-001,2,1,0.000000e+000,0,1,0,
1473180301.215,,-5.000000e+004,5.499945e+001,-8.922808e-004,0.000000e+000,1.295665e-002,0.000000e+000,3,9.399101e-001,1.825000e+000,,,,,,,,,,,,,,,,,,0,5.000000e+000,5.000000e-001,2,1,4.459381e-003,0,1,0,
1473180327.644,,-5.000000e+004,5.500093e+001,-8.907309e-004,0.000000e+000,1.448293e-002,0.000000e+000,3,9.395023e-001,1.825000e+000,,,,,,,,,,,,,,,,,,0,5.000000e+000,5.000000e-001,2,1,1.487732e-003,0,1,0,
1473180509.274,,-6.000000e+004,5.500690e+001,-9.049894e-004,0.000000e+000,1.252853e-002,0.000000e+000,3,9.423382e-001,1.825000e+000,,,,,,,,,,,,,,,,,,0,5.000000e+000,5.000000e-001,2,1,2.233887e-002,0,0,0,
1473180533.560,,-6.000000e+004,5.499796e+001,-9.110728e-004,0.000000e+000,1.407320e-002,0.000000e+000,3,9.430929e-001,1.825000e+000,,,,,,,,,,,,,,,,,,0,5.000000e+000,5.000000e-001,2,1,1.491547e-003,0,0,0,
1473180710.806,,-7.000000e+004,5.499573e+001,-9.259625e-004,0.000000e+000,1.301950e-002,0.000000e+000,3,9.384515e-001,1.825000e+000,,,,,,,,,,,,,,,,,,0,5.000000e+000,5.000000e-001,2,1,2.979279e-003,0,0,0,
1473180733.544,,-7.000000e+004,5.499573e+001,-9.205272e-004,0.000000e+000,1.480706e-002,0.000000e+000,3,9.372574e-001,1.825000e+000,,,,,,,,,,,,,,,,,,0,5.000000e+000,5.000000e-001,2,1,0.000000e+000,0,0,0,
1473180932.604,,-6.000000e+004,5.499870e+001,-9.092388e-004,0.000000e+000,1.219906e-002,0.000000e+000,3,9.392807e-001,1.825000e+000,,,,,,,,,,,,,,,,,,0,5.000000e+000,5.000000e-001,2,1,8.930206e-003,0,0,0,
1473180955.232,,-6.000000e+004,5.500019e+001,-9.092898e-004,0.000000e+000,1.232788e-002,0.000000e+000,3,9.394917e-001,1.825000e+000,,,,,,,,,,,,,,,,,,0,5.000000e+000,5.000000e-001,2,1,0.000000e+000,0,0,0,
1473181130.034,,-5.000000e+004,5.499870e+001,-8.948394e-004,0.000000e+000,1.122080e-002,0.000000e+000,3,9.394304e-001,1.825000e+000,,,,,,,,,,,,,,,,,,0,5.000000e+000,5.000000e-001,2,1,5.947113e-003,0,0,0,
1473181156.963,,-5.000000e+004,5.499871e+001,-8.947628e-004,0.000000e+000,1.128460e-002,0.000000e+000,3,9.392596e-001,1.825000e+000,,,,,,,,,,,,,,,,,,0,5.000000e+000,5.000000e-001,2,1,0.000000e+000,0,0,0,
1473181341.911,,-4.000000e+004,5.500094e+001,-8.753418e-004,0.000000e+000,1.103773e-002,0.000000e+000,3,9.387418e-001,1.825000e+000,,,,,,,,,,,,,,,,,,0,5.000000e+000,5.000000e-001,2,1,4.459381e-003,0,1,0,
1473181365.593,,-4.000000e+004,5.500019e+001,-8.764762e-004,0.000000e+000,1.100139e-002,0.000000e+000,3,9.383567e-001,1.825000e+000,,,,,,,,,,,,,,,,,,0,5.000000e+000,5.000000e-001,2,1,2.967834e-003,0,1,0,
1473181539.821,,-3.000000e+004,5.500616e+001,-8.517150e-004,0.000000e+000,9.887934e-003,0.000000e+000,3,9.376232e-001,1.825000e+000,,,,,,,,,,,,,,,,,,0,5.000000e+000,5.000000e-001,2,1,2.971649e-003,0,1,0,
1473181563.045,,-3.000000e+004,5.500019e+001,-8.509547e-004,0.000000e+000,9.836081e-003,0.000000e+000,3,9.386856e-001,1.825000e+000,,,,,,,,,,,,,,,,,,0,5.000000e+000,5.000000e-001,2,1,0.000000e+000,0,1,0,
1473181736.173,,-2.000000e+004,5.500093e+001,-8.198196e-004,0.000000e+000,6.907233e-003,0.000000e+000,3,9.381373e-001,1.825000e+000,,,,,,,,,,,,,,,,,,0,5.000000e+000,5.000000e-001,2,1,1.487732e-003,0,1,0,
1473181761.249,,-2.000000e+004,5.499945e+001,-8.182594e-004,0.000000e+000,9.353547e-003,0.000000e+000,3,9.348639e-001,1.825000e+000,,,,,,,,,,,,,,,,,,0,5.000000e+000,5.000000e-001,2,1,1.480103e-003,0,1,0,
1473181931.706,,-1.000000e+004,5.500019e+001,-7.668291e-004,0.000000e+000,8.104941e-003,0.000000e+000,3,9.329299e-001,1.825000e+000,,,,,,,,,,,,,,,,,,0,5.000000e+000,5.000000e-001,2,1,1.489258e-002,0,1,0,
1473181955.905,,-1.000000e+004,5.499945e+001,-7.671032e-004,0.000000e+000,7.184044e-003,0.000000e+000,3,9.342262e-001,1.825000e+000,,,,,,,,,,,,,,,,,,0,5.000000e+000,5.000000e-001,2,1,1.480103e-003,0,0,0,
1473182088.131,,-9.000000e+003,5.499796e+001,-7.603896e-004,0.000000e+000,7.713629e-003,0.000000e+000,3,9.328862e-001,1.825000e+000,,,,,,,,,,,,,,,,,,0,5.000000e+000,5.000000e-001,2,1,1.491547e-003,0,0,0,
1473182111.548,,-9.000000e+003,5.500243e+001,-7.601197e-004,0.000000e+000,7.412245e-003,0.000000e+000,3,9.328514e-001,1.825000e+000,,,,,,,,,,,,,,,,,,0,5.000000e+000,5.000000e-001,2,1,1.339722e-002,0,0,0,
1473182243.170,,-7.000000e+003,5.499722e+001,-7.441228e-004,0.000000e+000,7.290394e-003,0.000000e+000,3,9.322446e-001,1.825000e+000,,,,,,,,,,,,,,,,,,0,5.000000e+000,5.000000e-001,2,1,8.930206e-003,0,0,0,
1473182266.376,,-7.000000e+003,5.500019e+001,-7.455325e-004,0.000000e+000,7.444502e-003,0.000000e+000,3,9.332011e-001,1.825000e+000,,,,,,,,,,,,,,,,,,0,5.000000e+000,5.000000e-001,2,1,2.967834e-003,0,0,0,
1473182401.584,,-5.000000e+003,5.500243e+001,-7.250434e-004,0.000000e+000,7.069333e-003,0.000000e+000,3,9.308596e-001,1.825000e+000,,,,,,,,,,,,,,,,,,0,5.000000e+000,5.000000e-001,2,1,1.491547e-003,0,0,0,
1473182427.513,,-5.000000e+003,5.500169e+001,-7.244012e-004,0.000000e+000,7.238307e-003,0.000000e+000,3,9.316074e-001,1.825000e+000,,,,,,,,,,,,,,,,,,0,5.000000e+000,5.000000e-001,2,1,5.958557e-003,0,0,0,
1473182556.213,,-3.000000e+003,5.500169e+001,-6.993038e-004,0.000000e+000,7.274721e-003,0.000000e+000,3,9.324673e-001,1.825000e+000,,,,,,,,,,,,,,,,,,0,5.000000e+000,5.000000e-001,2,1,5.958557e-003,0,0,0,
1473182581.417,,-3.000000e+003,5.499648e+001,-6.993460e-004,0.000000e+000,7.520144e-003,0.000000e+000,3,9.326598e-001,1.825000e+000,,,,,,,,,,,,,,,,,,0,5.000000e+000,5.000000e-001,2,1,1.487732e-003,0,0,0,
1473182724.111,,-1.000000e+003,5.499870e+001,-6.575989e-004,0.000000e+000,9.218318e-003,0.000000e+000,3,9.432371e-001,1.825000e+000,,,,,,,,,,,,,,,,,,0,5.000000e+000,5.000000e-001,2,1,5.947113e-003,0,0,0,
1473182751.790,,-1.000000e+003,5.500019e+001,-6.576618e-004,0.000000e+000,9.918272e-003,0.000000e+000,3,9.430550e-001,1.825000e+000,,,,,,,,,,,,,,,,,,0,5.000000e+000,5.000000e-001,2,1,2.967834e-003,0,0,0,
1473182887.737,,-7.000000e+002,5.499945e+001,-6.462657e-004,0.000000e+000,1.131916e-002,0.000000e+000,3,9.474691e-001,1.825000e+000,,,,,,,,,,,,,,,,,,0,5.000000e+000,5.000000e-001,2,1,1.480103e-003,0,1,0,
1473182915.352,,-7.000000e+002,5.499573e+001,-6.461527e-004,0.000000e+000,1.034556e-002,0.000000e+000,3,9.492599e-001,1.825000e+000,,,,,,,,,,,,,,,,,,0,5.000000e+000,5.000000e-001,2,1,5.962372e-003,0,1,0,
1473183048.599,,-6.000000e+002,5.500093e+001,-6.409682e-004,0.000000e+000,1.082623e-002,0.000000e+000,3,9.516239e-001,1.825000e+000,,,,,,,,,,,,,,,,,,0,5.000000e+000,5.000000e-001,2,1,1.487732e-003,0,1,0,
1473183073.966,,-6.000000e+002,5.500093e+001,-6.409961e-004,0.000000e+000,1.114022e-002,0.000000e+000,3,9.515685e-001,1.825000e+000,,,,,,,,,,,,,,,,,,0,5.000000e+000,5.000000e-001,2,1,1.487732e-003,0,1,0,
1473183206.488,,-5.000000e+002,5.500764e+001,-6.344144e-004,0.000000e+000,1.177729e-002,0.000000e+000,3,9.551244e-001,1.825000e+000,,,,,,,,,,,,,,,,,,0,5.000000e+000,5.000000e-001,2,1,8.930206e-003,0,1,0,
1473183231.166,,-5.000000e+002,5.499870e+001,-6.341241e-004,0.000000e+000,1.156360e-002,0.000000e+000,3,9.548840e-001,1.825000e+000,,,,,,,,,,,,,,,,,,0,5.000000e+000,5.000000e-001,2,1,5.947113e-003,0,1,0,
1473183362.663,,-4.000000e+002,5.500168e+001,-6.250027e-004,0.000000e+000,1.186117e-002,0.000000e+000,3,9.604467e-001,1.825000e+000,,,,,,,,,,,,,,,,,,0,5.000000e+000,5.000000e-001,2,1,0.000000e+000,0,1,0,
1473183389.842,,-4.000000e+002,5.499200e+001,-6.248858e-004,0.000000e+000,1.209969e-002,0.000000e+000,3,9.594439e-001,1.825000e+000,,,,,,,,,,,,,,,,,,0,5.000000e+000,5.000000e-001,2,1,1.636887e-002,0,1,0,
1473183525.596,,-3.000000e+002,5.499201e+001,-6.106513e-004,0.000000e+000,1.260156e-002,0.000000e+000,3,9.650473e-001,1.825000e+000,,,,,,,,,,,,,,,,,,0,5.000000e+000,5.000000e-001,2,1,2.531052e-002,0,1,0,
1473183550.025,,-3.000000e+002,5.499945e+001,-6.107499e-004,0.000000e+000,1.265354e-002,0.000000e+000,3,9.633108e-001,1.825000e+000,,,,,,,,,,,,,,,,,,0,5.000000e+000,5.000000e-001,2,1,1.480103e-003,0,0,0,
1473183682.767,,-2.000000e+002,5.499722e+001,-5.872039e-004,0.000000e+000,1.317430e-002,0.000000e+000,3,9.696956e-001,1.825000e+000,,,,,,,,,,,,,,,,,,0,5.000000e+000,5.000000e-001,2,1,2.979279e-003,0,0,0,
1473183708.799,,-2.000000e+002,5.499870e+001,-5.874198e-004,0.000000e+000,1.281743e-002,0.000000e+000,3,9.697154e-001,1.825000e+000,,,,,,,,,,,,,,,,,,0,5.000000e+000,5.000000e-001,2,1,2.971649e-003,0,0,0,
1473183830.177,,-1.800000e+002,5.499126e+001,-5.798933e-004,0.000000e+000,1.320184e-002,0.000000e+000,3,9.716190e-001,1.825000e+000,,,,,,,,,,,,,,,,,,0,5.000000e+000,5.000000e-001,2,1,1.786041e-002,0,0,0,
1473183856.714,,-1.800000e+002,5.500019e+001,-5.804290e-004,0.000000e+000,1.281060e-002,0.000000e+000,3,9.712923e-001,1.825000e+000,,,,,,,,,,,,,,,,,,0,5.000000e+000,5.000000e-001,2,1,0.000000e+000,0,0,0,
1473183976.929,,-1.600000e+002,5.500838e+001,-5.709243e-004,0.000000e+000,1.377663e-002,0.000000e+000,3,9.722143e-001,1.825000e+000,,,,,,,,,,,,,,,,,,0,5.000000e+000,5.000000e-001,2,1,1.638794e-002,0,0,0,
1473184003.667,,-1.600000e+002,5.499722e+001,-5.714307e-004,0.000000e+000,1.408115e-002,0.000000e+000,3,9.721789e-001,1.825000e+000,,,,,,,,,,,,,,,,,,0,5.000000e+000,5.000000e-001,2,1,2.979279e-003,0,0,0,
1473184125.105,,-1.400000e+002,5.500019e+001,-5.620469e-004,0.000000e+000,1.395124e-002,0.000000e+000,3,9.730395e-001,1.825000e+000,,,,,,,,,,,,,,,,,,0,5.000000e+000,5.000000e-001,2,1,2.967834e-003,0,0,0,
1473184152.045,,-1.400000e+002,5.499871e+001,-5.623698e-004,0.000000e+000,1.364532e-002,0.000000e+000,3,9.740403e-001,1.825000e+000,,,,,,,,,,,,,,,,,,0,5.000000e+000,5.000000e-001,2,1,0.000000e+000,0,0,0,
1473184272.680,,-1.200000e+002,5.499945e+001,-5.506431e-004,0.000000e+000,1.453337e-002,0.000000e+000,3,9.734500e-001,1.825000e+000,,,,,,,,,,,,,,,,,,0,5.000000e+000,5.000000e-001,2,1,1.042938e-002,0,0,0,
1473184299.982,,-1.200000e+002,5.499573e+001,-5.505991e-004,0.000000e+000,1.415155e-002,0.000000e+000,3,9.747330e-001,1.825000e+000,,,,,,,,,,,,,,,,,,0,5.000000e+000,5.000000e-001,2,1,5.962372e-003,0,0,0,
1473184429.171,,-1.000000e+002,5.500093e+001,-5.357736e-004,0.000000e+000,1.463275e-002,0.000000e+000,3,9.753035e-001,1.825000e+000,,,,,,,,,,,,,,,,,,0,5.000000e+000,5.000000e-001,2,1,1.487732e-003,0,1,0,
1473184454.545,,-1.000000e+002,5.500019e+001,-5.360373e-004,0.000000e+000,1.335027e-002,0.000000e+000,3,9.766191e-001,1.825000e+000,,,,,,,,,,,,,,,,,,0,5.000000e+000,5.000000e-001,2,1,2.967834e-003,0,1,0,
1473184573.385,,-8.000000e+001,5.500243e+001,-5.172103e-004,0.000000e+000,1.449018e-002,0.000000e+000,3,9.776981e-001,1.825000e+000,,,,,,,,,,,,,,,,,,0,5.000000e+000,5.000000e-001,2,1,1.042175e-002,0,1,0,
1473184597.814,,-8.000000e+001,5.499870e+001,-5.184397e-004,0.000000e+000,1.385772e-002,0.000000e+000,3,9.783515e-001,1.825000e+000,,,,,,,,,,,,,,,,,,0,5.000000e+000,5.000000e-001,2,1,5.947113e-003,0,1,0,
1473184716.251,,-6.000000e+001,5.500615e+001,-4.949406e-004,0.000000e+000,1.446796e-002,0.000000e+000,3,9.788871e-001,1.825000e+000,,,,,,,,,,,,,,,,,,0,5.000000e+000,5.000000e-001,2,1,5.958557e-003,0,1,0,
1473184741.680,,-6.000000e+001,5.500168e+001,-4.953826e-004,0.000000e+000,1.441883e-002,0.000000e+000,3,9.788554e-001,1.825000e+000,,,,,,,,,,,,,,,,,,0,5.000000e+000,5.000000e-001,2,1,2.979279e-003,0,1,0,
1473184864.166,,-4.000000e+001,5.499126e+001,-4.644032e-004,0.000000e+000,1.441063e-002,0.000000e+000,3,9.794807e-001,1.825000e+000,,,,,,,,,,,,,,,,,,0,5.000000e+000,5.000000e-001,2,1,2.381134e-002,0,1,0,
1473184886.094,,-4.000000e+001,5.500093e+001,-4.636774e-004,0.000000e+000,1.440066e-002,0.000000e+000,3,9.807615e-001,1.825000e+000,,,,,,,,,,,,,,,,,,0,5.000000e+000,5.000000e-001,2,1,1.487732e-003,0,1,0,
1473185006.783,,-2.000000e+001,5.499945e+001,-4.158611e-004,0.000000e+000,1.350564e-002,0.000000e+000,3,9.826044e-001,1.825000e+000,,,,,,,,,,,,,,,,,,0,5.000000e+000,5.000000e-001,2,1,1.480103e-003,0,1,0,
1473185030.463,,-2.000000e+001,5.500019e+001,-4.154239e-004,0.000000e+000,1.396100e-002,0.000000e+000,3,9.833084e-001,1.825000e+000,,,,,,,,,,,,,,,,,,0,5.000000e+000,5.000000e-001,2,1,2.967834e-003,0,0,0,
1473185150.156,,0.000000e+000,5.499722e+001,-3.161255e-004,0.000000e+000,1.791783e-002,0.000000e+000,3,9.801145e-001,1.825000e+000,,,,,,,,,,,,,,,,,,0,5.000000e+000,5.000000e-001,2,1,2.979279e-003,0,0,0,
1473185174.124,,0.000000e+000,5.499796e+001,-3.152083e-004,0.000000e+000,1.518929e-002,0.000000e+000,3,9.836116e-001,1.825000e+000,,,,,,,,,,,,,,,,,,0,5.000000e+000,5.000000e-001,2,1,7.438660e-003,0,0,0,
1473185300.586,,2.000000e+001,5.500019e+001,3.756567e-004,0.000000e+000,1.552871e-002,0.000000e+000,3,9.760873e-001,1.825000e+000,,,,,,,,,,,,,,,,,,0,5.000000e+000,5.000000e-001,2,1,2.967834e-003,0,0,0,
1473185327.015,,2.000000e+001,5.499945e+001,3.817158e-004,0.000000e+000,1.424933e-002,0.000000e+000,3,9.815121e-001,1.825000e+000,,,,,,,,,,,,,,,,,,0,5.000000e+000,5.000000e-001,2,1,1.480103e-003,0,0,0,
1473185447.457,,4.000000e+001,5.499796e+001,4.706173e-004,0.000000e+000,1.475444e-002,0.000000e+000,3,9.801494e-001,1.825000e+000,,,,,,,,,,,,,,,,,,0,5.000000e+000,5.000000e-001,2,1,1.491547e-003,0,0,0,
1473185471.635,,4.000000e+001,5.499722e+001,4.720141e-004,0.000000e+000,1.540849e-002,0.000000e+000,3,9.793791e-001,1.825000e+000,,,,,,,,,,,,,,,,,,0,5.000000e+000,5.000000e-001,2,1,5.950928e-003,0,0,0,
1473185599.612,,6.000000e+001,5.500094e+001,5.083936e-004,0.000000e+000,1.375935e-002,0.000000e+000,3,9.802169e-001,1.825000e+000,,,,,,,,,,,,,,,,,,0,5.000000e+000,5.000000e-001,2,1,1.041794e-002,0,0,0,
1473185623.740,,6.000000e+001,5.499796e+001,5.086544e-004,0.000000e+000,1.468655e-002,0.000000e+000,3,9.794269e-001,1.825000e+000,,,,,,,,,,,,,,,,,,0,5.000000e+000,5.000000e-001,2,1,1.491547e-003,0,0,0,
1473185746.540,,8.000000e+001,5.499796e+001,5.319799e-004,0.000000e+000,1.421529e-002,0.000000e+000,3,9.781090e-001,1.825000e+000,,,,,,,,,,,,,,,,,,0,5.000000e+000,5.000000e-001,2,1,1.042175e-002,0,0,0,
1473185773.236,,8.000000e+001,5.499945e+001,5.314659e-004,0.000000e+000,1.459018e-002,0.000000e+000,3,9.780828e-001,1.825000e+000,,,,,,,,,,,,,,,,,,0,5.000000e+000,5.000000e-001,2,1,1.480103e-003,0,0,0,
1473185901.675,,1.000000e+002,5.500019e+001,5.489033e-004,0.000000e+000,1.379745e-002,0.000000e+000,3,9.765874e-001,1.825000e+000,,,,,,,,,,,,,,,,,,0,5.000000e+000,5.000000e-001,2,1,5.950928e-003,0,1,0,
1473185926.910,,1.000000e+002,5.500243e+001,5.490996e-004,0.000000e+000,1.449697e-002,0.000000e+000,3,9.758974e-001,1.825000e+000,,,,,,,,,,,,,,,,,,0,5.000000e+000,5.000000e-001,2,1,1.638031e-002,0,1,0,
1473186047.693,,1.200000e+002,5.499945e+001,5.615996e-004,0.000000e+000,1.447955e-002,0.000000e+000,3,9.744616e-001,1.825000e+000,,,,,,,,,,,,,,,,,,0,5.000000e+000,5.000000e-001,2,1,4.459381e-003,0,1,0,
1473186073.182,,1.200000e+002,5.500168e+001,5.620433e-004,0.000000e+000,1.447594e-002,0.000000e+000,3,9.746252e-001,1.825000e+000,,,,,,,,,,,,,,,,,,0,5.000000e+000,5.000000e-001,2,1,2.979279e-003,0,1,0,
1473186191.673,,1.400000e+002,5.500243e+001,5.728384e-004,0.000000e+000,1.384206e-002,0.000000e+000,3,9.741385e-001,1.825000e+000,,,,,,,,,,,,,,,,,,0,5.000000e+000,5.000000e-001,2,1,4.478455e-003,0,1,0,
1473186216.692,,1.400000e+002,5.500169e+001,5.725538e-004,0.000000e+000,1.377365e-002,0.000000e+000,3,9.737449e-001,1.825000e+000,,,,,,,,,,,,,,,,,,0,5.000000e+000,5.000000e-001,2,1,5.958557e-003,0,1,0,
1473186335.383,,1.600000e+002,5.499647e+001,5.809621e-004,0.000000e+000,1.372925e-002,0.000000e+000,3,9.721928e-001,1.825000e+000,,,,,,,,,,,,,,,,,,0,5.000000e+000,5.000000e-001,2,1,1.041794e-002,0,1,0,
1473186361.562,,1.600000e+002,5.499945e+001,5.812292e-004,0.000000e+000,1.371058e-002,0.000000e+000,3,9.724784e-001,1.825000e+000,,,,,,,,,,,,,,,,,,0,5.000000e+000,5.000000e-001,2,1,4.459381e-003,0,1,0,
1473186486.781,,1.800000e+002,5.499796e+001,5.882660e-004,0.000000e+000,1.391101e-002,0.000000e+000,3,9.710320e-001,1.825000e+000,,,,,,,,,,,,,,,,,,0,5.000000e+000,5.000000e-001,2,1,4.459381e-003,0,1,0,
1473186513.209,,1.800000e+002,5.500392e+001,5.880122e-004,0.000000e+000,1.409258e-002,0.000000e+000,3,9.714061e-001,1.825000e+000,,,,,,,,,,,,,,,,,,0,5.000000e+000,5.000000e-001,2,1,1.499176e-003,0,0,0,
1473186632.651,,2.000000e+002,5.499722e+001,5.946051e-004,0.000000e+000,1.500611e-002,0.000000e+000,3,9.689724e-001,1.825000e+000,,,,,,,,,,,,,,,,,,0,5.000000e+000,5.000000e-001,2,1,5.950928e-003,0,0,0,
1473186655.354,,2.000000e+002,5.499945e+001,5.945220e-004,0.000000e+000,1.349370e-002,0.000000e+000,3,9.700111e-001,1.825000e+000,,,,,,,,,,,,,,,,,,0,5.000000e+000,5.000000e-001,2,1,4.459381e-003,0,0,0,
1473186790.794,,3.000000e+002,5.499647e+001,6.140928e-004,0.000000e+000,1.180018e-002,0.000000e+000,3,9.619835e-001,1.825000e+000,,,,,,,,,,,,,,,,,,0,5.000000e+000,5.000000e-001,2,1,7.442474e-003,0,0,0,
1473186815.277,,3.000000e+002,5.499796e+001,6.152104e-004,0.000000e+000,1.294529e-002,0.000000e+000,3,9.646336e-001,1.825000e+000,,,,,,,,,,,,,,,,,,0,5.000000e+000,5.000000e-001,2,1,1.491547e-003,0,0,0,
1473186945.733,,4.000000e+002,5.499722e+001,6.288849e-004,0.000000e+000,1.255056e-002,0.000000e+000,3,9.606782e-001,1.825000e+000,,,,,,,,,,,,,,,,,,0,5.000000e+000,5.000000e-001,2,1,5.950928e-003,0,0,0,
1473186970.944,,4.000000e+002,5.499573e+001,6.281484e-004,0.000000e+000,1.241237e-002,0.000000e+000,3,9.596592e-001,1.825000e+000,,,,,,,,,,,,,,,,,,0,5.000000e+000,5.000000e-001,2,1,2.979279e-003,0,0,0,
1473187105.164,,5.000000e+002,5.499870e+001,6.373089e-004,0.000000e+000,1.154303e-002,0.000000e+000,3,9.554248e-001,1.825000e+000,,,,,,,,,,,,,,,,,,0,5.000000e+000,5.000000e-001,2,1,2.971649e-003,0,0,0,
1473187131.447,,5.000000e+002,5.499647e+001,6.364937e-004,0.000000e+000,1.206688e-002,0.000000e+000,3,9.550868e-001,1.825000e+000,,,,,,,,,,,,,,,,,,0,5.000000e+000,5.000000e-001,2,1,1.041794e-002,0,0,0,
1473187260.698,,6.000000e+002,5.498903e+001,6.429607e-004,0.000000e+000,1.119090e-002,0.000000e+000,3,9.527096e-001,1.825000e+000,,,,,,,,,,,,,,,,,,0,5.000000e+000,5.000000e-001,2,1,1.340103e-002,0,0,0,
1473187287.660,,6.000000e+002,5.500093e+001,6.440114e-004,0.000000e+000,1.139461e-002,0.000000e+000,3,9.529336e-001,1.825000e+000,,,,,,,,,,,,,,,,,,0,5.000000e+000,5.000000e-001,2,1,1.487732e-003,0,0,0,
1473187420.145,,7.000000e+002,5.499573e+001,6.480843e-004,0.000000e+000,1.114956e-002,0.000000e+000,3,9.490210e-001,1.825000e+000,,,,,,,,,,,,,,,,,,0,5.000000e+000,5.000000e-001,2,1,5.962372e-003,0,1,0,
1473187446.397,,7.000000e+002,5.499945e+001,6.480362e-004,0.000000e+000,1.098250e-002,0.000000e+000,3,9.491819e-001,1.825000e+000,,,,,,,,,,,,,,,,,,0,5.000000e+000,5.000000e-001,2,1,1.480103e-003,0,1,0,
1473187572.339,,1.000000e+003,5.499722e+001,6.588213e-004,0.000000e+000,1.015188e-002,0.000000e+000,3,9.434659e-001,1.825000e+000,,,,,,,,,,,,,,,,,,0,5.000000e+000,5.000000e-001,2,1,0.000000e+000,0,1,0,
1473187597.540,,1.000000e+003,5.499871e+001,6.588075e-004,0.000000e+000,1.013664e-002,0.000000e+000,3,9.433472e-001,1.825000e+000,,,,,,,,,,,,,,,,,,0,5.000000e+000,5.000000e-001,2,1,0.000000e+000,0,1,0,
1473187731.774,,3.000000e+003,5.500243e+001,6.993248e-004,0.000000e+000,6.932876e-003,0.000000e+000,3,9.334682e-001,1.825000e+000,,,,,,,,,,,,,,,,,,0,5.000000e+000,5.000000e-001,2,1,1.491547e-003,0,1,0,
1473187755.452,,3.000000e+003,5.500391e+001,6.995401e-004,0.000000e+000,8.256475e-003,0.000000e+000,3,9.321542e-001,1.825000e+000,,,,,,,,,,,,,,,,,,0,5.000000e+000,5.000000e-001,2,1,4.470825e-003,0,1,0,
1473187892.895,,5.000000e+003,5.500243e+001,7.249059e-004,0.000000e+000,7.490281e-003,0.000000e+000,3,9.316388e-001,1.825000e+000,,,,,,,,,,,,,,,,,,0,5.000000e+000,5.000000e-001,2,1,1.638031e-002,0,1,0,
1473187918.324,,5.000000e+003,5.499945e+001,7.246458e-004,0.000000e+000,8.277459e-003,0.000000e+000,3,9.318122e-001,1.825000e+000,,,,,,,,,,,,,,,,,,0,5.000000e+000,5.000000e-001,2,1,4.459381e-003,0,1,0,
1473188056.282,,7.000000e+003,5.500019e+001,7.441625e-004,0.000000e+000,8.045679e-003,0.000000e+000,3,9.327064e-001,1.825000e+000,,,,,,,,,,,,,,,,,,0,5.000000e+000,5.000000e-001,2,1,0.000000e+000,0,0,0,
1473188080.711,,7.000000e+003,5.499945e+001,7.443857e-004,0.000000e+000,7.744764e-003,0.000000e+000,3,9.318814e-001,1.825000e+000,,,,,,,,,,,,,,,,,,0,5.000000e+000,5.000000e-001,2,1,1.480103e-003,0,0,0,
1473188218.442,,9.000000e+003,5.499424e+001,7.599946e-004,0.000000e+000,9.014614e-003,0.000000e+000,3,9.331467e-001,1.825000e+000,,,,,,,,,,,,,,,,,,0,5.000000e+000,5.000000e-001,2,1,2.983093e-003,0,0,0,
1473188241.939,,9.000000e+003,5.499870e+001,7.602459e-004,0.000000e+000,8.257156e-003,0.000000e+000,3,9.329284e-001,1.825000e+000,,,,,,,,,,,,,,,,,,0,5.000000e+000,5.000000e-001,2,1,2.971649e-003,0,0,0,
1473188374.628,,1.000000e+004,5.499648e+001,7.669867e-004,0.000000e+000,8.246905e-003,0.000000e+000,3,9.335910e-001,1.825000e+000,,,,,,,,,,,,,,,,,,0,5.000000e+000,5.000000e-001,2,1,1.638031e-002,0,0,0,
1473188401.117,,1.000000e+004,5.499796e+001,7.668673e-004,0.000000e+000,8.089971e-003,0.000000e+000,3,9.338012e-001,1.825000e+000,,,,,,,,,,,,,,,,,,0,5.000000e+000,5.000000e-001,2,1,4.459381e-003,0,0,0,
1473188575.750,,2.000000e+004,5.500094e+001,8.163571e-004,0.000000e+000,9.410935e-003,0.000000e+000,3,9.352128e-001,1.825000e+000,,,,,,,,,,,,,,,,,,0,5.000000e+000,5.000000e-001,2,1,4.459381e-003,0,0,0,
1473188601.787,,2.000000e+004,5.499796e+001,8.186196e-004,0.000000e+000,9.707890e-003,0.000000e+000,3,9.364544e-001,1.825000e+000,,,,,,,,,,,,,,,,,,0,5.000000e+000,5.000000e-001,2,1,1.491547e-003,0,0,0,
1473188776.734,,3.000000e+004,5.499201e+001,8.521046e-004,0.000000e+000,1.073136e-002,0.000000e+000,3,9.378774e-001,1.825000e+000,,,,,,,,,,,,,,,,,,0,5.000000e+000,5.000000e-001,2,1,1.340103e-002,0,0,0,
1473188802.668,,3.000000e+004,5.499871e+001,8.520901e-004,0.000000e+000,1.083875e-002,0.000000e+000,3,9.379326e-001,1.825000e+000,,,,,,,,,,,,,,,,,,0,5.000000e+000,5.000000e-001,2,1,0.000000e+000,0,0,0,
1473188970.673,,4.000000e+004,5.500168e+001,8.764232e-004,0.000000e+000,1.196917e-002,0.000000e+000,3,9.392613e-001,1.825000e+000,,,,,,,,,,,,,,,,,,0,5.000000e+000,5.000000e-001,2,1,0.000000e+000,0,1,0,
1473188995.101,,4.000000e+004,5.499945e+001,8.764467e-004,0.000000e+000,1.200609e-002,0.000000e+000,3,9.380577e-001,1.825000e+000,,,,,,,,,,,,,,,,,,0,5.000000e+000,5.000000e-001,2,1,1.480103e-003,0,1,0,
1473189180.309,,5.000000e+004,5.500466e+001,8.945919e-004,0.000000e+000,1.251791e-002,0.000000e+000,3,9.393088e-001,1.825000e+000,,,,,,,,,,,,,,,,,,0,5.000000e+000,5.000000e-001,2,1,2.979279e-003,0,1,0,
1473189204.012,,5.000000e+004,5.500764e+001,8.943902e-004,0.000000e+000,1.289046e-002,0.000000e+000,3,9.382834e-001,1.825000e+000,,,,,,,,,,,,,,,,,,0,5.000000e+000,5.000000e-001,2,1,0.000000e+000,0,1,0,
1473189385.460,,6.000000e+004,5.500391e+001,9.101574e-004,0.000000e+000,1.458646e-002,0.000000e+000,3,9.349827e-001,1.825000e+000,,,,,,,,,,,,,,,,,,0,5.000000e+000,5.000000e-001,2,1,4.470825e-003,0,1,0,
1473189409.694,,6.000000e+004,5.500093e+001,9.096497e-004,0.000000e+000,1.635194e-002,0.000000e+000,3,9.345075e-001,1.825000e+000,,,,,,,,,,,,,,,,,,0,5.000000e+000,5.000000e-001,2,1,1.487732e-003,0,1,0,
1473189592.186,,7.000000e+004,5.499424e+001,9.272725e-004,0.000000e+000,1.303031e-002,0.000000e+000,3,9.378686e-001,1.825000e+000,,,,,,,,,,,,,,,,,,0,5.000000e+000,5.000000e-001,2,1,5.958557e-003,0,1,0,
1473189617.118,,7.000000e+004,5.499945e+001,9.205253e-004,0.000000e+000,1.611682e-002,0.000000e+000,3,9.382409e-001,1.825000e+000,,,,,,,,,,,,,,,,,,0,5.000000e+000,5.000000e-001,2,1,1.480103e-003,0,1,0,
1473189629.332,,7.000000e+004,5.499945e+001,9.156025e-004,0.000000e+000,1.066886e-002,0.000000e+000,3,9.386986e-001,1.825000e+000,,,,,,,,,,,,,,,,,,0,5.000000e+000,5.000000e-001,2,1,1.480103e-003,0,1,0,