File: data/A344/A344_GdN_MH_030K_160908.rso.dat
[Header]
TITLE,MPMS RSO Measurement
BYAPP,MPMS Measurement,1.1,Summary
FILEOPENTIME, 1473307860.326000 9/8/2016, 4:11:00 PM

INFO, APPNAME, MPMS MultiVu Application, Revision 1.61,  Build 082

INFO, NAME, A344
INFO, WEIGHT, 10.500
INFO, AREA, 1.000
INFO, LENGTH, 1.000
INFO, SHAPE, 0
INFO, COMMENT, m = 0.0105g
INFO, SEQUENCE FILE: 7T_hysteresis_sweep_hi_res_zero_n4.seq


INFO, BACKGROUND DATA FILE:, None


STARTUPAXIS,X,4,LINEAR,AUTO,0.000000,0.000000
STARTUPAXIS,Y1,5,LINEAR,AUTO,0.000000,0.000000


STARTUPGROUP,Longitudinal
FIELDGROUP,Longitudinal,1,2,3,4,5,6,7,8,9,10,11,19,20,21,22,23,35
FIELDGROUP,Transverse,1,2,3,4,12,13,14,15,16,17,18,24,25,26,27,28,35

PLOT_APPEARANCE,ALL,HORZ_GRID_ON,VERT_GRID_ON,MARKERS_AND_LINES

[Data]
Time,Comment,Field (Oe),Temperature (K),Long Moment (emu),Long Scan Std Dev,Long Offset (cm),Long Offset Std Dev,Long Algorithm,Long Reg Fit,Long Reg Factor,Trans Moment (emu),Trans Scan Std Dev,Trans Offset (cm),Trans Offset Std Dev,Trans Algorithm,Trans Reg Fit,Trans Reg Factor,Long Moment [w/o ABS] (emu),Long Scan Std Dev [w/o ABS],Long Offset [w/o ABS] (cm),Long Offset Std Dev [w/o ABS],Long Reg Fit [w/o ABS],Trans Moment [w/o ABS] (emu),Trans Scan Std Dev [w/o ABS],Trans Offset [w/o ABS] (cm),Trans Offset Std Dev [w/o ABS],Trans Reg Fit [w/o ABS],RSO Position (deg),Amplitude (cm),Frequency,Cycles to Average,Scans per Measurement,Delta Temp (K),Error,EC Comp. Running,Using ABS,
1473307860.325,,7.000000e+004,3.001350e+001,1.158834e-003,0.000000e+000,8.376954e-003,0.000000e+000,3,9.492412e-001,1.825000e+000,,,,,,,,,,,,,,,,,,0,5.000000e+000,5.000000e-001,2,1,0.000000e+000,0,0,0,
1473307884.758,,7.000000e+004,3.000645e+001,1.158768e-003,0.000000e+000,8.452006e-003,0.000000e+000,3,9.493638e-001,1.825000e+000,,,,,,,,,,,,,,,,,,0,5.000000e+000,5.000000e-001,2,1,2.340317e-003,0,0,0,
1473308074.244,,6.000000e+004,3.000117e+001,1.158328e-003,0.000000e+000,7.207365e-003,0.000000e+000,3,9.491668e-001,1.825000e+000,,,,,,,,,,,,,,,,,,0,5.000000e+000,5.000000e-001,2,1,1.180649e-003,0,1,0,
1473308099.233,,6.000000e+004,3.000175e+001,1.157249e-003,0.000000e+000,7.139210e-003,0.000000e+000,3,9.493393e-001,1.825000e+000,,,,,,,,,,,,,,,,,,0,5.000000e+000,5.000000e-001,2,1,2.349854e-003,0,1,0,
1473308272.480,,5.000000e+004,3.000235e+001,1.156050e-003,0.000000e+000,6.621531e-003,0.000000e+000,3,9.500948e-001,1.825000e+000,,,,,,,,,,,,,,,,,,0,5.000000e+000,5.000000e-001,2,1,1.169205e-003,0,1,0,
1473308296.947,,5.000000e+004,3.000469e+001,1.154806e-003,0.000000e+000,7.068277e-003,0.000000e+000,3,9.494367e-001,1.825000e+000,,,,,,,,,,,,,,,,,,0,5.000000e+000,5.000000e-001,2,1,3.520966e-003,0,1,0,
1473308473.723,,4.000000e+004,3.000058e+001,1.149059e-003,0.000000e+000,3.276886e-003,0.000000e+000,3,9.459320e-001,1.825000e+000,,,,,,,,,,,,,,,,,,0,5.000000e+000,5.000000e-001,2,1,0.000000e+000,0,1,0,
1473308498.414,,4.000000e+004,3.000117e+001,1.149812e-003,0.000000e+000,7.785048e-003,0.000000e+000,3,9.477571e-001,1.825000e+000,,,,,,,,,,,,,,,,,,0,5.000000e+000,5.000000e-001,2,1,1.180649e-003,0,1,0,
1473308672.107,,3.000000e+004,3.000117e+001,1.145188e-003,0.000000e+000,4.742327e-003,0.000000e+000,3,9.505751e-001,1.825000e+000,,,,,,,,,,,,,,,,,,0,5.000000e+000,5.000000e-001,2,1,3.519058e-003,0,0,0,
1473308696.537,,3.000000e+004,2.999882e+001,1.145163e-003,0.000000e+000,4.737761e-003,0.000000e+000,3,9.509375e-001,1.825000e+000,,,,,,,,,,,,,,,,,,0,5.000000e+000,5.000000e-001,2,1,3.519058e-003,0,0,0,
1473308869.985,,2.000000e+004,3.000000e+001,1.137185e-003,0.000000e+000,4.553871e-003,0.000000e+000,3,9.504595e-001,1.825000e+000,,,,,,,,,,,,,,,,,,0,5.000000e+000,5.000000e-001,2,1,3.520966e-003,0,0,0,
1473308895.451,,2.000000e+004,3.000058e+001,1.135638e-003,0.000000e+000,4.196632e-003,0.000000e+000,3,9.509332e-001,1.825000e+000,,,,,,,,,,,,,,,,,,0,5.000000e+000,5.000000e-001,2,1,0.000000e+000,0,0,0,
1473309065.410,,1.000000e+004,2.999824e+001,1.115078e-003,0.000000e+000,3.307352e-003,0.000000e+000,3,9.509233e-001,1.825000e+000,,,,,,,,,,,,,,,,,,0,5.000000e+000,5.000000e-001,2,1,0.000000e+000,0,0,0,
1473309091.132,,1.000000e+004,2.999824e+001,1.115309e-003,0.000000e+000,3.597434e-003,0.000000e+000,3,9.509448e-001,1.825000e+000,,,,,,,,,,,,,,,,,,0,5.000000e+000,5.000000e-001,2,1,2.349854e-003,0,0,0,
1473309223.821,,9.000000e+003,3.000234e+001,1.112460e-003,0.000000e+000,3.509995e-003,0.000000e+000,3,9.509500e-001,1.825000e+000,,,,,,,,,,,,,,,,,,0,5.000000e+000,5.000000e-001,2,1,3.520966e-003,0,0,0,
1473309249.750,,9.000000e+003,3.000000e+001,1.112529e-003,0.000000e+000,3.288524e-003,0.000000e+000,3,9.509495e-001,1.825000e+000,,,,,,,,,,,,,,,,,,0,5.000000e+000,5.000000e-001,2,1,1.169205e-003,0,0,0,
1473309387.194,,7.000000e+003,3.000000e+001,1.105258e-003,0.000000e+000,3.577291e-003,0.000000e+000,3,9.509249e-001,1.825000e+000,,,,,,,,,,,,,,,,,,0,5.000000e+000,5.000000e-001,2,1,1.169205e-003,0,1,0,
1473309411.144,,7.000000e+003,3.000058e+001,1.105145e-003,0.000000e+000,3.483089e-003,0.000000e+000,3,9.509549e-001,1.825000e+000,,,,,,,,,,,,,,,,,,0,5.000000e+000,5.000000e-001,2,1,0.000000e+000,0,1,0,
1473309549.385,,5.000000e+003,3.000235e+001,1.095671e-003,0.000000e+000,3.721975e-003,0.000000e+000,3,9.510135e-001,1.825000e+000,,,,,,,,,,,,,,,,,,0,5.000000e+000,5.000000e-001,2,1,1.169205e-003,0,1,0,
1473309572.563,,5.000000e+003,3.000235e+001,1.095520e-003,0.000000e+000,3.663242e-003,0.000000e+000,3,9.510210e-001,1.825000e+000,,,,,,,,,,,,,,,,,,0,5.000000e+000,5.000000e-001,2,1,1.169205e-003,0,1,0,
1473309700.844,,3.000000e+003,2.999941e+001,1.081369e-003,0.000000e+000,3.635365e-003,0.000000e+000,3,9.527009e-001,1.825000e+000,,,,,,,,,,,,,,,,,,0,5.000000e+000,5.000000e-001,2,1,4.699707e-003,0,1,0,
1473309725.799,,3.000000e+003,3.000176e+001,1.080394e-003,0.000000e+000,4.422914e-003,0.000000e+000,3,9.519526e-001,1.825000e+000,,,,,,,,,,,,,,,,,,0,5.000000e+000,5.000000e-001,2,1,0.000000e+000,0,1,0,
1473309858.726,,1.000000e+003,3.000000e+001,1.045406e-003,0.000000e+000,5.601965e-003,0.000000e+000,3,9.600287e-001,1.825000e+000,,,,,,,,,,,,,,,,,,0,5.000000e+000,5.000000e-001,2,1,1.169205e-003,0,1,0,
1473309882.814,,1.000000e+003,3.000234e+001,1.045048e-003,0.000000e+000,5.339120e-003,0.000000e+000,3,9.598613e-001,1.825000e+000,,,,,,,,,,,,,,,,,,0,5.000000e+000,5.000000e-001,2,1,3.520966e-003,0,1,0,
1473310022.258,,7.000000e+002,3.000059e+001,1.032146e-003,0.000000e+000,5.729766e-003,0.000000e+000,3,9.643475e-001,1.825000e+000,,,,,,,,,,,,,,,,,,0,5.000000e+000,5.000000e-001,2,1,2.349854e-003,0,0,0,
1473310047.438,,7.000000e+002,3.000000e+001,1.033338e-003,0.000000e+000,5.600040e-003,0.000000e+000,3,9.638216e-001,1.825000e+000,,,,,,,,,,,,,,,,,,0,5.000000e+000,5.000000e-001,2,1,1.169205e-003,0,0,0,
1473310182.126,,6.000000e+002,2.999883e+001,1.025246e-003,0.000000e+000,6.529874e-003,0.000000e+000,3,9.641764e-001,1.825000e+000,,,,,,,,,,,,,,,,,,0,5.000000e+000,5.000000e-001,2,1,1.171112e-003,0,0,0,
1473310206.738,,6.000000e+002,3.000059e+001,1.026189e-003,0.000000e+000,6.543375e-003,0.000000e+000,3,9.650234e-001,1.825000e+000,,,,,,,,,,,,,,,,,,0,5.000000e+000,5.000000e-001,2,1,2.349854e-003,0,0,0,
1473310339.050,,5.000000e+002,2.999941e+001,1.021751e-003,0.000000e+000,7.003798e-003,0.000000e+000,3,9.660394e-001,1.825000e+000,,,,,,,,,,,,,,,,,,0,5.000000e+000,5.000000e-001,2,1,2.340317e-003,0,0,0,
1473310364.729,,5.000000e+002,3.000059e+001,1.019451e-003,0.000000e+000,6.248685e-003,0.000000e+000,3,9.677956e-001,1.825000e+000,,,,,,,,,,,,,,,,,,0,5.000000e+000,5.000000e-001,2,1,2.349854e-003,0,0,0,
1473310497.353,,4.000000e+002,2.999765e+001,1.008463e-003,0.000000e+000,7.197252e-003,0.000000e+000,3,9.700141e-001,1.825000e+000,,,,,,,,,,,,,,,,,,0,5.000000e+000,5.000000e-001,2,1,1.178741e-003,0,0,0,
1473310521.639,,4.000000e+002,3.000000e+001,1.008639e-003,0.000000e+000,6.838917e-003,0.000000e+000,3,9.697580e-001,1.825000e+000,,,,,,,,,,,,,,,,,,0,5.000000e+000,5.000000e-001,2,1,1.169205e-003,0,0,0,
1473310648.899,,3.000000e+002,2.999824e+001,9.935857e-004,0.000000e+000,7.369862e-003,0.000000e+000,3,9.728176e-001,1.825000e+000,,,,,,,,,,,,,,,,,,0,5.000000e+000,5.000000e-001,2,1,0.000000e+000,0,0,0,
1473310674.348,,3.000000e+002,2.999882e+001,9.932596e-004,0.000000e+000,7.335924e-003,0.000000e+000,3,9.723641e-001,1.825000e+000,,,,,,,,,,,,,,,,,,0,5.000000e+000,5.000000e-001,2,1,3.519058e-003,0,0,0,
1473310808.069,,2.000000e+002,3.000000e+001,9.694833e-004,0.000000e+000,7.822437e-003,0.000000e+000,3,9.754542e-001,1.825000e+000,,,,,,,,,,,,,,,,,,0,5.000000e+000,5.000000e-001,2,1,1.169205e-003,0,0,0,
1473310832.450,,2.000000e+002,2.999941e+001,9.692796e-004,0.000000e+000,7.714125e-003,0.000000e+000,3,9.759065e-001,1.825000e+000,,,,,,,,,,,,,,,,,,0,5.000000e+000,5.000000e-001,2,1,2.340317e-003,0,0,0,
1473310962.798,,1.800000e+002,3.000000e+001,9.629476e-004,0.000000e+000,7.913738e-003,0.000000e+000,3,9.762552e-001,1.825000e+000,,,,,,,,,,,,,,,,,,0,5.000000e+000,5.000000e-001,2,1,1.169205e-003,0,1,0,
1473310986.982,,1.800000e+002,2.999941e+001,9.623339e-004,0.000000e+000,7.619995e-003,0.000000e+000,3,9.765841e-001,1.825000e+000,,,,,,,,,,,,,,,,,,0,5.000000e+000,5.000000e-001,2,1,4.699707e-003,0,1,0,
1473311105.475,,1.600000e+002,3.000175e+001,9.550871e-004,0.000000e+000,8.133605e-003,0.000000e+000,3,9.769388e-001,1.825000e+000,,,,,,,,,,,,,,,,,,0,5.000000e+000,5.000000e-001,2,1,2.349854e-003,0,1,0,
1473311128.702,,1.600000e+002,3.000117e+001,9.550963e-004,0.000000e+000,7.589389e-003,0.000000e+000,3,9.773827e-001,1.825000e+000,,,,,,,,,,,,,,,,,,0,5.000000e+000,5.000000e-001,2,1,1.180649e-003,0,1,0,
1473311248.165,,1.400000e+002,3.000293e+001,9.471390e-004,0.000000e+000,7.840931e-003,0.000000e+000,3,9.780496e-001,1.825000e+000,,,,,,,,,,,,,,,,,,0,5.000000e+000,5.000000e-001,2,1,2.340317e-003,0,1,0,
1473311272.899,,1.400000e+002,3.000293e+001,9.469904e-004,0.000000e+000,7.825634e-003,0.000000e+000,3,9.776763e-001,1.825000e+000,,,,,,,,,,,,,,,,,,0,5.000000e+000,5.000000e-001,2,1,0.000000e+000,0,1,0,
1473311391.337,,1.200000e+002,3.000117e+001,9.374331e-004,0.000000e+000,7.750554e-003,0.000000e+000,3,9.791140e-001,1.825000e+000,,,,,,,,,,,,,,,,,,0,5.000000e+000,5.000000e-001,2,1,1.180649e-003,0,1,0,
1473311414.551,,1.200000e+002,3.000176e+001,9.371180e-004,0.000000e+000,8.151726e-003,0.000000e+000,3,9.787182e-001,1.825000e+000,,,,,,,,,,,,,,,,,,0,5.000000e+000,5.000000e-001,2,1,0.000000e+000,0,1,0,
1473311542.753,,1.000000e+002,2.999941e+001,9.262532e-004,0.000000e+000,7.871646e-003,0.000000e+000,3,9.799297e-001,1.825000e+000,,,,,,,,,,,,,,,,,,0,5.000000e+000,5.000000e-001,2,1,2.340317e-003,0,1,0,
1473311567.224,,1.000000e+002,3.000059e+001,9.251281e-004,0.000000e+000,8.147663e-003,0.000000e+000,3,9.793525e-001,1.825000e+000,,,,,,,,,,,,,,,,,,0,5.000000e+000,5.000000e-001,2,1,2.349854e-003,0,0,0,
1473311684.973,,8.000000e+001,3.000059e+001,9.125283e-004,0.000000e+000,8.049626e-003,0.000000e+000,3,9.804113e-001,1.825000e+000,,,,,,,,,,,,,,,,,,0,5.000000e+000,5.000000e-001,2,1,2.349854e-003,0,0,0,
1473311709.403,,8.000000e+001,3.000000e+001,9.121426e-004,0.000000e+000,8.554283e-003,0.000000e+000,3,9.798896e-001,1.825000e+000,,,,,,,,,,,,,,,,,,0,5.000000e+000,5.000000e-001,2,1,1.169205e-003,0,0,0,
1473311834.885,,6.000000e+001,2.999883e+001,8.960895e-004,0.000000e+000,8.413983e-003,0.000000e+000,3,9.811093e-001,1.825000e+000,,,,,,,,,,,,,,,,,,0,5.000000e+000,5.000000e-001,2,1,1.171112e-003,0,0,0,
1473311859.563,,6.000000e+001,2.999941e+001,8.961124e-004,0.000000e+000,8.394458e-003,0.000000e+000,3,9.812895e-001,1.825000e+000,,,,,,,,,,,,,,,,,,0,5.000000e+000,5.000000e-001,2,1,0.000000e+000,0,0,0,
1473311985.940,,4.000000e+001,2.999941e+001,8.768932e-004,0.000000e+000,7.853787e-003,0.000000e+000,3,9.818855e-001,1.825000e+000,,,,,,,,,,,,,,,,,,0,5.000000e+000,5.000000e-001,2,1,0.000000e+000,0,0,0,
1473312013.476,,4.000000e+001,3.000000e+001,8.761316e-004,0.000000e+000,8.742617e-003,0.000000e+000,3,9.820938e-001,1.825000e+000,,,,,,,,,,,,,,,,,,0,5.000000e+000,5.000000e-001,2,1,1.169205e-003,0,0,0,
1473312135.762,,2.000000e+001,2.999765e+001,8.501654e-004,0.000000e+000,8.709287e-003,0.000000e+000,3,9.826266e-001,1.825000e+000,,,,,,,,,,,,,,,,,,0,5.000000e+000,5.000000e-001,2,1,1.178741e-003,0,0,0,
1473312161.190,,2.000000e+001,2.999883e+001,8.507550e-004,0.000000e+000,8.564263e-003,0.000000e+000,3,9.826134e-001,1.825000e+000,,,,,,,,,,,,,,,,,,0,5.000000e+000,5.000000e-001,2,1,1.171112e-003,0,0,0,
1473312285.668,,0.000000e+000,3.000000e+001,8.158477e-004,0.000000e+000,9.136375e-003,0.000000e+000,3,9.830996e-001,1.825000e+000,,,,,,,,,,,,,,,,,,0,5.000000e+000,5.000000e-001,2,1,1.169205e-003,0,0,0,
1473312310.348,,0.000000e+000,2.999941e+001,8.160795e-004,0.000000e+000,8.941301e-003,0.000000e+000,3,9.833989e-001,1.825000e+000,,,,,,,,,,,,,,,,,,0,5.000000e+000,5.000000e-001,2,1,0.000000e+000,0,0,0,
1473312435.041,,-2.000000e+001,3.000058e+001,7.616721e-004,0.000000e+000,9.640392e-003,0.000000e+000,3,9.833506e-001,1.825000e+000,,,,,,,,,,,,,,,,,,0,5.000000e+000,5.000000e-001,2,1,7.040024e-003,0,1,0,
1473312460.752,,-2.000000e+001,3.000059e+001,7.603638e-004,0.000000e+000,8.636678e-003,0.000000e+000,3,9.845073e-001,1.825000e+000,,,,,,,,,,,,,,,,,,0,5.000000e+000,5.000000e-001,2,1,2.349854e-003,0,1,0,
1473312579.940,,-4.000000e+001,2.999765e+001,6.449294e-004,0.000000e+000,8.686794e-003,0.000000e+000,3,9.855000e-001,1.825000e+000,,,,,,,,,,,,,,,,,,0,5.000000e+000,5.000000e-001,2,1,5.859375e-003,0,1,0,
1473312604.582,,-4.000000e+001,3.000117e+001,6.416690e-004,0.000000e+000,9.404397e-003,0.000000e+000,3,9.843478e-001,1.825000e+000,,,,,,,,,,,,,,,,,,0,5.000000e+000,5.000000e-001,2,1,1.180649e-003,0,1,0,
1473312731.883,,-6.000000e+001,3.000235e+001,-4.511898e-004,0.000000e+000,6.184296e-003,0.000000e+000,3,9.778832e-001,1.825000e+000,,,,,,,,,,,,,,,,,,0,5.000000e+000,5.000000e-001,2,1,1.169205e-003,0,1,0,
1473312757.312,,-6.000000e+001,3.000235e+001,-4.630726e-004,0.000000e+000,6.978351e-003,0.000000e+000,3,9.779592e-001,1.825000e+000,,,,,,,,,,,,,,,,,,0,5.000000e+000,5.000000e-001,2,1,1.169205e-003,0,1,0,
1473312878.750,,-8.000000e+001,3.000117e+001,-6.851245e-004,0.000000e+000,7.514519e-003,0.000000e+000,3,9.793488e-001,1.825000e+000,,,,,,,,,,,,,,,,,,0,5.000000e+000,5.000000e-001,2,1,1.180649e-003,0,1,0,
1473312902.897,,-8.000000e+001,3.000059e+001,-6.893945e-004,0.000000e+000,7.724999e-003,0.000000e+000,3,9.791072e-001,1.825000e+000,,,,,,,,,,,,,,,,,,0,5.000000e+000,5.000000e-001,2,1,2.349854e-003,0,1,0,
1473313026.016,,-1.000000e+002,3.001253e+001,-7.747456e-004,0.000000e+000,7.988906e-003,0.000000e+000,3,9.784033e-001,1.825000e+000,,,,,,,,,,,,,,,,,,0,5.000000e+000,5.000000e-001,2,1,2.390099e-002,0,1,0,
1473313049.194,,-1.000000e+002,3.000000e+001,-7.791457e-004,0.000000e+000,7.643840e-003,0.000000e+000,3,9.788194e-001,1.825000e+000,,,,,,,,,,,,,,,,,,0,5.000000e+000,5.000000e-001,2,1,5.868912e-003,0,0,0,
1473313168.686,,-1.200000e+002,2.999765e+001,-8.316205e-004,0.000000e+000,7.634379e-003,0.000000e+000,3,9.777820e-001,1.825000e+000,,,,,,,,,,,,,,,,,,0,5.000000e+000,5.000000e-001,2,1,1.178741e-003,0,0,0,
1473313191.864,,-1.200000e+002,2.999941e+001,-8.337548e-004,0.000000e+000,7.236364e-003,0.000000e+000,3,9.784222e-001,1.825000e+000,,,,,,,,,,,,,,,,,,0,5.000000e+000,5.000000e-001,2,1,0.000000e+000,0,0,0,
1473313313.556,,-1.400000e+002,2.999883e+001,-8.687348e-004,0.000000e+000,7.876109e-003,0.000000e+000,3,9.773707e-001,1.825000e+000,,,,,,,,,,,,,,,,,,0,5.000000e+000,5.000000e-001,2,1,1.171112e-003,0,0,0,
1473313340.998,,-1.400000e+002,3.000293e+001,-8.703792e-004,0.000000e+000,7.908638e-003,0.000000e+000,3,9.774949e-001,1.825000e+000,,,,,,,,,,,,,,,,,,0,5.000000e+000,5.000000e-001,2,1,2.340317e-003,0,0,0,
1473313471.187,,-1.600000e+002,3.000000e+001,-8.956661e-004,0.000000e+000,7.956743e-003,0.000000e+000,3,9.766109e-001,1.825000e+000,,,,,,,,,,,,,,,,,,0,5.000000e+000,5.000000e-001,2,1,1.169205e-003,0,0,0,
1473313494.922,,-1.600000e+002,3.000000e+001,-8.971259e-004,0.000000e+000,7.862540e-003,0.000000e+000,3,9.767115e-001,1.825000e+000,,,,,,,,,,,,,,,,,,0,5.000000e+000,5.000000e-001,2,1,1.169205e-003,0,0,0,
1473313622.866,,-1.800000e+002,3.000117e+001,-9.158264e-004,0.000000e+000,7.660473e-003,0.000000e+000,3,9.763251e-001,1.825000e+000,,,,,,,,,,,,,,,,,,0,5.000000e+000,5.000000e-001,2,1,3.519058e-003,0,0,0,
1473313646.839,,-1.800000e+002,2.999941e+001,-9.163996e-004,0.000000e+000,7.675354e-003,0.000000e+000,3,9.761767e-001,1.825000e+000,,,,,,,,,,,,,,,,,,0,5.000000e+000,5.000000e-001,2,1,0.000000e+000,0,0,0,
1473313766.344,,-2.000000e+002,3.000000e+001,-9.310344e-004,0.000000e+000,7.302045e-003,0.000000e+000,3,9.759794e-001,1.825000e+000,,,,,,,,,,,,,,,,,,0,5.000000e+000,5.000000e-001,2,1,1.169205e-003,0,0,0,
1473313794.069,,-2.000000e+002,3.000000e+001,-9.314424e-004,0.000000e+000,7.734107e-003,0.000000e+000,3,9.757124e-001,1.825000e+000,,,,,,,,,,,,,,,,,,0,5.000000e+000,5.000000e-001,2,1,1.169205e-003,0,0,0,
1473313922.512,,-3.000000e+002,3.000000e+001,-9.759757e-004,0.000000e+000,6.960142e-003,0.000000e+000,3,9.731099e-001,1.825000e+000,,,,,,,,,,,,,,,,,,0,5.000000e+000,5.000000e-001,2,1,1.169205e-003,0,1,0,
1473313946.488,,-3.000000e+002,2.999941e+001,-9.752667e-004,0.000000e+000,7.778060e-003,0.000000e+000,3,9.723997e-001,1.825000e+000,,,,,,,,,,,,,,,,,,0,5.000000e+000,5.000000e-001,2,1,2.340317e-003,0,1,0,
1473314077.716,,-4.000000e+002,3.000528e+001,-9.982499e-004,0.000000e+000,7.019368e-003,0.000000e+000,3,9.697552e-001,1.825000e+000,,,,,,,,,,,,,,,,,,0,5.000000e+000,5.000000e-001,2,1,2.349854e-003,0,1,0,
1473314101.965,,-4.000000e+002,3.000293e+001,-9.987323e-004,0.000000e+000,7.104510e-003,0.000000e+000,3,9.697619e-001,1.825000e+000,,,,,,,,,,,,,,,,,,0,5.000000e+000,5.000000e-001,2,1,0.000000e+000,0,1,0,
1473314234.475,,-5.000000e+002,3.000000e+001,-1.013180e-003,0.000000e+000,6.277295e-003,0.000000e+000,3,9.683346e-001,1.825000e+000,,,,,,,,,,,,,,,,,,0,5.000000e+000,5.000000e-001,2,1,1.169205e-003,0,1,0,
1473314258.419,,-5.000000e+002,3.000117e+001,-1.012398e-003,0.000000e+000,6.610275e-003,0.000000e+000,3,9.677154e-001,1.825000e+000,,,,,,,,,,,,,,,,,,0,5.000000e+000,5.000000e-001,2,1,1.056099e-002,0,1,0,
1473314384.164,,-6.000000e+002,3.000058e+001,-1.022141e-003,0.000000e+000,6.924330e-003,0.000000e+000,3,9.650308e-001,1.825000e+000,,,,,,,,,,,,,,,,,,0,5.000000e+000,5.000000e-001,2,1,0.000000e+000,0,1,0,
1473314408.343,,-6.000000e+002,3.000058e+001,-1.021543e-003,0.000000e+000,6.417004e-003,0.000000e+000,3,9.654362e-001,1.825000e+000,,,,,,,,,,,,,,,,,,0,5.000000e+000,5.000000e-001,2,1,0.000000e+000,0,1,0,
1473314542.286,,-7.000000e+002,2.999824e+001,-1.028703e-003,0.000000e+000,6.738522e-003,0.000000e+000,3,9.633281e-001,1.825000e+000,,,,,,,,,,,,,,,,,,0,5.000000e+000,5.000000e-001,2,1,0.000000e+000,0,0,0,
1473314565.465,,-7.000000e+002,3.000117e+001,-1.029751e-003,0.000000e+000,5.857504e-003,0.000000e+000,3,9.627661e-001,1.825000e+000,,,,,,,,,,,,,,,,,,0,5.000000e+000,5.000000e-001,2,1,1.180649e-003,0,0,0,
1473314691.447,,-1.000000e+003,3.000117e+001,-1.041190e-003,0.000000e+000,5.504045e-003,0.000000e+000,3,9.584603e-001,1.825000e+000,,,,,,,,,,,,,,,,,,0,5.000000e+000,5.000000e-001,2,1,1.180649e-003,0,0,0,
1473314714.891,,-1.000000e+003,3.000117e+001,-1.043495e-003,0.000000e+000,5.938763e-003,0.000000e+000,3,9.598357e-001,1.825000e+000,,,,,,,,,,,,,,,,,,0,5.000000e+000,5.000000e-001,2,1,1.180649e-003,0,0,0,
1473314852.127,,-3.000000e+003,2.999941e+001,-1.081040e-003,0.000000e+000,4.519966e-003,0.000000e+000,3,9.519845e-001,1.825000e+000,,,,,,,,,,,,,,,,,,0,5.000000e+000,5.000000e-001,2,1,4.699707e-003,0,0,0,
1473314878.306,,-3.000000e+003,3.000000e+001,-1.080586e-003,0.000000e+000,4.473916e-003,0.000000e+000,3,9.520246e-001,1.825000e+000,,,,,,,,,,,,,,,,,,0,5.000000e+000,5.000000e-001,2,1,1.169205e-003,0,0,0,
1473315017.038,,-5.000000e+003,2.999648e+001,-1.095361e-003,0.000000e+000,4.305363e-003,0.000000e+000,3,9.507803e-001,1.825000e+000,,,,,,,,,,,,,,,,,,0,5.000000e+000,5.000000e-001,2,1,3.519058e-003,0,0,0,
1473315042.012,,-5.000000e+003,2.999706e+001,-1.095329e-003,0.000000e+000,4.306066e-003,0.000000e+000,3,9.510229e-001,1.825000e+000,,,,,,,,,,,,,,,,,,0,5.000000e+000,5.000000e-001,2,1,0.000000e+000,0,0,0,
1473315178.705,,-7.000000e+003,3.000058e+001,-1.105165e-003,0.000000e+000,4.360744e-003,0.000000e+000,3,9.507055e-001,1.825000e+000,,,,,,,,,,,,,,,,,,0,5.000000e+000,5.000000e-001,2,1,0.000000e+000,0,0,0,
1473315204.417,,-7.000000e+003,3.000000e+001,-1.105170e-003,0.000000e+000,4.430126e-003,0.000000e+000,3,9.508536e-001,1.825000e+000,,,,,,,,,,,,,,,,,,0,5.000000e+000,5.000000e-001,2,1,1.169205e-003,0,0,0,
1473315343.857,,-9.000000e+003,2.999941e+001,-1.112222e-003,0.000000e+000,4.499950e-003,0.000000e+000,3,9.505981e-001,1.825000e+000,,,,,,,,,,,,,,,,,,0,5.000000e+000,5.000000e-001,2,1,0.000000e+000,0,1,0,
1473315368.045,,-9.000000e+003,3.000058e+001,-1.112356e-003,0.000000e+000,4.472375e-003,0.000000e+000,3,9.508441e-001,1.825000e+000,,,,,,,,,,,,,,,,,,0,5.000000e+000,5.000000e-001,2,1,0.000000e+000,0,1,0,
1473315502.776,,-1.000000e+004,3.000469e+001,-1.115532e-003,0.000000e+000,4.468543e-003,0.000000e+000,3,9.507702e-001,1.825000e+000,,,,,,,,,,,,,,,,,,0,5.000000e+000,5.000000e-001,2,1,1.178741e-003,0,1,0,
1473315526.063,,-1.000000e+004,3.000293e+001,-1.115264e-003,0.000000e+000,4.554120e-003,0.000000e+000,3,9.507960e-001,1.825000e+000,,,,,,,,,,,,,,,,,,0,5.000000e+000,5.000000e-001,2,1,0.000000e+000,0,1,0,
1473315700.059,,-2.000000e+004,3.000000e+001,-1.132763e-003,0.000000e+000,5.259981e-003,0.000000e+000,3,9.501448e-001,1.825000e+000,,,,,,,,,,,,,,,,,,0,5.000000e+000,5.000000e-001,2,1,1.169205e-003,0,1,0,
1473315724.040,,-2.000000e+004,2.999941e+001,-1.136255e-003,0.000000e+000,3.672173e-003,0.000000e+000,3,9.518093e-001,1.825000e+000,,,,,,,,,,,,,,,,,,0,5.000000e+000,5.000000e-001,2,1,0.000000e+000,0,1,0,
1473315905.326,,-3.000000e+004,3.000175e+001,-1.143065e-003,0.000000e+000,6.159446e-003,0.000000e+000,3,9.522629e-001,1.825000e+000,,,,,,,,,,,,,,,,,,0,5.000000e+000,5.000000e-001,2,1,4.690170e-003,0,1,0,
1473315929.809,,-3.000000e+004,2.999941e+001,-1.147625e-003,0.000000e+000,6.160128e-003,0.000000e+000,3,9.494714e-001,1.825000e+000,,,,,,,,,,,,,,,,,,0,5.000000e+000,5.000000e-001,2,1,0.000000e+000,0,0,0,
1473316106.802,,-4.000000e+004,3.000117e+001,-1.152241e-003,0.000000e+000,6.611432e-003,0.000000e+000,3,9.501819e-001,1.825000e+000,,,,,,,,,,,,,,,,,,0,5.000000e+000,5.000000e-001,2,1,3.519058e-003,0,0,0,
1473316130.327,,-4.000000e+004,3.000175e+001,-1.151927e-003,0.000000e+000,6.606315e-003,0.000000e+000,3,9.506115e-001,1.825000e+000,,,,,,,,,,,,,,,,,,0,5.000000e+000,5.000000e-001,2,1,2.349854e-003,0,0,0,
1473316316.776,,-5.000000e+004,3.000175e+001,-1.153243e-003,0.000000e+000,6.665226e-003,0.000000e+000,3,9.491411e-001,1.825000e+000,,,,,,,,,,,,,,,,,,0,5.000000e+000,5.000000e-001,2,1,4.690170e-003,0,0,0,
1473316341.954,,-5.000000e+004,3.000058e+001,-1.156042e-003,0.000000e+000,7.141604e-003,0.000000e+000,3,9.501888e-001,1.825000e+000,,,,,,,,,,,,,,,,,,0,5.000000e+000,5.000000e-001,2,1,0.000000e+000,0,0,0,
1473316519.398,,-6.000000e+004,3.000058e+001,-1.158175e-003,0.000000e+000,7.551856e-003,0.000000e+000,3,9.496289e-001,1.825000e+000,,,,,,,,,,,,,,,,,,0,5.000000e+000,5.000000e-001,2,1,4.690170e-003,0,0,0,
1473316545.633,,-6.000000e+004,2.999883e+001,-1.157945e-003,0.000000e+000,7.617885e-003,0.000000e+000,3,9.497024e-001,1.825000e+000,,,,,,,,,,,,,,,,,,0,5.000000e+000,5.000000e-001,2,1,1.171112e-003,0,0,0,
1473316725.080,,-7.000000e+004,2.999941e+001,-1.159133e-003,0.000000e+000,8.101691e-003,0.000000e+000,3,9.491882e-001,1.825000e+000,,,,,,,,,,,,,,,,,,0,5.000000e+000,5.000000e-001,2,1,4.699707e-003,0,1,0,
1473316750.081,,-7.000000e+004,2.999883e+001,-1.159607e-003,0.000000e+000,7.885671e-003,0.000000e+000,3,9.488883e-001,1.825000e+000,,,,,,,,,,,,,,,,,,0,5.000000e+000,5.000000e-001,2,1,5.870819e-003,0,1,0,
1473316931.090,,-6.000000e+004,3.000293e+001,-1.158598e-003,0.000000e+000,6.749792e-003,0.000000e+000,3,9.487039e-001,1.825000e+000,,,,,,,,,,,,,,,,,,0,5.000000e+000,5.000000e-001,2,1,0.000000e+000,0,1,0,
1473316954.028,,-6.000000e+004,3.000352e+001,-1.158816e-003,0.000000e+000,6.773554e-003,0.000000e+000,3,9.491580e-001,1.825000e+000,,,,,,,,,,,,,,,,,,0,5.000000e+000,5.000000e-001,2,1,3.519058e-003,0,1,0,
1473317137.473,,-5.000000e+004,3.000000e+001,-1.158062e-003,0.000000e+000,4.966212e-003,0.000000e+000,3,9.479155e-001,1.825000e+000,,,,,,,,,,,,,,,,,,0,5.000000e+000,5.000000e-001,2,1,1.169205e-003,0,1,0,
1473317161.401,,-5.000000e+004,3.000059e+001,-1.157789e-003,0.000000e+000,3.908552e-003,0.000000e+000,3,9.491798e-001,1.825000e+000,,,,,,,,,,,,,,,,,,0,5.000000e+000,5.000000e-001,2,1,2.349854e-003,0,1,0,
1473317339.348,,-4.000000e+004,3.000117e+001,-1.149324e-003,0.000000e+000,5.726709e-003,0.000000e+000,3,9.477551e-001,1.825000e+000,,,,,,,,,,,,,,,,,,0,5.000000e+000,5.000000e-001,2,1,1.180649e-003,0,0,0,
1473317364.588,,-4.000000e+004,3.000235e+001,-1.153231e-003,0.000000e+000,3.728047e-003,0.000000e+000,3,9.493434e-001,1.825000e+000,,,,,,,,,,,,,,,,,,0,5.000000e+000,5.000000e-001,2,1,1.169205e-003,0,0,0,
1473317539.096,,-3.000000e+004,2.999941e+001,-1.145291e-003,0.000000e+000,5.017278e-003,0.000000e+000,3,9.507271e-001,1.825000e+000,,,,,,,,,,,,,,,,,,0,5.000000e+000,5.000000e-001,2,1,0.000000e+000,0,0,0,
1473317564.774,,-3.000000e+004,3.000176e+001,-1.145083e-003,0.000000e+000,4.735330e-003,0.000000e+000,3,9.507033e-001,1.825000e+000,,,,,,,,,,,,,,,,,,0,5.000000e+000,5.000000e-001,2,1,0.000000e+000,0,0,0,
1473317730.749,,-2.000000e+004,3.000234e+001,-1.130559e-003,0.000000e+000,3.097909e-003,0.000000e+000,3,9.494758e-001,1.825000e+000,,,,,,,,,,,,,,,,,,0,5.000000e+000,5.000000e-001,2,1,3.520966e-003,0,0,0,
1473317767.235,,-2.000000e+004,2.999824e+001,-1.134591e-003,0.000000e+000,4.118701e-003,0.000000e+000,3,9.508942e-001,1.825000e+000,,,,,,,,,,,,,,,,,,0,5.000000e+000,5.000000e-001,2,1,2.349854e-003,0,0,0,
1473317939.432,,-1.000000e+004,3.000059e+001,-1.115223e-003,0.000000e+000,3.622897e-003,0.000000e+000,3,9.508117e-001,1.825000e+000,,,,,,,,,,,,,,,,,,0,5.000000e+000,5.000000e-001,2,1,2.349854e-003,0,0,0,
1473317964.417,,-1.000000e+004,2.999941e+001,-1.115464e-003,0.000000e+000,3.706402e-003,0.000000e+000,3,9.506843e-001,1.825000e+000,,,,,,,,,,,,,,,,,,0,5.000000e+000,5.000000e-001,2,1,2.340317e-003,0,0,0,
1473318101.151,,-9.000000e+003,2.999648e+001,-1.112046e-003,0.000000e+000,3.811966e-003,0.000000e+000,3,9.507415e-001,1.825000e+000,,,,,,,,,,,,,,,,,,0,5.000000e+000,5.000000e-001,2,1,3.519058e-003,0,0,0,
1473318126.759,,-9.000000e+003,2.999883e+001,-1.112594e-003,0.000000e+000,3.769518e-003,0.000000e+000,3,9.508626e-001,1.825000e+000,,,,,,,,,,,,,,,,,,0,5.000000e+000,5.000000e-001,2,1,1.171112e-003,0,0,0,
1473318265.855,,-7.000000e+003,3.000587e+001,-1.105445e-003,0.000000e+000,3.954972e-003,0.000000e+000,3,9.507581e-001,1.825000e+000,,,,,,,,,,,,,,,,,,0,5.000000e+000,5.000000e-001,2,1,5.870819e-003,0,1,0,
1473318291.033,,-7.000000e+003,3.000117e+001,-1.105097e-003,0.000000e+000,3.785851e-003,0.000000e+000,3,9.508260e-001,1.825000e+000,,,,,,,,,,,,,,,,,,0,5.000000e+000,5.000000e-001,2,1,1.180649e-003,0,1,0,
1473318426.733,,-5.000000e+003,3.000117e+001,-1.095370e-003,0.000000e+000,4.013536e-003,0.000000e+000,3,9.510058e-001,1.825000e+000,,,,,,,,,,,,,,,,,,0,5.000000e+000,5.000000e-001,2,1,3.519058e-003,0,1,0,
1473318450.954,,-5.000000e+003,3.000293e+001,-1.095333e-003,0.000000e+000,3.921030e-003,0.000000e+000,3,9.509610e-001,1.825000e+000,,,,,,,,,,,,,,,,,,0,5.000000e+000,5.000000e-001,2,1,2.340317e-003,0,1,0,
1473318582.216,,-3.000000e+003,2.999882e+001,-1.080091e-003,0.000000e+000,4.497592e-003,0.000000e+000,3,9.522455e-001,1.825000e+000,,,,,,,,,,,,,,,,,,0,5.000000e+000,5.000000e-001,2,1,3.519058e-003,0,1,0,
1473318606.839,,-3.000000e+003,3.000000e+001,-1.080709e-003,0.000000e+000,4.154867e-003,0.000000e+000,3,9.523195e-001,1.825000e+000,,,,,,,,,,,,,,,,,,0,5.000000e+000,5.000000e-001,2,1,1.169205e-003,0,1,0,
1473318742.140,,-1.000000e+003,3.000000e+001,-1.045343e-003,0.000000e+000,5.315374e-003,0.000000e+000,3,9.605161e-001,1.825000e+000,,,,,,,,,,,,,,,,,,0,5.000000e+000,5.000000e-001,2,1,1.169205e-003,0,1,0,
1473318765.569,,-1.000000e+003,3.000175e+001,-1.045386e-003,0.000000e+000,5.625678e-003,0.000000e+000,3,9.598284e-001,1.825000e+000,,,,,,,,,,,,,,,,,,0,5.000000e+000,5.000000e-001,2,1,2.349854e-003,0,1,0,
1473318897.094,,-7.000000e+002,3.000058e+001,-1.032797e-003,0.000000e+000,5.992373e-003,0.000000e+000,3,9.635840e-001,1.825000e+000,,,,,,,,,,,,,,,,,,0,5.000000e+000,5.000000e-001,2,1,0.000000e+000,0,0,0,
1473318922.022,,-7.000000e+002,2.999941e+001,-1.031998e-003,0.000000e+000,6.053876e-003,0.000000e+000,3,9.632621e-001,1.825000e+000,,,,,,,,,,,,,,,,,,0,5.000000e+000,5.000000e-001,2,1,0.000000e+000,0,0,0,
1473319057.662,,-6.000000e+002,3.000000e+001,-1.025019e-003,0.000000e+000,6.348744e-003,0.000000e+000,3,9.647907e-001,1.825000e+000,,,,,,,,,,,,,,,,,,0,5.000000e+000,5.000000e-001,2,1,1.169205e-003,0,0,0,
1473319081.711,,-6.000000e+002,3.000000e+001,-1.026663e-003,0.000000e+000,6.661878e-003,0.000000e+000,3,9.650304e-001,1.825000e+000,,,,,,,,,,,,,,,,,,0,5.000000e+000,5.000000e-001,2,1,1.169205e-003,0,0,0,
1473319212.150,,-5.000000e+002,3.000117e+001,-1.018346e-003,0.000000e+000,7.014813e-003,0.000000e+000,3,9.671192e-001,1.825000e+000,,,,,,,,,,,,,,,,,,0,5.000000e+000,5.000000e-001,2,1,1.180649e-003,0,0,0,
1473319237.859,,-5.000000e+002,3.000000e+001,-1.018698e-003,0.000000e+000,6.673330e-003,0.000000e+000,3,9.678074e-001,1.825000e+000,,,,,,,,,,,,,,,,,,0,5.000000e+000,5.000000e-001,2,1,1.169205e-003,0,0,0,
1473319371.802,,-4.000000e+002,2.999589e+001,-1.006680e-003,0.000000e+000,6.722234e-003,0.000000e+000,3,9.706478e-001,1.825000e+000,,,,,,,,,,,,,,,,,,0,5.000000e+000,5.000000e-001,2,1,2.340317e-003,0,0,0,
1473319398.981,,-4.000000e+002,2.999941e+001,-1.008152e-003,0.000000e+000,7.185831e-003,0.000000e+000,3,9.699483e-001,1.825000e+000,,,,,,,,,,,,,,,,,,0,5.000000e+000,5.000000e-001,2,1,0.000000e+000,0,0,0,
1473319522.419,,-3.000000e+002,3.000176e+001,-9.928980e-004,0.000000e+000,7.794994e-003,0.000000e+000,3,9.722505e-001,1.825000e+000,,,,,,,,,,,,,,,,,,0,5.000000e+000,5.000000e-001,2,1,0.000000e+000,0,0,0,
1473319547.366,,-3.000000e+002,2.999941e+001,-9.928643e-004,0.000000e+000,7.695003e-003,0.000000e+000,3,9.725904e-001,1.825000e+000,,,,,,,,,,,,,,,,,,0,5.000000e+000,5.000000e-001,2,1,2.340317e-003,0,0,0,
1473319675.558,,-2.000000e+002,3.000117e+001,-9.686821e-004,0.000000e+000,8.149902e-003,0.000000e+000,3,9.758145e-001,1.825000e+000,,,,,,,,,,,,,,,,,,0,5.000000e+000,5.000000e-001,2,1,1.180649e-003,0,1,0,
1473319699.737,,-2.000000e+002,2.999941e+001,-9.687349e-004,0.000000e+000,8.068668e-003,0.000000e+000,3,9.760490e-001,1.825000e+000,,,,,,,,,,,,,,,,,,0,5.000000e+000,5.000000e-001,2,1,4.699707e-003,0,1,0,
1473319821.448,,-1.800000e+002,2.999883e+001,-9.616960e-004,0.000000e+000,8.639742e-003,0.000000e+000,3,9.765423e-001,1.825000e+000,,,,,,,,,,,,,,,,,,0,5.000000e+000,5.000000e-001,2,1,1.055145e-002,0,1,0,
1473319848.377,,-1.800000e+002,3.000293e+001,-9.622898e-004,0.000000e+000,8.162219e-003,0.000000e+000,3,9.765502e-001,1.825000e+000,,,,,,,,,,,,,,,,,,0,5.000000e+000,5.000000e-001,2,1,2.340317e-003,0,1,0,
1473319966.835,,-1.600000e+002,3.000058e+001,-9.557732e-004,0.000000e+000,8.125862e-003,0.000000e+000,3,9.776897e-001,1.825000e+000,,,,,,,,,,,,,,,,,,0,5.000000e+000,5.000000e-001,2,1,0.000000e+000,0,1,0,
1473319993.325,,-1.600000e+002,3.000293e+001,-9.549985e-004,0.000000e+000,8.249599e-003,0.000000e+000,3,9.772334e-001,1.825000e+000,,,,,,,,,,,,,,,,,,0,5.000000e+000,5.000000e-001,2,1,7.040024e-003,0,1,0,
1473320111.564,,-1.400000e+002,3.000176e+001,-9.461970e-004,0.000000e+000,8.195798e-003,0.000000e+000,3,9.775867e-001,1.825000e+000,,,,,,,,,,,,,,,,,,0,5.000000e+000,5.000000e-001,2,1,0.000000e+000,0,1,0,
1473320136.493,,-1.400000e+002,3.000117e+001,-9.462959e-004,0.000000e+000,8.336435e-003,0.000000e+000,3,9.779532e-001,1.825000e+000,,,,,,,,,,,,,,,,,,0,5.000000e+000,5.000000e-001,2,1,1.180649e-003,0,1,0,
1473320257.935,,-1.200000e+002,3.000058e+001,-9.368762e-004,0.000000e+000,8.374341e-003,0.000000e+000,3,9.790874e-001,1.825000e+000,,,,,,,,,,,,,,,,,,0,5.000000e+000,5.000000e-001,2,1,0.000000e+000,0,0,0,
1473320282.613,,-1.200000e+002,3.000117e+001,-9.369609e-004,0.000000e+000,8.287353e-003,0.000000e+000,3,9.789562e-001,1.825000e+000,,,,,,,,,,,,,,,,,,0,5.000000e+000,5.000000e-001,2,1,1.180649e-003,0,0,0,
1473320407.802,,-1.000000e+002,3.000058e+001,-9.259033e-004,0.000000e+000,8.388947e-003,0.000000e+000,3,9.797163e-001,1.825000e+000,,,,,,,,,,,,,,,,,,0,5.000000e+000,5.000000e-001,2,1,0.000000e+000,0,0,0,
1473320432.730,,-1.000000e+002,2.999941e+001,-9.257152e-004,0.000000e+000,8.298671e-003,0.000000e+000,3,9.796453e-001,1.825000e+000,,,,,,,,,,,,,,,,,,0,5.000000e+000,5.000000e-001,2,1,0.000000e+000,0,0,0,
1473320552.374,,-8.000000e+001,3.000117e+001,-9.118278e-004,0.000000e+000,8.558385e-003,0.000000e+000,3,9.805444e-001,1.825000e+000,,,,,,,,,,,,,,,,,,0,5.000000e+000,5.000000e-001,2,1,3.519058e-003,0,0,0,
1473320576.161,,-8.000000e+001,3.000059e+001,-9.114792e-004,0.000000e+000,8.404099e-003,0.000000e+000,3,9.797732e-001,1.825000e+000,,,,,,,,,,,,,,,,,,0,5.000000e+000,5.000000e-001,2,1,2.349854e-003,0,0,0,
1473320696.099,,-6.000000e+001,2.999941e+001,-8.955469e-004,0.000000e+000,8.729514e-003,0.000000e+000,3,9.805728e-001,1.825000e+000,,,,,,,,,,,,,,,,,,0,5.000000e+000,5.000000e-001,2,1,0.000000e+000,0,0,0,
1473320720.325,,-6.000000e+001,3.000058e+001,-8.959941e-004,0.000000e+000,8.648509e-003,0.000000e+000,3,9.806696e-001,1.825000e+000,,,,,,,,,,,,,,,,,,0,5.000000e+000,5.000000e-001,2,1,4.690170e-003,0,0,0,
1473320840.809,,-4.000000e+001,2.999941e+001,-8.763379e-004,0.000000e+000,8.907834e-003,0.000000e+000,3,9.818935e-001,1.825000e+000,,,,,,,,,,,,,,,,,,0,5.000000e+000,5.000000e-001,2,1,2.340317e-003,0,0,0,
1473320867.534,,-4.000000e+001,2.999941e+001,-8.758570e-004,0.000000e+000,8.815966e-003,0.000000e+000,3,9.818861e-001,1.825000e+000,,,,,,,,,,,,,,,,,,0,5.000000e+000,5.000000e-001,2,1,0.000000e+000,0,0,0,
1473320988.222,,-2.000000e+001,3.000000e+001,-8.502667e-004,0.000000e+000,9.324512e-003,0.000000e+000,3,9.824886e-001,1.825000e+000,,,,,,,,,,,,,,,,,,0,5.000000e+000,5.000000e-001,2,1,1.169205e-003,0,0,0,
1473321011.915,,-2.000000e+001,3.000000e+001,-8.493627e-004,0.000000e+000,9.093601e-003,0.000000e+000,3,9.825182e-001,1.825000e+000,,,,,,,,,,,,,,,,,,0,5.000000e+000,5.000000e-001,2,1,1.169205e-003,0,0,0,
1473321126.357,,0.000000e+000,3.000000e+001,-8.158062e-004,0.000000e+000,9.245063e-003,0.000000e+000,3,9.834149e-001,1.825000e+000,,,,,,,,,,,,,,,,,,0,5.000000e+000,5.000000e-001,2,1,3.520966e-003,0,1,0,
1473321150.535,,0.000000e+000,3.000059e+001,-8.148575e-004,0.000000e+000,9.199038e-003,0.000000e+000,3,9.836940e-001,1.825000e+000,,,,,,,,,,,,,,,,,,0,5.000000e+000,5.000000e-001,2,1,2.349854e-003,0,1,0,
1473321276.224,,2.000000e+001,2.999765e+001,-7.599622e-004,0.000000e+000,9.317234e-003,0.000000e+000,3,9.838959e-001,1.825000e+000,,,,,,,,,,,,,,,,,,0,5.000000e+000,5.000000e-001,2,1,8.211136e-003,0,1,0,
1473321300.685,,2.000000e+001,3.000235e+001,-7.587588e-004,0.000000e+000,9.310256e-003,0.000000e+000,3,9.841819e-001,1.825000e+000,,,,,,,,,,,,,,,,,,0,5.000000e+000,5.000000e-001,2,1,1.169205e-003,0,1,0,
1473321419.127,,4.000000e+001,3.000352e+001,-6.430976e-004,0.000000e+000,9.356100e-003,0.000000e+000,3,9.852248e-001,1.825000e+000,,,,,,,,,,,,,,,,,,0,5.000000e+000,5.000000e-001,2,1,1.171112e-003,0,1,0,
1473321443.337,,4.000000e+001,3.000645e+001,-6.397885e-004,0.000000e+000,8.720389e-003,0.000000e+000,3,9.852545e-001,1.825000e+000,,,,,,,,,,,,,,,,,,0,5.000000e+000,5.000000e-001,2,1,4.699707e-003,0,1,0,
1473321573.924,,6.000000e+001,2.999941e+001,4.632354e-004,0.000000e+000,7.133331e-003,0.000000e+000,3,9.781397e-001,1.825000e+000,,,,,,,,,,,,,,,,,,0,5.000000e+000,5.000000e-001,2,1,0.000000e+000,0,1,0,
1473321597.175,,6.000000e+001,3.000000e+001,4.735053e-004,0.000000e+000,7.098465e-003,0.000000e+000,3,9.783963e-001,1.825000e+000,,,,,,,,,,,,,,,,,,0,5.000000e+000,5.000000e-001,2,1,1.169205e-003,0,1,0,
1473321735.189,,8.000000e+001,3.000058e+001,6.976280e-004,0.000000e+000,7.957009e-003,0.000000e+000,3,9.791800e-001,1.825000e+000,,,,,,,,,,,,,,,,,,0,5.000000e+000,5.000000e-001,2,1,0.000000e+000,0,1,0,
1473321759.915,,8.000000e+001,3.000058e+001,7.011241e-004,0.000000e+000,8.081391e-003,0.000000e+000,3,9.788067e-001,1.825000e+000,,,,,,,,,,,,,,,,,,0,5.000000e+000,5.000000e-001,2,1,0.000000e+000,0,0,0,
1473321880.149,,1.000000e+002,3.000117e+001,7.829645e-004,0.000000e+000,7.678200e-003,0.000000e+000,3,9.790365e-001,1.825000e+000,,,,,,,,,,,,,,,,,,0,5.000000e+000,5.000000e-001,2,1,1.180649e-003,0,0,0,
1473321903.910,,1.000000e+002,2.999941e+001,7.855954e-004,0.000000e+000,7.636286e-003,0.000000e+000,3,9.789680e-001,1.825000e+000,,,,,,,,,,,,,,,,,,0,5.000000e+000,5.000000e-001,2,1,0.000000e+000,0,0,0,
1473322027.158,,1.200000e+002,2.999883e+001,8.377671e-004,0.000000e+000,7.960660e-003,0.000000e+000,3,9.785060e-001,1.825000e+000,,,,,,,,,,,,,,,,,,0,5.000000e+000,5.000000e-001,2,1,1.171112e-003,0,0,0,
1473322052.586,,1.200000e+002,3.000000e+001,8.398410e-004,0.000000e+000,7.765893e-003,0.000000e+000,3,9.781876e-001,1.825000e+000,,,,,,,,,,,,,,,,,,0,5.000000e+000,5.000000e-001,2,1,1.169205e-003,0,0,0,
1473322176.025,,1.400000e+002,3.000117e+001,8.736035e-004,0.000000e+000,7.611655e-003,0.000000e+000,3,9.782030e-001,1.825000e+000,,,,,,,,,,,,,,,,,,0,5.000000e+000,5.000000e-001,2,1,1.180649e-003,0,0,0,
1473322199.453,,1.400000e+002,2.999883e+001,8.744683e-004,0.000000e+000,8.535279e-003,0.000000e+000,3,9.768420e-001,1.825000e+000,,,,,,,,,,,,,,,,,,0,5.000000e+000,5.000000e-001,2,1,1.171112e-003,0,0,0,
1473322330.396,,1.600000e+002,2.999765e+001,8.991217e-004,0.000000e+000,8.144046e-003,0.000000e+000,3,9.768646e-001,1.825000e+000,,,,,,,,,,,,,,,,,,0,5.000000e+000,5.000000e-001,2,1,1.178741e-003,0,0,0,
1473322355.324,,1.600000e+002,3.000000e+001,9.003156e-004,0.000000e+000,7.976035e-003,0.000000e+000,3,9.769766e-001,1.825000e+000,,,,,,,,,,,,,,,,,,0,5.000000e+000,5.000000e-001,2,1,1.169205e-003,0,0,0,
1473322481.727,,1.800000e+002,2.999648e+001,9.184395e-004,0.000000e+000,7.924265e-003,0.000000e+000,3,9.764517e-001,1.825000e+000,,,,,,,,,,,,,,,,,,0,5.000000e+000,5.000000e-001,2,1,3.519058e-003,0,0,0,
1473322508.014,,1.800000e+002,3.000000e+001,9.197498e-004,0.000000e+000,7.971028e-003,0.000000e+000,3,9.762033e-001,1.825000e+000,,,,,,,,,,,,,,,,,,0,5.000000e+000,5.000000e-001,2,1,1.169205e-003,0,0,0,
1473322628.956,,2.000000e+002,3.000293e+001,9.340137e-004,0.000000e+000,7.554847e-003,0.000000e+000,3,9.760882e-001,1.825000e+000,,,,,,,,,,,,,,,,,,0,5.000000e+000,5.000000e-001,2,1,4.699707e-003,0,1,0,
1473322654.134,,2.000000e+002,3.000117e+001,9.336400e-004,0.000000e+000,7.992290e-003,0.000000e+000,3,9.760659e-001,1.825000e+000,,,,,,,,,,,,,,,,,,0,5.000000e+000,5.000000e-001,2,1,3.519058e-003,0,1,0,
1473322788.844,,3.000000e+002,3.000293e+001,9.772284e-004,0.000000e+000,7.463925e-003,0.000000e+000,3,9.731404e-001,1.825000e+000,,,,,,,,,,,,,,,,,,0,5.000000e+000,5.000000e-001,2,1,0.000000e+000,0,1,0,
1473322812.062,,3.000000e+002,3.000175e+001,9.778739e-004,0.000000e+000,7.644243e-003,0.000000e+000,3,9.726411e-001,1.825000e+000,,,,,,,,,,,,,,,,,,0,5.000000e+000,5.000000e-001,2,1,2.349854e-003,0,1,0,
1473322948.756,,4.000000e+002,3.000117e+001,9.991635e-004,0.000000e+000,7.201787e-003,0.000000e+000,3,9.702267e-001,1.825000e+000,,,,,,,,,,,,,,,,,,0,5.000000e+000,5.000000e-001,2,1,1.180649e-003,0,1,0,
1473322973.475,,4.000000e+002,2.999883e+001,9.996227e-004,0.000000e+000,7.157903e-003,0.000000e+000,3,9.699246e-001,1.825000e+000,,,,,,,,,,,,,,,,,,0,5.000000e+000,5.000000e-001,2,1,1.171112e-003,0,1,0,
1473323107.966,,5.000000e+002,3.000234e+001,1.012967e-003,0.000000e+000,7.016992e-003,0.000000e+000,3,9.672049e-001,1.825000e+000,,,,,,,,,,,,,,,,,,0,5.000000e+000,5.000000e-001,2,1,3.520966e-003,0,1,0,
1473323133.156,,5.000000e+002,3.000117e+001,1.013051e-003,0.000000e+000,6.789118e-003,0.000000e+000,3,9.675072e-001,1.825000e+000,,,,,,,,,,,,,,,,,,0,5.000000e+000,5.000000e-001,2,1,3.519058e-003,0,1,0,
1473323257.398,,6.000000e+002,2.999824e+001,1.023163e-003,0.000000e+000,6.950216e-003,0.000000e+000,3,9.653779e-001,1.825000e+000,,,,,,,,,,,,,,,,,,0,5.000000e+000,5.000000e-001,2,1,2.349854e-003,0,0,0,
1473323281.866,,6.000000e+002,2.999941e+001,1.024415e-003,0.000000e+000,6.031359e-003,0.000000e+000,3,9.647284e-001,1.825000e+000,,,,,,,,,,,,,,,,,,0,5.000000e+000,5.000000e-001,2,1,2.340317e-003,0,0,0,
1473323416.316,,7.000000e+002,2.999883e+001,1.026352e-003,0.000000e+000,5.413388e-003,0.000000e+000,3,9.627331e-001,1.825000e+000,,,,,,,,,,,,,,,,,,0,5.000000e+000,5.000000e-001,2,1,1.171112e-003,0,0,0,
1473323439.244,,7.000000e+002,3.000058e+001,1.029909e-003,0.000000e+000,6.448451e-003,0.000000e+000,3,9.635471e-001,1.825000e+000,,,,,,,,,,,,,,,,,,0,5.000000e+000,5.000000e-001,2,1,0.000000e+000,0,0,0,
1473323564.198,,1.000000e+003,3.000117e+001,1.043927e-003,0.000000e+000,5.925561e-003,0.000000e+000,3,9.600364e-001,1.825000e+000,,,,,,,,,,,,,,,,,,0,5.000000e+000,5.000000e-001,2,1,3.519058e-003,0,0,0,
1473323589.377,,1.000000e+003,2.999941e+001,1.043970e-003,0.000000e+000,6.009925e-003,0.000000e+000,3,9.598648e-001,1.825000e+000,,,,,,,,,,,,,,,,,,0,5.000000e+000,5.000000e-001,2,1,0.000000e+000,0,0,0,
1473323725.066,,3.000000e+003,2.999824e+001,1.079968e-003,0.000000e+000,4.665443e-003,0.000000e+000,3,9.528199e-001,1.825000e+000,,,,,,,,,,,,,,,,,,0,5.000000e+000,5.000000e-001,2,1,0.000000e+000,0,0,0,
1473323750.304,,3.000000e+003,2.999883e+001,1.080354e-003,0.000000e+000,4.531476e-003,0.000000e+000,3,9.519285e-001,1.825000e+000,,,,,,,,,,,,,,,,,,0,5.000000e+000,5.000000e-001,2,1,8.209229e-003,0,0,0,
1473323885.775,,5.000000e+003,2.999765e+001,1.095267e-003,0.000000e+000,4.391212e-003,0.000000e+000,3,9.507598e-001,1.825000e+000,,,,,,,,,,,,,,,,,,0,5.000000e+000,5.000000e-001,2,1,3.520966e-003,0,0,0,
1473323909.718,,5.000000e+003,3.000000e+001,1.095489e-003,0.000000e+000,4.369244e-003,0.000000e+000,3,9.509481e-001,1.825000e+000,,,,,,,,,,,,,,,,,,0,5.000000e+000,5.000000e-001,2,1,3.520966e-003,0,0,0,
1473324044.907,,7.000000e+003,2.999941e+001,1.104952e-003,0.000000e+000,4.436675e-003,0.000000e+000,3,9.507091e-001,1.825000e+000,,,,,,,,,,,,,,,,,,0,5.000000e+000,5.000000e-001,2,1,4.699707e-003,0,1,0,
1473324071.836,,7.000000e+003,3.000235e+001,1.105254e-003,0.000000e+000,4.435360e-003,0.000000e+000,3,9.507413e-001,1.825000e+000,,,,,,,,,,,,,,,,,,0,5.000000e+000,5.000000e-001,2,1,1.169205e-003,0,1,0,
1473324206.281,,9.000000e+003,3.000410e+001,1.112366e-003,0.000000e+000,4.575576e-003,0.000000e+000,3,9.508412e-001,1.825000e+000,,,,,,,,,,,,,,,,,,0,5.000000e+000,5.000000e-001,2,1,2.349854e-003,0,1,0,
1473324232.209,,9.000000e+003,3.000469e+001,1.112437e-003,0.000000e+000,4.590380e-003,0.000000e+000,3,9.508494e-001,1.825000e+000,,,,,,,,,,,,,,,,,,0,5.000000e+000,5.000000e-001,2,1,1.178741e-003,0,1,0,
1473324366.694,,1.000000e+004,3.000000e+001,1.114880e-003,0.000000e+000,4.899207e-003,0.000000e+000,3,9.511105e-001,1.825000e+000,,,,,,,,,,,,,,,,,,0,5.000000e+000,5.000000e-001,2,1,1.169205e-003,0,1,0,
1473324391.669,,1.000000e+004,3.000234e+001,1.115159e-003,0.000000e+000,4.410969e-003,0.000000e+000,3,9.504656e-001,1.825000e+000,,,,,,,,,,,,,,,,,,0,5.000000e+000,5.000000e-001,2,1,3.520966e-003,0,1,0,
1473324554.812,,2.000000e+004,3.000000e+001,1.136267e-003,0.000000e+000,5.898897e-003,0.000000e+000,3,9.535619e-001,1.825000e+000,,,,,,,,,,,,,,,,,,0,5.000000e+000,5.000000e-001,2,1,1.169205e-003,0,1,0,
1473324578.849,,2.000000e+004,3.000176e+001,1.133333e-003,0.000000e+000,5.549293e-003,0.000000e+000,3,9.502420e-001,1.825000e+000,,,,,,,,,,,,,,,,,,0,5.000000e+000,5.000000e-001,2,1,0.000000e+000,0,1,0,
1473324752.587,,3.000000e+004,3.000000e+001,1.145191e-003,0.000000e+000,6.284623e-003,0.000000e+000,3,9.508298e-001,1.825000e+000,,,,,,,,,,,,,,,,,,0,5.000000e+000,5.000000e-001,2,1,3.520966e-003,0,0,0,
1473324776.766,,3.000000e+004,2.999941e+001,1.145451e-003,0.000000e+000,5.863184e-003,0.000000e+000,3,9.509096e-001,1.825000e+000,,,,,,,,,,,,,,,,,,0,5.000000e+000,5.000000e-001,2,1,2.340317e-003,0,0,0,
1473324954.211,,4.000000e+004,3.000000e+001,1.150426e-003,0.000000e+000,6.573601e-003,0.000000e+000,3,9.499530e-001,1.825000e+000,,,,,,,,,,,,,,,,,,0,5.000000e+000,5.000000e-001,2,1,3.520966e-003,0,0,0,
1473324979.682,,4.000000e+004,2.999883e+001,1.151664e-003,0.000000e+000,6.473335e-003,0.000000e+000,3,9.504272e-001,1.825000e+000,,,,,,,,,,,,,,,,,,0,5.000000e+000,5.000000e-001,2,1,1.171112e-003,0,0,0,
1473325159.911,,5.000000e+004,2.999883e+001,1.156091e-003,0.000000e+000,7.132615e-003,0.000000e+000,3,9.500635e-001,1.825000e+000,,,,,,,,,,,,,,,,,,0,5.000000e+000,5.000000e-001,2,1,1.171112e-003,0,0,0,
1473325185.089,,5.000000e+004,2.999824e+001,1.156040e-003,0.000000e+000,7.049663e-003,0.000000e+000,3,9.500942e-001,1.825000e+000,,,,,,,,,,,,,,,,,,0,5.000000e+000,5.000000e-001,2,1,2.349854e-003,0,0,0,
1473325365.837,,6.000000e+004,2.999765e+001,1.177654e-003,0.000000e+000,4.093635e-003,0.000000e+000,3,9.112927e-001,1.825000e+000,,,,,,,,,,,,,,,,,,0,5.000000e+000,5.000000e-001,2,1,1.178741e-003,0,1,0,
1473325390.016,,6.000000e+004,2.999941e+001,1.158755e-003,0.000000e+000,7.935657e-003,0.000000e+000,3,9.492446e-001,1.825000e+000,,,,,,,,,,,,,,,,,,0,5.000000e+000,5.000000e-001,2,1,2.340317e-003,0,1,0,
1473325568.504,,7.000000e+004,3.000117e+001,1.157700e-003,0.000000e+000,8.281954e-003,0.000000e+000,3,9.494438e-001,1.825000e+000,,,,,,,,,,,,,,,,,,0,5.000000e+000,5.000000e-001,2,1,1.180649e-003,0,1,0,
1473325592.219,,7.000000e+004,3.000293e+001,1.158135e-003,0.000000e+000,7.970618e-003,0.000000e+000,3,9.483949e-001,1.825000e+000,,,,,,,,,,,,,,,,,,0,5.000000e+000,5.000000e-001,2,1,2.340317e-003,0,1,0,
1473325603.682,,7.000000e+004,3.000293e+001,1.159175e-003,0.000000e+000,8.652396e-003,0.000000e+000,3,9.490545e-001,1.825000e+000,,,,,,,,,,,,,,,,,,0,5.000000e+000,5.000000e-001,2,1,2.340317e-003,0,1,0,