File: data/A344/A344_GdN_MH_050K_160905.rso.dat
[Header]
TITLE,MPMS RSO Measurement
BYAPP,MPMS Measurement,1.1,Summary
FILEOPENTIME, 1473153837.031000 9/6/2016, 9:23:57 PM

INFO, APPNAME, MPMS MultiVu Application, Revision 1.61,  Build 082

INFO, NAME, A344
INFO, WEIGHT, 10.500
INFO, AREA, 1.000
INFO, LENGTH, 1.000
INFO, SHAPE, 0
INFO, COMMENT, m = 0.0105g
INFO, SEQUENCE FILE: 7T_hysteresis_sweep_hi_res_zero_n4.seq


INFO, BACKGROUND DATA FILE:, None


STARTUPAXIS,X,4,LINEAR,AUTO,0.000000,0.000000
STARTUPAXIS,Y1,5,LINEAR,AUTO,0.000000,0.000000


STARTUPGROUP,Longitudinal
FIELDGROUP,Longitudinal,1,2,3,4,5,6,7,8,9,10,11,19,20,21,22,23,35
FIELDGROUP,Transverse,1,2,3,4,12,13,14,15,16,17,18,24,25,26,27,28,35

PLOT_APPEARANCE,ALL,HORZ_GRID_ON,VERT_GRID_ON,MARKERS_AND_LINES

[Data]
Time,Comment,Field (Oe),Temperature (K),Long Moment (emu),Long Scan Std Dev,Long Offset (cm),Long Offset Std Dev,Long Algorithm,Long Reg Fit,Long Reg Factor,Trans Moment (emu),Trans Scan Std Dev,Trans Offset (cm),Trans Offset Std Dev,Trans Algorithm,Trans Reg Fit,Trans Reg Factor,Long Moment [w/o ABS] (emu),Long Scan Std Dev [w/o ABS],Long Offset [w/o ABS] (cm),Long Offset Std Dev [w/o ABS],Long Reg Fit [w/o ABS],Trans Moment [w/o ABS] (emu),Trans Scan Std Dev [w/o ABS],Trans Offset [w/o ABS] (cm),Trans Offset Std Dev [w/o ABS],Trans Reg Fit [w/o ABS],RSO Position (deg),Amplitude (cm),Frequency,Cycles to Average,Scans per Measurement,Delta Temp (K),Error,EC Comp. Running,Using ABS,
1473153837.030,,7.000000e+004,5.004070e+001,9.740071e-004,0.000000e+000,1.107612e-002,0.000000e+000,3,9.416149e-001,1.825000e+000,,,,,,,,,,,,,,,,,,0,5.000000e+000,5.000000e-001,2,1,4.978180e-003,0,0,0,
1473153865.985,,7.000000e+004,5.002329e+001,9.740914e-004,0.000000e+000,1.112587e-002,0.000000e+000,3,9.414189e-001,1.825000e+000,,,,,,,,,,,,,,,,,,0,5.000000e+000,5.000000e-001,2,1,2.498627e-003,0,0,0,
1473154049.959,,6.000000e+004,5.000216e+001,9.665744e-004,0.000000e+000,1.013834e-002,0.000000e+000,3,9.414933e-001,1.825000e+000,,,,,,,,,,,,,,,,,,0,5.000000e+000,5.000000e-001,2,1,0.000000e+000,0,1,0,
1473154074.616,,6.000000e+004,5.000588e+001,9.661262e-004,0.000000e+000,9.870585e-003,0.000000e+000,3,9.407763e-001,1.825000e+000,,,,,,,,,,,,,,,,,,0,5.000000e+000,5.000000e-001,2,1,1.491165e-002,0,1,0,
1473154247.671,,5.000000e+004,5.000092e+001,9.537299e-004,0.000000e+000,9.414824e-003,0.000000e+000,3,9.404194e-001,1.825000e+000,,,,,,,,,,,,,,,,,,0,5.000000e+000,5.000000e-001,2,1,4.981995e-003,0,1,0,
1473154271.886,,5.000000e+004,5.000092e+001,9.541782e-004,0.000000e+000,9.751250e-003,0.000000e+000,3,9.424725e-001,1.825000e+000,,,,,,,,,,,,,,,,,,0,5.000000e+000,5.000000e-001,2,1,2.479553e-003,0,1,0,
1473154449.832,,4.000000e+004,5.000278e+001,9.412320e-004,0.000000e+000,9.316755e-003,0.000000e+000,3,9.447727e-001,1.825000e+000,,,,,,,,,,,,,,,,,,0,5.000000e+000,5.000000e-001,2,1,6.198883e-003,0,1,0,
1473154474.010,,4.000000e+004,4.999843e+001,9.396771e-004,0.000000e+000,1.151252e-002,0.000000e+000,3,9.378958e-001,1.825000e+000,,,,,,,,,,,,,,,,,,0,5.000000e+000,5.000000e-001,2,1,0.000000e+000,0,1,0,
1473154651.965,,3.000000e+004,4.999782e+001,9.208923e-004,0.000000e+000,6.735056e-003,0.000000e+000,3,9.417245e-001,1.825000e+000,,,,,,,,,,,,,,,,,,0,5.000000e+000,5.000000e-001,2,1,1.366043e-002,0,0,0,
1473154676.945,,3.000000e+004,4.999905e+001,9.192162e-004,0.000000e+000,7.684054e-003,0.000000e+000,3,9.407502e-001,1.825000e+000,,,,,,,,,,,,,,,,,,0,5.000000e+000,5.000000e-001,2,1,1.251221e-003,0,0,0,
1473154849.201,,2.000000e+004,5.000340e+001,8.933078e-004,0.000000e+000,6.979310e-003,0.000000e+000,3,9.407107e-001,1.825000e+000,,,,,,,,,,,,,,,,,,0,5.000000e+000,5.000000e-001,2,1,4.959106e-003,0,0,0,
1473154874.399,,2.000000e+004,5.000029e+001,8.933574e-004,0.000000e+000,6.627392e-003,0.000000e+000,3,9.408504e-001,1.825000e+000,,,,,,,,,,,,,,,,,,0,5.000000e+000,5.000000e-001,2,1,3.730774e-003,0,0,0,
1473155045.794,,1.000000e+004,5.000340e+001,8.477582e-004,0.000000e+000,6.105588e-003,0.000000e+000,3,9.345195e-001,1.825000e+000,,,,,,,,,,,,,,,,,,0,5.000000e+000,5.000000e-001,2,1,1.240921e-002,0,0,0,
1473155072.885,,1.000000e+004,4.999906e+001,8.520009e-004,0.000000e+000,5.816988e-003,0.000000e+000,3,9.390549e-001,1.825000e+000,,,,,,,,,,,,,,,,,,0,5.000000e+000,5.000000e-001,2,1,3.719330e-003,0,0,0,
1473155208.080,,9.000000e+003,5.000029e+001,8.459990e-004,0.000000e+000,6.346242e-003,0.000000e+000,3,9.386548e-001,1.825000e+000,,,,,,,,,,,,,,,,,,0,5.000000e+000,5.000000e-001,2,1,1.116943e-002,0,0,0,
1473155234.008,,9.000000e+003,4.999657e+001,8.467964e-004,0.000000e+000,5.891507e-003,0.000000e+000,3,9.386611e-001,1.825000e+000,,,,,,,,,,,,,,,,,,0,5.000000e+000,5.000000e-001,2,1,1.251221e-003,0,0,0,
1473155371.005,,7.000000e+003,4.999720e+001,8.339792e-004,0.000000e+000,5.771486e-003,0.000000e+000,3,9.387247e-001,1.825000e+000,,,,,,,,,,,,,,,,,,0,5.000000e+000,5.000000e-001,2,1,0.000000e+000,0,0,0,
1473155399.688,,7.000000e+003,4.999905e+001,8.338547e-004,0.000000e+000,5.855217e-003,0.000000e+000,3,9.384205e-001,1.825000e+000,,,,,,,,,,,,,,,,,,0,5.000000e+000,5.000000e-001,2,1,1.251221e-003,0,0,0,
1473155533.877,,5.000000e+003,4.999844e+001,8.177319e-004,0.000000e+000,5.787971e-003,0.000000e+000,3,9.384515e-001,1.825000e+000,,,,,,,,,,,,,,,,,,0,5.000000e+000,5.000000e-001,2,1,2.479553e-003,0,1,0,
1473155558.306,,5.000000e+003,4.999781e+001,8.179067e-004,0.000000e+000,5.908318e-003,0.000000e+000,3,9.380683e-001,1.825000e+000,,,,,,,,,,,,,,,,,,0,5.000000e+000,5.000000e-001,2,1,3.730774e-003,0,1,0,
1473155689.724,,3.000000e+003,5.000278e+001,7.969542e-004,0.000000e+000,6.063698e-003,0.000000e+000,3,9.393737e-001,1.825000e+000,,,,,,,,,,,,,,,,,,0,5.000000e+000,5.000000e-001,2,1,1.251221e-003,0,1,0,
1473155715.761,,3.000000e+003,5.000651e+001,7.972389e-004,0.000000e+000,6.136230e-003,0.000000e+000,3,9.391146e-001,1.825000e+000,,,,,,,,,,,,,,,,,,0,5.000000e+000,5.000000e-001,2,1,8.701324e-003,0,1,0,
1473155843.699,,1.000000e+003,5.000092e+001,7.587674e-004,0.000000e+000,8.953325e-003,0.000000e+000,3,9.484966e-001,1.825000e+000,,,,,,,,,,,,,,,,,,0,5.000000e+000,5.000000e-001,2,1,0.000000e+000,0,1,0,
1473155868.057,,1.000000e+003,5.000278e+001,7.605136e-004,0.000000e+000,7.368662e-003,0.000000e+000,3,9.500127e-001,1.825000e+000,,,,,,,,,,,,,,,,,,0,5.000000e+000,5.000000e-001,2,1,6.198883e-003,0,1,0,
1473156000.392,,7.000000e+002,4.999844e+001,7.480899e-004,0.000000e+000,9.033779e-003,0.000000e+000,3,9.541895e-001,1.825000e+000,,,,,,,,,,,,,,,,,,0,5.000000e+000,5.000000e-001,2,1,2.479553e-003,0,1,0,
1473156025.376,,7.000000e+002,5.000029e+001,7.482553e-004,0.000000e+000,8.702269e-003,0.000000e+000,3,9.543549e-001,1.825000e+000,,,,,,,,,,,,,,,,,,0,5.000000e+000,5.000000e-001,2,1,3.730774e-003,0,1,0,
1473156152.814,,6.000000e+002,4.999719e+001,7.425033e-004,0.000000e+000,9.144209e-003,0.000000e+000,3,9.570819e-001,1.825000e+000,,,,,,,,,,,,,,,,,,0,5.000000e+000,5.000000e-001,2,1,7.450104e-003,0,0,0,
1473156176.799,,6.000000e+002,4.999657e+001,7.425647e-004,0.000000e+000,9.522239e-003,0.000000e+000,3,9.562031e-001,1.825000e+000,,,,,,,,,,,,,,,,,,0,5.000000e+000,5.000000e-001,2,1,3.719330e-003,0,0,0,
1473156310.186,,5.000000e+002,4.999533e+001,7.372206e-004,0.000000e+000,1.046196e-002,0.000000e+000,3,9.586177e-001,1.825000e+000,,,,,,,,,,,,,,,,,,0,5.000000e+000,5.000000e-001,2,1,1.239777e-003,0,0,0,
1473156333.972,,5.000000e+002,4.999471e+001,7.359112e-004,0.000000e+000,9.611490e-003,0.000000e+000,3,9.599500e-001,1.825000e+000,,,,,,,,,,,,,,,,,,0,5.000000e+000,5.000000e-001,2,1,2.479553e-003,0,0,0,
1473156459.661,,4.000000e+002,4.999905e+001,7.255841e-004,0.000000e+000,1.011793e-002,0.000000e+000,3,9.637710e-001,1.825000e+000,,,,,,,,,,,,,,,,,,0,5.000000e+000,5.000000e-001,2,1,1.251221e-003,0,0,0,
1473156484.339,,4.000000e+002,5.000030e+001,7.252558e-004,0.000000e+000,1.000050e-002,0.000000e+000,3,9.635383e-001,1.825000e+000,,,,,,,,,,,,,,,,,,0,5.000000e+000,5.000000e-001,2,1,1.239777e-003,0,0,0,
1473156616.306,,3.000000e+002,5.000217e+001,7.094652e-004,0.000000e+000,1.160064e-002,0.000000e+000,3,9.653781e-001,1.825000e+000,,,,,,,,,,,,,,,,,,0,5.000000e+000,5.000000e-001,2,1,4.970551e-003,0,0,0,
1473156641.810,,3.000000e+002,4.999781e+001,7.100875e-004,0.000000e+000,1.072494e-002,0.000000e+000,3,9.672484e-001,1.825000e+000,,,,,,,,,,,,,,,,,,0,5.000000e+000,5.000000e-001,2,1,1.228333e-003,0,0,0,
1473156776.341,,2.000000e+002,4.999720e+001,6.861934e-004,0.000000e+000,1.056103e-002,0.000000e+000,3,9.717855e-001,1.825000e+000,,,,,,,,,,,,,,,,,,0,5.000000e+000,5.000000e-001,2,1,0.000000e+000,0,0,0,
1473156802.554,,2.000000e+002,5.000092e+001,6.853066e-004,0.000000e+000,1.113673e-002,0.000000e+000,3,9.722517e-001,1.825000e+000,,,,,,,,,,,,,,,,,,0,5.000000e+000,5.000000e-001,2,1,2.479553e-003,0,0,0,
1473156932.018,,1.800000e+002,4.999781e+001,6.773053e-004,0.000000e+000,1.140019e-002,0.000000e+000,3,9.731615e-001,1.825000e+000,,,,,,,,,,,,,,,,,,0,5.000000e+000,5.000000e-001,2,1,1.228333e-003,0,1,0,
1473156957.947,,1.800000e+002,4.999905e+001,6.782026e-004,0.000000e+000,1.084357e-002,0.000000e+000,3,9.730132e-001,1.825000e+000,,,,,,,,,,,,,,,,,,0,5.000000e+000,5.000000e-001,2,1,1.251221e-003,0,1,0,
1473157079.149,,1.600000e+002,5.000465e+001,6.696298e-004,0.000000e+000,1.150989e-002,0.000000e+000,3,9.736611e-001,1.825000e+000,,,,,,,,,,,,,,,,,,0,5.000000e+000,5.000000e-001,2,1,2.468109e-003,0,1,0,
1473157105.328,,1.600000e+002,5.000154e+001,6.698149e-004,0.000000e+000,1.112640e-002,0.000000e+000,3,9.734492e-001,1.825000e+000,,,,,,,,,,,,,,,,,,0,5.000000e+000,5.000000e-001,2,1,1.239777e-003,0,1,0,
1473157226.818,,1.400000e+002,4.999844e+001,6.601161e-004,0.000000e+000,1.133006e-002,0.000000e+000,3,9.751677e-001,1.825000e+000,,,,,,,,,,,,,,,,,,0,5.000000e+000,5.000000e-001,2,1,7.450104e-003,0,1,0,
1473157251.999,,1.400000e+002,5.000092e+001,6.595530e-004,0.000000e+000,1.174274e-002,0.000000e+000,3,9.747512e-001,1.825000e+000,,,,,,,,,,,,,,,,,,0,5.000000e+000,5.000000e-001,2,1,4.981995e-003,0,1,0,
1473157373.977,,1.200000e+002,4.999781e+001,6.476431e-004,0.000000e+000,1.118012e-002,0.000000e+000,3,9.767174e-001,1.825000e+000,,,,,,,,,,,,,,,,,,0,5.000000e+000,5.000000e-001,2,1,1.228333e-003,0,1,0,
1473157396.205,,1.200000e+002,4.999844e+001,6.478970e-004,0.000000e+000,1.149377e-002,0.000000e+000,3,9.766474e-001,1.825000e+000,,,,,,,,,,,,,,,,,,0,5.000000e+000,5.000000e-001,2,1,2.479553e-003,0,1,0,
1473157521.945,,1.000000e+002,5.008755e+001,6.323190e-004,0.000000e+000,1.138985e-002,0.000000e+000,3,9.781682e-001,1.825000e+000,,,,,,,,,,,,,,,,,,0,5.000000e+000,5.000000e-001,2,1,1.832008e-001,0,1,0,
1473157545.874,,1.000000e+002,5.003511e+001,6.322982e-004,0.000000e+000,1.085591e-002,0.000000e+000,3,9.792676e-001,1.825000e+000,,,,,,,,,,,,,,,,,,0,5.000000e+000,5.000000e-001,2,1,3.855896e-002,0,0,0,
1473157665.312,,8.000000e+001,4.999657e+001,6.172013e-004,0.000000e+000,1.186498e-002,0.000000e+000,3,9.778138e-001,1.825000e+000,,,,,,,,,,,,,,,,,,0,5.000000e+000,5.000000e-001,2,1,1.251221e-003,0,0,0,
1473157692.426,,8.000000e+001,4.999471e+001,6.176868e-004,0.000000e+000,1.188580e-002,0.000000e+000,3,9.785330e-001,1.825000e+000,,,,,,,,,,,,,,,,,,0,5.000000e+000,5.000000e-001,2,1,1.490021e-002,0,0,0,
1473157814.476,,6.000000e+001,5.000278e+001,5.953900e-004,0.000000e+000,1.278076e-002,0.000000e+000,3,9.794334e-001,1.825000e+000,,,,,,,,,,,,,,,,,,0,5.000000e+000,5.000000e-001,2,1,1.116943e-002,0,0,0,
1473157838.921,,6.000000e+001,4.999905e+001,5.948222e-004,0.000000e+000,1.234646e-002,0.000000e+000,3,9.796931e-001,1.825000e+000,,,,,,,,,,,,,,,,,,0,5.000000e+000,5.000000e-001,2,1,1.251221e-003,0,0,0,
1473157966.675,,4.000000e+001,4.999719e+001,5.661762e-004,0.000000e+000,1.255319e-002,0.000000e+000,3,9.808569e-001,1.825000e+000,,,,,,,,,,,,,,,,,,0,5.000000e+000,5.000000e-001,2,1,2.479553e-003,0,0,0,
1473157991.638,,4.000000e+001,4.998975e+001,5.660603e-004,0.000000e+000,1.285735e-002,0.000000e+000,3,9.809350e-001,1.825000e+000,,,,,,,,,,,,,,,,,,0,5.000000e+000,5.000000e-001,2,1,3.226852e-002,0,0,0,
1473158110.830,,2.000000e+001,4.999595e+001,5.273712e-004,0.000000e+000,1.244955e-002,0.000000e+000,3,9.817684e-001,1.825000e+000,,,,,,,,,,,,,,,,,,0,5.000000e+000,5.000000e-001,2,1,0.000000e+000,0,0,0,
1473158138.704,,2.000000e+001,4.999595e+001,5.267418e-004,0.000000e+000,1.240399e-002,0.000000e+000,3,9.821676e-001,1.825000e+000,,,,,,,,,,,,,,,,,,0,5.000000e+000,5.000000e-001,2,1,4.959106e-003,0,0,0,
1473158259.502,,0.000000e+000,4.999781e+001,4.601817e-004,0.000000e+000,1.391193e-002,0.000000e+000,3,9.824644e-001,1.825000e+000,,,,,,,,,,,,,,,,,,0,5.000000e+000,5.000000e-001,2,1,6.210327e-003,0,0,0,
1473158282.933,,0.000000e+000,4.999657e+001,4.586428e-004,0.000000e+000,1.280337e-002,0.000000e+000,3,9.835907e-001,1.825000e+000,,,,,,,,,,,,,,,,,,0,5.000000e+000,5.000000e-001,2,1,1.251221e-003,0,0,0,
1473158413.456,,-2.000000e+001,5.004443e+001,1.503253e-004,0.000000e+000,1.614845e-002,0.000000e+000,3,9.861633e-001,1.825000e+000,,,,,,,,,,,,,,,,,,0,5.000000e+000,5.000000e-001,2,1,3.235245e-002,0,1,0,
1473158447.411,,-2.000000e+001,5.000340e+001,1.289764e-004,0.000000e+000,1.548679e-002,0.000000e+000,3,9.857974e-001,1.825000e+000,,,,,,,,,,,,,,,,,,0,5.000000e+000,5.000000e-001,2,1,2.490997e-003,0,1,0,
1473158578.034,,-4.000000e+001,5.000154e+001,-5.093510e-004,0.000000e+000,1.138958e-002,0.000000e+000,3,9.820608e-001,1.825000e+000,,,,,,,,,,,,,,,,,,0,5.000000e+000,5.000000e-001,2,1,6.221771e-003,0,1,0,
1473158602.071,,-4.000000e+001,5.000092e+001,-5.117839e-004,0.000000e+000,1.303884e-002,0.000000e+000,3,9.806864e-001,1.825000e+000,,,,,,,,,,,,,,,,,,0,5.000000e+000,5.000000e-001,2,1,4.981995e-003,0,1,0,
1473158730.013,,-6.000000e+001,5.000402e+001,-5.770283e-004,0.000000e+000,1.267724e-002,0.000000e+000,3,9.803975e-001,1.825000e+000,,,,,,,,,,,,,,,,,,0,5.000000e+000,5.000000e-001,2,1,3.719330e-003,0,1,0,
1473158753.995,,-6.000000e+001,5.000340e+001,-5.786026e-004,0.000000e+000,1.254727e-002,0.000000e+000,3,9.798844e-001,1.825000e+000,,,,,,,,,,,,,,,,,,0,5.000000e+000,5.000000e-001,2,1,2.490997e-003,0,1,0,
1473158876.736,,-8.000000e+001,5.000030e+001,-6.114788e-004,0.000000e+000,1.210590e-002,0.000000e+000,3,9.787943e-001,1.825000e+000,,,,,,,,,,,,,,,,,,0,5.000000e+000,5.000000e-001,2,1,1.239777e-003,0,1,0,
1473158903.414,,-8.000000e+001,5.000029e+001,-6.119576e-004,0.000000e+000,1.226817e-002,0.000000e+000,3,9.784096e-001,1.825000e+000,,,,,,,,,,,,,,,,,,0,5.000000e+000,5.000000e-001,2,1,3.730774e-003,0,1,0,
1473159021.607,,-1.000000e+002,5.000154e+001,-6.335506e-004,0.000000e+000,1.265622e-002,0.000000e+000,3,9.778014e-001,1.825000e+000,,,,,,,,,,,,,,,,,,0,5.000000e+000,5.000000e-001,2,1,8.678436e-003,0,1,0,
1473159045.537,,-1.000000e+002,5.000030e+001,-6.337557e-004,0.000000e+000,1.312795e-002,0.000000e+000,3,9.764873e-001,1.825000e+000,,,,,,,,,,,,,,,,,,0,5.000000e+000,5.000000e-001,2,1,8.701324e-003,0,0,0,
1473159164.473,,-1.200000e+002,4.999844e+001,-6.507124e-004,0.000000e+000,1.197693e-002,0.000000e+000,3,9.775195e-001,1.825000e+000,,,,,,,,,,,,,,,,,,0,5.000000e+000,5.000000e-001,2,1,2.479553e-003,0,0,0,
1473159189.208,,-1.200000e+002,5.000154e+001,-6.503141e-004,0.000000e+000,1.187303e-002,0.000000e+000,3,9.760333e-001,1.825000e+000,,,,,,,,,,,,,,,,,,0,5.000000e+000,5.000000e-001,2,1,8.678436e-003,0,0,0,
1473159310.150,,-1.400000e+002,4.999657e+001,-6.623071e-004,0.000000e+000,1.288261e-002,0.000000e+000,3,9.735721e-001,1.825000e+000,,,,,,,,,,,,,,,,,,0,5.000000e+000,5.000000e-001,2,1,6.210327e-003,0,0,0,
1473159346.293,,-1.400000e+002,5.000029e+001,-6.629167e-004,0.000000e+000,1.176051e-002,0.000000e+000,3,9.752791e-001,1.825000e+000,,,,,,,,,,,,,,,,,,0,5.000000e+000,5.000000e-001,2,1,3.730774e-003,0,0,0,
1473159466.541,,-1.600000e+002,4.999906e+001,-6.734326e-004,0.000000e+000,1.279196e-002,0.000000e+000,3,9.733170e-001,1.825000e+000,,,,,,,,,,,,,,,,,,0,5.000000e+000,5.000000e-001,2,1,8.701324e-003,0,0,0,
1473159492.482,,-1.600000e+002,4.999967e+001,-6.732343e-004,0.000000e+000,1.208952e-002,0.000000e+000,3,9.743322e-001,1.825000e+000,,,,,,,,,,,,,,,,,,0,5.000000e+000,5.000000e-001,2,1,2.490997e-003,0,0,0,
1473159620.237,,-1.800000e+002,4.999719e+001,-6.828740e-004,0.000000e+000,1.137958e-002,0.000000e+000,3,9.732318e-001,1.825000e+000,,,,,,,,,,,,,,,,,,0,5.000000e+000,5.000000e-001,2,1,2.479553e-003,0,0,0,
1473159645.166,,-1.800000e+002,4.999471e+001,-6.818783e-004,0.000000e+000,1.206456e-002,0.000000e+000,3,9.736363e-001,1.825000e+000,,,,,,,,,,,,,,,,,,0,5.000000e+000,5.000000e-001,2,1,4.970551e-003,0,0,0,
1473159765.368,,-2.000000e+002,4.999844e+001,-6.898784e-004,0.000000e+000,1.129974e-002,0.000000e+000,3,9.722348e-001,1.825000e+000,,,,,,,,,,,,,,,,,,0,5.000000e+000,5.000000e-001,2,1,4.970551e-003,0,0,0,
1473159791.585,,-2.000000e+002,4.999596e+001,-6.899263e-004,0.000000e+000,1.148017e-002,0.000000e+000,3,9.722100e-001,1.825000e+000,,,,,,,,,,,,,,,,,,0,5.000000e+000,5.000000e-001,2,1,2.490997e-003,0,0,0,
1473159917.589,,-3.000000e+002,5.000092e+001,-7.133088e-004,0.000000e+000,1.058139e-002,0.000000e+000,3,9.685210e-001,1.825000e+000,,,,,,,,,,,,,,,,,,0,5.000000e+000,5.000000e-001,2,1,2.479553e-003,0,1,0,
1473159940.767,,-3.000000e+002,4.999905e+001,-7.139703e-004,0.000000e+000,1.137150e-002,0.000000e+000,3,9.682720e-001,1.825000e+000,,,,,,,,,,,,,,,,,,0,5.000000e+000,5.000000e-001,2,1,1.251221e-003,0,1,0,
1473160073.997,,-4.000000e+002,4.999905e+001,-7.278651e-004,0.000000e+000,1.107353e-002,0.000000e+000,3,9.626281e-001,1.825000e+000,,,,,,,,,,,,,,,,,,0,5.000000e+000,5.000000e-001,2,1,1.251221e-003,0,1,0,
1473160098.926,,-4.000000e+002,4.999905e+001,-7.282803e-004,0.000000e+000,1.099491e-002,0.000000e+000,3,9.635651e-001,1.825000e+000,,,,,,,,,,,,,,,,,,0,5.000000e+000,5.000000e-001,2,1,1.251221e-003,0,1,0,
1473160231.119,,-5.000000e+002,5.000217e+001,-7.371444e-004,0.000000e+000,1.056773e-002,0.000000e+000,3,9.601389e-001,1.825000e+000,,,,,,,,,,,,,,,,,,0,5.000000e+000,5.000000e-001,2,1,2.490997e-003,0,1,0,
1473160256.548,,-5.000000e+002,5.000217e+001,-7.377332e-004,0.000000e+000,1.040207e-002,0.000000e+000,3,9.598938e-001,1.825000e+000,,,,,,,,,,,,,,,,,,0,5.000000e+000,5.000000e-001,2,1,2.490997e-003,0,1,0,
1473160384.492,,-6.000000e+002,5.000402e+001,-7.441106e-004,0.000000e+000,9.970950e-003,0.000000e+000,3,9.570432e-001,1.825000e+000,,,,,,,,,,,,,,,,,,0,5.000000e+000,5.000000e-001,2,1,1.118088e-002,0,1,0,
1473160409.421,,-6.000000e+002,5.000030e+001,-7.450059e-004,0.000000e+000,9.989817e-003,0.000000e+000,3,9.564542e-001,1.825000e+000,,,,,,,,,,,,,,,,,,0,5.000000e+000,5.000000e-001,2,1,1.239777e-003,0,1,0,
1473160536.439,,-7.000000e+002,4.999968e+001,-7.494695e-004,0.000000e+000,9.420169e-003,0.000000e+000,3,9.541880e-001,1.825000e+000,,,,,,,,,,,,,,,,,,0,5.000000e+000,5.000000e-001,2,1,0.000000e+000,0,1,0,
1473160560.367,,-7.000000e+002,5.000030e+001,-7.498657e-004,0.000000e+000,9.420119e-003,0.000000e+000,3,9.546067e-001,1.825000e+000,,,,,,,,,,,,,,,,,,0,5.000000e+000,5.000000e-001,2,1,1.239777e-003,0,0,0,
1473160686.345,,-1.000000e+003,4.999843e+001,-7.607106e-004,0.000000e+000,8.837360e-003,0.000000e+000,3,9.493923e-001,1.825000e+000,,,,,,,,,,,,,,,,,,0,5.000000e+000,5.000000e-001,2,1,0.000000e+000,0,0,0,
1473160711.573,,-1.000000e+003,4.999843e+001,-7.607447e-004,0.000000e+000,8.898097e-003,0.000000e+000,3,9.493250e-001,1.825000e+000,,,,,,,,,,,,,,,,,,0,5.000000e+000,5.000000e-001,2,1,0.000000e+000,0,0,0,
1473160846.571,,-3.000000e+003,5.000092e+001,-7.987201e-004,0.000000e+000,7.804479e-003,0.000000e+000,3,9.375746e-001,1.825000e+000,,,,,,,,,,,,,,,,,,0,5.000000e+000,5.000000e-001,2,1,4.981995e-003,0,0,0,
1473160870.999,,-3.000000e+003,4.999719e+001,-8.032970e-004,0.000000e+000,7.605873e-003,0.000000e+000,3,9.359989e-001,1.825000e+000,,,,,,,,,,,,,,,,,,0,5.000000e+000,5.000000e-001,2,1,2.479553e-003,0,0,0,
1473161006.969,,-5.000000e+003,5.000030e+001,-8.176633e-004,0.000000e+000,6.824474e-003,0.000000e+000,3,9.380790e-001,1.825000e+000,,,,,,,,,,,,,,,,,,0,5.000000e+000,5.000000e-001,2,1,1.239777e-003,0,0,0,
1473161030.433,,-5.000000e+003,5.000154e+001,-8.181457e-004,0.000000e+000,6.697998e-003,0.000000e+000,3,9.381356e-001,1.825000e+000,,,,,,,,,,,,,,,,,,0,5.000000e+000,5.000000e-001,2,1,3.730774e-003,0,0,0,
1473161168.127,,-7.000000e+003,4.999160e+001,-8.344623e-004,0.000000e+000,7.390912e-003,0.000000e+000,3,9.377339e-001,1.825000e+000,,,,,,,,,,,,,,,,,,0,5.000000e+000,5.000000e-001,2,1,1.364899e-002,0,0,0,
1473161193.805,,-7.000000e+003,4.999719e+001,-8.339118e-004,0.000000e+000,6.736007e-003,0.000000e+000,3,9.385309e-001,1.825000e+000,,,,,,,,,,,,,,,,,,0,5.000000e+000,5.000000e-001,2,1,2.479553e-003,0,0,0,
1473161324.550,,-9.000000e+003,4.999719e+001,-8.467112e-004,0.000000e+000,6.902763e-003,0.000000e+000,3,9.388328e-001,1.825000e+000,,,,,,,,,,,,,,,,,,0,5.000000e+000,5.000000e-001,2,1,2.479553e-003,0,0,0,
1473161352.979,,-9.000000e+003,4.999657e+001,-8.466906e-004,0.000000e+000,6.993317e-003,0.000000e+000,3,9.389124e-001,1.825000e+000,,,,,,,,,,,,,,,,,,0,5.000000e+000,5.000000e-001,2,1,3.719330e-003,0,0,0,
1473161487.672,,-1.000000e+004,4.999844e+001,-8.522095e-004,0.000000e+000,7.091498e-003,0.000000e+000,3,9.390882e-001,1.825000e+000,,,,,,,,,,,,,,,,,,0,5.000000e+000,5.000000e-001,2,1,9.941101e-003,0,1,0,
1473161512.152,,-1.000000e+004,5.000030e+001,-8.523499e-004,0.000000e+000,7.216610e-003,0.000000e+000,3,9.389784e-001,1.825000e+000,,,,,,,,,,,,,,,,,,0,5.000000e+000,5.000000e-001,2,1,1.239777e-003,0,1,0,
1473161677.363,,-2.000000e+004,5.000465e+001,-8.929189e-004,0.000000e+000,7.811712e-003,0.000000e+000,3,9.407228e-001,1.825000e+000,,,,,,,,,,,,,,,,,,0,5.000000e+000,5.000000e-001,2,1,2.468109e-003,0,1,0,
1473161701.806,,-2.000000e+004,5.000589e+001,-8.940551e-004,0.000000e+000,8.063802e-003,0.000000e+000,3,9.402668e-001,1.825000e+000,,,,,,,,,,,,,,,,,,0,5.000000e+000,5.000000e-001,2,1,2.479553e-003,0,1,0,
1473161875.777,,-3.000000e+004,5.000216e+001,-9.181187e-004,0.000000e+000,8.817216e-003,0.000000e+000,3,9.442195e-001,1.825000e+000,,,,,,,,,,,,,,,,,,0,5.000000e+000,5.000000e-001,2,1,0.000000e+000,0,1,0,
1473161900.219,,-3.000000e+004,4.999905e+001,-9.173602e-004,0.000000e+000,1.043350e-002,0.000000e+000,3,9.439348e-001,1.825000e+000,,,,,,,,,,,,,,,,,,0,5.000000e+000,5.000000e-001,2,1,1.251221e-003,0,1,0,
1473162072.165,,-4.000000e+004,5.000154e+001,-9.399636e-004,0.000000e+000,6.701231e-003,0.000000e+000,3,9.414461e-001,1.825000e+000,,,,,,,,,,,,,,,,,,0,5.000000e+000,5.000000e-001,2,1,8.678436e-003,0,1,0,
1473162095.651,,-4.000000e+004,4.999905e+001,-9.378439e-004,0.000000e+000,1.067096e-002,0.000000e+000,3,9.405345e-001,1.825000e+000,,,,,,,,,,,,,,,,,,0,5.000000e+000,5.000000e-001,2,1,1.251221e-003,0,0,0,
1473162271.594,,-5.000000e+004,4.999719e+001,-9.528599e-004,0.000000e+000,1.028475e-002,0.000000e+000,3,9.425566e-001,1.825000e+000,,,,,,,,,,,,,,,,,,0,5.000000e+000,5.000000e-001,2,1,4.970551e-003,0,0,0,
1473162296.776,,-5.000000e+004,4.999160e+001,-9.535937e-004,0.000000e+000,1.013683e-002,0.000000e+000,3,9.427577e-001,1.825000e+000,,,,,,,,,,,,,,,,,,0,5.000000e+000,5.000000e-001,2,1,1.364899e-002,0,0,0,
1473162470.150,,-6.000000e+004,4.999719e+001,-9.688201e-004,0.000000e+000,1.173398e-002,0.000000e+000,3,9.411234e-001,1.825000e+000,,,,,,,,,,,,,,,,,,0,5.000000e+000,5.000000e-001,2,1,2.479553e-003,0,0,0,
1473162495.881,,-6.000000e+004,4.999844e+001,-9.655003e-004,0.000000e+000,1.059326e-002,0.000000e+000,3,9.418522e-001,1.825000e+000,,,,,,,,,,,,,,,,,,0,5.000000e+000,5.000000e-001,2,1,2.479553e-003,0,0,0,
1473162675.128,,-7.000000e+004,4.999719e+001,-9.743466e-004,0.000000e+000,1.089777e-002,0.000000e+000,3,9.416775e-001,1.825000e+000,,,,,,,,,,,,,,,,,,0,5.000000e+000,5.000000e-001,2,1,4.970551e-003,0,0,0,
1473162700.198,,-7.000000e+004,4.999347e+001,-9.743549e-004,0.000000e+000,1.104143e-002,0.000000e+000,3,9.416273e-001,1.825000e+000,,,,,,,,,,,,,,,,,,0,5.000000e+000,5.000000e-001,2,1,0.000000e+000,0,0,0,
1473162885.697,,-6.000000e+004,5.000278e+001,-9.665528e-004,0.000000e+000,1.030003e-002,0.000000e+000,3,9.412144e-001,1.825000e+000,,,,,,,,,,,,,,,,,,0,5.000000e+000,5.000000e-001,2,1,3.730774e-003,0,1,0,
1473162908.561,,-6.000000e+004,4.999781e+001,-9.639167e-004,0.000000e+000,1.063089e-002,0.000000e+000,3,9.424653e-001,1.825000e+000,,,,,,,,,,,,,,,,,,0,5.000000e+000,5.000000e-001,2,1,1.228333e-003,0,1,0,
1473163089.126,,-5.000000e+004,5.000340e+001,-9.536765e-004,0.000000e+000,8.028436e-003,0.000000e+000,3,9.426607e-001,1.825000e+000,,,,,,,,,,,,,,,,,,0,5.000000e+000,5.000000e-001,2,1,2.490997e-003,0,1,0,
1473163113.749,,-5.000000e+004,5.000651e+001,-9.541594e-004,0.000000e+000,1.014999e-002,0.000000e+000,3,9.384663e-001,1.825000e+000,,,,,,,,,,,,,,,,,,0,5.000000e+000,5.000000e-001,2,1,3.719330e-003,0,1,0,
1473163284.054,,-4.000000e+004,5.000465e+001,-9.407411e-004,0.000000e+000,1.284653e-002,0.000000e+000,3,9.420325e-001,1.825000e+000,,,,,,,,,,,,,,,,,,0,5.000000e+000,5.000000e-001,2,1,9.929657e-003,0,1,0,
1473163308.784,,-4.000000e+004,4.999906e+001,-9.417448e-004,0.000000e+000,7.682772e-003,0.000000e+000,3,9.391016e-001,1.825000e+000,,,,,,,,,,,,,,,,,,0,5.000000e+000,5.000000e-001,2,1,3.719330e-003,0,1,0,
1473163485.750,,-3.000000e+004,4.992227e+001,-9.193912e-004,0.000000e+000,7.176031e-003,0.000000e+000,3,9.414755e-001,1.825000e+000,,,,,,,,,,,,,,,,,,0,5.000000e+000,5.000000e-001,2,1,1.548195e-001,0,1,0,
1473163510.692,,-3.000000e+004,5.000837e+001,-9.212115e-004,0.000000e+000,8.548564e-003,0.000000e+000,3,9.376767e-001,1.825000e+000,,,,,,,,,,,,,,,,,,0,5.000000e+000,5.000000e-001,2,1,1.988220e-002,0,0,0,
1473163688.636,,-2.000000e+004,4.999968e+001,-8.936780e-004,0.000000e+000,6.422119e-003,0.000000e+000,3,9.416581e-001,1.825000e+000,,,,,,,,,,,,,,,,,,0,5.000000e+000,5.000000e-001,2,1,7.461548e-003,0,0,0,
1473163712.314,,-2.000000e+004,4.999781e+001,-8.944054e-004,0.000000e+000,7.085371e-003,0.000000e+000,3,9.397550e-001,1.825000e+000,,,,,,,,,,,,,,,,,,0,5.000000e+000,5.000000e-001,2,1,6.210327e-003,0,0,0,
1473163884.523,,-1.000000e+004,5.000092e+001,-8.529504e-004,0.000000e+000,6.634857e-003,0.000000e+000,3,9.387108e-001,1.825000e+000,,,,,,,,,,,,,,,,,,0,5.000000e+000,5.000000e-001,2,1,4.981995e-003,0,0,0,
1473163910.202,,-1.000000e+004,4.999905e+001,-8.538891e-004,0.000000e+000,6.696261e-003,0.000000e+000,3,9.388918e-001,1.825000e+000,,,,,,,,,,,,,,,,,,0,5.000000e+000,5.000000e-001,2,1,1.251221e-003,0,0,0,
1473164043.891,,-9.000000e+003,5.000465e+001,-8.467582e-004,0.000000e+000,6.028984e-003,0.000000e+000,3,9.391215e-001,1.825000e+000,,,,,,,,,,,,,,,,,,0,5.000000e+000,5.000000e-001,2,1,1.243210e-002,0,0,0,
1473164069.252,,-9.000000e+003,4.999719e+001,-8.466992e-004,0.000000e+000,6.031225e-003,0.000000e+000,3,9.390718e-001,1.825000e+000,,,,,,,,,,,,,,,,,,0,5.000000e+000,5.000000e-001,2,1,2.479553e-003,0,0,0,
1473164200.064,,-7.000000e+003,5.000030e+001,-8.338789e-004,0.000000e+000,6.685764e-003,0.000000e+000,3,9.382780e-001,1.825000e+000,,,,,,,,,,,,,,,,,,0,5.000000e+000,5.000000e-001,2,1,1.366043e-002,0,0,0,
1473164224.742,,-7.000000e+003,4.999906e+001,-8.335903e-004,0.000000e+000,6.225220e-003,0.000000e+000,3,9.382926e-001,1.825000e+000,,,,,,,,,,,,,,,,,,0,5.000000e+000,5.000000e-001,2,1,3.719330e-003,0,0,0,
1473164359.932,,-5.000000e+003,4.999843e+001,-8.174668e-004,0.000000e+000,6.611759e-003,0.000000e+000,3,9.386796e-001,1.825000e+000,,,,,,,,,,,,,,,,,,0,5.000000e+000,5.000000e-001,2,1,0.000000e+000,0,1,0,
1473164385.364,,-5.000000e+003,5.000030e+001,-8.177921e-004,0.000000e+000,6.181142e-003,0.000000e+000,3,9.384643e-001,1.825000e+000,,,,,,,,,,,,,,,,,,0,5.000000e+000,5.000000e-001,2,1,1.239777e-003,0,1,0,
1473164514.053,,-3.000000e+003,4.999905e+001,-7.972402e-004,0.000000e+000,6.519137e-003,0.000000e+000,3,9.392313e-001,1.825000e+000,,,,,,,,,,,,,,,,,,0,5.000000e+000,5.000000e-001,2,1,1.251221e-003,0,1,0,
1473164538.732,,-3.000000e+003,5.000527e+001,-7.976788e-004,0.000000e+000,6.246712e-003,0.000000e+000,3,9.391384e-001,1.825000e+000,,,,,,,,,,,,,,,,,,0,5.000000e+000,5.000000e-001,2,1,1.118088e-002,0,1,0,
1473164672.193,,-1.000000e+003,5.000092e+001,-7.592710e-004,0.000000e+000,8.591942e-003,0.000000e+000,3,9.490662e-001,1.825000e+000,,,,,,,,,,,,,,,,,,0,5.000000e+000,5.000000e-001,2,1,9.929657e-003,0,1,0,
1473164695.559,,-1.000000e+003,5.000589e+001,-7.598172e-004,0.000000e+000,8.582791e-003,0.000000e+000,3,9.496475e-001,1.825000e+000,,,,,,,,,,,,,,,,,,0,5.000000e+000,5.000000e-001,2,1,2.479553e-003,0,1,0,
1473164837.107,,-7.000000e+002,5.000092e+001,-7.476464e-004,0.000000e+000,9.227399e-003,0.000000e+000,3,9.539282e-001,1.825000e+000,,,,,,,,,,,,,,,,,,0,5.000000e+000,5.000000e-001,2,1,0.000000e+000,0,1,0,
1473164862.285,,-7.000000e+002,5.000030e+001,-7.479627e-004,0.000000e+000,9.437403e-003,0.000000e+000,3,9.543225e-001,1.825000e+000,,,,,,,,,,,,,,,,,,0,5.000000e+000,5.000000e-001,2,1,1.239777e-003,0,1,0,
1473164995.027,,-6.000000e+002,5.000031e+001,-7.428299e-004,0.000000e+000,9.538041e-003,0.000000e+000,3,9.566541e-001,1.825000e+000,,,,,,,,,,,,,,,,,,0,5.000000e+000,5.000000e-001,2,1,6.210327e-003,0,1,0,
1473165019.481,,-6.000000e+002,5.000402e+001,-7.415276e-004,0.000000e+000,1.035482e-002,0.000000e+000,3,9.556785e-001,1.825000e+000,,,,,,,,,,,,,,,,,,0,5.000000e+000,5.000000e-001,2,1,6.210327e-003,0,0,0,
1473165151.170,,-5.000000e+002,4.999905e+001,-7.348131e-004,0.000000e+000,1.065704e-002,0.000000e+000,3,9.584691e-001,1.825000e+000,,,,,,,,,,,,,,,,,,0,5.000000e+000,5.000000e-001,2,1,1.251221e-003,0,0,0,
1473165176.600,,-5.000000e+002,5.000340e+001,-7.341144e-004,0.000000e+000,1.011479e-002,0.000000e+000,3,9.602035e-001,1.825000e+000,,,,,,,,,,,,,,,,,,0,5.000000e+000,5.000000e-001,2,1,1.491165e-002,0,0,0,
1473165311.793,,-4.000000e+002,4.999906e+001,-7.275864e-004,0.000000e+000,1.082211e-002,0.000000e+000,3,9.617148e-001,1.825000e+000,,,,,,,,,,,,,,,,,,0,5.000000e+000,5.000000e-001,2,1,3.719330e-003,0,0,0,
1473165337.494,,-4.000000e+002,4.999905e+001,-7.249588e-004,0.000000e+000,1.100927e-002,0.000000e+000,3,9.631652e-001,1.825000e+000,,,,,,,,,,,,,,,,,,0,5.000000e+000,5.000000e-001,2,1,1.251221e-003,0,0,0,
1473165465.933,,-3.000000e+002,5.000217e+001,-7.114671e-004,0.000000e+000,1.197814e-002,0.000000e+000,3,9.665292e-001,1.825000e+000,,,,,,,,,,,,,,,,,,0,5.000000e+000,5.000000e-001,2,1,4.970551e-003,0,0,0,
1473165491.361,,-3.000000e+002,5.000215e+001,-7.104842e-004,0.000000e+000,1.135541e-002,0.000000e+000,3,9.680919e-001,1.825000e+000,,,,,,,,,,,,,,,,,,0,5.000000e+000,5.000000e-001,2,1,7.450104e-003,0,0,0,
1473165618.304,,-2.000000e+002,4.999284e+001,-6.865091e-004,0.000000e+000,1.075154e-002,0.000000e+000,3,9.724097e-001,1.825000e+000,,,,,,,,,,,,,,,,,,0,5.000000e+000,5.000000e-001,2,1,1.116943e-002,0,0,0,
1473165643.982,,-2.000000e+002,4.999596e+001,-6.857863e-004,0.000000e+000,1.100271e-002,0.000000e+000,3,9.729115e-001,1.825000e+000,,,,,,,,,,,,,,,,,,0,5.000000e+000,5.000000e-001,2,1,2.490997e-003,0,0,0,
1473165765.184,,-1.800000e+002,4.999720e+001,-6.784828e-004,0.000000e+000,1.080434e-002,0.000000e+000,3,9.743183e-001,1.825000e+000,,,,,,,,,,,,,,,,,,0,5.000000e+000,5.000000e-001,2,1,0.000000e+000,0,0,0,
1473165790.666,,-1.800000e+002,4.999781e+001,-6.774986e-004,0.000000e+000,1.162864e-002,0.000000e+000,3,9.733599e-001,1.825000e+000,,,,,,,,,,,,,,,,,,0,5.000000e+000,5.000000e-001,2,1,1.228333e-003,0,0,0,
1473165908.876,,-1.600000e+002,4.999657e+001,-6.696011e-004,0.000000e+000,1.163081e-002,0.000000e+000,3,9.743136e-001,1.825000e+000,,,,,,,,,,,,,,,,,,0,5.000000e+000,5.000000e-001,2,1,1.251221e-003,0,1,0,
1473165933.056,,-1.600000e+002,5.000154e+001,-6.696222e-004,0.000000e+000,1.161976e-002,0.000000e+000,3,9.748333e-001,1.825000e+000,,,,,,,,,,,,,,,,,,0,5.000000e+000,5.000000e-001,2,1,3.730774e-003,0,1,0,
1473166055.015,,-1.400000e+002,5.000031e+001,-6.591656e-004,0.000000e+000,1.216256e-002,0.000000e+000,3,9.753438e-001,1.825000e+000,,,,,,,,,,,,,,,,,,0,5.000000e+000,5.000000e-001,2,1,6.210327e-003,0,1,0,
1473166080.126,,-1.400000e+002,4.999780e+001,-6.593633e-004,0.000000e+000,1.170553e-002,0.000000e+000,3,9.756511e-001,1.825000e+000,,,,,,,,,,,,,,,,,,0,5.000000e+000,5.000000e-001,2,1,1.614761e-002,0,1,0,
1473166200.176,,-1.200000e+002,5.000278e+001,-6.471546e-004,0.000000e+000,1.249383e-002,0.000000e+000,3,9.763739e-001,1.825000e+000,,,,,,,,,,,,,,,,,,0,5.000000e+000,5.000000e-001,2,1,6.198883e-003,0,1,0,
1473166224.642,,-1.200000e+002,4.999905e+001,-6.476308e-004,0.000000e+000,1.212064e-002,0.000000e+000,3,9.761847e-001,1.825000e+000,,,,,,,,,,,,,,,,,,0,5.000000e+000,5.000000e-001,2,1,6.210327e-003,0,1,0,
1473166349.361,,-1.000000e+002,5.000340e+001,-6.335375e-004,0.000000e+000,1.251919e-002,0.000000e+000,3,9.774160e-001,1.825000e+000,,,,,,,,,,,,,,,,,,0,5.000000e+000,5.000000e-001,2,1,1.491165e-002,0,1,0,
1473166374.326,,-1.000000e+002,4.999967e+001,-6.335356e-004,0.000000e+000,1.229560e-002,0.000000e+000,3,9.775721e-001,1.825000e+000,,,,,,,,,,,,,,,,,,0,5.000000e+000,5.000000e-001,2,1,2.490997e-003,0,1,0,
1473166496.084,,-8.000000e+001,5.000402e+001,-6.168235e-004,0.000000e+000,1.213084e-002,0.000000e+000,3,9.786369e-001,1.825000e+000,,,,,,,,,,,,,,,,,,0,5.000000e+000,5.000000e-001,2,1,1.118088e-002,0,1,0,
1473166521.303,,-8.000000e+001,4.999906e+001,-6.101193e-004,0.000000e+000,9.661984e-003,0.000000e+000,3,9.703057e-001,1.825000e+000,,,,,,,,,,,,,,,,,,0,5.000000e+000,5.000000e-001,2,1,3.719330e-003,0,1,0,
1473166641.491,,-6.000000e+001,4.999967e+001,-5.956284e-004,0.000000e+000,1.163470e-002,0.000000e+000,3,9.800065e-001,1.825000e+000,,,,,,,,,,,,,,,,,,0,5.000000e+000,5.000000e-001,2,1,2.490997e-003,0,0,0,
1473166666.977,,-6.000000e+001,4.999471e+001,-5.947446e-004,0.000000e+000,1.292990e-002,0.000000e+000,3,9.797151e-001,1.825000e+000,,,,,,,,,,,,,,,,,,0,5.000000e+000,5.000000e-001,2,1,2.479553e-003,0,0,0,
1473166788.452,,-4.000000e+001,5.000340e+001,-5.655676e-004,0.000000e+000,1.177764e-002,0.000000e+000,3,9.779699e-001,1.825000e+000,,,,,,,,,,,,,,,,,,0,5.000000e+000,5.000000e-001,2,1,2.490997e-003,0,0,0,
1473166814.387,,-4.000000e+001,5.000465e+001,-5.662962e-004,0.000000e+000,1.284674e-002,0.000000e+000,3,9.810749e-001,1.825000e+000,,,,,,,,,,,,,,,,,,0,5.000000e+000,5.000000e-001,2,1,9.929657e-003,0,0,0,
1473166934.959,,-2.000000e+001,4.999906e+001,-5.266601e-004,0.000000e+000,1.325453e-002,0.000000e+000,3,9.812168e-001,1.825000e+000,,,,,,,,,,,,,,,,,,0,5.000000e+000,5.000000e-001,2,1,8.701324e-003,0,0,0,
1473166957.893,,-2.000000e+001,4.999906e+001,-5.261415e-004,0.000000e+000,1.321377e-002,0.000000e+000,3,9.822204e-001,1.825000e+000,,,,,,,,,,,,,,,,,,0,5.000000e+000,5.000000e-001,2,1,3.719330e-003,0,0,0,
1473167072.884,,0.000000e+000,4.999844e+001,-4.597675e-004,0.000000e+000,1.361290e-002,0.000000e+000,3,9.841218e-001,1.825000e+000,,,,,,,,,,,,,,,,,,0,5.000000e+000,5.000000e-001,2,1,4.970551e-003,0,0,0,
1473167097.589,,0.000000e+000,5.000030e+001,-4.594644e-004,0.000000e+000,1.259315e-002,0.000000e+000,3,9.843478e-001,1.825000e+000,,,,,,,,,,,,,,,,,,0,5.000000e+000,5.000000e-001,2,1,1.239777e-003,0,0,0,
1473167223.527,,2.000000e+001,5.000092e+001,-1.519556e-004,0.000000e+000,1.680206e-002,0.000000e+000,3,9.792936e-001,1.825000e+000,,,,,,,,,,,,,,,,,,0,5.000000e+000,5.000000e-001,2,1,9.929657e-003,0,0,0,
1473167260.475,,2.000000e+001,4.999905e+001,-1.288447e-004,0.000000e+000,1.604714e-002,0.000000e+000,3,9.844315e-001,1.825000e+000,,,,,,,,,,,,,,,,,,0,5.000000e+000,5.000000e-001,2,1,1.251221e-003,0,0,0,
1473167392.928,,4.000000e+001,5.000154e+001,5.100538e-004,0.000000e+000,1.235404e-002,0.000000e+000,3,9.809229e-001,1.825000e+000,,,,,,,,,,,,,,,,,,0,5.000000e+000,5.000000e-001,2,1,1.239777e-003,0,0,0,
1473167418.107,,4.000000e+001,4.999844e+001,5.117541e-004,0.000000e+000,1.287514e-002,0.000000e+000,3,9.810492e-001,1.825000e+000,,,,,,,,,,,,,,,,,,0,5.000000e+000,5.000000e-001,2,1,2.479553e-003,0,1,0,
1473167536.602,,6.000000e+001,5.000154e+001,5.771325e-004,0.000000e+000,1.335493e-002,0.000000e+000,3,9.787263e-001,1.825000e+000,,,,,,,,,,,,,,,,,,0,5.000000e+000,5.000000e-001,2,1,3.730774e-003,0,1,0,
1473167560.830,,6.000000e+001,5.000402e+001,5.784279e-004,0.000000e+000,1.226280e-002,0.000000e+000,3,9.803953e-001,1.825000e+000,,,,,,,,,,,,,,,,,,0,5.000000e+000,5.000000e-001,2,1,3.719330e-003,0,1,0,
1473167680.051,,8.000000e+001,5.000526e+001,6.120956e-004,0.000000e+000,1.292900e-002,0.000000e+000,3,9.783782e-001,1.825000e+000,,,,,,,,,,,,,,,,,,0,5.000000e+000,5.000000e-001,2,1,6.210327e-003,0,1,0,
1473167707.166,,8.000000e+001,5.000402e+001,6.121623e-004,0.000000e+000,1.287943e-002,0.000000e+000,3,9.786465e-001,1.825000e+000,,,,,,,,,,,,,,,,,,0,5.000000e+000,5.000000e-001,2,1,3.719330e-003,0,1,0,
1473167824.799,,1.000000e+002,5.000030e+001,6.342340e-004,0.000000e+000,1.253890e-002,0.000000e+000,3,9.779810e-001,1.825000e+000,,,,,,,,,,,,,,,,,,0,5.000000e+000,5.000000e-001,2,1,1.239777e-003,0,1,0,
1473167849.228,,1.000000e+002,5.000527e+001,6.344813e-004,0.000000e+000,1.219391e-002,0.000000e+000,3,9.777703e-001,1.825000e+000,,,,,,,,,,,,,,,,,,0,5.000000e+000,5.000000e-001,2,1,3.719330e-003,0,1,0,
1473167969.735,,1.200000e+002,5.000278e+001,6.504480e-004,0.000000e+000,1.218246e-002,0.000000e+000,3,9.764484e-001,1.825000e+000,,,,,,,,,,,,,,,,,,0,5.000000e+000,5.000000e-001,2,1,3.730774e-003,0,1,0,
1473167993.167,,1.200000e+002,4.999968e+001,6.507970e-004,0.000000e+000,1.233348e-002,0.000000e+000,3,9.764544e-001,1.825000e+000,,,,,,,,,,,,,,,,,,0,5.000000e+000,5.000000e-001,2,1,0.000000e+000,0,1,0,
1473168113.625,,1.400000e+002,4.999533e+001,6.628638e-004,0.000000e+000,1.277239e-002,0.000000e+000,3,9.750596e-001,1.825000e+000,,,,,,,,,,,,,,,,,,0,5.000000e+000,5.000000e-001,2,1,3.730774e-003,0,0,0,
1473168139.097,,1.400000e+002,5.000030e+001,6.634642e-004,0.000000e+000,1.237111e-002,0.000000e+000,3,9.754735e-001,1.825000e+000,,,,,,,,,,,,,,,,,,0,5.000000e+000,5.000000e-001,2,1,1.239777e-003,0,0,0,
1473168263.285,,1.600000e+002,4.999967e+001,6.727928e-004,0.000000e+000,1.298314e-002,0.000000e+000,3,9.737545e-001,1.825000e+000,,,,,,,,,,,,,,,,,,0,5.000000e+000,5.000000e-001,2,1,2.490997e-003,0,0,0,
1473168286.529,,1.600000e+002,5.000340e+001,6.740295e-004,0.000000e+000,1.154768e-002,0.000000e+000,3,9.741902e-001,1.825000e+000,,,,,,,,,,,,,,,,,,0,5.000000e+000,5.000000e-001,2,1,7.450104e-003,0,0,0,
1473168410.717,,1.800000e+002,5.000217e+001,6.820609e-004,0.000000e+000,1.231316e-002,0.000000e+000,3,9.731404e-001,1.825000e+000,,,,,,,,,,,,,,,,,,0,5.000000e+000,5.000000e-001,2,1,2.490997e-003,0,0,0,
1473168437.146,,1.800000e+002,5.000278e+001,6.829163e-004,0.000000e+000,1.142807e-002,0.000000e+000,3,9.736043e-001,1.825000e+000,,,,,,,,,,,,,,,,,,0,5.000000e+000,5.000000e-001,2,1,6.198883e-003,0,0,0,
1473168560.584,,2.000000e+002,4.999782e+001,6.894670e-004,0.000000e+000,1.197538e-002,0.000000e+000,3,9.724727e-001,1.825000e+000,,,,,,,,,,,,,,,,,,0,5.000000e+000,5.000000e-001,2,1,1.366043e-002,0,0,0,
1473168586.018,,2.000000e+002,4.999657e+001,6.895121e-004,0.000000e+000,1.193234e-002,0.000000e+000,3,9.725053e-001,1.825000e+000,,,,,,,,,,,,,,,,,,0,5.000000e+000,5.000000e-001,2,1,3.719330e-003,0,0,0,
1473168721.457,,3.000000e+002,5.000031e+001,7.137702e-004,0.000000e+000,1.177241e-002,0.000000e+000,3,9.668311e-001,1.825000e+000,,,,,,,,,,,,,,,,,,0,5.000000e+000,5.000000e-001,2,1,6.210327e-003,0,0,0,
1473168749.136,,3.000000e+002,4.999781e+001,7.144870e-004,0.000000e+000,1.137271e-002,0.000000e+000,3,9.679954e-001,1.825000e+000,,,,,,,,,,,,,,,,,,0,5.000000e+000,5.000000e-001,2,1,6.210327e-003,0,0,0,
1473168875.875,,4.000000e+002,4.999968e+001,7.281372e-004,0.000000e+000,1.088502e-002,0.000000e+000,3,9.640659e-001,1.825000e+000,,,,,,,,,,,,,,,,,,0,5.000000e+000,5.000000e-001,2,1,7.461548e-003,0,0,0,
1473168900.603,,4.000000e+002,5.000030e+001,7.278945e-004,0.000000e+000,1.131966e-002,0.000000e+000,3,9.630868e-001,1.825000e+000,,,,,,,,,,,,,,,,,,0,5.000000e+000,5.000000e-001,2,1,1.239777e-003,0,0,0,
1473169029.842,,5.000000e+002,5.000092e+001,7.380575e-004,0.000000e+000,1.031454e-002,0.000000e+000,3,9.601291e-001,1.825000e+000,,,,,,,,,,,,,,,,,,0,5.000000e+000,5.000000e-001,2,1,0.000000e+000,0,1,0,
1473169053.276,,5.000000e+002,4.999967e+001,7.376506e-004,0.000000e+000,1.069302e-002,0.000000e+000,3,9.598730e-001,1.825000e+000,,,,,,,,,,,,,,,,,,0,5.000000e+000,5.000000e-001,2,1,2.490997e-003,0,1,0,
1473169179.276,,6.000000e+002,4.999967e+001,7.444124e-004,0.000000e+000,1.009163e-002,0.000000e+000,3,9.572712e-001,1.825000e+000,,,,,,,,,,,,,,,,,,0,5.000000e+000,5.000000e-001,2,1,2.490997e-003,0,1,0,
1473169203.221,,6.000000e+002,5.000278e+001,7.448327e-004,0.000000e+000,1.046805e-002,0.000000e+000,3,9.563436e-001,1.825000e+000,,,,,,,,,,,,,,,,,,0,5.000000e+000,5.000000e-001,2,1,3.730774e-003,0,1,0,
1473169336.911,,7.000000e+002,5.000092e+001,7.503001e-004,0.000000e+000,1.073330e-002,0.000000e+000,3,9.535972e-001,1.825000e+000,,,,,,,,,,,,,,,,,,0,5.000000e+000,5.000000e-001,2,1,2.479553e-003,0,1,0,
1473169361.131,,7.000000e+002,5.000217e+001,7.498225e-004,0.000000e+000,1.004968e-002,0.000000e+000,3,9.542395e-001,1.825000e+000,,,,,,,,,,,,,,,,,,0,5.000000e+000,5.000000e-001,2,1,4.970551e-003,0,1,0,
1473169488.824,,1.000000e+003,5.000215e+001,7.608504e-004,0.000000e+000,9.095810e-003,0.000000e+000,3,9.493012e-001,1.825000e+000,,,,,,,,,,,,,,,,,,0,5.000000e+000,5.000000e-001,2,1,7.450104e-003,0,1,0,
1473169511.502,,1.000000e+003,4.999781e+001,7.608134e-004,0.000000e+000,9.178382e-003,0.000000e+000,3,9.495315e-001,1.825000e+000,,,,,,,,,,,,,,,,,,0,5.000000e+000,5.000000e-001,2,1,1.228333e-003,0,1,0,
1473169662.315,,3.000000e+003,5.000278e+001,7.963675e-004,0.000000e+000,7.042344e-003,0.000000e+000,3,9.400817e-001,1.825000e+000,,,,,,,,,,,,,,,,,,0,5.000000e+000,5.000000e-001,2,1,1.251221e-003,0,1,0,
1473169688.244,,3.000000e+003,5.000030e+001,7.965504e-004,0.000000e+000,7.439092e-003,0.000000e+000,3,9.391591e-001,1.825000e+000,,,,,,,,,,,,,,,,,,0,5.000000e+000,5.000000e-001,2,1,1.239777e-003,0,0,0,
1473169821.874,,5.000000e+003,4.999843e+001,8.180637e-004,0.000000e+000,6.662107e-003,0.000000e+000,3,9.377896e-001,1.825000e+000,,,,,,,,,,,,,,,,,,0,5.000000e+000,5.000000e-001,2,1,0.000000e+000,0,0,0,
1473169847.161,,5.000000e+003,4.999905e+001,8.181356e-004,0.000000e+000,7.155323e-003,0.000000e+000,3,9.381137e-001,1.825000e+000,,,,,,,,,,,,,,,,,,0,5.000000e+000,5.000000e-001,2,1,1.251221e-003,0,0,0,
1473169989.389,,7.000000e+003,4.999347e+001,8.328512e-004,0.000000e+000,6.829694e-003,0.000000e+000,3,9.383358e-001,1.825000e+000,,,,,,,,,,,,,,,,,,0,5.000000e+000,5.000000e-001,2,1,4.959106e-003,0,0,0,
1473170012.127,,7.000000e+003,4.999223e+001,8.330438e-004,0.000000e+000,6.642202e-003,0.000000e+000,3,9.385156e-001,1.825000e+000,,,,,,,,,,,,,,,,,,0,5.000000e+000,5.000000e-001,2,1,1.490021e-002,0,0,0,
1473170148.629,,9.000000e+003,4.999720e+001,8.467837e-004,0.000000e+000,7.353589e-003,0.000000e+000,3,9.388445e-001,1.825000e+000,,,,,,,,,,,,,,,,,,0,5.000000e+000,5.000000e-001,2,1,0.000000e+000,0,0,0,
1473170173.114,,9.000000e+003,4.999844e+001,8.466548e-004,0.000000e+000,7.346962e-003,0.000000e+000,3,9.389217e-001,1.825000e+000,,,,,,,,,,,,,,,,,,0,5.000000e+000,5.000000e-001,2,1,4.970551e-003,0,0,0,
1473170305.053,,1.000000e+004,4.999596e+001,8.522980e-004,0.000000e+000,7.366077e-003,0.000000e+000,3,9.391350e-001,1.825000e+000,,,,,,,,,,,,,,,,,,0,5.000000e+000,5.000000e-001,2,1,2.490997e-003,0,0,0,
1473170329.732,,1.000000e+004,4.999596e+001,8.523173e-004,0.000000e+000,7.314256e-003,0.000000e+000,3,9.391576e-001,1.825000e+000,,,,,,,,,,,,,,,,,,0,5.000000e+000,5.000000e-001,2,1,2.490997e-003,0,0,0,
1473170499.973,,2.000000e+004,4.999844e+001,8.933039e-004,0.000000e+000,8.399894e-003,0.000000e+000,3,9.394637e-001,1.825000e+000,,,,,,,,,,,,,,,,,,0,5.000000e+000,5.000000e-001,2,1,2.479553e-003,0,1,0,
1473170523.668,,2.000000e+004,4.999906e+001,8.932707e-004,0.000000e+000,8.508968e-003,0.000000e+000,3,9.404291e-001,1.825000e+000,,,,,,,,,,,,,,,,,,0,5.000000e+000,5.000000e-001,2,1,3.719330e-003,0,1,0,
1473170696.866,,3.000000e+004,5.000215e+001,9.205376e-004,0.000000e+000,9.006356e-003,0.000000e+000,3,9.409100e-001,1.825000e+000,,,,,,,,,,,,,,,,,,0,5.000000e+000,5.000000e-001,2,1,7.450104e-003,0,1,0,
1473170720.528,,3.000000e+004,4.999967e+001,9.194857e-004,0.000000e+000,9.038067e-003,0.000000e+000,3,9.412364e-001,1.825000e+000,,,,,,,,,,,,,,,,,,0,5.000000e+000,5.000000e-001,2,1,2.490997e-003,0,1,0,
1473170889.138,,4.000000e+004,5.000465e+001,9.422822e-004,0.000000e+000,9.676948e-003,0.000000e+000,3,9.428526e-001,1.825000e+000,,,,,,,,,,,,,,,,,,0,5.000000e+000,5.000000e-001,2,1,4.970551e-003,0,1,0,
1473170914.380,,4.000000e+004,5.000340e+001,9.400127e-004,0.000000e+000,9.159114e-003,0.000000e+000,3,9.418474e-001,1.825000e+000,,,,,,,,,,,,,,,,,,0,5.000000e+000,5.000000e-001,2,1,2.490997e-003,0,1,0,
1473171093.622,,5.000000e+004,5.000278e+001,9.528531e-004,0.000000e+000,9.995192e-003,0.000000e+000,3,9.428483e-001,1.825000e+000,,,,,,,,,,,,,,,,,,0,5.000000e+000,5.000000e-001,2,1,1.251221e-003,0,1,0,
1473171117.611,,5.000000e+004,5.000030e+001,9.448951e-004,0.000000e+000,1.198245e-002,0.000000e+000,3,9.412522e-001,1.825000e+000,,,,,,,,,,,,,,,,,,0,5.000000e+000,5.000000e-001,2,1,1.239777e-003,0,1,0,
1473171299.600,,6.000000e+004,4.999968e+001,9.631973e-004,0.000000e+000,9.545317e-003,0.000000e+000,3,9.456015e-001,1.825000e+000,,,,,,,,,,,,,,,,,,0,5.000000e+000,5.000000e-001,2,1,0.000000e+000,0,0,0,
1473171324.549,,6.000000e+004,4.999906e+001,9.671568e-004,0.000000e+000,1.401780e-002,0.000000e+000,3,9.396742e-001,1.825000e+000,,,,,,,,,,,,,,,,,,0,5.000000e+000,5.000000e-001,2,1,3.719330e-003,0,0,0,
1473171510.994,,7.000000e+004,4.999408e+001,9.745334e-004,0.000000e+000,1.102124e-002,0.000000e+000,3,9.394891e-001,1.825000e+000,,,,,,,,,,,,,,,,,,0,5.000000e+000,5.000000e-001,2,1,8.697510e-003,0,0,0,
1473171535.436,,7.000000e+004,4.999905e+001,9.730195e-004,0.000000e+000,1.171480e-002,0.000000e+000,3,9.420187e-001,1.825000e+000,,,,,,,,,,,,,,,,,,0,5.000000e+000,5.000000e-001,2,1,1.251221e-003,0,0,0,
1473171548.151,,7.000000e+004,4.999844e+001,9.754385e-004,0.000000e+000,1.163894e-002,0.000000e+000,3,9.418260e-001,1.825000e+000,,,,,,,,,,,,,,,,,,0,5.000000e+000,5.000000e-001,2,1,4.970551e-003,0,0,0,