File: data/A344/A344_GdN_MH_005K_160905.rso.dat
[Header]
TITLE,MPMS RSO Measurement
BYAPP,MPMS Measurement,1.1,Summary
FILEOPENTIME, 1473065094.120000 9/5/2016, 8:44:54 PM

INFO, APPNAME, MPMS MultiVu Application, Revision 1.61,  Build 082

INFO, NAME, A344
INFO, WEIGHT, 10.500
INFO, AREA, 1.000
INFO, LENGTH, 1.000
INFO, SHAPE, 0
INFO, COMMENT, m = 0.0105g
INFO, SEQUENCE FILE: 7T_hysteresis_sweep_hi_res_zero_n4.seq


INFO, BACKGROUND DATA FILE:, None


STARTUPAXIS,X,4,LINEAR,AUTO,0.000000,0.000000
STARTUPAXIS,Y1,5,LINEAR,AUTO,0.000000,0.000000


STARTUPGROUP,Longitudinal
FIELDGROUP,Longitudinal,1,2,3,4,5,6,7,8,9,10,11,19,20,21,22,23,35
FIELDGROUP,Transverse,1,2,3,4,12,13,14,15,16,17,18,24,25,26,27,28,35

PLOT_APPEARANCE,ALL,HORZ_GRID_ON,VERT_GRID_ON,MARKERS_AND_LINES

[Data]
Time,Comment,Field (Oe),Temperature (K),Long Moment (emu),Long Scan Std Dev,Long Offset (cm),Long Offset Std Dev,Long Algorithm,Long Reg Fit,Long Reg Factor,Trans Moment (emu),Trans Scan Std Dev,Trans Offset (cm),Trans Offset Std Dev,Trans Algorithm,Trans Reg Fit,Trans Reg Factor,Long Moment [w/o ABS] (emu),Long Scan Std Dev [w/o ABS],Long Offset [w/o ABS] (cm),Long Offset Std Dev [w/o ABS],Long Reg Fit [w/o ABS],Trans Moment [w/o ABS] (emu),Trans Scan Std Dev [w/o ABS],Trans Offset [w/o ABS] (cm),Trans Offset Std Dev [w/o ABS],Trans Reg Fit [w/o ABS],RSO Position (deg),Amplitude (cm),Frequency,Cycles to Average,Scans per Measurement,Delta Temp (K),Error,EC Comp. Running,Using ABS,
1473065094.120,,7.000000e+004,4.945290e+000,1.321030e-003,0.000000e+000,4.841945e-003,0.000000e+000,3,9.538912e-001,1.825000e+000,,,,,,,,,,,,,,,,,,0,5.000000e+000,5.000000e-001,2,1,7.112980e-003,0,1,0,
1473065118.480,,7.000000e+004,4.949570e+000,1.319913e-003,0.000000e+000,5.331455e-003,0.000000e+000,3,9.547251e-001,1.825000e+000,,,,,,,,,,,,,,,,,,0,5.000000e+000,5.000000e-001,2,1,1.207829e-003,0,1,0,
1473065301.297,,6.000000e+004,4.942216e+000,1.331937e-003,0.000000e+000,3.909627e-003,0.000000e+000,3,9.555019e-001,1.825000e+000,,,,,,,,,,,,,,,,,,0,5.000000e+000,5.000000e-001,2,1,4.333973e-003,0,1,0,
1473065324.729,,6.000000e+004,4.947277e+000,1.331249e-003,0.000000e+000,5.791531e-003,0.000000e+000,3,9.551502e-001,1.825000e+000,,,,,,,,,,,,,,,,,,0,5.000000e+000,5.000000e-001,2,1,2.897263e-003,0,0,0,
1473065507.698,,5.000000e+004,4.943783e+000,1.334511e-003,0.000000e+000,2.708847e-003,0.000000e+000,3,9.553457e-001,1.825000e+000,,,,,,,,,,,,,,,,,,0,5.000000e+000,5.000000e-001,2,1,6.745815e-003,0,0,0,
1473065532.877,,5.000000e+004,4.948121e+000,1.334704e-003,0.000000e+000,2.943033e-003,0.000000e+000,3,9.552429e-001,1.825000e+000,,,,,,,,,,,,,,,,,,0,5.000000e+000,5.000000e-001,2,1,0.000000e+000,0,0,0,
1473065704.074,,4.000000e+004,4.942097e+000,1.336071e-003,0.000000e+000,1.974247e-003,0.000000e+000,3,9.555056e-001,1.825000e+000,,,,,,,,,,,,,,,,,,0,5.000000e+000,5.000000e-001,2,1,6.018162e-003,0,1,0,
1473065728.559,,4.000000e+004,4.946673e+000,1.335918e-003,0.000000e+000,1.835570e-003,0.000000e+000,3,9.558074e-001,1.825000e+000,,,,,,,,,,,,,,,,,,0,5.000000e+000,5.000000e-001,2,1,4.830360e-004,0,1,0,
1473065904.764,,3.000000e+004,4.941555e+000,1.331073e-003,0.000000e+000,1.587062e-003,0.000000e+000,3,9.561018e-001,1.825000e+000,,,,,,,,,,,,,,,,,,0,5.000000e+000,5.000000e-001,2,1,5.895615e-003,0,0,0,
1473065929.495,,3.000000e+004,4.945167e+000,1.331500e-003,0.000000e+000,1.462129e-003,0.000000e+000,3,9.563423e-001,1.825000e+000,,,,,,,,,,,,,,,,,,0,5.000000e+000,5.000000e-001,2,1,1.807213e-003,0,0,0,
1473066103.188,,2.000000e+004,4.939569e+000,1.320770e-003,0.000000e+000,6.286294e-004,0.000000e+000,3,9.564005e-001,1.825000e+000,,,,,,,,,,,,,,,,,,0,5.000000e+000,5.000000e-001,2,1,9.613037e-004,0,0,0,
1473066127.366,,2.000000e+004,4.945709e+000,1.321684e-003,0.000000e+000,8.744259e-004,0.000000e+000,3,9.560806e-001,1.825000e+000,,,,,,,,,,,,,,,,,,0,5.000000e+000,5.000000e-001,2,1,9.636879e-004,0,0,0,
1473066298.313,,1.000000e+004,4.939990e+000,1.297248e-003,0.000000e+000,-1.910621e-004,0.000000e+000,3,9.567995e-001,1.825000e+000,,,,,,,,,,,,,,,,,,0,5.000000e+000,5.000000e-001,2,1,2.765656e-003,0,1,0,
1473066322.992,,1.000000e+004,4.945045e+000,1.297564e-003,0.000000e+000,3.827918e-005,0.000000e+000,3,9.561802e-001,1.825000e+000,,,,,,,,,,,,,,,,,,0,5.000000e+000,5.000000e-001,2,1,6.027222e-004,0,1,0,
1473066455.681,,9.000000e+003,4.939268e+000,1.293767e-003,0.000000e+000,-2.435239e-004,0.000000e+000,3,9.566947e-001,1.825000e+000,,,,,,,,,,,,,,,,,,0,5.000000e+000,5.000000e-001,2,1,3.245831e-003,0,1,0,
1473066480.875,,9.000000e+003,4.944563e+000,1.294114e-003,0.000000e+000,2.394504e-005,0.000000e+000,3,9.563412e-001,1.825000e+000,,,,,,,,,,,,,,,,,,0,5.000000e+000,5.000000e-001,2,1,1.211166e-004,0,0,0,
1473066616.818,,7.000000e+003,4.941374e+000,1.286953e-003,0.000000e+000,-3.616716e-004,0.000000e+000,3,9.568971e-001,1.825000e+000,,,,,,,,,,,,,,,,,,0,5.000000e+000,5.000000e-001,2,1,4.811764e-003,0,0,0,
1473066639.553,,7.000000e+003,4.946190e+000,1.286221e-003,0.000000e+000,-2.145562e-004,0.000000e+000,3,9.562685e-001,1.825000e+000,,,,,,,,,,,,,,,,,,0,5.000000e+000,5.000000e-001,2,1,7.238388e-004,0,0,0,
1473066773.992,,5.000000e+003,4.939087e+000,1.279656e-003,0.000000e+000,1.440652e-006,0.000000e+000,3,9.559293e-001,1.825000e+000,,,,,,,,,,,,,,,,,,0,5.000000e+000,5.000000e-001,2,1,1.442909e-003,0,0,0,
1473066799.249,,5.000000e+003,4.945287e+000,1.275540e-003,0.000000e+000,-4.653347e-005,0.000000e+000,3,9.571685e-001,1.825000e+000,,,,,,,,,,,,,,,,,,0,5.000000e+000,5.000000e-001,2,1,1.196861e-004,0,1,0,
1473066935.273,,3.000000e+003,4.944626e+000,1.260567e-003,0.000000e+000,1.327106e-004,0.000000e+000,3,9.575880e-001,1.825000e+000,,,,,,,,,,,,,,,,,,0,5.000000e+000,5.000000e-001,2,1,5.543232e-003,0,1,0,
1473066960.202,,3.000000e+003,4.948242e+000,1.260583e-003,0.000000e+000,-5.336940e-005,0.000000e+000,3,9.572914e-001,1.825000e+000,,,,,,,,,,,,,,,,,,0,5.000000e+000,5.000000e-001,2,1,1.206875e-003,0,1,0,
1473067091.919,,1.000000e+003,4.944142e+000,1.227280e-003,0.000000e+000,1.056295e-003,0.000000e+000,3,9.640114e-001,1.825000e+000,,,,,,,,,,,,,,,,,,0,5.000000e+000,5.000000e-001,2,1,2.891064e-003,0,0,0,
1473067116.347,,1.000000e+003,4.949268e+000,1.226389e-003,0.000000e+000,1.189244e-003,0.000000e+000,3,9.643444e-001,1.825000e+000,,,,,,,,,,,,,,,,,,0,5.000000e+000,5.000000e-001,2,1,1.327038e-003,0,0,0,
1473067248.032,,7.000000e+002,4.944685e+000,1.217403e-003,0.000000e+000,1.734435e-003,0.000000e+000,3,9.671721e-001,1.825000e+000,,,,,,,,,,,,,,,,,,0,5.000000e+000,5.000000e-001,2,1,4.940987e-003,0,0,0,
1473067272.819,,7.000000e+002,4.948665e+000,1.215365e-003,0.000000e+000,1.450995e-003,0.000000e+000,3,9.677127e-001,1.825000e+000,,,,,,,,,,,,,,,,,,0,5.000000e+000,5.000000e-001,2,1,3.628731e-004,0,1,0,
1473067399.538,,6.000000e+002,4.945890e+000,1.209967e-003,0.000000e+000,1.881219e-003,0.000000e+000,3,9.686335e-001,1.825000e+000,,,,,,,,,,,,,,,,,,0,5.000000e+000,5.000000e-001,2,1,4.942894e-003,0,1,0,
1473067425.045,,6.000000e+002,4.951081e+000,1.211210e-003,0.000000e+000,1.589068e-003,0.000000e+000,3,9.692294e-001,1.825000e+000,,,,,,,,,,,,,,,,,,0,5.000000e+000,5.000000e-001,2,1,1.329899e-003,0,1,0,
1473067555.276,,5.000000e+002,4.946252e+000,1.203197e-003,0.000000e+000,2.172895e-003,0.000000e+000,3,9.704846e-001,1.825000e+000,,,,,,,,,,,,,,,,,,0,5.000000e+000,5.000000e-001,2,1,3.255844e-003,0,1,0,
1473067578.504,,5.000000e+002,4.950355e+000,1.202652e-003,0.000000e+000,2.479458e-003,0.000000e+000,3,9.701488e-001,1.825000e+000,,,,,,,,,,,,,,,,,,0,5.000000e+000,5.000000e-001,2,1,1.220703e-004,0,0,0,
1473067710.194,,4.000000e+002,4.945468e+000,1.194339e-003,0.000000e+000,3.184701e-003,0.000000e+000,3,9.720037e-001,1.825000e+000,,,,,,,,,,,,,,,,,,0,5.000000e+000,5.000000e-001,2,1,4.341125e-003,0,0,0,
1473067732.625,,4.000000e+002,4.949571e+000,1.194648e-003,0.000000e+000,1.861741e-003,0.000000e+000,3,9.735109e-001,1.825000e+000,,,,,,,,,,,,,,,,,,0,5.000000e+000,5.000000e-001,2,1,1.932144e-003,0,0,0,
1473067867.067,,3.000000e+002,4.943781e+000,1.182645e-003,0.000000e+000,3.232043e-003,0.000000e+000,3,9.748949e-001,1.825000e+000,,,,,,,,,,,,,,,,,,0,5.000000e+000,5.000000e-001,2,1,3.131866e-003,0,0,0,
1473067890.996,,3.000000e+002,4.948302e+000,1.183510e-003,0.000000e+000,2.700028e-003,0.000000e+000,3,9.752314e-001,1.825000e+000,,,,,,,,,,,,,,,,,,0,5.000000e+000,5.000000e-001,2,1,1.327038e-003,0,1,0,
1473068021.999,,2.000000e+002,4.946133e+000,1.164772e-003,0.000000e+000,3.499173e-003,0.000000e+000,3,9.775010e-001,1.825000e+000,,,,,,,,,,,,,,,,,,0,5.000000e+000,5.000000e-001,2,1,5.426884e-003,0,1,0,
1473068046.197,,2.000000e+002,4.950597e+000,1.164215e-003,0.000000e+000,3.875029e-003,0.000000e+000,3,9.769549e-001,1.825000e+000,,,,,,,,,,,,,,,,,,0,5.000000e+000,5.000000e-001,2,1,6.051064e-004,0,1,0,
1473068164.821,,1.800000e+002,4.947036e+000,1.160106e-003,0.000000e+000,3.370812e-003,0.000000e+000,3,9.781177e-001,1.825000e+000,,,,,,,,,,,,,,,,,,0,5.000000e+000,5.000000e-001,2,1,4.583836e-003,0,1,0,
1473068187.857,,1.800000e+002,4.951806e+000,1.160246e-003,0.000000e+000,3.261388e-003,0.000000e+000,3,9.781795e-001,1.825000e+000,,,,,,,,,,,,,,,,,,0,5.000000e+000,5.000000e-001,2,1,6.036758e-004,0,0,0,
1473068308.552,,1.600000e+002,4.945409e+000,1.155615e-003,0.000000e+000,3.007211e-003,0.000000e+000,3,9.790937e-001,1.825000e+000,,,,,,,,,,,,,,,,,,0,5.000000e+000,5.000000e-001,2,1,4.703045e-003,0,0,0,
1473068331.735,,1.600000e+002,4.948906e+000,1.156177e-003,0.000000e+000,3.389895e-003,0.000000e+000,3,9.786078e-001,1.825000e+000,,,,,,,,,,,,,,,,,,0,5.000000e+000,5.000000e-001,2,1,1.569748e-003,0,0,0,
1473068456.672,,1.400000e+002,4.944866e+000,1.148817e-003,0.000000e+000,3.477507e-003,0.000000e+000,3,9.797669e-001,1.825000e+000,,,,,,,,,,,,,,,,,,0,5.000000e+000,5.000000e-001,2,1,5.062103e-003,0,0,0,
1473068482.851,,1.400000e+002,4.947820e+000,1.149909e-003,0.000000e+000,3.460364e-003,0.000000e+000,3,9.795907e-001,1.825000e+000,,,,,,,,,,,,,,,,,,0,5.000000e+000,5.000000e-001,2,1,1.327038e-003,0,0,0,
1473068604.095,,1.200000e+002,4.945830e+000,1.143330e-003,0.000000e+000,3.919363e-003,0.000000e+000,3,9.793188e-001,1.825000e+000,,,,,,,,,,,,,,,,,,0,5.000000e+000,5.000000e-001,2,1,5.304813e-003,0,1,0,
1473068626.836,,1.200000e+002,4.950658e+000,1.142881e-003,0.000000e+000,3.809337e-003,0.000000e+000,3,9.801166e-001,1.825000e+000,,,,,,,,,,,,,,,,,,0,5.000000e+000,5.000000e-001,2,1,2.408028e-004,0,1,0,
1473068747.024,,1.000000e+002,4.947821e+000,1.220280e-003,0.000000e+000,1.632022e-002,0.000000e+000,3,8.742039e-001,1.825000e+000,,,,,,,,,,,,,,,,,,0,5.000000e+000,5.000000e-001,2,1,4.947186e-003,0,1,0,
1473068770.500,,1.000000e+002,4.951262e+000,1.135722e-003,0.000000e+000,3.951655e-003,0.000000e+000,3,9.802442e-001,1.825000e+000,,,,,,,,,,,,,,,,,,0,5.000000e+000,5.000000e-001,2,1,7.247925e-004,0,0,0,
1473068890.688,,8.000000e+001,4.946011e+000,1.126854e-003,0.000000e+000,3.793909e-003,0.000000e+000,3,9.814608e-001,1.825000e+000,,,,,,,,,,,,,,,,,,0,5.000000e+000,5.000000e-001,2,1,4.702091e-003,0,0,0,
1473068913.666,,8.000000e+001,4.950356e+000,1.126161e-003,0.000000e+000,3.268074e-003,0.000000e+000,3,9.821136e-001,1.825000e+000,,,,,,,,,,,,,,,,,,0,5.000000e+000,5.000000e-001,2,1,1.087189e-003,0,0,0,
1473069033.300,,6.000000e+001,4.944142e+000,1.115846e-003,0.000000e+000,3.214854e-003,0.000000e+000,3,9.823076e-001,1.825000e+000,,,,,,,,,,,,,,,,,,0,5.000000e+000,5.000000e-001,2,1,2.409935e-003,0,0,0,
1473069056.382,,6.000000e+001,4.949027e+000,1.116521e-003,0.000000e+000,3.975531e-003,0.000000e+000,3,9.820366e-001,1.825000e+000,,,,,,,,,,,,,,,,,,0,5.000000e+000,5.000000e-001,2,1,1.211166e-004,0,0,0,
1473069174.113,,4.000000e+001,4.945891e+000,1.103637e-003,0.000000e+000,4.272429e-003,0.000000e+000,3,9.823140e-001,1.825000e+000,,,,,,,,,,,,,,,,,,0,5.000000e+000,5.000000e-001,2,1,5.426884e-003,0,1,0,
1473069198.828,,4.000000e+001,4.949570e+000,1.103680e-003,0.000000e+000,4.125310e-003,0.000000e+000,3,9.824734e-001,1.825000e+000,,,,,,,,,,,,,,,,,,0,5.000000e+000,5.000000e-001,2,1,1.207829e-003,0,1,0,
1473069322.315,,2.000000e+001,4.946734e+000,1.097743e-003,0.000000e+000,-1.613264e-003,0.000000e+000,3,9.522181e-001,1.825000e+000,,,,,,,,,,,,,,,,,,0,5.000000e+000,5.000000e-001,2,1,2.774239e-003,0,1,0,
1473069346.244,,2.000000e+001,4.951866e+000,1.089147e-003,0.000000e+000,4.058704e-003,0.000000e+000,3,9.832394e-001,1.825000e+000,,,,,,,,,,,,,,,,,,0,5.000000e+000,5.000000e-001,2,1,2.408028e-004,0,0,0,
1473069471.189,,0.000000e+000,4.946554e+000,1.071147e-003,0.000000e+000,4.178656e-003,0.000000e+000,3,9.841545e-001,1.825000e+000,,,,,,,,,,,,,,,,,,0,5.000000e+000,5.000000e-001,2,1,5.065918e-003,0,0,0,
1473069495.805,,0.000000e+000,4.950114e+000,1.071741e-003,0.000000e+000,4.564229e-003,0.000000e+000,3,9.824864e-001,1.825000e+000,,,,,,,,,,,,,,,,,,0,5.000000e+000,5.000000e-001,2,1,8.463860e-004,0,0,0,
1473069614.878,,-2.000000e+001,4.945830e+000,1.044964e-003,0.000000e+000,4.230040e-003,0.000000e+000,3,9.840953e-001,1.825000e+000,,,,,,,,,,,,,,,,,,0,5.000000e+000,5.000000e-001,2,1,5.064011e-003,0,0,0,
1473069638.105,,-2.000000e+001,4.949631e+000,1.045677e-003,0.000000e+000,4.255373e-003,0.000000e+000,3,9.841883e-001,1.825000e+000,,,,,,,,,,,,,,,,,,0,5.000000e+000,5.000000e-001,2,1,8.463860e-004,0,0,0,
1473069756.793,,-4.000000e+001,4.946433e+000,1.012209e-003,0.000000e+000,4.484440e-003,0.000000e+000,3,9.847400e-001,1.825000e+000,,,,,,,,,,,,,,,,,,0,5.000000e+000,5.000000e-001,2,1,4.584312e-003,0,1,0,
1473069780.511,,-4.000000e+001,4.951141e+000,1.011535e-003,0.000000e+000,4.535755e-003,0.000000e+000,3,9.848279e-001,1.825000e+000,,,,,,,,,,,,,,,,,,0,5.000000e+000,5.000000e-001,2,1,1.450062e-003,0,1,0,
1473069901.453,,-6.000000e+001,4.946010e+000,9.599021e-004,0.000000e+000,4.851606e-003,0.000000e+000,3,9.849131e-001,1.825000e+000,,,,,,,,,,,,,,,,,,0,5.000000e+000,5.000000e-001,2,1,1.201630e-004,0,1,0,
1473069926.650,,-6.000000e+001,4.951564e+000,9.582884e-004,0.000000e+000,4.828936e-003,0.000000e+000,3,9.853444e-001,1.825000e+000,,,,,,,,,,,,,,,,,,0,5.000000e+000,5.000000e-001,2,1,1.572132e-003,0,0,0,
1473070045.893,,-8.000000e+001,4.945648e+000,8.431245e-004,0.000000e+000,4.473868e-003,0.000000e+000,3,9.859223e-001,1.825000e+000,,,,,,,,,,,,,,,,,,0,5.000000e+000,5.000000e-001,2,1,2.291203e-003,0,0,0,
1473070070.626,,-8.000000e+001,4.950598e+000,8.387145e-004,0.000000e+000,4.023311e-003,0.000000e+000,3,9.847160e-001,1.825000e+000,,,,,,,,,,,,,,,,,,0,5.000000e+000,5.000000e-001,2,1,2.295971e-003,0,0,0,
1473070199.382,,-1.000000e+002,4.951323e+000,-7.541984e-005,0.000000e+000,-2.684963e-002,0.000000e+000,3,9.127040e-001,1.825000e+000,,,,,,,,,,,,,,,,,,0,5.000000e+000,5.000000e-001,2,1,2.296925e-003,0,0,0,
1473070234.274,,-1.000000e+002,4.951504e+000,-8.504414e-005,0.000000e+000,-1.199171e-002,0.000000e+000,3,9.173273e-001,1.825000e+000,,,,,,,,,,,,,,,,,,0,5.000000e+000,5.000000e-001,2,1,4.839897e-004,0,1,0,
1473070375.559,,-1.200000e+002,4.955073e+000,-3.383136e-004,0.000000e+000,4.036353e-004,0.000000e+000,3,9.674595e-001,1.825000e+000,,,,,,,,,,,,,,,,,,0,5.000000e+000,5.000000e-001,2,1,1.331806e-003,0,1,0,
1473070397.987,,-1.200000e+002,4.955497e+000,-3.619053e-004,0.000000e+000,-3.732792e-002,0.000000e+000,3,8.839794e-001,1.825000e+000,,,,,,,,,,,,,,,,,,0,5.000000e+000,5.000000e-001,2,1,2.417564e-004,0,1,0,
1473070517.238,,-1.400000e+002,4.949210e+000,-4.341826e-004,0.000000e+000,1.862392e-003,0.000000e+000,3,9.673758e-001,1.825000e+000,,,,,,,,,,,,,,,,,,0,5.000000e+000,5.000000e-001,2,1,4.589081e-003,0,0,0,
1473070541.675,,-1.400000e+002,4.952894e+000,-4.363623e-004,0.000000e+000,-2.113343e-004,0.000000e+000,3,9.700089e-001,1.825000e+000,,,,,,,,,,,,,,,,,,0,5.000000e+000,5.000000e-001,2,1,6.051064e-004,0,0,0,
1473070665.613,,-1.600000e+002,4.949208e+000,-5.039919e-004,0.000000e+000,1.686501e-003,0.000000e+000,3,9.711572e-001,1.825000e+000,,,,,,,,,,,,,,,,,,0,5.000000e+000,5.000000e-001,2,1,2.657413e-003,0,0,0,
1473070689.979,,-1.600000e+002,4.954588e+000,-5.059693e-004,0.000000e+000,2.133030e-003,0.000000e+000,3,9.698823e-001,1.825000e+000,,,,,,,,,,,,,,,,,,0,5.000000e+000,5.000000e-001,2,1,1.211166e-004,0,1,0,
1473070808.777,,-1.800000e+002,4.952894e+000,-5.598929e-004,0.000000e+000,1.987722e-003,0.000000e+000,3,9.711854e-001,1.825000e+000,,,,,,,,,,,,,,,,,,0,5.000000e+000,5.000000e-001,2,1,1.573086e-003,0,1,0,
1473070832.207,,-1.800000e+002,4.957436e+000,-5.628652e-004,0.000000e+000,1.416240e-003,0.000000e+000,3,9.709541e-001,1.825000e+000,,,,,,,,,,,,,,,,,,0,5.000000e+000,5.000000e-001,2,1,9.698868e-004,0,1,0,
1473070949.644,,-2.000000e+002,4.951564e+000,-6.093607e-004,0.000000e+000,7.169203e-004,0.000000e+000,3,9.720150e-001,1.825000e+000,,,,,,,,,,,,,,,,,,0,5.000000e+000,5.000000e-001,2,1,6.041527e-004,0,0,0,
1473070973.330,,-2.000000e+002,4.957315e+000,-6.113832e-004,0.000000e+000,1.647335e-003,0.000000e+000,3,9.708009e-001,1.825000e+000,,,,,,,,,,,,,,,,,,0,5.000000e+000,5.000000e-001,2,1,4.863739e-004,0,0,0,
1473071115.798,,-3.000000e+002,4.953985e+000,-7.931494e-004,0.000000e+000,1.955435e-003,0.000000e+000,3,9.698502e-001,1.825000e+000,,,,,,,,,,,,,,,,,,0,5.000000e+000,5.000000e-001,2,1,5.446911e-003,0,1,0,
1473071140.977,,-3.000000e+002,4.955982e+000,-7.944332e-004,0.000000e+000,1.927474e-003,0.000000e+000,3,9.702443e-001,1.825000e+000,,,,,,,,,,,,,,,,,,0,5.000000e+000,5.000000e-001,2,1,1.211643e-003,0,1,0,
1473071267.415,,-4.000000e+002,4.954650e+000,-9.083465e-004,0.000000e+000,1.962800e-003,0.000000e+000,3,9.683071e-001,1.825000e+000,,,,,,,,,,,,,,,,,,0,5.000000e+000,5.000000e-001,2,1,3.874779e-003,0,1,0,
1473071290.899,,-4.000000e+002,4.957678e+000,-9.108318e-004,0.000000e+000,2.098707e-003,0.000000e+000,3,9.687015e-001,1.825000e+000,,,,,,,,,,,,,,,,,,0,5.000000e+000,5.000000e-001,2,1,9.698868e-004,0,1,0,
1473071424.341,,-5.000000e+002,4.954105e+000,-9.875407e-004,0.000000e+000,1.854972e-003,0.000000e+000,3,9.680101e-001,1.825000e+000,,,,,,,,,,,,,,,,,,0,5.000000e+000,5.000000e-001,2,1,4.237175e-003,0,0,0,
1473071450.270,,-5.000000e+002,4.956709e+000,-9.897569e-004,0.000000e+000,1.745669e-003,0.000000e+000,3,9.671244e-001,1.825000e+000,,,,,,,,,,,,,,,,,,0,5.000000e+000,5.000000e-001,2,1,2.422333e-004,0,0,0,
1473071573.766,,-6.000000e+002,4.953923e+000,-1.039982e-003,0.000000e+000,1.629390e-003,0.000000e+000,3,9.662163e-001,1.825000e+000,,,,,,,,,,,,,,,,,,0,5.000000e+000,5.000000e-001,2,1,3.873348e-003,0,1,0,
1473071597.504,,-6.000000e+002,4.957194e+000,-1.040920e-003,0.000000e+000,1.808693e-003,0.000000e+000,3,9.676888e-001,1.825000e+000,,,,,,,,,,,,,,,,,,0,5.000000e+000,5.000000e-001,2,1,9.698868e-004,0,1,0,
1473071729.450,,-7.000000e+002,4.956589e+000,-1.078051e-003,0.000000e+000,1.654221e-003,0.000000e+000,3,9.648676e-001,1.825000e+000,,,,,,,,,,,,,,,,,,0,5.000000e+000,5.000000e-001,2,1,4.121304e-003,0,1,0,
1473071754.185,,-7.000000e+002,4.959315e+000,-1.079289e-003,0.000000e+000,1.767575e-003,0.000000e+000,3,9.647160e-001,1.825000e+000,,,,,,,,,,,,,,,,,,0,5.000000e+000,5.000000e-001,2,1,1.206398e-004,0,1,0,
1473071883.927,,-1.000000e+003,4.954710e+000,-1.138102e-003,0.000000e+000,1.538859e-003,0.000000e+000,3,9.628161e-001,1.825000e+000,,,,,,,,,,,,,,,,,,0,5.000000e+000,5.000000e-001,2,1,3.026962e-003,0,0,0,
1473071908.127,,-1.000000e+003,4.958345e+000,-1.138541e-003,0.000000e+000,1.402591e-003,0.000000e+000,3,9.626010e-001,1.825000e+000,,,,,,,,,,,,,,,,,,0,5.000000e+000,5.000000e-001,2,1,6.070137e-004,0,0,0,
1473072042.821,,-3.000000e+003,4.953862e+000,-1.236690e-003,0.000000e+000,3.427856e-004,0.000000e+000,3,9.572999e-001,1.825000e+000,,,,,,,,,,,,,,,,,,0,5.000000e+000,5.000000e-001,2,1,2.541065e-003,0,1,0,
1473072067.749,,-3.000000e+003,4.958163e+000,-1.237438e-003,0.000000e+000,3.989573e-004,0.000000e+000,3,9.563135e-001,1.825000e+000,,,,,,,,,,,,,,,,,,0,5.000000e+000,5.000000e-001,2,1,1.698971e-003,0,1,0,
1473072202.666,,-5.000000e+003,4.956467e+000,-1.263164e-003,0.000000e+000,4.515091e-004,0.000000e+000,3,9.562206e-001,1.825000e+000,,,,,,,,,,,,,,,,,,0,5.000000e+000,5.000000e-001,2,1,3.392696e-003,0,1,0,
1473072227.502,,-5.000000e+003,4.959741e+000,-1.263508e-003,0.000000e+000,4.951200e-004,0.000000e+000,3,9.561335e-001,1.825000e+000,,,,,,,,,,,,,,,,,,0,5.000000e+000,5.000000e-001,2,1,2.422333e-004,0,0,0,
1473072365.941,,-7.000000e+003,4.954832e+000,-1.278885e-003,0.000000e+000,6.055965e-004,0.000000e+000,3,9.561472e-001,1.825000e+000,,,,,,,,,,,,,,,,,,0,5.000000e+000,5.000000e-001,2,1,3.511906e-003,0,0,0,
1473072390.920,,-7.000000e+003,4.959377e+000,-1.279208e-003,0.000000e+000,5.607937e-004,0.000000e+000,3,9.561889e-001,1.825000e+000,,,,,,,,,,,,,,,,,,0,5.000000e+000,5.000000e-001,2,1,7.281303e-004,0,0,0,
1473072521.146,,-9.000000e+003,4.954105e+000,-1.289706e-003,0.000000e+000,8.033700e-004,0.000000e+000,3,9.560208e-001,1.825000e+000,,,,,,,,,,,,,,,,,,0,5.000000e+000,5.000000e-001,2,1,2.542019e-003,0,1,0,
1473072545.078,,-9.000000e+003,4.957982e+000,-1.289723e-003,0.000000e+000,7.644846e-004,0.000000e+000,3,9.561744e-001,1.825000e+000,,,,,,,,,,,,,,,,,,0,5.000000e+000,5.000000e-001,2,1,1.211166e-004,0,1,0,
1473072678.037,,-1.000000e+004,4.955012e+000,-1.293761e-003,0.000000e+000,8.367817e-004,0.000000e+000,3,9.557787e-001,1.825000e+000,,,,,,,,,,,,,,,,,,0,5.000000e+000,5.000000e-001,2,1,9.689331e-004,0,1,0,
1473072702.715,,-1.000000e+004,4.958830e+000,-1.294368e-003,0.000000e+000,8.884057e-004,0.000000e+000,3,9.558885e-001,1.825000e+000,,,,,,,,,,,,,,,,,,0,5.000000e+000,5.000000e-001,2,1,8.502007e-004,0,0,0,
1473072873.917,,-2.000000e+004,4.954953e+000,-1.320130e-003,0.000000e+000,1.774136e-003,0.000000e+000,3,9.562807e-001,1.825000e+000,,,,,,,,,,,,,,,,,,0,5.000000e+000,5.000000e-001,2,1,3.511906e-003,0,0,0,
1473072898.203,,-2.000000e+004,4.959073e+000,-1.319933e-003,0.000000e+000,1.860621e-003,0.000000e+000,3,9.562154e-001,1.825000e+000,,,,,,,,,,,,,,,,,,0,5.000000e+000,5.000000e-001,2,1,6.060600e-004,0,0,0,
1473073072.147,,-3.000000e+004,4.958163e+000,-1.332776e-003,0.000000e+000,2.689958e-003,0.000000e+000,3,9.566913e-001,1.825000e+000,,,,,,,,,,,,,,,,,,0,5.000000e+000,5.000000e-001,2,1,2.666950e-003,0,1,0,
1473073097.120,,-3.000000e+004,4.962898e+000,-1.331810e-003,0.000000e+000,2.022898e-003,0.000000e+000,3,9.555454e-001,1.825000e+000,,,,,,,,,,,,,,,,,,0,5.000000e+000,5.000000e-001,2,1,4.858971e-004,0,1,0,
1473073267.817,,-4.000000e+004,4.961805e+000,-1.336469e-003,0.000000e+000,3.424884e-003,0.000000e+000,3,9.559074e-001,1.825000e+000,,,,,,,,,,,,,,,,,,0,5.000000e+000,5.000000e-001,2,1,3.886700e-003,0,0,0,
1473073291.251,,-4.000000e+004,4.964662e+000,-1.336275e-003,0.000000e+000,3.244169e-003,0.000000e+000,3,9.558901e-001,1.825000e+000,,,,,,,,,,,,,,,,,,0,5.000000e+000,5.000000e-001,2,1,6.089211e-004,0,0,0,
1473073470.475,,-5.000000e+004,4.961562e+000,-1.334889e-003,0.000000e+000,5.048245e-003,0.000000e+000,3,9.551346e-001,1.825000e+000,,,,,,,,,,,,,,,,,,0,5.000000e+000,5.000000e-001,2,1,2.914906e-003,0,1,0,
1473073493.909,,-5.000000e+004,4.964662e+000,-1.333700e-003,0.000000e+000,4.809942e-003,0.000000e+000,3,9.541019e-001,1.825000e+000,,,,,,,,,,,,,,,,,,0,5.000000e+000,5.000000e-001,2,1,1.094818e-003,0,1,0,
1473073674.163,,-6.000000e+004,4.958892e+000,-1.329653e-003,0.000000e+000,4.244397e-003,0.000000e+000,3,9.549929e-001,1.825000e+000,,,,,,,,,,,,,,,,,,0,5.000000e+000,5.000000e-001,2,1,4.849434e-004,0,0,0,
1473073697.888,,-6.000000e+004,4.963324e+000,-1.329783e-003,0.000000e+000,4.248322e-003,0.000000e+000,3,9.548121e-001,1.825000e+000,,,,,,,,,,,,,,,,,,0,5.000000e+000,5.000000e-001,2,1,6.079674e-004,0,0,0,
1473073877.586,,-7.000000e+004,4.961806e+000,-1.319425e-003,0.000000e+000,3.382660e-003,0.000000e+000,3,9.541401e-001,1.825000e+000,,,,,,,,,,,,,,,,,,0,5.000000e+000,5.000000e-001,2,1,3.402233e-003,0,1,0,
1473073900.298,,-7.000000e+004,4.964601e+000,-1.326583e-003,0.000000e+000,2.043270e-003,0.000000e+000,3,9.534783e-001,1.825000e+000,,,,,,,,,,,,,,,,,,0,5.000000e+000,5.000000e-001,2,1,1.459122e-003,0,1,0,
1473074083.042,,-6.000000e+004,4.960105e+000,-1.329615e-003,0.000000e+000,3.445886e-003,0.000000e+000,3,9.548420e-001,1.825000e+000,,,,,,,,,,,,,,,,,,0,5.000000e+000,5.000000e-001,2,1,3.154755e-003,0,0,0,
1473074109.721,,-6.000000e+004,4.962352e+000,-1.329461e-003,0.000000e+000,3.526800e-003,0.000000e+000,3,9.547642e-001,1.825000e+000,,,,,,,,,,,,,,,,,,0,5.000000e+000,5.000000e-001,2,1,1.220703e-004,0,0,0,
1473074281.357,,-5.000000e+004,4.960591e+000,-1.338151e-003,0.000000e+000,3.279108e-003,0.000000e+000,3,9.548091e-001,1.825000e+000,,,,,,,,,,,,,,,,,,0,5.000000e+000,5.000000e-001,2,1,3.643036e-003,0,1,0,
1473074305.893,,-5.000000e+004,4.964174e+000,-1.334735e-003,0.000000e+000,3.810015e-003,0.000000e+000,3,9.542567e-001,1.825000e+000,,,,,,,,,,,,,,,,,,0,5.000000e+000,5.000000e-001,2,1,3.647804e-004,0,1,0,
1473074479.055,,-4.000000e+004,4.958830e+000,-1.336271e-003,0.000000e+000,2.094484e-003,0.000000e+000,3,9.558554e-001,1.825000e+000,,,,,,,,,,,,,,,,,,0,5.000000e+000,5.000000e-001,2,1,8.502007e-004,0,0,0,
1473074503.699,,-4.000000e+004,4.963749e+000,-1.336161e-003,0.000000e+000,2.066787e-003,0.000000e+000,3,9.558484e-001,1.825000e+000,,,,,,,,,,,,,,,,,,0,5.000000e+000,5.000000e-001,2,1,0.000000e+000,0,0,0,
1473074672.909,,-3.000000e+004,4.960409e+000,-1.332653e-003,0.000000e+000,1.412311e-003,0.000000e+000,3,9.546652e-001,1.825000e+000,,,,,,,,,,,,,,,,,,0,5.000000e+000,5.000000e-001,2,1,3.279209e-003,0,1,0,
1473074698.052,,-3.000000e+004,4.964053e+000,-1.332921e-003,0.000000e+000,4.853578e-004,0.000000e+000,3,9.549617e-001,1.825000e+000,,,,,,,,,,,,,,,,,,0,5.000000e+000,5.000000e-001,2,1,3.638268e-004,0,1,0,
1473074869.912,,-2.000000e+004,4.959255e+000,-1.322542e-003,0.000000e+000,-2.002161e-004,0.000000e+000,3,9.572418e-001,1.825000e+000,,,,,,,,,,,,,,,,,,0,5.000000e+000,5.000000e-001,2,1,1.942158e-003,0,0,0,
1473074894.090,,-2.000000e+004,4.962898e+000,-1.320626e-003,0.000000e+000,3.997924e-004,0.000000e+000,3,9.563056e-001,1.825000e+000,,,,,,,,,,,,,,,,,,0,5.000000e+000,5.000000e-001,2,1,0.000000e+000,0,0,0,
1473075066.205,,-1.000000e+004,4.959558e+000,-1.297729e-003,0.000000e+000,-1.888842e-004,0.000000e+000,3,9.562801e-001,1.825000e+000,,,,,,,,,,,,,,,,,,0,5.000000e+000,5.000000e-001,2,1,1.818657e-003,0,1,0,
1473075102.885,,-1.000000e+004,4.964236e+000,-1.282856e-003,0.000000e+000,-1.267974e-002,0.000000e+000,3,9.582551e-001,1.825000e+000,,,,,,,,,,,,,,,,,,0,5.000000e+000,5.000000e-001,2,1,7.300377e-004,0,1,0,
1473075238.051,,-9.000000e+003,4.959135e+000,-1.294556e-003,0.000000e+000,-2.703190e-004,0.000000e+000,3,9.564600e-001,1.825000e+000,,,,,,,,,,,,,,,,,,0,5.000000e+000,5.000000e-001,2,1,1.213074e-003,0,0,0,
1473075263.274,,-9.000000e+003,4.963810e+000,-1.294591e-003,0.000000e+000,-4.245371e-004,0.000000e+000,3,9.564949e-001,1.825000e+000,,,,,,,,,,,,,,,,,,0,5.000000e+000,5.000000e-001,2,1,1.220703e-004,0,0,0,
1473075402.252,,-7.000000e+003,4.959195e+000,-1.285601e-003,0.000000e+000,-1.420196e-004,0.000000e+000,3,9.559293e-001,1.825000e+000,,,,,,,,,,,,,,,,,,0,5.000000e+000,5.000000e-001,2,1,3.032207e-003,0,1,0,
1473075429.678,,-7.000000e+003,4.962291e+000,-1.286542e-003,0.000000e+000,-3.257451e-004,0.000000e+000,3,9.563999e-001,1.825000e+000,,,,,,,,,,,,,,,,,,0,5.000000e+000,5.000000e-001,2,1,1.458645e-003,0,1,0,
1473075566.359,,-5.000000e+003,4.959923e+000,-1.276944e-003,0.000000e+000,-8.005819e-004,0.000000e+000,3,9.565880e-001,1.825000e+000,,,,,,,,,,,,,,,,,,0,5.000000e+000,5.000000e-001,2,1,6.060600e-004,0,1,0,
1473075591.034,,-5.000000e+003,4.964296e+000,-1.276314e-003,0.000000e+000,-5.097919e-004,0.000000e+000,3,9.564706e-001,1.825000e+000,,,,,,,,,,,,,,,,,,0,5.000000e+000,5.000000e-001,2,1,1.095295e-003,0,0,0,
1473075720.465,,-3.000000e+003,4.959680e+000,-1.298545e-003,0.000000e+000,3.689029e-003,0.000000e+000,3,9.019286e-001,1.825000e+000,,,,,,,,,,,,,,,,,,0,5.000000e+000,5.000000e-001,2,1,2.061844e-003,0,0,0,
1473075746.640,,-3.000000e+003,4.963628e+000,-1.261074e-003,0.000000e+000,-7.290990e-005,0.000000e+000,3,9.576274e-001,1.825000e+000,,,,,,,,,,,,,,,,,,0,5.000000e+000,5.000000e-001,2,1,0.000000e+000,0,0,0,
1473075881.820,,-1.000000e+003,4.960106e+000,-1.226558e-003,0.000000e+000,6.003272e-004,0.000000e+000,3,9.647514e-001,1.825000e+000,,,,,,,,,,,,,,,,,,0,5.000000e+000,5.000000e-001,2,1,3.886223e-003,0,1,0,
1473075907.448,,-1.000000e+003,4.962716e+000,-1.226386e-003,0.000000e+000,1.413885e-003,0.000000e+000,3,9.637709e-001,1.825000e+000,,,,,,,,,,,,,,,,,,0,5.000000e+000,5.000000e-001,2,1,8.502007e-004,0,1,0,
1473076046.491,,-7.000000e+002,4.961806e+000,-1.215837e-003,0.000000e+000,1.572110e-003,0.000000e+000,3,9.670706e-001,1.825000e+000,,,,,,,,,,,,,,,,,,0,5.000000e+000,5.000000e-001,2,1,4.129887e-003,0,0,0,
1473076071.920,,-7.000000e+002,4.964115e+000,-1.215144e-003,0.000000e+000,1.564909e-003,0.000000e+000,3,9.674489e-001,1.825000e+000,,,,,,,,,,,,,,,,,,0,5.000000e+000,5.000000e-001,2,1,1.215935e-003,0,0,0,
1473076204.613,,-6.000000e+002,4.960044e+000,-1.209902e-003,0.000000e+000,1.454094e-003,0.000000e+000,3,9.694083e-001,1.825000e+000,,,,,,,,,,,,,,,,,,0,5.000000e+000,5.000000e-001,2,1,2.549171e-003,0,0,0,
1473076230.792,,-6.000000e+002,4.963689e+000,-1.210394e-003,0.000000e+000,1.967625e-003,0.000000e+000,3,9.685257e-001,1.825000e+000,,,,,,,,,,,,,,,,,,0,5.000000e+000,5.000000e-001,2,1,8.511543e-004,0,0,0,
1473076364.043,,-5.000000e+002,4.960530e+000,-1.202666e-003,0.000000e+000,2.470413e-003,0.000000e+000,3,9.703156e-001,1.825000e+000,,,,,,,,,,,,,,,,,,0,5.000000e+000,5.000000e-001,2,1,3.520966e-003,0,1,0,
1473076390.978,,-5.000000e+002,4.963993e+000,-1.203389e-003,0.000000e+000,1.990770e-003,0.000000e+000,3,9.703348e-001,1.825000e+000,,,,,,,,,,,,,,,,,,0,5.000000e+000,5.000000e-001,2,1,9.717941e-004,0,1,0,
1473076523.225,,-4.000000e+002,4.961987e+000,-1.195084e-003,0.000000e+000,2.532518e-003,0.000000e+000,3,9.722206e-001,1.825000e+000,,,,,,,,,,,,,,,,,,0,5.000000e+000,5.000000e-001,2,1,2.307892e-003,0,0,0,
1473076549.703,,-4.000000e+002,4.964783e+000,-1.195713e-003,0.000000e+000,2.336642e-003,0.000000e+000,3,9.726202e-001,1.825000e+000,,,,,,,,,,,,,,,,,,0,5.000000e+000,5.000000e-001,2,1,6.079674e-004,0,0,0,
1473076678.447,,-3.000000e+002,4.960895e+000,-1.183369e-003,0.000000e+000,2.658647e-003,0.000000e+000,3,9.749429e-001,1.825000e+000,,,,,,,,,,,,,,,,,,0,5.000000e+000,5.000000e-001,2,1,3.520966e-003,0,1,0,
1473076702.915,,-3.000000e+002,4.963445e+000,-1.183146e-003,0.000000e+000,2.793736e-003,0.000000e+000,3,9.749043e-001,1.825000e+000,,,,,,,,,,,,,,,,,,0,5.000000e+000,5.000000e-001,2,1,6.079674e-004,0,1,0,
1473076836.294,,-2.000000e+002,4.962898e+000,-1.165741e-003,0.000000e+000,3.005354e-003,0.000000e+000,3,9.777628e-001,1.825000e+000,,,,,,,,,,,,,,,,,,0,5.000000e+000,5.000000e-001,2,1,1.945019e-003,0,1,0,
1473076860.631,,-2.000000e+002,4.966670e+000,-1.165814e-003,0.000000e+000,3.008421e-003,0.000000e+000,3,9.778616e-001,1.825000e+000,,,,,,,,,,,,,,,,,,0,5.000000e+000,5.000000e-001,2,1,9.727478e-004,0,0,0,
1473076987.319,,-1.800000e+002,4.961866e+000,-1.161130e-003,0.000000e+000,3.083610e-003,0.000000e+000,3,9.785730e-001,1.825000e+000,,,,,,,,,,,,,,,,,,0,5.000000e+000,5.000000e-001,2,1,1.093864e-003,0,0,0,
1473077014.308,,-1.800000e+002,4.964722e+000,-1.161572e-003,0.000000e+000,3.248501e-003,0.000000e+000,3,9.780765e-001,1.825000e+000,,,,,,,,,,,,,,,,,,0,5.000000e+000,5.000000e-001,2,1,9.741783e-004,0,0,0,
1473077136.198,,-1.600000e+002,4.960226e+000,-1.155769e-003,0.000000e+000,3.271253e-003,0.000000e+000,3,9.785932e-001,1.825000e+000,,,,,,,,,,,,,,,,,,0,5.000000e+000,5.000000e-001,2,1,7.276535e-004,0,1,0,
1473077161.986,,-1.600000e+002,4.964357e+000,-1.155901e-003,0.000000e+000,2.907886e-003,0.000000e+000,3,9.790049e-001,1.825000e+000,,,,,,,,,,,,,,,,,,0,5.000000e+000,5.000000e-001,2,1,9.732246e-004,0,1,0,
1473077283.805,,-1.400000e+002,4.964602e+000,-1.150485e-003,0.000000e+000,3.501935e-003,0.000000e+000,3,9.794289e-001,1.825000e+000,,,,,,,,,,,,,,,,,,0,5.000000e+000,5.000000e-001,2,1,3.892899e-003,0,0,0,
1473077310.235,,-1.400000e+002,4.967278e+000,-1.149782e-003,0.000000e+000,3.382139e-003,0.000000e+000,3,9.793159e-001,1.825000e+000,,,,,,,,,,,,,,,,,,0,5.000000e+000,5.000000e-001,2,1,4.882813e-004,0,0,0,
1473077432.362,,-1.200000e+002,4.962898e+000,-1.141633e-003,0.000000e+000,3.100392e-003,0.000000e+000,3,9.771484e-001,1.825000e+000,,,,,,,,,,,,,,,,,,0,5.000000e+000,5.000000e-001,2,1,2.188206e-003,0,0,0,
1473077458.398,,-1.200000e+002,4.965392e+000,-1.143728e-003,0.000000e+000,3.470875e-003,0.000000e+000,3,9.801914e-001,1.825000e+000,,,,,,,,,,,,,,,,,,0,5.000000e+000,5.000000e-001,2,1,1.582146e-003,0,0,0,
1473077584.027,,-1.000000e+002,4.961563e+000,-1.135912e-003,0.000000e+000,3.418418e-003,0.000000e+000,3,9.804652e-001,1.825000e+000,,,,,,,,,,,,,,,,,,0,5.000000e+000,5.000000e-001,2,1,3.400803e-003,0,1,0,
1473077608.264,,-1.000000e+002,4.964844e+000,-1.135776e-003,0.000000e+000,3.635861e-003,0.000000e+000,3,9.804392e-001,1.825000e+000,,,,,,,,,,,,,,,,,,0,5.000000e+000,5.000000e-001,2,1,0.000000e+000,0,1,0,
1473077726.505,,-8.000000e+001,4.961926e+000,-1.127699e-003,0.000000e+000,4.326441e-003,0.000000e+000,3,9.800684e-001,1.825000e+000,,,,,,,,,,,,,,,,,,0,5.000000e+000,5.000000e-001,2,1,9.727478e-004,0,0,0,
1473077751.535,,-8.000000e+001,4.966122e+000,-1.127964e-003,0.000000e+000,4.090578e-003,0.000000e+000,3,9.807135e-001,1.825000e+000,,,,,,,,,,,,,,,,,,0,5.000000e+000,5.000000e-001,2,1,1.220703e-004,0,0,0,
1473077876.887,,-6.000000e+001,4.960894e+000,-1.117310e-003,0.000000e+000,3.982346e-003,0.000000e+000,3,9.816799e-001,1.825000e+000,,,,,,,,,,,,,,,,,,0,5.000000e+000,5.000000e-001,2,1,3.647804e-004,0,1,0,
1473077901.066,,-6.000000e+001,4.965087e+000,-1.116853e-003,0.000000e+000,3.744241e-003,0.000000e+000,3,9.822462e-001,1.825000e+000,,,,,,,,,,,,,,,,,,0,5.000000e+000,5.000000e-001,2,1,9.727478e-004,0,1,0,
1473078027.265,,-4.000000e+001,4.963324e+000,-1.105668e-003,0.000000e+000,3.752254e-003,0.000000e+000,3,9.826995e-001,1.825000e+000,,,,,,,,,,,,,,,,,,0,5.000000e+000,5.000000e-001,2,1,1.337051e-003,0,1,0,
1473078053.395,,-4.000000e+001,4.967217e+000,-1.105148e-003,0.000000e+000,4.031834e-003,0.000000e+000,3,9.822223e-001,1.825000e+000,,,,,,,,,,,,,,,,,,0,5.000000e+000,5.000000e-001,2,1,3.671646e-004,0,0,0,
1473078174.225,,-2.000000e+001,4.962777e+000,-1.090831e-003,0.000000e+000,3.730527e-003,0.000000e+000,3,9.833167e-001,1.825000e+000,,,,,,,,,,,,,,,,,,0,5.000000e+000,5.000000e-001,2,1,2.915859e-003,0,0,0,
1473078197.903,,-2.000000e+001,4.965817e+000,-1.089301e-003,0.000000e+000,3.866032e-003,0.000000e+000,3,9.828970e-001,1.825000e+000,,,,,,,,,,,,,,,,,,0,5.000000e+000,5.000000e-001,2,1,2.450943e-004,0,0,0,
1473078316.854,,0.000000e+000,4.960651e+000,-1.072385e-003,0.000000e+000,3.833583e-003,0.000000e+000,3,9.835802e-001,1.825000e+000,,,,,,,,,,,,,,,,,,0,5.000000e+000,5.000000e-001,2,1,1.335144e-003,0,1,0,
1473078340.835,,0.000000e+000,4.964662e+000,-1.073003e-003,0.000000e+000,4.238010e-003,0.000000e+000,3,9.830430e-001,1.825000e+000,,,,,,,,,,,,,,,,,,0,5.000000e+000,5.000000e-001,2,1,1.220703e-004,0,1,0,
1473078459.023,,2.000000e+001,4.962473e+000,-1.048981e-003,0.000000e+000,4.203930e-003,0.000000e+000,3,9.841895e-001,1.825000e+000,,,,,,,,,,,,,,,,,,0,5.000000e+000,5.000000e-001,2,1,2.795219e-003,0,1,0,
1473078482.474,,2.000000e+001,4.966427e+000,-1.047979e-003,0.000000e+000,4.034359e-003,0.000000e+000,3,9.844078e-001,1.825000e+000,,,,,,,,,,,,,,,,,,0,5.000000e+000,5.000000e-001,2,1,4.868507e-004,0,0,0,
1473078604.972,,4.000000e+001,4.963020e+000,-1.016717e-003,0.000000e+000,5.457249e-003,0.000000e+000,3,9.837111e-001,1.825000e+000,,,,,,,,,,,,,,,,,,0,5.000000e+000,5.000000e-001,2,1,2.674103e-003,0,0,0,
1473078630.849,,4.000000e+001,4.965635e+000,-1.016656e-003,0.000000e+000,4.929529e-003,0.000000e+000,3,9.839804e-001,1.825000e+000,,,,,,,,,,,,,,,,,,0,5.000000e+000,5.000000e-001,2,1,3.638268e-004,0,0,0,
1473078759.647,,6.000000e+001,4.961562e+000,-9.674075e-004,0.000000e+000,4.855540e-003,0.000000e+000,3,9.843749e-001,1.825000e+000,,,,,,,,,,,,,,,,,,0,5.000000e+000,5.000000e-001,2,1,2.671719e-003,0,1,0,
1473078782.511,,6.000000e+001,4.964844e+000,-9.665480e-004,0.000000e+000,4.673689e-003,0.000000e+000,3,9.849042e-001,1.825000e+000,,,,,,,,,,,,,,,,,,0,5.000000e+000,5.000000e-001,2,1,4.858971e-004,0,1,0,
1473078902.811,,8.000000e+001,4.963324e+000,-8.649884e-004,0.000000e+000,4.831873e-003,0.000000e+000,3,9.853494e-001,1.825000e+000,,,,,,,,,,,,,,,,,,0,5.000000e+000,5.000000e-001,2,1,1.220703e-004,0,0,0,
1473078929.007,,8.000000e+001,4.968313e+000,-8.613251e-004,0.000000e+000,4.886074e-003,0.000000e+000,3,9.855650e-001,1.825000e+000,,,,,,,,,,,,,,,,,,0,5.000000e+000,5.000000e-001,2,1,1.206398e-004,0,0,0,
1473079057.660,,1.000000e+002,4.966852e+000,1.240873e-005,0.000000e+000,-2.073849e-001,0.000000e+000,3,0.000000e+000,1.825000e+000,,,,,,,,,,,,,,,,,,0,5.000000e+000,5.000000e-001,2,1,2.314091e-003,0,0,0,
1473079092.864,,1.000000e+002,4.967095e+000,2.129031e-005,0.000000e+000,-1.230709e-001,0.000000e+000,3,6.959595e-001,1.825000e+000,,,,,,,,,,,,,,,,,,0,5.000000e+000,5.000000e-001,2,1,1.220703e-004,0,0,0,
1473079231.906,,1.200000e+002,4.965635e+000,3.228078e-004,0.000000e+000,-1.935692e-003,0.000000e+000,3,9.694130e-001,1.825000e+000,,,,,,,,,,,,,,,,,,0,5.000000e+000,5.000000e-001,2,1,8.521080e-004,0,1,0,
1473079255.489,,1.200000e+002,4.966244e+000,3.258828e-004,0.000000e+000,-2.956540e-004,0.000000e+000,3,9.662198e-001,1.825000e+000,,,,,,,,,,,,,,,,,,0,5.000000e+000,5.000000e-001,2,1,3.647804e-004,0,1,0,
1473079386.907,,1.400000e+002,4.966852e+000,4.262342e-004,0.000000e+000,1.304704e-003,0.000000e+000,3,9.682035e-001,1.825000e+000,,,,,,,,,,,,,,,,,,0,5.000000e+000,5.000000e-001,2,1,3.286839e-003,0,0,0,
1473079412.836,,1.400000e+002,4.967887e+000,4.270589e-004,0.000000e+000,9.282281e-004,0.000000e+000,3,9.686214e-001,1.825000e+000,,,,,,,,,,,,,,,,,,0,5.000000e+000,5.000000e-001,2,1,9.727478e-004,0,0,0,
1473079534.274,,1.600000e+002,4.963993e+000,4.972905e-004,0.000000e+000,1.113426e-003,0.000000e+000,3,9.705592e-001,1.825000e+000,,,,,,,,,,,,,,,,,,0,5.000000e+000,5.000000e-001,2,1,1.215935e-003,0,1,0,
1473079558.952,,1.600000e+002,4.966791e+000,4.998788e-004,0.000000e+000,9.221627e-004,0.000000e+000,3,9.704165e-001,1.825000e+000,,,,,,,,,,,,,,,,,,0,5.000000e+000,5.000000e-001,2,1,1.948833e-003,0,1,0,
1473079688.183,,1.800000e+002,4.965756e+000,5.567871e-004,0.000000e+000,1.446337e-003,0.000000e+000,3,9.699303e-001,1.825000e+000,,,,,,,,,,,,,,,,,,0,5.000000e+000,5.000000e-001,2,1,2.799034e-003,0,1,0,
1473079711.894,,1.800000e+002,4.967887e+000,5.587568e-004,0.000000e+000,1.676821e-003,0.000000e+000,3,9.700617e-001,1.825000e+000,,,,,,,,,,,,,,,,,,0,5.000000e+000,5.000000e-001,2,1,1.217842e-003,0,0,0,
1473079830.679,,2.000000e+002,4.966061e+000,6.061061e-004,0.000000e+000,2.402881e-003,0.000000e+000,3,9.695936e-001,1.825000e+000,,,,,,,,,,,,,,,,,,0,5.000000e+000,5.000000e-001,2,1,2.190113e-003,0,0,0,
1473079856.117,,2.000000e+002,4.968619e+000,6.073968e-004,0.000000e+000,8.464672e-004,0.000000e+000,3,9.709556e-001,1.825000e+000,,,,,,,,,,,,,,,,,,0,5.000000e+000,5.000000e-001,2,1,1.461983e-003,0,0,0,
1473079989.813,,3.000000e+002,4.965635e+000,7.944187e-004,0.000000e+000,1.682665e-003,0.000000e+000,3,9.699432e-001,1.825000e+000,,,,,,,,,,,,,,,,,,0,5.000000e+000,5.000000e-001,2,1,2.312183e-003,0,1,0,
1473080014.991,,3.000000e+002,4.968375e+000,7.966588e-004,0.000000e+000,9.389840e-004,0.000000e+000,3,9.709458e-001,1.825000e+000,,,,,,,,,,,,,,,,,,0,5.000000e+000,5.000000e-001,2,1,1.461983e-003,0,1,0,
1473080150.913,,4.000000e+002,4.968496e+000,9.059836e-004,0.000000e+000,-1.215523e-002,0.000000e+000,3,9.548609e-001,1.825000e+000,,,,,,,,,,,,,,,,,,0,5.000000e+000,5.000000e-001,2,1,4.868507e-004,0,1,0,
1473080177.092,,4.000000e+002,4.969716e+000,9.188118e-004,0.000000e+000,1.679418e-003,0.000000e+000,3,9.688988e-001,1.825000e+000,,,,,,,,,,,,,,,,,,0,5.000000e+000,5.000000e-001,2,1,0.000000e+000,0,0,0,
1473080311.583,,5.000000e+002,4.966852e+000,9.983419e-004,0.000000e+000,1.789710e-003,0.000000e+000,3,9.673689e-001,1.825000e+000,,,,,,,,,,,,,,,,,,0,5.000000e+000,5.000000e-001,2,1,3.043652e-003,0,0,0,
1473080336.317,,5.000000e+002,4.969959e+000,9.990892e-004,0.000000e+000,1.800759e-003,0.000000e+000,3,9.675323e-001,1.825000e+000,,,,,,,,,,,,,,,,,,0,5.000000e+000,5.000000e-001,2,1,7.309914e-004,0,0,0,
1473080462.477,,6.000000e+002,4.964965e+000,1.050965e-003,0.000000e+000,1.955631e-003,0.000000e+000,3,9.656634e-001,1.825000e+000,,,,,,,,,,,,,,,,,,0,5.000000e+000,5.000000e-001,2,1,1.460075e-003,0,1,0,
1473080487.263,,6.000000e+002,4.968923e+000,1.053255e-003,0.000000e+000,1.501871e-003,0.000000e+000,3,9.661276e-001,1.825000e+000,,,,,,,,,,,,,,,,,,0,5.000000e+000,5.000000e-001,2,1,8.540154e-004,0,1,0,
1473080620.203,,7.000000e+002,4.968071e+000,1.089041e-003,0.000000e+000,1.731473e-003,0.000000e+000,3,9.652194e-001,1.825000e+000,,,,,,,,,,,,,,,,,,0,5.000000e+000,5.000000e-001,2,1,3.290176e-003,0,1,0,
1473080646.221,,7.000000e+002,4.971363e+000,1.090340e-003,0.000000e+000,1.539386e-003,0.000000e+000,3,9.652115e-001,1.825000e+000,,,,,,,,,,,,,,,,,,0,5.000000e+000,5.000000e-001,2,1,1.211166e-004,0,0,0,
1473080774.161,,1.000000e+003,4.967157e+000,1.147482e-003,0.000000e+000,1.112707e-003,0.000000e+000,3,9.626049e-001,1.825000e+000,,,,,,,,,,,,,,,,,,0,5.000000e+000,5.000000e-001,2,1,9.741783e-004,0,0,0,
1473080798.838,,1.000000e+003,4.971789e+000,1.148682e-003,0.000000e+000,1.406971e-003,0.000000e+000,3,9.625445e-001,1.825000e+000,,,,,,,,,,,,,,,,,,0,5.000000e+000,5.000000e-001,2,1,2.431870e-004,0,0,0,
1473080927.229,,3.000000e+003,4.967218e+000,1.240731e-003,0.000000e+000,3.103313e-004,0.000000e+000,3,9.575551e-001,1.825000e+000,,,,,,,,,,,,,,,,,,0,5.000000e+000,5.000000e-001,2,1,3.289223e-003,0,1,0,
1473080950.569,,3.000000e+003,4.969594e+000,1.240094e-003,0.000000e+000,3.614156e-004,0.000000e+000,3,9.568872e-001,1.825000e+000,,,,,,,,,,,,,,,,,,0,5.000000e+000,5.000000e-001,2,1,1.217842e-003,0,1,0,
1473081089.520,,5.000000e+003,4.969960e+000,1.265746e-003,0.000000e+000,1.946381e-004,0.000000e+000,3,9.561794e-001,1.825000e+000,,,,,,,,,,,,,,,,,,0,5.000000e+000,5.000000e-001,2,1,1.708031e-003,0,1,0,
1473081112.948,,5.000000e+003,4.974110e+000,1.265327e-003,0.000000e+000,2.069040e-004,0.000000e+000,3,9.558558e-001,1.825000e+000,,,,,,,,,,,,,,,,,,0,5.000000e+000,5.000000e-001,2,1,7.338524e-004,0,0,0,
1473081249.449,,7.000000e+003,4.969656e+000,1.280100e-003,0.000000e+000,3.699949e-004,0.000000e+000,3,9.561379e-001,1.825000e+000,,,,,,,,,,,,,,,,,,0,5.000000e+000,5.000000e-001,2,1,3.293037e-003,0,0,0,
1473081275.877,,7.000000e+003,4.972339e+000,1.280199e-003,0.000000e+000,3.521721e-004,0.000000e+000,3,9.561768e-001,1.825000e+000,,,,,,,,,,,,,,,,,,0,5.000000e+000,5.000000e-001,2,1,3.657341e-004,0,0,0,
1473081412.817,,9.000000e+003,4.968071e+000,1.290202e-003,0.000000e+000,5.122139e-004,0.000000e+000,3,9.563258e-001,1.825000e+000,,,,,,,,,,,,,,,,,,0,5.000000e+000,5.000000e-001,2,1,1.585007e-003,0,1,0,
1473081439.240,,9.000000e+003,4.972156e+000,1.290397e-003,0.000000e+000,6.327396e-004,0.000000e+000,3,9.559759e-001,1.825000e+000,,,,,,,,,,,,,,,,,,0,5.000000e+000,5.000000e-001,2,1,0.000000e+000,0,1,0,
1473081570.579,,1.000000e+004,4.972644e+000,1.302032e-003,0.000000e+000,2.371404e-003,0.000000e+000,3,9.566885e-001,1.825000e+000,,,,,,,,,,,,,,,,,,0,5.000000e+000,5.000000e-001,2,1,1.709938e-003,0,1,0,
1473081594.257,,1.000000e+004,4.980228e+000,1.294524e-003,0.000000e+000,6.216909e-004,0.000000e+000,3,9.561681e-001,1.825000e+000,,,,,,,,,,,,,,,,,,0,5.000000e+000,5.000000e-001,2,1,4.654884e-003,0,0,0,
1473081763.950,,2.000000e+004,4.971912e+000,1.319871e-003,0.000000e+000,1.476711e-003,0.000000e+000,3,9.562739e-001,1.825000e+000,,,,,,,,,,,,,,,,,,0,5.000000e+000,5.000000e-001,2,1,2.439976e-003,0,0,0,
1473081791.156,,2.000000e+004,4.975637e+000,1.319671e-003,0.000000e+000,1.526230e-003,0.000000e+000,3,9.561350e-001,1.825000e+000,,,,,,,,,,,,,,,,,,0,5.000000e+000,5.000000e-001,2,1,1.588821e-003,0,0,0,
1473081966.904,,3.000000e+004,4.967340e+000,1.331972e-003,0.000000e+000,2.030622e-003,0.000000e+000,3,9.560157e-001,1.825000e+000,,,,,,,,,,,,,,,,,,0,5.000000e+000,5.000000e-001,2,1,4.992962e-003,0,1,0,
1473081991.332,,3.000000e+004,4.974049e+000,1.331191e-003,0.000000e+000,2.106415e-003,0.000000e+000,3,9.572020e-001,1.825000e+000,,,,,,,,,,,,,,,,,,0,5.000000e+000,5.000000e-001,2,1,1.832962e-003,0,1,0,
1473082168.807,,4.000000e+004,4.981453e+000,1.336643e-003,0.000000e+000,3.144514e-003,0.000000e+000,3,9.555770e-001,1.825000e+000,,,,,,,,,,,,,,,,,,0,5.000000e+000,5.000000e-001,2,1,2.205849e-003,0,0,0,
1473082195.237,,4.000000e+004,4.991226e+000,1.335714e-003,0.000000e+000,2.910674e-003,0.000000e+000,3,9.557732e-001,1.825000e+000,,,,,,,,,,,,,,,,,,0,5.000000e+000,5.000000e-001,2,1,8.496761e-003,0,0,0,
1473082371.992,,5.000000e+004,4.968740e+000,1.334809e-003,0.000000e+000,3.325836e-003,0.000000e+000,3,9.551990e-001,1.825000e+000,,,,,,,,,,,,,,,,,,0,5.000000e+000,5.000000e-001,2,1,2.436638e-003,0,1,0,
1473082396.670,,5.000000e+004,4.976861e+000,1.333612e-003,0.000000e+000,3.596164e-003,0.000000e+000,3,9.549803e-001,1.825000e+000,,,,,,,,,,,,,,,,,,0,5.000000e+000,5.000000e-001,2,1,2.079964e-003,0,1,0,
1473082572.868,,6.000000e+004,5.040554e+000,1.328808e-003,0.000000e+000,3.596614e-003,0.000000e+000,3,9.168247e-001,1.825000e+000,,,,,,,,,,,,,,,,,,0,5.000000e+000,5.000000e-001,2,1,7.433891e-003,0,1,0,
1473082598.296,,6.000000e+004,5.060502e+000,1.327736e-003,0.000000e+000,5.913599e-003,0.000000e+000,3,9.528725e-001,1.825000e+000,,,,,,,,,,,,,,,,,,0,5.000000e+000,5.000000e-001,2,1,1.652908e-002,0,0,0,
1473082778.292,,7.000000e+004,5.133681e+000,1.321235e-003,0.000000e+000,4.279562e-003,0.000000e+000,3,9.542210e-001,1.825000e+000,,,,,,,,,,,,,,,,,,0,5.000000e+000,5.000000e-001,2,1,3.551960e-003,0,0,0,
1473082805.740,,7.000000e+004,5.149926e+000,1.320856e-003,0.000000e+000,4.422777e-003,0.000000e+000,3,9.539946e-001,1.825000e+000,,,,,,,,,,,,,,,,,,0,5.000000e+000,5.000000e-001,2,1,7.026196e-003,0,0,0,
1473082820.954,,7.000000e+004,5.159291e+000,1.320414e-003,0.000000e+000,4.414810e-003,0.000000e+000,3,9.538942e-001,1.825000e+000,,,,,,,,,,,,,,,,,,0,5.000000e+000,5.000000e-001,2,1,5.857944e-003,0,0,0,