File: data/A344/A344_GdN_ZFC_050_Oe_160908.rso.raw
[Header]
TITLE,MPMS RSO Measurement
BYAPP,MPMS Measurement,2.1,Raw with ABS
FILEOPENTIME, 1473337409.834000 9/9/2016, 12:23:29 AM

INFO, APPNAME, MPMS MultiVu Application, Revision 1.61,  Build 082

INFO, NAME, A344
INFO, WEIGHT, 10.500
INFO, AREA, 1.000
INFO, LENGTH, 1.000
INFO, SHAPE, 0
INFO, COMMENT, m = 0.0105g
INFO, SEQUENCE FILE: ZFC_5K-120K.seq


INFO, BACKGROUND DATA FILE:, None


STARTUPAXIS,X,8,LINEAR,AUTO,0.000000,0.000000
STARTUPAXIS,Y1,9,LINEAR,AUTO,0.000000,0.000000


STARTUPGROUP,Longitudinal
FIELDGROUP,Longitudinal,1,2,3,4,5,6,7,8,9,10,11,12,13,14,15,16,17,18,19,20,21,22
FIELDGROUP,Transverse,1,2,3,4,5,6,7,8,23,24,25,26,27,28,29,30,31,32,33,34,35,36

PLOT_APPEARANCE,ALL,HORZ_GRID_ON,VERT_GRID_ON,MARKERS_ONLY

[Data]
Time,Comment,Field (Oe),Start Temperature (K),End Temperature (K),Scan,Rejected,Position (cm),Long Voltage,Long Average Voltage,Long Detrended Voltage,Long Demeaned Voltage,Long Reg Fit,Long Detrended Fit,Long Demeaned Fit,Long Scaled Response,Long Avg. Scaled Response,Long Background Response,Long Response [w/ABS],Long Detrended Resp. [w/ABS],Long Fit [w/ABS],Long Detrended Fit [w/ABS],Trans Voltage,Trans Average Voltage,Trans Detrended Voltage,Trans Demeaned Voltage,Trans Reg Fit,Trans Detrended Fit,Trans Demeaned Fit,Trans Scaled Response,Trans Avg. Scaled Response,Trans Background Response,Trans Response [w/ABS],Trans Detrended Resp. [w/ABS],Trans Adjusted Fit,Trans Detrended Fit [w/ABS],
1473337409.826,,5.000000e+001,4.946432e+000,4.951020e+000,1,0,2.591152e+000,1.390118e-001,1.390118e-001,1.682929e+000,1.682929e+000,1.583181e-001,1.702236e+000,1.702236e+000,6.964234e-005,6.964234e-005,,,,,,,,,,,,,,,,,,,,
1473337409.826,,5.000000e+001,4.946432e+000,4.951020e+000,1,0,4.825611e+000,-1.927702e+000,-1.927702e+000,-3.840502e-001,-3.837841e-001,-1.910252e+000,-3.666006e-001,-3.663344e-001,-9.657428e-004,-9.657428e-004,,,,,,,,,,,,,,,,,,,,
1473337421.787,,5.000000e+001,4.951020e+000,4.951383e+000,1,0,3.736649e+000,-2.000183e+000,-2.000183e+000,-4.553327e-001,-4.552609e-001,-2.000528e+000,-4.556772e-001,-4.556054e-001,-1.002055e-003,-1.002055e-003,,,,,,,,,,,,,,,,,,,,
1473337434.499,,5.000000e+001,4.951866e+000,4.950657e+000,1,0,1.025333e+000,-2.232276e+000,-2.232276e+000,-6.874106e-001,-6.872455e-001,-2.259202e+000,-7.143364e-001,-7.141713e-001,-1.118329e-003,-1.118329e-003,,,,,,,,,,,,,,,,,,,,
1473337445.961,,5.000000e+001,4.951383e+000,4.950294e+000,1,0,2.335412e-001,-1.952269e+000,-1.952269e+000,-4.073751e-001,-4.072967e-001,-1.942037e+000,-3.971428e-001,-3.970643e-001,-9.780506e-004,-9.780506e-004,,,,,,,,,,,,,,,,,,,,
1473337445.961,,5.000000e+001,4.951383e+000,4.950294e+000,1,0,2.812304e+000,-1.016266e-001,-1.016266e-001,1.442934e+000,1.443346e+000,-1.247094e-001,1.419851e+000,1.420263e+000,-5.091306e-005,-5.091306e-005,,,,,,,,,,,,,,,,,,,,
1473337553.169,,5.000000e+001,6.101620e+000,6.285388e+000,1,0,4.910374e+000,-2.225105e+000,-2.225105e+000,-3.089886e-001,-6.492299e-001,-2.243255e+000,-3.271390e-001,-6.673802e-001,-1.114736e-003,-1.114736e-003,,,,,,,,,,,,,,,,,,,,
1473337567.632,,5.000000e+001,6.321944e+000,6.547426e+000,1,0,3.525685e+000,-1.647847e+000,-1.647847e+000,-9.911188e-002,-9.875810e-002,-1.648006e+000,-9.927055e-002,-9.891677e-002,-8.255407e-004,-8.255407e-004,,,,,,,,,,,,,,,,,,,,
1473337579.595,,5.000000e+001,6.547426e+000,6.699438e+000,1,0,8.595703e-001,-2.294534e+000,-2.294534e+000,-7.447845e-001,-7.446336e-001,-2.319066e+000,-7.693166e-001,-7.691656e-001,-1.149519e-003,-1.149519e-003,,,,,,,,,,,,,,,,,,,,
1473337592.811,,5.000000e+001,6.777765e+000,6.927696e+000,1,0,3.631069e-001,-2.050844e+000,-2.050844e+000,-4.998692e-001,-4.997901e-001,-2.044359e+000,-4.933842e-001,-4.933051e-001,-1.027435e-003,-1.027435e-003,,,,,,,,,,,,,,,,,,,,
1473337592.811,,5.000000e+001,6.777765e+000,6.927696e+000,1,0,3.027254e+000,-5.125583e-001,-5.125583e-001,1.038049e+000,1.038496e+000,-5.612925e-001,9.893152e-001,9.897614e-001,-2.567823e-004,-2.567823e-004,,,,,,,,,,,,,,,,,,,,
1473337616.086,,5.000000e+001,7.140015e+000,7.298593e+000,1,0,4.967551e+000,-1.863918e+000,-1.863918e+000,-3.118863e-001,-3.111907e-001,-1.849176e+000,-2.971447e-001,-2.964492e-001,-9.337884e-004,-9.337884e-004,,,,,,,,,,,,,,,,,,,,
1473337629.049,,5.000000e+001,7.336732e+000,7.477795e+000,1,0,3.308634e+000,-5.153050e-001,-5.153050e-001,3.582491e-001,3.587524e-001,-5.215176e-001,3.520365e-001,3.525398e-001,-2.581583e-004,-2.581583e-004,,,,,,,,,,,,,,,,,,,,
1473337639.762,,5.000000e+001,7.515215e+000,7.668210e+000,1,0,7.006119e-001,-2.269662e+000,-2.269662e+000,-7.164328e-001,-7.160771e-001,-2.283674e+000,-7.304447e-001,-7.300889e-001,-1.137058e-003,-1.137058e-003,,,,,,,,,,,,,,,,,,,,
1473337653.905,,5.000000e+001,7.706402e+000,7.898024e+000,1,0,5.144113e-001,-2.163305e+000,-2.163305e+000,-6.093942e-001,-6.092577e-001,-2.165444e+000,-6.115340e-001,-6.113975e-001,-1.083775e-003,-1.083775e-003,,,,,,,,,,,,,,,,,,,,
1473337653.905,,5.000000e+001,7.706402e+000,7.898024e+000,1,0,3.234351e+000,-9.875790e-001,-9.875790e-001,5.656353e-001,5.664679e-001,-1.032380e+000,5.208345e-001,5.216671e-001,-4.947588e-004,-4.947588e-004,,,,,,,,,,,,,,,,,,,,
1473337676.164,,5.000000e+001,8.124521e+000,8.280554e+000,1,0,4.993498e+000,-1.181219e+000,-1.181219e+000,-3.047591e-001,-3.039857e-001,-1.164338e+000,-2.878788e-001,-2.871053e-001,-5.917688e-004,-5.917688e-004,,,,,,,,,,,,,,,,,,,,
1473337688.485,,5.000000e+001,8.317774e+000,8.457533e+000,1,0,3.086635e+000,-6.810206e-001,-6.810206e-001,8.755128e-001,8.760291e-001,-6.876539e-001,8.688795e-001,8.693957e-001,-3.411787e-004,-3.411787e-004,,,,,,,,,,,,,,,,,,,,
1473337702.198,,5.000000e+001,8.527245e+000,8.678802e+000,1,0,5.499732e-001,-2.200232e+000,-2.200232e+000,-6.423808e-001,-6.419861e-001,-2.201129e+000,-6.432779e-001,-6.428833e-001,-1.102275e-003,-1.102275e-003,,,,,,,,,,,,,,,,,,,,
1473337715.161,,5.000000e+001,8.716906e+000,8.861971e+000,1,0,6.833805e-001,-1.597339e+000,-1.597339e+000,-7.170399e-001,-7.168683e-001,-1.612243e+000,-7.319437e-001,-7.317721e-001,-8.002371e-004,-8.002371e-004,,,,,,,,,,,,,,,,,,,,
1473337715.161,,5.000000e+001,8.716906e+000,8.861971e+000,1,0,3.432611e+000,-7.684560e-001,-7.684560e-001,1.108704e-001,1.120145e-001,-7.910995e-001,8.822687e-002,8.937097e-002,-3.849822e-004,-3.849822e-004,,,,,,,,,,,,,,,,,,,,
1473337734.820,,5.000000e+001,9.035191e+000,9.184057e+000,1,0,4.986028e+000,-1.194952e+000,-1.194952e+000,-3.135288e-001,-3.127642e-001,-1.176182e+000,-2.947583e-001,-2.939938e-001,-5.986489e-004,-5.986489e-004,,,,,,,,,,,,,,,,,,,,
1473337746.141,,5.000000e+001,9.222660e+000,9.391264e+000,1,0,2.861357e+000,4.979095e-001,4.979095e-001,1.380633e+000,1.381216e+000,5.101076e-001,1.392831e+000,1.393414e+000,2.494434e-004,2.494434e-004,,,,,,,,,,,,,,,,,,,,
1473337758.658,,5.000000e+001,9.431192e+000,9.589895e+000,1,0,4.096136e-001,-1.438337e+000,-1.438337e+000,-5.540579e-001,-5.536757e-001,-1.428434e+000,-5.441547e-001,-5.437725e-001,-7.205803e-004,-7.205803e-004,,,,,,,,,,,,,,,,,,,,
1473337771.371,,5.000000e+001,9.667303e+000,9.826957e+000,1,0,8.664293e-001,-1.655629e+000,-1.655629e+000,-7.698453e-001,-7.696768e-001,-1.684242e+000,-7.984583e-001,-7.982898e-001,-8.294395e-004,-8.294395e-004,,,,,,,,,,,,,,,,,,,,
1473337771.371,,5.000000e+001,9.667303e+000,9.826957e+000,1,0,3.621768e+000,-1.163213e+000,-1.163213e+000,-2.785032e-001,-2.772607e-001,-1.171721e+000,-2.870117e-001,-2.857691e-001,-5.827482e-004,-5.827482e-004,,,,,,,,,,,,,,,,,,,,
1473337800.087,,5.000000e+001,1.006008e+001,1.026547e+001,1,0,4.944688e+000,-1.227454e+000,-1.227454e+000,-3.395781e-001,-3.386569e-001,-1.207587e+000,-3.197108e-001,-3.187896e-001,-6.149319e-004,-6.149319e-004,,,,,,,,,,,,,,,,,,,,
1473337813.093,,5.000000e+001,1.030478e+001,1.046689e+001,1,0,2.634875e+000,8.499405e-001,8.499405e-001,1.739768e+000,1.740447e+000,8.852195e-001,1.775047e+000,1.775726e+000,4.258044e-004,4.258044e-004,,,,,,,,,,,,,,,,,,,,
1473337825.557,,5.000000e+001,1.050684e+001,1.071367e+001,1,0,2.832420e-001,-1.362194e+000,-1.362194e+000,-4.707023e-001,-4.703190e-001,-1.348641e+000,-4.571492e-001,-4.567660e-001,-6.824338e-004,-6.824338e-004,,,,,,,,,,,,,,,,,,,,
1473337839.019,,5.000000e+001,1.076398e+001,1.093250e+001,1,0,1.060697e+000,-1.601001e+000,-1.601001e+000,-7.062878e-001,-7.061796e-001,-1.633218e+000,-7.385045e-001,-7.383962e-001,-8.020718e-004,-8.020718e-004,,,,,,,,,,,,,,,,,,,,
1473337839.019,,5.000000e+001,1.076398e+001,1.093250e+001,1,0,3.802359e+000,-1.475417e+000,-1.475417e+000,-5.814927e-001,-5.805959e-001,-1.475777e+000,-5.818527e-001,-5.809559e-001,-7.391567e-004,-7.391567e-004,,,,,,,,,,,,,,,,,,,,
1473337855.748,,5.000000e+001,1.105520e+001,1.122304e+001,1,0,4.870905e+000,-1.279794e+000,-1.279794e+000,-3.852238e-001,-3.831212e-001,-1.259624e+000,-3.650544e-001,-3.629518e-001,-6.411529e-004,-6.411529e-004,,,,,,,,,,,,,,,,,,,,
1473337867.961,,5.000000e+001,1.126378e+001,1.142828e+001,1,0,2.409881e+000,9.141819e-001,9.141819e-001,1.799619e+000,1.800791e+000,9.370138e-001,1.822451e+000,1.823623e+000,4.579882e-004,4.579882e-004,,,,,,,,,,,,,,,,,,,,
1473337881.924,,5.000000e+001,1.146817e+001,1.163511e+001,1,0,1.752819e-001,1.431929e+000,1.431929e+000,-1.943416e-001,-6.404245e-002,1.346907e+000,-2.793632e-001,-1.490641e-001,7.173696e-004,7.173696e-004,,,,,,,,,,,,,,,,,,,,
1473337894.681,,5.000000e+001,1.167527e+001,1.181811e+001,1,0,1.263967e+000,-1.373486e+000,-1.373486e+000,-4.836086e-001,-4.835494e-001,-1.395979e+000,-5.061024e-001,-5.060432e-001,-6.880908e-004,-6.880908e-004,,,,,,,,,,,,,,,,,,,,
1473337894.681,,5.000000e+001,1.167527e+001,1.181811e+001,1,0,3.975272e+000,-1.654256e+000,-1.654256e+000,-7.648820e-001,-7.643195e-001,-1.653858e+000,-7.644839e-001,-7.639214e-001,-8.287515e-004,-8.287515e-004,,,,,,,,,,,,,,,,,,,,
1473337921.644,,5.000000e+001,1.200275e+001,1.219201e+001,1,0,4.767313e+000,-1.355022e+000,-1.355022e+000,-4.591307e-001,-4.578905e-001,-1.332429e+000,-4.365380e-001,-4.352978e-001,-6.788408e-004,-6.788408e-004,,,,,,,,,,,,,,,,,,,,
1473337934.107,,5.000000e+001,1.226371e+001,1.240578e+001,1,0,2.188582e+000,6.460769e-001,6.460769e-001,1.543039e+000,1.543999e+000,6.259667e-001,1.522929e+000,1.523889e+000,3.236725e-004,3.236725e-004,,,,,,,,,,,,,,,,,,,,
1473337948.820,,5.000000e+001,1.253054e+001,1.265914e+001,1,0,9.039298e-002,-1.247902e+000,-1.247902e+000,-3.500877e-001,-3.495498e-001,-1.239791e+000,-3.419773e-001,-3.414394e-001,-6.251757e-004,-6.251757e-004,,,,,,,,,,,,,,,,,,,,
1473337963.033,,5.000000e+001,1.273837e+001,1.290379e+001,1,0,1.474916e+000,-1.012146e+000,-1.012146e+000,-1.137739e-001,-1.136200e-001,-1.024638e+000,-1.262655e-001,-1.261116e-001,-5.070666e-004,-5.070666e-004,,,,,,,,,,,,,,,,,,,,
1473337963.033,,5.000000e+001,1.273837e+001,1.290379e+001,1,0,4.141200e+000,-1.725059e+000,-1.725059e+000,-8.282566e-001,-8.265324e-001,-1.722367e+000,-8.255651e-001,-8.238409e-001,-8.642225e-004,-8.642225e-004,,,,,,,,,,,,,,,,,,,,
1473337983.996,,5.000000e+001,1.306409e+001,1.326643e+001,1,0,4.637706e+000,-1.457869e+000,-1.457869e+000,-5.600799e-001,-5.587601e-001,-1.434537e+000,-5.367482e-001,-5.354283e-001,-7.303655e-004,-7.303655e-004,,,,,,,,,,,,,,,,,,,,
1473337998.459,,5.000000e+001,1.330613e+001,1.350681e+001,1,0,1.973580e+000,1.931822e-001,1.931822e-001,1.091833e+000,1.092931e+000,1.425363e-001,1.041187e+000,1.042285e+000,9.678068e-005,9.678068e-005,,,,,,,,,,,,,,,,,,,,
1473338011.172,,5.000000e+001,1.358779e+001,1.374813e+001,1,0,3.315089e-002,-1.221503e+000,-1.221503e+000,-3.235761e-001,-3.228744e-001,-1.211751e+000,-3.138242e-001,-3.131225e-001,-6.119505e-004,-6.119505e-004,,,,,,,,,,,,,,,,,,,,
1473338023.385,,5.000000e+001,1.378593e+001,1.394502e+001,1,0,1.692037e+000,-5.325480e-001,-5.325480e-001,3.641385e-001,3.642930e-001,-5.415686e-001,3.551179e-001,3.552724e-001,-2.667967e-004,-2.667967e-004,,,,,,,,,,,,,,,,,,,,
1473338023.385,,5.000000e+001,1.378593e+001,1.394502e+001,1,0,4.300020e+000,-1.692709e+000,-1.692709e+000,-7.979919e-001,-7.958681e-001,-1.681385e+000,-7.866677e-001,-7.845439e-001,-8.480159e-004,-8.480159e-004,,,,,,,,,,,,,,,,,,,,
1473338042.405,,5.000000e+001,1.410170e+001,1.423093e+001,1,0,4.486378e+000,-1.573687e+000,-1.573687e+000,-6.817108e-001,-6.798382e-001,-1.553725e+000,-6.617488e-001,-6.598762e-001,-7.883880e-004,-7.883880e-004,,,,,,,,,,,,,,,,,,,,
1473338055.868,,5.000000e+001,1.431252e+001,1.446899e+001,1,0,1.766486e+000,-3.051851e-001,-3.051851e-001,5.846118e-001,5.857967e-001,-3.542337e-001,5.355632e-001,5.367482e-001,-1.528921e-004,-1.528921e-004,,,,,,,,,,,,,,,,,,,,
1473338068.025,,5.000000e+001,1.446899e+001,1.466274e+001,1,0,7.253086e-003,-1.203803e+000,-1.203803e+000,-3.150429e-001,-3.143771e-001,-1.191666e+000,-3.029066e-001,-3.022408e-001,-6.030828e-004,-6.030828e-004,,,,,,,,,,,,,,,,,,,,
1473338082.124,,5.000000e+001,1.473950e+001,1.489253e+001,1,0,1.914150e+000,-6.625568e-001,-6.625568e-001,9.041957e-001,9.043234e-001,-6.618978e-001,9.048547e-001,9.049824e-001,-3.319287e-004,-3.319287e-004,,,,,,,,,,,,,,,,,,,,
1473338082.124,,5.000000e+001,1.473950e+001,1.489253e+001,1,0,4.450788e+000,-2.280190e+000,-2.280190e+000,-7.156095e-001,-7.133102e-001,-2.257741e+000,-6.931605e-001,-6.908612e-001,-1.142333e-003,-1.142333e-003,,,,,,,,,,,,,,,,,,,,
1473338165.343,,5.000000e+001,1.499603e+001,1.499847e+001,1,0,4.317380e+000,-2.727744e+000,-2.727744e+000,-8.019460e-001,-8.004131e-001,-2.717658e+000,-7.918597e-001,-7.903268e-001,-1.366549e-003,-1.366549e-003,,,,,,,,,,,,,,,,,,,,
1473338178.308,,5.000000e+001,1.499847e+001,1.500030e+001,1,0,1.568247e+000,-1.817377e+000,-1.817377e+000,1.101642e-001,1.112213e-001,-1.854186e+000,7.335497e-002,7.441211e-002,-9.104723e-004,-9.104723e-004,,,,,,,,,,,,,,,,,,,,
1473338192.025,,5.000000e+001,1.499908e+001,1.500152e+001,1,0,1.471888e-002,-2.254708e+000,-2.254708e+000,-3.252520e-001,-3.246355e-001,-2.240461e+000,-3.110055e-001,-3.103890e-001,-1.129567e-003,-1.129567e-003,,,,,,,,,,,,,,,,,,,,
1473338203.294,,5.000000e+001,1.500152e+001,1.500030e+001,1,0,2.139338e+000,-4.832606e-001,-4.832606e-001,1.447168e+000,1.447250e+000,-4.609674e-001,1.469461e+000,1.469543e+000,-2.421046e-004,-2.421046e-004,,,,,,,,,,,,,,,,,,,,
1473338203.294,,5.000000e+001,1.500152e+001,1.500030e+001,1,0,4.591081e+000,-2.547685e+000,-2.547685e+000,-6.193414e-001,-6.171750e-001,-2.517430e+000,-5.890861e-001,-5.869197e-001,-1.276343e-003,-1.276343e-003,,,,,,,,,,,,,,,,,,,,
1473338295.016,,5.000000e+001,1.499908e+001,1.500030e+001,1,0,4.134316e+000,-2.763756e+000,-2.763756e+000,-8.521707e-001,-8.507789e-001,-2.765752e+000,-8.541667e-001,-8.527750e-001,-1.384591e-003,-1.384591e-003,,,,,,,,,,,,,,,,,,,,
1473338306.731,,5.000000e+001,1.500030e+001,1.500091e+001,1,0,1.379067e+000,-2.214270e+000,-2.214270e+000,-2.987221e-001,-2.978594e-001,-2.241013e+000,-3.254651e-001,-3.246024e-001,-1.109308e-003,-1.109308e-003,,,,,,,,,,,,,,,,,,,,
1473338320.140,,5.000000e+001,1.500213e+001,1.500091e+001,1,0,5.600832e-002,-2.267373e+000,-2.267373e+000,-3.482680e-001,-3.477390e-001,-2.254018e+000,-3.349130e-001,-3.343840e-001,-1.135912e-003,-1.135912e-003,,,,,,,,,,,,,,,,,,,,
1473338332.989,,5.000000e+001,1.500091e+001,1.500091e+001,1,0,2.365826e+000,-8.957183e-002,-8.957183e-002,1.832553e+000,1.832591e+000,-4.629398e-002,1.875831e+000,1.875869e+000,-4.487382e-005,-4.487382e-005,,,,,,,,,,,,,,,,,,,,
1473338332.989,,5.000000e+001,1.500091e+001,1.500091e+001,1,0,4.717464e+000,-2.441633e+000,-2.441633e+000,-5.214235e-001,-5.194708e-001,-2.412245e+000,-4.920353e-001,-4.900826e-001,-1.223213e-003,-1.223213e-003,,,,,,,,,,,,,,,,,,,,
1473338417.461,,5.000000e+001,1.818217e+001,1.875027e+001,1,0,3.940083e+000,-2.701041e+000,-2.701041e+000,-7.695212e-001,-7.679229e-001,-2.706584e+000,-7.750642e-001,-7.734659e-001,-1.353171e-003,-1.353171e-003,,,,,,,,,,,,,,,,,,,,
1473338431.675,,5.000000e+001,1.898364e+001,1.937465e+001,1,0,1.198375e+000,-2.541276e+000,-2.541276e+000,-6.075599e-001,-6.064668e-001,-2.567768e+000,-6.340520e-001,-6.329589e-001,-1.273132e-003,-1.273132e-003,,,,,,,,,,,,,,,,,,,,
1473338444.198,,5.000000e+001,1.959630e+001,2.007537e+001,1,0,1.298906e-001,-2.330241e+000,-2.330241e+000,-3.945406e-001,-3.939799e-001,-2.318407e+000,-3.827070e-001,-3.821462e-001,-1.167407e-003,-1.167407e-003,,,,,,,,,,,,,,,,,,,,
1473338457.932,,5.000000e+001,2.031019e+001,2.078575e+001,1,0,2.590889e+000,-6.561480e-003,-6.561480e-003,1.931053e+000,1.931053e+000,1.573643e-002,1.953351e+000,1.953351e+000,-3.287180e-006,-3.287180e-006,,,,,,,,,,,,,,,,,,,,
1473338457.932,,5.000000e+001,2.031019e+001,2.078575e+001,1,0,4.825495e+000,-2.376934e+000,-2.376934e+000,-4.414631e-001,-4.393196e-001,-2.356781e+000,-4.213096e-001,-4.191661e-001,-1.190800e-003,-1.190800e-003,,,,,,,,,,,,,,,,,,,,
1473338476.397,,5.000000e+001,2.114010e+001,2.160991e+001,1,0,3.736785e+000,-2.459639e+000,-2.459639e+000,-5.218967e-001,-5.200409e-001,-2.461008e+000,-5.232649e-001,-5.214092e-001,-1.232234e-003,-1.232234e-003,,,,,,,,,,,,,,,,,,,,
1473338489.361,,5.000000e+001,2.172592e+001,2.231252e+001,1,0,1.025462e+000,-2.737052e+000,-2.737052e+000,-7.973700e-001,-7.962264e-001,-2.765793e+000,-8.261108e-001,-8.249673e-001,-1.371213e-003,-1.371213e-003,,,,,,,,,,,,,,,,,,,,
1473338502.879,,5.000000e+001,2.254914e+001,2.289890e+001,1,0,2.334232e-001,-2.412488e+000,-2.412488e+000,-4.701848e-001,-4.695582e-001,-2.401545e+000,-4.592411e-001,-4.586146e-001,-1.208612e-003,-1.208612e-003,,,,,,,,,,,,,,,,,,,,
1473338502.879,,5.000000e+001,2.254914e+001,2.289890e+001,1,0,2.812171e+000,-2.658162e-001,-2.658162e-001,1.673825e+000,1.677114e+000,-2.912262e-001,1.648414e+000,1.651704e+000,-1.331690e-004,-1.331690e-004,,,,,,,,,,,,,,,,,,,,
1473338516.344,,5.000000e+001,2.313199e+001,2.371614e+001,1,0,4.910381e+000,-2.328562e+000,-2.328562e+000,-3.886529e-001,-3.859203e-001,-2.311716e+000,-3.718069e-001,-3.690743e-001,-1.166567e-003,-1.166567e-003,,,,,,,,,,,,,,,,,,,,
1473338532.808,,5.000000e+001,2.406548e+001,2.453061e+001,1,0,3.525841e+000,-2.052522e+000,-2.052522e+000,-1.100953e-001,-1.081194e-001,-2.053632e+000,-1.112052e-001,-1.092292e-001,-1.028276e-003,-1.028276e-003,,,,,,,,,,,,,,,,,,,,
1473338547.523,,5.000000e+001,2.476712e+001,2.523133e+001,1,0,8.594933e-001,-2.803125e+000,-2.803125e+000,-8.583114e-001,-8.570384e-001,-2.829160e+000,-8.843465e-001,-8.830734e-001,-1.404314e-003,-1.404314e-003,,,,,,,,,,,,,,,,,,,,
1473338558.499,,5.000000e+001,2.534656e+001,2.580962e+001,1,0,3.630087e-001,-2.520066e+000,-2.520066e+000,-5.723863e-001,-5.717486e-001,-2.512926e+000,-5.652461e-001,-5.646085e-001,-1.262506e-003,-1.262506e-003,,,,,,,,,,,,,,,,,,,,
1473338558.499,,5.000000e+001,2.534656e+001,2.580962e+001,1,0,3.027165e+000,-7.492294e-001,-7.492294e-001,1.195494e+000,1.199088e+000,-8.040349e-001,1.140688e+000,1.144282e+000,-3.753500e-004,-3.753500e-004,,,,,,,,,,,,,,,,,,,,
1473338571.713,,5.000000e+001,2.604405e+001,2.644845e+001,1,0,4.967536e+000,-2.303232e+000,-2.303232e+000,-3.578914e-001,-3.552977e-001,-2.286678e+000,-3.413378e-001,-3.387440e-001,-1.153877e-003,-1.153877e-003,,,,,,,,,,,,,,,,,,,,
1473338596.714,,5.000000e+001,2.718213e+001,2.767427e+001,1,0,3.308710e+000,-1.532640e+000,-1.532640e+000,4.156367e-001,4.175228e-001,-1.540111e+000,4.081650e-001,4.100511e-001,-7.678240e-004,-7.678240e-004,,,,,,,,,,,,,,,,,,,,
1473338607.928,,5.000000e+001,2.779947e+001,2.823482e+001,1,0,7.007192e-001,-2.770928e+000,-2.770928e+000,-8.206276e-001,-8.193351e-001,-2.785299e+000,-8.349987e-001,-8.337063e-001,-1.388184e-003,-1.388184e-003,,,,,,,,,,,,,,,,,,,,
1473338620.142,,5.000000e+001,2.835860e+001,2.884250e+001,1,0,5.143362e-001,-2.647328e+000,-2.647328e+000,-6.947909e-001,-6.942202e-001,-2.649329e+000,-6.967922e-001,-6.962215e-001,-1.326262e-003,-1.326262e-003,,,,,,,,,,,,,,,,,,,,
1473338620.142,,5.000000e+001,2.835860e+001,2.884250e+001,1,0,3.234290e+000,-1.298105e+000,-1.298105e+000,6.515219e-001,6.550032e-001,-1.348983e+000,6.006439e-001,6.041253e-001,-6.503264e-004,-6.503264e-004,,,,,,,,,,,,,,,,,,,,
1473338632.606,,5.000000e+001,2.896594e+001,2.945304e+001,1,0,4.993483e+000,-2.301096e+000,-2.301096e+000,-3.478255e-001,-3.453937e-001,-2.282120e+000,-3.288500e-001,-3.264182e-001,-1.152806e-003,-1.152806e-003,,,,,,,,,,,,,,,,,,,,
1473338655.821,,5.000000e+001,3.006212e+001,3.054768e+001,1,0,3.086647e+000,-9.448531e-001,-9.448531e-001,1.000849e+000,1.003550e+000,-9.521160e-001,9.935863e-001,9.962872e-001,-4.733539e-004,-4.733539e-004,,,,,,,,,,,,,,,,,,,,
1473338668.036,,5.000000e+001,3.079119e+001,3.115276e+001,1,0,5.498855e-001,-2.672506e+000,-2.672506e+000,-7.273057e-001,-7.261385e-001,-2.672108e+000,-7.269080e-001,-7.257408e-001,-1.338876e-003,-1.338876e-003,,,,,,,,,,,,,,,,,,,,
1473338681.752,,5.000000e+001,3.138768e+001,3.186784e+001,1,0,6.833277e-001,-2.761773e+000,-2.761773e+000,-8.100823e-001,-8.096291e-001,-2.777406e+000,-8.257159e-001,-8.252627e-001,-1.383597e-003,-1.383597e-003,,,,,,,,,,,,,,,,,,,,
1473338681.752,,5.000000e+001,3.138768e+001,3.186784e+001,1,0,3.432504e+000,-1.816767e+000,-1.816767e+000,1.323553e-001,1.353767e-001,-1.842902e+000,1.062199e-001,1.092412e-001,-9.101665e-004,-9.101665e-004,,,,,,,,,,,,,,,,,,,,
1473338694.466,,5.000000e+001,3.186784e+001,3.246289e+001,1,0,4.986036e+000,-2.306131e+000,-2.306131e+000,-3.546742e-001,-3.519921e-001,-2.284891e+000,-3.334338e-001,-3.307517e-001,-1.155329e-003,-1.155329e-003,,,,,,,,,,,,,,,,,,,,
1473338711.932,,5.000000e+001,3.294014e+001,3.341226e+001,1,0,2.861301e+000,-3.968932e-001,-3.968932e-001,1.556354e+000,1.558448e+000,-3.826907e-001,1.570556e+000,1.572651e+000,-1.988361e-004,-1.988361e-004,,,,,,,,,,,,,,,,,,,,
1473338724.432,,5.000000e+001,3.353087e+001,3.400718e+001,1,0,4.096397e-001,-2.572253e+000,-2.572253e+000,-6.181383e-001,-6.167872e-001,-2.560611e+000,-6.064973e-001,-6.051462e-001,-1.288651e-003,-1.288651e-003,,,,,,,,,,,,,,,,,,,,
1473338738.660,,5.000000e+001,3.424725e+001,3.459641e+001,1,0,8.663678e-001,-2.814264e+000,-2.814264e+000,-8.595020e-001,-8.590153e-001,-2.845112e+000,-8.903496e-001,-8.898629e-001,-1.409894e-003,-1.409894e-003,,,,,,,,,,,,,,,,,,,,
1473338738.660,,5.000000e+001,3.424725e+001,3.459641e+001,1,0,3.621737e+000,-2.256081e+000,-2.256081e+000,-3.044211e-001,-3.008319e-001,-2.265278e+000,-3.136183e-001,-3.100291e-001,-1.130255e-003,-1.130255e-003,,,,,,,,,,,,,,,,,,,,
1473338751.624,,5.000000e+001,3.495075e+001,3.530716e+001,1,0,4.944715e+000,-2.330393e+000,-2.330393e+000,-3.780189e-001,-3.752414e-001,-2.308455e+000,-3.560804e-001,-3.533028e-001,-1.167484e-003,-1.167484e-003,,,,,,,,,,,,,,,,,,,,
1473338787.591,,5.000000e+001,3.654093e+001,3.700877e+001,1,0,2.634926e+000,-8.972442e-002,-8.972442e-002,1.916138e+000,1.918296e+000,-5.032469e-002,1.955537e+000,1.957696e+000,-4.495027e-005,-4.495027e-005,,,,,,,,,,,,,,,,,,,,
1473338801.058,,5.000000e+001,3.724429e+001,3.770580e+001,1,0,2.832556e-001,-2.516404e+000,-2.516404e+000,-5.124550e-001,-5.111582e-001,-2.501325e+000,-4.973764e-001,-4.960797e-001,-1.260672e-003,-1.260672e-003,,,,,,,,,,,,,,,,,,,,
1473338814.772,,5.000000e+001,3.793512e+001,3.840145e+001,1,0,1.060602e+000,-2.775811e+000,-2.775811e+000,-7.729748e-001,-7.725565e-001,-2.809840e+000,-8.070039e-001,-8.065856e-001,-1.390630e-003,-1.390630e-003,,,,,,,,,,,,,,,,,,,,
1473338814.772,,5.000000e+001,3.793512e+001,3.840145e+001,1,0,3.802336e+000,-2.625965e+000,-2.625965e+000,-6.261768e-001,-6.227107e-001,-2.627194e+000,-6.274056e-001,-6.239395e-001,-1.315560e-003,-1.315560e-003,,,,,,,,,,,,,,,,,,,,
1473338827.789,,5.000000e+001,3.863327e+001,3.906629e+001,1,0,4.870909e+000,-2.418287e+000,-2.418287e+000,-4.194995e-001,-4.166899e-001,-2.396339e+000,-3.975519e-001,-3.947423e-001,-1.211517e-003,-1.211517e-003,,,,,,,,,,,,,,,,,,,,
1473338841.270,,5.000000e+001,3.917698e+001,3.974157e+001,1,0,2.409769e+000,-6.424146e-002,-6.424146e-002,1.933409e+000,1.935414e+000,-3.998766e-002,1.957662e+000,1.959668e+000,-3.218378e-005,-3.218378e-005,,,,,,,,,,,,,,,,,,,,
1473338854.734,,5.000000e+001,3.984993e+001,4.031377e+001,1,0,1.752421e-001,-2.419202e+000,-2.419202e+000,-4.223111e-001,-4.212792e-001,-2.409954e+000,-4.130626e-001,-4.120307e-001,-1.211975e-003,-1.211975e-003,,,,,,,,,,,,,,,,,,,,
1473338868.449,,5.000000e+001,4.065807e+001,4.100168e+001,1,0,1.264001e+000,-2.518082e+000,-2.518082e+000,-5.215282e-001,-5.212058e-001,-2.541350e+000,-5.447962e-001,-5.444738e-001,-1.261513e-003,-1.261513e-003,,,,,,,,,,,,,,,,,,,,
1473338868.449,,5.000000e+001,4.065807e+001,4.100168e+001,1,0,3.975331e+000,-2.802362e+000,-2.802362e+000,-8.085493e-001,-8.054858e-001,-2.802847e+000,-8.090345e-001,-8.059710e-001,-1.403932e-003,-1.403932e-003,,,,,,,,,,,,,,,,,,,,
1473338879.667,,5.000000e+001,4.111462e+001,4.139504e+001,1,0,4.767336e+000,-2.481002e+000,-2.481002e+000,-4.869509e-001,-4.845324e-001,-2.457217e+000,-4.631656e-001,-4.607470e-001,-1.242936e-003,-1.242936e-003,,,,,,,,,,,,,,,,,,,,
1473338892.396,,5.000000e+001,4.175915e+001,4.212857e+001,1,0,2.188686e+000,-3.878902e-001,-3.878902e-001,1.605977e+000,1.607534e+000,-4.098935e-001,1.583974e+000,1.585530e+000,-1.943258e-004,-1.943258e-004,,,,,,,,,,,,,,,,,,,,
1473338903.610,,5.000000e+001,4.236810e+001,4.283291e+001,1,0,9.043647e-002,-2.355113e+000,-2.355113e+000,-3.611088e-001,-3.602041e-001,-2.346765e+000,-3.527608e-001,-3.518561e-001,-1.179868e-003,-1.179868e-003,,,,,,,,,,,,,,,,,,,,
1473338918.575,,5.000000e+001,4.305343e+001,4.352518e+001,1,0,1.474906e+000,-2.122105e+000,-2.122105e+000,-1.281793e-001,-1.279428e-001,-2.134601e+000,-1.406755e-001,-1.404390e-001,-1.063135e-003,-1.063135e-003,,,,,,,,,,,,,,,,,,,,
1473338918.575,,5.000000e+001,4.305343e+001,4.352518e+001,1,0,4.141200e+000,-2.845393e+000,-2.845393e+000,-8.538802e-001,-8.512313e-001,-2.843280e+000,-8.517671e-001,-8.491182e-001,-1.425489e-003,-1.425489e-003,,,,,,,,,,,,,,,,,,,,
1473338930.789,,5.000000e+001,4.364657e+001,4.412012e+001,1,0,4.637763e+000,-2.568743e+000,-2.568743e+000,-5.769208e-001,-5.748824e-001,-2.544713e+000,-5.528911e-001,-5.508527e-001,-1.286893e-003,-1.286893e-003,,,,,,,,,,,,,,,,,,,,
1473338954.191,,5.000000e+001,4.472177e+001,4.527856e+001,1,0,1.973570e+000,-9.036531e-001,-9.036531e-001,1.088869e+000,1.090107e+000,-9.553059e-001,1.037217e+000,1.038454e+000,-4.527134e-004,-4.527134e-004,,,,,,,,,,,,,,,,,,,,
1473338967.764,,5.000000e+001,4.539503e+001,4.585931e+001,1,0,3.318533e-002,-2.313761e+000,-2.313761e+000,-3.209208e-001,-3.202035e-001,-2.303790e+000,-3.109502e-001,-3.102329e-001,-1.159151e-003,-1.159151e-003,,,,,,,,,,,,,,,,,,,,
1473338981.228,,5.000000e+001,4.608796e+001,4.656380e+001,1,0,1.692110e+000,-1.645405e+000,-1.645405e+000,3.475488e-001,3.477081e-001,-1.654266e+000,3.386885e-001,3.388478e-001,-8.243176e-004,-8.243176e-004,,,,,,,,,,,,,,,,,,,,
1473338981.228,,5.000000e+001,4.608796e+001,4.656380e+001,1,0,4.300061e+000,-2.783593e+000,-2.783593e+000,-7.926694e-001,-7.904797e-001,-2.772867e+000,-7.819430e-001,-7.797532e-001,-1.394529e-003,-1.394529e-003,,,,,,,,,,,,,,,,,,,,
1473338993.692,,5.000000e+001,4.668560e+001,4.715894e+001,1,0,4.486439e+000,-2.663350e+000,-2.663350e+000,-6.723736e-001,-6.708126e-001,-2.643807e+000,-6.528307e-001,-6.512697e-001,-1.334289e-003,-1.334289e-003,,,,,,,,,,,,,,,,,,,,
1473339014.407,,5.000000e+001,4.772216e+001,4.817076e+001,1,0,1.766443e+000,-1.439863e+000,-1.439863e+000,5.505642e-001,5.514647e-001,-1.487901e+000,5.025266e-001,5.034271e-001,-7.213448e-004,-7.213448e-004,,,,,,,,,,,,,,,,,,,,
1473339027.372,,5.000000e+001,4.827284e+001,4.871383e+001,1,0,7.268671e-003,-2.288736e+000,-2.288736e+000,-2.985724e-001,-2.980993e-001,-2.276465e+000,-2.863017e-001,-2.858286e-001,-1.146614e-003,-1.146614e-003,,,,,,,,,,,,,,,,,,,,
1473339040.336,,5.000000e+001,4.895260e+001,4.940160e+001,1,0,1.914144e+000,-1.150090e+000,-1.150090e+000,8.395068e-001,8.395861e-001,-1.150447e+000,8.391498e-001,8.392291e-001,-5.761738e-004,-5.761738e-004,,,,,,,,,,,,,,,,,,,,
1473339040.336,,5.000000e+001,4.895260e+001,4.940160e+001,1,0,4.450758e+000,-2.668386e+000,-2.668386e+000,-6.801381e-001,-6.787099e-001,-2.647149e+000,-6.589007e-001,-6.574725e-001,-1.336812e-003,-1.336812e-003,,,,,,,,,,,,,,,,,,,,
1473339052.550,,5.000000e+001,4.951476e+001,4.998353e+001,1,0,4.317452e+000,-2.733238e+000,-2.733238e+000,-7.455001e-001,-7.444412e-001,-2.723809e+000,-7.360712e-001,-7.350122e-001,-1.369301e-003,-1.369301e-003,,,,,,,,,,,,,,,,,,,,
1473339075.306,,5.000000e+001,5.068798e+001,5.114695e+001,1,0,1.568234e+000,-1.220740e+000,-1.220740e+000,8.673615e-002,8.724272e-002,-1.254657e+000,5.281992e-002,5.332649e-002,-6.115683e-004,-6.115683e-004,,,,,,,,,,,,,,,,,,,,
1473339088.271,,5.000000e+001,5.126000e+001,5.172888e+001,1,0,1.470743e-002,-1.595050e+000,-1.595050e+000,-2.883912e-001,-2.881873e-001,-1.581327e+000,-2.746685e-001,-2.744646e-001,-7.990904e-004,-7.990904e-004,,,,,,,,,,,,,,,,,,,,
1473339102.240,,5.000000e+001,5.195770e+001,5.253548e+001,1,0,2.139440e+000,-4.516739e-002,-4.516739e-002,1.260430e+000,1.260453e+000,-2.645820e-002,1.279140e+000,1.279162e+000,-2.262803e-005,-2.262803e-005,,,,,,,,,,,,,,,,,,,,
1473339102.240,,5.000000e+001,5.195770e+001,5.253548e+001,1,0,4.591136e+000,-1.855525e+000,-1.855525e+000,-5.504971e-001,-5.499052e-001,-1.828351e+000,-5.233227e-001,-5.227308e-001,-9.295838e-004,-9.295838e-004,,,,,,,,,,,,,,,,,,,,
1473339115.703,,5.000000e+001,5.265443e+001,5.312141e+001,1,0,4.134404e+000,-2.040620e+000,-2.040620e+000,-7.363930e-001,-7.361257e-001,-2.041552e+000,-7.373250e-001,-7.370577e-001,-1.022313e-003,-1.022313e-003,,,,,,,,,,,,,,,,,,,,
1473339135.203,,5.000000e+001,5.358073e+001,5.415873e+001,1,0,1.379051e+000,-8.862575e-001,-8.862575e-001,-2.623812e-001,-2.623559e-001,-9.101960e-001,-2.863197e-001,-2.862944e-001,-4.439986e-004,-4.439986e-004,,,,,,,,,,,,,,,,,,,,
1473339147.918,,5.000000e+001,5.439384e+001,5.472462e+001,1,0,5.600027e-002,-9.091464e-001,-9.091464e-001,-2.863514e-001,-2.864372e-001,-8.964723e-001,-2.736773e-001,-2.737631e-001,-4.554655e-004,-4.554655e-004,,,,,,,,,,,,,,,,,,,,
1473339162.072,,5.000000e+001,5.495408e+001,5.553209e+001,1,0,2.365837e+000,1.776177e-001,1.776177e-001,1.477931e+000,1.477919e+000,2.125676e-001,1.512880e+000,1.512869e+000,8.898319e-005,8.898319e-005,,,,,,,,,,,,,,,,,,,,
1473339162.072,,5.000000e+001,5.495408e+001,5.553209e+001,1,0,4.717467e+000,-1.728568e+000,-1.728568e+000,-4.276747e-001,-4.282670e-001,-1.704380e+000,-4.034866e-001,-4.040788e-001,-8.659807e-004,-8.659807e-004,,,,,,,,,,,,,,,,,,,,
1473339176.895,,5.000000e+001,5.575740e+001,5.622110e+001,1,0,3.940121e+000,-1.902219e+000,-1.902219e+000,-6.025640e-001,-6.031934e-001,-1.905760e+000,-6.061053e-001,-6.067346e-001,-9.529763e-004,-9.529763e-004,,,,,,,,,,,,,,,,,,,,
1473339213.861,,5.000000e+001,5.765451e+001,5.798062e+001,1,0,1.198381e+000,-1.884976e+000,-1.884976e+000,-4.503760e-001,-4.520397e-001,-1.907916e+000,-4.733165e-001,-4.749802e-001,-9.443379e-004,-9.443379e-004,,,,,,,,,,,,,,,,,,,,
1473339228.076,,5.000000e+001,5.820388e+001,5.875666e+001,1,0,1.298361e-001,-1.723991e+000,-1.723991e+000,-2.782047e-001,-2.791247e-001,-1.713393e+000,-2.676069e-001,-2.685269e-001,-8.636873e-004,-8.636873e-004,,,,,,,,,,,,,,,,,,,,
1473339243.040,,5.000000e+001,5.898742e+001,5.943174e+001,1,0,2.590895e+000,-1.361126e-001,-1.361126e-001,1.318217e+000,1.318217e+000,-1.209998e-001,1.333329e+000,1.333329e+000,-6.818987e-005,-6.818987e-005,,,,,,,,,,,,,,,,,,,,
1473339243.040,,5.000000e+001,5.898742e+001,5.943174e+001,1,0,4.825475e+000,-1.762596e+000,-1.762596e+000,-3.048831e-001,-3.082672e-001,-1.748345e+000,-2.906321e-001,-2.940162e-001,-8.830282e-004,-8.830282e-004,,,,,,,,,,,,,,,,,,,,
1473339256.267,,5.000000e+001,5.964676e+001,6.009720e+001,1,0,3.736803e+000,-1.795709e+000,-1.795709e+000,-3.330909e-001,-3.357627e-001,-1.795202e+000,-3.325840e-001,-3.352559e-001,-8.996170e-004,-8.996170e-004,,,,,,,,,,,,,,,,,,,,
1473339269.414,,5.000000e+001,6.021395e+001,6.065652e+001,1,0,1.025445e+000,-1.283303e+000,-1.283303e+000,-4.963935e-001,-4.982702e-001,-1.307009e+000,-5.200987e-001,-5.219754e-001,-6.429112e-004,-6.429112e-004,,,,,,,,,,,,,,,,,,,,
1473339282.689,,5.000000e+001,6.098896e+001,6.142973e+001,1,0,2.334056e-001,-1.066622e+000,-1.066622e+000,-2.784859e-001,-2.794318e-001,-1.057943e+000,-2.698072e-001,-2.707531e-001,-5.343578e-004,-5.343578e-004,,,,,,,,,,,,,,,,,,,,
1473339282.689,,5.000000e+001,6.098896e+001,6.142973e+001,1,0,2.812088e+000,2.134770e-001,2.134770e-001,1.005633e+000,1.000667e+000,1.999746e-001,9.921308e-001,9.871646e-001,1.069480e-004,1.069480e-004,,,,,,,,,,,,,,,,,,,,
1473339296.011,,5.000000e+001,6.165495e+001,6.210118e+001,1,0,4.910349e+000,-1.014740e+000,-1.014740e+000,-2.223188e-001,-2.267066e-001,-1.004828e+000,-2.124064e-001,-2.167942e-001,-5.083662e-004,-5.083662e-004,,,,,,,,,,,,,,,,,,,,
1473339309.226,,5.000000e+001,6.233132e+001,6.274471e+001,1,0,3.525872e+000,-1.622059e-001,-1.622059e-001,-4.931406e-002,-5.288638e-002,-1.620432e-001,-4.915139e-002,-5.272371e-002,-8.126214e-005,-8.126214e-005,,,,,,,,,,,,,,,,,,,,
1473339324.233,,5.000000e+001,6.295818e+001,6.337952e+001,1,0,8.595671e-001,-1.200293e+000,-1.200293e+000,-4.101054e-001,-4.126882e-001,-1.219849e+000,-4.296618e-001,-4.322446e-001,-6.013245e-004,-6.013245e-004,,,,,,,,,,,,,,,,,,,,
1473339339.198,,5.000000e+001,6.359514e+001,6.414037e+001,1,0,3.629761e-001,-1.037172e+000,-1.037172e+000,-2.494876e-001,-2.508277e-001,-1.032658e+000,-2.449741e-001,-2.463142e-001,-5.196037e-004,-5.196037e-004,,,,,,,,,,,,,,,,,,,,
1473339339.198,,5.000000e+001,6.359514e+001,6.414037e+001,1,0,3.027115e+000,-2.592547e-001,-2.592547e-001,5.346425e-001,5.270892e-001,-2.845250e-001,5.093721e-001,5.018189e-001,-1.298818e-004,-1.298818e-004,,,,,,,,,,,,,,,,,,,,
1473339355.162,,5.000000e+001,6.434687e+001,6.498838e+001,1,0,4.967562e+000,-9.289834e-001,-9.289834e-001,-1.373743e-001,-1.444188e-001,-9.220538e-001,-1.304446e-001,-1.374891e-001,-4.654035e-004,-4.654035e-004,,,,,,,,,,,,,,,,,,,,
1473339368.628,,5.000000e+001,6.498838e+001,6.569441e+001,1,0,3.308725e+000,-6.509598e-001,-6.509598e-001,1.377989e-001,1.320143e-001,-6.539017e-001,1.348570e-001,1.290724e-001,-3.261188e-004,-3.261188e-004,,,,,,,,,,,,,,,,,,,,
1473339396.368,,5.000000e+001,6.639381e+001,6.680821e+001,1,0,7.006947e-001,-2.073427e+000,-2.073427e+000,-5.239589e-001,-5.430681e-001,-2.118800e+000,-5.693316e-001,-5.884408e-001,-2.596872e-004,-2.596872e-004,,,,,,,,,,,,,,,,,,,,
1473339412.015,,5.000000e+001,6.714242e+001,6.764309e+001,1,0,5.143302e-001,-1.136204e+000,-1.136204e+000,-2.571389e-001,-2.663924e-001,-1.144063e+000,-2.649977e-001,-2.742511e-001,-1.423043e-004,-1.423043e-004,,,,,,,,,,,,,,,,,,,,
1473339412.015,,5.000000e+001,6.714242e+001,6.764309e+001,1,0,3.234257e+000,-6.631672e-001,-6.631672e-001,2.630903e-001,2.066445e-001,-7.009218e-001,2.253358e-001,1.688900e-001,-8.305862e-005,-8.305862e-005,,,,,,,,,,,,,,,,,,,,
1473339426.588,,5.000000e+001,6.794737e+001,6.834438e+001,1,0,4.993444e+000,-5.775628e-001,-5.775628e-001,-7.604066e-002,-1.226675e-001,-5.678918e-001,-6.636962e-002,-1.129964e-001,-7.233706e-005,-7.233706e-005,,,,,,,,,,,,,,,,,,,,
1473339454.599,,5.000000e+001,6.908726e+001,6.961559e+001,1,0,3.086591e+000,-5.432295e-001,-5.432295e-001,3.706972e-001,1.841974e-001,-5.789282e-001,3.349984e-001,1.484986e-001,-1.360739e-005,-1.360739e-005,,,,,,,,,,,,,,,,,,,,
1473339471.814,,5.000000e+001,7.005043e+001,7.062244e+001,1,0,5.499708e-001,-4.911954e-001,-4.911954e-001,-2.387549e-002,-1.396364e-001,-6.482617e-001,-1.809417e-001,-2.967026e-001,-1.230399e-005,-1.230399e-005,,,,,,,,,,,,,,,,,,,,
1473339484.528,,5.000000e+001,7.074033e+001,7.118889e+001,1,0,6.833191e-001,-2.546769e-001,-2.546770e-001,1.366993e-002,-3.248686e-002,-4.110609e-001,-1.427140e-001,-1.888708e-001,-6.379422e-006,-6.379422e-006,,,,,,,,,,,,,,,,,,,,
1473339484.528,,5.000000e+001,7.074033e+001,7.118889e+001,1,0,3.432555e+000,-4.647969e-001,-4.647969e-001,6.510514e-002,-2.426068e-001,-5.728385e-001,-4.293650e-002,-3.506484e-001,-1.164273e-005,-1.164273e-005,,,,,,,,,,,,,,,,,,,,
1473339496.993,,5.000000e+001,7.129148e+001,7.174683e+001,1,0,4.986046e+000,-4.284799e-001,-4.284799e-001,-7.523590e-002,-3.029049e-001,-3.730930e-001,-1.984900e-002,-2.475180e-001,-1.073302e-005,-1.073302e-005,,,,,,,,,,,,,,,,,,,,
1473339513.207,,5.000000e+001,7.208517e+001,7.254785e+001,1,0,2.861248e+000,-9.872738e-002,-9.872738e-002,1.280102e-001,-1.163833e-002,-3.170499e-001,-9.031234e-002,-2.299608e-001,-2.473029e-006,-2.473029e-006,,,,,,,,,,,,,,,,,,,,
1473339526.421,,5.000000e+001,7.277116e+001,7.334049e+001,1,0,4.096194e-001,5.798517e-003,5.798517e-003,3.242052e-002,-8.926935e-002,-4.762233e-002,-2.100032e-002,-1.426902e-001,1.452475e-007,1.452475e-007,,,,,,,,,,,,,,,,,,,,
1473339541.074,,5.000000e+001,7.346212e+001,7.392897e+001,1,0,8.663557e-001,2.475051e-001,2.475051e-001,1.834100e-001,1.369653e-001,5.480209e-002,-9.292968e-003,-5.573776e-002,6.199774e-006,6.199774e-006,,,,,,,,,,,,,,,,,,,,
1473339541.074,,5.000000e+001,7.346212e+001,7.392897e+001,1,0,3.621763e+000,-2.261422e-001,-2.261422e-001,5.848364e-003,-3.366820e-001,-2.354353e-001,-3.444775e-003,-3.459752e-001,-5.664651e-006,-5.664651e-006,,,,,,,,,,,,,,,,,,,,
1473339556.417,,5.000000e+001,7.426633e+001,7.485318e+001,1,0,4.944759e+000,-1.036103e-001,-1.036103e-001,-3.969233e-002,-1.728859e-001,-6.994226e-002,-6.024255e-003,-1.392178e-001,-2.595343e-006,-2.595343e-006,,,,,,,,,,,,,,,,,,,,
1473339570.132,,5.000000e+001,7.485318e+001,7.554744e+001,1,0,2.634866e+000,-1.648000e-002,-1.648000e-002,-2.418154e-002,-2.178964e-001,-4.016900e-002,-4.787055e-002,-2.415854e-001,-4.128086e-007,-4.128086e-007,,,,,,,,,,,,,,,,,,,,
1473339582.346,,5.000000e+001,7.554744e+001,7.612910e+001,1,0,2.832607e-001,1.173437e-001,1.173437e-001,-2.466558e-003,-1.203030e-001,1.395792e-001,1.976898e-002,-9.806748e-002,2.939350e-006,2.939350e-006,,,,,,,,,,,,,,,,,,,,
1473339595.005,,5.000000e+001,7.624312e+001,7.682391e+001,1,0,1.060611e+000,4.463332e-001,4.463332e-001,2.465495e-001,2.059244e-001,2.424656e-001,4.268184e-002,2.056733e-003,1.118023e-005,1.118023e-005,,,,,,,,,,,,,,,,,,,,
1473339595.005,,5.000000e+001,7.624312e+001,7.682391e+001,1,0,3.802400e+000,-1.049837e-001,-1.049837e-001,-8.784454e-003,-3.453925e-001,-7.005983e-002,2.613939e-002,-3.104686e-001,-2.629744e-006,-2.629744e-006,,,,,,,,,,,,,,,,,,,,
1473339608.330,,5.000000e+001,7.682391e+001,7.740472e+001,1,0,4.870885e+000,-9.308145e-003,-9.308145e-003,-2.347367e-002,-2.826781e-001,4.303915e-002,2.887363e-002,-2.303308e-001,-2.331604e-007,-2.331604e-007,,,,,,,,,,,,,,,,,,,,
1473339622.044,,5.000000e+001,7.751672e+001,7.809897e+001,1,0,2.409816e+000,5.188147e-003,5.188147e-003,-8.442464e-002,-2.688944e-001,-3.648382e-002,-1.260966e-001,-3.105664e-001,1.299583e-007,1.299583e-007,,,,,,,,,,,,,,,,,,,,
1473339635.008,,5.000000e+001,7.821586e+001,7.878357e+001,1,0,1.751931e-001,1.277200e-001,1.277200e-001,-6.138120e-002,-1.704865e-001,2.159922e-001,2.689099e-002,-8.221436e-002,3.199267e-006,3.199267e-006,,,,,,,,,,,,,,,,,,,,
1473339650.175,,5.000000e+001,7.901257e+001,7.946828e+001,1,0,1.264029e+000,4.535051e-001,4.535050e-001,1.970117e-001,1.625064e-001,3.122851e-001,5.579176e-002,2.128640e-002,1.135988e-005,1.135988e-005,,,,,,,,,,,,,,,,,,,,
1473339650.175,,5.000000e+001,7.901257e+001,7.946828e+001,1,0,3.975430e+000,-3.967406e-002,-3.967406e-002,-2.871820e-003,-3.306727e-001,2.407963e-002,6.088187e-002,-2.669190e-001,-9.937985e-007,-9.937985e-007,,,,,,,,,,,,,,,,,,,,
1473339662.043,,5.000000e+001,7.957394e+001,7.980424e+001,1,0,4.767333e+000,3.585925e-002,3.585925e-002,-2.751016e-002,-2.803995e-001,1.100042e-001,4.663483e-002,-2.062545e-001,8.982410e-007,8.982410e-007,,,,,,,,,,,,,,,,,,,,
1473339679.008,,5.000000e+001,8.028706e+001,8.049038e+001,1,0,2.188699e+000,5.645924e-002,5.645924e-002,-8.401060e-002,-2.637060e-001,1.010293e-002,-1.303669e-001,-3.100623e-001,1.414252e-006,1.414252e-006,,,,,,,,,,,,,,,,,,,,
1473339831.989,,5.000000e+001,8.004802e+001,8.004191e+001,1,0,9.041623e-002,8.438368e-002,8.438368e-002,-1.152644e-001,-2.229265e-001,2.276859e-001,2.803789e-002,-7.962421e-002,2.113733e-006,2.113733e-006,,,,,,,,,,,,,,,,,,,,
1473339844.703,,5.000000e+001,8.003580e+001,8.002663e+001,1,0,1.474903e+000,3.704947e-001,3.704947e-001,8.910326e-002,5.943879e-002,3.095671e-001,2.817563e-002,-1.488835e-003,9.280549e-006,9.280549e-006,,,,,,,,,,,,,,,,,,,,
1473339844.703,,5.000000e+001,8.003580e+001,8.002663e+001,1,0,4.141246e+000,-2.319407e-002,-2.319407e-002,-2.007950e-003,-3.342500e-001,5.631456e-002,7.750068e-002,-2.547413e-001,-5.809899e-007,-5.809899e-007,,,,,,,,,,,,,,,,,,,,
1473339857.862,,5.000000e+001,8.001748e+001,8.002053e+001,1,0,4.637779e+000,8.087405e-003,8.087405e-003,-3.981831e-002,-2.948109e-001,1.052018e-001,5.729605e-002,-1.976966e-001,2.025820e-007,2.025820e-007,,,,,,,,,,,,,,,,,,,,
1473339871.117,,5.000000e+001,8.001748e+001,8.002357e+001,1,0,1.973587e+000,1.391644e-001,1.391644e-001,-1.207947e-002,-1.886376e-001,7.291514e-002,-7.832873e-002,-2.548868e-001,3.485939e-006,3.485939e-006,,,,,,,,,,,,,,,,,,,,
1473340063.711,,5.000000e+001,7.999915e+001,8.000526e+001,1,0,3.319556e-002,8.957183e-002,8.957183e-002,-1.483769e-001,-2.443750e-001,2.634781e-001,2.552942e-002,-7.046866e-002,2.243691e-006,2.243691e-006,,,,,,,,,,,,,,,,,,,,
1473340076.858,,5.000000e+001,8.000832e+001,7.999915e+001,1,0,1.692050e+000,2.948088e-001,2.948088e-001,-3.053576e-002,-5.318823e-002,3.105403e-001,-1.480422e-002,-3.745669e-002,7.384687e-006,7.384687e-006,,,,,,,,,,,,,,,,,,,,
1473340076.858,,5.000000e+001,8.000832e+001,7.999915e+001,1,0,4.300037e+000,3.570665e-002,3.570666e-002,-8.189250e-004,-3.122904e-001,1.136146e-001,7.708902e-002,-2.343824e-001,8.944186e-007,8.944186e-007,,,,,,,,,,,,,,,,,,,,
1473340090.380,,5.000000e+001,7.998694e+001,7.999915e+001,1,0,4.486418e+000,4.119999e-002,4.119999e-002,-5.667526e-002,-2.905620e-001,1.667105e-001,6.883529e-002,-1.650515e-001,1.032021e-006,1.032021e-006,,,,,,,,,,,,,,,,,,,,
1473340103.202,,5.000000e+001,7.998998e+001,8.000832e+001,1,0,1.766420e+000,2.502518e-001,2.502518e-001,7.397398e-002,-9.087285e-002,1.462114e-001,-3.006635e-002,-1.949132e-001,6.268575e-006,6.268575e-006,,,,,,,,,,,,,,,,,,,,
1473340206.984,,5.000000e+001,8.508823e+001,8.609722e+001,1,0,7.274057e-003,1.442000e-001,1.442000e-001,-1.594027e-001,-2.494801e-001,3.352301e-001,3.162742e-002,-5.845001e-002,3.612075e-006,3.612075e-006,,,,,,,,,,,,,,,,,,,,
1473340219.948,,5.000000e+001,8.630456e+001,8.712549e+001,1,0,1.914141e+000,2.111881e-001,2.111881e-001,-1.562436e-001,-1.731344e-001,2.812956e-001,-8.613610e-002,-1.030269e-001,5.290066e-006,5.290066e-006,,,,,,,,,,,,,,,,,,,,
1473340219.948,,5.000000e+001,8.630456e+001,8.712549e+001,1,0,4.450797e+000,1.089511e-001,1.089511e-001,2.866347e-002,-2.753714e-001,1.732564e-001,9.296876e-002,-2.110661e-001,2.729123e-006,2.729123e-006,,,,,,,,,,,,,,,,,,,,
1473340233.591,,5.000000e+001,8.758313e+001,8.846971e+001,1,0,4.317441e+000,1.263466e-001,1.263466e-001,-5.012927e-002,-2.831509e-001,2.803134e-001,1.038375e-001,-1.291841e-001,3.164866e-006,3.164866e-006,,,,,,,,,,,,,,,,,,,,
1473340246.693,,5.000000e+001,8.889608e+001,8.975294e+001,1,0,1.568195e+000,4.040651e-001,4.040651e-001,1.637850e-001,4.776776e-003,2.536089e-001,1.332885e-002,-1.456794e-001,1.012146e-005,1.012146e-005,,,,,,,,,,,,,,,,,,,,
1473340264.157,,5.000000e+001,9.018723e+001,9.125912e+001,1,0,1.473792e-002,1.788385e-001,1.788385e-001,-1.566015e-001,-2.421252e-001,3.707294e-001,3.528937e-002,-5.023435e-002,4.479738e-006,4.479738e-006,,,,,,,,,,,,,,,,,,,,
1473340276.622,,5.000000e+001,9.167175e+001,9.232729e+001,1,0,2.139460e+000,1.011689e-001,1.011689e-001,-2.786624e-001,-2.900538e-001,2.104382e-001,-1.693930e-001,-1.807845e-001,2.534186e-006,2.534186e-006,,,,,,,,,,,,,,,,,,,,
1473340276.622,,5.000000e+001,9.167175e+001,9.232729e+001,1,0,4.591103e+000,1.274148e-001,1.274148e-001,3.806669e-002,-2.638080e-001,1.760225e-001,8.667444e-002,-2.152002e-001,3.191622e-006,3.191622e-006,,,,,,,,,,,,,,,,,,,,
1473340292.018,,5.000000e+001,9.274907e+001,9.380106e+001,1,0,4.134385e+000,1.043733e-001,1.043733e-001,-5.632823e-002,-2.837711e-001,2.728911e-001,1.121896e-001,-1.152533e-001,2.614455e-006,2.614455e-006,,,,,,,,,,,,,,,,,,,,
1473340304.343,,5.000000e+001,9.423151e+001,9.483370e+001,1,0,1.379038e+000,5.540636e-001,5.540636e-001,2.803267e-001,1.273822e-001,3.382547e-001,6.451784e-002,-8.842665e-002,1.387878e-005,1.387878e-005,,,,,,,,,,,,,,,,,,,,
1473340320.058,,5.000000e+001,9.568224e+001,9.650172e+001,1,0,5.598351e-002,1.925718e-001,1.925718e-001,-1.381960e-001,-2.172373e-001,3.704810e-001,3.971327e-002,-3.932804e-002,4.823745e-006,4.823745e-006,,,,,,,,,,,,,,,,,,,,
1473340333.272,,5.000000e+001,9.670213e+001,9.752497e+001,1,0,2.365892e+000,3.967406e-002,3.967406e-002,-3.746640e-001,-3.803593e-001,1.718034e-001,-2.425347e-001,-2.482300e-001,9.937985e-007,9.937985e-007,,,,,,,,,,,,,,,,,,,,
1473340333.272,,5.000000e+001,9.670213e+001,9.752497e+001,1,0,4.717512e+000,1.615955e-001,1.615955e-001,3.771867e-002,-2.584379e-001,2.000013e-001,7.612443e-002,-2.200321e-001,4.047818e-006,4.047818e-006,,,,,,,,,,,,,,,,,,,,
1473340347.487,,5.000000e+001,9.810036e+001,9.895506e+001,1,0,3.940138e+000,1.420637e-001,1.420637e-001,-6.569090e-002,-2.859694e-001,3.029369e-001,9.518228e-002,-1.250962e-001,3.558563e-006,3.558563e-006,,,,,,,,,,,,,,,,,,,,
1473340359.951,,5.000000e+001,9.915605e+001,9.995242e+001,1,0,1.198326e+000,6.476027e-001,6.476028e-001,3.809257e-001,2.342130e-001,3.683848e-001,1.017078e-001,-4.500496e-002,1.622185e-005,1.622185e-005,,,,,,,,,,,,,,,,,,,,
1473340378.364,,5.000000e+001,1.007623e+002,1.015416e+002,1,0,1.298448e-001,2.653584e-001,2.653584e-001,-9.586370e-002,-1.699528e-001,4.076716e-001,4.644948e-002,-2.763960e-002,6.646983e-006,6.646983e-006,,,,,,,,,,,,,,,,,,,,
1473340391.686,,5.000000e+001,1.017382e+002,1.026928e+002,1,0,2.590928e+000,-3.814814e-003,-3.814814e-003,-4.211638e-001,-4.211638e-001,1.407167e-001,-2.766323e-001,-2.766323e-001,-9.555755e-008,-9.555755e-008,,,,,,,,,,,,,,,,,,,,
1473340391.686,,5.000000e+001,1.017382e+002,1.026928e+002,1,0,4.825518e+000,1.733451e-001,1.733451e-001,4.415195e-002,-2.440039e-001,1.961981e-001,6.700492e-002,-2.211509e-001,4.342135e-006,4.342135e-006,,,,,,,,,,,,,,,,,,,,
1473340407.671,,5.000000e+001,1.032776e+002,1.040488e+002,1,0,3.736732e+000,1.387066e-001,1.387066e-001,-7.714029e-002,-2.916241e-001,2.683827e-001,5.253579e-002,-1.619481e-001,3.474472e-006,3.474472e-006,,,,,,,,,,,,,,,,,,,,
1473340422.385,,5.000000e+001,1.044258e+002,1.052184e+002,1,0,1.025359e+000,7.075716e-001,7.075716e-001,4.278679e-001,2.867995e-001,4.003775e-001,1.206738e-001,-2.039465e-002,1.772401e-005,1.772401e-005,,,,,,,,,,,,,,,,,,,,
1473340440.350,,5.000000e+001,1.059653e+002,1.069118e+002,1,0,2.334144e-001,3.372295e-001,3.372295e-001,-3.785772e-002,-1.051228e-001,4.312191e-001,5.613187e-002,-1.113325e-002,8.447288e-006,8.447288e-006,,,,,,,,,,,,,,,,,,,,
1473340440.350,,5.000000e+001,1.059653e+002,1.069118e+002,1,0,2.812169e+000,3.692739e-002,3.692740e-002,-5.228308e-002,-4.054250e-001,-1.637427e-001,-2.529532e-001,-6.060951e-001,9.249971e-007,9.249971e-007,,,,,,,,,,,,,,,,,,,,
1473340453.814,,5.000000e+001,1.070967e+002,1.078797e+002,1,0,4.910403e+000,1.896725e-001,1.896725e-001,4.190625e-002,-2.398061e-001,2.074650e-001,5.969869e-002,-2.220137e-001,4.751121e-006,4.751121e-006,,,,,,,,,,,,,,,,,,,,
1473340467.279,,5.000000e+001,1.082510e+002,1.092090e+002,1,0,3.525816e+000,1.159703e-001,1.159703e-001,-9.233049e-002,-3.001349e-001,1.971213e-001,-1.117950e-002,-2.189839e-001,2.904949e-006,2.904949e-006,,,,,,,,,,,,,,,,,,,,
1473340480.243,,5.000000e+001,1.094234e+002,1.103228e+002,1,0,8.595014e-001,7.037568e-001,7.037568e-001,4.050182e-001,2.696690e-001,4.201365e-001,1.213979e-001,-1.395133e-002,1.762846e-005,1.762846e-005,,,,,,,,,,,,,,,,,,,,
1473340494.707,,5.000000e+001,1.105133e+002,1.114640e+002,1,0,3.629749e-001,4.345836e-001,4.345836e-001,4.127028e-002,-2.088356e-002,4.633447e-001,7.003137e-002,7.877529e-003,1.088592e-005,1.088592e-005,,,,,,,,,,,,,,,,,,,,
1473340494.707,,5.000000e+001,1.105133e+002,1.114640e+002,1,0,3.027215e+000,7.950072e-002,7.950072e-002,-2.564478e-002,-3.759664e-001,-8.655485e-002,-1.917003e-001,-5.420220e-001,1.991419e-006,1.991419e-006,,,,,,,,,,,,,,,,,,,,
1473340507.672,,5.000000e+001,1.116525e+002,1.125581e+002,1,0,4.967617e+000,2.035585e-001,2.035585e-001,3.938811e-002,-2.377327e-001,2.193735e-001,5.520317e-002,-2.219177e-001,5.098951e-006,5.098951e-006,,,,,,,,,,,,,,,,,,,,
1473340523.386,,5.000000e+001,1.127648e+002,1.137738e+002,1,0,3.308673e+000,1.081881e-001,1.081881e-001,-1.212598e-001,-3.241006e-001,1.416234e-001,-8.782458e-002,-2.906654e-001,2.710012e-006,2.710012e-006,,,,,,,,,,,,,,,,,,,,
1473340535.856,,5.000000e+001,1.139759e+002,1.147704e+002,1,0,7.006418e-001,6.517228e-001,6.517228e-001,3.350642e-001,2.055185e-001,4.262994e-001,1.096409e-001,-1.990485e-002,1.632505e-005,1.632505e-005,,,,,,,,,,,,,,,,,,,,
1473340571.073,,5.000000e+001,1.170943e+002,1.178524e+002,1,0,5.143634e-001,4.437391e-001,4.437391e-001,1.376652e-001,7.495993e-002,3.942802e-001,8.820623e-002,2.550098e-002,1.111525e-005,1.111525e-005,,,,,,,,,,,,,,,,,,,,
1473340571.073,,5.000000e+001,1.170943e+002,1.178524e+002,1,0,3.234408e+000,-7.171850e-003,-7.171850e-003,6.550996e-003,-3.759510e-001,-1.304188e-001,-1.166959e-001,-4.991980e-001,-1.796482e-007,-1.796482e-007,,,,,,,,,,,,,,,,,,,,
1473340587.538,,5.000000e+001,1.182191e+002,1.189689e+002,1,0,4.993501e+000,9.720146e-002,9.720145e-002,3.054655e-002,-2.640476e-001,1.205048e-001,5.384988e-002,-2.407442e-001,2.434806e-006,2.434806e-006,,,,,,,,,,,,,,,,,,,,
1473340602.255,,5.000000e+001,1.195316e+002,1.199020e+002,1,0,3.086549e+000,2.258370e-002,2.258370e-002,-1.617365e-001,-3.768071e-001,1.107983e-002,-1.732403e-001,-3.883109e-001,5.657007e-007,5.657007e-007,,,,,,,,,,,,,,,,,,,,
1473340615.719,,5.000000e+001,1.204303e+002,1.208162e+002,1,0,5.498928e-001,5.259865e-001,5.259865e-001,2.341256e-001,1.039929e-001,3.844701e-001,9.260917e-002,-3.752348e-002,1.317548e-005,1.317548e-005,,,,,,,,,,,,,,,,,,,,
1473340766.817,,5.000000e+001,1.201029e+002,1.200732e+002,1,0,6.833083e-001,5.937376e-001,5.937376e-001,2.423208e-001,1.896893e-001,4.593686e-001,1.079518e-001,5.532035e-002,1.487258e-005,1.487258e-005,,,,,,,,,,,,,,,,,,,,
1473340766.817,,5.000000e+001,1.201029e+002,1.200732e+002,1,0,3.432459e+000,8.255257e-002,8.255257e-002,2.938069e-002,-3.214957e-001,8.305511e-003,-4.486637e-002,-3.957428e-001,2.067865e-006,2.067865e-006,,,,,,,,,,,,,,,,,,,,
1473340779.781,,5.000000e+001,1.200732e+002,1.200567e+002,1,0,4.986020e+000,1.646474e-001,1.646474e-001,2.540387e-002,-2.442133e-001,1.939191e-001,5.467565e-002,-2.149415e-001,4.124264e-006,4.124264e-006,,,,,,,,,,,,,,,,,,,,
1473340793.245,,5.000000e+001,1.200567e+002,1.200501e+002,1,0,2.861289e+000,-4.577776e-003,-4.577776e-003,-2.127670e-001,-4.079247e-001,-4.136522e-002,-2.495544e-001,-4.447122e-001,-1.146691e-007,-1.146691e-007,,,,,,,,,,,,,,,,,,,,
1473340804.209,,5.000000e+001,1.200468e+002,1.200370e+002,1,0,4.096427e-001,4.324473e-001,4.324473e-001,1.339057e-001,1.415271e-002,3.750418e-001,7.650018e-002,-4.325283e-002,1.083240e-005,1.083240e-005,,,,,,,,,,,,,,,,,,,,
1473340804.209,,5.000000e+001,1.200468e+002,1.200370e+002,1,0,2.812098e+000,-4.577776e-003,-4.577776e-003,-6.361332e-002,-4.228724e-001,-2.046929e-001,-2.637284e-001,-6.229874e-001,-1.146691e-007,-1.146691e-007,,,,,,,,,,,,,,,,,,,,