File: data/A344/A344_GdN_FC_050_Oe_160908.rso.raw
[Header]
TITLE,MPMS RSO Measurement
BYAPP,MPMS Measurement,2.1,Raw with ABS
FILEOPENTIME, 1473341040.724000 9/9/2016, 1:24:00 AM

INFO, APPNAME, MPMS MultiVu Application, Revision 1.61,  Build 082

INFO, NAME, A344
INFO, WEIGHT, 10.500
INFO, AREA, 1.000
INFO, LENGTH, 1.000
INFO, SHAPE, 0
INFO, COMMENT, m = 0.0105g
INFO, SEQUENCE FILE: FC_120K-5K.seq


INFO, BACKGROUND DATA FILE:, None


STARTUPAXIS,X,8,LINEAR,AUTO,0.000000,0.000000
STARTUPAXIS,Y1,9,LINEAR,AUTO,0.000000,0.000000


STARTUPGROUP,Longitudinal
FIELDGROUP,Longitudinal,1,2,3,4,5,6,7,8,9,10,11,12,13,14,15,16,17,18,19,20,21,22
FIELDGROUP,Transverse,1,2,3,4,5,6,7,8,23,24,25,26,27,28,29,30,31,32,33,34,35,36

PLOT_APPEARANCE,ALL,HORZ_GRID_ON,VERT_GRID_ON,MARKERS_ONLY

[Data]
Time,Comment,Field (Oe),Start Temperature (K),End Temperature (K),Scan,Rejected,Position (cm),Long Voltage,Long Average Voltage,Long Detrended Voltage,Long Demeaned Voltage,Long Reg Fit,Long Detrended Fit,Long Demeaned Fit,Long Scaled Response,Long Avg. Scaled Response,Long Background Response,Long Response [w/ABS],Long Detrended Resp. [w/ABS],Long Fit [w/ABS],Long Detrended Fit [w/ABS],Trans Voltage,Trans Average Voltage,Trans Detrended Voltage,Trans Demeaned Voltage,Trans Reg Fit,Trans Detrended Fit,Trans Demeaned Fit,Trans Scaled Response,Trans Avg. Scaled Response,Trans Background Response,Trans Response [w/ABS],Trans Detrended Resp. [w/ABS],Trans Adjusted Fit,Trans Detrended Fit [w/ABS],
1473341040.700,,5.000000e+001,1.200106e+002,1.200073e+002,1,0,2.591049e+000,-4.577776e-002,-4.577776e-002,-4.353184e-001,-4.353184e-001,1.013245e-001,-2.882161e-001,-2.882161e-001,-1.146691e-006,-1.146691e-006,,,,,,,,,,,,,,,,,,,,
1473341040.700,,5.000000e+001,1.200106e+002,1.200073e+002,1,0,4.825616e+000,1.275674e-001,1.275674e-001,4.290212e-002,-2.619733e-001,1.549923e-001,7.032710e-002,-2.345483e-001,3.195444e-006,3.195444e-006,,,,,,,,,,,,,,,,,,,,
1473341052.915,,5.000000e+001,1.200106e+002,1.200106e+002,1,0,3.736772e+000,1.075777e-001,1.075777e-001,-7.442594e-002,-2.966757e-001,2.344023e-001,5.239856e-002,-1.698512e-001,2.694723e-006,2.694723e-006,,,,,,,,,,,,,,,,,,,,
1473341064.921,,5.000000e+001,1.200073e+002,1.200106e+002,1,0,1.025405e+000,7.112339e-001,7.112339e-001,4.383947e-001,2.922545e-001,3.991626e-001,1.263234e-001,-1.981676e-002,1.781575e-005,1.781575e-005,,,,,,,,,,,,,,,,,,,,
1473341077.580,,5.000000e+001,1.200073e+002,1.200073e+002,1,0,2.334023e-001,3.019806e-001,3.019806e-001,-4.032422e-002,-1.106366e-001,3.994751e-001,5.717020e-002,-1.314220e-002,7.564336e-006,7.564336e-006,,,,,,,,,,,,,,,,,,,,
1473341077.580,,5.000000e+001,1.200073e+002,1.200073e+002,1,0,2.812145e+000,-2.029481e-002,-2.029481e-002,-6.377198e-002,-4.329121e-001,-2.182595e-001,-2.617366e-001,-6.308767e-001,-5.083662e-007,-5.083662e-007,,,,,,,,,,,,,,,,,,,,
1473341322.482,,5.000000e+001,1.147885e+002,1.141280e+002,1,0,4.910360e+000,1.622059e-001,1.622059e-001,3.930536e-002,-2.493740e-001,1.837537e-001,6.085321e-002,-2.278261e-001,4.063107e-006,4.063107e-006,,,,,,,,,,,,,,,,,,,,
1473341335.482,,5.000000e+001,1.139968e+002,1.134365e+002,1,0,3.525881e+000,9.811701e-002,9.811701e-002,-9.249276e-002,-3.096967e-001,1.777219e-001,-1.288788e-002,-2.300918e-001,2.457740e-006,2.457740e-006,,,,,,,,,,,,,,,,,,,,
1473341348.496,,5.000000e+001,1.131598e+002,1.125697e+002,1,0,8.594851e-001,6.634724e-001,6.634724e-001,4.095191e-001,2.684827e-001,3.754007e-001,1.214474e-001,-1.958904e-002,1.661937e-005,1.661937e-005,,,,,,,,,,,,,,,,,,,,
1473341361.710,,5.000000e+001,1.124405e+002,1.118377e+002,1,0,3.630444e-001,3.994873e-001,3.994873e-001,4.038794e-002,-2.271643e-002,4.289944e-001,6.989507e-002,6.790698e-003,1.000679e-005,1.000679e-005,,,,,,,,,,,,,,,,,,,,
1473341361.710,,5.000000e+001,1.124405e+002,1.118377e+002,1,0,3.027241e+000,4.226813e-002,4.226813e-002,-2.425639e-002,-3.799356e-001,-1.265746e-001,-1.930991e-001,-5.487783e-001,1.058778e-006,1.058778e-006,,,,,,,,,,,,,,,,,,,,
1473341401.866,,5.000000e+001,1.099039e+002,1.092165e+002,1,0,4.967550e+000,1.881466e-001,1.881466e-001,3.882527e-002,-2.363895e-001,2.043233e-001,5.500196e-002,-2.202128e-001,4.712898e-006,4.712898e-006,,,,,,,,,,,,,,,,,,,,
1473341413.438,,5.000000e+001,1.090438e+002,1.083557e+002,1,0,3.308637e+000,1.002533e-001,1.002533e-001,-1.193395e-001,-3.205632e-001,1.325280e-001,-8.706483e-002,-2.882885e-001,2.511252e-006,2.511252e-006,,,,,,,,,,,,,,,,,,,,
1473341426.903,,5.000000e+001,1.081694e+002,1.074171e+002,1,0,7.006701e-001,6.407362e-001,6.407361e-001,3.304646e-001,2.021910e-001,4.178833e-001,1.076118e-001,-2.066177e-002,1.604985e-005,1.604985e-005,,,,,,,,,,,,,,,,,,,,
1473341441.394,,5.000000e+001,1.070698e+002,1.063161e+002,1,0,5.143335e-001,5.194250e-001,5.194250e-001,1.387442e-001,8.257127e-002,4.672916e-001,8.661073e-002,3.043780e-002,1.301112e-005,1.301112e-005,,,,,,,,,,,,,,,,,,,,
1473341441.394,,5.000000e+001,1.070698e+002,1.063161e+002,1,0,3.234321e+000,1.031526e-001,1.031526e-001,8.953704e-003,-3.337012e-001,-1.916616e-002,-1.133650e-001,-4.560199e-001,2.583876e-006,2.583876e-006,,,,,,,,,,,,,,,,,,,,
1473341472.610,,5.000000e+001,1.046001e+002,1.037839e+002,1,0,4.993491e+000,1.667836e-001,1.667837e-001,3.212830e-002,-2.385611e-001,1.862473e-001,5.159197e-002,-2.190974e-001,4.177776e-006,4.177776e-006,,,,,,,,,,,,,,,,,,,,
1473341484.881,,5.000000e+001,1.035947e+002,1.027614e+002,1,0,3.086576e+000,2.113407e-001,2.113407e-001,-1.565402e-001,-3.291140e-001,2.018868e-001,-1.659940e-001,-3.385678e-001,5.293888e-006,5.293888e-006,,,,,,,,,,,,,,,,,,,,
1473341499.551,,5.000000e+001,1.023615e+002,1.014917e+002,1,0,5.499805e-001,4.898221e-001,4.898221e-001,2.310947e-001,9.698591e-002,3.478235e-001,8.909608e-002,-4.501271e-002,1.226959e-005,1.226959e-005,,,,,,,,,,,,,,,,,,,,
1473341512.934,,5.000000e+001,1.013198e+002,1.004641e+002,1,0,6.833358e-001,6.289865e-001,6.289865e-001,2.380297e-001,1.880757e-001,4.941097e-001,1.031530e-001,5.319893e-002,1.575553e-005,1.575553e-005,,,,,,,,,,,,,,,,,,,,
1473341512.934,,5.000000e+001,1.013198e+002,1.004641e+002,1,0,3.432585e+000,1.388592e-001,1.388592e-001,3.097541e-002,-3.020516e-001,6.612849e-002,-4.175531e-002,-3.747823e-001,3.478295e-006,3.478295e-006,,,,,,,,,,,,,,,,,,,,
1473341534.209,,5.000000e+001,9.935610e+001,9.842950e+001,1,0,4.986033e+000,1.696829e-001,1.696829e-001,2.529921e-002,-2.394454e-001,1.957704e-001,5.138669e-002,-2.133579e-001,4.250400e-006,4.250400e-006,,,,,,,,,,,,,,,,,,,,
1473341547.174,,5.000000e+001,9.823804e+001,9.731995e+001,1,0,2.861246e+000,1.297037e-002,1.297037e-002,-1.954854e-001,-3.884382e-001,-2.397635e-002,-2.324322e-001,-4.253849e-001,3.248957e-007,3.248957e-007,,,,,,,,,,,,,,,,,,,,
1473341560.388,,5.000000e+001,9.709516e+001,9.639190e+001,1,0,4.095823e-001,4.359569e-001,4.359569e-001,1.334613e-001,1.465109e-002,3.737695e-001,7.127389e-002,-4.753634e-002,1.092032e-005,1.092032e-005,,,,,,,,,,,,,,,,,,,,
1473341573.293,,5.000000e+001,9.568966e+001,9.496749e+001,1,0,8.663565e-001,6.807154e-001,6.807154e-001,3.132328e-001,2.677695e-001,4.817763e-001,1.142938e-001,6.883037e-002,1.705129e-005,1.705129e-005,,,,,,,,,,,,,,,,,,,,
1473341573.293,,5.000000e+001,9.568966e+001,9.496749e+001,1,0,3.621770e+000,1.126133e-001,1.126133e-001,3.495985e-002,-3.003326e-001,9.648348e-002,1.883003e-002,-3.164625e-001,2.820859e-006,2.820859e-006,,,,,,,,,,,,,,,,,,,,
1473341589.313,,5.000000e+001,9.427218e+001,9.329189e+001,1,0,4.944767e+000,1.683096e-001,1.683096e-001,1.720020e-002,-2.424989e-001,2.038854e-001,5.277601e-002,-2.069231e-001,4.215999e-006,4.215999e-006,,,,,,,,,,,,,,,,,,,,
1473341602.696,,5.000000e+001,9.307216e+001,9.211318e+001,1,0,2.634909e+000,2.868740e-002,2.868740e-002,-2.208286e-001,-4.073730e-001,-9.619887e-003,-2.591359e-001,-4.456803e-001,7.185928e-007,7.185928e-007,,,,,,,,,,,,,,,,,,,,
1473341616.410,,5.000000e+001,9.161601e+001,9.089035e+001,1,0,2.832340e-001,3.292947e-001,3.292947e-001,3.916487e-002,-7.439572e-002,3.457277e-001,5.559787e-002,-5.796272e-002,8.248528e-006,8.248528e-006,,,,,,,,,,,,,,,,,,,,
1473341628.125,,5.000000e+001,9.061546e+001,8.964474e+001,1,0,1.060623e+000,6.663716e-001,6.663716e-001,3.089931e-001,2.693210e-001,4.651318e-001,1.077533e-001,6.808123e-002,1.669199e-005,1.669199e-005,,,,,,,,,,,,,,,,,,,,
1473341628.125,,5.000000e+001,9.061546e+001,8.964474e+001,1,0,3.802451e+000,1.031526e-001,1.031526e-001,3.481320e-002,-2.938980e-001,1.310085e-001,6.266913e-002,-2.660421e-001,2.583876e-006,2.583876e-006,,,,,,,,,,,,,,,,,,,,
1473341641.589,,5.000000e+001,8.919105e+001,8.822303e+001,1,0,4.870958e+000,1.416059e-001,1.416059e-001,2.677635e-003,-2.519741e-001,1.950717e-001,5.614349e-002,-1.985082e-001,3.547096e-006,3.547096e-006,,,,,,,,,,,,,,,,,,,,
1473341654.303,,5.000000e+001,8.798502e+001,8.726742e+001,1,0,2.409828e+000,4.623554e-002,4.623554e-002,-1.905051e-001,-3.713900e-001,9.921444e-003,-2.268192e-001,-4.077041e-001,1.158157e-006,1.158157e-006,,,,,,,,,,,,,,,,,,,,
1473341667.518,,5.000000e+001,8.678268e+001,8.579695e+001,1,0,1.751959e-001,2.298044e-001,2.298044e-001,-4.590596e-002,-1.535280e-001,3.187616e-001,4.305122e-002,-6.457087e-002,5.756387e-006,5.756387e-006,,,,,,,,,,,,,,,,,,,,
1473341679.732,,5.000000e+001,8.534819e+001,8.463659e+001,1,0,1.264011e+000,5.662709e-001,5.662709e-001,2.219478e-001,1.878776e-001,4.210361e-001,7.671294e-002,4.264280e-002,1.418456e-005,1.418456e-005,,,,,,,,,,,,,,,,,,,,
1473341679.732,,5.000000e+001,8.534819e+001,8.463659e+001,1,0,3.975405e+000,7.339701e-002,7.339702e-002,1.866997e-002,-3.049963e-001,1.396018e-001,8.487476e-002,-2.387915e-001,1.838527e-006,1.838527e-006,,,,,,,,,,,,,,,,,,,,
1473341694.696,,5.000000e+001,8.440807e+001,8.324157e+001,1,0,4.767371e+000,1.127659e-001,1.127659e-001,-1.240420e-002,-2.633361e-001,1.832890e-001,5.811890e-002,-1.928129e-001,2.824681e-006,2.824681e-006,,,,,,,,,,,,,,,,,,,,
1473341707.911,,5.000000e+001,8.281112e+001,8.213075e+001,1,0,2.188616e+000,8.804590e-002,8.804590e-002,-1.040543e-001,-2.803334e-001,4.421430e-002,-1.478859e-001,-3.241650e-001,2.205468e-006,2.205468e-006,,,,,,,,,,,,,,,,,,,,
1473341721.375,,5.000000e+001,8.189089e+001,8.106320e+001,1,0,9.037734e-002,1.413007e-001,1.413007e-001,-1.133438e-001,-2.162431e-001,2.853217e-001,3.067714e-002,-7.222211e-002,3.539452e-006,3.539452e-006,,,,,,,,,,,,,,,,,,,,
1473341734.779,,5.000000e+001,8.043420e+001,7.961273e+001,1,0,1.474864e+000,4.193243e-001,4.193243e-001,9.016289e-002,6.162733e-002,3.585272e-001,2.936579e-002,8.302331e-004,1.050369e-005,1.050369e-005,,,,,,,,,,,,,,,,,,,,
1473341734.779,,5.000000e+001,8.043420e+001,7.961273e+001,1,0,4.141218e+000,3.448591e-002,3.448592e-002,-3.612835e-003,-3.232111e-001,1.158098e-001,7.771108e-002,-2.418872e-001,8.638402e-007,8.638402e-007,,,,,,,,,,,,,,,,,,,,
1473341873.367,,5.000000e+001,8.016679e+001,8.015913e+001,1,0,4.637757e+000,-5.005036e-002,-5.005036e-002,-3.867494e-002,-3.079357e-001,4.679088e-002,5.816629e-002,-2.110945e-001,-1.253715e-006,-1.253715e-006,,,,,,,,,,,,,,,,,,,,
1473341884.620,,5.000000e+001,8.016679e+001,8.011779e+001,1,0,1.973611e+000,1.005585e-001,1.005585e-001,-9.252548e-003,-1.935489e-001,3.202546e-002,-7.778558e-002,-2.620820e-001,2.518897e-006,2.518897e-006,,,,,,,,,,,,,,,,,,,,
1473341897.858,,5.000000e+001,8.011779e+001,8.013462e+001,1,0,3.318669e-002,6.561480e-002,6.561480e-002,-1.533865e-001,-2.552465e-001,2.443138e-001,2.531250e-002,-7.654746e-002,1.643590e-006,1.643590e-006,,,,,,,,,,,,,,,,,,,,
1473341911.588,,5.000000e+001,8.011166e+001,8.011932e+001,1,0,1.692046e+000,2.375866e-001,2.375866e-001,-2.743542e-002,-5.144806e-002,2.502318e-001,-1.479019e-002,-3.880283e-002,5.951324e-006,5.951324e-006,,,,,,,,,,,,,,,,,,,,
1473341911.588,,5.000000e+001,8.011166e+001,8.011932e+001,1,0,4.300056e+000,-4.013184e-002,-4.013184e-002,1.007322e-003,-3.291665e-001,3.633046e-002,7.746962e-002,-2.527042e-001,-1.005265e-006,-1.005265e-006,,,,,,,,,,,,,,,,,,,,
1473342101.573,,5.000000e+001,8.001233e+001,8.001537e+001,1,0,4.486400e+000,-2.471999e-002,-2.471999e-002,-5.501181e-002,-3.084306e-001,9.936195e-002,6.907013e-002,-1.843487e-001,-6.192129e-007,-6.192129e-007,,,,,,,,,,,,,,,,,,,,
1473342113.287,,5.000000e+001,8.001385e+001,8.000469e+001,1,0,1.766469e+000,1.962340e-001,1.962340e-001,7.511418e-002,-1.029022e-001,9.075267e-002,-3.036716e-002,-2.083835e-001,4.915480e-006,4.915480e-006,,,,,,,,,,,,,,,,,,,,
1473342125.251,,5.000000e+001,8.000469e+001,8.001537e+001,1,0,7.280325e-003,4.730369e-002,4.730369e-002,-1.684650e-001,-2.620230e-001,2.405573e-001,2.478852e-002,-6.876944e-002,1.184914e-006,1.184914e-006,,,,,,,,,,,,,,,,,,,,
1473342137.966,,5.000000e+001,8.001233e+001,8.001537e+001,1,0,1.914159e+000,1.989807e-001,1.989807e-001,-1.316451e-001,-1.486707e-001,2.657891e-001,-6.483670e-002,-8.186230e-002,4.984282e-006,4.984282e-006,,,,,,,,,,,,,,,,,,,,
1473342137.966,,5.000000e+001,8.001233e+001,8.001537e+001,1,0,4.450756e+000,4.852443e-002,4.852443e-002,7.333986e-003,-2.991270e-001,1.122895e-001,7.109909e-002,-2.353619e-001,1.215492e-006,1.215492e-006,,,,,,,,,,,,,,,,,,,,
1473342318.947,,5.000000e+001,7.674615e+001,7.628906e+001,1,0,4.317417e+000,-6.225776e-002,-6.225776e-002,-1.051101e-001,-3.467669e-001,8.769471e-002,4.484238e-002,-1.968144e-001,-1.559499e-006,-1.559499e-006,,,,,,,,,,,,,,,,,,,,
1473342331.411,,5.000000e+001,7.616380e+001,7.566258e+001,1,0,1.568161e+000,2.528459e-001,2.528459e-001,1.664099e-001,2.281249e-003,8.986437e-002,3.428379e-003,-1.607002e-001,6.333554e-006,6.333554e-006,,,,,,,,,,,,,,,,,,,,
1473342343.875,,5.000000e+001,7.553382e+001,7.498793e+001,1,0,1.471247e-002,-5.066073e-002,-5.066073e-002,-1.858043e-001,-2.745178e-001,1.457835e-001,1.063986e-002,-7.807358e-002,-1.269004e-006,-1.269004e-006,,,,,,,,,,,,,,,,,,,,
1473342356.840,,5.000000e+001,7.486408e+001,7.429038e+001,1,0,2.139497e+000,9.186071e-002,9.186071e-002,-1.288051e-001,-1.405667e-001,1.926447e-001,-2.802106e-002,-3.978272e-002,2.301026e-006,2.301026e-006,,,,,,,,,,,,,,,,,,,,
1473342356.840,,5.000000e+001,7.486408e+001,7.429038e+001,1,0,4.591152e+000,-1.095615e-001,-1.095615e-001,-3.030498e-002,-3.419889e-001,-6.820060e-002,1.105586e-002,-3.006280e-001,-2.744413e-006,-2.744413e-006,,,,,,,,,,,,,,,,,,,,
1473342375.304,,5.000000e+001,7.386239e+001,7.327499e+001,1,0,4.134412e+000,-2.511673e-001,-2.511673e-001,-1.767576e-001,-4.113811e-001,-8.288823e-002,-8.478481e-003,-2.431020e-001,-6.291509e-006,-6.291509e-006,,,,,,,,,,,,,,,,,,,,
1473342386.800,,5.000000e+001,7.311416e+001,7.247499e+001,1,0,1.379002e+000,1.741081e-001,1.741081e-001,2.212922e-001,6.406948e-002,-5.842111e-002,-1.123700e-002,-1.684597e-001,4.361247e-006,4.361247e-006,,,,,,,,,,,,,,,,,,,,
1473342398.517,,5.000000e+001,7.247499e+001,7.200703e+001,1,0,5.600858e-002,-2.192755e-001,-2.192755e-001,-1.524119e-001,-2.108447e-001,-1.195144e-001,-5.265088e-002,-1.110836e-001,-5.492648e-006,-5.492648e-006,,,,,,,,,,,,,,,,,,,,
1473342412.231,,5.000000e+001,7.169732e+001,7.091425e+001,1,0,2.365893e+000,2.838221e-002,2.838221e-002,1.024919e-001,9.749926e-002,1.616375e-001,2.357472e-001,2.307546e-001,7.109481e-007,7.109481e-007,,,,,,,,,,,,,,,,,,,,
1473342412.231,,5.000000e+001,7.169732e+001,7.091425e+001,1,0,4.717500e+000,-4.455702e-001,-4.455702e-001,-1.168340e-001,-3.764532e-001,-3.667578e-001,-3.802156e-002,-2.976407e-001,-1.116112e-005,-1.116112e-005,,,,,,,,,,,,,,,,,,,,
1473342425.499,,5.000000e+001,7.076443e+001,7.015225e+001,1,0,3.940107e+000,-7.065035e-001,-7.065035e-001,-3.290561e-001,-5.355547e-001,-5.510255e-001,-1.735781e-001,-3.800767e-001,-1.769726e-005,-1.769726e-005,,,,,,,,,,,,,,,,,,,,
1473342438.492,,5.000000e+001,6.998663e+001,6.933444e+001,1,0,1.198319e+000,-4.654073e-001,-4.654073e-001,7.491944e-002,-6.431034e-002,-7.385989e-001,-1.982722e-001,-3.375019e-001,-1.165802e-005,-1.165802e-005,,,,,,,,,,,,,,,,,,,,
1473342452.706,,5.000000e+001,6.904354e+001,6.838950e+001,1,0,1.298231e-001,-1.293680e+000,-1.293680e+000,-3.733581e-001,-4.440976e-001,-1.164249e+000,-2.439276e-001,-3.146671e-001,-3.240547e-005,-3.240547e-005,,,,,,,,,,,,,,,,,,,,
1473342466.367,,5.000000e+001,6.822503e+001,6.759447e+001,1,0,2.590918e+000,3.773614e-001,3.773614e-001,2.239530e+000,2.239530e+000,7.784022e-001,2.640571e+000,2.640571e+000,9.452553e-006,9.452553e-006,,,,,,,,,,,,,,,,,,,,
1473342466.367,,5.000000e+001,6.822503e+001,6.759447e+001,1,0,4.825496e+000,-2.787561e+000,-2.787561e+000,-6.480366e-001,-9.253919e-001,-2.718841e+000,-5.793170e-001,-8.566723e-001,-6.982582e-005,-6.982582e-005,,,,,,,,,,,,,,,,,,,,
1473342496.279,,5.000000e+001,6.594634e+001,6.544845e+001,1,0,3.736785e+000,-1.284677e+000,-1.284677e+000,-2.987941e-001,-3.150096e-001,-1.265532e+000,-2.796492e-001,-2.958647e-001,-3.217996e-004,-3.217996e-004,,,,,,,,,,,,,,,,,,,,
1473342509.494,,5.000000e+001,6.512183e+001,6.465597e+001,1,0,1.025445e+000,-1.919614e+000,-1.919614e+000,-5.742489e-001,-5.830743e-001,-1.960743e+000,-6.153772e-001,-6.242027e-001,-4.808456e-004,-4.808456e-004,,,,,,,,,,,,,,,,,,,,
1473342522.722,,5.000000e+001,6.415637e+001,6.365222e+001,1,0,2.334017e-001,-2.056490e+000,-2.056490e+000,-4.067882e-001,-4.102936e-001,-2.045117e+000,-3.954157e-001,-3.989210e-001,-5.151316e-004,-5.151316e-004,,,,,,,,,,,,,,,,,,,,
1473342522.722,,5.000000e+001,6.415637e+001,6.365222e+001,1,0,2.812131e+000,-1.571703e-001,-1.571703e-001,1.507429e+000,1.489026e+000,-1.927992e-001,1.471800e+000,1.453397e+000,-3.936971e-005,-3.936971e-005,,,,,,,,,,,,,,,,,,,,
1473342535.881,,5.000000e+001,6.333460e+001,6.277156e+001,1,0,4.910357e+000,-2.300943e+000,-2.300943e+000,-3.952805e-001,-4.077040e-001,-2.281569e+000,-3.759066e-001,-3.883301e-001,-5.763649e-004,-5.763649e-004,,,,,,,,,,,,,,,,,,,,
1473342569.300,,5.000000e+001,6.109995e+001,6.050771e+001,1,0,3.525870e+000,-1.197699e+000,-1.197699e+000,-5.516563e-002,-5.839086e-002,-1.195734e+000,-5.320082e-002,-5.642605e-002,-6.000249e-004,-6.000249e-004,,,,,,,,,,,,,,,,,,,,
1473342584.021,,5.000000e+001,6.018915e+001,5.941620e+001,1,0,8.594981e-001,-1.692862e+000,-1.692862e+000,-5.503789e-001,-5.520850e-001,-1.714502e+000,-5.720189e-001,-5.737250e-001,-8.480923e-004,-8.480923e-004,,,,,,,,,,,,,,,,,,,,
1473342597.486,,5.000000e+001,5.926114e+001,5.864361e+001,1,0,3.629506e-001,-8.470412e-001,-8.470412e-001,-3.834510e-001,-3.841232e-001,-8.426057e-001,-3.790154e-001,-3.796876e-001,-4.243520e-004,-4.243520e-004,,,,,,,,,,,,,,,,,,,,
1473342597.486,,5.000000e+001,5.926114e+001,5.864361e+001,1,0,3.027124e+000,3.677481e-001,3.677481e-001,8.344551e-001,8.306661e-001,3.273306e-001,7.940376e-001,7.902486e-001,1.842349e-004,1.842349e-004,,,,,,,,,,,,,,,,,,,,
1473342609.978,,5.000000e+001,5.850415e+001,5.791642e+001,1,0,4.967566e+000,-7.254249e-001,-7.254249e-001,-2.585756e-001,-2.609916e-001,-7.127528e-001,-2.459035e-001,-2.483194e-001,-3.634244e-004,-3.634244e-004,,,,,,,,,,,,,,,,,,,,
1473342624.960,,5.000000e+001,5.760890e+001,5.703350e+001,1,0,3.308712e+000,-1.428266e-001,-1.428266e-001,3.246158e-001,3.231608e-001,-1.486947e-001,3.187477e-001,3.172927e-001,-7.155349e-005,-7.155349e-005,,,,,,,,,,,,,,,,,,,,
1473342636.482,,5.000000e+001,5.688224e+001,5.632221e+001,1,0,7.007084e-001,-1.766716e+000,-1.766716e+000,-6.198723e-001,-6.205701e-001,-1.779882e+000,-6.330382e-001,-6.337360e-001,-8.850922e-004,-8.850922e-004,,,,,,,,,,,,,,,,,,,,
1473342649.196,,5.000000e+001,5.617765e+001,5.562170e+001,1,0,5.142496e-001,-1.687521e+000,-1.687521e+000,-5.399283e-001,-5.401055e-001,-1.690470e+000,-5.428776e-001,-5.430548e-001,-8.454167e-004,-8.454167e-004,,,,,,,,,,,,,,,,,,,,
1473342649.196,,5.000000e+001,5.617765e+001,5.562170e+001,1,0,3.234301e+000,-6.167791e-001,-6.167791e-001,5.317172e-001,5.306364e-001,-6.589196e-001,4.895767e-001,4.884959e-001,-3.089949e-004,-3.089949e-004,,,,,,,,,,,,,,,,,,,,
1473342661.910,,5.000000e+001,5.534767e+001,5.491694e+001,1,0,4.993510e+000,-2.114475e+000,-2.114475e+000,-2.864379e-001,-2.869610e-001,-2.098014e+000,-2.699772e-001,-2.705003e-001,-1.059313e-003,-1.059313e-003,,,,,,,,,,,,,,,,,,,,
1473342676.374,,5.000000e+001,5.453067e+001,5.410674e+001,1,0,3.086631e+000,-9.750664e-001,-9.750664e-001,8.540671e-001,8.539075e-001,-9.825489e-001,8.465846e-001,8.464250e-001,-4.884902e-004,-4.884902e-004,,,,,,,,,,,,,,,,,,,,
1473342689.339,,5.000000e+001,5.384824e+001,5.331153e+001,1,0,5.499890e-001,-2.448195e+000,-2.448195e+000,-6.180652e-001,-6.179941e-001,-2.448510e+000,-6.183808e-001,-6.183097e-001,-1.226500e-003,-1.226500e-003,,,,,,,,,,,,,,,,,,,,
1473342701.808,,5.000000e+001,5.319395e+001,5.267088e+001,1,0,6.832688e-001,-2.536699e+000,-2.536699e+000,-7.052292e-001,-7.051206e-001,-2.552665e+000,-7.211951e-001,-7.210865e-001,-1.270839e-003,-1.270839e-003,,,,,,,,,,,,,,,,,,,,
1473342701.808,,5.000000e+001,5.319395e+001,5.267088e+001,1,0,3.432514e+000,-1.699576e+000,-1.699576e+000,1.312783e-001,1.320022e-001,-1.723523e+000,1.073315e-001,1.080555e-001,-8.514560e-004,-8.514560e-004,,,,,,,,,,,,,,,,,,,,
1473342714.522,,5.000000e+001,5.254367e+001,5.203931e+001,1,0,4.986058e+000,-2.154302e+000,-2.154302e+000,-3.222973e-001,-3.215317e-001,-2.134693e+000,-3.026888e-001,-3.019232e-001,-1.079265e-003,-1.079265e-003,,,,,,,,,,,,,,,,,,,,
1473342727.487,,5.000000e+001,5.190032e+001,5.138137e+001,1,0,2.861281e+000,-3.885006e-001,-3.885006e-001,1.444734e+000,1.445588e+000,-3.772773e-001,1.455958e+000,1.456811e+000,-1.946316e-004,-1.946316e-004,,,,,,,,,,,,,,,,,,,,
1473342740.701,,5.000000e+001,5.111844e+001,5.061543e+001,1,0,4.095861e-001,-2.411573e+000,-2.411573e+000,-5.768561e-001,-5.761740e-001,-2.400185e+000,-5.654685e-001,-5.647864e-001,-1.208153e-003,-1.208153e-003,,,,,,,,,,,,,,,,,,,,
1473342753.969,,5.000000e+001,5.049872e+001,5.000341e+001,1,0,8.663308e-001,-2.659230e+000,-2.659230e+000,-8.228691e-001,-8.225384e-001,-2.691096e+000,-8.547352e-001,-8.544044e-001,-1.332225e-003,-1.332225e-003,,,,,,,,,,,,,,,,,,,,
1473342753.969,,5.000000e+001,5.049872e+001,5.000341e+001,1,0,3.621753e+000,-2.116459e+000,-2.116459e+000,-2.822062e-001,-2.797668e-001,-2.125222e+000,-2.909693e-001,-2.885299e-001,-1.060307e-003,-1.060307e-003,,,,,,,,,,,,,,,,,,,,
1473342765.705,,5.000000e+001,4.987205e+001,4.937369e+001,1,0,4.944777e+000,-2.208930e+000,-2.208930e+000,-3.732203e-001,-3.709862e-001,-2.186914e+000,-3.512050e-001,-3.489709e-001,-1.106633e-003,-1.106633e-003,,,,,,,,,,,,,,,,,,,,
1473342779.420,,5.000000e+001,4.911901e+001,4.873867e+001,1,0,2.634856e+000,8.957183e-002,8.957183e-002,1.926538e+000,1.928428e+000,1.276657e-001,1.964632e+000,1.966521e+000,4.487382e-005,4.487382e-005,,,,,,,,,,,,,,,,,,,,
1473342791.634,,5.000000e+001,4.862058e+001,4.811756e+001,1,0,2.832568e-001,-2.359691e+000,-2.359691e+000,-5.210249e-001,-5.198177e-001,-2.343865e+000,-5.051989e-001,-5.039917e-001,-1.182162e-003,-1.182162e-003,,,,,,,,,,,,,,,,,,,,
1473342804.613,,5.000000e+001,4.787843e+001,4.750930e+001,1,0,1.060572e+000,-1.968902e+000,-1.968902e+000,-8.070371e-001,-8.065728e-001,-2.006186e+000,-8.443210e-001,-8.438567e-001,-9.863832e-004,-9.863832e-004,,,,,,,,,,,,,,,,,,,,
1473342804.613,,5.000000e+001,4.787843e+001,4.750930e+001,1,0,3.802384e+000,-1.806391e+000,-1.806391e+000,-6.479089e-001,-6.440617e-001,-1.807155e+000,-6.486736e-001,-6.448264e-001,-9.049682e-004,-9.049682e-004,,,,,,,,,,,,,,,,,,,,
1473342816.027,,5.000000e+001,4.726475e+001,4.690022e+001,1,0,4.870947e+000,-2.286447e+000,-2.286447e+000,-4.473740e-001,-4.441118e-001,-2.262919e+000,-4.238462e-001,-4.205840e-001,-1.145467e-003,-1.145467e-003,,,,,,,,,,,,,,,,,,,,
1473342827.645,,5.000000e+001,4.677298e+001,4.628125e+001,1,0,2.409813e+000,9.242530e-001,9.242530e-001,2.086560e+000,2.088997e+000,9.482496e-001,2.110557e+000,2.112993e+000,4.630336e-004,4.630336e-004,,,,,,,,,,,,,,,,,,,,
1473342840.359,,5.000000e+001,4.628125e+001,4.566833e+001,1,0,1.752619e-001,-1.627400e+000,-1.627400e+000,-4.624290e-001,-4.608785e-001,-1.617374e+000,-4.524036e-001,-4.508531e-001,-8.152970e-004,-8.152970e-004,,,,,,,,,,,,,,,,,,,,
1473342852.509,,5.000000e+001,4.553908e+001,4.504123e+001,1,0,1.263961e+000,-1.754967e+000,-1.754967e+000,-5.876304e-001,-5.871124e-001,-1.781858e+000,-6.145219e-001,-6.140039e-001,-8.792059e-004,-8.792059e-004,,,,,,,,,,,,,,,,,,,,
1473342852.509,,5.000000e+001,4.553908e+001,4.504123e+001,1,0,3.975384e+000,-2.067782e+000,-2.067782e+000,-9.048481e-001,-8.999273e-001,-2.067421e+000,-9.044876e-001,-8.995668e-001,-1.035920e-003,-1.035920e-003,,,,,,,,,,,,,,,,,,,,
1473342865.331,,5.000000e+001,4.492345e+001,4.443833e+001,1,0,4.767374e+000,-2.401196e+000,-2.401196e+000,-5.570248e-001,-5.530391e-001,-2.374117e+000,-5.299460e-001,-5.259602e-001,-1.202955e-003,-1.202955e-003,,,,,,,,,,,,,,,,,,,,
1473342880.296,,5.000000e+001,4.419460e+001,4.369455e+001,1,0,2.188604e+000,2.182074e-002,2.182074e-002,1.868636e+000,1.871669e+000,-5.755208e-003,1.841060e+000,1.844093e+000,1.093178e-005,1.093178e-005,,,,,,,,,,,,,,,,,,,,
1473342893.010,,5.000000e+001,4.357290e+001,4.320708e+001,1,0,9.038280e-002,-2.275613e+000,-2.275613e+000,-4.259425e-001,-4.241085e-001,-2.266929e+000,-4.172590e-001,-4.154251e-001,-1.140040e-003,-1.140040e-003,,,,,,,,,,,,,,,,,,,,
1473342906.724,,5.000000e+001,4.282366e+001,4.245337e+001,1,0,1.474846e+000,-2.688375e+000,-2.688375e+000,-1.576710e-001,-1.571126e-001,-2.703247e+000,-1.725424e-001,-1.719840e-001,-1.346826e-003,-1.346826e-003,,,,,,,,,,,,,,,,,,,,
1473342906.724,,5.000000e+001,4.282366e+001,4.245337e+001,1,0,4.141222e+000,-3.557390e+000,-3.557390e+000,-1.032382e+000,-1.026127e+000,-3.554554e+000,-1.029546e+000,-1.023291e+000,-1.782186e-003,-1.782186e-003,,,,,,,,,,,,,,,,,,,,
1473342918.189,,5.000000e+001,4.233372e+001,4.184738e+001,1,0,4.637786e+000,-3.236335e+000,-3.236335e+000,-7.089350e-001,-7.041490e-001,-3.207380e+000,-6.799796e-001,-6.751935e-001,-1.621344e-003,-1.621344e-003,,,,,,,,,,,,,,,,,,,,
1473342931.903,,5.000000e+001,4.172219e+001,4.122085e+001,1,0,1.973569e+000,-1.158788e+000,-1.158788e+000,1.372170e+000,1.375602e+000,-1.225024e+000,1.305934e+000,1.309366e+000,-5.805312e-004,-5.805312e-004,,,,,,,,,,,,,,,,,,,,
1473342945.117,,5.000000e+001,4.109924e+001,4.059710e+001,1,0,3.319325e-002,-2.944426e+000,-2.944426e+000,-4.095762e-001,-4.075100e-001,-2.934240e+000,-3.993905e-001,-3.973243e-001,-1.475103e-003,-1.475103e-003,,,,,,,,,,,,,,,,,,,,
1473342959.332,,5.000000e+001,4.046988e+001,3.985637e+001,1,0,1.692074e+000,-2.081973e+000,-2.081973e+000,4.573126e-001,4.578238e-001,-2.093582e+000,4.457030e-001,4.462142e-001,-1.043030e-003,-1.043030e-003,,,,,,,,,,,,,,,,,,,,
1473342959.332,,5.000000e+001,4.046988e+001,3.985637e+001,1,0,4.300063e+000,-3.571429e+000,-3.571429e+000,-1.038661e+000,-1.031632e+000,-3.557187e+000,-1.024420e+000,-1.017391e+000,-1.789220e-003,-1.789220e-003,,,,,,,,,,,,,,,,,,,,
1473342987.867,,5.000000e+001,3.896313e+001,3.845399e+001,1,0,4.486516e+000,-1.376080e+000,-1.376080e+000,-3.632074e-001,-3.607069e-001,-1.366112e+000,-3.532402e-001,-3.507397e-001,-1.723476e-003,-1.723476e-003,,,,,,,,,,,,,,,,,,,,
1473343000.950,,5.000000e+001,3.833038e+001,3.781067e+001,1,0,1.766395e+000,-7.045198e-001,-7.045198e-001,3.076898e-001,3.094723e-001,-7.310215e-001,2.811881e-001,2.829705e-001,-8.823784e-004,-8.823784e-004,,,,,,,,,,,,,,,,,,,,
1473343013.914,,5.000000e+001,3.767579e+001,3.699934e+001,1,0,7.228808e-003,-1.180151e+000,-1.180151e+000,-1.682097e-001,-1.672084e-001,-1.174676e+000,-1.627353e-001,-1.617341e-001,-1.478084e-003,-1.478084e-003,,,,,,,,,,,,,,,,,,,,
1473343026.128,,5.000000e+001,3.699934e+001,3.630560e+001,1,0,1.914160e+000,-5.236976e-001,-5.236976e-001,4.882476e-001,4.884398e-001,-5.237829e-001,4.881623e-001,4.883545e-001,-6.559070e-004,-6.559070e-004,,,,,,,,,,,,,,,,,,,,
1473343026.128,,5.000000e+001,3.699934e+001,3.630560e+001,1,0,4.450861e+000,-1.400647e+000,-1.400647e+000,-3.919688e-001,-3.885096e-001,-1.388593e+000,-3.799147e-001,-3.764555e-001,-1.754245e-003,-1.754245e-003,,,,,,,,,,,,,,,,,,,,
1473343038.593,,5.000000e+001,3.616924e+001,3.572792e+001,1,0,4.317478e+000,-1.446882e+000,-1.446882e+000,-4.381575e-001,-4.354566e-001,-1.442364e+000,-4.336393e-001,-4.309384e-001,-1.812153e-003,-1.812153e-003,,,,,,,,,,,,,,,,,,,,
1473343052.057,,5.000000e+001,3.543908e+001,3.498907e+001,1,0,1.568135e+000,-9.530931e-001,-9.530931e-001,5.574807e-002,5.763686e-002,-9.730117e-001,3.582939e-002,3.771818e-002,-1.193705e-003,-1.193705e-003,,,,,,,,,,,,,,,,,,,,
1473343063.521,,5.000000e+001,3.483562e+001,3.423608e+001,1,0,1.470917e-002,-1.187933e+000,-1.187933e+000,-1.788560e-001,-1.778158e-001,-1.181289e+000,-1.722116e-001,-1.711714e-001,-1.487831e-003,-1.487831e-003,,,,,,,,,,,,,,,,,,,,
1473343076.986,,5.000000e+001,3.407857e+001,3.354248e+001,1,0,2.139498e+000,-1.982177e-001,-1.982177e-001,8.112622e-001,8.114014e-001,-1.862200e-001,8.232599e-001,8.233991e-001,-2.482585e-004,-2.482585e-004,,,,,,,,,,,,,,,,,,,,
1473343076.986,,5.000000e+001,3.407857e+001,3.354248e+001,1,0,4.591236e+000,-1.356090e+000,-1.356090e+000,-3.501576e-001,-3.464708e-001,-1.339141e+000,-3.332081e-001,-3.295214e-001,-1.698440e-003,-1.698440e-003,,,,,,,,,,,,,,,,,,,,
1473343088.950,,5.000000e+001,3.339929e+001,3.265771e+001,1,0,4.134425e+000,-1.216773e+000,-1.216773e+000,-4.819301e-001,-4.790289e-001,-1.219060e+000,-4.842169e-001,-4.813157e-001,-1.523952e-003,-1.523952e-003,,,,,,,,,,,,,,,,,,,,
1473343102.664,,5.000000e+001,3.235140e+001,3.173669e+001,1,0,1.378914e+000,-9.111301e-001,-9.111301e-001,-1.759721e-001,-1.739610e-001,-9.251835e-001,-1.900255e-001,-1.880145e-001,-1.141148e-003,-1.141148e-003,,,,,,,,,,,,,,,,,,,,
1473343116.879,,5.000000e+001,3.143507e+001,3.080599e+001,1,0,5.604588e-002,-9.350871e-001,-9.350871e-001,-1.993837e-001,-1.983063e-001,-9.289480e-001,-1.932446e-001,-1.921672e-001,-1.171153e-003,-1.171153e-003,,,,,,,,,,,,,,,,,,,,
1473343129.593,,5.000000e+001,3.065491e+001,3.002682e+001,1,0,2.365918e+000,3.355510e-001,3.355510e-001,1.071725e+000,1.071805e+000,3.603633e-001,1.096538e+000,1.096617e+000,4.202621e-004,4.202621e-004,,,,,,,,,,,,,,,,,,,,
1473343129.593,,5.000000e+001,3.065491e+001,3.002682e+001,1,0,4.717599e+000,-1.038392e+000,-1.038392e+000,-3.062699e-001,-3.021386e-001,-1.021284e+000,-2.891616e-001,-2.850303e-001,-1.300538e-003,-1.300538e-003,,,,,,,,,,,,,,,,,,,,
1473343142.057,,5.000000e+001,2.986624e+001,2.922707e+001,1,0,3.940171e+000,-1.183660e+000,-1.183660e+000,-4.510008e-001,-4.479154e-001,-1.188442e+000,-4.557822e-001,-4.526969e-001,-1.482480e-003,-1.482480e-003,,,,,,,,,,,,,,,,,,,,
1473343154.827,,5.000000e+001,2.890683e+001,2.841348e+001,1,0,1.198254e+000,-1.368908e+000,-1.368908e+000,-3.639519e-001,-3.617885e-001,-1.382438e+000,-3.774819e-001,-3.753185e-001,-1.714493e-003,-1.714493e-003,,,,,,,,,,,,,,,,,,,,
1473343167.303,,5.000000e+001,2.809757e+001,2.743499e+001,1,0,1.298403e-001,-1.238746e+000,-1.238746e+000,-2.332758e-001,-2.321707e-001,-1.232974e+000,-2.275035e-001,-2.263983e-001,-1.551472e-003,-1.551472e-003,,,,,,,,,,,,,,,,,,,,
1473343179.517,,5.000000e+001,2.727863e+001,2.662288e+001,1,0,2.591055e+000,1.519822e-001,1.519822e-001,1.158309e+000,1.158309e+000,1.644968e-001,1.170824e+000,1.170824e+000,1.903506e-004,1.903506e-004,,,,,,,,,,,,,,,,,,,,
1473343179.517,,5.000000e+001,2.727863e+001,2.662288e+001,1,0,4.825587e+000,-1.266823e+000,-1.266823e+000,-2.648814e-001,-2.604963e-001,-1.254899e+000,-2.529568e-001,-2.485716e-001,-1.586637e-003,-1.586637e-003,,,,,,,,,,,,,,,,,,,,
1473343193.981,,5.000000e+001,2.629804e+001,2.563987e+001,1,0,3.736799e+000,-1.314280e+000,-1.314280e+000,-3.117641e-001,-3.084346e-001,-1.316512e+000,-3.139963e-001,-3.106668e-001,-1.646074e-003,-1.646074e-003,,,,,,,,,,,,,,,,,,,,
1473343208.446,,5.000000e+001,2.531596e+001,2.481446e+001,1,0,1.025317e+000,-1.761071e+000,-1.761071e+000,-4.863866e-001,-4.841564e-001,-1.775918e+000,-5.012341e-001,-4.990039e-001,-2.205659e-003,-2.205659e-003,,,,,,,,,,,,,,,,,,,,
1473343220.845,,5.000000e+001,2.464712e+001,2.400928e+001,1,0,2.333937e-001,-1.560564e+000,-1.560564e+000,-2.852119e-001,-2.841332e-001,-1.554716e+000,-2.793638e-001,-2.782851e-001,-1.954534e-003,-1.954534e-003,,,,,,,,,,,,,,,,,,,,
1473343220.845,,5.000000e+001,2.464712e+001,2.400928e+001,1,0,2.812172e+000,-2.520829e-001,-2.520829e-001,1.018685e+000,1.024348e+000,-2.658094e-001,1.004958e+000,1.010621e+000,-3.157221e-004,-3.157221e-004,,,,,,,,,,,,,,,,,,,,
1473343234.167,,5.000000e+001,2.374620e+001,2.348778e+001,1,0,4.910456e+000,-1.508835e+000,-1.508835e+000,-2.372773e-001,-2.326185e-001,-1.498696e+000,-2.271379e-001,-2.224790e-001,-1.889746e-003,-1.889746e-003,,,,,,,,,,,,,,,,,,,,
1473343247.132,,5.000000e+001,2.342897e+001,2.303792e+001,1,0,3.525861e+000,-1.338694e+000,-1.338694e+000,-6.640506e-002,-6.296241e-002,-1.339717e+000,-6.742728e-002,-6.398463e-002,-1.676653e-003,-1.676653e-003,,,,,,,,,,,,,,,,,,,,
1473343260.846,,5.000000e+001,2.275039e+001,2.207347e+001,1,0,8.594698e-001,-1.802576e+000,-1.802576e+000,-5.296298e-001,-5.273713e-001,-1.815780e+000,-5.428340e-001,-5.405755e-001,-2.257643e-003,-2.257643e-003,,,,,,,,,,,,,,,,,,,,
1473343272.810,,5.000000e+001,2.173353e+001,2.119132e+001,1,0,3.629605e-001,-1.626942e+000,-1.626942e+000,-3.531485e-001,-3.520854e-001,-1.622525e+000,-3.487323e-001,-3.476691e-001,-2.037669e-003,-2.037669e-003,,,,,,,,,,,,,,,,,,,,
1473343272.810,,5.000000e+001,2.173353e+001,2.119132e+001,1,0,3.027290e+000,-5.327006e-001,-5.327006e-001,7.361634e-001,7.421557e-001,-5.652761e-001,7.035879e-001,7.095802e-001,-6.671828e-004,-6.671828e-004,,,,,,,,,,,,,,,,,,,,
1473343285.524,,5.000000e+001,2.093397e+001,2.076250e+001,1,0,4.967701e+000,-1.490982e+000,-1.490982e+000,-2.213825e-001,-2.165000e-001,-1.480770e+000,-2.111709e-001,-2.062885e-001,-1.867386e-003,-1.867386e-003,,,,,,,,,,,,,,,,,,,,
1473343296.741,,5.000000e+001,2.074047e+001,2.070403e+001,1,0,3.308721e+000,-1.014893e+000,-1.014893e+000,2.557076e-001,2.591790e-001,-1.019251e+000,2.513497e-001,2.548211e-001,-1.271107e-003,-1.271107e-003,,,,,,,,,,,,,,,,,,,,
1473343308.755,,5.000000e+001,2.057548e+001,1.990764e+001,1,0,7.006193e-001,-1.782128e+000,-1.782128e+000,-5.108272e-001,-5.085975e-001,-1.788456e+000,-5.171548e-001,-5.149250e-001,-2.232033e-003,-2.232033e-003,,,,,,,,,,,,,,,,,,,,
1473343324.723,,5.000000e+001,1.954249e+001,1.885139e+001,1,0,5.142772e-001,-1.706900e+000,-1.706900e+000,-4.349740e-001,-4.339858e-001,-1.707397e+000,-4.354709e-001,-4.344827e-001,-2.137813e-003,-2.137813e-003,,,,,,,,,,,,,,,,,,,,
1473343324.723,,5.000000e+001,1.954249e+001,1.885139e+001,1,0,3.234298e+000,-8.624531e-001,-8.624531e-001,4.044334e-001,4.104613e-001,-8.929943e-001,3.738922e-001,3.799201e-001,-1.080182e-003,-1.080182e-003,,,,,,,,,,,,,,,,,,,,
1473343337.470,,5.000000e+001,1.868196e+001,1.780951e+001,1,0,4.993496e+000,-1.485794e+000,-1.485794e+000,-2.182318e-001,-2.133318e-001,-1.473876e+000,-2.063142e-001,-2.014142e-001,-1.860888e-003,-1.860888e-003,,,,,,,,,,,,,,,,,,,,
1473343350.434,,5.000000e+001,1.763659e+001,1.697535e+001,1,0,3.086651e+000,-6.387524e-001,-6.387524e-001,6.298479e-001,6.334105e-001,-6.427941e-001,6.258062e-001,6.293688e-001,-8.000078e-004,-8.000078e-004,,,,,,,,,,,,,,,,,,,,
1473343364.148,,5.000000e+001,1.669270e+001,1.619576e+001,1,0,5.499848e-001,-1.733909e+000,-1.733909e+000,-4.644664e-001,-4.622260e-001,-1.731973e+000,-4.625300e-001,-4.602897e-001,-2.171641e-003,-2.171641e-003,,,,,,,,,,,,,,,,,,,,
1473343378.417,,5.000000e+001,1.607770e+001,1.564913e+001,1,0,6.832473e-001,-1.788995e+000,-1.788995e+000,-5.187113e-001,-5.177583e-001,-1.797387e+000,-5.271029e-001,-5.261499e-001,-2.240633e-003,-2.240633e-003,,,,,,,,,,,,,,,,,,,,
1473343378.417,,5.000000e+001,1.607770e+001,1.564913e+001,1,0,3.432572e+000,-1.184576e+000,-1.184576e+000,8.030715e-002,8.666086e-002,-1.199694e+000,6.518926e-002,7.154298e-002,-1.483626e-003,-1.483626e-003,,,,,,,,,,,,,,,,,,,,
1473343391.381,,5.000000e+001,1.561927e+001,1.564647e+001,1,0,4.986050e+000,-1.491134e+000,-1.491134e+000,-2.252253e-001,-2.204009e-001,-1.478018e+000,-2.121091e-001,-2.072848e-001,-1.867577e-003,-1.867577e-003,,,,,,,,,,,,,,,,,,,,
1473343403.345,,5.000000e+001,1.565911e+001,1.560604e+001,1,0,2.861366e+000,-2.760399e-001,-2.760399e-001,9.909136e-001,9.943956e-001,-2.670185e-001,9.999351e-001,1.003417e+000,-3.457272e-004,-3.457272e-004,,,,,,,,,,,,,,,,,,,,
1473343416.559,,5.000000e+001,1.554284e+001,1.472009e+001,1,0,4.096711e-001,-1.666311e+000,-1.666311e+000,-3.986266e-001,-3.964355e-001,-1.657870e+000,-3.901860e-001,-3.879949e-001,-2.086977e-003,-2.086977e-003,,,,,,,,,,,,,,,,,,,,
1473343429.473,,5.000000e+001,1.455830e+001,1.351971e+001,1,0,8.662986e-001,-1.825617e+000,-1.825617e+000,-5.571839e-001,-5.563343e-001,-1.843586e+000,-5.751528e-001,-5.743032e-001,-2.286501e-003,-2.286501e-003,,,,,,,,,,,,,,,,,,,,
1473343429.473,,5.000000e+001,1.455830e+001,1.351971e+001,1,0,3.621726e+000,-1.463057e+000,-1.463057e+000,-2.000405e-001,-1.937745e-001,-1.468456e+000,-2.054389e-001,-1.991729e-001,-1.832412e-003,-1.832412e-003,,,,,,,,,,,,,,,,,,,,
1473343442.799,,5.000000e+001,1.329832e+001,1.242391e+001,1,0,4.944773e+000,-1.508225e+000,-1.508225e+000,-2.443819e-001,-2.394875e-001,-1.494576e+000,-2.307328e-001,-2.258384e-001,-1.888982e-003,-1.888982e-003,,,,,,,,,,,,,,,,,,,,
1473343461.514,,5.000000e+001,1.221425e+001,1.207273e+001,1,0,2.634893e+000,2.604755e-001,2.604755e-001,1.253187e+000,1.256664e+000,2.869757e-001,1.279688e+000,1.283165e+000,3.262335e-004,3.262335e-004,,,,,,,,,,,,,,,,,,,,
1473343678.753,,5.000000e+001,1.500274e+001,1.500274e+001,1,0,2.832192e-001,-1.622364e+000,-1.622364e+000,-3.335571e-001,-3.315840e-001,-1.612559e+000,-3.237518e-001,-3.217787e-001,-2.031936e-003,-2.031936e-003,,,,,,,,,,,,,,,,,,,,
1473343691.217,,5.000000e+001,1.500335e+001,1.500396e+001,1,0,1.060559e+000,-1.795099e+000,-1.795099e+000,-5.032176e-001,-5.025072e-001,-1.814976e+000,-5.230943e-001,-5.223839e-001,-2.248278e-003,-2.248278e-003,,,,,,,,,,,,,,,,,,,,
1473343691.217,,5.000000e+001,1.500335e+001,1.500396e+001,1,0,3.802394e+000,-1.696371e+000,-1.696371e+000,-4.096658e-001,-4.037797e-001,-1.697501e+000,-4.107953e-001,-4.049093e-001,-2.124626e-003,-2.124626e-003,,,,,,,,,,,,,,,,,,,,
1473343702.431,,5.000000e+001,1.500274e+001,1.500213e+001,1,0,4.870952e+000,-1.560717e+000,-1.560717e+000,-2.714216e-001,-2.669760e-001,-1.547198e+000,-2.579032e-001,-2.534575e-001,-1.954725e-003,-1.954725e-003,,,,,,,,,,,,,,,,,,,,
1473343714.645,,5.000000e+001,1.500213e+001,1.500091e+001,1,0,2.409886e+000,-2.624592e-002,-2.624592e-002,1.265590e+000,1.268800e+000,-9.535000e-003,1.282301e+000,1.285511e+000,-3.287180e-005,-3.287180e-005,,,,,,,,,,,,,,,,,,,,
1473343807.368,,5.000000e+001,1.499725e+001,1.499664e+001,1,0,1.752381e-001,-1.578112e+000,-1.578112e+000,-2.778720e-001,-2.758862e-001,-1.572952e+000,-2.727114e-001,-2.707256e-001,-1.976512e-003,-1.976512e-003,,,,,,,,,,,,,,,,,,,,
1473343819.582,,5.000000e+001,1.499664e+001,1.499481e+001,1,0,1.263938e+000,-1.643117e+000,-1.643117e+000,-3.419235e-001,-3.412836e-001,-1.656871e+000,-3.556781e-001,-3.550382e-001,-2.057927e-003,-2.057927e-003,,,,,,,,,,,,,,,,,,,,
1473343819.582,,5.000000e+001,1.499664e+001,1.499481e+001,1,0,3.975317e+000,-1.830195e+000,-1.830195e+000,-5.344414e-001,-5.283620e-001,-1.830961e+000,-5.352073e-001,-5.291280e-001,-2.292234e-003,-2.292234e-003,,,,,,,,,,,,,,,,,,,,
1473343831.046,,5.000000e+001,1.499603e+001,1.499420e+001,1,0,4.767376e+000,-1.616108e+000,-1.616108e+000,-3.196630e-001,-3.149794e-001,-1.601296e+000,-3.048517e-001,-3.001682e-001,-2.024100e-003,-2.024100e-003,,,,,,,,,,,,,,,,,,,,
1473343843.510,,5.000000e+001,1.499603e+001,1.499420e+001,1,0,2.188694e+000,-2.238533e-001,-2.238533e-001,1.072786e+000,1.076109e+000,-2.376241e-001,1.059016e+000,1.062338e+000,-2.803658e-004,-2.803658e-004,,,,,,,,,,,,,,,,,,,,
1473343907.268,,5.000000e+001,1.393347e+001,1.365101e+001,1,0,9.039186e-002,-1.535081e+000,-1.535081e+000,-2.426823e-001,-2.407414e-001,-1.531222e+000,-2.388229e-001,-2.368820e-001,-1.922618e-003,-1.922618e-003,,,,,,,,,,,,,,,,,,,,
1473343920.982,,5.000000e+001,1.359656e+001,1.332812e+001,1,0,1.474820e+000,-1.374249e+000,-1.374249e+000,-8.161145e-002,-8.106339e-002,-1.382156e+000,-8.951908e-002,-8.897102e-002,-1.721182e-003,-1.721182e-003,,,,,,,,,,,,,,,,,,,,
1473343920.982,,5.000000e+001,1.359656e+001,1.332812e+001,1,0,4.141151e+000,-1.864681e+000,-1.864681e+000,-5.776340e-001,-5.714958e-001,-1.863983e+000,-5.769365e-001,-5.707983e-001,-2.335426e-003,-2.335426e-003,,,,,,,,,,,,,,,,,,,,
1473343933.696,,5.000000e+001,1.327614e+001,1.306990e+001,1,0,4.637797e+000,-1.677297e+000,-1.677297e+000,-3.897021e-001,-3.850343e-001,-1.662295e+000,-3.747003e-001,-3.700325e-001,-2.100737e-003,-2.100737e-003,,,,,,,,,,,,,,,,,,,,
1473343944.933,,5.000000e+001,1.301941e+001,1.281965e+001,1,0,1.973635e+000,-5.291910e-001,-5.291910e-001,7.591154e-001,7.623276e-001,-5.640752e-001,7.242312e-001,7.274434e-001,-6.627871e-004,-6.627871e-004,,,,,,,,,,,,,,,,,,,,
1473343958.698,,5.000000e+001,1.277101e+001,1.252716e+001,1,0,3.321484e-002,-1.511582e+000,-1.511582e+000,-2.226380e-001,-2.207887e-001,-1.507173e+000,-2.182297e-001,-2.163804e-001,-1.893186e-003,-1.893186e-003,,,,,,,,,,,,,,,,,,,,
1473343971.412,,5.000000e+001,1.247916e+001,1.228878e+001,1,0,1.691984e+000,-1.037324e+000,-1.037324e+000,2.525706e-001,2.529945e-001,-1.043971e+000,2.459235e-001,2.463474e-001,-1.299200e-003,-1.299200e-003,,,,,,,,,,,,,,,,,,,,
1473343971.412,,5.000000e+001,1.247916e+001,1.228878e+001,1,0,4.299989e+000,-1.838740e+000,-1.838740e+000,-5.542508e-001,-5.484215e-001,-1.831974e+000,-5.474841e-001,-5.416548e-001,-2.302937e-003,-2.302937e-003,,,,,,,,,,,,,,,,,,,,
1473343986.626,,5.000000e+001,1.219404e+001,1.200312e+001,1,0,4.486486e+000,-1.757103e+000,-1.757103e+000,-4.718841e-001,-4.672925e-001,-1.745146e+000,-4.599265e-001,-4.553349e-001,-2.200690e-003,-2.200690e-003,,,,,,,,,,,,,,,,,,,,
1473344000.282,,5.000000e+001,1.191001e+001,1.172146e+001,1,0,1.766540e+000,-8.825952e-001,-8.825953e-001,4.035853e-001,4.067153e-001,-9.154911e-001,3.706895e-001,3.738195e-001,-1.105410e-003,-1.105410e-003,,,,,,,,,,,,,,,,,,,,
1473344014.104,,5.000000e+001,1.162891e+001,1.144397e+001,1,0,7.228849e-003,-1.503037e+000,-1.503037e+000,-2.159039e-001,-2.141194e-001,-1.497054e+000,-2.099211e-001,-2.081367e-001,-1.882484e-003,-1.882484e-003,,,,,,,,,,,,,,,,,,,,
1473344027.069,,5.000000e+001,1.135140e+001,1.116726e+001,1,0,1.914062e+000,-6.611835e-001,-6.611835e-001,6.268758e-001,6.272044e-001,-6.622047e-001,6.258546e-001,6.261832e-001,-8.281017e-004,-8.281017e-004,,,,,,,,,,,,,,,,,,,,
1473344027.069,,5.000000e+001,1.135140e+001,1.116726e+001,1,0,4.450786e+000,-1.777856e+000,-1.777856e+000,-4.953831e-001,-4.894679e-001,-1.763104e+000,-4.806316e-001,-4.747163e-001,-2.226682e-003,-2.226682e-003,,,,,,,,,,,,,,,,,,,,
1473344040.294,,5.000000e+001,1.112176e+001,1.093933e+001,1,0,4.317494e+000,-1.832331e+000,-1.832331e+000,-5.487318e-001,-5.441847e-001,-1.827562e+000,-5.439630e-001,-5.394158e-001,-2.294910e-003,-2.294910e-003,,,,,,,,,,,,,,,,,,,,
1473344053.314,,5.000000e+001,1.089354e+001,1.070946e+001,1,0,1.568254e+000,-1.212043e+000,-1.212043e+000,7.276709e-002,7.581162e-002,-1.235201e+000,4.960901e-002,5.265355e-002,-1.518027e-003,-1.518027e-003,,,,,,,,,,,,,,,,,,,,
1473344066.528,,5.000000e+001,1.066496e+001,1.043922e+001,1,0,1.470958e-002,-1.507157e+000,-1.507157e+000,-2.206010e-001,-2.189405e-001,-1.499971e+000,-2.134153e-001,-2.117548e-001,-1.887644e-003,-1.887644e-003,,,,,,,,,,,,,,,,,,,,
1473344078.743,,5.000000e+001,1.039316e+001,1.020969e+001,1,0,2.139419e+000,-2.916043e-001,-2.916044e-001,9.955534e-001,9.957740e-001,-2.783070e-001,1.008851e+000,1.009071e+000,-3.652209e-004,-3.652209e-004,,,,,,,,,,,,,,,,,,,,
1473344078.743,,5.000000e+001,1.039316e+001,1.020969e+001,1,0,4.591112e+000,-1.706748e+000,-1.706748e+000,-4.252156e-001,-4.193692e-001,-1.686512e+000,-4.049797e-001,-3.991333e-001,-2.137622e-003,-2.137622e-003,,,,,,,,,,,,,,,,,,,,
1473344092.957,,5.000000e+001,1.011828e+001,9.936956e+000,1,0,4.134444e+000,-1.864681e+000,-1.864681e+000,-5.816197e-001,-5.771939e-001,-1.868368e+000,-5.853066e-001,-5.808808e-001,-2.335426e-003,-2.335426e-003,,,,,,,,,,,,,,,,,,,,
1473344105.111,,5.000000e+001,9.892939e+000,9.757333e+000,1,0,1.379017e+000,-1.491745e+000,-1.491745e+000,-2.081923e-001,-2.051932e-001,-1.507365e+000,-2.238129e-001,-2.208138e-001,-1.868341e-003,-1.868341e-003,,,,,,,,,,,,,,,,,,,,
1473344117.684,,5.000000e+001,9.670424e+000,9.492496e+000,1,0,5.597847e-002,-1.521348e+000,-1.521348e+000,-2.363477e-001,-2.348046e-001,-1.514497e+000,-2.294966e-001,-2.279536e-001,-1.905418e-003,-1.905418e-003,,,,,,,,,,,,,,,,,,,,
1473344140.894,,5.000000e+001,9.231415e+000,9.060871e+000,1,0,2.365749e+000,-1.373333e-002,-1.373333e-002,6.296747e-001,6.297286e-001,2.731917e-004,6.436812e-001,6.437351e-001,-3.440072e-005,-3.440072e-005,,,,,,,,,,,,,,,,,,,,
1473344140.894,,5.000000e+001,9.231415e+000,9.060871e+000,1,0,4.717449e+000,-8.194219e-001,-8.194220e-001,-1.787645e-001,-1.759601e-001,-8.096532e-001,-1.689958e-001,-1.661913e-001,-2.052576e-003,-2.052576e-003,,,,,,,,,,,,,,,,,,,,
1473344154.108,,5.000000e+001,8.975334e+000,8.851753e+000,1,0,3.940213e+000,-9.036530e-001,-9.036531e-001,-2.621495e-001,-2.599984e-001,-9.068917e-001,-2.653882e-001,-2.632371e-001,-2.263567e-003,-2.263567e-003,,,,,,,,,,,,,,,,,,,,
1473344166.822,,5.000000e+001,8.811769e+000,8.655733e+000,1,0,1.198400e+000,-8.517717e-001,-8.517716e-001,-2.091959e-001,-2.077696e-001,-8.588839e-001,-2.163082e-001,-2.148818e-001,-2.133609e-003,-2.133609e-003,,,,,,,,,,,,,,,,,,,,
1473344178.537,,5.000000e+001,8.618799e+000,8.473164e+000,1,0,1.297805e-001,-7.770013e-001,-7.770013e-001,-1.333110e-001,-1.325926e-001,-7.738487e-001,-1.301585e-001,-1.294400e-001,-1.946316e-003,-1.946316e-003,,,,,,,,,,,,,,,,,,,,
1473344190.022,,5.000000e+001,8.437635e+000,8.330385e+000,1,0,2.590783e+000,1.144444e-002,1.144444e-002,6.557127e-001,6.557127e-001,1.783600e-002,6.621042e-001,6.621042e-001,2.866726e-005,2.866726e-005,,,,,,,,,,,,,,,,,,,,
1473344190.022,,5.000000e+001,8.437635e+000,8.330385e+000,1,0,4.825444e+000,-7.908872e-001,-7.908872e-001,-1.493925e-001,-1.466189e-001,-7.842696e-001,-1.427749e-001,-1.400013e-001,-1.981099e-003,-1.981099e-003,,,,,,,,,,,,,,,,,,,,
1473344200.988,,5.000000e+001,8.330385e+000,8.166164e+000,1,0,3.736837e+000,-8.177435e-001,-8.177435e-001,-1.752900e-001,-1.732185e-001,-8.192503e-001,-1.767968e-001,-1.747254e-001,-2.048372e-003,-2.048372e-003,,,,,,,,,,,,,,,,,,,,
1473344212.952,,5.000000e+001,8.166164e+000,8.039879e+000,1,0,1.025459e+000,-9.137241e-001,-9.137242e-001,-2.701683e-001,-2.687883e-001,-9.215316e-001,-2.779757e-001,-2.765957e-001,-2.288794e-003,-2.288794e-003,,,,,,,,,,,,,,,,,,,,
1473344229.425,,5.000000e+001,7.947674e+000,7.828452e+000,1,0,2.333664e-001,-8.017213e-001,-8.017212e-001,-1.574486e-001,-1.568136e-001,-7.984882e-001,-1.542156e-001,-1.535806e-001,-2.008237e-003,-2.008237e-003,,,,,,,,,,,,,,,,,,,,
1473344229.425,,5.000000e+001,7.947674e+000,7.828452e+000,1,0,2.812028e+000,-8.148442e-002,-8.148442e-002,5.600894e-001,5.634232e-001,-8.843470e-002,5.531392e-001,5.564729e-001,-2.041109e-004,-2.041109e-004,,,,,,,,,,,,,,,,,,,,
1473344243.139,,5.000000e+001,7.799812e+000,7.712914e+000,1,0,4.910307e+000,-7.722709e-001,-7.722709e-001,-1.298857e-001,-1.271617e-001,-7.667985e-001,-1.244133e-001,-1.216893e-001,-1.934467e-003,-1.934467e-003,,,,,,,,,,,,,,,,,,,,
1473344254.853,,5.000000e+001,7.660809e+000,7.555223e+000,1,0,3.525912e+000,-6.802576e-001,-6.802576e-001,-3.682353e-002,-3.476650e-002,-6.810743e-001,-3.764024e-002,-3.558320e-002,-1.703982e-003,-1.703982e-003,,,,,,,,,,,,,,,,,,,,
1473344266.067,,5.000000e+001,7.555223e+000,7.457264e+000,1,0,8.595704e-001,-9.320353e-001,-9.320353e-001,-2.877935e-001,-2.864581e-001,-9.388556e-001,-2.946139e-001,-2.932785e-001,-2.334662e-003,-2.334662e-003,,,,,,,,,,,,,,,,,,,,
1473344331.787,,5.000000e+001,6.961990e+000,6.882856e+000,1,0,3.629266e-001,-8.372753e-001,-8.372753e-001,-1.908440e-001,-1.902450e-001,-8.348381e-001,-1.884068e-001,-1.878078e-001,-2.097297e-003,-2.097297e-003,,,,,,,,,,,,,,,,,,,,
1473344331.787,,5.000000e+001,6.961990e+000,6.882856e+000,1,0,3.027123e+000,-2.471999e-001,-2.471999e-001,3.964544e-001,3.998304e-001,-2.644162e-001,3.792381e-001,3.826141e-001,-6.192129e-004,-6.192129e-004,,,,,,,,,,,,,,,,,,,,
1473344343.501,,5.000000e+001,6.863554e+000,6.802374e+000,1,0,4.967558e+000,-7.635731e-001,-7.635731e-001,-1.186968e-001,-1.160612e-001,-7.581965e-001,-1.133202e-001,-1.106846e-001,-1.912680e-003,-1.912680e-003,,,,,,,,,,,,,,,,,,,,
1473344353.965,,5.000000e+001,6.783313e+000,6.719923e+000,1,0,3.308737e+000,-5.092013e-001,-5.092013e-001,1.368939e-001,1.388609e-001,-5.117571e-001,1.343381e-001,1.363052e-001,-1.275502e-003,-1.275502e-003,,,,,,,,,,,,,,,,,,,,
1473344366.429,,5.000000e+001,6.698358e+000,6.622945e+000,1,0,7.007163e-001,-6.494339e-001,-6.494339e-001,-2.077743e-001,-1.404920e-001,-7.248238e-001,-2.831641e-001,-2.158819e-001,-1.626772e-003,-1.626772e-003,,,,,,,,,,,,,,,,,,,,
1473344422.398,,5.000000e+001,5.943312e+000,5.811363e+000,1,0,5.142773e-001,-8.772546e-001,-8.772545e-001,-2.311316e-001,-2.305594e-001,-8.774411e-001,-2.313182e-001,-2.307460e-001,-2.197441e-003,-2.197441e-003,,,,,,,,,,,,,,,,,,,,
1473344422.398,,5.000000e+001,5.943312e+000,5.811363e+000,1,0,3.234229e+000,-4.292428e-001,-4.292428e-001,2.139618e-001,2.174523e-001,-4.451982e-001,1.980064e-001,2.014969e-001,-1.075214e-003,-1.075214e-003,,,,,,,,,,,,,,,,,,,,
1473344434.151,,5.000000e+001,5.811363e+000,5.679643e+000,1,0,4.993509e+000,-7.582324e-001,-7.582324e-001,-1.150237e-001,-1.122481e-001,-7.519135e-001,-1.087049e-001,-1.059293e-001,-1.899302e-003,-1.899302e-003,,,,,,,,,,,,,,,,,,,,
1473344445.865,,5.000000e+001,5.619110e+000,5.521118e+000,1,0,3.086673e+000,-3.135777e-001,-3.135777e-001,3.298327e-001,3.318450e-001,-3.158442e-001,3.275662e-001,3.295785e-001,-7.854830e-004,-7.854830e-004,,,,,,,,,,,,,,,,,,,,
1473344458.262,,5.000000e+001,5.460263e+000,5.336331e+000,1,0,5.500216e-001,-8.861049e-001,-8.861049e-001,-2.424208e-001,-2.411405e-001,-8.849850e-001,-2.413008e-001,-2.400206e-001,-2.219611e-003,-2.219611e-003,,,,,,,,,,,,,,,,,,,,
1473344563.119,,5.000000e+001,4.991529e+000,5.000788e+000,1,0,6.832553e-001,-9.479049e-001,-9.479049e-001,-2.698090e-001,-2.693124e-001,-9.521728e-001,-2.740769e-001,-2.735803e-001,-2.374414e-003,-2.374414e-003,,,,,,,,,,,,,,,,,,,,
1473344563.119,,5.000000e+001,4.991529e+000,5.000788e+000,1,0,3.432463e+000,-6.335642e-001,-6.335642e-001,4.171782e-002,4.502821e-002,-6.415423e-001,3.373980e-002,3.705019e-002,-1.587020e-003,-1.587020e-003,,,,,,,,,,,,,,,,,,,,
1473344575.083,,5.000000e+001,5.000788e+000,5.006361e+000,1,0,4.986013e+000,-7.928709e-001,-7.928709e-001,-1.169464e-001,-1.143551e-001,-7.861150e-001,-1.101905e-001,-1.075993e-001,-1.986068e-003,-1.986068e-003,,,,,,,,,,,,,,,,,,,,
1473344587.298,,5.000000e+001,5.009464e+000,5.015435e+000,1,0,2.861407e+000,-1.622059e-001,-1.622059e-001,5.147123e-001,5.165721e-001,-1.574493e-001,5.194688e-001,5.213287e-001,-4.063107e-004,-4.063107e-004,,,,,,,,,,,,,,,,,,,,
1473344598.512,,5.000000e+001,5.015435e+000,5.019050e+000,1,0,4.097025e-001,-8.841212e-001,-8.841212e-001,-2.065445e-001,-2.053707e-001,-8.796886e-001,-2.021118e-001,-2.009380e-001,-2.214642e-003,-2.214642e-003,,,,,,,,,,,,,,,,,,,,
1473344598.512,,5.000000e+001,5.015435e+000,5.019050e+000,1,0,2.812069e+000,-1.120029e-001,-1.120029e-001,5.632262e-001,5.667477e-001,-1.190484e-001,5.561808e-001,5.597022e-001,-2.805570e-004,-2.805570e-004,,,,,,,,,,,,,,,,,,,,