File: data/A344/A344_GdN_MH_070K_160905.rso.dat
[Header]
TITLE,MPMS RSO Measurement
BYAPP,MPMS Measurement,1.1,Summary
FILEOPENTIME, 1473226403.087000 9/7/2016, 5:33:23 PM

INFO, APPNAME, MPMS MultiVu Application, Revision 1.61,  Build 082

INFO, NAME, A344
INFO, WEIGHT, 10.500
INFO, AREA, 1.000
INFO, LENGTH, 1.000
INFO, SHAPE, 0
INFO, COMMENT, m = 0.0105g
INFO, SEQUENCE FILE: 7T_hysteresis_sweep_hi_res_zero_n4.seq


INFO, BACKGROUND DATA FILE:, None


STARTUPAXIS,X,4,LINEAR,AUTO,0.000000,0.000000
STARTUPAXIS,Y1,5,LINEAR,AUTO,0.000000,0.000000


STARTUPGROUP,Longitudinal
FIELDGROUP,Longitudinal,1,2,3,4,5,6,7,8,9,10,11,19,20,21,22,23,35
FIELDGROUP,Transverse,1,2,3,4,12,13,14,15,16,17,18,24,25,26,27,28,35

PLOT_APPEARANCE,ALL,HORZ_GRID_ON,VERT_GRID_ON,MARKERS_AND_LINES

[Data]
Time,Comment,Field (Oe),Temperature (K),Long Moment (emu),Long Scan Std Dev,Long Offset (cm),Long Offset Std Dev,Long Algorithm,Long Reg Fit,Long Reg Factor,Trans Moment (emu),Trans Scan Std Dev,Trans Offset (cm),Trans Offset Std Dev,Trans Algorithm,Trans Reg Fit,Trans Reg Factor,Long Moment [w/o ABS] (emu),Long Scan Std Dev [w/o ABS],Long Offset [w/o ABS] (cm),Long Offset Std Dev [w/o ABS],Long Reg Fit [w/o ABS],Trans Moment [w/o ABS] (emu),Trans Scan Std Dev [w/o ABS],Trans Offset [w/o ABS] (cm),Trans Offset Std Dev [w/o ABS],Trans Reg Fit [w/o ABS],RSO Position (deg),Amplitude (cm),Frequency,Cycles to Average,Scans per Measurement,Delta Temp (K),Error,EC Comp. Running,Using ABS,
1473226403.086,,7.000000e+004,7.010249e+001,7.470404e-004,0.000000e+000,1.617707e-002,0.000000e+000,3,9.292122e-001,1.825000e+000,,,,,,,,,,,,,,,,,,0,5.000000e+000,5.000000e-001,2,1,2.367401e-002,0,1,0,
1473226429.765,,7.000000e+004,7.005753e+001,7.450775e-004,0.000000e+000,2.004876e-002,0.000000e+000,3,9.306277e-001,1.825000e+000,,,,,,,,,,,,,,,,,,0,5.000000e+000,5.000000e-001,2,1,1.419067e-002,0,1,0,
1473226619.468,,6.000000e+004,7.000435e+001,7.314036e-004,0.000000e+000,1.900106e-002,0.000000e+000,3,9.279147e-001,1.825000e+000,,,,,,,,,,,,,,,,,,0,5.000000e+000,5.000000e-001,2,1,2.357483e-003,0,1,0,
1473226646.697,,6.000000e+004,7.000317e+001,7.317932e-004,0.000000e+000,1.847890e-002,0.000000e+000,3,9.284581e-001,1.825000e+000,,,,,,,,,,,,,,,,,,0,5.000000e+000,5.000000e-001,2,1,9.445190e-003,0,1,0,
1473226824.702,,5.000000e+004,7.000198e+001,7.019813e-004,0.000000e+000,1.498021e-002,0.000000e+000,3,9.229340e-001,1.825000e+000,,,,,,,,,,,,,,,,,,0,5.000000e+000,5.000000e-001,2,1,1.652527e-002,0,1,0,
1473226851.989,,5.000000e+004,7.000080e+001,6.976807e-004,0.000000e+000,1.724349e-002,0.000000e+000,3,9.246263e-001,1.825000e+000,,,,,,,,,,,,,,,,,,0,5.000000e+000,5.000000e-001,2,1,9.445190e-003,0,1,0,
1473227028.974,,4.000000e+004,6.999844e+001,6.665404e-004,0.000000e+000,1.434885e-002,0.000000e+000,3,9.216343e-001,1.825000e+000,,,,,,,,,,,,,,,,,,0,5.000000e+000,5.000000e-001,2,1,4.722595e-003,0,1,0,
1473227054.418,,4.000000e+004,6.999726e+001,6.686719e-004,0.000000e+000,1.180138e-002,0.000000e+000,3,9.259402e-001,1.825000e+000,,,,,,,,,,,,,,,,,,0,5.000000e+000,5.000000e-001,2,1,7.080078e-003,0,1,0,
1473227238.117,,3.000000e+004,7.000081e+001,6.201314e-004,0.000000e+000,1.096175e-002,0.000000e+000,3,9.165662e-001,1.825000e+000,,,,,,,,,,,,,,,,,,0,5.000000e+000,5.000000e-001,2,1,4.722595e-003,0,1,0,
1473227264.795,,3.000000e+004,7.000198e+001,6.173931e-004,0.000000e+000,1.099624e-002,0.000000e+000,3,9.163815e-001,1.825000e+000,,,,,,,,,,,,,,,,,,0,5.000000e+000,5.000000e-001,2,1,7.080078e-003,0,1,0,
1473227438.243,,2.000000e+004,7.000789e+001,5.511979e-004,0.000000e+000,1.114965e-002,0.000000e+000,3,9.102690e-001,1.825000e+000,,,,,,,,,,,,,,,,,,0,5.000000e+000,5.000000e-001,2,1,2.833557e-002,0,1,0,
1473227465.216,,2.000000e+004,7.000198e+001,5.532329e-004,0.000000e+000,9.974694e-003,0.000000e+000,3,9.109303e-001,1.825000e+000,,,,,,,,,,,,,,,,,,0,5.000000e+000,5.000000e-001,2,1,1.181030e-002,0,1,0,
1473227638.453,,1.000000e+004,7.000316e+001,4.380405e-004,0.000000e+000,7.270006e-003,0.000000e+000,3,8.905506e-001,1.825000e+000,,,,,,,,,,,,,,,,,,0,5.000000e+000,5.000000e-001,2,1,4.722595e-003,0,1,0,
1473227665.392,,1.000000e+004,7.000081e+001,4.373652e-004,0.000000e+000,6.974421e-003,0.000000e+000,3,8.891556e-001,1.825000e+000,,,,,,,,,,,,,,,,,,0,5.000000e+000,5.000000e-001,2,1,4.722595e-003,0,1,0,
1473227800.337,,9.000000e+003,6.999608e+001,4.197512e-004,0.000000e+000,5.740547e-003,0.000000e+000,3,8.871012e-001,1.825000e+000,,,,,,,,,,,,,,,,,,0,5.000000e+000,5.000000e-001,2,1,0.000000e+000,0,1,0,
1473227825.454,,9.000000e+003,7.000317e+001,4.188589e-004,0.000000e+000,5.466654e-003,0.000000e+000,3,8.874027e-001,1.825000e+000,,,,,,,,,,,,,,,,,,0,5.000000e+000,5.000000e-001,2,1,0.000000e+000,0,1,0,
1473227969.784,,7.000000e+003,6.999371e+001,3.787114e-004,0.000000e+000,4.663144e-003,0.000000e+000,3,8.753085e-001,1.825000e+000,,,,,,,,,,,,,,,,,,0,5.000000e+000,5.000000e-001,2,1,1.416779e-002,0,1,0,
1473227997.962,,7.000000e+003,7.000316e+001,3.796534e-004,0.000000e+000,4.476017e-003,0.000000e+000,3,8.766667e-001,1.825000e+000,,,,,,,,,,,,,,,,,,0,5.000000e+000,5.000000e-001,2,1,1.416779e-002,0,1,0,
1473228135.406,,5.000000e+003,6.999844e+001,3.254472e-004,0.000000e+000,2.183096e-003,0.000000e+000,3,8.584363e-001,1.825000e+000,,,,,,,,,,,,,,,,,,0,5.000000e+000,5.000000e-001,2,1,4.722595e-003,0,1,0,
1473228162.136,,5.000000e+003,7.000080e+001,3.262153e-004,0.000000e+000,1.293260e-003,0.000000e+000,3,8.601473e-001,1.825000e+000,,,,,,,,,,,,,,,,,,0,5.000000e+000,5.000000e-001,2,1,0.000000e+000,0,1,0,
1473228297.825,,3.000000e+003,7.000081e+001,2.495323e-004,0.000000e+000,-4.769841e-003,0.000000e+000,3,8.277124e-001,1.825000e+000,,,,,,,,,,,,,,,,,,0,5.000000e+000,5.000000e-001,2,1,4.722595e-003,0,1,0,
1473228324.757,,3.000000e+003,6.999844e+001,2.496308e-004,0.000000e+000,-4.150562e-003,0.000000e+000,3,8.292406e-001,1.825000e+000,,,,,,,,,,,,,,,,,,0,5.000000e+000,5.000000e-001,2,1,0.000000e+000,0,1,0,
1473228455.946,,1.000000e+003,6.999372e+001,1.155390e-004,0.000000e+000,-9.340866e-003,0.000000e+000,3,7.157043e-001,1.825000e+000,,,,,,,,,,,,,,,,,,0,5.000000e+000,5.000000e-001,2,1,4.714966e-003,0,1,0,
1473228485.059,,1.000000e+003,6.999962e+001,1.149271e-004,0.000000e+000,-1.569976e-002,0.000000e+000,3,7.223109e-001,1.825000e+000,,,,,,,,,,,,,,,,,,0,5.000000e+000,5.000000e-001,2,1,1.180267e-002,0,1,0,
1473228631.914,,7.000000e+002,6.999844e+001,8.625726e-005,0.000000e+000,-2.978582e-002,0.000000e+000,3,6.912379e-001,1.825000e+000,,,,,,,,,,,,,,,,,,0,5.000000e+000,5.000000e-001,2,1,4.722595e-003,0,1,0,
1473228657.092,,7.000000e+002,6.999962e+001,8.624192e-005,0.000000e+000,-2.299600e-002,0.000000e+000,3,6.800083e-001,1.825000e+000,,,,,,,,,,,,,,,,,,0,5.000000e+000,5.000000e-001,2,1,2.357483e-003,0,1,0,
1473228784.085,,6.000000e+002,7.000198e+001,7.524991e-005,0.000000e+000,-2.992730e-002,0.000000e+000,3,6.657138e-001,1.825000e+000,,,,,,,,,,,,,,,,,,0,5.000000e+000,5.000000e-001,2,1,2.365112e-003,0,1,0,
1473228808.575,,6.000000e+002,6.999962e+001,7.492646e-005,0.000000e+000,-2.980564e-002,0.000000e+000,3,6.689137e-001,1.825000e+000,,,,,,,,,,,,,,,,,,0,5.000000e+000,5.000000e-001,2,1,2.357483e-003,0,1,0,
1473228947.519,,5.000000e+002,6.998900e+001,6.392351e-005,0.000000e+000,-4.291238e-002,0.000000e+000,3,6.636338e-001,1.825000e+000,,,,,,,,,,,,,,,,,,0,5.000000e+000,5.000000e-001,2,1,1.888275e-002,0,1,0,
1473228973.702,,5.000000e+002,7.000198e+001,6.400893e-005,0.000000e+000,-3.395429e-002,0.000000e+000,3,6.541095e-001,1.825000e+000,,,,,,,,,,,,,,,,,,0,5.000000e+000,5.000000e-001,2,1,7.080078e-003,0,1,0,
1473229104.861,,4.000000e+002,6.998782e+001,5.103249e-005,0.000000e+000,-3.330230e-002,0.000000e+000,3,6.322215e-001,1.825000e+000,,,,,,,,,,,,,,,,,,0,5.000000e+000,5.000000e-001,2,1,2.124023e-002,0,1,0,
1473229128.713,,4.000000e+002,7.000198e+001,5.065682e-005,0.000000e+000,-3.293251e-002,0.000000e+000,3,6.097147e-001,1.825000e+000,,,,,,,,,,,,,,,,,,0,5.000000e+000,5.000000e-001,2,1,2.365112e-003,0,1,0,
1473229255.861,,3.000000e+002,7.000316e+001,3.862904e-005,0.000000e+000,-1.877147e-002,0.000000e+000,3,5.926222e-001,1.825000e+000,,,,,,,,,,,,,,,,,,0,5.000000e+000,5.000000e-001,2,1,4.722595e-003,0,1,0,
1473229290.398,,3.000000e+002,6.999844e+001,3.841243e-005,0.000000e+000,-3.163194e-002,0.000000e+000,3,5.844850e-001,1.825000e+000,,,,,,,,,,,,,,,,,,0,5.000000e+000,5.000000e-001,2,1,4.722595e-003,0,1,0,
1473229434.060,,2.000000e+002,6.999372e+001,2.559342e-005,0.000000e+000,-4.738465e-002,0.000000e+000,3,5.546131e-001,1.825000e+000,,,,,,,,,,,,,,,,,,0,5.000000e+000,5.000000e-001,2,1,4.714966e-003,0,1,0,
1473229458.796,,2.000000e+002,6.999962e+001,2.506477e-005,0.000000e+000,-2.988796e-002,0.000000e+000,3,5.489852e-001,1.825000e+000,,,,,,,,,,,,,,,,,,0,5.000000e+000,5.000000e-001,2,1,2.357483e-003,0,1,0,
1473229588.938,,1.800000e+002,7.000198e+001,2.233163e-005,0.000000e+000,-3.378416e-002,0.000000e+000,3,5.014175e-001,1.825000e+000,,,,,,,,,,,,,,,,,,0,5.000000e+000,5.000000e-001,2,1,2.365112e-003,0,1,0,
1473229616.030,,1.800000e+002,7.000435e+001,2.284053e-005,0.000000e+000,-5.165008e-002,0.000000e+000,3,5.544582e-001,1.825000e+000,,,,,,,,,,,,,,,,,,0,5.000000e+000,5.000000e-001,2,1,2.357483e-003,0,1,0,
1473229739.718,,1.600000e+002,6.999962e+001,2.030989e-005,0.000000e+000,-5.802837e-002,0.000000e+000,3,5.489273e-001,1.825000e+000,,,,,,,,,,,,,,,,,,0,5.000000e+000,5.000000e-001,2,1,7.087708e-003,0,1,0,
1473229764.897,,1.600000e+002,7.000080e+001,2.068226e-005,0.000000e+000,-9.015889e-002,0.000000e+000,3,5.565822e-001,1.825000e+000,,,,,,,,,,,,,,,,,,0,5.000000e+000,5.000000e-001,2,1,9.445190e-003,0,1,0,
1473229890.340,,1.400000e+002,7.000198e+001,1.719297e-005,0.000000e+000,-5.419775e-002,0.000000e+000,3,5.131635e-001,1.825000e+000,,,,,,,,,,,,,,,,,,0,5.000000e+000,5.000000e-001,2,1,2.365112e-003,0,1,0,
1473229917.842,,1.400000e+002,7.000198e+001,1.786513e-005,0.000000e+000,-6.000136e-002,0.000000e+000,3,5.289544e-001,1.825000e+000,,,,,,,,,,,,,,,,,,0,5.000000e+000,5.000000e-001,2,1,2.365112e-003,0,1,0,
1473230043.788,,1.200000e+002,7.000435e+001,1.467366e-005,0.000000e+000,-6.235783e-002,0.000000e+000,3,4.944645e-001,1.825000e+000,,,,,,,,,,,,,,,,,,0,5.000000e+000,5.000000e-001,2,1,7.087708e-003,0,1,0,
1473230075.467,,1.200000e+002,7.000435e+001,1.484587e-005,0.000000e+000,-4.263099e-002,0.000000e+000,3,4.893982e-001,1.825000e+000,,,,,,,,,,,,,,,,,,0,5.000000e+000,5.000000e-001,2,1,7.087708e-003,0,1,0,
1473230205.410,,1.000000e+002,6.999844e+001,1.209360e-005,0.000000e+000,-1.046814e-001,0.000000e+000,3,4.961892e-001,1.825000e+000,,,,,,,,,,,,,,,,,,0,5.000000e+000,5.000000e-001,2,1,9.445190e-003,0,1,0,
1473230245.355,,1.000000e+002,6.999844e+001,1.178622e-005,0.000000e+000,-7.441851e-002,0.000000e+000,3,4.702531e-001,1.825000e+000,,,,,,,,,,,,,,,,,,0,5.000000e+000,5.000000e-001,2,1,9.445190e-003,0,1,0,
1473230371.829,,8.000000e+001,7.000198e+001,9.073773e-006,0.000000e+000,-9.859598e-002,0.000000e+000,3,4.000418e-001,1.825000e+000,,,,,,,,,,,,,,,,,,0,5.000000e+000,5.000000e-001,2,1,2.365112e-003,0,1,0,
1473230402.258,,8.000000e+001,6.999962e+001,8.919564e-006,0.000000e+000,-1.389261e-001,0.000000e+000,3,4.549161e-001,1.825000e+000,,,,,,,,,,,,,,,,,,0,5.000000e+000,5.000000e-001,2,1,7.087708e-003,0,1,0,
1473230533.641,,6.000000e+001,6.999608e+001,5.832008e-006,0.000000e+000,-4.379284e-002,0.000000e+000,3,2.553708e-001,1.825000e+000,,,,,,,,,,,,,,,,,,0,5.000000e+000,5.000000e-001,2,1,9.437561e-003,0,1,0,
1473230560.178,,6.000000e+001,7.000317e+001,6.228861e-006,0.000000e+000,-8.973256e-002,0.000000e+000,3,3.604823e-001,1.825000e+000,,,,,,,,,,,,,,,,,,0,5.000000e+000,5.000000e-001,2,1,9.445190e-003,0,1,0,
1473230688.126,,4.000000e+001,6.999726e+001,3.816267e-006,0.000000e+000,-2.381383e-001,0.000000e+000,3,2.762673e-001,1.825000e+000,,,,,,,,,,,,,,,,,,0,5.000000e+000,5.000000e-001,2,1,7.080078e-003,0,1,0,
1473230716.004,,4.000000e+001,7.000198e+001,3.590477e-006,0.000000e+000,-2.113748e-001,0.000000e+000,3,3.351581e-001,1.825000e+000,,,,,,,,,,,,,,,,,,0,5.000000e+000,5.000000e-001,2,1,7.080078e-003,0,1,0,
1473230838.303,,2.000000e+001,7.000080e+001,6.557106e-007,0.000000e+000,0.000000e+000,0.000000e+000,3,0.000000e+000,1.825000e+000,,,,,,,,,,,,,,,,,,0,5.000000e+000,5.000000e-001,2,1,0.000000e+000,0,1,0,
1473230865.482,,2.000000e+001,7.000081e+001,3.622216e-007,0.000000e+000,0.000000e+000,0.000000e+000,3,0.000000e+000,1.825000e+000,,,,,,,,,,,,,,,,,,0,5.000000e+000,5.000000e-001,2,1,1.416779e-002,0,1,0,
1473231021.039,,0.000000e+000,6.999844e+001,-3.063715e-006,0.000000e+000,1.870020e-003,0.000000e+000,3,6.527390e-001,1.825000e+000,,,,,,,,,,,,,,,,,,0,5.000000e+000,5.000000e-001,2,1,0.000000e+000,0,1,0,
1473231051.028,,0.000000e+000,6.999844e+001,-2.899127e-006,0.000000e+000,1.414242e-001,0.000000e+000,3,8.346300e-001,1.825000e+000,,,,,,,,,,,,,,,,,,0,5.000000e+000,5.000000e-001,2,1,4.722595e-003,0,1,0,
1473231173.667,,-2.000000e+001,6.999844e+001,-5.111840e-006,0.000000e+000,6.060232e-002,0.000000e+000,3,4.603772e-001,1.825000e+000,,,,,,,,,,,,,,,,,,0,5.000000e+000,5.000000e-001,2,1,0.000000e+000,0,1,0,
1473231201.892,,-2.000000e+001,7.000080e+001,-6.151321e-006,0.000000e+000,1.575315e-003,0.000000e+000,3,8.133711e-001,1.825000e+000,,,,,,,,,,,,,,,,,,0,5.000000e+000,5.000000e-001,2,1,0.000000e+000,0,1,0,
1473231328.487,,-4.000000e+001,7.000198e+001,-8.067592e-006,0.000000e+000,-3.237728e-002,0.000000e+000,3,3.250866e-001,1.825000e+000,,,,,,,,,,,,,,,,,,0,5.000000e+000,5.000000e-001,2,1,7.080078e-003,0,1,0,
1473231359.416,,-4.000000e+001,6.999962e+001,-8.602489e-006,0.000000e+000,2.365814e-002,0.000000e+000,3,6.578156e-001,1.825000e+000,,,,,,,,,,,,,,,,,,0,5.000000e+000,5.000000e-001,2,1,2.357483e-003,0,1,0,
1473231487.605,,-6.000000e+001,7.000317e+001,-1.161683e-005,0.000000e+000,-4.427568e-002,0.000000e+000,3,6.405798e-001,1.825000e+000,,,,,,,,,,,,,,,,,,0,5.000000e+000,5.000000e-001,2,1,9.445190e-003,0,1,0,
1473231523.290,,-6.000000e+001,6.999726e+001,-1.198324e-005,0.000000e+000,-1.648884e-002,0.000000e+000,3,7.030908e-001,1.825000e+000,,,,,,,,,,,,,,,,,,0,5.000000e+000,5.000000e-001,2,1,7.080078e-003,0,1,0,
1473231671.020,,-8.000000e+001,6.999844e+001,-1.492659e-005,0.000000e+000,-3.902286e-004,0.000000e+000,3,6.784142e-001,1.825000e+000,,,,,,,,,,,,,,,,,,0,5.000000e+000,5.000000e-001,2,1,1.416016e-002,0,1,0,
1473231697.502,,-8.000000e+001,6.999844e+001,-1.422806e-005,0.000000e+000,-1.264437e-002,0.000000e+000,3,6.622313e-001,1.825000e+000,,,,,,,,,,,,,,,,,,0,5.000000e+000,5.000000e-001,2,1,9.445190e-003,0,1,0,
1473231821.482,,-1.000000e+002,6.999727e+001,-1.660514e-005,0.000000e+000,-3.312787e-002,0.000000e+000,3,6.410791e-001,1.825000e+000,,,,,,,,,,,,,,,,,,0,5.000000e+000,5.000000e-001,2,1,1.180267e-002,0,1,0,
1473231849.109,,-1.000000e+002,7.001143e+001,-1.686383e-005,0.000000e+000,-2.702736e-002,0.000000e+000,3,5.952429e-001,1.825000e+000,,,,,,,,,,,,,,,,,,0,5.000000e+000,5.000000e-001,2,1,1.653290e-002,0,1,0,
1473231968.909,,-1.200000e+002,7.000435e+001,-1.991461e-005,0.000000e+000,-1.762990e-002,0.000000e+000,3,6.471496e-001,1.825000e+000,,,,,,,,,,,,,,,,,,0,5.000000e+000,5.000000e-001,2,1,2.357483e-003,0,1,0,
1473231996.099,,-1.200000e+002,7.000435e+001,-1.947885e-005,0.000000e+000,-9.285248e-003,0.000000e+000,3,6.177747e-001,1.825000e+000,,,,,,,,,,,,,,,,,,0,5.000000e+000,5.000000e-001,2,1,2.357483e-003,0,1,0,
1473232133.002,,-1.400000e+002,7.000317e+001,-2.237292e-005,0.000000e+000,-3.475331e-002,0.000000e+000,3,6.438408e-001,1.825000e+000,,,,,,,,,,,,,,,,,,0,5.000000e+000,5.000000e-001,2,1,0.000000e+000,0,1,0,
1473232163.181,,-1.400000e+002,7.000552e+001,-2.250173e-005,0.000000e+000,-3.802554e-002,0.000000e+000,3,6.380188e-001,1.825000e+000,,,,,,,,,,,,,,,,,,0,5.000000e+000,5.000000e-001,2,1,4.722595e-003,0,1,0,
1473232311.784,,-1.600000e+002,7.000080e+001,-2.536299e-005,0.000000e+000,-5.024375e-002,0.000000e+000,3,6.236985e-001,1.825000e+000,,,,,,,,,,,,,,,,,,0,5.000000e+000,5.000000e-001,2,1,0.000000e+000,0,1,0,
1473232339.599,,-1.600000e+002,7.000316e+001,-2.484036e-005,0.000000e+000,-4.422999e-002,0.000000e+000,3,6.431146e-001,1.825000e+000,,,,,,,,,,,,,,,,,,0,5.000000e+000,5.000000e-001,2,1,4.722595e-003,0,1,0,
1473232471.289,,-1.800000e+002,7.000552e+001,-2.777208e-005,0.000000e+000,-3.982685e-002,0.000000e+000,3,6.224298e-001,1.825000e+000,,,,,,,,,,,,,,,,,,0,5.000000e+000,5.000000e-001,2,1,9.445190e-003,0,1,0,
1473232499.023,,-1.800000e+002,7.000081e+001,-2.808006e-005,0.000000e+000,-3.803921e-002,0.000000e+000,3,6.414890e-001,1.825000e+000,,,,,,,,,,,,,,,,,,0,5.000000e+000,5.000000e-001,2,1,4.722595e-003,0,1,0,
1473232620.018,,-2.000000e+002,6.999726e+001,-3.013199e-005,0.000000e+000,-3.256173e-002,0.000000e+000,3,6.388289e-001,1.825000e+000,,,,,,,,,,,,,,,,,,0,5.000000e+000,5.000000e-001,2,1,2.365112e-003,0,1,0,
1473232646.197,,-2.000000e+002,6.999608e+001,-2.990659e-005,0.000000e+000,-3.552671e-002,0.000000e+000,3,6.293695e-001,1.825000e+000,,,,,,,,,,,,,,,,,,0,5.000000e+000,5.000000e-001,2,1,0.000000e+000,0,1,0,
1473232778.429,,-3.000000e+002,7.000789e+001,-4.236579e-005,0.000000e+000,-1.800309e-002,0.000000e+000,3,6.261176e-001,1.825000e+000,,,,,,,,,,,,,,,,,,0,5.000000e+000,5.000000e-001,2,1,1.888275e-002,0,1,0,
1473232805.859,,-3.000000e+002,6.999962e+001,-4.339853e-005,0.000000e+000,-4.583372e-002,0.000000e+000,3,6.491588e-001,1.825000e+000,,,,,,,,,,,,,,,,,,0,5.000000e+000,5.000000e-001,2,1,7.087708e-003,0,1,0,
1473232975.353,,-4.000000e+002,7.000081e+001,-5.549250e-005,0.000000e+000,-3.389606e-002,0.000000e+000,3,6.536841e-001,1.825000e+000,,,,,,,,,,,,,,,,,,0,5.000000e+000,5.000000e-001,2,1,4.722595e-003,0,1,0,
1473233002.462,,-4.000000e+002,7.000317e+001,-5.506812e-005,0.000000e+000,-3.049473e-002,0.000000e+000,3,6.555906e-001,1.825000e+000,,,,,,,,,,,,,,,,,,0,5.000000e+000,5.000000e-001,2,1,0.000000e+000,0,1,0,
1473233158.478,,-5.000000e+002,7.000081e+001,-6.708174e-005,0.000000e+000,-1.943332e-002,0.000000e+000,3,6.656389e-001,1.825000e+000,,,,,,,,,,,,,,,,,,0,5.000000e+000,5.000000e-001,2,1,4.722595e-003,0,1,0,
1473233184.464,,-5.000000e+002,6.999608e+001,-6.703431e-005,0.000000e+000,-2.474334e-002,0.000000e+000,3,6.671275e-001,1.825000e+000,,,,,,,,,,,,,,,,,,0,5.000000e+000,5.000000e-001,2,1,2.362061e-002,0,1,0,
1473233315.158,,-6.000000e+002,6.999962e+001,-7.828428e-005,0.000000e+000,-2.373010e-002,0.000000e+000,3,6.787329e-001,1.825000e+000,,,,,,,,,,,,,,,,,,0,5.000000e+000,5.000000e-001,2,1,2.357483e-003,0,1,0,
1473233341.837,,-6.000000e+002,7.000081e+001,-7.839586e-005,0.000000e+000,-2.099287e-002,0.000000e+000,3,6.773791e-001,1.825000e+000,,,,,,,,,,,,,,,,,,0,5.000000e+000,5.000000e-001,2,1,4.722595e-003,0,1,0,
1473233479.279,,-7.000000e+002,6.999372e+001,-8.966310e-005,0.000000e+000,-2.416088e-002,0.000000e+000,3,6.961147e-001,1.825000e+000,,,,,,,,,,,,,,,,,,0,5.000000e+000,5.000000e-001,2,1,4.714966e-003,0,1,0,
1473233507.208,,-7.000000e+002,7.000317e+001,-9.017044e-005,0.000000e+000,-2.672466e-002,0.000000e+000,3,6.989046e-001,1.825000e+000,,,,,,,,,,,,,,,,,,0,5.000000e+000,5.000000e-001,2,1,9.445190e-003,0,1,0,
1473233635.152,,-1.000000e+003,6.999608e+001,-1.179333e-004,0.000000e+000,-1.716802e-002,0.000000e+000,3,7.292623e-001,1.825000e+000,,,,,,,,,,,,,,,,,,0,5.000000e+000,5.000000e-001,2,1,4.722595e-003,0,1,0,
1473233661.776,,-1.000000e+003,6.999844e+001,-1.178991e-004,0.000000e+000,-1.698985e-002,0.000000e+000,3,7.288971e-001,1.825000e+000,,,,,,,,,,,,,,,,,,0,5.000000e+000,5.000000e-001,2,1,0.000000e+000,0,1,0,
1473233814.042,,-3.000000e+003,6.999844e+001,-2.503774e-004,0.000000e+000,-2.634601e-003,0.000000e+000,3,8.252740e-001,1.825000e+000,,,,,,,,,,,,,,,,,,0,5.000000e+000,5.000000e-001,2,1,0.000000e+000,0,1,0,
1473233840.260,,-3.000000e+003,6.999490e+001,-2.502513e-004,0.000000e+000,-1.645912e-003,0.000000e+000,3,8.284472e-001,1.825000e+000,,,,,,,,,,,,,,,,,,0,5.000000e+000,5.000000e-001,2,1,7.080078e-003,0,1,0,
1473233978.009,,-5.000000e+003,6.999844e+001,-3.261246e-004,0.000000e+000,1.884517e-003,0.000000e+000,3,8.596989e-001,1.825000e+000,,,,,,,,,,,,,,,,,,0,5.000000e+000,5.000000e-001,2,1,4.722595e-003,0,1,0,
1473234004.188,,-5.000000e+003,7.000317e+001,-3.266614e-004,0.000000e+000,3.162194e-003,0.000000e+000,3,8.600189e-001,1.825000e+000,,,,,,,,,,,,,,,,,,0,5.000000e+000,5.000000e-001,2,1,0.000000e+000,0,1,0,
1473234140.168,,-7.000000e+003,7.000080e+001,-3.790429e-004,0.000000e+000,5.699193e-003,0.000000e+000,3,8.767042e-001,1.825000e+000,,,,,,,,,,,,,,,,,,0,5.000000e+000,5.000000e-001,2,1,0.000000e+000,0,1,0,
1473234167.106,,-7.000000e+003,7.000080e+001,-3.798820e-004,0.000000e+000,5.652052e-003,0.000000e+000,3,8.768436e-001,1.825000e+000,,,,,,,,,,,,,,,,,,0,5.000000e+000,5.000000e-001,2,1,0.000000e+000,0,1,0,
1473234308.603,,-9.000000e+003,6.999962e+001,-4.197996e-004,0.000000e+000,7.501833e-003,0.000000e+000,3,8.867068e-001,1.825000e+000,,,,,,,,,,,,,,,,,,0,5.000000e+000,5.000000e-001,2,1,2.357483e-003,0,1,0,
1473234337.077,,-9.000000e+003,6.999608e+001,-4.200726e-004,0.000000e+000,6.624170e-003,0.000000e+000,3,8.872535e-001,1.825000e+000,,,,,,,,,,,,,,,,,,0,5.000000e+000,5.000000e-001,2,1,9.437561e-003,0,1,0,
1473234472.321,,-1.000000e+004,6.999844e+001,-4.371861e-004,0.000000e+000,7.641620e-003,0.000000e+000,3,8.912181e-001,1.825000e+000,,,,,,,,,,,,,,,,,,0,5.000000e+000,5.000000e-001,2,1,0.000000e+000,0,1,0,
1473234501.999,,-1.000000e+004,6.999726e+001,-4.376991e-004,0.000000e+000,6.835418e-003,0.000000e+000,3,8.912131e-001,1.825000e+000,,,,,,,,,,,,,,,,,,0,5.000000e+000,5.000000e-001,2,1,2.365112e-003,0,1,0,
1473234694.974,,-2.000000e+004,7.000198e+001,-5.516956e-004,0.000000e+000,1.182329e-002,0.000000e+000,3,9.097118e-001,1.825000e+000,,,,,,,,,,,,,,,,,,0,5.000000e+000,5.000000e-001,2,1,2.365112e-003,0,1,0,
1473234720.857,,-2.000000e+004,6.999962e+001,-5.535971e-004,0.000000e+000,1.166176e-002,0.000000e+000,3,9.111233e-001,1.825000e+000,,,,,,,,,,,,,,,,,,0,5.000000e+000,5.000000e-001,2,1,2.357483e-003,0,1,0,
1473234894.158,,-3.000000e+004,6.999962e+001,-6.190742e-004,0.000000e+000,1.387704e-002,0.000000e+000,3,9.156992e-001,1.825000e+000,,,,,,,,,,,,,,,,,,0,5.000000e+000,5.000000e-001,2,1,7.087708e-003,0,1,0,
1473234919.846,,-3.000000e+004,6.999490e+001,-6.186207e-004,0.000000e+000,1.512385e-002,0.000000e+000,3,9.210938e-001,1.825000e+000,,,,,,,,,,,,,,,,,,0,5.000000e+000,5.000000e-001,2,1,2.125549e-002,0,1,0,
1473235090.544,,-4.000000e+004,6.999608e+001,-6.666670e-004,0.000000e+000,1.692318e-002,0.000000e+000,3,9.261326e-001,1.825000e+000,,,,,,,,,,,,,,,,,,0,5.000000e+000,5.000000e-001,2,1,0.000000e+000,0,1,0,
1473235120.223,,-4.000000e+004,6.999608e+001,-6.681572e-004,0.000000e+000,1.453148e-002,0.000000e+000,3,9.202960e-001,1.825000e+000,,,,,,,,,,,,,,,,,,0,5.000000e+000,5.000000e-001,2,1,0.000000e+000,0,1,0,
1473235299.920,,-5.000000e+004,6.999726e+001,-6.988779e-004,0.000000e+000,1.752361e-002,0.000000e+000,3,9.297651e-001,1.825000e+000,,,,,,,,,,,,,,,,,,0,5.000000e+000,5.000000e-001,2,1,2.365112e-003,0,1,0,
1473235325.599,,-5.000000e+004,7.000080e+001,-6.996192e-004,0.000000e+000,1.553298e-002,0.000000e+000,3,9.257350e-001,1.825000e+000,,,,,,,,,,,,,,,,,,0,5.000000e+000,5.000000e-001,2,1,0.000000e+000,0,1,0,
1473235508.567,,-6.000000e+004,7.000198e+001,-7.256417e-004,0.000000e+000,1.607698e-002,0.000000e+000,3,9.318873e-001,1.825000e+000,,,,,,,,,,,,,,,,,,0,5.000000e+000,5.000000e-001,2,1,1.652527e-002,0,1,0,
1473235535.258,,-6.000000e+004,7.000198e+001,-7.303308e-004,0.000000e+000,2.071093e-002,0.000000e+000,3,9.244820e-001,1.825000e+000,,,,,,,,,,,,,,,,,,0,5.000000e+000,5.000000e-001,2,1,2.365112e-003,0,1,0,
1473235718.452,,-7.000000e+004,6.999962e+001,-7.469452e-004,0.000000e+000,1.932744e-002,0.000000e+000,3,9.296984e-001,1.825000e+000,,,,,,,,,,,,,,,,,,0,5.000000e+000,5.000000e-001,2,1,2.357483e-003,0,1,0,
1473235747.668,,-7.000000e+004,7.000198e+001,-7.465652e-004,0.000000e+000,2.090464e-002,0.000000e+000,3,9.270067e-001,1.825000e+000,,,,,,,,,,,,,,,,,,0,5.000000e+000,5.000000e-001,2,1,2.365112e-003,0,1,0,
1473235932.617,,-6.000000e+004,7.000081e+001,-7.286865e-004,0.000000e+000,1.990469e-002,0.000000e+000,3,9.250249e-001,1.825000e+000,,,,,,,,,,,,,,,,,,0,5.000000e+000,5.000000e-001,2,1,4.722595e-003,0,1,0,
1473235959.590,,-6.000000e+004,6.999490e+001,-7.299286e-004,0.000000e+000,2.112808e-002,0.000000e+000,3,9.300749e-001,1.825000e+000,,,,,,,,,,,,,,,,,,0,5.000000e+000,5.000000e-001,2,1,2.357483e-003,0,1,0,
1473236136.538,,-5.000000e+004,7.001617e+001,-7.016413e-004,0.000000e+000,1.989678e-002,0.000000e+000,3,9.228759e-001,1.825000e+000,,,,,,,,,,,,,,,,,,0,5.000000e+000,5.000000e-001,2,1,4.961395e-002,0,1,0,
1473236159.966,,-5.000000e+004,7.000435e+001,-7.017521e-004,0.000000e+000,1.447171e-002,0.000000e+000,3,9.274611e-001,1.825000e+000,,,,,,,,,,,,,,,,,,0,5.000000e+000,5.000000e-001,2,1,2.357483e-003,0,1,0,
1473236337.941,,-4.000000e+004,7.000198e+001,-6.633804e-004,0.000000e+000,1.288047e-002,0.000000e+000,3,9.243668e-001,1.825000e+000,,,,,,,,,,,,,,,,,,0,5.000000e+000,5.000000e-001,2,1,2.365112e-003,0,1,0,
1473236365.377,,-4.000000e+004,6.999962e+001,-6.655009e-004,0.000000e+000,1.660892e-002,0.000000e+000,3,9.196616e-001,1.825000e+000,,,,,,,,,,,,,,,,,,0,5.000000e+000,5.000000e-001,2,1,2.357483e-003,0,1,0,
1473236546.378,,-3.000000e+004,6.999726e+001,-6.204975e-004,0.000000e+000,1.344410e-002,0.000000e+000,3,9.163049e-001,1.825000e+000,,,,,,,,,,,,,,,,,,0,5.000000e+000,5.000000e-001,2,1,7.080078e-003,0,1,0,
1473236572.104,,-3.000000e+004,6.999490e+001,-6.197570e-004,0.000000e+000,1.437110e-002,0.000000e+000,3,9.174929e-001,1.825000e+000,,,,,,,,,,,,,,,,,,0,5.000000e+000,5.000000e-001,2,1,2.357483e-003,0,1,0,
1473236747.303,,-2.000000e+004,7.000552e+001,-5.520699e-004,0.000000e+000,1.261112e-002,0.000000e+000,3,9.097092e-001,1.825000e+000,,,,,,,,,,,,,,,,,,0,5.000000e+000,5.000000e-001,2,1,0.000000e+000,0,1,0,
1473236772.482,,-2.000000e+004,7.000198e+001,-5.527341e-004,0.000000e+000,1.140110e-002,0.000000e+000,3,9.084947e-001,1.825000e+000,,,,,,,,,,,,,,,,,,0,5.000000e+000,5.000000e-001,2,1,2.365112e-003,0,1,0,
1473236945.925,,-1.000000e+004,6.999608e+001,-4.370149e-004,0.000000e+000,7.300914e-003,0.000000e+000,3,8.904063e-001,1.825000e+000,,,,,,,,,,,,,,,,,,0,5.000000e+000,5.000000e-001,2,1,4.722595e-003,0,1,0,
1473236971.354,,-1.000000e+004,6.999962e+001,-4.363366e-004,0.000000e+000,6.947499e-003,0.000000e+000,3,8.900553e-001,1.825000e+000,,,,,,,,,,,,,,,,,,0,5.000000e+000,5.000000e-001,2,1,2.357483e-003,0,1,0,
1473237108.493,,-9.000000e+003,6.998900e+001,-4.190237e-004,0.000000e+000,6.742870e-003,0.000000e+000,3,8.867780e-001,1.825000e+000,,,,,,,,,,,,,,,,,,0,5.000000e+000,5.000000e-001,2,1,2.359772e-002,0,1,0,
1473237134.568,,-9.000000e+003,6.999726e+001,-4.197300e-004,0.000000e+000,6.092575e-003,0.000000e+000,3,8.862437e-001,1.825000e+000,,,,,,,,,,,,,,,,,,0,5.000000e+000,5.000000e-001,2,1,2.365112e-003,0,1,0,
1473237277.508,,-7.000000e+003,7.000198e+001,-3.788016e-004,0.000000e+000,4.872643e-003,0.000000e+000,3,8.768639e-001,1.825000e+000,,,,,,,,,,,,,,,,,,0,5.000000e+000,5.000000e-001,2,1,7.080078e-003,0,1,0,
1473237305.707,,-7.000000e+003,7.000198e+001,-3.783603e-004,0.000000e+000,3.993339e-003,0.000000e+000,3,8.764864e-001,1.825000e+000,,,,,,,,,,,,,,,,,,0,5.000000e+000,5.000000e-001,2,1,2.365112e-003,0,1,0,
1473237446.400,,-5.000000e+003,6.999371e+001,-3.265243e-004,0.000000e+000,5.328623e-004,0.000000e+000,3,8.598335e-001,1.825000e+000,,,,,,,,,,,,,,,,,,0,5.000000e+000,5.000000e-001,2,1,1.416779e-002,0,1,0,
1473237475.370,,-5.000000e+003,7.000198e+001,-3.263208e-004,0.000000e+000,1.635420e-003,0.000000e+000,3,8.594894e-001,1.825000e+000,,,,,,,,,,,,,,,,,,0,5.000000e+000,5.000000e-001,2,1,2.365112e-003,0,1,0,
1473237611.999,,-3.000000e+003,7.000317e+001,-2.491729e-004,0.000000e+000,-3.761528e-003,0.000000e+000,3,8.251705e-001,1.825000e+000,,,,,,,,,,,,,,,,,,0,5.000000e+000,5.000000e-001,2,1,9.445190e-003,0,1,0,
1473237638.276,,-3.000000e+003,7.000081e+001,-2.496329e-004,0.000000e+000,-2.819913e-003,0.000000e+000,3,8.285193e-001,1.825000e+000,,,,,,,,,,,,,,,,,,0,5.000000e+000,5.000000e-001,2,1,4.722595e-003,0,1,0,
1473237782.075,,-1.000000e+003,6.999962e+001,-1.154511e-004,0.000000e+000,-2.263731e-002,0.000000e+000,3,7.263125e-001,1.825000e+000,,,,,,,,,,,,,,,,,,0,5.000000e+000,5.000000e-001,2,1,7.087708e-003,0,1,0,
1473237809.003,,-1.000000e+003,7.000435e+001,-1.155246e-004,0.000000e+000,-1.822898e-002,0.000000e+000,3,7.240466e-001,1.825000e+000,,,,,,,,,,,,,,,,,,0,5.000000e+000,5.000000e-001,2,1,1.180267e-002,0,1,0,
1473237950.948,,-7.000000e+002,6.999726e+001,-8.633963e-005,0.000000e+000,-2.294251e-002,0.000000e+000,3,6.762083e-001,1.825000e+000,,,,,,,,,,,,,,,,,,0,5.000000e+000,5.000000e-001,2,1,7.080078e-003,0,1,0,
1473237978.673,,-7.000000e+002,6.999844e+001,-8.623156e-005,0.000000e+000,-2.457906e-002,0.000000e+000,3,6.797702e-001,1.825000e+000,,,,,,,,,,,,,,,,,,0,5.000000e+000,5.000000e-001,2,1,4.722595e-003,0,1,0,
1473238111.689,,-6.000000e+002,6.999608e+001,-7.514752e-005,0.000000e+000,-2.982425e-002,0.000000e+000,3,6.680879e-001,1.825000e+000,,,,,,,,,,,,,,,,,,0,5.000000e+000,5.000000e-001,2,1,4.722595e-003,0,1,0,
1473238136.909,,-6.000000e+002,6.999726e+001,-7.503365e-005,0.000000e+000,-3.155274e-002,0.000000e+000,3,6.739192e-001,1.825000e+000,,,,,,,,,,,,,,,,,,0,5.000000e+000,5.000000e-001,2,1,2.365112e-003,0,1,0,
1473238285.604,,-5.000000e+002,6.998428e+001,-6.310228e-005,0.000000e+000,-3.790432e-002,0.000000e+000,3,6.419132e-001,1.825000e+000,,,,,,,,,,,,,,,,,,0,5.000000e+000,5.000000e-001,2,1,9.437561e-003,0,1,0,
1473238313.007,,-5.000000e+002,6.999844e+001,-6.356643e-005,0.000000e+000,-2.867801e-002,0.000000e+000,3,6.404200e-001,1.825000e+000,,,,,,,,,,,,,,,,,,0,5.000000e+000,5.000000e-001,2,1,4.722595e-003,0,1,0,
1473238470.168,,-4.000000e+002,6.999727e+001,-5.088726e-005,0.000000e+000,-2.975682e-002,0.000000e+000,3,6.105154e-001,1.825000e+000,,,,,,,,,,,,,,,,,,0,5.000000e+000,5.000000e-001,2,1,1.180267e-002,0,1,0,
1473238495.511,,-4.000000e+002,7.000080e+001,-5.073764e-005,0.000000e+000,-2.984658e-002,0.000000e+000,3,6.162962e-001,1.825000e+000,,,,,,,,,,,,,,,,,,0,5.000000e+000,5.000000e-001,2,1,9.445190e-003,0,1,0,
1473238625.374,,-3.000000e+002,7.000198e+001,-3.787657e-005,0.000000e+000,-3.473221e-002,0.000000e+000,3,5.935748e-001,1.825000e+000,,,,,,,,,,,,,,,,,,0,5.000000e+000,5.000000e-001,2,1,7.080078e-003,0,1,0,
1473238651.647,,-3.000000e+002,7.000080e+001,-3.796209e-005,0.000000e+000,-3.884667e-002,0.000000e+000,3,5.945135e-001,1.825000e+000,,,,,,,,,,,,,,,,,,0,5.000000e+000,5.000000e-001,2,1,0.000000e+000,0,1,0,
1473238800.227,,-2.000000e+002,7.000789e+001,-2.547268e-005,0.000000e+000,-3.903625e-002,0.000000e+000,3,5.814318e-001,1.825000e+000,,,,,,,,,,,,,,,,,,0,5.000000e+000,5.000000e-001,2,1,1.417542e-002,0,1,0,
1473238829.907,,-2.000000e+002,6.999608e+001,-2.535994e-005,0.000000e+000,-5.958799e-002,0.000000e+000,3,5.642064e-001,1.825000e+000,,,,,,,,,,,,,,,,,,0,5.000000e+000,5.000000e-001,2,1,4.722595e-003,0,1,0,
1473238958.640,,-1.800000e+002,6.999608e+001,-2.202459e-005,0.000000e+000,-6.254737e-002,0.000000e+000,3,5.541062e-001,1.825000e+000,,,,,,,,,,,,,,,,,,0,5.000000e+000,5.000000e-001,2,1,0.000000e+000,0,1,0,
1473238984.873,,-1.800000e+002,6.999844e+001,-2.287224e-005,0.000000e+000,-6.927583e-002,0.000000e+000,3,5.576650e-001,1.825000e+000,,,,,,,,,,,,,,,,,,0,5.000000e+000,5.000000e-001,2,1,0.000000e+000,0,1,0,
1473239106.474,,-1.600000e+002,7.000435e+001,-2.096919e-005,0.000000e+000,-5.883497e-002,0.000000e+000,3,5.026182e-001,1.825000e+000,,,,,,,,,,,,,,,,,,0,5.000000e+000,5.000000e-001,2,1,2.357483e-003,0,1,0,
1473239133.796,,-1.600000e+002,7.000435e+001,-2.011696e-005,0.000000e+000,-7.848433e-002,0.000000e+000,3,5.412706e-001,1.825000e+000,,,,,,,,,,,,,,,,,,0,5.000000e+000,5.000000e-001,2,1,7.087708e-003,0,1,0,
1473239259.015,,-1.400000e+002,7.000080e+001,-1.714218e-005,0.000000e+000,-8.977287e-002,0.000000e+000,3,5.119272e-001,1.825000e+000,,,,,,,,,,,,,,,,,,0,5.000000e+000,5.000000e-001,2,1,9.445190e-003,0,1,0,
1473239287.390,,-1.400000e+002,6.999608e+001,-1.772356e-005,0.000000e+000,-7.389480e-002,0.000000e+000,3,5.267331e-001,1.825000e+000,,,,,,,,,,,,,,,,,,0,5.000000e+000,5.000000e-001,2,1,0.000000e+000,0,1,0,
1473239410.952,,-1.200000e+002,6.999608e+001,-1.404863e-005,0.000000e+000,-1.266942e-001,0.000000e+000,3,5.180688e-001,1.825000e+000,,,,,,,,,,,,,,,,,,0,5.000000e+000,5.000000e-001,2,1,0.000000e+000,0,1,0,
1473239437.690,,-1.200000e+002,6.999490e+001,-1.397597e-005,0.000000e+000,-7.438198e-002,0.000000e+000,3,4.824918e-001,1.825000e+000,,,,,,,,,,,,,,,,,,0,5.000000e+000,5.000000e-001,2,1,7.080078e-003,0,1,0,
1473239567.866,,-1.000000e+002,6.999844e+001,-1.196263e-005,0.000000e+000,-7.938750e-002,0.000000e+000,3,4.444535e-001,1.825000e+000,,,,,,,,,,,,,,,,,,0,5.000000e+000,5.000000e-001,2,1,9.445190e-003,0,1,0,
1473239596.572,,-1.000000e+002,6.999372e+001,-1.163276e-005,0.000000e+000,-9.073620e-002,0.000000e+000,3,4.922513e-001,1.825000e+000,,,,,,,,,,,,,,,,,,0,5.000000e+000,5.000000e-001,2,1,9.445190e-003,0,1,0,
1473239721.998,,-8.000000e+001,6.998900e+001,-8.443089e-006,0.000000e+000,-5.451628e-002,0.000000e+000,3,3.696967e-001,1.825000e+000,,,,,,,,,,,,,,,,,,0,5.000000e+000,5.000000e-001,2,1,2.359772e-002,0,1,0,
1473239747.782,,-8.000000e+001,7.000198e+001,-8.933085e-006,0.000000e+000,-9.330704e-002,0.000000e+000,3,4.536915e-001,1.825000e+000,,,,,,,,,,,,,,,,,,0,5.000000e+000,5.000000e-001,2,1,2.365112e-003,0,1,0,
1473239877.271,,-6.000000e+001,7.000908e+001,-6.979214e-006,0.000000e+000,-1.803644e-001,0.000000e+000,3,4.754891e-001,1.825000e+000,,,,,,,,,,,,,,,,,,0,5.000000e+000,5.000000e-001,2,1,4.015350e-002,0,1,0,
1473239908.219,,-6.000000e+001,6.999254e+001,-6.413049e-006,0.000000e+000,-1.349988e-001,0.000000e+000,3,3.759998e-001,1.825000e+000,,,,,,,,,,,,,,,,,,0,5.000000e+000,5.000000e-001,2,1,1.181030e-002,0,1,0,
1473240036.662,,-4.000000e+001,6.999844e+001,-4.170523e-006,0.000000e+000,-3.916831e-001,0.000000e+000,3,4.699516e-001,1.825000e+000,,,,,,,,,,,,,,,,,,0,5.000000e+000,5.000000e-001,2,1,9.445190e-003,0,1,0,
1473240064.591,,-4.000000e+001,6.999844e+001,-2.841509e-006,0.000000e+000,-1.927588e-001,0.000000e+000,3,0.000000e+000,1.825000e+000,,,,,,,,,,,,,,,,,,0,5.000000e+000,5.000000e-001,2,1,4.722595e-003,0,1,0,
1473240197.051,,-2.000000e+001,7.000081e+001,4.638392e-007,0.000000e+000,-2.847967e-001,0.000000e+000,3,0.000000e+000,1.825000e+000,,,,,,,,,,,,,,,,,,0,5.000000e+000,5.000000e-001,2,1,4.722595e-003,0,1,0,
1473240224.730,,-2.000000e+001,7.000198e+001,-2.896100e-007,0.000000e+000,0.000000e+000,0.000000e+000,3,0.000000e+000,1.825000e+000,,,,,,,,,,,,,,,,,,0,5.000000e+000,5.000000e-001,2,1,1.181030e-002,0,1,0,
1473240349.672,,0.000000e+000,6.999962e+001,2.107661e-006,0.000000e+000,-1.709539e-001,0.000000e+000,3,0.000000e+000,1.825000e+000,,,,,,,,,,,,,,,,,,0,5.000000e+000,5.000000e-001,2,1,7.087708e-003,0,1,0,
1473240377.912,,0.000000e+000,6.999962e+001,2.720500e-006,0.000000e+000,9.888569e-002,0.000000e+000,3,7.771637e-001,1.825000e+000,,,,,,,,,,,,,,,,,,0,5.000000e+000,5.000000e-001,2,1,2.357483e-003,0,1,0,
1473240529.425,,2.000000e+001,7.000198e+001,5.447184e-006,0.000000e+000,4.978703e-002,0.000000e+000,3,6.820191e-001,1.825000e+000,,,,,,,,,,,,,,,,,,0,5.000000e+000,5.000000e-001,2,1,2.365112e-003,0,1,0,
1473240555.354,,2.000000e+001,6.999726e+001,5.831983e-006,0.000000e+000,1.712724e-002,0.000000e+000,3,7.913322e-001,1.825000e+000,,,,,,,,,,,,,,,,,,0,5.000000e+000,5.000000e-001,2,1,2.365112e-003,0,1,0,
1473240677.046,,4.000000e+001,6.999844e+001,9.201091e-006,0.000000e+000,-1.407462e-002,0.000000e+000,3,6.795338e-001,1.825000e+000,,,,,,,,,,,,,,,,,,0,5.000000e+000,5.000000e-001,2,1,0.000000e+000,0,1,0,
1473240702.725,,4.000000e+001,7.000317e+001,9.090303e-006,0.000000e+000,-2.280040e-005,0.000000e+000,3,7.311028e-001,1.825000e+000,,,,,,,,,,,,,,,,,,0,5.000000e+000,5.000000e-001,2,1,0.000000e+000,0,1,0,
1473240825.971,,6.000000e+001,6.999962e+001,1.212177e-005,0.000000e+000,-4.718596e-002,0.000000e+000,3,7.180364e-001,1.825000e+000,,,,,,,,,,,,,,,,,,0,5.000000e+000,5.000000e-001,2,1,2.357483e-003,0,1,0,
1473240853.853,,6.000000e+001,6.999844e+001,1.148962e-005,0.000000e+000,-8.600515e-003,0.000000e+000,3,7.101117e-001,1.825000e+000,,,,,,,,,,,,,,,,,,0,5.000000e+000,5.000000e-001,2,1,4.722595e-003,0,1,0,
1473240979.903,,8.000000e+001,6.998192e+001,1.435493e-005,0.000000e+000,-2.571490e-002,0.000000e+000,3,6.703020e-001,1.825000e+000,,,,,,,,,,,,,,,,,,0,5.000000e+000,5.000000e-001,2,1,2.359772e-002,0,1,0,
1473241006.582,,8.000000e+001,6.999844e+001,1.470757e-005,0.000000e+000,-4.008388e-002,0.000000e+000,3,6.672825e-001,1.825000e+000,,,,,,,,,,,,,,,,,,0,5.000000e+000,5.000000e-001,2,1,4.722595e-003,0,1,0,
1473241127.386,,1.000000e+002,7.000316e+001,1.692774e-005,0.000000e+000,-4.172381e-002,0.000000e+000,3,6.792688e-001,1.825000e+000,,,,,,,,,,,,,,,,,,0,5.000000e+000,5.000000e-001,2,1,4.722595e-003,0,1,0,
1473241155.353,,1.000000e+002,6.999490e+001,1.724702e-005,0.000000e+000,-2.181034e-002,0.000000e+000,3,6.562483e-001,1.825000e+000,,,,,,,,,,,,,,,,,,0,5.000000e+000,5.000000e-001,2,1,7.080078e-003,0,1,0,
1473241280.798,,1.200000e+002,6.999962e+001,1.888320e-005,0.000000e+000,-1.360685e-002,0.000000e+000,3,5.984796e-001,1.825000e+000,,,,,,,,,,,,,,,,,,0,5.000000e+000,5.000000e-001,2,1,2.357483e-003,0,1,0,
1473241308.476,,1.200000e+002,6.999726e+001,1.945965e-005,0.000000e+000,-3.964910e-002,0.000000e+000,3,6.428211e-001,1.825000e+000,,,,,,,,,,,,,,,,,,0,5.000000e+000,5.000000e-001,2,1,2.365112e-003,0,1,0,
1473241433.665,,1.400000e+002,6.998546e+001,2.206978e-005,0.000000e+000,-2.378344e-002,0.000000e+000,3,6.265209e-001,1.825000e+000,,,,,,,,,,,,,,,,,,0,5.000000e+000,5.000000e-001,2,1,3.541565e-002,0,1,0,
1473241460.879,,1.400000e+002,7.000080e+001,2.232548e-005,0.000000e+000,-4.137794e-002,0.000000e+000,3,6.293949e-001,1.825000e+000,,,,,,,,,,,,,,,,,,0,5.000000e+000,5.000000e-001,2,1,0.000000e+000,0,1,0,
1473241584.359,,1.600000e+002,6.999844e+001,2.480600e-005,0.000000e+000,-3.731439e-002,0.000000e+000,3,6.123945e-001,1.825000e+000,,,,,,,,,,,,,,,,,,0,5.000000e+000,5.000000e-001,2,1,9.445190e-003,0,1,0,
1473241612.288,,1.600000e+002,6.999962e+001,2.495760e-005,0.000000e+000,-3.354594e-002,0.000000e+000,3,6.346990e-001,1.825000e+000,,,,,,,,,,,,,,,,,,0,5.000000e+000,5.000000e-001,2,1,1.180267e-002,0,1,0,
1473241748.694,,1.800000e+002,6.999726e+001,2.705563e-005,0.000000e+000,-4.319395e-002,0.000000e+000,3,6.213851e-001,1.825000e+000,,,,,,,,,,,,,,,,,,0,5.000000e+000,5.000000e-001,2,1,7.080078e-003,0,1,0,
1473241777.374,,1.800000e+002,7.000789e+001,2.761906e-005,0.000000e+000,-3.620488e-002,0.000000e+000,3,6.360726e-001,1.825000e+000,,,,,,,,,,,,,,,,,,0,5.000000e+000,5.000000e-001,2,1,1.417542e-002,0,1,0,
1473241901.566,,2.000000e+002,6.999490e+001,2.982887e-005,0.000000e+000,-3.711949e-002,0.000000e+000,3,6.472318e-001,1.825000e+000,,,,,,,,,,,,,,,,,,0,5.000000e+000,5.000000e-001,2,1,2.357483e-003,0,1,0,
1473241927.547,,2.000000e+002,6.999254e+001,3.035012e-005,0.000000e+000,-3.097930e-002,0.000000e+000,3,6.236572e-001,1.825000e+000,,,,,,,,,,,,,,,,,,0,5.000000e+000,5.000000e-001,2,1,1.181030e-002,0,1,0,
1473242061.797,,3.000000e+002,7.000317e+001,4.317144e-005,0.000000e+000,-2.381515e-002,0.000000e+000,3,6.332438e-001,1.825000e+000,,,,,,,,,,,,,,,,,,0,5.000000e+000,5.000000e-001,2,1,0.000000e+000,0,1,0,
1473242111.214,,3.000000e+002,6.999490e+001,4.297851e-005,0.000000e+000,-2.951714e-002,0.000000e+000,3,6.408105e-001,1.825000e+000,,,,,,,,,,,,,,,,,,0,5.000000e+000,5.000000e-001,2,1,7.080078e-003,0,1,0,
1473242247.940,,4.000000e+002,7.001616e+001,5.570898e-005,0.000000e+000,-2.727037e-002,0.000000e+000,3,6.511983e-001,1.825000e+000,,,,,,,,,,,,,,,,,,0,5.000000e+000,5.000000e-001,2,1,4.016113e-002,0,1,0,
1473242273.619,,4.000000e+002,7.000081e+001,5.511969e-005,0.000000e+000,-2.659106e-002,0.000000e+000,3,6.576669e-001,1.825000e+000,,,,,,,,,,,,,,,,,,0,5.000000e+000,5.000000e-001,2,1,4.722595e-003,0,1,0,
1473242408.742,,5.000000e+002,6.999962e+001,6.669218e-005,0.000000e+000,-2.270844e-002,0.000000e+000,3,6.689051e-001,1.825000e+000,,,,,,,,,,,,,,,,,,0,5.000000e+000,5.000000e-001,2,1,2.357483e-003,0,1,0,
1473242438.032,,5.000000e+002,6.999844e+001,6.801815e-005,0.000000e+000,-2.485140e-002,0.000000e+000,3,6.767012e-001,1.825000e+000,,,,,,,,,,,,,,,,,,0,5.000000e+000,5.000000e-001,2,1,0.000000e+000,0,1,0,
1473242590.496,,6.000000e+002,7.000081e+001,7.867759e-005,0.000000e+000,-2.850530e-002,0.000000e+000,3,6.744137e-001,1.825000e+000,,,,,,,,,,,,,,,,,,0,5.000000e+000,5.000000e-001,2,1,4.722595e-003,0,1,0,
1473242616.685,,6.000000e+002,7.000081e+001,7.839639e-005,0.000000e+000,-2.090583e-002,0.000000e+000,3,6.805207e-001,1.825000e+000,,,,,,,,,,,,,,,,,,0,5.000000e+000,5.000000e-001,2,1,4.722595e-003,0,1,0,
1473242755.598,,7.000000e+002,6.999726e+001,8.949221e-005,0.000000e+000,-2.235235e-002,0.000000e+000,3,6.962485e-001,1.825000e+000,,,,,,,,,,,,,,,,,,0,5.000000e+000,5.000000e-001,2,1,2.365112e-003,0,1,0,
1473242782.445,,7.000000e+002,7.000198e+001,8.912940e-005,0.000000e+000,-2.137351e-002,0.000000e+000,3,6.871841e-001,1.825000e+000,,,,,,,,,,,,,,,,,,0,5.000000e+000,5.000000e-001,2,1,7.080078e-003,0,1,0,
1473242906.409,,1.000000e+003,6.999608e+001,1.178616e-004,0.000000e+000,-1.551559e-002,0.000000e+000,3,7.301184e-001,1.825000e+000,,,,,,,,,,,,,,,,,,0,5.000000e+000,5.000000e-001,2,1,0.000000e+000,0,1,0,
1473242935.883,,1.000000e+003,6.999726e+001,1.180237e-004,0.000000e+000,-1.596102e-002,0.000000e+000,3,7.289943e-001,1.825000e+000,,,,,,,,,,,,,,,,,,0,5.000000e+000,5.000000e-001,2,1,7.080078e-003,0,1,0,
1473243093.940,,3.000000e+003,6.999962e+001,2.493119e-004,0.000000e+000,-7.021285e-004,0.000000e+000,3,8.256314e-001,1.825000e+000,,,,,,,,,,,,,,,,,,0,5.000000e+000,5.000000e-001,2,1,2.357483e-003,0,1,0,
1473243121.298,,3.000000e+003,6.999962e+001,2.505828e-004,0.000000e+000,-3.889289e-003,0.000000e+000,3,8.290374e-001,1.825000e+000,,,,,,,,,,,,,,,,,,0,5.000000e+000,5.000000e-001,2,1,2.357483e-003,0,1,0,
1473243258.095,,5.000000e+003,7.000316e+001,3.264290e-004,0.000000e+000,2.100460e-003,0.000000e+000,3,8.595737e-001,1.825000e+000,,,,,,,,,,,,,,,,,,0,5.000000e+000,5.000000e-001,2,1,4.722595e-003,0,1,0,
1473243284.474,,5.000000e+003,7.000316e+001,3.262164e-004,0.000000e+000,3.345382e-003,0.000000e+000,3,8.600697e-001,1.825000e+000,,,,,,,,,,,,,,,,,,0,5.000000e+000,5.000000e-001,2,1,4.722595e-003,0,1,0,
1473243422.276,,7.000000e+003,6.999962e+001,3.795695e-004,0.000000e+000,5.522576e-003,0.000000e+000,3,8.766256e-001,1.825000e+000,,,,,,,,,,,,,,,,,,0,5.000000e+000,5.000000e-001,2,1,2.357483e-003,0,1,0,
1473243449.204,,7.000000e+003,6.999844e+001,3.795174e-004,0.000000e+000,4.545767e-003,0.000000e+000,3,8.762380e-001,1.825000e+000,,,,,,,,,,,,,,,,,,0,5.000000e+000,5.000000e-001,2,1,0.000000e+000,0,1,0,
1473243585.940,,9.000000e+003,6.999726e+001,4.200778e-004,0.000000e+000,7.664352e-003,0.000000e+000,3,8.877138e-001,1.825000e+000,,,,,,,,,,,,,,,,,,0,5.000000e+000,5.000000e-001,2,1,2.365112e-003,0,1,0,
1473243615.916,,9.000000e+003,7.000317e+001,4.204055e-004,0.000000e+000,6.758274e-003,0.000000e+000,3,8.873386e-001,1.825000e+000,,,,,,,,,,,,,,,,,,0,5.000000e+000,5.000000e-001,2,1,2.361298e-002,0,1,0,
1473243749.587,,1.000000e+004,6.999726e+001,4.370069e-004,0.000000e+000,8.550675e-003,0.000000e+000,3,8.923811e-001,1.825000e+000,,,,,,,,,,,,,,,,,,0,5.000000e+000,5.000000e-001,2,1,2.365112e-003,0,1,0,
1473243777.874,,1.000000e+004,6.999844e+001,4.371718e-004,0.000000e+000,8.477286e-003,0.000000e+000,3,8.902919e-001,1.825000e+000,,,,,,,,,,,,,,,,,,0,5.000000e+000,5.000000e-001,2,1,4.722595e-003,0,1,0,
1473243948.321,,2.000000e+004,6.999608e+001,5.523190e-004,0.000000e+000,1.317656e-002,0.000000e+000,3,9.090540e-001,1.825000e+000,,,,,,,,,,,,,,,,,,0,5.000000e+000,5.000000e-001,2,1,4.722595e-003,0,1,0,
1473243974.000,,2.000000e+004,6.999962e+001,5.518431e-004,0.000000e+000,1.313428e-002,0.000000e+000,3,9.124961e-001,1.825000e+000,,,,,,,,,,,,,,,,,,0,5.000000e+000,5.000000e-001,2,1,1.180267e-002,0,1,0,
1473244145.943,,3.000000e+004,6.999844e+001,6.215735e-004,0.000000e+000,1.505524e-002,0.000000e+000,3,9.174591e-001,1.825000e+000,,,,,,,,,,,,,,,,,,0,5.000000e+000,5.000000e-001,2,1,4.722595e-003,0,1,0,
1473244174.372,,3.000000e+004,6.999608e+001,6.184413e-004,0.000000e+000,1.189566e-002,0.000000e+000,3,9.204586e-001,1.825000e+000,,,,,,,,,,,,,,,,,,0,5.000000e+000,5.000000e-001,2,1,4.722595e-003,0,1,0,
1473244352.570,,4.000000e+004,6.999962e+001,6.712801e-004,0.000000e+000,1.512155e-002,0.000000e+000,3,9.199785e-001,1.825000e+000,,,,,,,,,,,,,,,,,,0,5.000000e+000,5.000000e-001,2,1,7.087708e-003,0,1,0,
1473244379.784,,4.000000e+004,7.000080e+001,6.663050e-004,0.000000e+000,1.566253e-002,0.000000e+000,3,9.227436e-001,1.825000e+000,,,,,,,,,,,,,,,,,,0,5.000000e+000,5.000000e-001,2,1,0.000000e+000,0,1,0,
1473244557.732,,5.000000e+004,6.999844e+001,7.052483e-004,0.000000e+000,1.688330e-002,0.000000e+000,3,9.278992e-001,1.825000e+000,,,,,,,,,,,,,,,,,,0,5.000000e+000,5.000000e-001,2,1,4.722595e-003,0,1,0,
1473244581.911,,5.000000e+004,6.999844e+001,7.001582e-004,0.000000e+000,1.680405e-002,0.000000e+000,3,9.288214e-001,1.825000e+000,,,,,,,,,,,,,,,,,,0,5.000000e+000,5.000000e-001,2,1,0.000000e+000,0,1,0,
1473244762.111,,6.000000e+004,6.999136e+001,7.284692e-004,0.000000e+000,1.741173e-002,0.000000e+000,3,9.277101e-001,1.825000e+000,,,,,,,,,,,,,,,,,,0,5.000000e+000,5.000000e-001,2,1,1.417542e-002,0,1,0,
1473244787.566,,6.000000e+004,7.000081e+001,7.299199e-004,0.000000e+000,1.865003e-002,0.000000e+000,3,9.261614e-001,1.825000e+000,,,,,,,,,,,,,,,,,,0,5.000000e+000,5.000000e-001,2,1,4.722595e-003,0,1,0,
1473244968.014,,7.000000e+004,6.999254e+001,7.536741e-004,0.000000e+000,1.671465e-002,0.000000e+000,3,9.228874e-001,1.825000e+000,,,,,,,,,,,,,,,,,,0,5.000000e+000,5.000000e-001,2,1,2.357483e-003,0,1,0,
1473244994.391,,7.000000e+004,6.999726e+001,7.497429e-004,0.000000e+000,1.695871e-002,0.000000e+000,3,9.293509e-001,1.825000e+000,,,,,,,,,,,,,,,,,,0,5.000000e+000,5.000000e-001,2,1,7.080078e-003,0,1,0,
1473245006.463,,7.000000e+004,6.999490e+001,7.486274e-004,0.000000e+000,2.171767e-002,0.000000e+000,3,9.270043e-001,1.825000e+000,,,,,,,,,,,,,,,,,,0,5.000000e+000,5.000000e-001,2,1,2.357483e-003,0,1,0,