File: data/A344/A344_cool_zero_field_050_160908.rso.raw
[Header]
TITLE,MPMS RSO Measurement
BYAPP,MPMS Measurement,2.1,Raw with ABS
FILEOPENTIME, 1473327917.201000 9/8/2016, 9:45:17 PM

INFO, APPNAME, MPMS MultiVu Application, Revision 1.61,  Build 082

INFO, NAME, A344
INFO, WEIGHT, 10.500
INFO, AREA, 1.000
INFO, LENGTH, 1.000
INFO, SHAPE, 0
INFO, COMMENT, m = 0.0105g
INFO, SEQUENCE FILE: cool_zero_field_magnet_reset_120K-5K.seq


INFO, BACKGROUND DATA FILE:, None


STARTUPAXIS,X,8,LINEAR,AUTO,0.000000,0.000000
STARTUPAXIS,Y1,9,LINEAR,AUTO,0.000000,0.000000


STARTUPGROUP,Longitudinal
FIELDGROUP,Longitudinal,1,2,3,4,5,6,7,8,9,10,11,12,13,14,15,16,17,18,19,20,21,22
FIELDGROUP,Transverse,1,2,3,4,5,6,7,8,23,24,25,26,27,28,29,30,31,32,33,34,35,36

PLOT_APPEARANCE,ALL,HORZ_GRID_ON,VERT_GRID_ON,MARKERS_ONLY

[Data]
Time,Comment,Field (Oe),Start Temperature (K),End Temperature (K),Scan,Rejected,Position (cm),Long Voltage,Long Average Voltage,Long Detrended Voltage,Long Demeaned Voltage,Long Reg Fit,Long Detrended Fit,Long Demeaned Fit,Long Scaled Response,Long Avg. Scaled Response,Long Background Response,Long Response [w/ABS],Long Detrended Resp. [w/ABS],Long Fit [w/ABS],Long Detrended Fit [w/ABS],Trans Voltage,Trans Average Voltage,Trans Detrended Voltage,Trans Demeaned Voltage,Trans Reg Fit,Trans Detrended Fit,Trans Demeaned Fit,Trans Scaled Response,Trans Avg. Scaled Response,Trans Background Response,Trans Response [w/ABS],Trans Detrended Resp. [w/ABS],Trans Adjusted Fit,Trans Detrended Fit [w/ABS],
1473327917.176,,0.000000e+000,1.199941e+002,1.200007e+002,1,0,2.591067e+000,4.638813e-002,4.638813e-002,-1.277855e-001,-1.277855e-001,8.853448e-002,-8.563914e-002,-8.563914e-002,1.161983e-006,1.161983e-006,,,,,,,,,,,,,,,,,,,,
1473327917.176,,0.000000e+000,1.199941e+002,1.200007e+002,1,0,4.825612e+000,1.208533e-001,1.208533e-001,1.143963e-002,-5.332033e-002,1.316751e-001,2.226143e-002,-4.249853e-002,3.027272e-006,3.027272e-006,,,,,,,,,,,,,,,,,,,,
1473327930.890,,0.000000e+000,1.199974e+002,1.199974e+002,1,0,3.736671e+000,1.304666e-001,1.304666e-001,-2.207672e-002,-6.464936e-002,1.655573e-001,1.301399e-002,-2.955864e-002,3.268078e-006,3.268078e-006,,,,,,,,,,,,,,,,,,,,
1473327943.854,,0.000000e+000,1.199974e+002,1.199941e+002,1,0,1.025323e+000,2.909940e-001,2.909940e-001,1.347227e-001,1.052236e-001,1.936439e-001,3.737260e-002,7.873505e-003,7.289152e-006,7.289152e-006,,,,,,,,,,,,,,,,,,,,
1473327957.319,,0.000000e+000,1.199941e+002,1.200007e+002,1,0,2.334674e-001,1.358074e-001,1.358074e-001,-1.524189e-002,-3.016394e-002,1.671491e-001,1.609985e-002,1.177803e-003,3.401859e-006,3.401859e-006,,,,,,,,,,,,,,,,,,,,
1473327957.319,,0.000000e+000,1.199941e+002,1.200007e+002,1,0,2.812204e+000,6.836146e-002,6.836146e-002,-1.926908e-002,-9.760985e-002,8.249485e-003,-7.938106e-002,-1.577218e-001,1.712396e-006,1.712396e-006,,,,,,,,,,,,,,,,,,,,
1473328118.302,,0.000000e+000,1.178429e+002,1.175038e+002,1,0,4.910382e+000,1.387066e-001,1.387066e-001,1.087319e-002,-5.123290e-002,1.470205e-001,1.918706e-002,-4.291902e-002,3.474483e-006,3.474483e-006,,,,,,,,,,,,,,,,,,,,
1473328132.016,,0.000000e+000,1.174154e+002,1.170316e+002,1,0,3.525836e+000,8.758812e-002,8.758812e-002,-3.000297e-002,-7.514649e-002,1.103871e-001,-7.204026e-003,-5.234755e-002,2.194008e-006,2.194008e-006,,,,,,,,,,,,,,,,,,,,
1473328146.484,,0.000000e+000,1.169188e+002,1.162621e+002,1,0,8.594825e-001,2.697836e-001,2.697836e-001,1.239060e-001,9.358232e-002,1.820073e-001,3.612967e-002,5.806014e-003,6.757850e-006,6.757850e-006,,,,,,,,,,,,,,,,,,,,
1473328160.448,,0.000000e+000,1.161353e+002,1.154993e+002,1,0,3.630000e-001,1.788385e-001,1.788385e-001,6.975271e-003,-6.725952e-003,1.916919e-001,1.982867e-002,6.127447e-003,4.479752e-006,4.479752e-006,,,,,,,,,,,,,,,,,,,,
1473328160.448,,0.000000e+000,1.161353e+002,1.154993e+002,1,0,3.027203e+000,9.842220e-002,9.842219e-002,-9.917147e-003,-8.714222e-002,4.680755e-002,-6.153179e-002,-1.387569e-001,2.465392e-006,2.465392e-006,,,,,,,,,,,,,,,,,,,,
1473328186.342,,0.000000e+000,1.144934e+002,1.138510e+002,1,0,4.967557e+000,1.307718e-001,1.307718e-001,1.427357e-002,-5.111620e-002,1.339822e-001,1.748392e-002,-4.790585e-002,3.275723e-006,3.275723e-006,,,,,,,,,,,,,,,,,,,,
1473328199.354,,0.000000e+000,1.136730e+002,1.129430e+002,1,0,3.308643e+000,8.743554e-002,8.743553e-002,-3.622782e-002,-8.347587e-002,9.400520e-002,-2.965815e-002,-7.690620e-002,2.190186e-006,2.190186e-006,,,,,,,,,,,,,,,,,,,,
1473328212.176,,0.000000e+000,1.125872e+002,1.118061e+002,1,0,7.007366e-001,2.511673e-001,2.511673e-001,9.638389e-002,6.403862e-002,1.855943e-001,3.081085e-002,-1.534417e-003,6.291528e-006,6.291528e-006,,,,,,,,,,,,,,,,,,,,
1473328225.140,,0.000000e+000,1.116257e+002,1.108021e+002,1,0,5.143544e-001,1.861629e-001,1.861629e-001,3.935450e-002,2.576673e-002,1.714238e-001,2.461541e-002,1.102765e-002,4.663223e-006,4.663223e-006,,,,,,,,,,,,,,,,,,,,
1473328225.140,,0.000000e+000,1.116257e+002,1.108021e+002,1,0,3.234322e+000,7.904294e-002,7.904294e-002,1.532132e-003,-8.135323e-002,3.914198e-002,-3.836883e-002,-1.212542e-001,1.979958e-006,1.979958e-006,,,,,,,,,,,,,,,,,,,,
1473328239.105,,0.000000e+000,1.103975e+002,1.095274e+002,1,0,4.993485e+000,1.193274e-001,1.193274e-001,9.041466e-003,-5.751742e-002,1.269830e-001,1.669712e-002,-4.986176e-002,2.989049e-006,2.989049e-006,,,,,,,,,,,,,,,,,,,,
1473328251.069,,0.000000e+000,1.095274e+002,1.086512e+002,1,0,3.086597e+000,7.553331e-002,7.553331e-002,-4.961533e-002,-9.832587e-002,7.159634e-002,-5.355230e-002,-1.022628e-001,1.892045e-006,1.892045e-006,,,,,,,,,,,,,,,,,,,,
1473328264.283,,0.000000e+000,1.084260e+002,1.072657e+002,1,0,5.499577e-001,2.174444e-001,2.174444e-001,6.966197e-002,3.914212e-002,1.733458e-001,2.556335e-002,-4.956499e-003,5.446797e-006,5.446797e-006,,,,,,,,,,,,,,,,,,,,
1473328276.998,,0.000000e+000,1.070619e+002,1.060896e+002,1,0,6.833084e-001,2.362133e-001,2.362133e-001,7.358569e-002,6.057033e-002,1.939750e-001,3.134744e-002,1.833208e-002,5.916941e-006,5.916941e-006,,,,,,,,,,,,,,,,,,,,
1473328276.998,,0.000000e+000,1.070619e+002,1.060896e+002,1,0,3.432573e+000,9.445479e-002,9.445479e-002,5.580907e-003,-8.118815e-002,7.235433e-002,-1.651955e-002,-1.032886e-001,2.366012e-006,2.366012e-006,,,,,,,,,,,,,,,,,,,,
1473328292.465,,0.000000e+000,1.056394e+002,1.046684e+002,1,0,4.986017e+000,9.872738e-002,9.872738e-002,5.125863e-003,-6.051236e-002,1.105702e-001,1.696866e-002,-4.866957e-002,2.473037e-006,2.473037e-006,,,,,,,,,,,,,,,,,,,,
1473328303.189,,0.000000e+000,1.046684e+002,1.037241e+002,1,0,2.861356e+000,4.943999e-002,4.943999e-002,-6.406253e-002,-1.131735e-001,3.952848e-002,-7.397404e-002,-1.230850e-001,1.238430e-006,1.238430e-006,,,,,,,,,,,,,,,,,,,,
1473328318.693,,0.000000e+000,1.032209e+002,1.024588e+002,1,0,4.096672e-001,1.773126e-001,1.773125e-001,3.782539e-002,7.419333e-003,1.614024e-001,2.191531e-002,-8.490756e-003,4.441528e-006,4.441528e-006,,,,,,,,,,,,,,,,,,,,
1473328332.935,,0.000000e+000,1.019839e+002,1.007510e+002,1,0,8.664052e-001,2.488784e-001,2.488784e-001,9.921258e-002,8.762535e-002,1.855820e-001,3.591611e-002,2.432889e-002,6.234193e-006,6.234193e-006,,,,,,,,,,,,,,,,,,,,
1473328332.935,,0.000000e+000,1.019839e+002,1.007510e+002,1,0,3.621809e+000,8.651998e-002,8.651997e-002,1.072264e-002,-7.473312e-002,7.923239e-002,3.435063e-003,-8.202070e-002,2.167252e-006,2.167252e-006,,,,,,,,,,,,,,,,,,,,
1473328347.650,,0.000000e+000,1.002441e+002,9.920930e+001,1,0,4.944733e+000,1.037629e-001,1.037629e-001,7.602509e-003,-5.783037e-002,1.146505e-001,1.849005e-002,-4.694283e-002,2.599173e-006,2.599173e-006,,,,,,,,,,,,,,,,,,,,
1473328362.114,,0.000000e+000,9.920930e+001,9.796672e+001,1,0,2.634920e+000,6.881924e-002,6.881924e-002,-7.235412e-002,-1.211440e-001,5.648938e-002,-8.468398e-002,-1.334738e-001,1.723863e-006,1.723863e-006,,,,,,,,,,,,,,,,,,,,
1473328375.328,,0.000000e+000,9.749473e+001,9.645918e+001,1,0,2.832524e-001,1.472518e-001,1.472518e-001,6.147214e-003,-2.196996e-002,1.583078e-001,1.720323e-002,-1.091394e-002,3.688533e-006,3.688533e-006,,,,,,,,,,,,,,,,,,,,
1473328387.293,,0.000000e+000,9.645918e+001,9.549110e+001,1,0,1.060676e+000,2.908414e-001,2.908414e-001,1.029738e-001,9.283938e-002,2.241559e-001,3.628825e-002,2.615386e-002,7.285330e-006,7.285330e-006,,,,,,,,,,,,,,,,,,,,
1473328387.293,,0.000000e+000,9.645918e+001,9.549110e+001,1,0,3.802441e+000,1.252785e-001,1.252785e-001,1.124708e-002,-7.272354e-002,1.320410e-001,1.800956e-002,-6.596106e-002,3.138119e-006,3.138119e-006,,,,,,,,,,,,,,,,,,,,
1473328401.007,,0.000000e+000,9.499490e+001,9.397564e+001,1,0,4.870924e+000,1.116977e-001,1.116977e-001,4.209377e-003,-6.499138e-002,1.276376e-001,2.014925e-002,-4.905151e-002,2.797934e-006,2.797934e-006,,,,,,,,,,,,,,,,,,,,
1473328412.971,,0.000000e+000,9.376315e+001,9.302953e+001,1,0,2.409855e+000,8.148442e-002,8.148442e-002,-7.040607e-002,-1.176627e-001,7.336563e-002,-7.852487e-002,-1.257815e-001,2.041115e-006,2.041115e-006,,,,,,,,,,,,,,,,,,,,
1473328426.435,,0.000000e+000,9.253708e+001,9.153922e+001,1,0,1.752535e-001,1.295511e-001,1.295511e-001,-1.445089e-002,-4.233104e-002,1.584885e-001,1.448654e-002,-1.339361e-002,3.245144e-006,3.245144e-006,,,,,,,,,,,,,,,,,,,,
1473328438.900,,0.000000e+000,9.153922e+001,9.057686e+001,1,0,1.263981e+000,2.671896e-001,2.671896e-001,7.902785e-002,7.009065e-002,2.184407e-001,3.027896e-002,2.134176e-002,6.692871e-006,6.692871e-006,,,,,,,,,,,,,,,,,,,,
1473328438.900,,0.000000e+000,9.153922e+001,9.057686e+001,1,0,3.975336e+000,1.228370e-001,1.228370e-001,1.064153e-002,-7.426191e-002,1.423517e-001,3.015628e-002,-5.474716e-002,3.076962e-006,3.076962e-006,,,,,,,,,,,,,,,,,,,,
1473328453.661,,0.000000e+000,9.011236e+001,8.918356e+001,1,0,4.767306e+000,1.164281e-001,1.164281e-001,1.982404e-003,-6.375993e-002,1.385292e-001,2.408349e-002,-4.165885e-002,2.916425e-006,2.916425e-006,,,,,,,,,,,,,,,,,,,,
1473328465.625,,0.000000e+000,8.918356e+001,8.821938e+001,1,0,2.188626e+000,1.084933e-001,1.084933e-001,-4.718979e-002,-9.323333e-002,9.735913e-002,-5.832396e-002,-1.043675e-001,2.717665e-006,2.717665e-006,,,,,,,,,,,,,,,,,,,,
1473328478.350,,0.000000e+000,8.776276e+001,8.705034e+001,1,0,9.041536e-002,1.100192e-001,1.100192e-001,-3.221370e-002,-5.932421e-002,1.547318e-001,1.249884e-002,-1.461168e-002,2.755888e-006,2.755888e-006,,,,,,,,,,,,,,,,,,,,
1473328490.756,,0.000000e+000,8.682005e+001,8.615008e+001,1,0,1.474857e+000,2.137821e-001,2.137822e-001,3.606316e-002,2.858944e-002,1.932706e-001,1.555164e-002,8.077919e-003,5.355061e-006,5.355061e-006,,,,,,,,,,,,,,,,,,,,
1473328490.756,,0.000000e+000,8.682005e+001,8.615008e+001,1,0,4.141219e+000,1.161229e-001,1.161229e-001,1.463585e-002,-6.906979e-002,1.385178e-001,3.703072e-002,-4.667492e-002,2.908781e-006,2.908781e-006,,,,,,,,,,,,,,,,,,,,
1473328506.579,,0.000000e+000,8.573953e+001,8.465016e+001,1,0,4.637771e+000,9.582812e-002,9.582812e-002,-3.313542e-003,-6.607398e-002,1.277312e-001,2.858949e-002,-3.417094e-002,2.400413e-006,2.400413e-006,,,,,,,,,,,,,,,,,,,,
1473328519.335,,0.000000e+000,8.426141e+001,8.365466e+001,1,0,1.973560e+000,1.197852e-001,1.197852e-001,-1.354842e-002,-5.825350e-002,1.003494e-001,-3.298419e-002,-7.768928e-002,3.000516e-006,3.000516e-006,,,,,,,,,,,,,,,,,,,,
1473328532.549,,0.000000e+000,8.345755e+001,8.268426e+001,1,0,3.319488e-002,9.460738e-002,9.460738e-002,-4.484585e-002,-6.985548e-002,1.505783e-001,1.112507e-002,-1.388456e-002,2.369834e-006,2.369834e-006,,,,,,,,,,,,,,,,,,,,
1473328545.523,,0.000000e+000,8.249628e+001,8.176984e+001,1,0,1.692035e+000,1.728874e-001,1.728874e-001,-8.195123e-003,-1.421927e-002,1.769350e-001,-4.147520e-003,-1.017167e-002,4.330681e-006,4.330681e-006,,,,,,,,,,,,,,,,,,,,
1473328545.523,,0.000000e+000,8.249628e+001,8.176984e+001,1,0,4.300053e+000,1.136815e-001,1.136815e-001,9.406840e-003,-7.342517e-002,1.407970e-001,3.652239e-002,-4.630962e-002,2.847624e-006,2.847624e-006,,,,,,,,,,,,,,,,,,,,
1473328559.533,,0.000000e+000,8.160161e+001,8.073434e+001,1,0,4.486407e+000,1.046785e-001,1.046785e-001,-1.039742e-002,-7.365189e-002,1.477292e-001,3.265331e-002,-3.060116e-002,2.622107e-006,2.622107e-006,,,,,,,,,,,,,,,,,,,,
1473328572.033,,0.000000e+000,8.073434e+001,7.996350e+001,1,0,1.766483e+000,1.741081e-001,1.741081e-001,1.824300e-002,-2.611248e-002,1.439512e-001,-1.191388e-002,-5.626936e-002,4.361259e-006,4.361259e-006,,,,,,,,,,,,,,,,,,,,
1473328589.751,,0.000000e+000,7.987363e+001,7.959913e+001,1,0,7.279048e-003,1.048311e-001,1.048311e-001,-4.662212e-002,-7.129293e-002,1.624559e-001,1.100266e-002,-1.366815e-002,2.625929e-006,2.625929e-006,,,,,,,,,,,,,,,,,,,,
1473328605.258,,0.000000e+000,7.959156e+001,7.960063e+001,1,0,1.914298e+000,1.532029e-001,1.532029e-001,-4.274200e-002,-4.742637e-002,1.694059e-001,-2.653899e-002,-3.122336e-002,3.837603e-006,3.837603e-006,,,,,,,,,,,,,,,,,,,,
1473328605.258,,0.000000e+000,7.959156e+001,7.960063e+001,1,0,4.450972e+000,1.293985e-001,1.293985e-001,1.308784e-002,-7.123081e-002,1.487804e-001,3.246978e-002,-5.184887e-002,3.241322e-006,3.241322e-006,,,,,,,,,,,,,,,,,,,,
1473328785.489,,0.000000e+000,8.005814e+001,8.006578e+001,1,0,4.317423e+000,1.275674e-001,1.275674e-001,-1.309152e-002,-7.291976e-002,1.772923e-001,3.663345e-002,-2.319479e-002,3.195454e-006,3.195454e-006,,,,,,,,,,,,,,,,,,,,
1473328797.454,,0.000000e+000,8.003371e+001,8.003980e+001,1,0,1.568258e+000,2.156133e-001,2.156133e-001,5.621592e-002,1.546928e-002,1.666681e-001,7.270758e-003,-3.347588e-002,5.400929e-006,5.400929e-006,,,,,,,,,,,,,,,,,,,,
1473328810.211,,0.000000e+000,8.003980e+001,8.003676e+001,1,0,1.473556e-002,1.329081e-001,1.329081e-001,-5.014779e-002,-7.197805e-002,1.939926e-001,1.093675e-002,-1.089351e-002,3.329235e-006,3.329235e-006,,,,,,,,,,,,,,,,,,,,
1473328822.222,,0.000000e+000,8.003676e+001,8.003371e+001,1,0,2.139452e+000,1.147496e-001,1.147496e-001,-8.538912e-002,-8.837490e-002,1.484587e-001,-5.168001e-002,-5.466579e-002,2.874380e-006,2.874380e-006,,,,,,,,,,,,,,,,,,,,
1473328822.222,,0.000000e+000,8.003676e+001,8.003371e+001,1,0,4.591137e+000,1.376385e-001,1.376385e-001,1.363710e-002,-6.548601e-002,1.531468e-001,2.914538e-002,-4.997773e-002,3.447727e-006,3.447727e-006,,,,,,,,,,,,,,,,,,,,
1473328991.456,,0.000000e+000,7.658009e+001,7.623473e+001,1,0,4.134377e+000,5.783258e-002,5.783258e-002,-1.407274e-002,-7.508228e-002,1.061610e-001,3.425568e-002,-2.675386e-002,1.448657e-006,1.448657e-006,,,,,,,,,,,,,,,,,,,,
1473329004.670,,0.000000e+000,7.597941e+001,7.559541e+001,1,0,1.378990e+000,1.997436e-001,1.997436e-001,8.955075e-002,4.907517e-002,1.319510e-001,2.175816e-002,-1.871742e-002,5.003408e-006,5.003408e-006,,,,,,,,,,,,,,,,,,,,
1473329017.135,,0.000000e+000,7.547234e+001,7.479559e+001,1,0,5.601782e-002,7.904294e-002,7.904294e-002,-4.191599e-002,-6.313933e-002,1.322515e-001,1.129254e-002,-9.930804e-003,1.979958e-006,1.979958e-006,,,,,,,,,,,,,,,,,,,,
1473329031.349,,0.000000e+000,7.450685e+001,7.391743e+001,1,0,2.365868e+000,2.502518e-002,2.502518e-002,-1.098244e-001,-1.113496e-001,6.537692e-002,-6.947261e-002,-7.099789e-002,6.268594e-007,6.268594e-007,,,,,,,,,,,,,,,,,,,,
1473329031.349,,0.000000e+000,7.450685e+001,7.391743e+001,1,0,4.717490e+000,6.714072e-002,6.714072e-002,1.008044e-002,-6.923410e-002,8.027354e-002,2.321326e-002,-5.610128e-002,1.681818e-006,1.681818e-006,,,,,,,,,,,,,,,,,,,,
1473329047.121,,0.000000e+000,7.378520e+001,7.320158e+001,1,0,3.940112e+000,5.539110e-002,5.539110e-002,-2.301425e-002,-8.201265e-002,1.046085e-001,2.620316e-002,-3.279524e-002,1.387500e-006,1.387500e-006,,,,,,,,,,,,,,,,,,,,
1473329058.393,,0.000000e+000,7.288372e+001,7.241570e+001,1,0,1.198375e+000,2.240059e-001,2.240059e-001,1.181383e-001,7.905479e-002,1.358595e-001,2.999194e-002,-9.091616e-003,5.611156e-006,5.611156e-006,,,,,,,,,,,,,,,,,,,,
1473329071.857,,0.000000e+000,7.210564e+001,7.163802e+001,1,0,1.298466e-001,8.163702e-002,8.163701e-002,-3.189378e-002,-5.146854e-002,1.253457e-001,1.181490e-002,-7.759854e-003,2.044938e-006,2.044938e-006,,,,,,,,,,,,,,,,,,,,
1473329083.821,,0.000000e+000,7.163802e+001,7.102338e+001,1,0,2.590894e+000,2.563555e-002,2.563555e-002,-1.194362e-001,-1.194362e-001,7.352720e-002,-7.154456e-002,-7.154456e-002,6.421487e-007,6.421487e-007,,,,,,,,,,,,,,,,,,,,
1473329083.821,,0.000000e+000,7.163802e+001,7.102338e+001,1,0,4.825495e+000,7.736442e-002,7.736442e-002,1.063327e-002,-6.770734e-002,8.517703e-002,1.844588e-002,-5.989473e-002,1.937913e-006,1.937913e-006,,,,,,,,,,,,,,,,,,,,
1473329102.036,,0.000000e+000,7.058401e+001,6.981942e+001,1,0,3.736778e+000,4.715110e-002,4.715110e-002,-2.717740e-002,-8.587898e-002,8.348859e-002,9.160097e-003,-4.954148e-002,1.181095e-006,1.181095e-006,,,,,,,,,,,,,,,,,,,,
1473329115.500,,0.000000e+000,6.950128e+001,6.870250e+001,1,0,1.025441e+000,2.015747e-001,2.015748e-001,1.180398e-001,7.950684e-002,1.072201e-001,2.368515e-002,-1.484783e-002,5.049276e-006,5.049276e-006,,,,,,,,,,,,,,,,,,,,
1473329127.977,,0.000000e+000,6.870250e+001,6.792285e+001,1,0,2.334155e-001,5.600147e-002,5.600147e-002,-2.814969e-002,-4.696877e-002,9.034313e-002,6.191972e-003,-1.262710e-002,1.402789e-006,1.402789e-006,,,,,,,,,,,,,,,,,,,,
1473329127.977,,0.000000e+000,6.870250e+001,6.792285e+001,1,0,2.812117e+000,3.479110e-002,3.479110e-002,3.062101e-002,-6.817913e-002,-2.585906e-002,-3.002916e-002,-1.288293e-001,8.714875e-007,8.714875e-007,,,,,,,,,,,,,,,,,,,,
1473329140.691,,0.000000e+000,6.792285e+001,6.717076e+001,1,0,4.910334e+000,-3.357036e-002,-3.357036e-002,-1.724005e-002,-6.333327e-002,-1.830909e-002,-1.978782e-003,-4.807200e-002,-8.409090e-007,-8.409090e-007,,,,,,,,,,,,,,,,,,,,
1473329156.155,,0.000000e+000,6.685576e+001,6.605820e+001,1,0,3.525897e+000,-2.674947e-001,-2.674947e-001,-4.790426e-002,-1.012149e-001,-2.442158e-001,-2.462536e-002,-7.793604e-002,-6.700515e-006,-6.700515e-006,,,,,,,,,,,,,,,,,,,,
1473329167.922,,0.000000e+000,6.605820e+001,6.542561e+001,1,0,8.595527e-001,-1.366161e+000,-1.366161e+000,-4.784422e-001,-5.113839e-001,-1.454111e+000,-5.663917e-001,-5.993334e-001,-3.422117e-005,-3.422117e-005,,,,,,,,,,,,,,,,,,,,
1473329179.386,,0.000000e+000,6.542561e+001,6.462148e+001,1,0,3.629673e-001,-2.560350e+000,-2.560350e+000,-6.644636e-001,-6.780679e-001,-2.566645e+000,-6.707585e-001,-6.843629e-001,-6.413460e-005,-6.413460e-005,,,,,,,,,,,,,,,,,,,,
1473329179.386,,0.000000e+000,6.542561e+001,6.462148e+001,1,0,3.027127e+000,-4.106266e-001,-4.106265e-001,1.548335e+000,1.471656e+000,-5.336535e-001,1.425308e+000,1.348629e+000,-1.028585e-005,-1.028585e-005,,,,,,,,,,,,,,,,,,,,
1473329202.608,,0.000000e+000,6.382802e+001,6.320607e+001,1,0,4.967529e+000,-2.485275e+000,-2.485275e+000,-4.123065e-001,-4.326315e-001,-2.460634e+000,-3.876662e-001,-4.079912e-001,-1.245080e-004,-1.245080e-004,,,,,,,,,,,,,,,,,,,,
1473329217.334,,0.000000e+000,6.320607e+001,6.225002e+001,1,0,3.308685e+000,-1.960509e+000,-1.960509e+000,5.975055e-001,5.851028e-001,-1.972364e+000,5.856509e-001,5.732481e-001,-9.821817e-005,-9.821817e-005,,,,,,,,,,,,,,,,,,,,
1473329242.522,,0.000000e+000,6.147743e+001,6.076094e+001,1,0,7.006868e-001,-1.827296e+000,-1.827296e+000,-5.347527e-001,-5.366794e-001,-1.841777e+000,-5.492336e-001,-5.511602e-001,-2.288610e-004,-2.288610e-004,,,,,,,,,,,,,,,,,,,,
1473329254.986,,0.000000e+000,6.076094e+001,6.008308e+001,1,0,5.142992e-001,-1.881619e+000,-1.881619e+000,-4.858268e-001,-4.864899e-001,-1.886405e+000,-4.906131e-001,-4.912761e-001,-2.356647e-004,-2.356647e-004,,,,,,,,,,,,,,,,,,,,
1473329254.986,,0.000000e+000,6.076094e+001,6.008308e+001,1,0,3.234231e+000,-9.137242e-001,-9.137242e-001,4.854494e-001,4.814047e-001,-9.539863e-001,4.451873e-001,4.411426e-001,-1.144401e-004,-1.144401e-004,,,,,,,,,,,,,,,,,,,,
1473329268.701,,0.000000e+000,5.979676e+001,5.924741e+001,1,0,4.993524e+000,-1.778466e+000,-1.778466e+000,-2.706750e-001,-2.729427e-001,-1.762569e+000,-2.547780e-001,-2.570456e-001,-2.227453e-004,-2.227453e-004,,,,,,,,,,,,,,,,,,,,
1473329281.915,,0.000000e+000,5.912911e+001,5.860995e+001,1,0,3.086676e+000,-7.698294e-001,-7.698294e-001,8.285167e-001,8.274608e-001,-7.776952e-001,8.206508e-001,8.195949e-001,-9.641785e-005,-9.641785e-005,,,,,,,,,,,,,,,,,,,,
1473329294.629,,0.000000e+000,5.846729e+001,5.793781e+001,1,0,5.500091e-001,-2.293466e+000,-2.293466e+000,-6.098163e-001,-6.101589e-001,-2.294757e+000,-6.111073e-001,-6.114500e-001,-2.872469e-004,-2.872469e-004,,,,,,,,,,,,,,,,,,,,
1473329308.547,,0.000000e+000,5.768549e+001,5.719357e+001,1,0,6.832574e-001,-2.480697e+000,-2.480697e+000,-7.120485e-001,-7.120891e-001,-2.499488e+000,-7.308397e-001,-7.308803e-001,-3.106967e-004,-3.106967e-004,,,,,,,,,,,,,,,,,,,,
1473329308.547,,0.000000e+000,5.768549e+001,5.719357e+001,1,0,3.432483e+000,-1.632893e+000,-1.632893e+000,1.359857e-001,1.357152e-001,-1.657851e+000,1.110274e-001,1.107570e-001,-2.045129e-004,-2.045129e-004,,,,,,,,,,,,,,,,,,,,
1473329320.119,,0.000000e+000,5.706225e+001,5.656945e+001,1,0,4.986026e+000,-2.168798e+000,-2.168798e+000,-3.326018e-001,-3.325305e-001,-2.148265e+000,-3.120687e-001,-3.119974e-001,-2.716327e-004,-2.716327e-004,,,,,,,,,,,,,,,,,,,,
1473329334.333,,0.000000e+000,5.630975e+001,5.581400e+001,1,0,2.861375e+000,-3.956725e-001,-3.956725e-001,1.519629e+000,1.520140e+000,-3.855699e-001,1.529732e+000,1.530243e+000,-4.955629e-005,-4.955629e-005,,,,,,,,,,,,,,,,,,,,
1473329349.048,,0.000000e+000,5.557457e+001,5.508069e+001,1,0,4.096757e-001,-2.615284e+000,-2.615284e+000,-6.152143e-001,-6.144767e-001,-2.603343e+000,-6.032734e-001,-6.025357e-001,-3.275532e-004,-3.275532e-004,,,,,,,,,,,,,,,,,,,,
1473329362.512,,0.000000e+000,5.495705e+001,5.433852e+001,1,0,8.663526e-001,-2.956938e+000,-2.956938e+000,-8.892219e-001,-8.888571e-001,-2.994092e+000,-9.263761e-001,-9.260113e-001,-3.703439e-004,-3.703439e-004,,,,,,,,,,,,,,,,,,,,
1473329362.512,,0.000000e+000,5.495705e+001,5.433852e+001,1,0,3.621702e+000,-2.368541e+000,-2.368541e+000,-3.031507e-001,-3.004603e-001,-2.378219e+000,-3.128281e-001,-3.101377e-001,-2.966498e-004,-2.966498e-004,,,,,,,,,,,,,,,,,,,,
1473329376.476,,0.000000e+000,5.422094e+001,5.375119e+001,1,0,4.944748e+000,-2.548906e+000,-2.548906e+000,-4.121572e-001,-4.093895e-001,-2.524205e+000,-3.874563e-001,-3.846886e-001,-3.192396e-004,-3.192396e-004,,,,,,,,,,,,,,,,,,,,
1473329392.968,,0.000000e+000,5.350578e+001,5.303794e+001,1,0,2.634911e+000,-5.798517e-002,-5.798517e-002,2.162914e+000,2.165200e+000,-1.750299e-002,2.203396e+000,2.205682e+000,-7.262396e-006,-7.262396e-006,,,,,,,,,,,,,,,,,,,,
1473329407.978,,0.000000e+000,5.266128e+001,5.219518e+001,1,0,2.832828e-001,-2.886593e+000,-2.886593e+000,-5.915682e-001,-5.899472e-001,-2.869198e+000,-5.741732e-001,-5.725522e-001,-3.615335e-004,-3.615335e-004,,,,,,,,,,,,,,,,,,,,
1473329420.942,,0.000000e+000,5.206746e+001,5.157959e+001,1,0,1.060612e+000,-3.291726e+000,-3.291726e+000,-9.268126e-001,-9.261501e-001,-3.335948e+000,-9.710340e-001,-9.703715e-001,-4.122747e-004,-4.122747e-004,,,,,,,,,,,,,,,,,,,,
1473329420.942,,0.000000e+000,5.206746e+001,5.157959e+001,1,0,3.802403e+000,-3.103732e+000,-3.103732e+000,-7.436455e-001,-7.381561e-001,-3.103660e+000,-7.435732e-001,-7.380838e-001,-3.887293e-004,-3.887293e-004,,,,,,,,,,,,,,,,,,,,
1473329434.406,,0.000000e+000,5.136699e+001,5.087089e+001,1,0,4.870989e+000,-2.943053e+000,-2.943053e+000,-5.206267e-001,-5.162215e-001,-2.916148e+000,-4.937226e-001,-4.893174e-001,-3.686048e-004,-3.686048e-004,,,,,,,,,,,,,,,,,,,,
1473329451.371,,0.000000e+000,5.051645e+001,5.003696e+001,1,0,2.409879e+000,-3.906369e-002,-3.906369e-002,2.470093e+000,2.473643e+000,-1.287872e-002,2.496278e+000,2.499828e+000,-4.892561e-006,-4.892561e-006,,,,,,,,,,,,,,,,,,,,
1473329463.878,,0.000000e+000,4.992154e+001,4.945143e+001,1,0,1.752578e-001,-3.117008e+000,-3.117008e+000,-5.505401e-001,-5.482497e-001,-3.104909e+000,-5.384415e-001,-5.361512e-001,-3.903920e-004,-3.903920e-004,,,,,,,,,,,,,,,,,,,,
1473329476.898,,0.000000e+000,4.933369e+001,4.886800e+001,1,0,1.263918e+000,-3.330332e+000,-3.330332e+000,-7.071352e-001,-7.063496e-001,-3.363679e+000,-7.404821e-001,-7.396965e-001,-4.171100e-004,-4.171100e-004,,,,,,,,,,,,,,,,,,,,
1473329476.898,,0.000000e+000,4.933369e+001,4.886800e+001,1,0,3.975288e+000,-3.703879e+000,-3.703879e+000,-1.087359e+000,-1.079896e+000,-3.702733e+000,-1.086213e+000,-1.078750e+000,-4.638951e-004,-4.638951e-004,,,,,,,,,,,,,,,,,,,,
1473329489.865,,0.000000e+000,4.874814e+001,4.814415e+001,1,0,4.767365e+000,-3.356121e+000,-3.356121e+000,-6.756628e-001,-6.693115e-001,-3.322957e+000,-6.424992e-001,-6.361480e-001,-4.203398e-004,-4.203398e-004,,,,,,,,,,,,,,,,,,,,
1473329505.579,,0.000000e+000,4.791507e+001,4.743277e+001,1,0,2.188691e+000,-4.675436e-001,-4.675436e-001,2.281962e+000,2.286684e+000,-5.025424e-001,2.246963e+000,2.251685e+000,-5.855784e-005,-5.855784e-005,,,,,,,,,,,,,,,,,,,,
1473329529.008,,0.000000e+000,4.684858e+001,4.638332e+001,1,0,9.038017e-002,-1.692251e+000,-1.692251e+000,-2.658984e-001,-2.643064e-001,-1.686834e+000,-2.604812e-001,-2.588892e-001,-4.238946e-004,-4.238946e-004,,,,,,,,,,,,,,,,,,,,
1473329542.472,,0.000000e+000,4.625875e+001,4.577413e+001,1,0,1.474866e+000,-1.557817e+000,-1.557817e+000,-9.966877e-002,-9.923327e-002,-1.567845e+000,-1.096961e-001,-1.092606e-001,-3.902200e-004,-3.902200e-004,,,,,,,,,,,,,,,,,,,,
1473329542.472,,0.000000e+000,4.625875e+001,4.577413e+001,1,0,4.141170e+000,-2.103488e+000,-2.103488e+000,-6.497818e-001,-6.449041e-001,-2.101108e+000,-6.474019e-001,-6.425242e-001,-5.269059e-004,-5.269059e-004,,,,,,,,,,,,,,,,,,,,
1473329555.186,,0.000000e+000,4.565579e+001,4.505548e+001,1,0,4.637790e+000,-1.928465e+000,-1.928465e+000,-4.487078e-001,-4.448285e-001,-1.910933e+000,-4.311757e-001,-4.272964e-001,-4.830640e-004,-4.830640e-004,,,,,,,,,,,,,,,,,,,,
1473329568.700,,0.000000e+000,4.494371e+001,4.446513e+001,1,0,1.973572e+000,-6.401258e-001,-6.401258e-001,8.726830e-001,8.757333e-001,-6.820285e-001,8.307803e-001,8.338305e-001,-1.603461e-004,-1.603461e-004,,,,,,,,,,,,,,,,,,,,
1473329580.925,,0.000000e+000,4.446513e+001,4.385455e+001,1,0,3.318539e-002,-1.801050e+000,-1.801050e+000,-2.617213e-001,-2.599398e-001,-1.794631e+000,-2.553029e-001,-2.535214e-001,-4.511476e-004,-4.511476e-004,,,,,,,,,,,,,,,,,,,,
1473329594.389,,0.000000e+000,4.373397e+001,4.312825e+001,1,0,1.692058e+000,-1.274911e+000,-1.274911e+000,2.932115e-001,2.936463e-001,-1.282965e+000,2.851572e-001,2.855921e-001,-3.193543e-004,-3.193543e-004,,,,,,,,,,,,,,,,,,,,
1473329594.389,,0.000000e+000,4.373397e+001,4.312825e+001,1,0,4.300042e+000,-2.231361e+000,-2.231361e+000,-6.687834e-001,-6.628039e-001,-2.222206e+000,-6.596286e-001,-6.536491e-001,-5.589369e-004,-5.589369e-004,,,,,,,,,,,,,,,,,,,,
1473329606.604,,0.000000e+000,4.312825e+001,4.264141e+001,1,0,4.486437e+000,-2.167730e+000,-2.167730e+000,-5.789431e-001,-5.739688e-001,-2.152599e+000,-5.638126e-001,-5.588382e-001,-5.429978e-004,-5.429978e-004,,,,,,,,,,,,,,,,,,,,
1473329621.568,,0.000000e+000,4.239256e+001,4.190138e+001,1,0,1.766488e+000,-1.533403e+000,-1.533403e+000,4.922671e-001,4.958988e-001,-1.575748e+000,4.499217e-001,4.535534e-001,-3.841043e-004,-3.841043e-004,,,,,,,,,,,,,,,,,,,,
1473329634.282,,0.000000e+000,4.177148e+001,4.127761e+001,1,0,7.245570e-003,-1.922666e+000,-1.922666e+000,-2.709785e-001,-2.689549e-001,-1.914042e+000,-2.623543e-001,-2.603307e-001,-4.816115e-004,-4.816115e-004,,,,,,,,,,,,,,,,,,,,
1473329646.747,,0.000000e+000,4.114369e+001,4.062046e+001,1,0,1.914106e+000,-8.862575e-001,-8.862575e-001,7.906913e-001,7.911060e-001,-8.864057e-001,7.905431e-001,7.909578e-001,-2.220000e-004,-2.220000e-004,,,,,,,,,,,,,,,,,,,,
1473329646.747,,0.000000e+000,4.114369e+001,4.062046e+001,1,0,4.450767e+000,-2.307047e+000,-2.307047e+000,-6.371471e-001,-6.296831e-001,-2.287478e+000,-6.175784e-001,-6.101145e-001,-5.778956e-004,-5.778956e-004,,,,,,,,,,,,,,,,,,,,
1473329659.142,,0.000000e+000,4.048813e+001,3.997829e+001,1,0,4.317490e+000,-2.415235e+000,-2.415235e+000,-7.148237e-001,-7.091743e-001,-2.408247e+000,-7.078359e-001,-7.021865e-001,-6.049958e-004,-6.049958e-004,,,,,,,,,,,,,,,,,,,,
1473329676.715,,0.000000e+000,3.959876e+001,3.908062e+001,1,0,1.568195e+000,-1.648457e+000,-1.648457e+000,8.885630e-002,9.302986e-002,-1.679911e+000,5.740269e-002,6.157625e-002,-4.129245e-004,-4.129245e-004,,,,,,,,,,,,,,,,,,,,
1473329690.707,,0.000000e+000,3.881570e+001,3.840970e+001,1,0,1.470075e-002,-2.065493e+000,-2.065493e+000,-2.955040e-001,-2.932422e-001,-2.055022e+000,-2.850336e-001,-2.827718e-001,-5.173883e-004,-5.173883e-004,,,,,,,,,,,,,,,,,,,,
1473329703.421,,0.000000e+000,3.827518e+001,3.758923e+001,1,0,2.139384e+000,-4.496902e-001,-4.496902e-001,1.347650e+000,1.347958e+000,-4.299982e-001,1.367342e+000,1.367650e+000,-1.126436e-004,-1.126436e-004,,,,,,,,,,,,,,,,,,,,
1473329703.421,,0.000000e+000,3.827518e+001,3.758923e+001,1,0,4.591084e+000,-2.372356e+000,-2.372356e+000,-5.828682e-001,-5.747085e-001,-2.344390e+000,-5.549019e-001,-5.467422e-001,-5.942550e-004,-5.942550e-004,,,,,,,,,,,,,,,,,,,,
1473329716.080,,0.000000e+000,3.745726e+001,3.701891e+001,1,0,4.134429e+000,-2.623981e+000,-2.623981e+000,-8.044011e-001,-7.978475e-001,-2.628630e+000,-8.090495e-001,-8.024960e-001,-6.572850e-004,-6.572850e-004,,,,,,,,,,,,,,,,,,,,
1473329738.434,,0.000000e+000,3.629482e+001,3.567958e+001,1,0,1.379058e+000,-2.171239e+000,-2.171239e+000,-3.010518e-001,-2.965583e-001,-2.193837e+000,-3.236496e-001,-3.191561e-001,-5.438770e-004,-5.438770e-004,,,,,,,,,,,,,,,,,,,,
1473329751.648,,0.000000e+000,3.537348e+001,3.490186e+001,1,0,5.597237e-002,-2.238991e+000,-2.238991e+000,-3.383338e-001,-3.359854e-001,-2.229290e+000,-3.286337e-001,-3.262854e-001,-5.608480e-004,-5.608480e-004,,,,,,,,,,,,,,,,,,,,
1473329762.612,,0.000000e+000,3.459518e+001,3.427899e+001,1,0,2.365769e+000,-1.001007e-001,-1.001007e-001,1.828934e+000,1.829112e+000,-5.801218e-002,1.871023e+000,1.871201e+000,-2.507438e-005,-2.507438e-005,,,,,,,,,,,,,,,,,,,,
1473329762.612,,0.000000e+000,3.459518e+001,3.427899e+001,1,0,4.717465e+000,-2.442854e+000,-2.442854e+000,-5.229068e-001,-5.136412e-001,-2.414310e+000,-4.943621e-001,-4.850966e-001,-6.119141e-004,-6.119141e-004,,,,,,,,,,,,,,,,,,,,
1473329775.845,,0.000000e+000,3.410852e+001,3.340506e+001,1,0,3.940213e+000,-2.723777e+000,-2.723777e+000,-7.730374e-001,-7.659692e-001,-2.732490e+000,-7.817504e-001,-7.746822e-001,-6.822830e-004,-6.822830e-004,,,,,,,,,,,,,,,,,,,,
1473329789.743,,0.000000e+000,3.309373e+001,3.230539e+001,1,0,1.198366e+000,-2.615131e+000,-2.615131e+000,-6.306740e-001,-6.258122e-001,-2.637124e+000,-6.526664e-001,-6.478046e-001,-6.550681e-004,-6.550681e-004,,,,,,,,,,,,,,,,,,,,
1473329801.815,,0.000000e+000,3.215202e+001,3.150835e+001,1,0,1.298017e-001,-2.415845e+000,-2.415845e+000,-4.032286e-001,-4.007733e-001,-2.406579e+000,-3.939622e-001,-3.915069e-001,-6.051487e-004,-6.051487e-004,,,,,,,,,,,,,,,,,,,,
1473329814.779,,0.000000e+000,3.135319e+001,3.070511e+001,1,0,2.590828e+000,-2.380444e-002,-2.380444e-002,2.019704e+000,2.019704e+000,-2.118508e-003,2.041390e+000,2.041390e+000,-5.962809e-006,-5.962809e-006,,,,,,,,,,,,,,,,,,,,
1473329814.779,,0.000000e+000,3.135319e+001,3.070511e+001,1,0,4.825460e+000,-2.495041e+000,-2.495041e+000,-4.614525e-001,-4.515319e-001,-2.475078e+000,-4.414897e-001,-4.315691e-001,-6.249865e-004,-6.249865e-004,,,,,,,,,,,,,,,,,,,,
1473329829.744,,0.000000e+000,3.037496e+001,2.954277e+001,1,0,3.736837e+000,-2.615131e+000,-2.615131e+000,-5.451423e-001,-5.375171e-001,-2.619465e+000,-5.494758e-001,-5.418506e-001,-6.550681e-004,-6.550681e-004,,,,,,,,,,,,,,,,,,,,
1473329843.491,,0.000000e+000,2.937847e+001,2.871141e+001,1,0,1.025482e+000,-2.963652e+000,-2.963652e+000,-8.594707e-001,-8.543313e-001,-2.987470e+000,-8.832884e-001,-8.781490e-001,-7.423697e-004,-7.423697e-004,,,,,,,,,,,,,,,,,,,,
1473329855.455,,0.000000e+000,2.854090e+001,2.770144e+001,1,0,2.333762e-001,-2.636494e+000,-2.636494e+000,-5.036848e-001,-5.011964e-001,-2.626378e+000,-4.935685e-001,-4.910800e-001,-6.604193e-004,-6.604193e-004,,,,,,,,,,,,,,,,,,,,
1473329855.455,,0.000000e+000,2.854090e+001,2.770144e+001,1,0,2.812076e+000,-3.202918e-001,-3.202918e-001,1.801941e+000,1.815006e+000,-3.433119e-001,1.778921e+000,1.791986e+000,-8.023036e-005,-8.023036e-005,,,,,,,,,,,,,,,,,,,,
1473329869.170,,0.000000e+000,2.753222e+001,2.702851e+001,1,0,4.910344e+000,-2.575915e+000,-2.575915e+000,-4.226197e-001,-4.119346e-001,-2.558640e+000,-4.053446e-001,-3.946595e-001,-6.452447e-004,-6.452447e-004,,,,,,,,,,,,,,,,,,,,
1473329883.635,,0.000000e+000,2.651778e+001,2.583165e+001,1,0,3.525871e+000,-2.302164e+000,-2.302164e+000,-1.181711e-001,-1.101820e-001,-2.304503e+000,-1.205105e-001,-1.125214e-001,-5.766724e-004,-5.766724e-004,,,,,,,,,,,,,,,,,,,,
1473329898.606,,0.000000e+000,2.548855e+001,2.480792e+001,1,0,8.596131e-001,-3.176061e+000,-3.176061e+000,-9.613994e-001,-9.560490e-001,-3.197010e+000,-9.823483e-001,-9.769979e-001,-7.955763e-004,-7.955763e-004,,,,,,,,,,,,,,,,,,,,
1473329913.070,,0.000000e+000,2.446279e+001,2.381335e+001,1,0,3.629427e-001,-2.887661e+000,-2.887661e+000,-6.416422e-001,-6.391780e-001,-2.879871e+000,-6.338516e-001,-6.313875e-001,-7.233346e-004,-7.233346e-004,,,,,,,,,,,,,,,,,,,,
1473329913.070,,0.000000e+000,2.446279e+001,2.381335e+001,1,0,3.027100e+000,-8.960235e-001,-8.960235e-001,1.338571e+000,1.352460e+000,-9.538769e-001,1.280718e+000,1.294607e+000,-2.244462e-004,-2.244462e-004,,,,,,,,,,,,,,,,,,,,
1473329928.285,,0.000000e+000,2.355354e+001,2.332674e+001,1,0,4.967527e+000,-2.658925e+000,-2.658925e+000,-4.027209e-001,-3.916276e-001,-2.641221e+000,-3.850169e-001,-3.739235e-001,-6.660381e-004,-6.660381e-004,,,,,,,,,,,,,,,,,,,,
1473329941.249,,0.000000e+000,2.326943e+001,2.285828e+001,1,0,3.308719e+000,-1.799829e+000,-1.799829e+000,4.692129e-001,4.775194e-001,-1.808597e+000,4.604449e-001,4.687514e-001,-4.508419e-004,-4.508419e-004,,,,,,,,,,,,,,,,,,,,
1473329956.964,,0.000000e+000,2.255867e+001,2.169870e+001,1,0,7.006979e-001,-3.240455e+000,-3.240455e+000,-9.434854e-001,-9.381123e-001,-3.249891e+000,-9.529209e-001,-9.475477e-001,-8.117065e-004,-8.117065e-004,,,,,,,,,,,,,,,,,,,,
1473329968.928,,0.000000e+000,2.152803e+001,2.085756e+001,1,0,5.142713e-001,-3.120975e+000,-3.120975e+000,-8.006856e-001,-7.983291e-001,-3.121702e+000,-8.014123e-001,-7.990558e-001,-7.817778e-004,-7.817778e-004,,,,,,,,,,,,,,,,,,,,
1473329968.928,,0.000000e+000,2.152803e+001,2.085756e+001,1,0,3.234252e+000,-1.565447e+000,-1.565447e+000,7.428247e-001,7.571992e-001,-1.619785e+000,6.884871e-001,7.028615e-001,-3.921311e-004,-3.921311e-004,,,,,,,,,,,,,,,,,,,,
1473329981.892,,0.000000e+000,2.071674e+001,2.029185e+001,1,0,4.993465e+000,-2.732017e+000,-2.732017e+000,-4.007520e-001,-3.890188e-001,-2.710991e+000,-3.797261e-001,-3.679929e-001,-6.843470e-004,-6.843470e-004,,,,,,,,,,,,,,,,,,,,
1473329996.634,,0.000000e+000,2.027299e+001,2.024200e+001,1,0,3.086663e+000,-1.184118e+000,-1.184118e+000,1.153128e+000,1.161574e+000,-1.191147e+000,1.146099e+000,1.154545e+000,-2.966115e-004,-2.966115e-004,,,,,,,,,,,,,,,,,,,,
1473330009.098,,0.000000e+000,2.022047e+001,1.947768e+001,1,0,5.500010e-001,-3.197729e+000,-3.197729e+000,-8.507848e-001,-8.454642e-001,-3.192704e+000,-8.457596e-001,-8.404391e-001,-8.010040e-004,-8.010040e-004,,,,,,,,,,,,,,,,,,,,
1473330022.562,,0.000000e+000,1.929580e+001,1.842963e+001,1,0,6.832610e-001,-3.323466e+000,-3.323466e+000,-9.541627e-001,-9.519610e-001,-3.338509e+000,-9.692064e-001,-9.670048e-001,-8.324999e-004,-8.324999e-004,,,,,,,,,,,,,,,,,,,,
1473330022.562,,0.000000e+000,1.929580e+001,1.842963e+001,1,0,3.432479e+000,-2.209235e+000,-2.209235e+000,1.475920e-001,1.622696e-001,-2.236218e+000,1.206085e-001,1.352861e-001,-5.533946e-004,-5.533946e-004,,,,,,,,,,,,,,,,,,,,
1473330036.588,,0.000000e+000,1.826091e+001,1.737680e+001,1,0,4.986040e+000,-2.796411e+000,-2.796411e+000,-4.169445e-001,-4.055479e-001,-2.772852e+000,-3.933854e-001,-3.819888e-001,-7.004772e-004,-7.004772e-004,,,,,,,,,,,,,,,,,,,,
1473330050.303,,0.000000e+000,1.701416e+001,1.649606e+001,1,0,2.861416e+000,-5.531480e-001,-5.531480e-001,1.852154e+000,1.860709e+000,-5.360258e-001,1.869277e+000,1.877831e+000,-1.385589e-004,-1.385589e-004,,,,,,,,,,,,,,,,,,,,
1473330064.767,,0.000000e+000,1.619540e+001,1.556845e+001,1,0,4.096764e-001,-3.172857e+000,-3.172857e+000,-7.481270e-001,-7.428126e-001,-3.156210e+000,-7.314799e-001,-7.261655e-001,-7.947736e-004,-7.947736e-004,,,,,,,,,,,,,,,,,,,,
1473330078.541,,0.000000e+000,1.545742e+001,1.498292e+001,1,0,8.663087e-001,-3.485977e+000,-3.485977e+000,-1.045002e+000,-1.042955e+000,-3.517772e+000,-1.076798e+000,-1.074751e+000,-8.732075e-004,-8.732075e-004,,,,,,,,,,,,,,,,,,,,
1473330078.541,,0.000000e+000,1.545742e+001,1.498292e+001,1,0,3.621722e+000,-2.802210e+000,-2.802210e+000,-3.742833e-001,-3.591883e-001,-2.812681e+000,-3.847548e-001,-3.696599e-001,-7.019296e-004,-7.019296e-004,,,,,,,,,,,,,,,,,,,,
1473330093.509,,0.000000e+000,1.492528e+001,1.493950e+001,1,0,4.944808e+000,-2.889035e+000,-2.889035e+000,-4.543877e-001,-4.425495e-001,-2.864547e+000,-4.298995e-001,-4.180613e-001,-7.236786e-004,-7.236786e-004,,,,,,,,,,,,,,,,,,,,
1473330109.003,,0.000000e+000,1.496497e+001,1.498383e+001,1,0,2.634939e+000,-1.072726e-001,-1.072726e-001,2.329552e+000,2.338042e+000,-5.842733e-002,2.378397e+000,2.386887e+000,-2.687086e-005,-2.687086e-005,,,,,,,,,,,,,,,,,,,,
1473330416.297,,0.000000e+000,1.500702e+001,1.500213e+001,1,0,2.833041e-001,-3.074740e+000,-3.074740e+000,-6.287875e-001,-6.242249e-001,-3.056248e+000,-6.102958e-001,-6.057332e-001,-7.701961e-004,-7.701961e-004,,,,,,,,,,,,,,,,,,,,
1473330428.807,,0.000000e+000,1.500213e+001,1.500213e+001,1,0,1.060558e+000,-3.396100e+000,-3.396100e+000,-9.496082e-001,-9.479134e-001,-3.432140e+000,-9.856488e-001,-9.839540e-001,-8.506941e-004,-8.506941e-004,,,,,,,,,,,,,,,,,,,,
1473330428.807,,0.000000e+000,1.500213e+001,1.500213e+001,1,0,3.802366e+000,-3.206885e+000,-3.206885e+000,-7.727411e-001,-7.586985e-001,-3.208495e+000,-7.743514e-001,-7.603087e-001,-8.032974e-004,-8.032974e-004,,,,,,,,,,,,,,,,,,,,
1473330442.021,,0.000000e+000,1.500213e+001,1.500518e+001,1,0,4.870950e+000,-2.950682e+000,-2.950682e+000,-5.107608e-001,-5.000331e-001,-2.925814e+000,-4.858923e-001,-4.751647e-001,-7.391208e-004,-7.391208e-004,,,,,,,,,,,,,,,,,,,,
1473330454.485,,0.000000e+000,1.500579e+001,1.500396e+001,1,0,2.409919e+000,-5.691702e-002,-5.691702e-002,2.385028e+000,2.392591e+000,-2.560392e-002,2.416341e+000,2.423904e+000,-1.425723e-005,-1.425723e-005,,,,,,,,,,,,,,,,,,,,
1473330553.208,,0.000000e+000,1.499847e+001,1.499725e+001,1,0,1.752568e-001,-2.967162e+000,-2.967162e+000,-5.229720e-001,-5.182052e-001,-2.958232e+000,-5.140415e-001,-5.092747e-001,-7.432488e-004,-7.432488e-004,,,,,,,,,,,,,,,,,,,,
1473330567.423,,0.000000e+000,1.499664e+001,1.499481e+001,1,0,1.263943e+000,-3.090304e+000,-3.090304e+000,-6.447482e-001,-6.431730e-001,-3.115439e+000,-6.698827e-001,-6.683075e-001,-7.740949e-004,-7.740949e-004,,,,,,,,,,,,,,,,,,,,
1473330567.423,,0.000000e+000,1.499664e+001,1.499481e+001,1,0,3.975300e+000,-3.439131e+000,-3.439131e+000,-1.006964e+000,-9.919994e-001,-3.440817e+000,-1.008650e+000,-9.936860e-001,-8.614730e-004,-8.614730e-004,,,,,,,,,,,,,,,,,,,,
1473330580.439,,0.000000e+000,1.499542e+001,1.499542e+001,1,0,4.767411e+000,-3.038423e+000,-3.038423e+000,-6.006767e-001,-5.892143e-001,-3.012090e+000,-5.743443e-001,-5.628819e-001,-7.610990e-004,-7.610990e-004,,,,,,,,,,,,,,,,,,,,
1473330592.903,,0.000000e+000,1.499542e+001,1.499603e+001,1,0,2.188676e+000,-4.182562e-001,-4.182562e-001,2.021414e+000,2.029657e+000,-4.437076e-001,1.995962e+000,2.004206e+000,-1.047696e-004,-1.047696e-004,,,,,,,,,,,,,,,,,,,,
1473330657.160,,0.000000e+000,1.384332e+001,1.368033e+001,1,0,9.042073e-002,-2.918027e+000,-2.918027e+000,-4.567433e-001,-4.520133e-001,-2.911885e+000,-4.506011e-001,-4.458711e-001,-7.309410e-004,-7.309410e-004,,,,,,,,,,,,,,,,,,,,
1473330669.624,,0.000000e+000,1.357605e+001,1.337114e+001,1,0,1.474896e+000,-2.620777e+000,-2.620777e+000,-1.537848e-001,-1.524634e-001,-2.635292e+000,-1.683002e-001,-1.669788e-001,-6.564824e-004,-6.564824e-004,,,,,,,,,,,,,,,,,,,,
1473330669.624,,0.000000e+000,1.357605e+001,1.337114e+001,1,0,4.141178e+000,-3.542894e+000,-3.542894e+000,-1.089380e+000,-1.074580e+000,-3.541807e+000,-1.088293e+000,-1.073493e+000,-8.874647e-004,-8.874647e-004,,,,,,,,,,,,,,,,,,,,
1473330683.588,,0.000000e+000,1.332148e+001,1.307261e+001,1,0,4.637800e+000,-3.196051e+000,-3.196051e+000,-7.335235e-001,-7.223871e-001,-3.169368e+000,-7.068409e-001,-6.957045e-001,-8.005836e-004,-8.005836e-004,,,,,,,,,,,,,,,,,,,,
1473330696.585,,0.000000e+000,1.302505e+001,1.283249e+001,1,0,1.973648e+000,-1.035798e+000,-1.035798e+000,1.432410e+000,1.440340e+000,-1.100862e+000,1.367346e+000,1.375276e+000,-2.594586e-004,-2.594586e-004,,,,,,,,,,,,,,,,,,,,
1473330711.050,,0.000000e+000,1.273705e+001,1.254889e+001,1,0,3.316756e-002,-2.896359e+000,-2.896359e+000,-4.192462e-001,-4.148073e-001,-2.889123e+000,-4.120105e-001,-4.075716e-001,-7.255133e-004,-7.255133e-004,,,,,,,,,,,,,,,,,,,,
1473330723.764,,0.000000e+000,1.250126e+001,1.231845e+001,1,0,1.692001e+000,-2.004456e+000,-2.004456e+000,4.774403e-001,4.785194e-001,-2.017157e+000,4.647395e-001,4.658186e-001,-5.020991e-004,-5.020991e-004,,,,,,,,,,,,,,,,,,,,
1473330723.764,,0.000000e+000,1.250126e+001,1.231845e+001,1,0,4.299994e+000,-3.514359e+000,-3.514359e+000,-1.046223e+000,-1.031384e+000,-3.501754e+000,-1.033618e+000,-1.018779e+000,-8.803170e-004,-8.803170e-004,,,,,,,,,,,,,,,,,,,,
1473330735.989,,0.000000e+000,1.227187e+001,1.208830e+001,1,0,4.486473e+000,-3.366955e+000,-3.366955e+000,-8.890105e-001,-8.779247e-001,-3.346037e+000,-8.680931e-001,-8.570073e-001,-8.433934e-004,-8.433934e-004,,,,,,,,,,,,,,,,,,,,
1473330750.454,,0.000000e+000,1.199908e+001,1.181555e+001,1,0,1.766527e+000,-1.719260e+000,-1.719260e+000,7.622579e-001,7.698743e-001,-1.780974e+000,7.005442e-001,7.081606e-001,-4.306601e-004,-4.306601e-004,,,,,,,,,,,,,,,,,,,,
1473330763.668,,0.000000e+000,1.172668e+001,1.154740e+001,1,0,7.273752e-003,-2.896664e+000,-2.896664e+000,-4.063888e-001,-4.021816e-001,-2.886786e+000,-3.965104e-001,-3.923032e-001,-7.255898e-004,-7.255898e-004,,,,,,,,,,,,,,,,,,,,
1473330776.883,,0.000000e+000,1.145815e+001,1.132368e+001,1,0,1.914062e+000,-1.308939e+000,-1.308939e+000,1.185033e+000,1.185848e+000,-1.311493e+000,1.182479e+000,1.183293e+000,-3.278780e-004,-3.278780e-004,,,,,,,,,,,,,,,,,,,,
1473330776.883,,0.000000e+000,1.145815e+001,1.132368e+001,1,0,4.450716e+000,-3.415021e+000,-3.415021e+000,-9.348900e-001,-9.202347e-001,-3.387727e+000,-9.075954e-001,-8.929400e-001,-8.554338e-004,-8.554338e-004,,,,,,,,,,,,,,,,,,,,
1473330789.407,,0.000000e+000,1.123635e+001,1.105961e+001,1,0,4.317483e+000,-3.522141e+000,-3.522141e+000,-1.034475e+000,-1.023635e+000,-3.514915e+000,-1.027249e+000,-1.016408e+000,-8.822664e-004,-8.822664e-004,,,,,,,,,,,,,,,,,,,,
1473330804.378,,0.000000e+000,1.097112e+001,1.079440e+001,1,0,1.568260e+000,-2.358623e+000,-2.358623e+000,1.376847e-001,1.451216e-001,-2.402102e+000,9.420571e-002,1.016426e-001,-5.908150e-004,-5.908150e-004,,,,,,,,,,,,,,,,,,,,
1473330818.843,,0.000000e+000,1.070654e+001,1.053129e+001,1,0,1.466596e-002,-2.918180e+000,-2.918180e+000,-4.156918e-001,-4.117606e-001,-2.905851e+000,-4.033629e-001,-3.994317e-001,-7.309792e-004,-7.309792e-004,,,,,,,,,,,,,,,,,,,,
1473330832.057,,0.000000e+000,1.048800e+001,1.031248e+001,1,0,2.139356e+000,-6.266976e-001,-6.266976e-001,1.882521e+000,1.883041e+000,-6.023325e-001,1.906886e+000,1.907406e+000,-1.569824e-004,-1.569824e-004,,,,,,,,,,,,,,,,,,,,
1473330832.057,,0.000000e+000,1.048800e+001,1.031248e+001,1,0,4.591048e+000,-3.298898e+000,-3.298898e+000,-8.029377e-001,-7.891593e-001,-3.261189e+000,-7.652287e-001,-7.514503e-001,-8.263459e-004,-8.263459e-004,,,,,,,,,,,,,,,,,,,,
1473330845.271,,0.000000e+000,1.022730e+001,1.005557e+001,1,0,4.134436e+000,-3.596759e+000,-3.596759e+000,-1.097959e+000,-1.087409e+000,-3.604979e+000,-1.106179e+000,-1.095630e+000,-9.009575e-004,-9.009575e-004,,,,,,,,,,,,,,,,,,,,
1473330859.744,,0.000000e+000,1.001261e+001,9.802570e+000,1,0,1.379123e+000,-2.903073e+000,-2.903073e+000,-3.955960e-001,-3.884594e-001,-2.929937e+000,-4.224593e-001,-4.153228e-001,-7.271951e-004,-7.271951e-004,,,,,,,,,,,,,,,,,,,,
1473330872.215,,0.000000e+000,9.761309e+000,9.594761e+000,1,0,5.599497e-002,-2.959380e+000,-2.959380e+000,-4.456568e-001,-4.419787e-001,-2.947643e+000,-4.339199e-001,-4.302418e-001,-7.412995e-004,-7.412995e-004,,,,,,,,,,,,,,,,,,,,
1473330886.236,,0.000000e+000,9.513113e+000,9.349735e+000,1,0,2.365744e+000,-1.371807e-001,-1.371807e-001,2.382210e+000,2.382474e+000,-8.690464e-002,2.432487e+000,2.432750e+000,-3.436260e-005,-3.436260e-005,,,,,,,,,,,,,,,,,,,,
1473330886.236,,0.000000e+000,9.513113e+000,9.349735e+000,1,0,4.717414e+000,-3.180639e+000,-3.180639e+000,-6.746973e-001,-6.609840e-001,-3.144507e+000,-6.385652e-001,-6.248519e-001,-7.967230e-004,-7.967230e-004,,,,,,,,,,,,,,,,,,,,
1473330898.451,,0.000000e+000,9.310030e+000,9.149738e+000,1,0,3.940213e+000,-3.498642e+000,-3.498642e+000,-9.898055e-001,-9.795887e-001,-3.511830e+000,-1.002994e+000,-9.927769e-001,-8.763800e-004,-8.763800e-004,,,,,,,,,,,,,,,,,,,,
1473330909.916,,0.000000e+000,9.111300e+000,8.956158e+000,1,0,1.198426e+000,-3.305155e+000,-3.305155e+000,-7.928470e-001,-7.859750e-001,-3.329539e+000,-8.172317e-001,-8.103597e-001,-8.279131e-004,-8.279131e-004,,,,,,,,,,,,,,,,,,,,
1473330924.129,,0.000000e+000,8.917618e+000,8.725960e+000,1,0,1.298009e-001,-3.023316e+000,-3.023316e+000,-5.024147e-001,-4.989431e-001,-3.012987e+000,-4.920852e-001,-4.886136e-001,-7.573150e-004,-7.573150e-004,,,,,,,,,,,,,,,,,,,,
1473330938.844,,0.000000e+000,8.650141e+000,8.502211e+000,1,0,2.590829e+000,-4.196295e-002,-4.196295e-002,2.481018e+000,2.481018e+000,-1.971210e-002,2.503269e+000,2.503269e+000,-1.051136e-005,-1.051136e-005,,,,,,,,,,,,,,,,,,,,
1473330938.844,,0.000000e+000,8.650141e+000,8.502211e+000,1,0,4.825459e+000,-3.073519e+000,-3.073519e+000,-5.640548e-001,-5.505381e-001,-3.049171e+000,-5.397068e-001,-5.261900e-001,-7.698904e-004,-7.698904e-004,,,,,,,,,,,,,,,,,,,,
1473330951.558,,0.000000e+000,8.465441e+000,8.321210e+000,1,0,3.736841e+000,-3.177282e+000,-3.177282e+000,-6.620066e-001,-6.518979e-001,-3.183993e+000,-6.687178e-001,-6.586092e-001,-7.958821e-004,-7.958821e-004,,,,,,,,,,,,,,,,,,,,
1473330964.772,,0.000000e+000,8.286039e+000,8.143097e+000,1,0,1.025512e+000,-3.546556e+000,-3.546556e+000,-1.025223e+000,-1.018621e+000,-3.572634e+000,-1.051302e+000,-1.044699e+000,-8.883821e-004,-8.883821e-004,,,,,,,,,,,,,,,,,,,,
1473330990.492,,0.000000e+000,7.932780e+000,7.768413e+000,1,0,2.333464e-001,-3.123722e+000,-3.123722e+000,-5.948104e-001,-5.917068e-001,-3.112621e+000,-5.837091e-001,-5.806055e-001,-7.824658e-004,-7.824658e-004,,,,,,,,,,,,,,,,,,,,
1473330990.492,,0.000000e+000,7.932780e+000,7.768413e+000,1,0,2.811976e+000,-3.979614e-001,-3.979614e-001,2.117760e+000,2.134054e+000,-4.226827e-001,2.093039e+000,2.109333e+000,-9.968593e-005,-9.968593e-005,,,,,,,,,,,,,,,,,,,,
1473331002.136,,0.000000e+000,7.768413e+000,7.647978e+000,1,0,4.910326e+000,-3.008209e+000,-3.008209e+000,-4.904748e-001,-4.772296e-001,-2.988491e+000,-4.707559e-001,-4.575107e-001,-7.535309e-004,-7.535309e-004,,,,,,,,,,,,,,,,,,,,
1473331014.958,,0.000000e+000,7.618799e+000,7.532216e+000,1,0,3.525944e+000,-2.661977e+000,-2.661977e+000,-1.383860e-001,-1.289046e-001,-2.666444e+000,-1.428528e-001,-1.333714e-001,-6.668026e-004,-6.668026e-004,,,,,,,,,,,,,,,,,,,,
1473331027.173,,0.000000e+000,7.506590e+000,7.373527e+000,1,0,8.595745e-001,-3.618274e+000,-3.618274e+000,-1.092242e+000,-1.085967e+000,-3.641216e+000,-1.115184e+000,-1.108909e+000,-9.063469e-004,-9.063469e-004,,,,,,,,,,,,,,,,,,,,
1473331083.141,,0.000000e+000,6.984797e+000,6.879928e+000,1,0,3.629524e-001,-3.256630e+000,-3.256630e+000,-7.221571e-001,-7.192898e-001,-3.247781e+000,-7.133074e-001,-7.104402e-001,-8.157581e-004,-8.157581e-004,,,,,,,,,,,,,,,,,,,,
1473331083.141,,0.000000e+000,6.984797e+000,6.879928e+000,1,0,3.027093e+000,-1.024049e+000,-1.024049e+000,1.497131e+000,1.513292e+000,-1.086386e+000,1.434794e+000,1.450955e+000,-2.565155e-004,-2.565155e-004,,,,,,,,,,,,,,,,,,,,
1473331096.355,,0.000000e+000,6.859001e+000,6.777765e+000,1,0,4.967543e+000,-2.971129e+000,-2.971129e+000,-4.479912e-001,-4.350629e-001,-2.951854e+000,-4.287155e-001,-4.157872e-001,-7.442426e-004,-7.442426e-004,,,,,,,,,,,,,,,,,,,,
1473331108.320,,0.000000e+000,6.756650e+000,6.690205e+000,1,0,3.308739e+000,-2.011780e+000,-2.011780e+000,5.171777e-001,5.265465e-001,-2.020874e+000,5.080837e-001,5.174525e-001,-5.039338e-004,-5.039338e-004,,,,,,,,,,,,,,,,,,,,
1473331120.034,,0.000000e+000,6.667304e+000,6.582347e+000,1,0,7.007744e-001,-3.569750e+000,-3.569750e+000,-1.038181e+000,-1.032181e+000,-3.579645e+000,-1.048076e+000,-1.042076e+000,-8.941920e-004,-8.941920e-004,,,,,,,,,,,,,,,,,,,,
1473331176.753,,0.000000e+000,5.950511e+000,5.821199e+000,1,0,5.142920e-001,-3.415632e+000,-3.415632e+000,-8.755251e-001,-8.729436e-001,-3.415883e+000,-8.757764e-001,-8.731949e-001,-8.555867e-004,-8.555867e-004,,,,,,,,,,,,,,,,,,,,
1473331176.753,,0.000000e+000,5.950511e+000,5.821199e+000,1,0,3.234214e+000,-1.719565e+000,-1.719565e+000,8.073759e-001,8.231225e-001,-1.777976e+000,7.489650e-001,7.647116e-001,-4.307365e-004,-4.307365e-004,,,,,,,,,,,,,,,,,,,,
1473331189.015,,0.000000e+000,5.791629e+000,5.663876e+000,1,0,4.993509e+000,-2.963805e+000,-2.963805e+000,-4.343413e-001,-4.215958e-001,-2.940816e+000,-4.113525e-001,-3.986070e-001,-7.424079e-004,-7.424079e-004,,,,,,,,,,,,,,,,,,,,
1473331201.231,,0.000000e+000,5.633780e+000,5.504942e+000,1,0,3.086668e+000,-1.287576e+000,-1.287576e+000,1.246546e+000,1.256057e+000,-1.294687e+000,1.239435e+000,1.248946e+000,-3.225268e-004,-3.225268e-004,,,,,,,,,,,,,,,,,,,,
1473331213.695,,0.000000e+000,5.475521e+000,5.324112e+000,1,0,5.500047e-001,-3.459883e+000,-3.459883e+000,-9.194148e-001,-9.133866e-001,-3.454190e+000,-9.137209e-001,-9.076927e-001,-8.666713e-004,-8.666713e-004,,,,,,,,,,,,,,,,,,,,
1473331337.174,,0.000000e+000,4.997944e+000,5.006858e+000,1,0,6.833194e-001,-3.567766e+000,-3.567766e+000,-1.022927e+000,-1.020534e+000,-3.582739e+000,-1.037899e+000,-1.035506e+000,-8.936951e-004,-8.936951e-004,,,,,,,,,,,,,,,,,,,,
1473331337.174,,0.000000e+000,4.997944e+000,5.006858e+000,1,0,3.432524e+000,-2.374798e+000,-2.374798e+000,1.564796e-001,1.724350e-001,-2.404408e+000,1.268699e-001,1.428254e-001,-5.948666e-004,-5.948666e-004,,,,,,,,,,,,,,,,,,,,
1473331349.888,,0.000000e+000,5.013443e+000,5.022546e+000,1,0,4.986057e+000,-2.976012e+000,-2.976012e+000,-4.418532e-001,-4.291980e-001,-2.951212e+000,-4.170526e-001,-4.043975e-001,-7.454658e-004,-7.454658e-004,,,,,,,,,,,,,,,,,,,,
1473331363.400,,0.000000e+000,5.024171e+000,5.030808e+000,1,0,2.861389e+000,-5.899228e-001,-5.899228e-001,1.947123e+000,1.956288e+000,-5.710284e-001,1.966018e+000,1.975182e+000,-1.477706e-004,-1.477706e-004,,,,,,,,,,,,,,,,,,,,
1473331375.614,,0.000000e+000,5.030808e+000,5.037592e+000,1,0,4.096965e-001,-3.322855e+000,-3.322855e+000,-7.823708e-001,-7.766838e-001,-3.305878e+000,-7.653935e-001,-7.597065e-001,-8.323470e-004,-8.323470e-004,,,,,,,,,,,,,,,,,,,,
1473331375.614,,0.000000e+000,5.030808e+000,5.037592e+000,1,0,2.812050e+000,-3.988769e-001,-3.988769e-001,2.130234e+000,2.147295e+000,-4.239320e-001,2.105178e+000,2.122239e+000,-9.991528e-005,-9.991528e-005,,,,,,,,,,,,,,,,,,,,