File: data/A344/A344_GdN_MH_065K_160905.rso.dat
[Header]
TITLE,MPMS RSO Measurement
BYAPP,MPMS Measurement,1.1,Summary
FILEOPENTIME, 1473207970.408000 9/7/2016, 12:26:10 PM

INFO, APPNAME, MPMS MultiVu Application, Revision 1.61,  Build 082

INFO, NAME, A344
INFO, WEIGHT, 10.500
INFO, AREA, 1.000
INFO, LENGTH, 1.000
INFO, SHAPE, 0
INFO, COMMENT, m = 0.0105g
INFO, SEQUENCE FILE: 7T_hysteresis_sweep_hi_res_zero_n4.seq


INFO, BACKGROUND DATA FILE:, None


STARTUPAXIS,X,4,LINEAR,AUTO,0.000000,0.000000
STARTUPAXIS,Y1,5,LINEAR,AUTO,0.000000,0.000000


STARTUPGROUP,Longitudinal
FIELDGROUP,Longitudinal,1,2,3,4,5,6,7,8,9,10,11,19,20,21,22,23,35
FIELDGROUP,Transverse,1,2,3,4,12,13,14,15,16,17,18,24,25,26,27,28,35

PLOT_APPEARANCE,ALL,HORZ_GRID_ON,VERT_GRID_ON,MARKERS_AND_LINES

[Data]
Time,Comment,Field (Oe),Temperature (K),Long Moment (emu),Long Scan Std Dev,Long Offset (cm),Long Offset Std Dev,Long Algorithm,Long Reg Fit,Long Reg Factor,Trans Moment (emu),Trans Scan Std Dev,Trans Offset (cm),Trans Offset Std Dev,Trans Algorithm,Trans Reg Fit,Trans Reg Factor,Long Moment [w/o ABS] (emu),Long Scan Std Dev [w/o ABS],Long Offset [w/o ABS] (cm),Long Offset Std Dev [w/o ABS],Long Reg Fit [w/o ABS],Trans Moment [w/o ABS] (emu),Trans Scan Std Dev [w/o ABS],Trans Offset [w/o ABS] (cm),Trans Offset Std Dev [w/o ABS],Trans Reg Fit [w/o ABS],RSO Position (deg),Amplitude (cm),Frequency,Cycles to Average,Scans per Measurement,Delta Temp (K),Error,EC Comp. Running,Using ABS,
1473207970.390,,7.000000e+004,6.511670e+001,8.051596e-004,0.000000e+000,1.877518e-002,0.000000e+000,3,9.335524e-001,1.825000e+000,,,,,,,,,,,,,,,,,,0,5.000000e+000,5.000000e-001,2,1,1.027679e-002,0,1,0,
1473207994.813,,7.000000e+004,6.508278e+001,8.076628e-004,0.000000e+000,1.621431e-002,0.000000e+000,3,9.365619e-001,1.825000e+000,,,,,,,,,,,,,,,,,,0,5.000000e+000,5.000000e-001,2,1,2.056122e-002,0,1,0,
1473208177.427,,6.000000e+004,6.500682e+001,7.918032e-004,0.000000e+000,1.762882e-002,0.000000e+000,3,9.310101e-001,1.825000e+000,,,,,,,,,,,,,,,,,,0,5.000000e+000,5.000000e-001,2,1,4.112244e-003,0,1,0,
1473208205.659,,6.000000e+004,6.499759e+001,7.924283e-004,0.000000e+000,1.381264e-002,0.000000e+000,3,9.296206e-001,1.825000e+000,,,,,,,,,,,,,,,,,,0,5.000000e+000,5.000000e-001,2,1,2.052307e-003,0,1,0,
1473208378.883,,5.000000e+004,6.499657e+001,7.696551e-004,0.000000e+000,1.585888e-002,0.000000e+000,3,9.302241e-001,1.825000e+000,,,,,,,,,,,,,,,,,,0,5.000000e+000,5.000000e-001,2,1,4.089355e-003,0,0,0,
1473208405.561,,5.000000e+004,6.499350e+001,7.702065e-004,0.000000e+000,1.454617e-002,0.000000e+000,3,9.267142e-001,1.825000e+000,,,,,,,,,,,,,,,,,,0,5.000000e+000,5.000000e-001,2,1,6.134033e-003,0,0,0,
1473208585.759,,4.000000e+004,6.499350e+001,7.376029e-004,0.000000e+000,1.354400e-002,0.000000e+000,3,9.284933e-001,1.825000e+000,,,,,,,,,,,,,,,,,,0,5.000000e+000,5.000000e-001,2,1,2.052307e-003,0,0,0,
1473208610.957,,4.000000e+004,6.500683e+001,7.404051e-004,0.000000e+000,1.297929e-002,0.000000e+000,3,9.303504e-001,1.825000e+000,,,,,,,,,,,,,,,,,,0,5.000000e+000,5.000000e-001,2,1,8.209229e-003,0,0,0,
1473208788.331,,3.000000e+004,6.499965e+001,7.041115e-004,0.000000e+000,1.211085e-002,0.000000e+000,3,9.271703e-001,1.825000e+000,,,,,,,,,,,,,,,,,,0,5.000000e+000,5.000000e-001,2,1,2.059937e-003,0,0,0,
1473208814.621,,3.000000e+004,6.500067e+001,7.020474e-004,0.000000e+000,1.152446e-002,0.000000e+000,3,9.270701e-001,1.825000e+000,,,,,,,,,,,,,,,,,,0,5.000000e+000,5.000000e-001,2,1,4.104614e-003,0,0,0,
1473208990.321,,2.000000e+004,6.499657e+001,6.486674e-004,0.000000e+000,1.007422e-002,0.000000e+000,3,9.225362e-001,1.825000e+000,,,,,,,,,,,,,,,,,,0,5.000000e+000,5.000000e-001,2,1,0.000000e+000,0,0,0,
1473209016.288,,2.000000e+004,6.500170e+001,6.486319e-004,0.000000e+000,1.009589e-002,0.000000e+000,3,9.225984e-001,1.825000e+000,,,,,,,,,,,,,,,,,,0,5.000000e+000,5.000000e-001,2,1,2.044678e-003,0,0,0,
1473209183.984,,1.000000e+004,6.499554e+001,5.616971e-004,0.000000e+000,7.823550e-003,0.000000e+000,3,9.126822e-001,1.825000e+000,,,,,,,,,,,,,,,,,,0,5.000000e+000,5.000000e-001,2,1,2.037048e-003,0,1,0,
1473209209.913,,1.000000e+004,6.499657e+001,5.618220e-004,0.000000e+000,7.684956e-003,0.000000e+000,3,9.130831e-001,1.825000e+000,,,,,,,,,,,,,,,,,,0,5.000000e+000,5.000000e-001,2,1,0.000000e+000,0,1,0,
1473209348.603,,9.000000e+003,6.500376e+001,5.486428e-004,0.000000e+000,7.996641e-003,0.000000e+000,3,9.112087e-001,1.825000e+000,,,,,,,,,,,,,,,,,,0,5.000000e+000,5.000000e-001,2,1,6.164551e-003,0,1,0,
1473209373.304,,9.000000e+003,6.500375e+001,5.486679e-004,0.000000e+000,7.873263e-003,0.000000e+000,3,9.110676e-001,1.825000e+000,,,,,,,,,,,,,,,,,,0,5.000000e+000,5.000000e-001,2,1,2.044678e-003,0,1,0,
1473209512.247,,7.000000e+003,6.500786e+001,5.197691e-004,0.000000e+000,7.358816e-003,0.000000e+000,3,9.076211e-001,1.825000e+000,,,,,,,,,,,,,,,,,,0,5.000000e+000,5.000000e-001,2,1,2.037048e-003,0,1,0,
1473209536.726,,7.000000e+003,6.500169e+001,5.197260e-004,0.000000e+000,6.966282e-003,0.000000e+000,3,9.073491e-001,1.825000e+000,,,,,,,,,,,,,,,,,,0,5.000000e+000,5.000000e-001,2,1,6.149292e-003,0,1,0,
1473209672.674,,5.000000e+003,6.500682e+001,4.823051e-004,0.000000e+000,6.516920e-003,0.000000e+000,3,9.028646e-001,1.825000e+000,,,,,,,,,,,,,,,,,,0,5.000000e+000,5.000000e-001,2,1,4.112244e-003,0,1,0,
1473209698.103,,5.000000e+003,6.499965e+001,4.830715e-004,0.000000e+000,5.069405e-003,0.000000e+000,3,9.021758e-001,1.825000e+000,,,,,,,,,,,,,,,,,,0,5.000000e+000,5.000000e-001,2,1,2.059937e-003,0,1,0,
1473209836.555,,3.000000e+003,6.499863e+001,4.324315e-004,0.000000e+000,4.450628e-003,0.000000e+000,3,8.958237e-001,1.825000e+000,,,,,,,,,,,,,,,,,,0,5.000000e+000,5.000000e-001,2,1,4.112244e-003,0,1,0,
1473209862.243,,3.000000e+003,6.500067e+001,4.326596e-004,0.000000e+000,5.882980e-003,0.000000e+000,3,8.959444e-001,1.825000e+000,,,,,,,,,,,,,,,,,,0,5.000000e+000,5.000000e-001,2,1,8.201599e-003,0,0,0,
1473210003.933,,1.000000e+003,6.499657e+001,3.498966e-004,0.000000e+000,8.716806e-003,0.000000e+000,3,8.990988e-001,1.825000e+000,,,,,,,,,,,,,,,,,,0,5.000000e+000,5.000000e-001,2,1,4.089355e-003,0,0,0,
1473210028.880,,1.000000e+003,6.499760e+001,3.503981e-004,0.000000e+000,6.961522e-003,0.000000e+000,3,9.028136e-001,1.825000e+000,,,,,,,,,,,,,,,,,,0,5.000000e+000,5.000000e-001,2,1,6.149292e-003,0,0,0,
1473210170.320,,7.000000e+002,6.499555e+001,3.323031e-004,0.000000e+000,8.689634e-003,0.000000e+000,3,9.096721e-001,1.825000e+000,,,,,,,,,,,,,,,,,,0,5.000000e+000,5.000000e-001,2,1,1.434326e-002,0,0,0,
1473210195.538,,7.000000e+002,6.499965e+001,3.307871e-004,0.000000e+000,8.941534e-003,0.000000e+000,3,9.105616e-001,1.825000e+000,,,,,,,,,,,,,,,,,,0,5.000000e+000,5.000000e-001,2,1,2.059937e-003,0,0,0,
1473210325.493,,6.000000e+002,6.500273e+001,3.234027e-004,0.000000e+000,8.030240e-003,0.000000e+000,3,9.157558e-001,1.825000e+000,,,,,,,,,,,,,,,,,,0,5.000000e+000,5.000000e-001,2,1,8.224487e-003,0,0,0,
1473210351.468,,6.000000e+002,6.499554e+001,3.226463e-004,0.000000e+000,8.723532e-003,0.000000e+000,3,9.153255e-001,1.825000e+000,,,,,,,,,,,,,,,,,,0,5.000000e+000,5.000000e-001,2,1,2.037048e-003,0,0,0,
1473210486.428,,5.000000e+002,6.499554e+001,3.128954e-004,0.000000e+000,1.058259e-002,0.000000e+000,3,9.195847e-001,1.825000e+000,,,,,,,,,,,,,,,,,,0,5.000000e+000,5.000000e-001,2,1,2.037048e-003,0,0,0,
1473210510.358,,5.000000e+002,6.500069e+001,3.142984e-004,0.000000e+000,1.015574e-002,0.000000e+000,3,9.216130e-001,1.825000e+000,,,,,,,,,,,,,,,,,,0,5.000000e+000,5.000000e-001,2,1,1.231384e-002,0,0,0,
1473210642.550,,4.000000e+002,6.499760e+001,3.038625e-004,0.000000e+000,7.754392e-003,0.000000e+000,3,9.288302e-001,1.825000e+000,,,,,,,,,,,,,,,,,,0,5.000000e+000,5.000000e-001,2,1,1.024628e-002,0,0,0,
1473210670.729,,4.000000e+002,6.500375e+001,3.030617e-004,0.000000e+000,1.167331e-002,0.000000e+000,3,9.269216e-001,1.825000e+000,,,,,,,,,,,,,,,,,,0,5.000000e+000,5.000000e-001,2,1,2.044678e-003,0,0,0,
1473210806.119,,3.000000e+002,6.499248e+001,2.885433e-004,0.000000e+000,1.155514e-002,0.000000e+000,3,9.378479e-001,1.825000e+000,,,,,,,,,,,,,,,,,,0,5.000000e+000,5.000000e-001,2,1,8.186340e-003,0,1,0,
1473210840.661,,3.000000e+002,6.499862e+001,2.898639e-004,0.000000e+000,1.223798e-002,0.000000e+000,3,9.377692e-001,1.825000e+000,,,,,,,,,,,,,,,,,,0,5.000000e+000,5.000000e-001,2,1,0.000000e+000,0,1,0,
1473210972.110,,2.000000e+002,6.500067e+001,2.708072e-004,0.000000e+000,1.235241e-002,0.000000e+000,3,9.501281e-001,1.825000e+000,,,,,,,,,,,,,,,,,,0,5.000000e+000,5.000000e-001,2,1,4.104614e-003,0,1,0,
1473210996.577,,2.000000e+002,6.500068e+001,2.708693e-004,0.000000e+000,1.184175e-002,0.000000e+000,3,9.481648e-001,1.825000e+000,,,,,,,,,,,,,,,,,,0,5.000000e+000,5.000000e-001,2,1,0.000000e+000,0,1,0,
1473211119.058,,1.800000e+002,6.500376e+001,2.648488e-004,0.000000e+000,1.295110e-002,0.000000e+000,3,9.512786e-001,1.825000e+000,,,,,,,,,,,,,,,,,,0,5.000000e+000,5.000000e-001,2,1,6.164551e-003,0,1,0,
1473211144.790,,1.800000e+002,6.500478e+001,2.648221e-004,0.000000e+000,1.349405e-002,0.000000e+000,3,9.515907e-001,1.825000e+000,,,,,,,,,,,,,,,,,,0,5.000000e+000,5.000000e-001,2,1,4.119873e-003,0,1,0,
1473211265.484,,1.600000e+002,6.500786e+001,2.592843e-004,0.000000e+000,1.437897e-002,0.000000e+000,3,9.540102e-001,1.825000e+000,,,,,,,,,,,,,,,,,,0,5.000000e+000,5.000000e-001,2,1,2.664948e-002,0,1,0,
1473211292.413,,1.600000e+002,6.500067e+001,2.590454e-004,0.000000e+000,1.416257e-002,0.000000e+000,3,9.540285e-001,1.825000e+000,,,,,,,,,,,,,,,,,,0,5.000000e+000,5.000000e-001,2,1,4.104614e-003,0,1,0,
1473211416.101,,1.400000e+002,6.499862e+001,2.515159e-004,0.000000e+000,1.593994e-002,0.000000e+000,3,9.547564e-001,1.825000e+000,,,,,,,,,,,,,,,,,,0,5.000000e+000,5.000000e-001,2,1,0.000000e+000,0,0,0,
1473211443.800,,1.400000e+002,6.499657e+001,2.527609e-004,0.000000e+000,1.587431e-002,0.000000e+000,3,9.570884e-001,1.825000e+000,,,,,,,,,,,,,,,,,,0,5.000000e+000,5.000000e-001,2,1,4.089355e-003,0,0,0,
1473211565.044,,1.200000e+002,6.500682e+001,2.435696e-004,0.000000e+000,1.200058e-002,0.000000e+000,3,9.606873e-001,1.825000e+000,,,,,,,,,,,,,,,,,,0,5.000000e+000,5.000000e-001,2,1,1.640320e-002,0,0,0,
1473211592.473,,1.200000e+002,6.499453e+001,2.443014e-004,0.000000e+000,1.442055e-002,0.000000e+000,3,9.585027e-001,1.825000e+000,,,,,,,,,,,,,,,,,,0,5.000000e+000,5.000000e-001,2,1,0.000000e+000,0,0,0,
1473211723.699,,1.000000e+002,6.499759e+001,2.337311e-004,0.000000e+000,1.576035e-002,0.000000e+000,3,9.615778e-001,1.825000e+000,,,,,,,,,,,,,,,,,,0,5.000000e+000,5.000000e-001,2,1,2.052307e-003,0,0,0,
1473211753.128,,1.000000e+002,6.499965e+001,2.337363e-004,0.000000e+000,1.489093e-002,0.000000e+000,3,9.632060e-001,1.825000e+000,,,,,,,,,,,,,,,,,,0,5.000000e+000,5.000000e-001,2,1,6.156921e-003,0,0,0,
1473211875.321,,8.000000e+001,6.500067e+001,2.210049e-004,0.000000e+000,1.377367e-002,0.000000e+000,3,9.643618e-001,1.825000e+000,,,,,,,,,,,,,,,,,,0,5.000000e+000,5.000000e-001,2,1,4.104614e-003,0,0,0,
1473211901.549,,8.000000e+001,6.499759e+001,2.218963e-004,0.000000e+000,1.329103e-002,0.000000e+000,3,9.674604e-001,1.825000e+000,,,,,,,,,,,,,,,,,,0,5.000000e+000,5.000000e-001,2,1,2.052307e-003,0,0,0,
1473212028.668,,6.000000e+001,6.499146e+001,2.018859e-004,0.000000e+000,1.638445e-002,0.000000e+000,3,9.687598e-001,1.825000e+000,,,,,,,,,,,,,,,,,,0,5.000000e+000,5.000000e-001,2,1,6.149292e-003,0,0,0,
1473212054.954,,6.000000e+001,6.499863e+001,2.019336e-004,0.000000e+000,1.607158e-002,0.000000e+000,3,9.697821e-001,1.825000e+000,,,,,,,,,,,,,,,,,,0,5.000000e+000,5.000000e-001,2,1,4.112244e-003,0,0,0,
1473212182.154,,4.000000e+001,6.498940e+001,1.726942e-004,0.000000e+000,1.633500e-002,0.000000e+000,3,9.697715e-001,1.825000e+000,,,,,,,,,,,,,,,,,,0,5.000000e+000,5.000000e-001,2,1,1.433563e-002,0,0,0,
1473212210.366,,4.000000e+001,6.500273e+001,1.730399e-004,0.000000e+000,1.396223e-002,0.000000e+000,3,9.733044e-001,1.825000e+000,,,,,,,,,,,,,,,,,,0,5.000000e+000,5.000000e-001,2,1,8.224487e-003,0,0,0,
1473212334.361,,2.000000e+001,6.500990e+001,1.071493e-004,0.000000e+000,1.123998e-002,0.000000e+000,3,9.818591e-001,1.825000e+000,,,,,,,,,,,,,,,,,,0,5.000000e+000,5.000000e-001,2,1,1.844788e-002,0,1,0,
1473212359.540,,2.000000e+001,6.500169e+001,1.085507e-004,0.000000e+000,1.127147e-002,0.000000e+000,3,9.802833e-001,1.825000e+000,,,,,,,,,,,,,,,,,,0,5.000000e+000,5.000000e-001,2,1,6.149292e-003,0,1,0,
1473212479.284,,0.000000e+000,6.500272e+001,-1.236314e-004,0.000000e+000,2.371955e-002,0.000000e+000,3,9.820008e-001,1.825000e+000,,,,,,,,,,,,,,,,,,0,5.000000e+000,5.000000e-001,2,1,0.000000e+000,0,1,0,
1473212503.215,,0.000000e+000,6.500169e+001,-1.243206e-004,0.000000e+000,2.016575e-002,0.000000e+000,3,9.792590e-001,1.825000e+000,,,,,,,,,,,,,,,,,,0,5.000000e+000,5.000000e-001,2,1,6.149292e-003,0,1,0,
1473212625.971,,-2.000000e+001,6.500067e+001,-1.812206e-004,0.000000e+000,1.919083e-002,0.000000e+000,3,9.777591e-001,1.825000e+000,,,,,,,,,,,,,,,,,,0,5.000000e+000,5.000000e-001,2,1,4.104614e-003,0,1,0,
1473212652.841,,-2.000000e+001,6.500273e+001,-1.810845e-004,0.000000e+000,1.770534e-002,0.000000e+000,3,9.790290e-001,1.825000e+000,,,,,,,,,,,,,,,,,,0,5.000000e+000,5.000000e-001,2,1,8.224487e-003,0,1,0,
1473212771.643,,-4.000000e+001,6.500170e+001,-2.081819e-004,0.000000e+000,1.628433e-002,0.000000e+000,3,9.736739e-001,1.825000e+000,,,,,,,,,,,,,,,,,,0,5.000000e+000,5.000000e-001,2,1,2.044678e-003,0,1,0,
1473212796.571,,-4.000000e+001,6.500376e+001,-2.075543e-004,0.000000e+000,1.827276e-002,0.000000e+000,3,9.752529e-001,1.825000e+000,,,,,,,,,,,,,,,,,,0,5.000000e+000,5.000000e-001,2,1,6.164551e-003,0,1,0,
1473212923.777,,-6.000000e+001,6.500272e+001,-2.258257e-004,0.000000e+000,1.643211e-002,0.000000e+000,3,9.701205e-001,1.825000e+000,,,,,,,,,,,,,,,,,,0,5.000000e+000,5.000000e-001,2,1,4.089355e-003,0,1,0,
1473212952.706,,-6.000000e+001,6.500170e+001,-2.255293e-004,0.000000e+000,1.681261e-002,0.000000e+000,3,9.717338e-001,1.825000e+000,,,,,,,,,,,,,,,,,,0,5.000000e+000,5.000000e-001,2,1,2.044678e-003,0,0,0,
1473213074.988,,-8.000000e+001,6.499554e+001,-2.372018e-004,0.000000e+000,1.668148e-002,0.000000e+000,3,9.711643e-001,1.825000e+000,,,,,,,,,,,,,,,,,,0,5.000000e+000,5.000000e-001,2,1,2.037048e-003,0,0,0,
1473213102.917,,-8.000000e+001,6.498837e+001,-2.375983e-004,0.000000e+000,1.634279e-002,0.000000e+000,3,9.687714e-001,1.825000e+000,,,,,,,,,,,,,,,,,,0,5.000000e+000,5.000000e-001,2,1,1.638794e-002,0,0,0,
1473213225.355,,-1.000000e+002,6.498735e+001,-2.464834e-004,0.000000e+000,1.621009e-002,0.000000e+000,3,9.656332e-001,1.825000e+000,,,,,,,,,,,,,,,,,,0,5.000000e+000,5.000000e-001,2,1,1.844025e-002,0,0,0,
1473213254.987,,-1.000000e+002,6.500581e+001,-2.477465e-004,0.000000e+000,1.470729e-002,0.000000e+000,3,9.665155e-001,1.825000e+000,,,,,,,,,,,,,,,,,,0,5.000000e+000,5.000000e-001,2,1,2.255249e-002,0,0,0,
1473213376.344,,-1.200000e+002,6.499657e+001,-2.559978e-004,0.000000e+000,1.413655e-002,0.000000e+000,3,9.624758e-001,1.825000e+000,,,,,,,,,,,,,,,,,,0,5.000000e+000,5.000000e-001,2,1,4.089355e-003,0,0,0,
1473213402.523,,-1.200000e+002,6.499657e+001,-2.557230e-004,0.000000e+000,1.698501e-002,0.000000e+000,3,9.584419e-001,1.825000e+000,,,,,,,,,,,,,,,,,,0,5.000000e+000,5.000000e-001,2,1,4.089355e-003,0,0,0,
1473213525.500,,-1.400000e+002,6.499759e+001,-2.624486e-004,0.000000e+000,1.449181e-002,0.000000e+000,3,9.605031e-001,1.825000e+000,,,,,,,,,,,,,,,,,,0,5.000000e+000,5.000000e-001,2,1,2.052307e-003,0,0,0,
1473213552.468,,-1.400000e+002,6.499965e+001,-2.620645e-004,0.000000e+000,1.345487e-002,0.000000e+000,3,9.575152e-001,1.825000e+000,,,,,,,,,,,,,,,,,,0,5.000000e+000,5.000000e-001,2,1,6.156921e-003,0,0,0,
1473213677.411,,-1.600000e+002,6.499657e+001,-2.674175e-004,0.000000e+000,1.679793e-002,0.000000e+000,3,9.547602e-001,1.825000e+000,,,,,,,,,,,,,,,,,,0,5.000000e+000,5.000000e-001,2,1,4.089355e-003,0,0,0,
1473213706.840,,-1.600000e+002,6.499863e+001,-2.681662e-004,0.000000e+000,1.398832e-002,0.000000e+000,3,9.552636e-001,1.825000e+000,,,,,,,,,,,,,,,,,,0,5.000000e+000,5.000000e-001,2,1,4.112244e-003,0,0,0,
1473213835.029,,-1.800000e+002,6.499350e+001,-2.732710e-004,0.000000e+000,1.463094e-002,0.000000e+000,3,9.497749e-001,1.825000e+000,,,,,,,,,,,,,,,,,,0,5.000000e+000,5.000000e-001,2,1,2.052307e-003,0,1,0,
1473213860.504,,-1.800000e+002,6.499863e+001,-2.735479e-004,0.000000e+000,1.348840e-002,0.000000e+000,3,9.545883e-001,1.825000e+000,,,,,,,,,,,,,,,,,,0,5.000000e+000,5.000000e-001,2,1,8.193970e-003,0,1,0,
1473213986.197,,-2.000000e+002,6.499863e+001,-2.777865e-004,0.000000e+000,1.527914e-002,0.000000e+000,3,9.499452e-001,1.825000e+000,,,,,,,,,,,,,,,,,,0,5.000000e+000,5.000000e-001,2,1,4.112244e-003,0,1,0,
1473214012.126,,-2.000000e+002,6.500272e+001,-2.774275e-004,0.000000e+000,1.405846e-002,0.000000e+000,3,9.504480e-001,1.825000e+000,,,,,,,,,,,,,,,,,,0,5.000000e+000,5.000000e-001,2,1,4.089355e-003,0,1,0,
1473214137.357,,-3.000000e+002,6.500478e+001,-2.950245e-004,0.000000e+000,1.143117e-002,0.000000e+000,3,9.403672e-001,1.825000e+000,,,,,,,,,,,,,,,,,,0,5.000000e+000,5.000000e-001,2,1,4.119873e-003,0,1,0,
1473214162.278,,-3.000000e+002,6.499863e+001,-2.946796e-004,0.000000e+000,1.169687e-002,0.000000e+000,3,9.401988e-001,1.825000e+000,,,,,,,,,,,,,,,,,,0,5.000000e+000,5.000000e-001,2,1,8.193970e-003,0,1,0,
1473214297.131,,-4.000000e+002,6.500067e+001,-3.070179e-004,0.000000e+000,1.219777e-002,0.000000e+000,3,9.291644e-001,1.825000e+000,,,,,,,,,,,,,,,,,,0,5.000000e+000,5.000000e-001,2,1,8.201599e-003,0,1,0,
1473214325.310,,-4.000000e+002,6.499657e+001,-3.066555e-004,0.000000e+000,1.223673e-002,0.000000e+000,3,9.290563e-001,1.825000e+000,,,,,,,,,,,,,,,,,,0,5.000000e+000,5.000000e-001,2,1,4.089355e-003,0,1,0,
1473214456.296,,-5.000000e+002,6.499554e+001,-3.164590e-004,0.000000e+000,1.005625e-002,0.000000e+000,3,9.217793e-001,1.825000e+000,,,,,,,,,,,,,,,,,,0,5.000000e+000,5.000000e-001,2,1,6.141663e-003,0,1,0,
1473214497.770,,-5.000000e+002,6.499863e+001,-3.173664e-004,0.000000e+000,1.084490e-002,0.000000e+000,3,9.221954e-001,1.825000e+000,,,,,,,,,,,,,,,,,,0,5.000000e+000,5.000000e-001,2,1,8.193970e-003,0,0,0,
1473214624.714,,-6.000000e+002,6.499862e+001,-3.260489e-004,0.000000e+000,9.790896e-003,0.000000e+000,3,9.167472e-001,1.825000e+000,,,,,,,,,,,,,,,,,,0,5.000000e+000,5.000000e-001,2,1,0.000000e+000,0,0,0,
1473214649.643,,-6.000000e+002,6.499760e+001,-3.252379e-004,0.000000e+000,1.121778e-002,0.000000e+000,3,9.145780e-001,1.825000e+000,,,,,,,,,,,,,,,,,,0,5.000000e+000,5.000000e-001,2,1,6.149292e-003,0,0,0,
1473214784.280,,-7.000000e+002,6.499248e+001,-3.322286e-004,0.000000e+000,7.892751e-003,0.000000e+000,3,9.107618e-001,1.825000e+000,,,,,,,,,,,,,,,,,,0,5.000000e+000,5.000000e-001,2,1,8.186340e-003,0,0,0,
1473214809.880,,-7.000000e+002,6.499965e+001,-3.331523e-004,0.000000e+000,8.738169e-003,0.000000e+000,3,9.110887e-001,1.825000e+000,,,,,,,,,,,,,,,,,,0,5.000000e+000,5.000000e-001,2,1,2.059937e-003,0,0,0,
1473214938.321,,-1.000000e+003,6.499965e+001,-3.520251e-004,0.000000e+000,9.200071e-003,0.000000e+000,3,9.017703e-001,1.825000e+000,,,,,,,,,,,,,,,,,,0,5.000000e+000,5.000000e-001,2,1,6.156921e-003,0,0,0,
1473214965.880,,-1.000000e+003,6.499965e+001,-3.514781e-004,0.000000e+000,7.687789e-003,0.000000e+000,3,9.032665e-001,1.825000e+000,,,,,,,,,,,,,,,,,,0,5.000000e+000,5.000000e-001,2,1,2.059937e-003,0,0,0,
1473215101.570,,-3.000000e+003,6.499759e+001,-4.324864e-004,0.000000e+000,7.044381e-003,0.000000e+000,3,8.965755e-001,1.825000e+000,,,,,,,,,,,,,,,,,,0,5.000000e+000,5.000000e-001,2,1,2.052307e-003,0,0,0,
1473215127.505,,-3.000000e+003,6.499863e+001,-4.332044e-004,0.000000e+000,6.427673e-003,0.000000e+000,3,8.959753e-001,1.825000e+000,,,,,,,,,,,,,,,,,,0,5.000000e+000,5.000000e-001,2,1,8.193970e-003,0,0,0,
1473215263.053,,-5.000000e+003,6.499760e+001,-4.834477e-004,0.000000e+000,6.667444e-003,0.000000e+000,3,9.025477e-001,1.825000e+000,,,,,,,,,,,,,,,,,,0,5.000000e+000,5.000000e-001,2,1,6.149292e-003,0,0,0,
1473215287.060,,-5.000000e+003,6.499452e+001,-4.834553e-004,0.000000e+000,6.708317e-003,0.000000e+000,3,9.024132e-001,1.825000e+000,,,,,,,,,,,,,,,,,,0,5.000000e+000,5.000000e-001,2,1,2.048492e-002,0,0,0,
1473215424.781,,-7.000000e+003,6.500887e+001,-5.199739e-004,0.000000e+000,7.392902e-003,0.000000e+000,3,9.078114e-001,1.825000e+000,,,,,,,,,,,,,,,,,,0,5.000000e+000,5.000000e-001,2,1,2.461243e-002,0,1,0,
1473215449.763,,-7.000000e+003,6.499759e+001,-5.199580e-004,0.000000e+000,7.402983e-003,0.000000e+000,3,9.079826e-001,1.825000e+000,,,,,,,,,,,,,,,,,,0,5.000000e+000,5.000000e-001,2,1,2.052307e-003,0,1,0,
1473215586.702,,-9.000000e+003,6.499554e+001,-5.493138e-004,0.000000e+000,8.253375e-003,0.000000e+000,3,9.117871e-001,1.825000e+000,,,,,,,,,,,,,,,,,,0,5.000000e+000,5.000000e-001,2,1,2.037048e-003,0,1,0,
1473215613.675,,-9.000000e+003,6.500272e+001,-5.490487e-004,0.000000e+000,8.285617e-003,0.000000e+000,3,9.117052e-001,1.825000e+000,,,,,,,,,,,,,,,,,,0,5.000000e+000,5.000000e-001,2,1,4.089355e-003,0,1,0,
1473215749.121,,-1.000000e+004,6.500478e+001,-5.609181e-004,0.000000e+000,9.419792e-003,0.000000e+000,3,9.135555e-001,1.825000e+000,,,,,,,,,,,,,,,,,,0,5.000000e+000,5.000000e-001,2,1,4.119873e-003,0,1,0,
1473215773.557,,-1.000000e+004,6.500170e+001,-5.612954e-004,0.000000e+000,9.475634e-003,0.000000e+000,3,9.133391e-001,1.825000e+000,,,,,,,,,,,,,,,,,,0,5.000000e+000,5.000000e-001,2,1,2.044678e-003,0,1,0,
1473215942.559,,-2.000000e+004,6.499863e+001,-6.491332e-004,0.000000e+000,8.144309e-003,0.000000e+000,3,9.226030e-001,1.825000e+000,,,,,,,,,,,,,,,,,,0,5.000000e+000,5.000000e-001,2,1,8.193970e-003,0,1,0,
1473215964.537,,-2.000000e+004,6.499554e+001,-6.514195e-004,0.000000e+000,1.417109e-002,0.000000e+000,3,9.231116e-001,1.825000e+000,,,,,,,,,,,,,,,,,,0,5.000000e+000,5.000000e-001,2,1,6.141663e-003,0,1,0,
1473216139.984,,-3.000000e+004,6.499452e+001,-7.022639e-004,0.000000e+000,1.423394e-002,0.000000e+000,3,9.294498e-001,1.825000e+000,,,,,,,,,,,,,,,,,,0,5.000000e+000,5.000000e-001,2,1,2.048492e-002,0,1,0,
1473216166.662,,-3.000000e+004,6.500170e+001,-7.011393e-004,0.000000e+000,1.180575e-002,0.000000e+000,3,9.257092e-001,1.825000e+000,,,,,,,,,,,,,,,,,,0,5.000000e+000,5.000000e-001,2,1,2.044678e-003,0,0,0,
1473216344.592,,-4.000000e+004,6.499965e+001,-7.397612e-004,0.000000e+000,1.390235e-002,0.000000e+000,3,9.289824e-001,1.825000e+000,,,,,,,,,,,,,,,,,,0,5.000000e+000,5.000000e-001,2,1,1.023865e-002,0,0,0,
1473216372.879,,-4.000000e+004,6.499759e+001,-7.375845e-004,0.000000e+000,1.274300e-002,0.000000e+000,3,9.313171e-001,1.825000e+000,,,,,,,,,,,,,,,,,,0,5.000000e+000,5.000000e-001,2,1,2.052307e-003,0,0,0,
1473216586.655,,-5.000000e+004,6.499965e+001,-7.690603e-004,0.000000e+000,1.496570e-002,0.000000e+000,3,9.319291e-001,1.825000e+000,,,,,,,,,,,,,,,,,,0,5.000000e+000,5.000000e-001,2,1,1.023865e-002,0,0,0,
1473216612.348,,-5.000000e+004,6.500272e+001,-7.688256e-004,0.000000e+000,1.514845e-002,0.000000e+000,3,9.315264e-001,1.825000e+000,,,,,,,,,,,,,,,,,,0,5.000000e+000,5.000000e-001,2,1,1.231384e-002,0,0,0,
1473216794.313,,-6.000000e+004,6.500785e+001,-7.910689e-004,0.000000e+000,1.596919e-002,0.000000e+000,3,9.323426e-001,1.825000e+000,,,,,,,,,,,,,,,,,,0,5.000000e+000,5.000000e-001,2,1,1.434326e-002,0,0,0,
1473216822.744,,-6.000000e+004,6.500273e+001,-7.911424e-004,0.000000e+000,1.587763e-002,0.000000e+000,3,9.326202e-001,1.825000e+000,,,,,,,,,,,,,,,,,,0,5.000000e+000,5.000000e-001,2,1,1.640320e-002,0,0,0,
1473217010.906,,-7.000000e+004,6.499452e+001,-8.081453e-004,0.000000e+000,1.749900e-002,0.000000e+000,3,9.342191e-001,1.825000e+000,,,,,,,,,,,,,,,,,,0,5.000000e+000,5.000000e-001,2,1,8.186340e-003,0,1,0,
1473217035.115,,-7.000000e+004,6.499350e+001,-8.091939e-004,0.000000e+000,1.786209e-002,0.000000e+000,3,9.319194e-001,1.825000e+000,,,,,,,,,,,,,,,,,,0,5.000000e+000,5.000000e-001,2,1,1.844025e-002,0,1,0,
1473217223.064,,-6.000000e+004,6.500581e+001,-7.899256e-004,0.000000e+000,1.583093e-002,0.000000e+000,3,9.302559e-001,1.825000e+000,,,,,,,,,,,,,,,,,,0,5.000000e+000,5.000000e-001,2,1,1.025391e-002,0,1,0,
1473217246.294,,-6.000000e+004,6.500067e+001,-7.912132e-004,0.000000e+000,1.608260e-002,0.000000e+000,3,9.341025e-001,1.825000e+000,,,,,,,,,,,,,,,,,,0,5.000000e+000,5.000000e-001,2,1,4.104614e-003,0,1,0,
1473217420.283,,-5.000000e+004,6.501196e+001,-7.663810e-004,0.000000e+000,1.414176e-002,0.000000e+000,3,9.312989e-001,1.825000e+000,,,,,,,,,,,,,,,,,,0,5.000000e+000,5.000000e-001,2,1,2.044678e-003,0,1,0,
1473217444.769,,-5.000000e+004,6.500375e+001,-7.692603e-004,0.000000e+000,1.608670e-002,0.000000e+000,3,9.261912e-001,1.825000e+000,,,,,,,,,,,,,,,,,,0,5.000000e+000,5.000000e-001,2,1,2.044678e-003,0,1,0,
1473217625.998,,-4.000000e+004,6.499657e+001,-7.399676e-004,0.000000e+000,1.387776e-002,0.000000e+000,3,9.314840e-001,1.825000e+000,,,,,,,,,,,,,,,,,,0,5.000000e+000,5.000000e-001,2,1,1.638794e-002,0,1,0,
1473217652.227,,-4.000000e+004,6.499862e+001,-7.371532e-004,0.000000e+000,1.574144e-002,0.000000e+000,3,9.321383e-001,1.825000e+000,,,,,,,,,,,,,,,,,,0,5.000000e+000,5.000000e-001,2,1,0.000000e+000,0,1,0,
1473217829.220,,-3.000000e+004,6.499657e+001,-7.037510e-004,0.000000e+000,9.660809e-003,0.000000e+000,3,9.283993e-001,1.825000e+000,,,,,,,,,,,,,,,,,,0,5.000000e+000,5.000000e-001,2,1,4.089355e-003,0,1,0,
1473217855.945,,-3.000000e+004,6.499965e+001,-6.998602e-004,0.000000e+000,1.240286e-002,0.000000e+000,3,9.268349e-001,1.825000e+000,,,,,,,,,,,,,,,,,,0,5.000000e+000,5.000000e-001,2,1,6.156921e-003,0,1,0,
1473218035.432,,-2.000000e+004,6.499965e+001,-6.481645e-004,0.000000e+000,9.509814e-003,0.000000e+000,3,9.217608e-001,1.825000e+000,,,,,,,,,,,,,,,,,,0,5.000000e+000,5.000000e-001,2,1,6.156921e-003,0,1,0,
1473218061.361,,-2.000000e+004,6.500067e+001,-6.483885e-004,0.000000e+000,8.787790e-003,0.000000e+000,3,9.233965e-001,1.825000e+000,,,,,,,,,,,,,,,,,,0,5.000000e+000,5.000000e-001,2,1,4.104614e-003,0,1,0,
1473218237.108,,-1.000000e+004,6.499657e+001,-5.605093e-004,0.000000e+000,6.267308e-003,0.000000e+000,3,9.132046e-001,1.825000e+000,,,,,,,,,,,,,,,,,,0,5.000000e+000,5.000000e-001,2,1,0.000000e+000,0,1,0,
1473218263.080,,-1.000000e+004,6.500068e+001,-5.609380e-004,0.000000e+000,5.658540e-003,0.000000e+000,3,9.133502e-001,1.825000e+000,,,,,,,,,,,,,,,,,,0,5.000000e+000,5.000000e-001,2,1,0.000000e+000,0,1,0,
1473218398.269,,-9.000000e+003,6.499759e+001,-5.486960e-004,0.000000e+000,5.764175e-003,0.000000e+000,3,9.133068e-001,1.825000e+000,,,,,,,,,,,,,,,,,,0,5.000000e+000,5.000000e-001,2,1,2.052307e-003,0,1,0,
1473218425.737,,-9.000000e+003,6.499657e+001,-5.485368e-004,0.000000e+000,5.709005e-003,0.000000e+000,3,9.118360e-001,1.825000e+000,,,,,,,,,,,,,,,,,,0,5.000000e+000,5.000000e-001,2,1,4.089355e-003,0,1,0,
1473218557.676,,-7.000000e+003,6.499863e+001,-5.201730e-004,0.000000e+000,4.962878e-003,0.000000e+000,3,9.083022e-001,1.825000e+000,,,,,,,,,,,,,,,,,,0,5.000000e+000,5.000000e-001,2,1,4.112244e-003,0,1,0,
1473218582.891,,-7.000000e+003,6.499760e+001,-5.200032e-004,0.000000e+000,4.325076e-003,0.000000e+000,3,9.076707e-001,1.825000e+000,,,,,,,,,,,,,,,,,,0,5.000000e+000,5.000000e-001,2,1,6.149292e-003,0,1,0,
1473218716.333,,-5.000000e+003,6.500170e+001,-4.827844e-004,0.000000e+000,4.477875e-003,0.000000e+000,3,9.012623e-001,1.825000e+000,,,,,,,,,,,,,,,,,,0,5.000000e+000,5.000000e-001,2,1,2.044678e-003,0,1,0,
1473218745.277,,-5.000000e+003,6.499863e+001,-4.829875e-004,0.000000e+000,4.131156e-003,0.000000e+000,3,9.027811e-001,1.825000e+000,,,,,,,,,,,,,,,,,,0,5.000000e+000,5.000000e-001,2,1,4.112244e-003,0,1,0,
1473218877.005,,-3.000000e+003,6.500067e+001,-4.329796e-004,0.000000e+000,3.896021e-003,0.000000e+000,3,8.960745e-001,1.825000e+000,,,,,,,,,,,,,,,,,,0,5.000000e+000,5.000000e-001,2,1,4.104614e-003,0,1,0,
1473218903.434,,-3.000000e+003,6.499452e+001,-4.319047e-004,0.000000e+000,3.458932e-003,0.000000e+000,3,8.963283e-001,1.825000e+000,,,,,,,,,,,,,,,,,,0,5.000000e+000,5.000000e-001,2,1,8.186340e-003,0,1,0,
1473219044.128,,-1.000000e+003,6.499759e+001,-3.504722e-004,0.000000e+000,5.259819e-003,0.000000e+000,3,9.037383e-001,1.825000e+000,,,,,,,,,,,,,,,,,,0,5.000000e+000,5.000000e-001,2,1,2.052307e-003,0,1,0,
1473219071.112,,-1.000000e+003,6.499965e+001,-3.495372e-004,0.000000e+000,5.934584e-003,0.000000e+000,3,9.017587e-001,1.825000e+000,,,,,,,,,,,,,,,,,,0,5.000000e+000,5.000000e-001,2,1,2.059937e-003,0,1,0,
1473219211.052,,-7.000000e+002,6.499043e+001,-3.317155e-004,0.000000e+000,8.904488e-003,0.000000e+000,3,9.090986e-001,1.825000e+000,,,,,,,,,,,,,,,,,,0,5.000000e+000,5.000000e-001,2,1,1.228333e-002,0,1,0,
1473219237.496,,-7.000000e+002,6.499759e+001,-3.297372e-004,0.000000e+000,7.480073e-003,0.000000e+000,3,9.096746e-001,1.825000e+000,,,,,,,,,,,,,,,,,,0,5.000000e+000,5.000000e-001,2,1,2.052307e-003,0,1,0,
1473219372.190,,-6.000000e+002,6.499452e+001,-3.223693e-004,0.000000e+000,6.191525e-003,0.000000e+000,3,9.173646e-001,1.825000e+000,,,,,,,,,,,,,,,,,,0,5.000000e+000,5.000000e-001,2,1,1.639557e-002,0,1,0,
1473219398.118,,-6.000000e+002,6.499657e+001,-3.220378e-004,0.000000e+000,7.734163e-003,0.000000e+000,3,9.147017e-001,1.825000e+000,,,,,,,,,,,,,,,,,,0,5.000000e+000,5.000000e-001,2,1,4.089355e-003,0,1,0,
1473219531.839,,-5.000000e+002,6.499657e+001,-3.137043e-004,0.000000e+000,8.455889e-003,0.000000e+000,3,9.185693e-001,1.825000e+000,,,,,,,,,,,,,,,,,,0,5.000000e+000,5.000000e-001,2,1,0.000000e+000,0,1,0,
1473219558.517,,-5.000000e+002,6.499862e+001,-3.136764e-004,0.000000e+000,8.788054e-003,0.000000e+000,3,9.218999e-001,1.825000e+000,,,,,,,,,,,,,,,,,,0,5.000000e+000,5.000000e-001,2,1,0.000000e+000,0,1,0,
1473219694.461,,-4.000000e+002,6.499248e+001,-3.035957e-004,0.000000e+000,9.325201e-003,0.000000e+000,3,9.272835e-001,1.825000e+000,,,,,,,,,,,,,,,,,,0,5.000000e+000,5.000000e-001,2,1,8.186340e-003,0,1,0,
1473219718.424,,-4.000000e+002,6.499965e+001,-3.035954e-004,0.000000e+000,8.546103e-003,0.000000e+000,3,9.281974e-001,1.825000e+000,,,,,,,,,,,,,,,,,,0,5.000000e+000,5.000000e-001,2,1,2.059937e-003,0,1,0,
1473219852.863,,-3.000000e+002,6.499863e+001,-2.893029e-004,0.000000e+000,1.293922e-002,0.000000e+000,3,9.327359e-001,1.825000e+000,,,,,,,,,,,,,,,,,,0,5.000000e+000,5.000000e-001,2,1,4.112244e-003,0,1,0,
1473219880.337,,-3.000000e+002,6.500478e+001,-2.888116e-004,0.000000e+000,1.136946e-002,0.000000e+000,3,9.378009e-001,1.825000e+000,,,,,,,,,,,,,,,,,,0,5.000000e+000,5.000000e-001,2,1,1.231384e-002,0,1,0,
1473220006.080,,-2.000000e+002,6.499863e+001,-2.697533e-004,0.000000e+000,1.226489e-002,0.000000e+000,3,9.502511e-001,1.825000e+000,,,,,,,,,,,,,,,,,,0,5.000000e+000,5.000000e-001,2,1,8.193970e-003,0,1,0,
1473220033.099,,-2.000000e+002,6.499965e+001,-2.695840e-004,0.000000e+000,1.076047e-002,0.000000e+000,3,9.485559e-001,1.825000e+000,,,,,,,,,,,,,,,,,,0,5.000000e+000,5.000000e-001,2,1,2.059937e-003,0,1,0,
1473220158.037,,-1.800000e+002,6.500375e+001,-2.650311e-004,0.000000e+000,1.337524e-002,0.000000e+000,3,9.510896e-001,1.825000e+000,,,,,,,,,,,,,,,,,,0,5.000000e+000,5.000000e-001,2,1,1.026154e-002,0,1,0,
1473220187.996,,-1.800000e+002,6.499760e+001,-2.648267e-004,0.000000e+000,1.169380e-002,0.000000e+000,3,9.528607e-001,1.825000e+000,,,,,,,,,,,,,,,,,,0,5.000000e+000,5.000000e-001,2,1,6.149292e-003,0,1,0,
1473220310.746,,-1.600000e+002,6.500170e+001,-2.593741e-004,0.000000e+000,1.121612e-002,0.000000e+000,3,9.559719e-001,1.825000e+000,,,,,,,,,,,,,,,,,,0,5.000000e+000,5.000000e-001,2,1,2.044678e-003,0,1,0,
1473220338.424,,-1.600000e+002,6.500068e+001,-2.584455e-004,0.000000e+000,1.349558e-002,0.000000e+000,3,9.545008e-001,1.825000e+000,,,,,,,,,,,,,,,,,,0,5.000000e+000,5.000000e-001,2,1,0.000000e+000,0,1,0,
1473220459.113,,-1.400000e+002,6.500170e+001,-2.528366e-004,0.000000e+000,1.460666e-002,0.000000e+000,3,9.521202e-001,1.825000e+000,,,,,,,,,,,,,,,,,,0,5.000000e+000,5.000000e-001,2,1,2.044678e-003,0,1,0,
1473220482.322,,-1.400000e+002,6.500068e+001,-2.526697e-004,0.000000e+000,1.265034e-002,0.000000e+000,3,9.565563e-001,1.825000e+000,,,,,,,,,,,,,,,,,,0,5.000000e+000,5.000000e-001,2,1,0.000000e+000,0,1,0,
1473220604.265,,-1.200000e+002,6.499657e+001,-2.440213e-004,0.000000e+000,1.400235e-002,0.000000e+000,3,9.589431e-001,1.825000e+000,,,,,,,,,,,,,,,,,,0,5.000000e+000,5.000000e-001,2,1,0.000000e+000,0,1,0,
1473220630.444,,-1.200000e+002,6.500067e+001,-2.445125e-004,0.000000e+000,1.468131e-002,0.000000e+000,3,9.575055e-001,1.825000e+000,,,,,,,,,,,,,,,,,,0,5.000000e+000,5.000000e-001,2,1,4.104614e-003,0,1,0,
1473220758.904,,-1.000000e+002,6.500888e+001,-2.331201e-004,0.000000e+000,1.359784e-002,0.000000e+000,3,9.625278e-001,1.825000e+000,,,,,,,,,,,,,,,,,,0,5.000000e+000,5.000000e-001,2,1,0.000000e+000,0,1,0,
1473220786.583,,-1.000000e+002,6.499657e+001,-2.341972e-004,0.000000e+000,1.372265e-002,0.000000e+000,3,9.634029e-001,1.825000e+000,,,,,,,,,,,,,,,,,,0,5.000000e+000,5.000000e-001,2,1,0.000000e+000,0,1,0,
1473220907.310,,-8.000000e+001,6.499759e+001,-2.206760e-004,0.000000e+000,1.353606e-002,0.000000e+000,3,9.687545e-001,1.825000e+000,,,,,,,,,,,,,,,,,,0,5.000000e+000,5.000000e-001,2,1,2.052307e-003,0,1,0,
1473220944.227,,-8.000000e+001,6.500170e+001,-2.208054e-004,0.000000e+000,1.374891e-002,0.000000e+000,3,9.668265e-001,1.825000e+000,,,,,,,,,,,,,,,,,,0,5.000000e+000,5.000000e-001,2,1,2.044678e-003,0,1,0,
1473221066.937,,-6.000000e+001,6.498837e+001,-2.012873e-004,0.000000e+000,1.701961e-002,0.000000e+000,3,9.684960e-001,1.825000e+000,,,,,,,,,,,,,,,,,,0,5.000000e+000,5.000000e-001,2,1,2.049255e-002,0,1,0,
1473221095.866,,-6.000000e+001,6.499965e+001,-2.015228e-004,0.000000e+000,1.352062e-002,0.000000e+000,3,9.732226e-001,1.825000e+000,,,,,,,,,,,,,,,,,,0,5.000000e+000,5.000000e-001,2,1,2.059937e-003,0,1,0,
1473221221.078,,-4.000000e+001,6.499248e+001,-1.722699e-004,0.000000e+000,1.610296e-002,0.000000e+000,3,9.748426e-001,1.825000e+000,,,,,,,,,,,,,,,,,,0,5.000000e+000,5.000000e-001,2,1,1.229095e-002,0,1,0,
1473221250.264,,-4.000000e+001,6.499452e+001,-1.720543e-004,0.000000e+000,1.639148e-002,0.000000e+000,3,9.711880e-001,1.825000e+000,,,,,,,,,,,,,,,,,,0,5.000000e+000,5.000000e-001,2,1,4.089355e-003,0,1,0,
1473221370.952,,-2.000000e+001,6.500273e+001,-1.074124e-004,0.000000e+000,6.382961e-003,0.000000e+000,3,9.823209e-001,1.825000e+000,,,,,,,,,,,,,,,,,,0,5.000000e+000,5.000000e-001,2,1,8.224487e-003,0,1,0,
1473221394.880,,-2.000000e+001,6.498531e+001,-1.087334e-004,0.000000e+000,1.260704e-002,0.000000e+000,3,9.750050e-001,1.825000e+000,,,,,,,,,,,,,,,,,,0,5.000000e+000,5.000000e-001,2,1,1.025391e-002,0,1,0,
1473221528.564,,0.000000e+000,6.499965e+001,1.244227e-004,0.000000e+000,2.243763e-002,0.000000e+000,3,9.782078e-001,1.825000e+000,,,,,,,,,,,,,,,,,,0,5.000000e+000,5.000000e-001,2,1,2.059937e-003,0,1,0,
1473221555.931,,0.000000e+000,6.499759e+001,1.234296e-004,0.000000e+000,2.090975e-002,0.000000e+000,3,9.789072e-001,1.825000e+000,,,,,,,,,,,,,,,,,,0,5.000000e+000,5.000000e-001,2,1,2.052307e-003,0,1,0,
1473221684.590,,2.000000e+001,6.499453e+001,1.827221e-004,0.000000e+000,1.378937e-002,0.000000e+000,3,9.765586e-001,1.825000e+000,,,,,,,,,,,,,,,,,,0,5.000000e+000,5.000000e-001,2,1,0.000000e+000,0,1,0,
1473221710.797,,2.000000e+001,6.499863e+001,1.801964e-004,0.000000e+000,1.767686e-002,0.000000e+000,3,9.715227e-001,1.825000e+000,,,,,,,,,,,,,,,,,,0,5.000000e+000,5.000000e-001,2,1,8.193970e-003,0,1,0,
1473221832.046,,4.000000e+001,6.500272e+001,2.077159e-004,0.000000e+000,1.732790e-002,0.000000e+000,3,9.762149e-001,1.825000e+000,,,,,,,,,,,,,,,,,,0,5.000000e+000,5.000000e-001,2,1,0.000000e+000,0,1,0,
1473221861.656,,4.000000e+001,6.499965e+001,2.080553e-004,0.000000e+000,1.673565e-002,0.000000e+000,3,9.749081e-001,1.825000e+000,,,,,,,,,,,,,,,,,,0,5.000000e+000,5.000000e-001,2,1,6.156921e-003,0,1,0,
1473221985.737,,6.000000e+001,6.500376e+001,2.251370e-004,0.000000e+000,1.534267e-002,0.000000e+000,3,9.732469e-001,1.825000e+000,,,,,,,,,,,,,,,,,,0,5.000000e+000,5.000000e-001,2,1,6.164551e-003,0,1,0,
1473222012.268,,6.000000e+001,6.500068e+001,2.248585e-004,0.000000e+000,1.631040e-002,0.000000e+000,3,9.729289e-001,1.825000e+000,,,,,,,,,,,,,,,,,,0,5.000000e+000,5.000000e-001,2,1,0.000000e+000,0,1,0,
1473222136.210,,8.000000e+001,6.499760e+001,2.366839e-004,0.000000e+000,1.693279e-002,0.000000e+000,3,9.664384e-001,1.825000e+000,,,,,,,,,,,,,,,,,,0,5.000000e+000,5.000000e-001,2,1,1.024628e-002,0,1,0,
1473222160.389,,8.000000e+001,6.499965e+001,2.374697e-004,0.000000e+000,1.536303e-002,0.000000e+000,3,9.680381e-001,1.825000e+000,,,,,,,,,,,,,,,,,,0,5.000000e+000,5.000000e-001,2,1,2.059937e-003,0,1,0,
1473222290.839,,1.000000e+002,6.500068e+001,2.478170e-004,0.000000e+000,1.662252e-002,0.000000e+000,3,9.637060e-001,1.825000e+000,,,,,,,,,,,,,,,,,,0,5.000000e+000,5.000000e-001,2,1,0.000000e+000,0,1,0,
1473222316.718,,1.000000e+002,6.499863e+001,2.478646e-004,0.000000e+000,1.554546e-002,0.000000e+000,3,9.642805e-001,1.825000e+000,,,,,,,,,,,,,,,,,,0,5.000000e+000,5.000000e-001,2,1,4.112244e-003,0,1,0,
1473222440.619,,1.200000e+002,6.500067e+001,2.560329e-004,0.000000e+000,1.300849e-002,0.000000e+000,3,9.620975e-001,1.825000e+000,,,,,,,,,,,,,,,,,,0,5.000000e+000,5.000000e-001,2,1,4.104614e-003,0,1,0,
1473222470.298,,1.200000e+002,6.500169e+001,2.563174e-004,0.000000e+000,1.475736e-002,0.000000e+000,3,9.618714e-001,1.825000e+000,,,,,,,,,,,,,,,,,,0,5.000000e+000,5.000000e-001,2,1,6.149292e-003,0,1,0,
1473222592.301,,1.400000e+002,6.500169e+001,2.625164e-004,0.000000e+000,1.381475e-002,0.000000e+000,3,9.567711e-001,1.825000e+000,,,,,,,,,,,,,,,,,,0,5.000000e+000,5.000000e-001,2,1,6.149292e-003,0,1,0,
1473222618.236,,1.400000e+002,6.499554e+001,2.622302e-004,0.000000e+000,1.422425e-002,0.000000e+000,3,9.600396e-001,1.825000e+000,,,,,,,,,,,,,,,,,,0,5.000000e+000,5.000000e-001,2,1,6.141663e-003,0,1,0,
1473222750.176,,1.600000e+002,6.499864e+001,2.681761e-004,0.000000e+000,1.088196e-002,0.000000e+000,3,9.595623e-001,1.825000e+000,,,,,,,,,,,,,,,,,,0,5.000000e+000,5.000000e-001,2,1,1.641083e-002,0,1,0,
1473222775.619,,1.600000e+002,6.499556e+001,2.678146e-004,0.000000e+000,1.303669e-002,0.000000e+000,3,9.563580e-001,1.825000e+000,,,,,,,,,,,,,,,,,,0,5.000000e+000,5.000000e-001,2,1,1.024628e-002,0,1,0,
1473222905.558,,1.800000e+002,6.499248e+001,2.724967e-004,0.000000e+000,1.366102e-002,0.000000e+000,3,9.537205e-001,1.825000e+000,,,,,,,,,,,,,,,,,,0,5.000000e+000,5.000000e-001,2,1,0.000000e+000,0,1,0,
1473222933.524,,1.800000e+002,6.500375e+001,2.726457e-004,0.000000e+000,1.297754e-002,0.000000e+000,3,9.532173e-001,1.825000e+000,,,,,,,,,,,,,,,,,,0,5.000000e+000,5.000000e-001,2,1,1.026154e-002,0,1,0,
1473223054.966,,2.000000e+002,6.500683e+001,2.772041e-004,0.000000e+000,1.305830e-002,0.000000e+000,3,9.498696e-001,1.825000e+000,,,,,,,,,,,,,,,,,,0,5.000000e+000,5.000000e-001,2,1,2.459717e-002,0,1,0,
1473223083.094,,2.000000e+002,6.499863e+001,2.773040e-004,0.000000e+000,1.393119e-002,0.000000e+000,3,9.498389e-001,1.825000e+000,,,,,,,,,,,,,,,,,,0,5.000000e+000,5.000000e-001,2,1,4.112244e-003,0,1,0,
1473223211.084,,3.000000e+002,6.500887e+001,2.944091e-004,0.000000e+000,1.338194e-002,0.000000e+000,3,9.394915e-001,1.825000e+000,,,,,,,,,,,,,,,,,,0,5.000000e+000,5.000000e-001,2,1,2.461243e-002,0,1,0,
1473223235.879,,3.000000e+002,6.499862e+001,2.946733e-004,0.000000e+000,1.355478e-002,0.000000e+000,3,9.363207e-001,1.825000e+000,,,,,,,,,,,,,,,,,,0,5.000000e+000,5.000000e-001,2,1,0.000000e+000,0,1,0,
1473223374.771,,4.000000e+002,6.500375e+001,3.065066e-004,0.000000e+000,9.703630e-003,0.000000e+000,3,9.302710e-001,1.825000e+000,,,,,,,,,,,,,,,,,,0,5.000000e+000,5.000000e-001,2,1,1.026154e-002,0,1,0,
1473223400.058,,4.000000e+002,6.500067e+001,3.071854e-004,0.000000e+000,1.082421e-002,0.000000e+000,3,9.290917e-001,1.825000e+000,,,,,,,,,,,,,,,,,,0,5.000000e+000,5.000000e-001,2,1,4.104614e-003,0,1,0,
1473223534.753,,5.000000e+002,6.500581e+001,3.173150e-004,0.000000e+000,9.397930e-003,0.000000e+000,3,9.207180e-001,1.825000e+000,,,,,,,,,,,,,,,,,,0,5.000000e+000,5.000000e-001,2,1,1.025391e-002,0,1,0,
1473223561.432,,5.000000e+002,6.499554e+001,3.172566e-004,0.000000e+000,9.871790e-003,0.000000e+000,3,9.220635e-001,1.825000e+000,,,,,,,,,,,,,,,,,,0,5.000000e+000,5.000000e-001,2,1,2.037048e-003,0,1,0,
1473223689.146,,6.000000e+002,6.501299e+001,3.253176e-004,0.000000e+000,9.317317e-003,0.000000e+000,3,9.148540e-001,1.825000e+000,,,,,,,,,,,,,,,,,,0,5.000000e+000,5.000000e-001,2,1,1.228333e-002,0,1,0,
1473223715.871,,6.000000e+002,6.500272e+001,3.260094e-004,0.000000e+000,1.121257e-002,0.000000e+000,3,9.139491e-001,1.825000e+000,,,,,,,,,,,,,,,,,,0,5.000000e+000,5.000000e-001,2,1,0.000000e+000,0,1,0,
1473223852.568,,7.000000e+002,6.499965e+001,3.325164e-004,0.000000e+000,9.237194e-003,0.000000e+000,3,9.109813e-001,1.825000e+000,,,,,,,,,,,,,,,,,,0,5.000000e+000,5.000000e-001,2,1,6.156921e-003,0,1,0,
1473223878.264,,7.000000e+002,6.499965e+001,3.328378e-004,0.000000e+000,7.380724e-003,0.000000e+000,3,9.075857e-001,1.825000e+000,,,,,,,,,,,,,,,,,,0,5.000000e+000,5.000000e-001,2,1,2.059937e-003,0,1,0,
1473224010.454,,1.000000e+003,6.499760e+001,3.512919e-004,0.000000e+000,7.471942e-003,0.000000e+000,3,9.028306e-001,1.825000e+000,,,,,,,,,,,,,,,,,,0,5.000000e+000,5.000000e-001,2,1,1.024628e-002,0,1,0,
1473224035.716,,1.000000e+003,6.499554e+001,3.513992e-004,0.000000e+000,7.171323e-003,0.000000e+000,3,9.027431e-001,1.825000e+000,,,,,,,,,,,,,,,,,,0,5.000000e+000,5.000000e-001,2,1,6.141663e-003,0,1,0,
1473224172.971,,3.000000e+003,6.499759e+001,4.325681e-004,0.000000e+000,3.625924e-003,0.000000e+000,3,8.975258e-001,1.825000e+000,,,,,,,,,,,,,,,,,,0,5.000000e+000,5.000000e-001,2,1,2.052307e-003,0,1,0,
1473224199.149,,3.000000e+003,6.499965e+001,4.328560e-004,0.000000e+000,5.330200e-003,0.000000e+000,3,8.985624e-001,1.825000e+000,,,,,,,,,,,,,,,,,,0,5.000000e+000,5.000000e-001,2,1,2.059937e-003,0,1,0,
1473224339.292,,5.000000e+003,6.499759e+001,4.832347e-004,0.000000e+000,6.292257e-003,0.000000e+000,3,9.018807e-001,1.825000e+000,,,,,,,,,,,,,,,,,,0,5.000000e+000,5.000000e-001,2,1,2.052307e-003,0,1,0,
1473224365.837,,5.000000e+003,6.500272e+001,4.829708e-004,0.000000e+000,6.740992e-003,0.000000e+000,3,9.020809e-001,1.825000e+000,,,,,,,,,,,,,,,,,,0,5.000000e+000,5.000000e-001,2,1,4.089355e-003,0,1,0,
1473224504.855,,7.000000e+003,6.499759e+001,5.201556e-004,0.000000e+000,7.744468e-003,0.000000e+000,3,9.066546e-001,1.825000e+000,,,,,,,,,,,,,,,,,,0,5.000000e+000,5.000000e-001,2,1,2.052307e-003,0,1,0,
1473224532.534,,7.000000e+003,6.500272e+001,5.187062e-004,0.000000e+000,6.358506e-003,0.000000e+000,3,9.080229e-001,1.825000e+000,,,,,,,,,,,,,,,,,,0,5.000000e+000,5.000000e-001,2,1,0.000000e+000,0,1,0,
1473224667.014,,9.000000e+003,6.500068e+001,5.492641e-004,0.000000e+000,8.069811e-003,0.000000e+000,3,9.121137e-001,1.825000e+000,,,,,,,,,,,,,,,,,,0,5.000000e+000,5.000000e-001,2,1,0.000000e+000,0,1,0,
1473224694.943,,9.000000e+003,6.500169e+001,5.497159e-004,0.000000e+000,8.051000e-003,0.000000e+000,3,9.117605e-001,1.825000e+000,,,,,,,,,,,,,,,,,,0,5.000000e+000,5.000000e-001,2,1,6.149292e-003,0,1,0,
1473224828.387,,1.000000e+004,6.499863e+001,5.616251e-004,0.000000e+000,7.450921e-003,0.000000e+000,3,9.136673e-001,1.825000e+000,,,,,,,,,,,,,,,,,,0,5.000000e+000,5.000000e-001,2,1,4.112244e-003,0,1,0,
1473224855.855,,1.000000e+004,6.500273e+001,5.617513e-004,0.000000e+000,7.363512e-003,0.000000e+000,3,9.120241e-001,1.825000e+000,,,,,,,,,,,,,,,,,,0,5.000000e+000,5.000000e-001,2,1,8.224487e-003,0,1,0,
1473225047.328,,2.000000e+004,6.499863e+001,6.493282e-004,0.000000e+000,1.093584e-002,0.000000e+000,3,9.218720e-001,1.825000e+000,,,,,,,,,,,,,,,,,,0,5.000000e+000,5.000000e-001,2,1,4.112244e-003,0,1,0,
1473225073.507,,2.000000e+004,6.499965e+001,6.485020e-004,0.000000e+000,8.432503e-003,0.000000e+000,3,9.204941e-001,1.825000e+000,,,,,,,,,,,,,,,,,,0,5.000000e+000,5.000000e-001,2,1,2.059937e-003,0,1,0,
1473225246.950,,3.000000e+004,6.500273e+001,7.013550e-004,0.000000e+000,1.549908e-002,0.000000e+000,3,9.280095e-001,1.825000e+000,,,,,,,,,,,,,,,,,,0,5.000000e+000,5.000000e-001,2,1,8.224487e-003,0,1,0,
1473225273.673,,3.000000e+004,6.499759e+001,7.016778e-004,0.000000e+000,1.181694e-002,0.000000e+000,3,9.267836e-001,1.825000e+000,,,,,,,,,,,,,,,,,,0,5.000000e+000,5.000000e-001,2,1,2.052307e-003,0,1,0,
1473225452.424,,4.000000e+004,6.499657e+001,7.340540e-004,0.000000e+000,1.499500e-002,0.000000e+000,3,9.341271e-001,1.825000e+000,,,,,,,,,,,,,,,,,,0,5.000000e+000,5.000000e-001,2,1,4.089355e-003,0,1,0,
1473225478.352,,4.000000e+004,6.499965e+001,7.415642e-004,0.000000e+000,1.092268e-002,0.000000e+000,3,9.289962e-001,1.825000e+000,,,,,,,,,,,,,,,,,,0,5.000000e+000,5.000000e-001,2,1,2.059937e-003,0,1,0,
1473225658.816,,5.000000e+004,6.500067e+001,7.657692e-004,0.000000e+000,1.377950e-002,0.000000e+000,3,9.317316e-001,1.825000e+000,,,,,,,,,,,,,,,,,,0,5.000000e+000,5.000000e-001,2,1,4.104614e-003,0,1,0,
1473225686.272,,5.000000e+004,6.500272e+001,7.627244e-004,0.000000e+000,1.464425e-002,0.000000e+000,3,9.267641e-001,1.825000e+000,,,,,,,,,,,,,,,,,,0,5.000000e+000,5.000000e-001,2,1,4.089355e-003,0,1,0,
1473225879.467,,6.000000e+004,6.499452e+001,7.921464e-004,0.000000e+000,1.902020e-002,0.000000e+000,3,9.308584e-001,1.825000e+000,,,,,,,,,,,,,,,,,,0,5.000000e+000,5.000000e-001,2,1,8.186340e-003,0,1,0,
1473225905.646,,6.000000e+004,6.500170e+001,7.883259e-004,0.000000e+000,1.809516e-002,0.000000e+000,3,9.289981e-001,1.825000e+000,,,,,,,,,,,,,,,,,,0,5.000000e+000,5.000000e-001,2,1,2.044678e-003,0,1,0,
1473226091.844,,7.000000e+004,6.499863e+001,8.119010e-004,0.000000e+000,1.631900e-002,0.000000e+000,3,9.292611e-001,1.825000e+000,,,,,,,,,,,,,,,,,,0,5.000000e+000,5.000000e-001,2,1,4.112244e-003,0,1,0,
1473226120.330,,7.000000e+004,6.499965e+001,8.038135e-004,0.000000e+000,1.648751e-002,0.000000e+000,3,9.381962e-001,1.825000e+000,,,,,,,,,,,,,,,,,,0,5.000000e+000,5.000000e-001,2,1,6.156921e-003,0,1,0,
1473226134.342,,7.000000e+004,6.499554e+001,8.154144e-004,0.000000e+000,1.483572e-002,0.000000e+000,3,9.333650e-001,1.825000e+000,,,,,,,,,,,,,,,,,,0,5.000000e+000,5.000000e-001,2,1,2.037048e-003,0,1,0,