File: data/A344/A344_GdN_MH_020K_160908.rso.dat
[Header]
TITLE,MPMS RSO Measurement
BYAPP,MPMS Measurement,1.1,Summary
FILEOPENTIME, 1473289632.547000 9/8/2016, 11:07:12 AM

INFO, APPNAME, MPMS MultiVu Application, Revision 1.61,  Build 082

INFO, NAME, A344
INFO, WEIGHT, 10.500
INFO, AREA, 1.000
INFO, LENGTH, 1.000
INFO, SHAPE, 0
INFO, COMMENT, m = 0.0105g
INFO, SEQUENCE FILE: 7T_hysteresis_sweep_hi_res_zero_n4.seq


INFO, BACKGROUND DATA FILE:, None


STARTUPAXIS,X,4,LINEAR,AUTO,0.000000,0.000000
STARTUPAXIS,Y1,5,LINEAR,AUTO,0.000000,0.000000


STARTUPGROUP,Longitudinal
FIELDGROUP,Longitudinal,1,2,3,4,5,6,7,8,9,10,11,19,20,21,22,23,35
FIELDGROUP,Transverse,1,2,3,4,12,13,14,15,16,17,18,24,25,26,27,28,35

PLOT_APPEARANCE,ALL,HORZ_GRID_ON,VERT_GRID_ON,MARKERS_AND_LINES

[Data]
Time,Comment,Field (Oe),Temperature (K),Long Moment (emu),Long Scan Std Dev,Long Offset (cm),Long Offset Std Dev,Long Algorithm,Long Reg Fit,Long Reg Factor,Trans Moment (emu),Trans Scan Std Dev,Trans Offset (cm),Trans Offset Std Dev,Trans Algorithm,Trans Reg Fit,Trans Reg Factor,Long Moment [w/o ABS] (emu),Long Scan Std Dev [w/o ABS],Long Offset [w/o ABS] (cm),Long Offset Std Dev [w/o ABS],Long Reg Fit [w/o ABS],Trans Moment [w/o ABS] (emu),Trans Scan Std Dev [w/o ABS],Trans Offset [w/o ABS] (cm),Trans Offset Std Dev [w/o ABS],Trans Reg Fit [w/o ABS],RSO Position (deg),Amplitude (cm),Frequency,Cycles to Average,Scans per Measurement,Delta Temp (K),Error,EC Comp. Running,Using ABS,
1473289632.546,,7.000000e+004,1.999791e+001,1.235335e-003,0.000000e+000,8.505881e-003,0.000000e+000,3,9.516765e-001,1.825000e+000,,,,,,,,,,,,,,,,,,0,5.000000e+000,5.000000e-001,2,1,2.159119e-003,0,0,0,
1473289659.279,,7.000000e+004,2.000276e+001,1.235167e-003,0.000000e+000,8.668194e-003,0.000000e+000,3,9.516043e-001,1.825000e+000,,,,,,,,,,,,,,,,,,0,5.000000e+000,5.000000e-001,2,1,0.000000e+000,0,0,0,
1473289840.663,,6.000000e+004,2.000061e+001,1.236871e-003,0.000000e+000,7.255847e-003,0.000000e+000,3,9.520600e-001,1.825000e+000,,,,,,,,,,,,,,,,,,0,5.000000e+000,5.000000e-001,2,1,2.149582e-003,0,0,0,
1473289864.954,,6.000000e+004,2.000276e+001,1.236889e-003,0.000000e+000,7.233722e-003,0.000000e+000,3,9.521152e-001,1.825000e+000,,,,,,,,,,,,,,,,,,0,5.000000e+000,5.000000e-001,2,1,0.000000e+000,0,0,0,
1473290046.403,,5.000000e+004,1.999736e+001,1.236983e-003,0.000000e+000,6.357372e-003,0.000000e+000,3,9.526324e-001,1.825000e+000,,,,,,,,,,,,,,,,,,0,5.000000e+000,5.000000e-001,2,1,1.070023e-003,0,0,0,
1473290073.940,,5.000000e+004,1.999979e+001,1.237018e-003,0.000000e+000,6.359283e-003,0.000000e+000,3,9.525408e-001,1.825000e+000,,,,,,,,,,,,,,,,,,0,5.000000e+000,5.000000e-001,2,1,2.700806e-003,0,0,0,
1473290254.638,,4.000000e+004,1.999790e+001,1.235554e-003,0.000000e+000,5.655479e-003,0.000000e+000,3,9.530581e-001,1.825000e+000,,,,,,,,,,,,,,,,,,0,5.000000e+000,5.000000e-001,2,1,0.000000e+000,0,0,0,
1473290282.597,,4.000000e+004,2.000168e+001,1.235523e-003,0.000000e+000,5.673693e-003,0.000000e+000,3,9.530857e-001,1.825000e+000,,,,,,,,,,,,,,,,,,0,5.000000e+000,5.000000e-001,2,1,1.079559e-003,0,0,0,
1473290460.041,,3.000000e+004,2.000168e+001,1.231691e-003,0.000000e+000,4.940624e-003,0.000000e+000,3,9.535140e-001,1.825000e+000,,,,,,,,,,,,,,,,,,0,5.000000e+000,5.000000e-001,2,1,0.000000e+000,0,0,0,
1473290485.723,,3.000000e+004,2.000222e+001,1.231644e-003,0.000000e+000,5.179426e-003,0.000000e+000,3,9.531863e-001,1.825000e+000,,,,,,,,,,,,,,,,,,0,5.000000e+000,5.000000e-001,2,1,0.000000e+000,0,1,0,
1473290660.675,,2.000000e+004,2.000735e+001,1.224167e-003,0.000000e+000,4.654588e-003,0.000000e+000,3,9.534647e-001,1.825000e+000,,,,,,,,,,,,,,,,,,0,5.000000e+000,5.000000e-001,2,1,2.698898e-003,0,1,0,
1473290684.854,,2.000000e+004,2.001167e+001,1.224248e-003,0.000000e+000,4.362837e-003,0.000000e+000,3,9.534465e-001,1.825000e+000,,,,,,,,,,,,,,,,,,0,5.000000e+000,5.000000e-001,2,1,5.302429e-004,0,1,0,
1473290855.310,,1.000000e+004,1.999736e+001,1.208970e-003,0.000000e+000,3.712416e-003,0.000000e+000,3,9.539001e-001,1.825000e+000,,,,,,,,,,,,,,,,,,0,5.000000e+000,5.000000e-001,2,1,2.159119e-003,0,1,0,
1473290880.488,,1.000000e+004,2.000276e+001,1.208514e-003,0.000000e+000,3.655058e-003,0.000000e+000,3,9.539157e-001,1.825000e+000,,,,,,,,,,,,,,,,,,0,5.000000e+000,5.000000e-001,2,1,0.000000e+000,0,1,0,
1473291012.987,,9.000000e+003,2.000411e+001,1.205296e-003,0.000000e+000,3.592087e-003,0.000000e+000,3,9.536004e-001,1.825000e+000,,,,,,,,,,,,,,,,,,0,5.000000e+000,5.000000e-001,2,1,5.397797e-004,0,1,0,
1473291037.868,,9.000000e+003,2.000438e+001,1.206872e-003,0.000000e+000,3.625533e-003,0.000000e+000,3,9.530876e-001,1.825000e+000,,,,,,,,,,,,,,,,,,0,5.000000e+000,5.000000e-001,2,1,1.079559e-003,0,1,0,
1473291179.223,,7.000000e+003,1.999736e+001,1.200029e-003,0.000000e+000,4.033344e-003,0.000000e+000,3,9.540455e-001,1.825000e+000,,,,,,,,,,,,,,,,,,0,5.000000e+000,5.000000e-001,2,1,1.070023e-003,0,0,0,
1473291203.401,,7.000000e+003,1.999898e+001,1.199661e-003,0.000000e+000,3.890833e-003,0.000000e+000,3,9.540076e-001,1.825000e+000,,,,,,,,,,,,,,,,,,0,5.000000e+000,5.000000e-001,2,1,3.240585e-003,0,0,0,
1473291338.091,,5.000000e+003,2.000087e+001,1.190768e-003,0.000000e+000,4.182746e-003,0.000000e+000,3,9.538225e-001,1.825000e+000,,,,,,,,,,,,,,,,,,0,5.000000e+000,5.000000e-001,2,1,1.621246e-003,0,0,0,
1473291363.311,,5.000000e+003,2.000222e+001,1.190835e-003,0.000000e+000,3.740436e-003,0.000000e+000,3,9.539676e-001,1.825000e+000,,,,,,,,,,,,,,,,,,0,5.000000e+000,5.000000e-001,2,1,1.079559e-003,0,0,0,
1473291497.751,,3.000000e+003,2.000114e+001,1.177496e-003,0.000000e+000,3.375398e-003,0.000000e+000,3,9.556530e-001,1.825000e+000,,,,,,,,,,,,,,,,,,0,5.000000e+000,5.000000e-001,2,1,1.079559e-003,0,0,0,
1473291521.929,,3.000000e+003,2.000168e+001,1.175842e-003,0.000000e+000,3.789292e-003,0.000000e+000,3,9.553580e-001,1.825000e+000,,,,,,,,,,,,,,,,,,0,5.000000e+000,5.000000e-001,2,1,0.000000e+000,0,0,0,
1473291657.403,,1.000000e+003,2.000033e+001,1.141226e-003,0.000000e+000,4.435799e-003,0.000000e+000,3,9.630690e-001,1.825000e+000,,,,,,,,,,,,,,,,,,0,5.000000e+000,5.000000e-001,2,1,5.416870e-004,0,0,0,
1473291681.857,,1.000000e+003,2.000195e+001,1.140972e-003,0.000000e+000,5.238877e-003,0.000000e+000,3,9.623709e-001,1.825000e+000,,,,,,,,,,,,,,,,,,0,5.000000e+000,5.000000e-001,2,1,5.397797e-004,0,0,0,
1473291820.037,,7.000000e+002,1.999683e+001,1.128424e-003,0.000000e+000,5.453568e-003,0.000000e+000,3,9.649228e-001,1.825000e+000,,,,,,,,,,,,,,,,,,0,5.000000e+000,5.000000e-001,2,1,4.318237e-003,0,0,0,
1473291845.825,,7.000000e+002,2.000087e+001,1.127841e-003,0.000000e+000,6.111080e-003,0.000000e+000,3,9.654899e-001,1.825000e+000,,,,,,,,,,,,,,,,,,0,5.000000e+000,5.000000e-001,2,1,1.621246e-003,0,0,0,
1473291980.264,,6.000000e+002,1.999979e+001,1.122675e-003,0.000000e+000,5.976137e-003,0.000000e+000,3,9.675350e-001,1.825000e+000,,,,,,,,,,,,,,,,,,0,5.000000e+000,5.000000e-001,2,1,2.700806e-003,0,0,0,
1473292008.314,,6.000000e+002,2.000088e+001,1.121791e-003,0.000000e+000,6.019800e-003,0.000000e+000,3,9.669702e-001,1.825000e+000,,,,,,,,,,,,,,,,,,0,5.000000e+000,5.000000e-001,2,1,2.689362e-003,0,0,0,
1473292142.753,,5.000000e+002,1.999790e+001,1.114168e-003,0.000000e+000,7.000638e-003,0.000000e+000,3,9.684333e-001,1.825000e+000,,,,,,,,,,,,,,,,,,0,5.000000e+000,5.000000e-001,2,1,4.318237e-003,0,0,0,
1473292170.479,,5.000000e+002,2.000195e+001,1.113591e-003,0.000000e+000,6.145251e-003,0.000000e+000,3,9.691883e-001,1.825000e+000,,,,,,,,,,,,,,,,,,0,5.000000e+000,5.000000e-001,2,1,2.698898e-003,0,0,0,
1473292303.923,,4.000000e+002,2.000114e+001,1.103285e-003,0.000000e+000,6.594741e-003,0.000000e+000,3,9.711603e-001,1.825000e+000,,,,,,,,,,,,,,,,,,0,5.000000e+000,5.000000e-001,2,1,6.479263e-003,0,1,0,
1473292330.101,,4.000000e+002,2.000871e+001,1.102853e-003,0.000000e+000,6.794187e-003,0.000000e+000,3,9.712130e-001,1.825000e+000,,,,,,,,,,,,,,,,,,0,5.000000e+000,5.000000e-001,2,1,8.649826e-003,0,1,0,
1473292462.592,,3.000000e+002,2.000384e+001,1.089393e-003,0.000000e+000,7.168746e-003,0.000000e+000,3,9.739941e-001,1.825000e+000,,,,,,,,,,,,,,,,,,0,5.000000e+000,5.000000e-001,2,1,4.320145e-003,0,1,0,
1473292487.771,,3.000000e+002,2.000600e+001,1.089320e-003,0.000000e+000,6.748372e-003,0.000000e+000,3,9.738577e-001,1.825000e+000,,,,,,,,,,,,,,,,,,0,5.000000e+000,5.000000e-001,2,1,0.000000e+000,0,1,0,
1473292620.726,,2.000000e+002,2.000978e+001,1.065802e-003,0.000000e+000,6.943274e-003,0.000000e+000,3,9.768677e-001,1.825000e+000,,,,,,,,,,,,,,,,,,0,5.000000e+000,5.000000e-001,2,1,1.081467e-003,0,1,0,
1473292646.655,,2.000000e+002,2.000708e+001,1.066828e-003,0.000000e+000,7.199023e-003,0.000000e+000,3,9.767328e-001,1.825000e+000,,,,,,,,,,,,,,,,,,0,5.000000e+000,5.000000e-001,2,1,0.000000e+000,0,1,0,
1473292774.344,,1.800000e+002,2.000330e+001,1.060046e-003,0.000000e+000,7.155729e-003,0.000000e+000,3,9.776136e-001,1.825000e+000,,,,,,,,,,,,,,,,,,0,5.000000e+000,5.000000e-001,2,1,3.238678e-003,0,1,0,
1473292798.711,,1.800000e+002,2.000492e+001,1.060516e-003,0.000000e+000,7.186034e-003,0.000000e+000,3,9.780269e-001,1.825000e+000,,,,,,,,,,,,,,,,,,0,5.000000e+000,5.000000e-001,2,1,1.081467e-003,0,1,0,
1473292915.528,,1.600000e+002,2.000114e+001,1.053114e-003,0.000000e+000,7.568641e-003,0.000000e+000,3,9.777079e-001,1.825000e+000,,,,,,,,,,,,,,,,,,0,5.000000e+000,5.000000e-001,2,1,3.229141e-003,0,1,0,
1473292941.456,,1.600000e+002,2.000222e+001,1.053529e-003,0.000000e+000,7.095104e-003,0.000000e+000,3,9.783159e-001,1.825000e+000,,,,,,,,,,,,,,,,,,0,5.000000e+000,5.000000e-001,2,1,5.388260e-003,0,0,0,
1473293065.191,,1.400000e+002,2.000141e+001,1.045535e-003,0.000000e+000,7.173128e-003,0.000000e+000,3,9.793074e-001,1.825000e+000,,,,,,,,,,,,,,,,,,0,5.000000e+000,5.000000e-001,2,1,1.619339e-003,0,0,0,
1473293088.969,,1.400000e+002,2.000276e+001,1.045301e-003,0.000000e+000,7.560926e-003,0.000000e+000,3,9.787925e-001,1.825000e+000,,,,,,,,,,,,,,,,,,0,5.000000e+000,5.000000e-001,2,1,1.079559e-003,0,0,0,
1473293208.929,,1.200000e+002,2.000087e+001,1.037002e-003,0.000000e+000,8.252274e-003,0.000000e+000,3,9.784721e-001,1.825000e+000,,,,,,,,,,,,,,,,,,0,5.000000e+000,5.000000e-001,2,1,1.621246e-003,0,0,0,
1473293234.358,,1.200000e+002,2.000168e+001,1.036694e-003,0.000000e+000,7.560726e-003,0.000000e+000,3,9.794967e-001,1.825000e+000,,,,,,,,,,,,,,,,,,0,5.000000e+000,5.000000e-001,2,1,1.079559e-003,0,0,0,
1473293360.046,,1.000000e+002,1.999952e+001,1.026634e-003,0.000000e+000,7.560164e-003,0.000000e+000,3,9.800660e-001,1.825000e+000,,,,,,,,,,,,,,,,,,0,5.000000e+000,5.000000e-001,2,1,4.320145e-003,0,0,0,
1473293385.975,,1.000000e+002,2.000141e+001,1.026463e-003,0.000000e+000,7.397165e-003,0.000000e+000,3,9.802954e-001,1.825000e+000,,,,,,,,,,,,,,,,,,0,5.000000e+000,5.000000e-001,2,1,5.397797e-004,0,0,0,
1473293506.721,,8.000000e+001,2.000222e+001,1.015512e-003,0.000000e+000,7.364975e-003,0.000000e+000,3,9.811206e-001,1.825000e+000,,,,,,,,,,,,,,,,,,0,5.000000e+000,5.000000e-001,2,1,0.000000e+000,0,0,0,
1473293531.714,,8.000000e+001,2.000330e+001,1.014920e-003,0.000000e+000,7.306824e-003,0.000000e+000,3,9.810249e-001,1.825000e+000,,,,,,,,,,,,,,,,,,0,5.000000e+000,5.000000e-001,2,1,3.238678e-003,0,0,0,
1473293653.652,,6.000000e+001,2.000006e+001,1.000624e-003,0.000000e+000,7.720273e-003,0.000000e+000,3,9.811131e-001,1.825000e+000,,,,,,,,,,,,,,,,,,0,5.000000e+000,5.000000e-001,2,1,4.320145e-003,0,0,0,
1473293679.514,,6.000000e+001,2.000087e+001,1.000319e-003,0.000000e+000,7.704569e-003,0.000000e+000,3,9.813963e-001,1.825000e+000,,,,,,,,,,,,,,,,,,0,5.000000e+000,5.000000e-001,2,1,5.397797e-004,0,0,0,
1473293800.064,,4.000000e+001,2.000087e+001,9.835552e-004,0.000000e+000,7.543817e-003,0.000000e+000,3,9.823425e-001,1.825000e+000,,,,,,,,,,,,,,,,,,0,5.000000e+000,5.000000e-001,2,1,5.397797e-004,0,0,0,
1473293825.761,,4.000000e+001,2.000087e+001,9.830588e-004,0.000000e+000,7.798368e-003,0.000000e+000,3,9.822242e-001,1.825000e+000,,,,,,,,,,,,,,,,,,0,5.000000e+000,5.000000e-001,2,1,5.397797e-004,0,0,0,
1473293946.745,,2.000000e+001,1.999817e+001,9.618241e-004,0.000000e+000,8.328421e-003,0.000000e+000,3,9.821393e-001,1.825000e+000,,,,,,,,,,,,,,,,,,0,5.000000e+000,5.000000e-001,2,1,1.628876e-003,0,0,0,
1473293975.727,,2.000000e+001,2.000222e+001,9.607892e-004,0.000000e+000,7.969774e-003,0.000000e+000,3,9.828816e-001,1.825000e+000,,,,,,,,,,,,,,,,,,0,5.000000e+000,5.000000e-001,2,1,1.079559e-003,0,0,0,
1473294092.968,,0.000000e+000,2.000141e+001,9.333638e-004,0.000000e+000,7.799910e-003,0.000000e+000,3,9.834076e-001,1.825000e+000,,,,,,,,,,,,,,,,,,0,5.000000e+000,5.000000e-001,2,1,5.939484e-003,0,1,0,
1473294117.455,,0.000000e+000,2.000222e+001,9.325172e-004,0.000000e+000,8.125145e-003,0.000000e+000,3,9.827965e-001,1.825000e+000,,,,,,,,,,,,,,,,,,0,5.000000e+000,5.000000e-001,2,1,5.388260e-003,0,1,0,
1473294246.673,,-2.000000e+001,2.000843e+001,8.905853e-004,0.000000e+000,8.121167e-003,0.000000e+000,3,9.841481e-001,1.825000e+000,,,,,,,,,,,,,,,,,,0,5.000000e+000,5.000000e-001,2,1,5.302429e-004,0,1,0,
1473294272.351,,-2.000000e+001,2.001113e+001,8.901591e-004,0.000000e+000,8.460526e-003,0.000000e+000,3,9.839869e-001,1.825000e+000,,,,,,,,,,,,,,,,,,0,5.000000e+000,5.000000e-001,2,1,1.619339e-003,0,1,0,
1473294393.229,,-4.000000e+001,1.999844e+001,8.247249e-004,0.000000e+000,8.119435e-003,0.000000e+000,3,9.850715e-001,1.825000e+000,,,,,,,,,,,,,,,,,,0,5.000000e+000,5.000000e-001,2,1,0.000000e+000,0,1,0,
1473294417.516,,-4.000000e+001,2.000006e+001,8.232435e-004,0.000000e+000,8.046207e-003,0.000000e+000,3,9.851274e-001,1.825000e+000,,,,,,,,,,,,,,,,,,0,5.000000e+000,5.000000e-001,2,1,1.070023e-003,0,1,0,
1473294535.704,,-6.000000e+001,2.000357e+001,5.835064e-004,0.000000e+000,8.163312e-003,0.000000e+000,3,9.862794e-001,1.825000e+000,,,,,,,,,,,,,,,,,,0,5.000000e+000,5.000000e-001,2,1,2.698898e-003,0,1,0,
1473294559.136,,-6.000000e+001,2.000654e+001,5.684237e-004,0.000000e+000,8.872794e-003,0.000000e+000,3,9.857938e-001,1.825000e+000,,,,,,,,,,,,,,,,,,0,5.000000e+000,5.000000e-001,2,1,1.079559e-003,0,1,0,
1473294677.120,,-8.000000e+001,2.000033e+001,-5.093014e-004,0.000000e+000,6.064878e-003,0.000000e+000,3,9.777110e-001,1.825000e+000,,,,,,,,,,,,,,,,,,0,5.000000e+000,5.000000e-001,2,1,5.416870e-004,0,0,0,
1473294702.298,,-8.000000e+001,1.999952e+001,-5.163118e-004,0.000000e+000,6.248595e-003,0.000000e+000,3,9.777218e-001,1.825000e+000,,,,,,,,,,,,,,,,,,0,5.000000e+000,5.000000e-001,2,1,2.161026e-003,0,0,0,
1473294821.095,,-1.000000e+002,2.000141e+001,-6.693884e-004,0.000000e+000,6.110943e-003,0.000000e+000,3,9.791564e-001,1.825000e+000,,,,,,,,,,,,,,,,,,0,5.000000e+000,5.000000e-001,2,1,1.619339e-003,0,0,0,
1473294847.213,,-1.000000e+002,2.000330e+001,-6.720715e-004,0.000000e+000,6.968229e-003,0.000000e+000,3,9.776651e-001,1.825000e+000,,,,,,,,,,,,,,,,,,0,5.000000e+000,5.000000e-001,2,1,0.000000e+000,0,0,0,
1473294966.512,,-1.200000e+002,1.999979e+001,-7.577448e-004,0.000000e+000,4.974095e-003,0.000000e+000,3,9.751815e-001,1.825000e+000,,,,,,,,,,,,,,,,,,0,5.000000e+000,5.000000e-001,2,1,1.611710e-003,0,0,0,
1473294991.440,,-1.200000e+002,2.000114e+001,-7.649447e-004,0.000000e+000,6.742709e-003,0.000000e+000,3,9.771483e-001,1.825000e+000,,,,,,,,,,,,,,,,,,0,5.000000e+000,5.000000e-001,2,1,1.079559e-003,0,0,0,
1473295119.129,,-1.400000e+002,2.000195e+001,-8.292784e-004,0.000000e+000,6.608103e-003,0.000000e+000,3,9.776272e-001,1.825000e+000,,,,,,,,,,,,,,,,,,0,5.000000e+000,5.000000e-001,2,1,5.397797e-004,0,0,0,
1473295146.381,,-1.400000e+002,2.000168e+001,-8.319156e-004,0.000000e+000,6.642547e-003,0.000000e+000,3,9.770036e-001,1.825000e+000,,,,,,,,,,,,,,,,,,0,5.000000e+000,5.000000e-001,2,1,1.079559e-003,0,0,0,
1473295268.572,,-1.600000e+002,1.999170e+001,-8.792997e-004,0.000000e+000,6.780947e-003,0.000000e+000,3,9.768046e-001,1.825000e+000,,,,,,,,,,,,,,,,,,0,5.000000e+000,5.000000e-001,2,1,9.160995e-003,0,0,0,
1473295293.526,,-1.600000e+002,1.999359e+001,-8.821735e-004,0.000000e+000,6.437180e-003,0.000000e+000,3,9.767210e-001,1.825000e+000,,,,,,,,,,,,,,,,,,0,5.000000e+000,5.000000e-001,2,1,2.161026e-003,0,0,0,
1473295415.251,,-1.800000e+002,1.999871e+001,-9.184350e-004,0.000000e+000,6.574426e-003,0.000000e+000,3,9.769262e-001,1.825000e+000,,,,,,,,,,,,,,,,,,0,5.000000e+000,5.000000e-001,2,1,3.770828e-003,0,0,0,
1473295441.679,,-1.800000e+002,2.000087e+001,-9.206395e-004,0.000000e+000,6.660832e-003,0.000000e+000,3,9.764314e-001,1.825000e+000,,,,,,,,,,,,,,,,,,0,5.000000e+000,5.000000e-001,2,1,1.621246e-003,0,0,0,
1473295571.122,,-2.000000e+002,1.999899e+001,-9.497016e-004,0.000000e+000,6.360823e-003,0.000000e+000,3,9.764964e-001,1.825000e+000,,,,,,,,,,,,,,,,,,0,5.000000e+000,5.000000e-001,2,1,1.091003e-003,0,0,0,
1473295598.344,,-2.000000e+002,2.000330e+001,-9.514037e-004,0.000000e+000,6.471217e-003,0.000000e+000,3,9.761319e-001,1.825000e+000,,,,,,,,,,,,,,,,,,0,5.000000e+000,5.000000e-001,2,1,1.079559e-003,0,0,0,
1473295734.558,,-3.000000e+002,2.000465e+001,-1.031283e-003,0.000000e+000,6.469440e-003,0.000000e+000,3,9.728605e-001,1.825000e+000,,,,,,,,,,,,,,,,,,0,5.000000e+000,5.000000e-001,2,1,5.939484e-003,0,1,0,
1473295758.486,,-3.000000e+002,2.000276e+001,-1.032453e-003,0.000000e+000,6.351621e-003,0.000000e+000,3,9.733667e-001,1.825000e+000,,,,,,,,,,,,,,,,,,0,5.000000e+000,5.000000e-001,2,1,2.159119e-003,0,1,0,
1473295890.429,,-4.000000e+002,2.000627e+001,-1.068945e-003,0.000000e+000,6.079689e-003,0.000000e+000,3,9.710101e-001,1.825000e+000,,,,,,,,,,,,,,,,,,0,5.000000e+000,5.000000e-001,2,1,2.700806e-003,0,1,0,
1473295915.887,,-4.000000e+002,2.000681e+001,-1.069909e-003,0.000000e+000,5.934888e-003,0.000000e+000,3,9.706419e-001,1.825000e+000,,,,,,,,,,,,,,,,,,0,5.000000e+000,5.000000e-001,2,1,2.708435e-003,0,1,0,
1473296043.075,,-5.000000e+002,2.000465e+001,-1.090662e-003,0.000000e+000,5.991425e-003,0.000000e+000,3,9.687930e-001,1.825000e+000,,,,,,,,,,,,,,,,,,0,5.000000e+000,5.000000e-001,2,1,1.621246e-003,0,1,0,
1473296067.956,,-5.000000e+002,2.000492e+001,-1.090618e-003,0.000000e+000,5.606581e-003,0.000000e+000,3,9.693676e-001,1.825000e+000,,,,,,,,,,,,,,,,,,0,5.000000e+000,5.000000e-001,2,1,1.081467e-003,0,1,0,
1473296204.007,,-6.000000e+002,2.000276e+001,-1.104944e-003,0.000000e+000,5.671910e-003,0.000000e+000,3,9.671385e-001,1.825000e+000,,,,,,,,,,,,,,,,,,0,5.000000e+000,5.000000e-001,2,1,2.159119e-003,0,1,0,
1473296228.940,,-6.000000e+002,2.000519e+001,-1.104608e-003,0.000000e+000,5.625449e-003,0.000000e+000,3,9.668196e-001,1.825000e+000,,,,,,,,,,,,,,,,,,0,5.000000e+000,5.000000e-001,2,1,5.416870e-004,0,1,0,
1473296354.674,,-7.000000e+002,1.999925e+001,-1.114566e-003,0.000000e+000,5.252018e-003,0.000000e+000,3,9.656080e-001,1.825000e+000,,,,,,,,,,,,,,,,,,0,5.000000e+000,5.000000e-001,2,1,1.619339e-003,0,0,0,
1473296380.352,,-7.000000e+002,1.999790e+001,-1.114249e-003,0.000000e+000,5.487782e-003,0.000000e+000,3,9.653783e-001,1.825000e+000,,,,,,,,,,,,,,,,,,0,5.000000e+000,5.000000e-001,2,1,0.000000e+000,0,0,0,
1473296504.294,,-1.000000e+003,2.000114e+001,-1.131869e-003,0.000000e+000,4.886549e-003,0.000000e+000,3,9.623237e-001,1.825000e+000,,,,,,,,,,,,,,,,,,0,5.000000e+000,5.000000e-001,2,1,1.079559e-003,0,0,0,
1473296529.723,,-1.000000e+003,2.000249e+001,-1.132476e-003,0.000000e+000,4.806495e-003,0.000000e+000,3,9.621766e-001,1.825000e+000,,,,,,,,,,,,,,,,,,0,5.000000e+000,5.000000e-001,2,1,1.619339e-003,0,0,0,
1473296666.413,,-3.000000e+003,2.000114e+001,-1.173744e-003,0.000000e+000,4.236131e-003,0.000000e+000,3,9.553414e-001,1.825000e+000,,,,,,,,,,,,,,,,,,0,5.000000e+000,5.000000e-001,2,1,2.161026e-003,0,0,0,
1473296690.781,,-3.000000e+003,2.000222e+001,-1.172691e-003,0.000000e+000,3.294771e-003,0.000000e+000,3,9.546279e-001,1.825000e+000,,,,,,,,,,,,,,,,,,0,5.000000e+000,5.000000e-001,2,1,1.079559e-003,0,0,0,
1473296827.392,,-5.000000e+003,2.000034e+001,-1.189902e-003,0.000000e+000,3.428421e-003,0.000000e+000,3,9.541240e-001,1.825000e+000,,,,,,,,,,,,,,,,,,0,5.000000e+000,5.000000e-001,2,1,1.609802e-003,0,0,0,
1473296853.793,,-5.000000e+003,2.000249e+001,-1.189995e-003,0.000000e+000,3.406692e-003,0.000000e+000,3,9.539918e-001,1.825000e+000,,,,,,,,,,,,,,,,,,0,5.000000e+000,5.000000e-001,2,1,1.619339e-003,0,0,0,
1473296989.144,,-7.000000e+003,1.999844e+001,-1.199358e-003,0.000000e+000,3.468971e-003,0.000000e+000,3,9.538349e-001,1.825000e+000,,,,,,,,,,,,,,,,,,0,5.000000e+000,5.000000e-001,2,1,1.089096e-003,0,0,0,
1473297016.073,,-7.000000e+003,2.000060e+001,-1.199181e-003,0.000000e+000,3.435003e-003,0.000000e+000,3,9.538667e-001,1.825000e+000,,,,,,,,,,,,,,,,,,0,5.000000e+000,5.000000e-001,2,1,0.000000e+000,0,0,0,
1473297152.779,,-9.000000e+003,1.999979e+001,-1.205591e-003,0.000000e+000,3.531897e-003,0.000000e+000,3,9.537743e-001,1.825000e+000,,,,,,,,,,,,,,,,,,0,5.000000e+000,5.000000e-001,2,1,2.700806e-003,0,0,0,
1473297179.958,,-9.000000e+003,2.000141e+001,-1.205693e-003,0.000000e+000,3.531619e-003,0.000000e+000,3,9.536961e-001,1.825000e+000,,,,,,,,,,,,,,,,,,0,5.000000e+000,5.000000e-001,2,1,5.397797e-004,0,0,0,
1473297316.898,,-1.000000e+004,1.999763e+001,-1.208382e-003,0.000000e+000,3.517257e-003,0.000000e+000,3,9.538506e-001,1.825000e+000,,,,,,,,,,,,,,,,,,0,5.000000e+000,5.000000e-001,2,1,3.789902e-003,0,1,0,
1473297343.553,,-1.000000e+004,2.000871e+001,-1.208365e-003,0.000000e+000,3.589269e-003,0.000000e+000,3,9.536494e-001,1.825000e+000,,,,,,,,,,,,,,,,,,0,5.000000e+000,5.000000e-001,2,1,1.081085e-002,0,1,0,
1473297514.909,,-2.000000e+004,2.000411e+001,-1.223766e-003,0.000000e+000,4.256608e-003,0.000000e+000,3,9.535473e-001,1.825000e+000,,,,,,,,,,,,,,,,,,0,5.000000e+000,5.000000e-001,2,1,2.700806e-003,0,1,0,
1473297538.529,,-2.000000e+004,2.000924e+001,-1.224119e-003,0.000000e+000,4.307084e-003,0.000000e+000,3,9.534473e-001,1.825000e+000,,,,,,,,,,,,,,,,,,0,5.000000e+000,5.000000e-001,2,1,6.479263e-003,0,1,0,
1473297716.085,,-3.000000e+004,1.999817e+001,-1.229958e-003,0.000000e+000,5.645881e-003,0.000000e+000,3,9.525346e-001,1.825000e+000,,,,,,,,,,,,,,,,,,0,5.000000e+000,5.000000e-001,2,1,5.397797e-004,0,1,0,
1473297741.271,,-3.000000e+004,2.000114e+001,-1.231826e-003,0.000000e+000,4.068368e-003,0.000000e+000,3,9.520339e-001,1.825000e+000,,,,,,,,,,,,,,,,,,0,5.000000e+000,5.000000e-001,2,1,1.079559e-003,0,1,0,
1473297917.667,,-4.000000e+004,2.000141e+001,-1.235727e-003,0.000000e+000,4.248515e-003,0.000000e+000,3,9.512004e-001,1.825000e+000,,,,,,,,,,,,,,,,,,0,5.000000e+000,5.000000e-001,2,1,2.700806e-003,0,1,0,
1473297939.975,,-4.000000e+004,2.000465e+001,-1.234129e-003,0.000000e+000,5.502750e-003,0.000000e+000,3,9.555258e-001,1.825000e+000,,,,,,,,,,,,,,,,,,0,5.000000e+000,5.000000e-001,2,1,2.700806e-003,0,1,0,
1473298117.607,,-5.000000e+004,2.000034e+001,-1.237147e-003,0.000000e+000,6.334032e-003,0.000000e+000,3,9.526747e-001,1.825000e+000,,,,,,,,,,,,,,,,,,0,5.000000e+000,5.000000e-001,2,1,2.691269e-003,0,0,0,
1473298143.582,,-5.000000e+004,2.000222e+001,-1.237274e-003,0.000000e+000,5.969204e-003,0.000000e+000,3,9.527161e-001,1.825000e+000,,,,,,,,,,,,,,,,,,0,5.000000e+000,5.000000e-001,2,1,1.079559e-003,0,0,0,
1473298324.639,,-6.000000e+004,2.000087e+001,-1.236441e-003,0.000000e+000,6.617554e-003,0.000000e+000,3,9.518626e-001,1.825000e+000,,,,,,,,,,,,,,,,,,0,5.000000e+000,5.000000e-001,2,1,5.397797e-004,0,0,0,
1473298349.559,,-6.000000e+004,2.000276e+001,-1.236399e-003,0.000000e+000,6.497292e-003,0.000000e+000,3,9.520867e-001,1.825000e+000,,,,,,,,,,,,,,,,,,0,5.000000e+000,5.000000e-001,2,1,1.079559e-003,0,0,0,
1473298526.111,,-7.000000e+004,1.999305e+001,-1.235222e-003,0.000000e+000,6.857724e-003,0.000000e+000,3,9.516234e-001,1.825000e+000,,,,,,,,,,,,,,,,,,0,5.000000e+000,5.000000e-001,2,1,1.079559e-003,0,0,0,
1473298552.789,,-7.000000e+004,1.999979e+001,-1.235126e-003,0.000000e+000,6.826527e-003,0.000000e+000,3,9.516731e-001,1.825000e+000,,,,,,,,,,,,,,,,,,0,5.000000e+000,5.000000e-001,2,1,3.780365e-003,0,0,0,
1473298730.001,,-6.000000e+004,1.999791e+001,-1.236728e-003,0.000000e+000,5.603188e-003,0.000000e+000,3,9.523417e-001,1.825000e+000,,,,,,,,,,,,,,,,,,0,5.000000e+000,5.000000e-001,2,1,3.250122e-003,0,0,0,
1473298755.364,,-6.000000e+004,2.000195e+001,-1.236805e-003,0.000000e+000,5.652427e-003,0.000000e+000,3,9.520790e-001,1.825000e+000,,,,,,,,,,,,,,,,,,0,5.000000e+000,5.000000e-001,2,1,2.698898e-003,0,0,0,
1473298934.690,,-5.000000e+004,2.000384e+001,-1.236417e-003,0.000000e+000,5.117270e-003,0.000000e+000,3,9.527552e-001,1.825000e+000,,,,,,,,,,,,,,,,,,0,5.000000e+000,5.000000e-001,2,1,2.159119e-003,0,1,0,
1473298960.124,,-5.000000e+004,2.000654e+001,-1.236699e-003,0.000000e+000,5.497374e-003,0.000000e+000,3,9.520163e-001,1.825000e+000,,,,,,,,,,,,,,,,,,0,5.000000e+000,5.000000e-001,2,1,0.000000e+000,0,1,0,
1473299136.817,,-4.000000e+004,2.000141e+001,-1.236683e-003,0.000000e+000,4.361571e-003,0.000000e+000,3,9.521114e-001,1.825000e+000,,,,,,,,,,,,,,,,,,0,5.000000e+000,5.000000e-001,2,1,5.397797e-004,0,1,0,
1473299163.495,,-4.000000e+004,2.000114e+001,-1.234408e-003,0.000000e+000,3.800980e-003,0.000000e+000,3,9.542129e-001,1.825000e+000,,,,,,,,,,,,,,,,,,0,5.000000e+000,5.000000e-001,2,1,1.079559e-003,0,1,0,
1473299339.138,,-3.000000e+004,2.000330e+001,-1.229580e-003,0.000000e+000,4.109199e-003,0.000000e+000,3,9.526865e-001,1.825000e+000,,,,,,,,,,,,,,,,,,0,5.000000e+000,5.000000e-001,2,1,3.238678e-003,0,1,0,
1473299364.233,,-3.000000e+004,2.000357e+001,-1.231650e-003,0.000000e+000,3.232973e-003,0.000000e+000,3,9.522131e-001,1.825000e+000,,,,,,,,,,,,,,,,,,0,5.000000e+000,5.000000e-001,2,1,5.397797e-004,0,1,0,
1473299533.704,,-2.000000e+004,1.999493e+001,-1.223961e-003,0.000000e+000,3.515261e-003,0.000000e+000,3,9.531982e-001,1.825000e+000,,,,,,,,,,,,,,,,,,0,5.000000e+000,5.000000e-001,2,1,1.611710e-003,0,0,0,
1473299557.451,,-2.000000e+004,2.000195e+001,-1.223706e-003,0.000000e+000,3.472595e-003,0.000000e+000,3,9.534415e-001,1.825000e+000,,,,,,,,,,,,,,,,,,0,5.000000e+000,5.000000e-001,2,1,5.397797e-004,0,0,0,
1473299727.644,,-1.000000e+004,2.000033e+001,-1.208126e-003,0.000000e+000,2.053975e-003,0.000000e+000,3,9.543743e-001,1.825000e+000,,,,,,,,,,,,,,,,,,0,5.000000e+000,5.000000e-001,2,1,5.416870e-004,0,0,0,
1473299751.134,,-1.000000e+004,2.000168e+001,-1.208418e-003,0.000000e+000,2.412688e-003,0.000000e+000,3,9.540646e-001,1.825000e+000,,,,,,,,,,,,,,,,,,0,5.000000e+000,5.000000e-001,2,1,0.000000e+000,0,0,0,
1473299884.576,,-9.000000e+003,2.000087e+001,-1.205860e-003,0.000000e+000,2.184701e-003,0.000000e+000,3,9.540693e-001,1.825000e+000,,,,,,,,,,,,,,,,,,0,5.000000e+000,5.000000e-001,2,1,1.621246e-003,0,0,0,
1473299910.005,,-9.000000e+003,2.000195e+001,-1.205645e-003,0.000000e+000,2.455040e-003,0.000000e+000,3,9.538505e-001,1.825000e+000,,,,,,,,,,,,,,,,,,0,5.000000e+000,5.000000e-001,2,1,5.397797e-004,0,0,0,
1473300041.694,,-7.000000e+003,1.999250e+001,-1.199220e-003,0.000000e+000,2.670944e-003,0.000000e+000,3,9.536266e-001,1.825000e+000,,,,,,,,,,,,,,,,,,0,5.000000e+000,5.000000e-001,2,1,7.551193e-003,0,0,0,
1473300065.373,,-7.000000e+003,1.999736e+001,-1.199245e-003,0.000000e+000,2.590626e-003,0.000000e+000,3,9.539263e-001,1.825000e+000,,,,,,,,,,,,,,,,,,0,5.000000e+000,5.000000e-001,2,1,0.000000e+000,0,0,0,
1473300204.621,,-5.000000e+003,2.000034e+001,-1.190526e-003,0.000000e+000,2.209483e-003,0.000000e+000,3,9.543715e-001,1.825000e+000,,,,,,,,,,,,,,,,,,0,5.000000e+000,5.000000e-001,2,1,2.691269e-003,0,0,0,
1473300232.300,,-5.000000e+003,1.999548e+001,-1.190359e-003,0.000000e+000,2.530477e-003,0.000000e+000,3,9.541949e-001,1.825000e+000,,,,,,,,,,,,,,,,,,0,5.000000e+000,5.000000e-001,2,1,5.302429e-004,0,0,0,
1473300368.995,,-3.000000e+003,1.999871e+001,-1.176316e-003,0.000000e+000,2.758499e-003,0.000000e+000,3,9.554279e-001,1.825000e+000,,,,,,,,,,,,,,,,,,0,5.000000e+000,5.000000e-001,2,1,5.493164e-004,0,1,0,
1473300394.222,,-3.000000e+003,2.000222e+001,-1.176115e-003,0.000000e+000,2.896742e-003,0.000000e+000,3,9.552671e-001,1.825000e+000,,,,,,,,,,,,,,,,,,0,5.000000e+000,5.000000e-001,2,1,0.000000e+000,0,1,0,
1473300528.682,,-1.000000e+003,2.000654e+001,-1.140515e-003,0.000000e+000,5.222736e-003,0.000000e+000,3,9.611300e-001,1.825000e+000,,,,,,,,,,,,,,,,,,0,5.000000e+000,5.000000e-001,2,1,5.399704e-003,0,1,0,
1473300552.610,,-1.000000e+003,2.001086e+001,-1.140254e-003,0.000000e+000,3.926933e-003,0.000000e+000,3,9.626164e-001,1.825000e+000,,,,,,,,,,,,,,,,,,0,5.000000e+000,5.000000e-001,2,1,2.159119e-003,0,1,0,
1473300693.304,,-7.000000e+002,1.999899e+001,-1.126614e-003,0.000000e+000,5.163033e-003,0.000000e+000,3,9.652003e-001,1.825000e+000,,,,,,,,,,,,,,,,,,0,5.000000e+000,5.000000e-001,2,1,1.091003e-003,0,1,0,
1473300715.733,,-7.000000e+002,2.000033e+001,-1.127271e-003,0.000000e+000,4.364318e-003,0.000000e+000,3,9.657928e-001,1.825000e+000,,,,,,,,,,,,,,,,,,0,5.000000e+000,5.000000e-001,2,1,5.416870e-004,0,1,0,
1473300848.922,,-6.000000e+002,2.000438e+001,-1.120342e-003,0.000000e+000,5.202979e-003,0.000000e+000,3,9.668794e-001,1.825000e+000,,,,,,,,,,,,,,,,,,0,5.000000e+000,5.000000e-001,2,1,2.161026e-003,0,1,0,
1473300872.350,,-6.000000e+002,2.000627e+001,-1.120697e-003,0.000000e+000,5.307288e-003,0.000000e+000,3,9.671462e-001,1.825000e+000,,,,,,,,,,,,,,,,,,0,5.000000e+000,5.000000e-001,2,1,1.619339e-003,0,1,0,
1473301002.793,,-5.000000e+002,2.000141e+001,-1.113273e-003,0.000000e+000,5.821449e-003,0.000000e+000,3,9.683133e-001,1.825000e+000,,,,,,,,,,,,,,,,,,0,5.000000e+000,5.000000e-001,2,1,5.397797e-004,0,0,0,
1473301026.475,,-5.000000e+002,2.000357e+001,-1.113993e-003,0.000000e+000,5.290111e-003,0.000000e+000,3,9.688436e-001,1.825000e+000,,,,,,,,,,,,,,,,,,0,5.000000e+000,5.000000e-001,2,1,5.397797e-004,0,0,0,
1473301158.644,,-4.000000e+002,1.999925e+001,-1.101571e-003,0.000000e+000,5.216216e-003,0.000000e+000,3,9.708418e-001,1.825000e+000,,,,,,,,,,,,,,,,,,0,5.000000e+000,5.000000e-001,2,1,2.700806e-003,0,0,0,
1473301183.154,,-4.000000e+002,2.000141e+001,-1.103077e-003,0.000000e+000,5.452171e-003,0.000000e+000,3,9.714528e-001,1.825000e+000,,,,,,,,,,,,,,,,,,0,5.000000e+000,5.000000e-001,2,1,5.397797e-004,0,0,0,
1473301315.956,,-3.000000e+002,2.000114e+001,-1.087571e-003,0.000000e+000,6.286900e-003,0.000000e+000,3,9.740966e-001,1.825000e+000,,,,,,,,,,,,,,,,,,0,5.000000e+000,5.000000e-001,2,1,0.000000e+000,0,0,0,
1473301340.926,,-3.000000e+002,2.000168e+001,-1.087544e-003,0.000000e+000,6.011306e-003,0.000000e+000,3,9.739024e-001,1.825000e+000,,,,,,,,,,,,,,,,,,0,5.000000e+000,5.000000e-001,2,1,0.000000e+000,0,0,0,
1473301473.888,,-2.000000e+002,1.999440e+001,-1.065543e-003,0.000000e+000,6.409885e-003,0.000000e+000,3,9.768508e-001,1.825000e+000,,,,,,,,,,,,,,,,,,0,5.000000e+000,5.000000e-001,2,1,2.691269e-003,0,0,0,
1473301499.608,,-2.000000e+002,1.999899e+001,-1.065998e-003,0.000000e+000,6.409314e-003,0.000000e+000,3,9.766018e-001,1.825000e+000,,,,,,,,,,,,,,,,,,0,5.000000e+000,5.000000e-001,2,1,1.091003e-003,0,0,0,
1473301621.346,,-1.800000e+002,1.999898e+001,-1.059397e-003,0.000000e+000,6.089753e-003,0.000000e+000,3,9.777562e-001,1.825000e+000,,,,,,,,,,,,,,,,,,0,5.000000e+000,5.000000e-001,2,1,2.159119e-003,0,0,0,
1473301644.538,,-1.800000e+002,2.000195e+001,-1.059254e-003,0.000000e+000,6.611940e-003,0.000000e+000,3,9.775209e-001,1.825000e+000,,,,,,,,,,,,,,,,,,0,5.000000e+000,5.000000e-001,2,1,5.397797e-004,0,0,0,
1473301763.726,,-1.600000e+002,2.000033e+001,-1.052985e-003,0.000000e+000,6.627025e-003,0.000000e+000,3,9.779282e-001,1.825000e+000,,,,,,,,,,,,,,,,,,0,5.000000e+000,5.000000e-001,2,1,3.780365e-003,0,0,0,
1473301789.584,,-1.600000e+002,1.999817e+001,-1.052329e-003,0.000000e+000,6.539235e-003,0.000000e+000,3,9.780817e-001,1.825000e+000,,,,,,,,,,,,,,,,,,0,5.000000e+000,5.000000e-001,2,1,1.628876e-003,0,0,0,
1473301930.724,,-1.400000e+002,2.000168e+001,-1.045379e-003,0.000000e+000,6.573978e-003,0.000000e+000,3,9.787572e-001,1.825000e+000,,,,,,,,,,,,,,,,,,0,5.000000e+000,5.000000e-001,2,1,1.079559e-003,0,1,0,
1473301955.663,,-1.400000e+002,2.000654e+001,-1.044494e-003,0.000000e+000,6.812769e-003,0.000000e+000,3,9.789448e-001,1.825000e+000,,,,,,,,,,,,,,,,,,0,5.000000e+000,5.000000e-001,2,1,1.079559e-003,0,1,0,
1473302075.192,,-1.200000e+002,2.000978e+001,-1.036219e-003,0.000000e+000,6.538237e-003,0.000000e+000,3,9.790970e-001,1.825000e+000,,,,,,,,,,,,,,,,,,0,5.000000e+000,5.000000e-001,2,1,1.081467e-003,0,1,0,
1473302099.855,,-1.200000e+002,2.001465e+001,-1.036135e-003,0.000000e+000,6.963308e-003,0.000000e+000,3,9.793157e-001,1.825000e+000,,,,,,,,,,,,,,,,,,0,5.000000e+000,5.000000e-001,2,1,2.159119e-003,0,1,0,
1473302221.905,,-1.000000e+002,1.999871e+001,-1.026266e-003,0.000000e+000,7.241925e-003,0.000000e+000,3,9.796175e-001,1.825000e+000,,,,,,,,,,,,,,,,,,0,5.000000e+000,5.000000e-001,2,1,5.493164e-004,0,1,0,
1473302246.834,,-1.000000e+002,2.000195e+001,-1.025406e-003,0.000000e+000,6.827368e-003,0.000000e+000,3,9.801279e-001,1.825000e+000,,,,,,,,,,,,,,,,,,0,5.000000e+000,5.000000e-001,2,1,5.397797e-004,0,1,0,
1473302366.772,,-8.000000e+001,2.000573e+001,-1.013876e-003,0.000000e+000,7.041176e-003,0.000000e+000,3,9.806197e-001,1.825000e+000,,,,,,,,,,,,,,,,,,0,5.000000e+000,5.000000e-001,2,1,5.397797e-004,0,1,0,
1473302391.745,,-8.000000e+001,2.000492e+001,-1.013104e-003,0.000000e+000,6.938574e-003,0.000000e+000,3,9.809648e-001,1.825000e+000,,,,,,,,,,,,,,,,,,0,5.000000e+000,5.000000e-001,2,1,1.081467e-003,0,1,0,
1473302528.934,,-6.000000e+001,2.000033e+001,-1.000062e-003,0.000000e+000,6.982450e-003,0.000000e+000,3,9.812008e-001,1.825000e+000,,,,,,,,,,,,,,,,,,0,5.000000e+000,5.000000e-001,2,1,4.859924e-003,0,0,0,
1473302553.378,,-6.000000e+001,2.000303e+001,-1.000627e-003,0.000000e+000,6.678769e-003,0.000000e+000,3,9.813411e-001,1.825000e+000,,,,,,,,,,,,,,,,,,0,5.000000e+000,5.000000e-001,2,1,5.397797e-004,0,0,0,
1473302673.319,,-4.000000e+001,2.000141e+001,-9.808919e-004,0.000000e+000,6.654595e-003,0.000000e+000,3,9.815246e-001,1.825000e+000,,,,,,,,,,,,,,,,,,0,5.000000e+000,5.000000e-001,2,1,5.397797e-004,0,0,0,
1473302698.093,,-4.000000e+001,2.000087e+001,-9.821845e-004,0.000000e+000,7.197547e-003,0.000000e+000,3,9.821852e-001,1.825000e+000,,,,,,,,,,,,,,,,,,0,5.000000e+000,5.000000e-001,2,1,1.621246e-003,0,0,0,
1473302819.535,,-2.000000e+001,2.000060e+001,-9.598162e-004,0.000000e+000,7.717847e-003,0.000000e+000,3,9.826978e-001,1.825000e+000,,,,,,,,,,,,,,,,,,0,5.000000e+000,5.000000e-001,2,1,1.081467e-003,0,0,0,
1473302844.263,,-2.000000e+001,2.000303e+001,-9.602551e-004,0.000000e+000,7.396091e-003,0.000000e+000,3,9.827568e-001,1.825000e+000,,,,,,,,,,,,,,,,,,0,5.000000e+000,5.000000e-001,2,1,5.397797e-004,0,0,0,
1473302965.000,,0.000000e+000,1.999979e+001,-9.316089e-004,0.000000e+000,7.259997e-003,0.000000e+000,3,9.837067e-001,1.825000e+000,,,,,,,,,,,,,,,,,,0,5.000000e+000,5.000000e-001,2,1,1.611710e-003,0,0,0,
1473302990.212,,0.000000e+000,1.999710e+001,-9.318229e-004,0.000000e+000,7.208470e-003,0.000000e+000,3,9.835962e-001,1.825000e+000,,,,,,,,,,,,,,,,,,0,5.000000e+000,5.000000e-001,2,1,1.673126e-002,0,0,0,
1473303117.655,,2.000000e+001,2.000114e+001,-8.906306e-004,0.000000e+000,8.032847e-003,0.000000e+000,3,9.838918e-001,1.825000e+000,,,,,,,,,,,,,,,,,,0,5.000000e+000,5.000000e-001,2,1,1.079559e-003,0,0,0,
1473303143.145,,2.000000e+001,2.000060e+001,-8.901285e-004,0.000000e+000,7.462454e-003,0.000000e+000,3,9.841584e-001,1.825000e+000,,,,,,,,,,,,,,,,,,0,5.000000e+000,5.000000e-001,2,1,0.000000e+000,0,0,0,
1473303263.583,,4.000000e+001,2.000034e+001,-8.255921e-004,0.000000e+000,7.437044e-003,0.000000e+000,3,9.852397e-001,1.825000e+000,,,,,,,,,,,,,,,,,,0,5.000000e+000,5.000000e-001,2,1,2.691269e-003,0,0,0,
1473303289.127,,4.000000e+001,2.000060e+001,-8.233095e-004,0.000000e+000,8.006198e-003,0.000000e+000,3,9.845483e-001,1.825000e+000,,,,,,,,,,,,,,,,,,0,5.000000e+000,5.000000e-001,2,1,0.000000e+000,0,0,0,
1473303410.062,,6.000000e+001,2.000303e+001,-5.892632e-004,0.000000e+000,8.543646e-003,0.000000e+000,3,9.860358e-001,1.825000e+000,,,,,,,,,,,,,,,,,,0,5.000000e+000,5.000000e-001,2,1,2.698898e-003,0,1,0,
1473303434.539,,6.000000e+001,2.000357e+001,-5.749940e-004,0.000000e+000,8.501656e-003,0.000000e+000,3,9.858131e-001,1.825000e+000,,,,,,,,,,,,,,,,,,0,5.000000e+000,5.000000e-001,2,1,1.619339e-003,0,1,0,
1473303553.143,,8.000000e+001,2.000708e+001,5.150084e-004,0.000000e+000,5.482970e-003,0.000000e+000,3,9.764212e-001,1.825000e+000,,,,,,,,,,,,,,,,,,0,5.000000e+000,5.000000e-001,2,1,4.320145e-003,0,1,0,
1473303577.581,,8.000000e+001,2.001005e+001,5.226269e-004,0.000000e+000,5.147321e-003,0.000000e+000,3,9.779656e-001,1.825000e+000,,,,,,,,,,,,,,,,,,0,5.000000e+000,5.000000e-001,2,1,1.621246e-003,0,1,0,
1473303698.523,,1.000000e+002,2.000276e+001,6.781796e-004,0.000000e+000,6.060658e-003,0.000000e+000,3,9.786742e-001,1.825000e+000,,,,,,,,,,,,,,,,,,0,5.000000e+000,5.000000e-001,2,1,1.079559e-003,0,1,0,
1473303722.951,,1.000000e+002,2.000195e+001,6.805785e-004,0.000000e+000,6.122630e-003,0.000000e+000,3,9.784529e-001,1.825000e+000,,,,,,,,,,,,,,,,,,0,5.000000e+000,5.000000e-001,2,1,5.397797e-004,0,1,0,
1473303847.366,,1.200000e+002,2.000303e+001,7.700882e-004,0.000000e+000,6.042714e-003,0.000000e+000,3,9.776029e-001,1.825000e+000,,,,,,,,,,,,,,,,,,0,5.000000e+000,5.000000e-001,2,1,2.698898e-003,0,1,0,
1473303871.302,,1.200000e+002,2.000546e+001,7.732334e-004,0.000000e+000,6.067798e-003,0.000000e+000,3,9.777071e-001,1.825000e+000,,,,,,,,,,,,,,,,,,0,5.000000e+000,5.000000e-001,2,1,0.000000e+000,0,1,0,
1473303994.322,,1.400000e+002,2.000168e+001,8.381216e-004,0.000000e+000,6.155573e-003,0.000000e+000,3,9.772753e-001,1.825000e+000,,,,,,,,,,,,,,,,,,0,5.000000e+000,5.000000e-001,2,1,2.159119e-003,0,0,0,
1473304017.253,,1.400000e+002,1.999898e+001,8.399947e-004,0.000000e+000,6.377694e-003,0.000000e+000,3,9.769682e-001,1.825000e+000,,,,,,,,,,,,,,,,,,0,5.000000e+000,5.000000e-001,2,1,2.159119e-003,0,0,0,
1473304142.103,,1.600000e+002,2.000087e+001,8.897959e-004,0.000000e+000,5.803302e-003,0.000000e+000,3,9.768064e-001,1.825000e+000,,,,,,,,,,,,,,,,,,0,5.000000e+000,5.000000e-001,2,1,1.621246e-003,0,0,0,
1473304167.725,,1.600000e+002,2.000195e+001,8.906352e-004,0.000000e+000,6.387095e-003,0.000000e+000,3,9.772621e-001,1.825000e+000,,,,,,,,,,,,,,,,,,0,5.000000e+000,5.000000e-001,2,1,1.619339e-003,0,0,0,
1473304295.764,,1.800000e+002,1.999952e+001,9.266618e-004,0.000000e+000,6.402450e-003,0.000000e+000,3,9.764314e-001,1.825000e+000,,,,,,,,,,,,,,,,,,0,5.000000e+000,5.000000e-001,2,1,1.070023e-003,0,0,0,
1473304321.976,,1.800000e+002,2.000168e+001,9.293214e-004,0.000000e+000,6.216988e-003,0.000000e+000,3,9.765576e-001,1.825000e+000,,,,,,,,,,,,,,,,,,0,5.000000e+000,5.000000e-001,2,1,0.000000e+000,0,0,0,
1473304441.876,,2.000000e+002,2.000060e+001,9.562484e-004,0.000000e+000,5.952640e-003,0.000000e+000,3,9.762051e-001,1.825000e+000,,,,,,,,,,,,,,,,,,0,5.000000e+000,5.000000e-001,2,1,3.231049e-003,0,0,0,
1473304466.488,,2.000000e+002,2.000168e+001,9.582709e-004,0.000000e+000,5.869686e-003,0.000000e+000,3,9.764699e-001,1.825000e+000,,,,,,,,,,,,,,,,,,0,5.000000e+000,5.000000e-001,2,1,0.000000e+000,0,0,0,
1473304601.023,,3.000000e+002,1.999817e+001,1.036306e-003,0.000000e+000,5.935244e-003,0.000000e+000,3,9.740156e-001,1.825000e+000,,,,,,,,,,,,,,,,,,0,5.000000e+000,5.000000e-001,2,1,4.859924e-003,0,0,0,
1473304626.946,,3.000000e+002,1.999844e+001,1.037035e-003,0.000000e+000,5.989836e-003,0.000000e+000,3,9.736797e-001,1.825000e+000,,,,,,,,,,,,,,,,,,0,5.000000e+000,5.000000e-001,2,1,1.089096e-003,0,0,0,
1473304760.087,,4.000000e+002,1.999952e+001,1.071695e-003,0.000000e+000,5.944098e-003,0.000000e+000,3,9.706984e-001,1.825000e+000,,,,,,,,,,,,,,,,,,0,5.000000e+000,5.000000e-001,2,1,1.070023e-003,0,0,0,
1473304787.415,,4.000000e+002,1.999926e+001,1.072089e-003,0.000000e+000,5.910653e-003,0.000000e+000,3,9.706854e-001,1.825000e+000,,,,,,,,,,,,,,,,,,0,5.000000e+000,5.000000e-001,2,1,5.416870e-004,0,0,0,
1473304923.345,,5.000000e+002,2.000331e+001,1.092450e-003,0.000000e+000,5.824515e-003,0.000000e+000,3,9.684584e-001,1.825000e+000,,,,,,,,,,,,,,,,,,0,5.000000e+000,5.000000e-001,2,1,7.549286e-003,0,1,0,
1473304948.210,,5.000000e+002,2.000141e+001,1.092897e-003,0.000000e+000,5.252624e-003,0.000000e+000,3,9.690983e-001,1.825000e+000,,,,,,,,,,,,,,,,,,0,5.000000e+000,5.000000e-001,2,1,2.700806e-003,0,1,0,
1473305074.180,,6.000000e+002,2.000276e+001,1.104431e-003,0.000000e+000,5.263987e-003,0.000000e+000,3,9.665473e-001,1.825000e+000,,,,,,,,,,,,,,,,,,0,5.000000e+000,5.000000e-001,2,1,0.000000e+000,0,1,0,
1473305098.495,,6.000000e+002,2.000843e+001,1.105855e-003,0.000000e+000,5.258109e-003,0.000000e+000,3,9.669426e-001,1.825000e+000,,,,,,,,,,,,,,,,,,0,5.000000e+000,5.000000e-001,2,1,1.619339e-003,0,1,0,
1473305232.360,,7.000000e+002,2.000438e+001,1.115721e-003,0.000000e+000,5.038317e-003,0.000000e+000,3,9.653543e-001,1.825000e+000,,,,,,,,,,,,,,,,,,0,5.000000e+000,5.000000e-001,2,1,1.079559e-003,0,1,0,
1473305256.167,,7.000000e+002,2.000654e+001,1.115737e-003,0.000000e+000,5.103298e-003,0.000000e+000,3,9.654978e-001,1.825000e+000,,,,,,,,,,,,,,,,,,0,5.000000e+000,5.000000e-001,2,1,2.159119e-003,0,1,0,
1473305383.426,,1.000000e+003,2.000114e+001,1.133003e-003,0.000000e+000,4.623802e-003,0.000000e+000,3,9.623194e-001,1.825000e+000,,,,,,,,,,,,,,,,,,0,5.000000e+000,5.000000e-001,2,1,2.161026e-003,0,1,0,
1473305407.605,,1.000000e+003,2.000438e+001,1.133308e-003,0.000000e+000,4.610081e-003,0.000000e+000,3,9.622245e-001,1.825000e+000,,,,,,,,,,,,,,,,,,0,5.000000e+000,5.000000e-001,2,1,0.000000e+000,0,1,0,
1473305541.840,,3.000000e+003,1.999360e+001,1.175415e-003,0.000000e+000,3.430340e-003,0.000000e+000,3,9.558854e-001,1.825000e+000,,,,,,,,,,,,,,,,,,0,5.000000e+000,5.000000e-001,2,1,2.048874e-002,0,0,0,
1473305566.217,,3.000000e+003,2.000384e+001,1.176004e-003,0.000000e+000,3.334615e-003,0.000000e+000,3,9.552572e-001,1.825000e+000,,,,,,,,,,,,,,,,,,0,5.000000e+000,5.000000e-001,2,1,3.240585e-003,0,0,0,
1473305701.514,,5.000000e+003,2.000249e+001,1.190370e-003,0.000000e+000,3.062879e-003,0.000000e+000,3,9.539611e-001,1.825000e+000,,,,,,,,,,,,,,,,,,0,5.000000e+000,5.000000e-001,2,1,5.397797e-004,0,0,0,
1473305724.745,,5.000000e+003,2.000222e+001,1.190173e-003,0.000000e+000,3.251692e-003,0.000000e+000,3,9.539203e-001,1.825000e+000,,,,,,,,,,,,,,,,,,0,5.000000e+000,5.000000e-001,2,1,1.079559e-003,0,0,0,
1473305854.688,,7.000000e+003,2.000006e+001,1.197543e-003,0.000000e+000,2.955491e-003,0.000000e+000,3,9.533574e-001,1.825000e+000,,,,,,,,,,,,,,,,,,0,5.000000e+000,5.000000e-001,2,1,1.070023e-003,0,0,0,
1473305879.876,,7.000000e+003,2.000141e+001,1.198336e-003,0.000000e+000,3.054712e-003,0.000000e+000,3,9.537087e-001,1.825000e+000,,,,,,,,,,,,,,,,,,0,5.000000e+000,5.000000e-001,2,1,1.619339e-003,0,0,0,
1473306013.815,,9.000000e+003,2.000141e+001,1.205840e-003,0.000000e+000,3.254516e-003,0.000000e+000,3,9.538111e-001,1.825000e+000,,,,,,,,,,,,,,,,,,0,5.000000e+000,5.000000e-001,2,1,1.619339e-003,0,0,0,
1473306038.552,,9.000000e+003,2.000195e+001,1.205842e-003,0.000000e+000,3.262714e-003,0.000000e+000,3,9.537954e-001,1.825000e+000,,,,,,,,,,,,,,,,,,0,5.000000e+000,5.000000e-001,2,1,5.397797e-004,0,0,0,
1473306171.028,,1.000000e+004,1.999844e+001,1.208366e-003,0.000000e+000,3.371775e-003,0.000000e+000,3,9.537558e-001,1.825000e+000,,,,,,,,,,,,,,,,,,0,5.000000e+000,5.000000e-001,2,1,1.089096e-003,0,0,0,
1473306195.723,,1.000000e+004,2.000141e+001,1.208468e-003,0.000000e+000,3.287215e-003,0.000000e+000,3,9.537168e-001,1.825000e+000,,,,,,,,,,,,,,,,,,0,5.000000e+000,5.000000e-001,2,1,1.619339e-003,0,0,0,
1473306364.214,,2.000000e+004,1.999818e+001,1.224092e-003,0.000000e+000,3.978634e-003,0.000000e+000,3,9.537032e-001,1.825000e+000,,,,,,,,,,,,,,,,,,0,5.000000e+000,5.000000e-001,2,1,2.700806e-003,0,0,0,
1473306389.647,,2.000000e+004,2.000087e+001,1.224201e-003,0.000000e+000,4.008129e-003,0.000000e+000,3,9.535966e-001,1.825000e+000,,,,,,,,,,,,,,,,,,0,5.000000e+000,5.000000e-001,2,1,5.397797e-004,0,0,0,
1473306564.855,,3.000000e+004,2.000384e+001,1.231396e-003,0.000000e+000,4.731113e-003,0.000000e+000,3,9.531167e-001,1.825000e+000,,,,,,,,,,,,,,,,,,0,5.000000e+000,5.000000e-001,2,1,0.000000e+000,0,1,0,
1473306590.283,,3.000000e+004,2.000628e+001,1.231135e-003,0.000000e+000,4.795517e-003,0.000000e+000,3,9.531329e-001,1.825000e+000,,,,,,,,,,,,,,,,,,0,5.000000e+000,5.000000e-001,2,1,3.789902e-003,0,1,0,
1473306767.242,,4.000000e+004,2.001330e+001,1.235327e-003,0.000000e+000,5.801972e-003,0.000000e+000,3,9.529497e-001,1.825000e+000,,,,,,,,,,,,,,,,,,0,5.000000e+000,5.000000e-001,2,1,5.416870e-004,0,1,0,
1473306791.213,,4.000000e+004,2.000762e+001,1.234827e-003,0.000000e+000,5.445749e-003,0.000000e+000,3,9.529768e-001,1.825000e+000,,,,,,,,,,,,,,,,,,0,5.000000e+000,5.000000e-001,2,1,4.320145e-003,0,1,0,
1473306980.509,,5.000000e+004,2.000087e+001,1.243745e-003,0.000000e+000,5.769839e-003,0.000000e+000,3,9.506006e-001,1.825000e+000,,,,,,,,,,,,,,,,,,0,5.000000e+000,5.000000e-001,2,1,3.770828e-003,0,1,0,
1473307007.241,,5.000000e+004,2.000411e+001,1.234834e-003,0.000000e+000,6.099070e-003,0.000000e+000,3,9.528173e-001,1.825000e+000,,,,,,,,,,,,,,,,,,0,5.000000e+000,5.000000e-001,2,1,5.397797e-004,0,1,0,
1473307190.185,,6.000000e+004,1.999548e+001,1.233516e-003,0.000000e+000,4.973961e-003,0.000000e+000,3,9.523723e-001,1.825000e+000,,,,,,,,,,,,,,,,,,0,5.000000e+000,5.000000e-001,2,1,2.700806e-003,0,0,0,
1473307214.145,,6.000000e+004,1.999710e+001,1.240568e-003,0.000000e+000,5.407095e-003,0.000000e+000,3,9.523389e-001,1.825000e+000,,,,,,,,,,,,,,,,,,0,5.000000e+000,5.000000e-001,2,1,5.302429e-004,0,0,0,
1473307392.844,,7.000000e+004,2.000060e+001,1.235567e-003,0.000000e+000,6.594027e-003,0.000000e+000,3,9.518037e-001,1.825000e+000,,,,,,,,,,,,,,,,,,0,5.000000e+000,5.000000e-001,2,1,1.081467e-003,0,0,0,
1473307415.025,,7.000000e+004,2.000357e+001,1.235411e-003,0.000000e+000,6.538911e-003,0.000000e+000,3,9.516376e-001,1.825000e+000,,,,,,,,,,,,,,,,,,0,5.000000e+000,5.000000e-001,2,1,5.397797e-004,0,0,0,
1473307427.036,,7.000000e+004,2.000249e+001,1.234596e-003,0.000000e+000,6.575318e-003,0.000000e+000,3,9.514671e-001,1.825000e+000,,,,,,,,,,,,,,,,,,0,5.000000e+000,5.000000e-001,2,1,5.397797e-004,0,0,0,