File: data/A344/A344_GdN_MH_060K_160905.rso.dat
[Header]
TITLE,MPMS RSO Measurement
BYAPP,MPMS Measurement,1.1,Summary
FILEOPENTIME, 1473189882.348000 9/7/2016, 7:24:42 AM

INFO, APPNAME, MPMS MultiVu Application, Revision 1.61,  Build 082

INFO, NAME, A344
INFO, WEIGHT, 10.500
INFO, AREA, 1.000
INFO, LENGTH, 1.000
INFO, SHAPE, 0
INFO, COMMENT, m = 0.0105g
INFO, SEQUENCE FILE: 7T_hysteresis_sweep_hi_res_zero_n4.seq


INFO, BACKGROUND DATA FILE:, None


STARTUPAXIS,X,4,LINEAR,AUTO,0.000000,0.000000
STARTUPAXIS,Y1,5,LINEAR,AUTO,0.000000,0.000000


STARTUPGROUP,Longitudinal
FIELDGROUP,Longitudinal,1,2,3,4,5,6,7,8,9,10,11,19,20,21,22,23,35
FIELDGROUP,Transverse,1,2,3,4,12,13,14,15,16,17,18,24,25,26,27,28,35

PLOT_APPEARANCE,ALL,HORZ_GRID_ON,VERT_GRID_ON,MARKERS_AND_LINES

[Data]
Time,Comment,Field (Oe),Temperature (K),Long Moment (emu),Long Scan Std Dev,Long Offset (cm),Long Offset Std Dev,Long Algorithm,Long Reg Fit,Long Reg Factor,Trans Moment (emu),Trans Scan Std Dev,Trans Offset (cm),Trans Offset Std Dev,Trans Algorithm,Trans Reg Fit,Trans Reg Factor,Long Moment [w/o ABS] (emu),Long Scan Std Dev [w/o ABS],Long Offset [w/o ABS] (cm),Long Offset Std Dev [w/o ABS],Long Reg Fit [w/o ABS],Trans Moment [w/o ABS] (emu),Trans Scan Std Dev [w/o ABS],Trans Offset [w/o ABS] (cm),Trans Offset Std Dev [w/o ABS],Trans Reg Fit [w/o ABS],RSO Position (deg),Amplitude (cm),Frequency,Cycles to Average,Scans per Measurement,Delta Temp (K),Error,EC Comp. Running,Using ABS,
1473189882.347,,7.000000e+004,6.010427e+001,8.625779e-004,0.000000e+000,1.639139e-002,0.000000e+000,3,9.364578e-001,1.825000e+000,,,,,,,,,,,,,,,,,,0,5.000000e+000,5.000000e-001,2,1,1.765823e-002,0,0,0,
1473189906.829,,7.000000e+004,6.006633e+001,8.658828e-004,0.000000e+000,1.650060e-002,0.000000e+000,3,9.370580e-001,1.825000e+000,,,,,,,,,,,,,,,,,,0,5.000000e+000,5.000000e-001,2,1,2.645874e-002,0,0,0,
1473190093.068,,6.000000e+004,5.999762e+001,8.514809e-004,0.000000e+000,1.391777e-002,0.000000e+000,3,9.365498e-001,1.825000e+000,,,,,,,,,,,,,,,,,,0,5.000000e+000,5.000000e-001,2,1,1.232147e-002,0,0,0,
1473190118.043,,6.000000e+004,5.999849e+001,8.512855e-004,0.000000e+000,1.385665e-002,0.000000e+000,3,9.364635e-001,1.825000e+000,,,,,,,,,,,,,,,,,,0,5.000000e+000,5.000000e-001,2,1,3.520966e-003,0,0,0,
1473190297.991,,5.000000e+004,5.999762e+001,8.329477e-004,0.000000e+000,1.275306e-002,0.000000e+000,3,9.357035e-001,1.825000e+000,,,,,,,,,,,,,,,,,,0,5.000000e+000,5.000000e-001,2,1,1.770020e-003,0,0,0,
1473190325.169,,5.000000e+004,5.999762e+001,8.329992e-004,0.000000e+000,1.281968e-002,0.000000e+000,3,9.356579e-001,1.825000e+000,,,,,,,,,,,,,,,,,,0,5.000000e+000,5.000000e-001,2,1,1.770020e-003,0,0,0,
1473190502.627,,4.000000e+004,5.998970e+001,8.102111e-004,0.000000e+000,1.217905e-002,0.000000e+000,3,9.346916e-001,1.825000e+000,,,,,,,,,,,,,,,,,,0,5.000000e+000,5.000000e-001,2,1,2.110291e-002,0,1,0,
1473190530.587,,4.000000e+004,5.999762e+001,8.095853e-004,0.000000e+000,1.234365e-002,0.000000e+000,3,9.346657e-001,1.825000e+000,,,,,,,,,,,,,,,,,,0,5.000000e+000,5.000000e-001,2,1,1.232147e-002,0,1,0,
1473190705.030,,3.000000e+004,6.000554e+001,7.795296e-004,0.000000e+000,1.105231e-002,0.000000e+000,3,9.327151e-001,1.825000e+000,,,,,,,,,,,,,,,,,,0,5.000000e+000,5.000000e-001,2,1,1.760864e-002,0,1,0,
1473190729.725,,3.000000e+004,6.000378e+001,7.800198e-004,0.000000e+000,9.316617e-003,0.000000e+000,3,9.346000e-001,1.825000e+000,,,,,,,,,,,,,,,,,,0,5.000000e+000,5.000000e-001,2,1,0.000000e+000,0,1,0,
1473190900.172,,2.000000e+004,6.000290e+001,7.377438e-004,0.000000e+000,1.024913e-002,0.000000e+000,3,9.335532e-001,1.825000e+000,,,,,,,,,,,,,,,,,,0,5.000000e+000,5.000000e-001,2,1,5.287170e-003,0,1,0,
1473190925.850,,2.000000e+004,6.000201e+001,7.389559e-004,0.000000e+000,7.825094e-003,0.000000e+000,3,9.297937e-001,1.825000e+000,,,,,,,,,,,,,,,,,,0,5.000000e+000,5.000000e-001,2,1,3.528595e-003,0,1,0,
1473191094.793,,1.000000e+004,5.999762e+001,6.709020e-004,0.000000e+000,8.359764e-003,0.000000e+000,3,9.269419e-001,1.825000e+000,,,,,,,,,,,,,,,,,,0,5.000000e+000,5.000000e-001,2,1,8.800507e-003,0,1,0,
1473191118.726,,1.000000e+004,5.999410e+001,6.713428e-004,0.000000e+000,9.006131e-003,0.000000e+000,3,9.256940e-001,1.825000e+000,,,,,,,,,,,,,,,,,,0,5.000000e+000,5.000000e-001,2,1,1.758575e-003,0,0,0,
1473191250.165,,9.000000e+003,6.000114e+001,6.625308e-004,0.000000e+000,7.729000e-003,0.000000e+000,3,9.254275e-001,1.825000e+000,,,,,,,,,,,,,,,,,,0,5.000000e+000,5.000000e-001,2,1,8.808136e-003,0,0,0,
1473191274.843,,9.000000e+003,5.999498e+001,6.613261e-004,0.000000e+000,6.873730e-003,0.000000e+000,3,9.261227e-001,1.825000e+000,,,,,,,,,,,,,,,,,,0,5.000000e+000,5.000000e-001,2,1,0.000000e+000,0,0,0,
1473191414.286,,7.000000e+003,5.999674e+001,6.414078e-004,0.000000e+000,8.133028e-003,0.000000e+000,3,9.228835e-001,1.825000e+000,,,,,,,,,,,,,,,,,,0,5.000000e+000,5.000000e-001,2,1,1.056290e-002,0,0,0,
1473191439.215,,7.000000e+003,5.999586e+001,6.396540e-004,0.000000e+000,7.126239e-003,0.000000e+000,3,9.225763e-001,1.825000e+000,,,,,,,,,,,,,,,,,,0,5.000000e+000,5.000000e-001,2,1,1.750946e-003,0,0,0,
1473191571.928,,5.000000e+003,6.000114e+001,6.148377e-004,0.000000e+000,7.405041e-003,0.000000e+000,3,9.213576e-001,1.825000e+000,,,,,,,,,,,,,,,,,,0,5.000000e+000,5.000000e-001,2,1,1.232147e-002,0,0,0,
1473191596.210,,5.000000e+003,5.999762e+001,6.152997e-004,0.000000e+000,7.095810e-003,0.000000e+000,3,9.213849e-001,1.825000e+000,,,,,,,,,,,,,,,,,,0,5.000000e+000,5.000000e-001,2,1,1.770020e-003,0,0,0,
1473191735.713,,3.000000e+003,5.999937e+001,5.816455e-004,0.000000e+000,6.945883e-003,0.000000e+000,3,9.208786e-001,1.825000e+000,,,,,,,,,,,,,,,,,,0,5.000000e+000,5.000000e-001,2,1,5.290985e-003,0,0,0,
1473191758.848,,3.000000e+003,5.999674e+001,5.818312e-004,0.000000e+000,7.118047e-003,0.000000e+000,3,9.204736e-001,1.825000e+000,,,,,,,,,,,,,,,,,,0,5.000000e+000,5.000000e-001,2,1,3.520966e-003,0,0,0,
1473191899.146,,1.000000e+003,5.999762e+001,5.298937e-004,0.000000e+000,8.831710e-003,0.000000e+000,3,9.311974e-001,1.825000e+000,,,,,,,,,,,,,,,,,,0,5.000000e+000,5.000000e-001,2,1,1.770020e-003,0,0,0,
1473191928.825,,1.000000e+003,5.999673e+001,5.295549e-004,0.000000e+000,9.819668e-003,0.000000e+000,3,9.318277e-001,1.825000e+000,,,,,,,,,,,,,,,,,,0,5.000000e+000,5.000000e-001,2,1,0.000000e+000,0,0,0,
1473192071.316,,7.000000e+002,6.000026e+001,5.172531e-004,0.000000e+000,1.020947e-002,0.000000e+000,3,9.395646e-001,1.825000e+000,,,,,,,,,,,,,,,,,,0,5.000000e+000,5.000000e-001,2,1,1.055908e-002,0,1,0,
1473192097.245,,7.000000e+002,6.000642e+001,5.175400e-004,0.000000e+000,1.079261e-002,0.000000e+000,3,9.384203e-001,1.825000e+000,,,,,,,,,,,,,,,,,,0,5.000000e+000,5.000000e-001,2,1,1.937103e-002,0,1,0,
1473192227.982,,6.000000e+002,6.000290e+001,5.109287e-004,0.000000e+000,1.188316e-002,0.000000e+000,3,9.421428e-001,1.825000e+000,,,,,,,,,,,,,,,,,,0,5.000000e+000,5.000000e-001,2,1,5.287170e-003,0,1,0,
1473192251.956,,6.000000e+002,6.000378e+001,5.113489e-004,0.000000e+000,1.177504e-002,0.000000e+000,3,9.422209e-001,1.825000e+000,,,,,,,,,,,,,,,,,,0,5.000000e+000,5.000000e-001,2,1,3.517151e-003,0,1,0,
1473192387.579,,5.000000e+002,5.999147e+001,5.056761e-004,0.000000e+000,1.187156e-002,0.000000e+000,3,9.467030e-001,1.825000e+000,,,,,,,,,,,,,,,,,,0,5.000000e+000,5.000000e-001,2,1,3.166962e-002,0,1,0,
1473192412.622,,5.000000e+002,6.000202e+001,5.054496e-004,0.000000e+000,1.167286e-002,0.000000e+000,3,9.470648e-001,1.825000e+000,,,,,,,,,,,,,,,,,,0,5.000000e+000,5.000000e-001,2,1,0.000000e+000,0,1,0,
1473192543.868,,4.000000e+002,6.000290e+001,4.963649e-004,0.000000e+000,1.207783e-002,0.000000e+000,3,9.526869e-001,1.825000e+000,,,,,,,,,,,,,,,,,,0,5.000000e+000,5.000000e-001,2,1,1.758575e-003,0,1,0,
1473192569.047,,4.000000e+002,5.999937e+001,4.967012e-004,0.000000e+000,1.248985e-002,0.000000e+000,3,9.515154e-001,1.825000e+000,,,,,,,,,,,,,,,,,,0,5.000000e+000,5.000000e-001,2,1,1.750946e-003,0,1,0,
1473192695.739,,3.000000e+002,5.999674e+001,4.861659e-004,0.000000e+000,1.226048e-002,0.000000e+000,3,9.579680e-001,1.825000e+000,,,,,,,,,,,,,,,,,,0,5.000000e+000,5.000000e-001,2,1,1.056290e-002,0,0,0,
1473192721.347,,3.000000e+002,5.999937e+001,4.857154e-004,0.000000e+000,1.231010e-002,0.000000e+000,3,9.590741e-001,1.825000e+000,,,,,,,,,,,,,,,,,,0,5.000000e+000,5.000000e-001,2,1,1.750946e-003,0,0,0,
1473192851.644,,2.000000e+002,5.999674e+001,4.648164e-004,0.000000e+000,1.479965e-002,0.000000e+000,3,9.651878e-001,1.825000e+000,,,,,,,,,,,,,,,,,,0,5.000000e+000,5.000000e-001,2,1,3.520966e-003,0,0,0,
1473192878.614,,2.000000e+002,5.999498e+001,4.664401e-004,0.000000e+000,1.364522e-002,0.000000e+000,3,9.656047e-001,1.825000e+000,,,,,,,,,,,,,,,,,,0,5.000000e+000,5.000000e-001,2,1,7.041931e-003,0,0,0,
1473192997.806,,1.800000e+002,5.999586e+001,4.588358e-004,0.000000e+000,1.394975e-002,0.000000e+000,3,9.675646e-001,1.825000e+000,,,,,,,,,,,,,,,,,,0,5.000000e+000,5.000000e-001,2,1,1.750946e-003,0,0,0,
1473193023.994,,1.800000e+002,6.000290e+001,4.593520e-004,0.000000e+000,1.398761e-002,0.000000e+000,3,9.671973e-001,1.825000e+000,,,,,,,,,,,,,,,,,,0,5.000000e+000,5.000000e-001,2,1,5.287170e-003,0,0,0,
1473193146.432,,1.600000e+002,5.999937e+001,4.527076e-004,0.000000e+000,1.405272e-002,0.000000e+000,3,9.678065e-001,1.825000e+000,,,,,,,,,,,,,,,,,,0,5.000000e+000,5.000000e-001,2,1,1.750946e-003,0,0,0,
1473193170.146,,1.600000e+002,6.000025e+001,4.520328e-004,0.000000e+000,1.367681e-002,0.000000e+000,3,9.693186e-001,1.825000e+000,,,,,,,,,,,,,,,,,,0,5.000000e+000,5.000000e-001,2,1,0.000000e+000,0,0,0,
1473193289.102,,1.400000e+002,6.000026e+001,4.446094e-004,0.000000e+000,1.447010e-002,0.000000e+000,3,9.683422e-001,1.825000e+000,,,,,,,,,,,,,,,,,,0,5.000000e+000,5.000000e-001,2,1,3.520966e-003,0,0,0,
1473193316.530,,1.400000e+002,5.999498e+001,4.439626e-004,0.000000e+000,1.497318e-002,0.000000e+000,3,9.695349e-001,1.825000e+000,,,,,,,,,,,,,,,,,,0,5.000000e+000,5.000000e-001,2,1,0.000000e+000,0,0,0,
1473193440.500,,1.200000e+002,6.000290e+001,4.336801e-004,0.000000e+000,1.431992e-002,0.000000e+000,3,9.714808e-001,1.825000e+000,,,,,,,,,,,,,,,,,,0,5.000000e+000,5.000000e-001,2,1,1.583862e-002,0,0,0,
1473193466.128,,1.200000e+002,5.999498e+001,4.337036e-004,0.000000e+000,1.367237e-002,0.000000e+000,3,9.724495e-001,1.825000e+000,,,,,,,,,,,,,,,,,,0,5.000000e+000,5.000000e-001,2,1,3.509521e-003,0,1,0,
1473193592.203,,1.000000e+002,5.999410e+001,4.200889e-004,0.000000e+000,1.562651e-002,0.000000e+000,3,9.724307e-001,1.825000e+000,,,,,,,,,,,,,,,,,,0,5.000000e+000,5.000000e-001,2,1,1.758575e-003,0,1,0,
1473193616.642,,1.000000e+002,6.000554e+001,4.198334e-004,0.000000e+000,1.370970e-002,0.000000e+000,3,9.742767e-001,1.825000e+000,,,,,,,,,,,,,,,,,,0,5.000000e+000,5.000000e-001,2,1,3.520966e-003,0,1,0,
1473193735.080,,8.000000e+001,5.999849e+001,4.030078e-004,0.000000e+000,1.437609e-002,0.000000e+000,3,9.768277e-001,1.825000e+000,,,,,,,,,,,,,,,,,,0,5.000000e+000,5.000000e-001,2,1,3.520966e-003,0,1,0,
1473193759.259,,8.000000e+001,6.000378e+001,4.023809e-004,0.000000e+000,1.449322e-002,0.000000e+000,3,9.752729e-001,1.825000e+000,,,,,,,,,,,,,,,,,,0,5.000000e+000,5.000000e-001,2,1,3.517151e-003,0,1,0,
1473193876.738,,6.000000e+001,5.999938e+001,3.794430e-004,0.000000e+000,1.489463e-002,0.000000e+000,3,9.782332e-001,1.825000e+000,,,,,,,,,,,,,,,,,,0,5.000000e+000,5.000000e-001,2,1,8.800507e-003,0,1,0,
1473193902.960,,6.000000e+001,6.000114e+001,3.797154e-004,0.000000e+000,1.487122e-002,0.000000e+000,3,9.775389e-001,1.825000e+000,,,,,,,,,,,,,,,,,,0,5.000000e+000,5.000000e-001,2,1,8.808136e-003,0,1,0,
1473194023.398,,4.000000e+001,6.001082e+001,3.455312e-004,0.000000e+000,1.463833e-002,0.000000e+000,3,9.798831e-001,1.825000e+000,,,,,,,,,,,,,,,,,,0,5.000000e+000,5.000000e-001,2,1,1.056290e-002,0,1,0,
1473194047.521,,4.000000e+001,6.000114e+001,3.457931e-004,0.000000e+000,1.440119e-002,0.000000e+000,3,9.803126e-001,1.825000e+000,,,,,,,,,,,,,,,,,,0,5.000000e+000,5.000000e-001,2,1,1.770020e-003,0,1,0,
1473194171.335,,2.000000e+001,6.009721e+001,2.839711e-004,0.000000e+000,1.525924e-002,0.000000e+000,3,9.817092e-001,1.825000e+000,,,,,,,,,,,,,,,,,,0,5.000000e+000,5.000000e-001,2,1,3.540039e-003,0,0,0,
1473194196.264,,2.000000e+001,6.001170e+001,2.858702e-004,0.000000e+000,1.471106e-002,0.000000e+000,3,9.796268e-001,1.825000e+000,,,,,,,,,,,,,,,,,,0,5.000000e+000,5.000000e-001,2,1,2.288818e-002,0,0,0,
1473194327.166,,0.000000e+000,5.999762e+001,-2.091215e-005,0.000000e+000,2.280507e-003,0.000000e+000,3,9.502596e-001,1.825000e+000,,,,,,,,,,,,,,,,,,0,5.000000e+000,5.000000e-001,2,1,8.800507e-003,0,0,0,
1473194353.129,,0.000000e+000,6.000026e+001,-2.919683e-005,0.000000e+000,4.861583e-003,0.000000e+000,3,9.548314e-001,1.825000e+000,,,,,,,,,,,,,,,,,,0,5.000000e+000,5.000000e-001,2,1,3.520966e-003,0,0,0,
1473194500.701,,-2.000000e+001,5.999674e+001,-3.435091e-004,0.000000e+000,1.680708e-002,0.000000e+000,3,9.800678e-001,1.825000e+000,,,,,,,,,,,,,,,,,,0,5.000000e+000,5.000000e-001,2,1,3.520966e-003,0,0,0,
1473194526.105,,-2.000000e+001,6.000290e+001,-3.432557e-004,0.000000e+000,1.630305e-002,0.000000e+000,3,9.813401e-001,1.825000e+000,,,,,,,,,,,,,,,,,,0,5.000000e+000,5.000000e-001,2,1,1.583862e-002,0,0,0,
1473194646.401,,-4.000000e+001,5.999498e+001,-3.820493e-004,0.000000e+000,1.676281e-002,0.000000e+000,3,9.793186e-001,1.825000e+000,,,,,,,,,,,,,,,,,,0,5.000000e+000,5.000000e-001,2,1,3.509521e-003,0,0,0,
1473194672.388,,-4.000000e+001,5.999673e+001,-3.810803e-004,0.000000e+000,1.583693e-002,0.000000e+000,3,9.804386e-001,1.825000e+000,,,,,,,,,,,,,,,,,,0,5.000000e+000,5.000000e-001,2,1,0.000000e+000,0,0,0,
1473194794.365,,-6.000000e+001,5.999762e+001,-4.066584e-004,0.000000e+000,1.555624e-002,0.000000e+000,3,9.781349e-001,1.825000e+000,,,,,,,,,,,,,,,,,,0,5.000000e+000,5.000000e-001,2,1,1.583862e-002,0,0,0,
1473194820.294,,-6.000000e+001,5.999498e+001,-4.063989e-004,0.000000e+000,1.616952e-002,0.000000e+000,3,9.777111e-001,1.825000e+000,,,,,,,,,,,,,,,,,,0,5.000000e+000,5.000000e-001,2,1,0.000000e+000,0,0,0,
1473194941.789,,-8.000000e+001,5.999586e+001,-4.237747e-004,0.000000e+000,1.456548e-002,0.000000e+000,3,9.762560e-001,1.825000e+000,,,,,,,,,,,,,,,,,,0,5.000000e+000,5.000000e-001,2,1,1.750946e-003,0,0,0,
1473194966.243,,-8.000000e+001,5.999762e+001,-4.241014e-004,0.000000e+000,1.476857e-002,0.000000e+000,3,9.766895e-001,1.825000e+000,,,,,,,,,,,,,,,,,,0,5.000000e+000,5.000000e-001,2,1,1.770020e-003,0,0,0,
1473195088.943,,-1.000000e+002,6.001082e+001,-4.360882e-004,0.000000e+000,1.582186e-002,0.000000e+000,3,9.744848e-001,1.825000e+000,,,,,,,,,,,,,,,,,,0,5.000000e+000,5.000000e-001,2,1,1.759720e-002,0,1,0,
1473195111.670,,-1.000000e+002,5.999762e+001,-4.373318e-004,0.000000e+000,1.532430e-002,0.000000e+000,3,9.750573e-001,1.825000e+000,,,,,,,,,,,,,,,,,,0,5.000000e+000,5.000000e-001,2,1,1.770020e-003,0,1,0,
1473195232.805,,-1.200000e+002,6.000026e+001,-4.468502e-004,0.000000e+000,1.584127e-002,0.000000e+000,3,9.722832e-001,1.825000e+000,,,,,,,,,,,,,,,,,,0,5.000000e+000,5.000000e-001,2,1,3.520966e-003,0,1,0,
1473195258.122,,-1.200000e+002,6.000114e+001,-4.464955e-004,0.000000e+000,1.495016e-002,0.000000e+000,3,9.727660e-001,1.825000e+000,,,,,,,,,,,,,,,,,,0,5.000000e+000,5.000000e-001,2,1,1.770020e-003,0,1,0,
1473195379.123,,-1.400000e+002,6.000201e+001,-4.550038e-004,0.000000e+000,1.458586e-002,0.000000e+000,3,9.703425e-001,1.825000e+000,,,,,,,,,,,,,,,,,,0,5.000000e+000,5.000000e-001,2,1,3.528595e-003,0,1,0,
1473195402.551,,-1.400000e+002,6.000554e+001,-4.548842e-004,0.000000e+000,1.551546e-002,0.000000e+000,3,9.693335e-001,1.825000e+000,,,,,,,,,,,,,,,,,,0,5.000000e+000,5.000000e-001,2,1,0.000000e+000,0,1,0,
1473195520.761,,-1.600000e+002,6.000201e+001,-4.624480e-004,0.000000e+000,1.440088e-002,0.000000e+000,3,9.695379e-001,1.825000e+000,,,,,,,,,,,,,,,,,,0,5.000000e+000,5.000000e-001,2,1,3.528595e-003,0,1,0,
1473195545.689,,-1.600000e+002,6.000201e+001,-4.625520e-004,0.000000e+000,1.440319e-002,0.000000e+000,3,9.688091e-001,1.825000e+000,,,,,,,,,,,,,,,,,,0,5.000000e+000,5.000000e-001,2,1,3.528595e-003,0,1,0,
1473195664.183,,-1.800000e+002,6.000378e+001,-4.680464e-004,0.000000e+000,1.470946e-002,0.000000e+000,3,9.681709e-001,1.825000e+000,,,,,,,,,,,,,,,,,,0,5.000000e+000,5.000000e-001,2,1,1.055908e-002,0,1,0,
1473195690.129,,-1.800000e+002,6.000202e+001,-4.681207e-004,0.000000e+000,1.479035e-002,0.000000e+000,3,9.667273e-001,1.825000e+000,,,,,,,,,,,,,,,,,,0,5.000000e+000,5.000000e-001,2,1,0.000000e+000,0,1,0,
1473195810.762,,-2.000000e+002,5.999674e+001,-4.736662e-004,0.000000e+000,1.346692e-002,0.000000e+000,3,9.667128e-001,1.825000e+000,,,,,,,,,,,,,,,,,,0,5.000000e+000,5.000000e-001,2,1,3.520966e-003,0,0,0,
1473195835.049,,-2.000000e+002,5.999849e+001,-4.728180e-004,0.000000e+000,1.401249e-002,0.000000e+000,3,9.666767e-001,1.825000e+000,,,,,,,,,,,,,,,,,,0,5.000000e+000,5.000000e-001,2,1,3.520966e-003,0,0,0,
1473195969.569,,-3.000000e+002,5.999586e+001,-4.912792e-004,0.000000e+000,1.394819e-002,0.000000e+000,3,9.573923e-001,1.825000e+000,,,,,,,,,,,,,,,,,,0,5.000000e+000,5.000000e-001,2,1,5.279541e-003,0,0,0,
1473195993.073,,-3.000000e+002,6.000114e+001,-4.908266e-004,0.000000e+000,1.412893e-002,0.000000e+000,3,9.587482e-001,1.825000e+000,,,,,,,,,,,,,,,,,,0,5.000000e+000,5.000000e-001,2,1,1.232147e-002,0,0,0,
1473196127.262,,-4.000000e+002,5.999937e+001,-5.011387e-004,0.000000e+000,1.252999e-002,0.000000e+000,3,9.525920e-001,1.825000e+000,,,,,,,,,,,,,,,,,,0,5.000000e+000,5.000000e-001,2,1,5.290985e-003,0,0,0,
1473196152.191,,-4.000000e+002,6.000202e+001,-5.016076e-004,0.000000e+000,1.231474e-002,0.000000e+000,3,9.531308e-001,1.825000e+000,,,,,,,,,,,,,,,,,,0,5.000000e+000,5.000000e-001,2,1,7.038116e-003,0,0,0,
1473196278.134,,-5.000000e+002,5.999937e+001,-5.092223e-004,0.000000e+000,1.134657e-002,0.000000e+000,3,9.465638e-001,1.825000e+000,,,,,,,,,,,,,,,,,,0,5.000000e+000,5.000000e-001,2,1,5.290985e-003,0,0,0,
1473196302.852,,-5.000000e+002,6.000290e+001,-5.084554e-004,0.000000e+000,1.258180e-002,0.000000e+000,3,9.468888e-001,1.825000e+000,,,,,,,,,,,,,,,,,,0,5.000000e+000,5.000000e-001,2,1,1.758575e-003,0,0,0,
1473196437.792,,-6.000000e+002,5.999234e+001,-5.148944e-004,0.000000e+000,1.179727e-002,0.000000e+000,3,9.448718e-001,1.825000e+000,,,,,,,,,,,,,,,,,,0,5.000000e+000,5.000000e-001,2,1,1.232147e-002,0,0,0,
1473196461.970,,-6.000000e+002,5.999762e+001,-5.142235e-004,0.000000e+000,1.156250e-002,0.000000e+000,3,9.428105e-001,1.825000e+000,,,,,,,,,,,,,,,,,,0,5.000000e+000,5.000000e-001,2,1,5.271912e-003,0,0,0,
1473196596.663,,-7.000000e+002,5.999586e+001,-5.191916e-004,0.000000e+000,1.110318e-002,0.000000e+000,3,9.388549e-001,1.825000e+000,,,,,,,,,,,,,,,,,,0,5.000000e+000,5.000000e-001,2,1,5.279541e-003,0,1,0,
1473196623.457,,-7.000000e+002,5.999322e+001,-5.191546e-004,0.000000e+000,1.098373e-002,0.000000e+000,3,9.394178e-001,1.825000e+000,,,,,,,,,,,,,,,,,,0,5.000000e+000,5.000000e-001,2,1,1.760101e-002,0,1,0,
1473196751.178,,-1.000000e+003,6.000114e+001,-5.307622e-004,0.000000e+000,9.943098e-003,0.000000e+000,3,9.324782e-001,1.825000e+000,,,,,,,,,,,,,,,,,,0,5.000000e+000,5.000000e-001,2,1,8.808136e-003,0,1,0,
1473196774.622,,-1.000000e+003,6.000290e+001,-5.306768e-004,0.000000e+000,1.012900e-002,0.000000e+000,3,9.322869e-001,1.825000e+000,,,,,,,,,,,,,,,,,,0,5.000000e+000,5.000000e-001,2,1,1.758575e-003,0,1,0,
1473196908.316,,-3.000000e+003,5.999674e+001,-5.824715e-004,0.000000e+000,7.342658e-003,0.000000e+000,3,9.212835e-001,1.825000e+000,,,,,,,,,,,,,,,,,,0,5.000000e+000,5.000000e-001,2,1,1.056290e-002,0,1,0,
1473196933.018,,-3.000000e+003,6.000554e+001,-5.814490e-004,0.000000e+000,7.871095e-003,0.000000e+000,3,9.204907e-001,1.825000e+000,,,,,,,,,,,,,,,,,,0,5.000000e+000,5.000000e-001,2,1,3.520966e-003,0,1,0,
1473197071.711,,-5.000000e+003,6.000114e+001,-6.149988e-004,0.000000e+000,8.177130e-003,0.000000e+000,3,9.211360e-001,1.825000e+000,,,,,,,,,,,,,,,,,,0,5.000000e+000,5.000000e-001,2,1,1.770020e-003,0,1,0,
1473197096.860,,-5.000000e+003,6.000290e+001,-6.152627e-004,0.000000e+000,7.736012e-003,0.000000e+000,3,9.218334e-001,1.825000e+000,,,,,,,,,,,,,,,,,,0,5.000000e+000,5.000000e-001,2,1,1.758575e-003,0,1,0,
1473197233.411,,-7.000000e+003,6.000201e+001,-6.407605e-004,0.000000e+000,8.709226e-003,0.000000e+000,3,9.227211e-001,1.825000e+000,,,,,,,,,,,,,,,,,,0,5.000000e+000,5.000000e-001,2,1,3.528595e-003,0,1,0,
1473197256.839,,-7.000000e+003,5.999762e+001,-6.591338e-004,0.000000e+000,-6.906361e-003,0.000000e+000,3,5.542346e-001,1.825000e+000,,,,,,,,,,,,,,,,,,0,5.000000e+000,5.000000e-001,2,1,5.271912e-003,0,1,0,
1473197388.779,,-9.000000e+003,6.000114e+001,-6.626251e-004,0.000000e+000,8.422483e-003,0.000000e+000,3,9.248928e-001,1.825000e+000,,,,,,,,,,,,,,,,,,0,5.000000e+000,5.000000e-001,2,1,1.770020e-003,0,0,0,
1473197415.460,,-9.000000e+003,5.999498e+001,-6.623057e-004,0.000000e+000,8.806728e-003,0.000000e+000,3,9.248813e-001,1.825000e+000,,,,,,,,,,,,,,,,,,0,5.000000e+000,5.000000e-001,2,1,0.000000e+000,0,0,0,
1473197545.649,,-1.000000e+004,5.999937e+001,-6.715737e-004,0.000000e+000,8.725268e-003,0.000000e+000,3,9.259985e-001,1.825000e+000,,,,,,,,,,,,,,,,,,0,5.000000e+000,5.000000e-001,2,1,1.750946e-003,0,0,0,
1473197572.328,,-1.000000e+004,5.999849e+001,-6.713959e-004,0.000000e+000,8.987824e-003,0.000000e+000,3,9.252838e-001,1.825000e+000,,,,,,,,,,,,,,,,,,0,5.000000e+000,5.000000e-001,2,1,3.520966e-003,0,0,0,
1473197747.858,,-2.000000e+004,5.999146e+001,-7.339593e-004,0.000000e+000,9.068759e-003,0.000000e+000,3,9.282134e-001,1.825000e+000,,,,,,,,,,,,,,,,,,0,5.000000e+000,5.000000e-001,2,1,1.759338e-002,0,0,0,
1473197771.536,,-2.000000e+004,6.000114e+001,-7.376218e-004,0.000000e+000,1.052890e-002,0.000000e+000,3,9.307128e-001,1.825000e+000,,,,,,,,,,,,,,,,,,0,5.000000e+000,5.000000e-001,2,1,8.808136e-003,0,0,0,
1473197945.538,,-3.000000e+004,5.999586e+001,-7.797424e-004,0.000000e+000,1.188137e-002,0.000000e+000,3,9.332205e-001,1.825000e+000,,,,,,,,,,,,,,,,,,0,5.000000e+000,5.000000e-001,2,1,5.279541e-003,0,0,0,
1473197971.769,,-3.000000e+004,5.999937e+001,-7.796694e-004,0.000000e+000,1.184126e-002,0.000000e+000,3,9.332939e-001,1.825000e+000,,,,,,,,,,,,,,,,,,0,5.000000e+000,5.000000e-001,2,1,1.750946e-003,0,0,0,
1473198148.028,,-4.000000e+004,5.999849e+001,-8.103834e-004,0.000000e+000,1.300714e-002,0.000000e+000,3,9.351625e-001,1.825000e+000,,,,,,,,,,,,,,,,,,0,5.000000e+000,5.000000e-001,2,1,3.520966e-003,0,1,0,
1473198173.154,,-4.000000e+004,5.999937e+001,-8.106257e-004,0.000000e+000,1.287198e-002,0.000000e+000,3,9.349148e-001,1.825000e+000,,,,,,,,,,,,,,,,,,0,5.000000e+000,5.000000e-001,2,1,5.290985e-003,0,1,0,
1473198357.648,,-5.000000e+004,5.999849e+001,-8.330921e-004,0.000000e+000,1.386448e-002,0.000000e+000,3,9.360550e-001,1.825000e+000,,,,,,,,,,,,,,,,,,0,5.000000e+000,5.000000e-001,2,1,3.520966e-003,0,1,0,
1473198381.185,,-5.000000e+004,6.000026e+001,-8.333681e-004,0.000000e+000,1.341050e-002,0.000000e+000,3,9.347666e-001,1.825000e+000,,,,,,,,,,,,,,,,,,0,5.000000e+000,5.000000e-001,2,1,3.520966e-003,0,1,0,
1473198564.437,,-6.000000e+004,6.000114e+001,-8.582464e-004,0.000000e+000,1.550189e-002,0.000000e+000,3,9.383070e-001,1.825000e+000,,,,,,,,,,,,,,,,,,0,5.000000e+000,5.000000e-001,2,1,1.770020e-003,0,1,0,
1473198590.366,,-6.000000e+004,5.999937e+001,-8.511397e-004,0.000000e+000,1.713541e-002,0.000000e+000,3,9.371005e-001,1.825000e+000,,,,,,,,,,,,,,,,,,0,5.000000e+000,5.000000e-001,2,1,1.750946e-003,0,1,0,
1473198769.081,,-7.000000e+004,5.999762e+001,-8.626606e-004,0.000000e+000,1.404577e-002,0.000000e+000,3,9.334939e-001,1.825000e+000,,,,,,,,,,,,,,,,,,0,5.000000e+000,5.000000e-001,2,1,5.271912e-003,0,1,0,
1473198793.709,,-7.000000e+004,5.999762e+001,-8.645492e-004,0.000000e+000,1.152148e-002,0.000000e+000,3,9.344857e-001,1.825000e+000,,,,,,,,,,,,,,,,,,0,5.000000e+000,5.000000e-001,2,1,5.271912e-003,0,1,0,
1473198982.197,,-6.000000e+004,5.999849e+001,-8.497856e-004,0.000000e+000,1.291358e-002,0.000000e+000,3,9.389525e-001,1.825000e+000,,,,,,,,,,,,,,,,,,0,5.000000e+000,5.000000e-001,2,1,3.520966e-003,0,0,0,
1473199007.237,,-6.000000e+004,5.999762e+001,-8.506761e-004,0.000000e+000,1.414264e-002,0.000000e+000,3,9.338340e-001,1.825000e+000,,,,,,,,,,,,,,,,,,0,5.000000e+000,5.000000e-001,2,1,1.770020e-003,0,0,0,
1473199182.294,,-5.000000e+004,5.999850e+001,-8.331040e-004,0.000000e+000,1.441975e-002,0.000000e+000,3,9.308438e-001,1.825000e+000,,,,,,,,,,,,,,,,,,0,5.000000e+000,5.000000e-001,2,1,0.000000e+000,0,0,0,
1473199206.725,,-5.000000e+004,6.000026e+001,-8.346496e-004,0.000000e+000,1.187884e-002,0.000000e+000,3,9.357805e-001,1.825000e+000,,,,,,,,,,,,,,,,,,0,5.000000e+000,5.000000e-001,2,1,3.520966e-003,0,0,0,
1473199384.919,,-4.000000e+004,6.000290e+001,-8.112527e-004,0.000000e+000,1.190813e-002,0.000000e+000,3,9.347944e-001,1.825000e+000,,,,,,,,,,,,,,,,,,0,5.000000e+000,5.000000e-001,2,1,1.758575e-003,0,0,0,
1473199411.848,,-4.000000e+004,6.000026e+001,-8.095787e-004,0.000000e+000,1.168223e-002,0.000000e+000,3,9.347981e-001,1.825000e+000,,,,,,,,,,,,,,,,,,0,5.000000e+000,5.000000e-001,2,1,3.520966e-003,0,0,0,
1473199589.559,,-3.000000e+004,5.999498e+001,-7.793463e-004,0.000000e+000,1.055122e-002,0.000000e+000,3,9.333526e-001,1.825000e+000,,,,,,,,,,,,,,,,,,0,5.000000e+000,5.000000e-001,2,1,3.509521e-003,0,0,0,
1473199614.037,,-3.000000e+004,5.999234e+001,-7.793657e-004,0.000000e+000,1.054768e-002,0.000000e+000,3,9.331788e-001,1.825000e+000,,,,,,,,,,,,,,,,,,0,5.000000e+000,5.000000e-001,2,1,1.936340e-002,0,0,0,
1473199788.231,,-2.000000e+004,6.000114e+001,-7.373429e-004,0.000000e+000,9.431277e-003,0.000000e+000,3,9.307071e-001,1.825000e+000,,,,,,,,,,,,,,,,,,0,5.000000e+000,5.000000e-001,2,1,5.279541e-003,0,0,0,
1473199811.473,,-2.000000e+004,6.000026e+001,-7.373494e-004,0.000000e+000,9.703672e-003,0.000000e+000,3,9.307297e-001,1.825000e+000,,,,,,,,,,,,,,,,,,0,5.000000e+000,5.000000e-001,2,1,3.520966e-003,0,1,0,
1473199988.167,,-1.000000e+004,6.000201e+001,-6.708120e-004,0.000000e+000,7.942913e-003,0.000000e+000,3,9.256222e-001,1.825000e+000,,,,,,,,,,,,,,,,,,0,5.000000e+000,5.000000e-001,2,1,3.528595e-003,0,1,0,
1473200011.845,,-1.000000e+004,6.000378e+001,-6.712723e-004,0.000000e+000,8.144598e-003,0.000000e+000,3,9.250485e-001,1.825000e+000,,,,,,,,,,,,,,,,,,0,5.000000e+000,5.000000e-001,2,1,0.000000e+000,0,1,0,
1473200147.497,,-9.000000e+003,6.000554e+001,-6.621170e-004,0.000000e+000,8.160010e-003,0.000000e+000,3,9.248009e-001,1.825000e+000,,,,,,,,,,,,,,,,,,0,5.000000e+000,5.000000e-001,2,1,7.038116e-003,0,1,0,
1473200173.534,,-9.000000e+003,5.999937e+001,-6.623234e-004,0.000000e+000,7.921544e-003,0.000000e+000,3,9.247357e-001,1.825000e+000,,,,,,,,,,,,,,,,,,0,5.000000e+000,5.000000e-001,2,1,1.750946e-003,0,1,0,
1473200310.990,,-7.000000e+003,6.000026e+001,-6.403398e-004,0.000000e+000,7.292048e-003,0.000000e+000,3,9.232843e-001,1.825000e+000,,,,,,,,,,,,,,,,,,0,5.000000e+000,5.000000e-001,2,1,3.520966e-003,0,1,0,
1473200335.224,,-7.000000e+003,6.000201e+001,-6.405118e-004,0.000000e+000,7.720891e-003,0.000000e+000,3,9.233670e-001,1.825000e+000,,,,,,,,,,,,,,,,,,0,5.000000e+000,5.000000e-001,2,1,3.528595e-003,0,1,0,
1473200467.465,,-5.000000e+003,5.999849e+001,-6.151570e-004,0.000000e+000,7.208187e-003,0.000000e+000,3,9.214220e-001,1.825000e+000,,,,,,,,,,,,,,,,,,0,5.000000e+000,5.000000e-001,2,1,3.520966e-003,0,1,0,
1473200493.190,,-5.000000e+003,5.999674e+001,-6.149260e-004,0.000000e+000,7.274942e-003,0.000000e+000,3,9.219208e-001,1.825000e+000,,,,,,,,,,,,,,,,,,0,5.000000e+000,5.000000e-001,2,1,3.520966e-003,0,0,0,
1473200620.174,,-3.000000e+003,5.999850e+001,-5.817867e-004,0.000000e+000,7.312345e-003,0.000000e+000,3,9.215473e-001,1.825000e+000,,,,,,,,,,,,,,,,,,0,5.000000e+000,5.000000e-001,2,1,7.041931e-003,0,0,0,
1473200643.947,,-3.000000e+003,6.000025e+001,-5.818153e-004,0.000000e+000,7.175107e-003,0.000000e+000,3,9.205673e-001,1.825000e+000,,,,,,,,,,,,,,,,,,0,5.000000e+000,5.000000e-001,2,1,0.000000e+000,0,0,0,
1473200781.891,,-1.000000e+003,5.999322e+001,-5.307154e-004,0.000000e+000,7.854757e-003,0.000000e+000,3,9.337960e-001,1.825000e+000,,,,,,,,,,,,,,,,,,0,5.000000e+000,5.000000e-001,2,1,1.407242e-002,0,0,0,
1473200805.924,,-1.000000e+003,6.000466e+001,-5.295352e-004,0.000000e+000,9.623424e-003,0.000000e+000,3,9.329229e-001,1.825000e+000,,,,,,,,,,,,,,,,,,0,5.000000e+000,5.000000e-001,2,1,1.231766e-002,0,0,0,
1473200943.914,,-7.000000e+002,5.999586e+001,-5.165261e-004,0.000000e+000,1.122297e-002,0.000000e+000,3,9.384900e-001,1.825000e+000,,,,,,,,,,,,,,,,,,0,5.000000e+000,5.000000e-001,2,1,1.935959e-002,0,0,0,
1473200969.843,,-7.000000e+002,5.999849e+001,-5.165049e-004,0.000000e+000,1.066519e-002,0.000000e+000,3,9.387927e-001,1.825000e+000,,,,,,,,,,,,,,,,,,0,5.000000e+000,5.000000e-001,2,1,3.520966e-003,0,0,0,
1473201101.536,,-6.000000e+002,5.999674e+001,-5.121475e-004,0.000000e+000,9.912947e-003,0.000000e+000,3,9.438593e-001,1.825000e+000,,,,,,,,,,,,,,,,,,0,5.000000e+000,5.000000e-001,2,1,3.520966e-003,0,0,0,
1473201125.268,,-6.000000e+002,5.999586e+001,-5.122693e-004,0.000000e+000,1.124567e-002,0.000000e+000,3,9.419671e-001,1.825000e+000,,,,,,,,,,,,,,,,,,0,5.000000e+000,5.000000e-001,2,1,1.750946e-003,0,0,0,
1473201260.708,,-5.000000e+002,6.000025e+001,-5.052331e-004,0.000000e+000,1.150891e-002,0.000000e+000,3,9.474934e-001,1.825000e+000,,,,,,,,,,,,,,,,,,0,5.000000e+000,5.000000e-001,2,1,0.000000e+000,0,0,0,
1473201286.136,,-5.000000e+002,5.999850e+001,-5.053222e-004,0.000000e+000,1.209255e-002,0.000000e+000,3,9.458891e-001,1.825000e+000,,,,,,,,,,,,,,,,,,0,5.000000e+000,5.000000e-001,2,1,7.041931e-003,0,0,0,
1473201417.625,,-4.000000e+002,5.999937e+001,-4.972912e-004,0.000000e+000,1.220324e-002,0.000000e+000,3,9.524512e-001,1.825000e+000,,,,,,,,,,,,,,,,,,0,5.000000e+000,5.000000e-001,2,1,1.750946e-003,0,1,0,
1473201442.554,,-4.000000e+002,6.000026e+001,-4.973886e-004,0.000000e+000,1.213461e-002,0.000000e+000,3,9.529446e-001,1.825000e+000,,,,,,,,,,,,,,,,,,0,5.000000e+000,5.000000e-001,2,1,1.055908e-002,0,1,0,
1473201570.243,,-3.000000e+002,6.000026e+001,-4.851866e-004,0.000000e+000,1.384927e-002,0.000000e+000,3,9.590142e-001,1.825000e+000,,,,,,,,,,,,,,,,,,0,5.000000e+000,5.000000e-001,2,1,3.520966e-003,0,1,0,
1473201596.226,,-3.000000e+002,6.000026e+001,-4.857440e-004,0.000000e+000,1.321177e-002,0.000000e+000,3,9.577872e-001,1.825000e+000,,,,,,,,,,,,,,,,,,0,5.000000e+000,5.000000e-001,2,1,1.055908e-002,0,1,0,
1473201728.132,,-2.000000e+002,6.000201e+001,-4.624698e-004,0.000000e+000,1.598743e-002,0.000000e+000,3,9.606675e-001,1.825000e+000,,,,,,,,,,,,,,,,,,0,5.000000e+000,5.000000e-001,2,1,3.528595e-003,0,1,0,
1473201753.419,,-2.000000e+002,6.000202e+001,-4.652161e-004,0.000000e+000,1.427657e-002,0.000000e+000,3,9.644705e-001,1.825000e+000,,,,,,,,,,,,,,,,,,0,5.000000e+000,5.000000e-001,2,1,0.000000e+000,0,1,0,
1473201873.107,,-1.800000e+002,6.000202e+001,-4.598699e-004,0.000000e+000,1.450464e-002,0.000000e+000,3,9.657868e-001,1.825000e+000,,,,,,,,,,,,,,,,,,0,5.000000e+000,5.000000e-001,2,1,7.038116e-003,0,1,0,
1473201898.786,,-1.800000e+002,5.999937e+001,-4.591333e-004,0.000000e+000,1.518135e-002,0.000000e+000,3,9.662273e-001,1.825000e+000,,,,,,,,,,,,,,,,,,0,5.000000e+000,5.000000e-001,2,1,1.750946e-003,0,1,0,
1473202017.519,,-1.600000e+002,5.999937e+001,-4.523945e-004,0.000000e+000,1.436515e-002,0.000000e+000,3,9.669461e-001,1.825000e+000,,,,,,,,,,,,,,,,,,0,5.000000e+000,5.000000e-001,2,1,1.750946e-003,0,1,0,
1473202041.992,,-1.600000e+002,6.000114e+001,-4.526347e-004,0.000000e+000,1.371856e-002,0.000000e+000,3,9.684399e-001,1.825000e+000,,,,,,,,,,,,,,,,,,0,5.000000e+000,5.000000e-001,2,1,1.770020e-003,0,0,0,
1473202162.455,,-1.400000e+002,5.999586e+001,-4.436324e-004,0.000000e+000,1.514203e-002,0.000000e+000,3,9.701303e-001,1.825000e+000,,,,,,,,,,,,,,,,,,0,5.000000e+000,5.000000e-001,2,1,8.792877e-003,0,0,0,
1473202184.384,,-1.400000e+002,5.999762e+001,-4.436410e-004,0.000000e+000,1.449001e-002,0.000000e+000,3,9.704600e-001,1.825000e+000,,,,,,,,,,,,,,,,,,0,5.000000e+000,5.000000e-001,2,1,1.770020e-003,0,0,0,
1473202307.616,,-1.200000e+002,5.999762e+001,-4.309052e-004,0.000000e+000,1.191273e-002,0.000000e+000,3,9.687962e-001,1.825000e+000,,,,,,,,,,,,,,,,,,0,5.000000e+000,5.000000e-001,2,1,1.770020e-003,0,0,0,
1473202331.295,,-1.200000e+002,5.999937e+001,-4.337172e-004,0.000000e+000,1.395522e-002,0.000000e+000,3,9.725580e-001,1.825000e+000,,,,,,,,,,,,,,,,,,0,5.000000e+000,5.000000e-001,2,1,1.750946e-003,0,0,0,
1473202456.793,,-1.000000e+002,5.999498e+001,-4.198972e-004,0.000000e+000,1.564885e-002,0.000000e+000,3,9.750267e-001,1.825000e+000,,,,,,,,,,,,,,,,,,0,5.000000e+000,5.000000e-001,2,1,0.000000e+000,0,0,0,
1473202480.007,,-1.000000e+002,6.000202e+001,-4.199753e-004,0.000000e+000,1.417696e-002,0.000000e+000,3,9.732546e-001,1.825000e+000,,,,,,,,,,,,,,,,,,0,5.000000e+000,5.000000e-001,2,1,1.408005e-002,0,0,0,
1473202598.948,,-8.000000e+001,6.000201e+001,-4.026309e-004,0.000000e+000,1.555171e-002,0.000000e+000,3,9.750360e-001,1.825000e+000,,,,,,,,,,,,,,,,,,0,5.000000e+000,5.000000e-001,2,1,1.057053e-002,0,0,0,
1473202623.126,,-8.000000e+001,6.000201e+001,-4.036983e-004,0.000000e+000,1.501027e-002,0.000000e+000,3,9.753302e-001,1.825000e+000,,,,,,,,,,,,,,,,,,0,5.000000e+000,5.000000e-001,2,1,3.528595e-003,0,0,0,
1473202743.374,,-6.000000e+001,5.999937e+001,-3.799092e-004,0.000000e+000,1.470476e-002,0.000000e+000,3,9.778917e-001,1.825000e+000,,,,,,,,,,,,,,,,,,0,5.000000e+000,5.000000e-001,2,1,1.750946e-003,0,0,0,
1473202768.361,,-6.000000e+001,5.999586e+001,-3.797314e-004,0.000000e+000,1.599762e-002,0.000000e+000,3,9.774432e-001,1.825000e+000,,,,,,,,,,,,,,,,,,0,5.000000e+000,5.000000e-001,2,1,1.750946e-003,0,0,0,
1473202891.591,,-4.000000e+001,6.000025e+001,-3.454304e-004,0.000000e+000,1.535550e-002,0.000000e+000,3,9.800550e-001,1.825000e+000,,,,,,,,,,,,,,,,,,0,5.000000e+000,5.000000e-001,2,1,0.000000e+000,0,0,0,
1473202915.519,,-4.000000e+001,5.999673e+001,-3.463052e-004,0.000000e+000,1.571877e-002,0.000000e+000,3,9.792149e-001,1.825000e+000,,,,,,,,,,,,,,,,,,0,5.000000e+000,5.000000e-001,2,1,0.000000e+000,0,0,0,
1473203040.263,,-2.000000e+001,5.999322e+001,-2.873102e-004,0.000000e+000,1.490018e-002,0.000000e+000,3,9.823104e-001,1.825000e+000,,,,,,,,,,,,,,,,,,0,5.000000e+000,5.000000e-001,2,1,3.520966e-003,0,1,0,
1473203064.956,,-2.000000e+001,5.999146e+001,-2.859414e-004,0.000000e+000,1.365992e-002,0.000000e+000,3,9.821262e-001,1.825000e+000,,,,,,,,,,,,,,,,,,0,5.000000e+000,5.000000e-001,2,1,3.520966e-003,0,1,0,
1473203215.069,,0.000000e+000,6.000290e+001,4.405852e-005,0.000000e+000,5.289113e-003,0.000000e+000,3,9.706756e-001,1.825000e+000,,,,,,,,,,,,,,,,,,0,5.000000e+000,5.000000e-001,2,1,5.287170e-003,0,1,0,
1473203240.110,,0.000000e+000,6.000465e+001,5.174934e-005,0.000000e+000,1.129020e-002,0.000000e+000,3,9.727117e-001,1.825000e+000,,,,,,,,,,,,,,,,,,0,5.000000e+000,5.000000e-001,2,1,8.808136e-003,0,1,0,
1473203382.709,,2.000000e+001,6.000202e+001,3.437542e-004,0.000000e+000,1.698932e-002,0.000000e+000,3,9.809926e-001,1.825000e+000,,,,,,,,,,,,,,,,,,0,5.000000e+000,5.000000e-001,2,1,0.000000e+000,0,1,0,
1473203407.640,,2.000000e+001,6.000290e+001,3.440359e-004,0.000000e+000,1.627939e-002,0.000000e+000,3,9.811472e-001,1.825000e+000,,,,,,,,,,,,,,,,,,0,5.000000e+000,5.000000e-001,2,1,1.758575e-003,0,1,0,
1473203529.329,,4.000000e+001,5.999498e+001,3.817637e-004,0.000000e+000,1.672020e-002,0.000000e+000,3,9.791888e-001,1.825000e+000,,,,,,,,,,,,,,,,,,0,5.000000e+000,5.000000e-001,2,1,1.408005e-002,0,1,0,
1473203552.325,,4.000000e+001,6.000026e+001,3.824755e-004,0.000000e+000,1.628983e-002,0.000000e+000,3,9.790299e-001,1.825000e+000,,,,,,,,,,,,,,,,,,0,5.000000e+000,5.000000e-001,2,1,3.520966e-003,0,1,0,
1473203675.770,,6.000000e+001,5.999850e+001,4.068002e-004,0.000000e+000,1.728187e-002,0.000000e+000,3,9.774824e-001,1.825000e+000,,,,,,,,,,,,,,,,,,0,5.000000e+000,5.000000e-001,2,1,0.000000e+000,0,0,0,
1473203698.767,,6.000000e+001,5.999849e+001,4.065642e-004,0.000000e+000,1.585749e-002,0.000000e+000,3,9.778570e-001,1.825000e+000,,,,,,,,,,,,,,,,,,0,5.000000e+000,5.000000e-001,2,1,3.520966e-003,0,0,0,
1473203821.254,,8.000000e+001,5.999322e+001,4.233584e-004,0.000000e+000,1.559116e-002,0.000000e+000,3,9.757861e-001,1.825000e+000,,,,,,,,,,,,,,,,,,0,5.000000e+000,5.000000e-001,2,1,1.055908e-002,0,0,0,
1473203845.932,,8.000000e+001,6.000026e+001,4.235754e-004,0.000000e+000,1.584534e-002,0.000000e+000,3,9.762350e-001,1.825000e+000,,,,,,,,,,,,,,,,,,0,5.000000e+000,5.000000e-001,2,1,3.520966e-003,0,0,0,
1473203965.120,,1.000000e+002,6.000290e+001,4.362889e-004,0.000000e+000,1.593921e-002,0.000000e+000,3,9.732916e-001,1.825000e+000,,,,,,,,,,,,,,,,,,0,5.000000e+000,5.000000e-001,2,1,5.287170e-003,0,0,0,
1473203990.576,,1.000000e+002,5.999586e+001,4.370788e-004,0.000000e+000,1.531039e-002,0.000000e+000,3,9.742118e-001,1.825000e+000,,,,,,,,,,,,,,,,,,0,5.000000e+000,5.000000e-001,2,1,1.750946e-003,0,0,0,
1473204109.587,,1.200000e+002,5.999674e+001,4.475457e-004,0.000000e+000,1.446515e-002,0.000000e+000,3,9.728813e-001,1.825000e+000,,,,,,,,,,,,,,,,,,0,5.000000e+000,5.000000e-001,2,1,1.759720e-002,0,0,0,
1473204135.449,,1.200000e+002,6.000290e+001,4.469508e-004,0.000000e+000,1.487426e-002,0.000000e+000,3,9.724799e-001,1.825000e+000,,,,,,,,,,,,,,,,,,0,5.000000e+000,5.000000e-001,2,1,1.758575e-003,0,0,0,
1473204253.495,,1.400000e+002,6.000201e+001,4.547207e-004,0.000000e+000,1.458055e-002,0.000000e+000,3,9.710436e-001,1.825000e+000,,,,,,,,,,,,,,,,,,0,5.000000e+000,5.000000e-001,2,1,3.528595e-003,0,0,0,
1473204281.424,,1.400000e+002,5.999762e+001,4.554592e-004,0.000000e+000,1.522205e-002,0.000000e+000,3,9.697002e-001,1.825000e+000,,,,,,,,,,,,,,,,,,0,5.000000e+000,5.000000e-001,2,1,1.770020e-003,0,0,0,
1473204407.963,,1.600000e+002,5.999937e+001,4.620403e-004,0.000000e+000,1.466925e-002,0.000000e+000,3,9.693059e-001,1.825000e+000,,,,,,,,,,,,,,,,,,0,5.000000e+000,5.000000e-001,2,1,1.750946e-003,0,0,0,
1473204434.446,,1.600000e+002,5.999850e+001,4.627084e-004,0.000000e+000,1.384470e-002,0.000000e+000,3,9.690231e-001,1.825000e+000,,,,,,,,,,,,,,,,,,0,5.000000e+000,5.000000e-001,2,1,0.000000e+000,0,0,0,
1473204561.923,,1.800000e+002,5.999850e+001,4.683056e-004,0.000000e+000,1.516802e-002,0.000000e+000,3,9.660628e-001,1.825000e+000,,,,,,,,,,,,,,,,,,0,5.000000e+000,5.000000e-001,2,1,0.000000e+000,0,1,0,
1473204586.148,,1.800000e+002,5.999850e+001,4.685444e-004,0.000000e+000,1.391712e-002,0.000000e+000,3,9.679535e-001,1.825000e+000,,,,,,,,,,,,,,,,,,0,5.000000e+000,5.000000e-001,2,1,7.041931e-003,0,1,0,
1473204705.415,,2.000000e+002,6.000025e+001,4.730807e-004,0.000000e+000,1.444283e-002,0.000000e+000,3,9.647348e-001,1.825000e+000,,,,,,,,,,,,,,,,,,0,5.000000e+000,5.000000e-001,2,1,0.000000e+000,0,1,0,
1473204729.617,,2.000000e+002,6.000026e+001,4.734719e-004,0.000000e+000,1.345601e-002,0.000000e+000,3,9.666597e-001,1.825000e+000,,,,,,,,,,,,,,,,,,0,5.000000e+000,5.000000e-001,2,1,3.520966e-003,0,1,0,
1473204860.806,,3.000000e+002,6.000290e+001,4.911228e-004,0.000000e+000,1.375457e-002,0.000000e+000,3,9.586492e-001,1.825000e+000,,,,,,,,,,,,,,,,,,0,5.000000e+000,5.000000e-001,2,1,1.758575e-003,0,1,0,
1473204885.507,,3.000000e+002,6.000554e+001,4.900210e-004,0.000000e+000,1.360701e-002,0.000000e+000,3,9.591954e-001,1.825000e+000,,,,,,,,,,,,,,,,,,0,5.000000e+000,5.000000e-001,2,1,7.038116e-003,0,1,0,
1473205020.178,,4.000000e+002,5.999850e+001,5.007023e-004,0.000000e+000,1.301902e-002,0.000000e+000,3,9.519525e-001,1.825000e+000,,,,,,,,,,,,,,,,,,0,5.000000e+000,5.000000e-001,2,1,0.000000e+000,0,1,0,
1473205044.018,,4.000000e+002,6.000114e+001,5.006758e-004,0.000000e+000,1.256015e-002,0.000000e+000,3,9.530399e-001,1.825000e+000,,,,,,,,,,,,,,,,,,0,5.000000e+000,5.000000e-001,2,1,5.279541e-003,0,1,0,
1473205177.162,,5.000000e+002,6.000290e+001,5.082252e-004,0.000000e+000,1.178648e-002,0.000000e+000,3,9.475493e-001,1.825000e+000,,,,,,,,,,,,,,,,,,0,5.000000e+000,5.000000e-001,2,1,5.287170e-003,0,1,0,
1473205201.041,,5.000000e+002,5.999674e+001,5.088121e-004,0.000000e+000,1.165334e-002,0.000000e+000,3,9.463949e-001,1.825000e+000,,,,,,,,,,,,,,,,,,0,5.000000e+000,5.000000e-001,2,1,3.520966e-003,0,1,0,
1473205326.285,,6.000000e+002,5.999322e+001,5.143638e-004,0.000000e+000,1.116379e-002,0.000000e+000,3,9.439350e-001,1.825000e+000,,,,,,,,,,,,,,,,,,0,5.000000e+000,5.000000e-001,2,1,2.112198e-002,0,0,0,
1473205349.259,,6.000000e+002,5.999849e+001,5.142045e-004,0.000000e+000,1.138359e-002,0.000000e+000,3,9.435462e-001,1.825000e+000,,,,,,,,,,,,,,,,,,0,5.000000e+000,5.000000e-001,2,1,3.520966e-003,0,0,0,
1473205484.504,,7.000000e+002,5.999146e+001,5.213498e-004,0.000000e+000,1.139806e-002,0.000000e+000,3,9.388204e-001,1.825000e+000,,,,,,,,,,,,,,,,,,0,5.000000e+000,5.000000e-001,2,1,1.055145e-002,0,0,0,
1473205511.206,,7.000000e+002,6.000026e+001,5.189383e-004,0.000000e+000,1.107010e-002,0.000000e+000,3,9.388969e-001,1.825000e+000,,,,,,,,,,,,,,,,,,0,5.000000e+000,5.000000e-001,2,1,3.520966e-003,0,0,0,
1473205641.734,,1.000000e+003,6.000026e+001,5.305619e-004,0.000000e+000,1.004663e-002,0.000000e+000,3,9.320512e-001,1.825000e+000,,,,,,,,,,,,,,,,,,0,5.000000e+000,5.000000e-001,2,1,7.049561e-003,0,0,0,
1473205666.160,,1.000000e+003,5.999937e+001,5.303201e-004,0.000000e+000,9.649499e-003,0.000000e+000,3,9.325201e-001,1.825000e+000,,,,,,,,,,,,,,,,,,0,5.000000e+000,5.000000e-001,2,1,5.290985e-003,0,0,0,
1473205802.663,,3.000000e+003,5.999410e+001,5.816577e-004,0.000000e+000,7.926106e-003,0.000000e+000,3,9.212880e-001,1.825000e+000,,,,,,,,,,,,,,,,,,0,5.000000e+000,5.000000e-001,2,1,8.800507e-003,0,0,0,
1473205827.811,,3.000000e+003,6.000730e+001,5.816678e-004,0.000000e+000,7.675618e-003,0.000000e+000,3,9.205261e-001,1.825000e+000,,,,,,,,,,,,,,,,,,0,5.000000e+000,5.000000e-001,2,1,1.760101e-002,0,0,0,
1473205964.682,,5.000000e+003,6.000114e+001,6.156400e-004,0.000000e+000,7.595262e-003,0.000000e+000,3,9.214758e-001,1.825000e+000,,,,,,,,,,,,,,,,,,0,5.000000e+000,5.000000e-001,2,1,1.583862e-002,0,0,0,
1473205992.408,,5.000000e+003,5.999937e+001,6.156121e-004,0.000000e+000,7.772165e-003,0.000000e+000,3,9.213075e-001,1.825000e+000,,,,,,,,,,,,,,,,,,0,5.000000e+000,5.000000e-001,2,1,1.750946e-003,0,0,0,
1473206132.838,,7.000000e+003,5.999586e+001,6.413754e-004,0.000000e+000,8.214068e-003,0.000000e+000,3,9.233982e-001,1.825000e+000,,,,,,,,,,,,,,,,,,0,5.000000e+000,5.000000e-001,2,1,1.232147e-002,0,1,0,
1473206157.011,,7.000000e+003,5.999937e+001,6.414944e-004,0.000000e+000,8.312117e-003,0.000000e+000,3,9.232033e-001,1.825000e+000,,,,,,,,,,,,,,,,,,0,5.000000e+000,5.000000e-001,2,1,1.750946e-003,0,1,0,
1473206293.174,,9.000000e+003,5.999937e+001,6.624754e-004,0.000000e+000,8.571308e-003,0.000000e+000,3,9.248622e-001,1.825000e+000,,,,,,,,,,,,,,,,,,0,5.000000e+000,5.000000e-001,2,1,1.750946e-003,0,1,0,
1473206318.632,,9.000000e+003,5.999850e+001,6.621929e-004,0.000000e+000,8.616393e-003,0.000000e+000,3,9.250404e-001,1.825000e+000,,,,,,,,,,,,,,,,,,0,5.000000e+000,5.000000e-001,2,1,0.000000e+000,0,1,0,
1473206449.849,,1.000000e+004,6.000201e+001,6.714948e-004,0.000000e+000,9.220923e-003,0.000000e+000,3,9.250324e-001,1.825000e+000,,,,,,,,,,,,,,,,,,0,5.000000e+000,5.000000e-001,2,1,3.528595e-003,0,1,0,
1473206474.839,,1.000000e+004,6.000642e+001,6.711083e-004,0.000000e+000,8.089105e-003,0.000000e+000,3,9.260065e-001,1.825000e+000,,,,,,,,,,,,,,,,,,0,5.000000e+000,5.000000e-001,2,1,5.279541e-003,0,1,0,
1473206646.324,,2.000000e+004,6.000201e+001,7.365859e-004,0.000000e+000,1.237075e-002,0.000000e+000,3,9.277251e-001,1.825000e+000,,,,,,,,,,,,,,,,,,0,5.000000e+000,5.000000e-001,2,1,3.528595e-003,0,1,0,
1473206671.043,,2.000000e+004,5.999762e+001,7.369287e-004,0.000000e+000,1.296099e-002,0.000000e+000,3,9.305001e-001,1.825000e+000,,,,,,,,,,,,,,,,,,0,5.000000e+000,5.000000e-001,2,1,1.770020e-003,0,1,0,
1473206846.153,,3.000000e+004,5.999937e+001,7.807899e-004,0.000000e+000,8.475003e-003,0.000000e+000,3,9.306410e-001,1.825000e+000,,,,,,,,,,,,,,,,,,0,5.000000e+000,5.000000e-001,2,1,1.750946e-003,0,0,0,
1473206870.188,,3.000000e+004,5.999849e+001,7.819469e-004,0.000000e+000,1.326498e-002,0.000000e+000,3,9.299231e-001,1.825000e+000,,,,,,,,,,,,,,,,,,0,5.000000e+000,5.000000e-001,2,1,3.520966e-003,0,0,0,
1473207045.568,,4.000000e+004,5.999498e+001,8.111300e-004,0.000000e+000,1.220490e-002,0.000000e+000,3,9.356906e-001,1.825000e+000,,,,,,,,,,,,,,,,,,0,5.000000e+000,5.000000e-001,2,1,3.509521e-003,0,0,0,
1473207069.355,,4.000000e+004,5.999762e+001,8.161864e-004,0.000000e+000,1.314863e-002,0.000000e+000,3,9.319145e-001,1.825000e+000,,,,,,,,,,,,,,,,,,0,5.000000e+000,5.000000e-001,2,1,1.770020e-003,0,0,0,
1473207261.563,,5.000000e+004,6.000026e+001,8.324001e-004,0.000000e+000,1.368535e-002,0.000000e+000,3,9.355860e-001,1.825000e+000,,,,,,,,,,,,,,,,,,0,5.000000e+000,5.000000e-001,2,1,1.055908e-002,0,0,0,
1473207298.013,,5.000000e+004,6.000025e+001,8.331838e-004,0.000000e+000,1.370857e-002,0.000000e+000,3,9.358209e-001,1.825000e+000,,,,,,,,,,,,,,,,,,0,5.000000e+000,5.000000e-001,2,1,0.000000e+000,0,0,0,
1473207479.720,,6.000000e+004,5.999673e+001,8.513539e-004,0.000000e+000,1.446850e-002,0.000000e+000,3,9.363361e-001,1.825000e+000,,,,,,,,,,,,,,,,,,0,5.000000e+000,5.000000e-001,2,1,0.000000e+000,0,0,0,
1473207503.974,,6.000000e+004,5.999674e+001,8.514249e-004,0.000000e+000,1.452605e-002,0.000000e+000,3,9.363630e-001,1.825000e+000,,,,,,,,,,,,,,,,,,0,5.000000e+000,5.000000e-001,2,1,3.520966e-003,0,0,0,
1473207680.453,,7.000000e+004,6.000202e+001,8.660688e-004,0.000000e+000,1.501465e-002,0.000000e+000,3,9.366785e-001,1.825000e+000,,,,,,,,,,,,,,,,,,0,5.000000e+000,5.000000e-001,2,1,0.000000e+000,0,1,0,
1473207704.934,,7.000000e+004,6.000201e+001,8.653831e-004,0.000000e+000,1.470349e-002,0.000000e+000,3,9.354679e-001,1.825000e+000,,,,,,,,,,,,,,,,,,0,5.000000e+000,5.000000e-001,2,1,3.528595e-003,0,1,0,
1473207716.398,,7.000000e+004,5.999937e+001,8.661696e-004,0.000000e+000,1.523454e-002,0.000000e+000,3,9.366658e-001,1.825000e+000,,,,,,,,,,,,,,,,,,0,5.000000e+000,5.000000e-001,2,1,1.750946e-003,0,1,0,