File: data/A344/A344_GdN_MH_075K_160905.rso.dat
[Header]
TITLE,MPMS RSO Measurement
BYAPP,MPMS Measurement,1.1,Summary
FILEOPENTIME, 1473245263.458000 9/7/2016, 10:47:43 PM

INFO, APPNAME, MPMS MultiVu Application, Revision 1.61,  Build 082

INFO, NAME, A344
INFO, WEIGHT, 10.500
INFO, AREA, 1.000
INFO, LENGTH, 1.000
INFO, SHAPE, 0
INFO, COMMENT, m = 0.0105g
INFO, SEQUENCE FILE: 7T_hysteresis_sweep_hi_res_zero_n4.seq


INFO, BACKGROUND DATA FILE:, None


STARTUPAXIS,X,4,LINEAR,AUTO,0.000000,0.000000
STARTUPAXIS,Y1,5,LINEAR,AUTO,0.000000,0.000000


STARTUPGROUP,Longitudinal
FIELDGROUP,Longitudinal,1,2,3,4,5,6,7,8,9,10,11,19,20,21,22,23,35
FIELDGROUP,Transverse,1,2,3,4,12,13,14,15,16,17,18,24,25,26,27,28,35

PLOT_APPEARANCE,ALL,HORZ_GRID_ON,VERT_GRID_ON,MARKERS_AND_LINES

[Data]
Time,Comment,Field (Oe),Temperature (K),Long Moment (emu),Long Scan Std Dev,Long Offset (cm),Long Offset Std Dev,Long Algorithm,Long Reg Fit,Long Reg Factor,Trans Moment (emu),Trans Scan Std Dev,Trans Offset (cm),Trans Offset Std Dev,Trans Algorithm,Trans Reg Fit,Trans Reg Factor,Long Moment [w/o ABS] (emu),Long Scan Std Dev [w/o ABS],Long Offset [w/o ABS] (cm),Long Offset Std Dev [w/o ABS],Long Reg Fit [w/o ABS],Trans Moment [w/o ABS] (emu),Trans Scan Std Dev [w/o ABS],Trans Offset [w/o ABS] (cm),Trans Offset Std Dev [w/o ABS],Trans Reg Fit [w/o ABS],RSO Position (deg),Amplitude (cm),Frequency,Cycles to Average,Scans per Measurement,Delta Temp (K),Error,EC Comp. Running,Using ABS,
1473245263.457,,7.000000e+004,7.514050e+001,6.859347e-004,0.000000e+000,2.162594e-002,0.000000e+000,3,9.220713e-001,1.825000e+000,,,,,,,,,,,,,,,,,,0,5.000000e+000,5.000000e-001,2,1,3.519440e-002,0,1,0,
1473245289.885,,7.000000e+004,7.507962e+001,6.925412e-004,0.000000e+000,2.085434e-002,0.000000e+000,3,9.241203e-001,1.825000e+000,,,,,,,,,,,,,,,,,,0,5.000000e+000,5.000000e-001,2,1,5.401611e-003,0,1,0,
1473245487.298,,6.000000e+004,7.499590e+001,6.618663e-004,0.000000e+000,2.244133e-002,0.000000e+000,3,9.228436e-001,1.825000e+000,,,,,,,,,,,,,,,,,,0,5.000000e+000,5.000000e-001,2,1,5.409241e-003,0,1,0,
1473245513.504,,6.000000e+004,7.500264e+001,6.682870e-004,0.000000e+000,1.643679e-002,0.000000e+000,3,9.228061e-001,1.825000e+000,,,,,,,,,,,,,,,,,,0,5.000000e+000,5.000000e-001,2,1,2.708435e-003,0,1,0,
1473245686.447,,5.000000e+004,7.499590e+001,6.353831e-004,0.000000e+000,1.948345e-002,0.000000e+000,3,9.196223e-001,1.825000e+000,,,,,,,,,,,,,,,,,,0,5.000000e+000,5.000000e-001,2,1,1.618958e-002,0,1,0,
1473245717.626,,5.000000e+004,7.499994e+001,6.295777e-004,0.000000e+000,2.136535e-002,0.000000e+000,3,9.124169e-001,1.825000e+000,,,,,,,,,,,,,,,,,,0,5.000000e+000,5.000000e-001,2,1,2.693176e-003,0,1,0,
1473245896.267,,4.000000e+004,7.499860e+001,5.908664e-004,0.000000e+000,1.872290e-002,0.000000e+000,3,9.166632e-001,1.825000e+000,,,,,,,,,,,,,,,,,,0,5.000000e+000,5.000000e-001,2,1,1.081085e-002,0,1,0,
1473245922.366,,4.000000e+004,7.499860e+001,5.916820e-004,0.000000e+000,1.723809e-002,0.000000e+000,3,9.163066e-001,1.825000e+000,,,,,,,,,,,,,,,,,,0,5.000000e+000,5.000000e-001,2,1,5.386353e-003,0,1,0,
1473246100.814,,3.000000e+004,7.499590e+001,5.350820e-004,0.000000e+000,1.262629e-002,0.000000e+000,3,9.064296e-001,1.825000e+000,,,,,,,,,,,,,,,,,,0,5.000000e+000,5.000000e-001,2,1,2.157593e-002,0,1,0,
1473246127.742,,3.000000e+004,7.500129e+001,5.352392e-004,0.000000e+000,1.503537e-002,0.000000e+000,3,9.079002e-001,1.825000e+000,,,,,,,,,,,,,,,,,,0,5.000000e+000,5.000000e-001,2,1,0.000000e+000,0,1,0,
1473246304.008,,2.000000e+004,7.499860e+001,4.511016e-004,0.000000e+000,1.208639e-002,0.000000e+000,3,8.927986e-001,1.825000e+000,,,,,,,,,,,,,,,,,,0,5.000000e+000,5.000000e-001,2,1,0.000000e+000,0,1,0,
1473246331.663,,2.000000e+004,7.500398e+001,4.513380e-004,0.000000e+000,9.655683e-003,0.000000e+000,3,8.942233e-001,1.825000e+000,,,,,,,,,,,,,,,,,,0,5.000000e+000,5.000000e-001,2,1,5.393982e-003,0,1,0,
1473246503.740,,1.000000e+004,7.499994e+001,3.105769e-004,0.000000e+000,3.264757e-003,0.000000e+000,3,8.504289e-001,1.825000e+000,,,,,,,,,,,,,,,,,,0,5.000000e+000,5.000000e-001,2,1,2.693176e-003,0,1,0,
1473246532.169,,1.000000e+004,7.500130e+001,3.104650e-004,0.000000e+000,3.919356e-003,0.000000e+000,3,8.515221e-001,1.825000e+000,,,,,,,,,,,,,,,,,,0,5.000000e+000,5.000000e-001,2,1,5.401611e-003,0,1,0,
1473246665.112,,9.000000e+003,7.499455e+001,2.900975e-004,0.000000e+000,1.047483e-003,0.000000e+000,3,8.378922e-001,1.825000e+000,,,,,,,,,,,,,,,,,,0,5.000000e+000,5.000000e-001,2,1,1.889038e-002,0,1,0,
1473246693.063,,9.000000e+003,7.499994e+001,2.897209e-004,0.000000e+000,2.732237e-003,0.000000e+000,3,8.393858e-001,1.825000e+000,,,,,,,,,,,,,,,,,,0,5.000000e+000,5.000000e-001,2,1,2.693176e-003,0,1,0,
1473246830.503,,7.000000e+003,7.499994e+001,2.416571e-004,0.000000e+000,-3.061310e-003,0.000000e+000,3,8.140301e-001,1.825000e+000,,,,,,,,,,,,,,,,,,0,5.000000e+000,5.000000e-001,2,1,2.693176e-003,0,1,0,
1473246855.212,,7.000000e+003,7.498647e+001,2.412076e-004,0.000000e+000,-2.117180e-003,0.000000e+000,3,8.134223e-001,1.825000e+000,,,,,,,,,,,,,,,,,,0,5.000000e+000,5.000000e-001,2,1,4.585266e-002,0,1,0,
1473246993.656,,5.000000e+003,7.499455e+001,1.811565e-004,0.000000e+000,-1.370754e-002,0.000000e+000,3,7.540614e-001,1.825000e+000,,,,,,,,,,,,,,,,,,0,5.000000e+000,5.000000e-001,2,1,1.889038e-002,0,1,0,
1473247020.821,,5.000000e+003,7.499860e+001,1.811150e-004,0.000000e+000,-1.210828e-002,0.000000e+000,3,7.544668e-001,1.825000e+000,,,,,,,,,,,,,,,,,,0,5.000000e+000,5.000000e-001,2,1,5.386353e-003,0,1,0,
1473247156.868,,3.000000e+003,7.499725e+001,1.056323e-004,0.000000e+000,-4.473963e-002,0.000000e+000,3,6.039539e-001,1.825000e+000,,,,,,,,,,,,,,,,,,0,5.000000e+000,5.000000e-001,2,1,1.349640e-002,0,1,0,
1473247180.606,,3.000000e+003,7.499860e+001,1.057133e-004,0.000000e+000,-4.587733e-002,0.000000e+000,3,6.078147e-001,1.825000e+000,,,,,,,,,,,,,,,,,,0,5.000000e+000,5.000000e-001,2,1,0.000000e+000,0,1,0,
1473247332.264,,1.000000e+003,7.500130e+001,2.984005e-005,0.000000e+000,-1.256808e+000,0.000000e+000,3,5.904025e-002,1.825000e+000,,,,,,,,,,,,,,,,,,0,5.000000e+000,5.000000e-001,2,1,5.401611e-003,0,1,0,
1473247360.442,,1.000000e+003,7.499994e+001,2.955131e-005,0.000000e+000,-1.254441e+000,0.000000e+000,3,5.108776e-002,1.825000e+000,,,,,,,,,,,,,,,,,,0,5.000000e+000,5.000000e-001,2,1,2.693176e-003,0,1,0,
1473247503.141,,7.000000e+002,7.499319e+001,5.614334e-006,0.000000e+000,0.000000e+000,0.000000e+000,3,0.000000e+000,1.825000e+000,,,,,,,,,,,,,,,,,,0,5.000000e+000,5.000000e-001,2,1,1.618195e-002,0,1,0,
1473247529.569,,7.000000e+002,7.499725e+001,5.947933e-006,0.000000e+000,0.000000e+000,0.000000e+000,3,0.000000e+000,1.825000e+000,,,,,,,,,,,,,,,,,,0,5.000000e+000,5.000000e-001,2,1,2.693176e-003,0,1,0,
1473247662.053,,6.000000e+002,7.499995e+001,1.922376e-006,0.000000e+000,0.000000e+000,0.000000e+000,3,0.000000e+000,1.825000e+000,,,,,,,,,,,,,,,,,,0,5.000000e+000,5.000000e-001,2,1,8.094788e-003,0,1,0,
1473247688.481,,6.000000e+002,7.499994e+001,2.698041e-006,0.000000e+000,0.000000e+000,0.000000e+000,3,0.000000e+000,1.825000e+000,,,,,,,,,,,,,,,,,,0,5.000000e+000,5.000000e-001,2,1,2.693176e-003,0,1,0,
1473247826.207,,5.000000e+002,7.499860e+001,4.937843e-007,0.000000e+000,0.000000e+000,0.000000e+000,3,0.000000e+000,1.825000e+000,,,,,,,,,,,,,,,,,,0,5.000000e+000,5.000000e-001,2,1,5.386353e-003,0,1,0,
1473247855.575,,5.000000e+002,7.499994e+001,3.033312e-007,0.000000e+000,0.000000e+000,0.000000e+000,3,0.000000e+000,1.825000e+000,,,,,,,,,,,,,,,,,,0,5.000000e+000,5.000000e-001,2,1,2.693176e-003,0,1,0,
1473247992.373,,4.000000e+002,7.500534e+001,-8.559044e-007,0.000000e+000,0.000000e+000,0.000000e+000,3,0.000000e+000,1.825000e+000,,,,,,,,,,,,,,,,,,0,5.000000e+000,5.000000e-001,2,1,2.429962e-002,0,1,0,
1473248022.052,,4.000000e+002,7.499860e+001,-1.480430e-006,0.000000e+000,0.000000e+000,0.000000e+000,3,0.000000e+000,1.825000e+000,,,,,,,,,,,,,,,,,,0,5.000000e+000,5.000000e-001,2,1,0.000000e+000,0,1,0,
1473248156.026,,3.000000e+002,7.499049e+001,-2.948915e-006,0.000000e+000,7.853565e-002,0.000000e+000,3,0.000000e+000,1.825000e+000,,,,,,,,,,,,,,,,,,0,5.000000e+000,5.000000e-001,2,1,5.378723e-003,0,1,0,
1473248179.748,,3.000000e+002,7.499725e+001,-2.405204e-006,0.000000e+000,0.000000e+000,0.000000e+000,3,0.000000e+000,1.825000e+000,,,,,,,,,,,,,,,,,,0,5.000000e+000,5.000000e-001,2,1,2.693176e-003,0,1,0,
1473248313.721,,2.000000e+002,7.499860e+001,-2.462361e-006,0.000000e+000,7.618390e-001,0.000000e+000,3,0.000000e+000,1.825000e+000,,,,,,,,,,,,,,,,,,0,5.000000e+000,5.000000e-001,2,1,1.081085e-002,0,1,0,
1473248339.649,,2.000000e+002,7.500130e+001,1.618162e-005,0.000000e+000,-1.400080e+000,0.000000e+000,3,6.072184e-001,1.825000e+000,,,,,,,,,,,,,,,,,,0,5.000000e+000,5.000000e-001,2,1,5.401611e-003,0,1,0,
1473248460.842,,1.800000e+002,7.500670e+001,-2.257511e-006,0.000000e+000,-1.190993e-001,0.000000e+000,3,0.000000e+000,1.825000e+000,,,,,,,,,,,,,,,,,,0,5.000000e+000,5.000000e-001,2,1,5.393982e-003,0,1,0,
1473248489.770,,1.800000e+002,7.500130e+001,-2.919366e-006,0.000000e+000,0.000000e+000,0.000000e+000,3,0.000000e+000,1.825000e+000,,,,,,,,,,,,,,,,,,0,5.000000e+000,5.000000e-001,2,1,5.401611e-003,0,1,0,
1473248621.519,,1.600000e+002,7.498915e+001,-1.891851e-006,0.000000e+000,-1.333549e-001,0.000000e+000,3,0.000000e+000,1.825000e+000,,,,,,,,,,,,,,,,,,0,5.000000e+000,5.000000e-001,2,1,2.427673e-002,0,1,0,
1473248647.230,,1.600000e+002,7.499320e+001,-2.624865e-006,0.000000e+000,1.492001e-002,0.000000e+000,3,0.000000e+000,1.825000e+000,,,,,,,,,,,,,,,,,,0,5.000000e+000,5.000000e-001,2,1,5.401611e-003,0,1,0,
1473248775.179,,1.400000e+002,7.500130e+001,-3.187432e-006,0.000000e+000,4.519037e-002,0.000000e+000,3,0.000000e+000,1.825000e+000,,,,,,,,,,,,,,,,,,0,5.000000e+000,5.000000e-001,2,1,5.401611e-003,0,1,0,
1473248802.858,,1.400000e+002,7.500130e+001,-3.387258e-006,0.000000e+000,1.229939e+000,0.000000e+000,3,0.000000e+000,1.825000e+000,,,,,,,,,,,,,,,,,,0,5.000000e+000,5.000000e-001,2,1,5.401611e-003,0,1,0,
1473248931.297,,1.200000e+002,7.500534e+001,-2.796728e-006,0.000000e+000,0.000000e+000,0.000000e+000,3,0.000000e+000,1.825000e+000,,,,,,,,,,,,,,,,,,0,5.000000e+000,5.000000e-001,2,1,1.349640e-002,0,1,0,
1473248968.992,,1.200000e+002,7.499590e+001,-3.257434e-006,0.000000e+000,3.727502e-002,0.000000e+000,3,0.000000e+000,1.825000e+000,,,,,,,,,,,,,,,,,,0,5.000000e+000,5.000000e-001,2,1,1.078796e-002,0,1,0,
1473249088.934,,1.000000e+002,7.500938e+001,-2.585305e-006,0.000000e+000,-4.605978e-002,0.000000e+000,3,0.000000e+000,1.825000e+000,,,,,,,,,,,,,,,,,,0,5.000000e+000,5.000000e-001,2,1,1.619720e-002,0,1,0,
1473249117.613,,1.000000e+002,7.499454e+001,-2.405045e-006,0.000000e+000,4.961825e-002,0.000000e+000,3,0.000000e+000,1.825000e+000,,,,,,,,,,,,,,,,,,0,5.000000e+000,5.000000e-001,2,1,2.716064e-003,0,1,0,
1473249239.801,,8.000000e+001,7.499994e+001,-1.255263e-006,0.000000e+000,-1.603874e-001,0.000000e+000,3,0.000000e+000,1.825000e+000,,,,,,,,,,,,,,,,,,0,5.000000e+000,5.000000e-001,2,1,2.693176e-003,0,1,0,
1473249268.498,,8.000000e+001,7.499860e+001,2.413599e-007,0.000000e+000,2.332004e+000,0.000000e+000,3,0.000000e+000,1.825000e+000,,,,,,,,,,,,,,,,,,0,5.000000e+000,5.000000e-001,2,1,0.000000e+000,0,1,0,
1473249390.969,,6.000000e+001,7.499860e+001,-2.272036e-006,0.000000e+000,-8.625428e-002,0.000000e+000,3,0.000000e+000,1.825000e+000,,,,,,,,,,,,,,,,,,0,5.000000e+000,5.000000e-001,2,1,1.081085e-002,0,1,0,
1473249420.678,,6.000000e+001,7.499590e+001,-1.643049e-006,0.000000e+000,1.820627e-002,0.000000e+000,3,0.000000e+000,1.825000e+000,,,,,,,,,,,,,,,,,,0,5.000000e+000,5.000000e-001,2,1,0.000000e+000,0,1,0,
1473249551.312,,4.000000e+001,7.499725e+001,-1.317150e-006,0.000000e+000,-3.179006e-002,0.000000e+000,3,0.000000e+000,1.825000e+000,,,,,,,,,,,,,,,,,,0,5.000000e+000,5.000000e-001,2,1,2.428436e-002,0,1,0,
1473249578.665,,4.000000e+001,7.500130e+001,-1.041510e-006,0.000000e+000,2.936723e-002,0.000000e+000,3,0.000000e+000,1.825000e+000,,,,,,,,,,,,,,,,,,0,5.000000e+000,5.000000e-001,2,1,5.401611e-003,0,1,0,
1473249741.928,,2.000000e+001,7.499590e+001,-1.345503e-006,0.000000e+000,-1.224919e-001,0.000000e+000,3,0.000000e+000,1.825000e+000,,,,,,,,,,,,,,,,,,0,5.000000e+000,5.000000e-001,2,1,0.000000e+000,0,1,0,
1473249768.400,,2.000000e+001,7.500264e+001,-5.178654e-007,0.000000e+000,5.295061e-001,0.000000e+000,3,0.000000e+000,1.825000e+000,,,,,,,,,,,,,,,,,,0,5.000000e+000,5.000000e-001,2,1,8.087158e-003,0,1,0,
1473249897.589,,0.000000e+000,7.500670e+001,-1.641490e-006,0.000000e+000,2.895673e-001,0.000000e+000,3,1.605269e-001,1.825000e+000,,,,,,,,,,,,,,,,,,0,5.000000e+000,5.000000e-001,2,1,5.393982e-003,0,1,0,
1473249923.518,,0.000000e+000,7.500264e+001,-8.017507e-007,0.000000e+000,2.925688e-001,0.000000e+000,3,2.732945e-001,1.825000e+000,,,,,,,,,,,,,,,,,,0,5.000000e+000,5.000000e-001,2,1,2.708435e-003,0,1,0,
1473250087.539,,-2.000000e+001,7.499994e+001,-7.330716e-007,0.000000e+000,-1.397382e+000,0.000000e+000,3,0.000000e+000,1.825000e+000,,,,,,,,,,,,,,,,,,0,5.000000e+000,5.000000e-001,2,1,2.693176e-003,0,1,0,
1473250116.763,,-2.000000e+001,7.499860e+001,-1.278287e-006,0.000000e+000,-3.642983e-001,0.000000e+000,3,0.000000e+000,1.825000e+000,,,,,,,,,,,,,,,,,,0,5.000000e+000,5.000000e-001,2,1,5.386353e-003,0,1,0,
1473250241.511,,-4.000000e+001,7.500264e+001,-3.361018e-007,0.000000e+000,0.000000e+000,0.000000e+000,3,0.000000e+000,1.825000e+000,,,,,,,,,,,,,,,,,,0,5.000000e+000,5.000000e-001,2,1,2.708435e-003,0,1,0,
1473250268.939,,-4.000000e+001,7.499590e+001,4.456332e-007,0.000000e+000,-3.353811e-001,0.000000e+000,3,0.000000e+000,1.825000e+000,,,,,,,,,,,,,,,,,,0,5.000000e+000,5.000000e-001,2,1,0.000000e+000,0,1,0,
1473250391.628,,-6.000000e+001,7.500398e+001,-3.162160e-007,0.000000e+000,0.000000e+000,0.000000e+000,3,0.000000e+000,1.825000e+000,,,,,,,,,,,,,,,,,,0,5.000000e+000,5.000000e-001,2,1,5.393982e-003,0,1,0,
1473250418.502,,-6.000000e+001,7.500265e+001,-5.553838e-008,0.000000e+000,0.000000e+000,0.000000e+000,3,0.000000e+000,1.825000e+000,,,,,,,,,,,,,,,,,,0,5.000000e+000,5.000000e-001,2,1,1.348877e-002,0,1,0,
1473250545.107,,-8.000000e+001,7.499860e+001,4.157523e-007,0.000000e+000,0.000000e+000,0.000000e+000,3,0.000000e+000,1.825000e+000,,,,,,,,,,,,,,,,,,0,5.000000e+000,5.000000e-001,2,1,1.081085e-002,0,1,0,
1473250570.064,,-8.000000e+001,7.500130e+001,3.201302e-007,0.000000e+000,0.000000e+000,0.000000e+000,3,0.000000e+000,1.825000e+000,,,,,,,,,,,,,,,,,,0,5.000000e+000,5.000000e-001,2,1,5.401611e-003,0,1,0,
1473250692.691,,-1.000000e+002,7.500534e+001,-2.135797e-007,0.000000e+000,0.000000e+000,0.000000e+000,3,0.000000e+000,1.825000e+000,,,,,,,,,,,,,,,,,,0,5.000000e+000,5.000000e-001,2,1,8.102417e-003,0,1,0,
1473250716.977,,-1.000000e+002,7.500129e+001,3.910612e-007,0.000000e+000,0.000000e+000,0.000000e+000,3,0.000000e+000,1.825000e+000,,,,,,,,,,,,,,,,,,0,5.000000e+000,5.000000e-001,2,1,0.000000e+000,0,1,0,
1473250845.479,,-1.200000e+002,7.500264e+001,-9.575828e-006,0.000000e+000,-1.397720e+000,0.000000e+000,3,5.009762e-001,1.825000e+000,,,,,,,,,,,,,,,,,,0,5.000000e+000,5.000000e-001,2,1,8.087158e-003,0,1,0,
1473250871.677,,-1.200000e+002,7.499185e+001,-9.023647e-006,0.000000e+000,-1.349216e+000,0.000000e+000,3,5.375474e-001,1.825000e+000,,,,,,,,,,,,,,,,,,0,5.000000e+000,5.000000e-001,2,1,1.348877e-002,0,1,0,
1473250993.881,,-1.400000e+002,7.499995e+001,9.566455e-007,0.000000e+000,0.000000e+000,0.000000e+000,3,0.000000e+000,1.825000e+000,,,,,,,,,,,,,,,,,,0,5.000000e+000,5.000000e-001,2,1,8.094788e-003,0,1,0,
1473251022.810,,-1.400000e+002,7.499860e+001,-1.085411e-005,0.000000e+000,-1.374107e+000,0.000000e+000,3,5.391456e-001,1.825000e+000,,,,,,,,,,,,,,,,,,0,5.000000e+000,5.000000e-001,2,1,5.386353e-003,0,1,0,
1473251150.560,,-1.600000e+002,7.499455e+001,-1.183225e-005,0.000000e+000,-1.364991e+000,0.000000e+000,3,5.403765e-001,1.825000e+000,,,,,,,,,,,,,,,,,,0,5.000000e+000,5.000000e-001,2,1,8.094788e-003,0,1,0,
1473251176.674,,-1.600000e+002,7.500130e+001,-1.209229e-005,0.000000e+000,-1.354956e+000,0.000000e+000,3,5.513066e-001,1.825000e+000,,,,,,,,,,,,,,,,,,0,5.000000e+000,5.000000e-001,2,1,1.078033e-002,0,1,0,
1473251296.225,,-1.800000e+002,7.499994e+001,1.413877e-006,0.000000e+000,0.000000e+000,0.000000e+000,3,0.000000e+000,1.825000e+000,,,,,,,,,,,,,,,,,,0,5.000000e+000,5.000000e-001,2,1,1.349640e-002,0,1,0,
1473251323.842,,-1.800000e+002,7.499994e+001,-1.289488e-005,0.000000e+000,-1.367230e+000,0.000000e+000,3,5.357808e-001,1.825000e+000,,,,,,,,,,,,,,,,,,0,5.000000e+000,5.000000e-001,2,1,1.349640e-002,0,1,0,
1473251450.142,,-2.000000e+002,7.499995e+001,-1.464869e-005,0.000000e+000,-1.401394e+000,0.000000e+000,3,5.141686e-001,1.825000e+000,,,,,,,,,,,,,,,,,,0,5.000000e+000,5.000000e-001,2,1,8.094788e-003,0,1,0,
1473251478.424,,-2.000000e+002,7.499860e+001,-1.444604e-005,0.000000e+000,-1.393456e+000,0.000000e+000,3,5.473454e-001,1.825000e+000,,,,,,,,,,,,,,,,,,0,5.000000e+000,5.000000e-001,2,1,0.000000e+000,0,1,0,
1473251646.914,,-3.000000e+002,7.499724e+001,8.921921e-007,0.000000e+000,0.000000e+000,0.000000e+000,3,0.000000e+000,1.825000e+000,,,,,,,,,,,,,,,,,,0,5.000000e+000,5.000000e-001,2,1,8.102417e-003,0,1,0,
1473251674.593,,-3.000000e+002,7.500264e+001,8.374774e-007,0.000000e+000,0.000000e+000,0.000000e+000,3,0.000000e+000,1.825000e+000,,,,,,,,,,,,,,,,,,0,5.000000e+000,5.000000e-001,2,1,8.087158e-003,0,1,0,
1473251801.036,,-4.000000e+002,7.500130e+001,-9.154319e-007,0.000000e+000,0.000000e+000,0.000000e+000,3,0.000000e+000,1.825000e+000,,,,,,,,,,,,,,,,,,0,5.000000e+000,5.000000e-001,2,1,5.401611e-003,0,1,0,
1473251830.214,,-4.000000e+002,7.500130e+001,-6.045051e-007,0.000000e+000,0.000000e+000,0.000000e+000,3,0.000000e+000,1.825000e+000,,,,,,,,,,,,,,,,,,0,5.000000e+000,5.000000e-001,2,1,1.078033e-002,0,1,0,
1473251967.944,,-5.000000e+002,7.499995e+001,-2.877728e-006,0.000000e+000,0.000000e+000,0.000000e+000,3,0.000000e+000,1.825000e+000,,,,,,,,,,,,,,,,,,0,5.000000e+000,5.000000e-001,2,1,8.094788e-003,0,1,0,
1473251996.873,,-5.000000e+002,7.499590e+001,-1.995784e-006,0.000000e+000,0.000000e+000,0.000000e+000,3,0.000000e+000,1.825000e+000,,,,,,,,,,,,,,,,,,0,5.000000e+000,5.000000e-001,2,1,1.078796e-002,0,1,0,
1473252125.817,,-6.000000e+002,7.499860e+001,-4.194101e-006,0.000000e+000,0.000000e+000,0.000000e+000,3,0.000000e+000,1.825000e+000,,,,,,,,,,,,,,,,,,0,5.000000e+000,5.000000e-001,2,1,1.618195e-002,0,1,0,
1473252154.787,,-6.000000e+002,7.499590e+001,-4.311392e-006,0.000000e+000,0.000000e+000,0.000000e+000,3,0.000000e+000,1.825000e+000,,,,,,,,,,,,,,,,,,0,5.000000e+000,5.000000e-001,2,1,0.000000e+000,0,1,0,
1473252291.017,,-7.000000e+002,7.499455e+001,-7.484805e-006,0.000000e+000,0.000000e+000,0.000000e+000,3,0.000000e+000,1.825000e+000,,,,,,,,,,,,,,,,,,0,5.000000e+000,5.000000e-001,2,1,8.094788e-003,0,1,0,
1473252318.460,,-7.000000e+002,7.499994e+001,-7.381163e-006,0.000000e+000,0.000000e+000,0.000000e+000,3,0.000000e+000,1.825000e+000,,,,,,,,,,,,,,,,,,0,5.000000e+000,5.000000e-001,2,1,2.693176e-003,0,1,0,
1473252452.460,,-1.000000e+003,7.500264e+001,-2.912302e-005,0.000000e+000,-1.248135e+000,0.000000e+000,3,1.194953e-002,1.825000e+000,,,,,,,,,,,,,,,,,,0,5.000000e+000,5.000000e-001,2,1,8.087158e-003,0,1,0,
1473252479.724,,-1.000000e+003,7.500129e+001,-2.902979e-005,0.000000e+000,-1.250478e+000,0.000000e+000,3,8.288832e-003,1.825000e+000,,,,,,,,,,,,,,,,,,0,5.000000e+000,5.000000e-001,2,1,0.000000e+000,0,1,0,
1473252636.326,,-3.000000e+003,7.499860e+001,-1.078156e-004,0.000000e+000,-4.626055e-002,0.000000e+000,3,6.076916e-001,1.825000e+000,,,,,,,,,,,,,,,,,,0,5.000000e+000,5.000000e-001,2,1,0.000000e+000,0,1,0,
1473252660.672,,-3.000000e+003,7.499994e+001,-1.061825e-004,0.000000e+000,-4.173681e-002,0.000000e+000,3,6.050716e-001,1.825000e+000,,,,,,,,,,,,,,,,,,0,5.000000e+000,5.000000e-001,2,1,2.693176e-003,0,1,0,
1473252798.163,,-5.000000e+003,7.499860e+001,-1.811315e-004,0.000000e+000,-9.951528e-003,0.000000e+000,3,7.533492e-001,1.825000e+000,,,,,,,,,,,,,,,,,,0,5.000000e+000,5.000000e-001,2,1,1.081085e-002,0,1,0,
1473252823.342,,-5.000000e+003,7.500130e+001,-1.822006e-004,0.000000e+000,-1.268445e-002,0.000000e+000,3,7.545112e-001,1.825000e+000,,,,,,,,,,,,,,,,,,0,5.000000e+000,5.000000e-001,2,1,5.401611e-003,0,1,0,
1473252959.585,,-7.000000e+003,7.500129e+001,-2.415349e-004,0.000000e+000,-4.755292e-003,0.000000e+000,3,8.117517e-001,1.825000e+000,,,,,,,,,,,,,,,,,,0,5.000000e+000,5.000000e-001,2,1,0.000000e+000,0,1,0,
1473252985.541,,-7.000000e+003,7.498915e+001,-2.418118e-004,0.000000e+000,-1.678562e-003,0.000000e+000,3,8.125076e-001,1.825000e+000,,,,,,,,,,,,,,,,,,0,5.000000e+000,5.000000e-001,2,1,2.427673e-002,0,1,0,
1473253122.912,,-9.000000e+003,7.499724e+001,-2.906213e-004,0.000000e+000,2.254893e-003,0.000000e+000,3,8.412074e-001,1.825000e+000,,,,,,,,,,,,,,,,,,0,5.000000e+000,5.000000e-001,2,1,8.102417e-003,0,1,0,
1473253149.983,,-9.000000e+003,7.499860e+001,-2.904806e-004,0.000000e+000,3.052885e-003,0.000000e+000,3,8.406284e-001,1.825000e+000,,,,,,,,,,,,,,,,,,0,5.000000e+000,5.000000e-001,2,1,5.386353e-003,0,1,0,
1473253284.427,,-1.000000e+004,7.500130e+001,-3.108669e-004,0.000000e+000,4.728585e-003,0.000000e+000,3,8.502812e-001,1.825000e+000,,,,,,,,,,,,,,,,,,0,5.000000e+000,5.000000e-001,2,1,5.401611e-003,0,1,0,
1473253311.606,,-1.000000e+004,7.499994e+001,-3.123055e-004,0.000000e+000,3.197944e-003,0.000000e+000,3,8.511527e-001,1.825000e+000,,,,,,,,,,,,,,,,,,0,5.000000e+000,5.000000e-001,2,1,2.693176e-003,0,1,0,
1473253491.341,,-2.000000e+004,7.500264e+001,-4.519169e-004,0.000000e+000,1.170442e-002,0.000000e+000,3,8.910215e-001,1.825000e+000,,,,,,,,,,,,,,,,,,0,5.000000e+000,5.000000e-001,2,1,2.708435e-003,0,1,0,
1473253515.969,,-2.000000e+004,7.501208e+001,-4.523279e-004,0.000000e+000,1.293663e-002,0.000000e+000,3,8.939899e-001,1.825000e+000,,,,,,,,,,,,,,,,,,0,5.000000e+000,5.000000e-001,2,1,2.159119e-002,0,1,0,
1473253693.285,,-3.000000e+004,7.499860e+001,-5.341264e-004,0.000000e+000,1.608204e-002,0.000000e+000,3,9.083111e-001,1.825000e+000,,,,,,,,,,,,,,,,,,0,5.000000e+000,5.000000e-001,2,1,0.000000e+000,0,1,0,
1473253719.963,,-3.000000e+004,7.499994e+001,-5.329024e-004,0.000000e+000,1.427765e-002,0.000000e+000,3,9.051291e-001,1.825000e+000,,,,,,,,,,,,,,,,,,0,5.000000e+000,5.000000e-001,2,1,2.693176e-003,0,1,0,
1473253897.358,,-4.000000e+004,7.499725e+001,-5.928031e-004,0.000000e+000,1.633792e-002,0.000000e+000,3,9.174735e-001,1.825000e+000,,,,,,,,,,,,,,,,,,0,5.000000e+000,5.000000e-001,2,1,2.693176e-003,0,1,0,
1473253923.895,,-4.000000e+004,7.499590e+001,-5.916182e-004,0.000000e+000,1.637890e-002,0.000000e+000,3,9.147158e-001,1.825000e+000,,,,,,,,,,,,,,,,,,0,5.000000e+000,5.000000e-001,2,1,5.409241e-003,0,1,0,
1473254101.839,,-5.000000e+004,7.499724e+001,-6.342081e-004,0.000000e+000,1.722825e-002,0.000000e+000,3,9.149935e-001,1.825000e+000,,,,,,,,,,,,,,,,,,0,5.000000e+000,5.000000e-001,2,1,8.102417e-003,0,1,0,
1473254127.767,,-5.000000e+004,7.500803e+001,-6.361658e-004,0.000000e+000,1.970873e-002,0.000000e+000,3,9.220095e-001,1.825000e+000,,,,,,,,,,,,,,,,,,0,5.000000e+000,5.000000e-001,2,1,2.969360e-002,0,1,0,
1473254310.410,,-6.000000e+004,7.499454e+001,-6.641243e-004,0.000000e+000,1.932198e-002,0.000000e+000,3,9.222628e-001,1.825000e+000,,,,,,,,,,,,,,,,,,0,5.000000e+000,5.000000e-001,2,1,2.716064e-003,0,1,0,
1473254336.447,,-6.000000e+004,7.500129e+001,-6.620936e-004,0.000000e+000,1.431017e-002,0.000000e+000,3,9.191580e-001,1.825000e+000,,,,,,,,,,,,,,,,,,0,5.000000e+000,5.000000e-001,2,1,0.000000e+000,0,1,0,
1473254521.421,,-7.000000e+004,7.499994e+001,-6.893513e-004,0.000000e+000,1.677049e-002,0.000000e+000,3,9.233161e-001,1.825000e+000,,,,,,,,,,,,,,,,,,0,5.000000e+000,5.000000e-001,2,1,2.693176e-003,0,1,0,
1473254550.599,,-7.000000e+004,7.500130e+001,-6.899689e-004,0.000000e+000,2.542646e-002,0.000000e+000,3,9.252372e-001,1.825000e+000,,,,,,,,,,,,,,,,,,0,5.000000e+000,5.000000e-001,2,1,1.078033e-002,0,1,0,
1473254742.024,,-6.000000e+004,7.500129e+001,-6.657836e-004,0.000000e+000,1.858951e-002,0.000000e+000,3,9.186392e-001,1.825000e+000,,,,,,,,,,,,,,,,,,0,5.000000e+000,5.000000e-001,2,1,0.000000e+000,0,1,0,
1473254767.452,,-6.000000e+004,7.499860e+001,-6.673188e-004,0.000000e+000,2.181581e-002,0.000000e+000,3,9.228048e-001,1.825000e+000,,,,,,,,,,,,,,,,,,0,5.000000e+000,5.000000e-001,2,1,5.386353e-003,0,1,0,
1473254943.235,,-5.000000e+004,7.500534e+001,-6.281745e-004,0.000000e+000,2.085862e-002,0.000000e+000,3,9.232485e-001,1.825000e+000,,,,,,,,,,,,,,,,,,0,5.000000e+000,5.000000e-001,2,1,8.102417e-003,0,1,0,
1473254967.497,,-5.000000e+004,7.499454e+001,-6.318958e-004,0.000000e+000,1.925129e-002,0.000000e+000,3,9.179404e-001,1.825000e+000,,,,,,,,,,,,,,,,,,0,5.000000e+000,5.000000e-001,2,1,2.716064e-003,0,1,0,
1473255147.705,,-4.000000e+004,7.499455e+001,-5.927606e-004,0.000000e+000,1.950615e-002,0.000000e+000,3,9.098456e-001,1.825000e+000,,,,,,,,,,,,,,,,,,0,5.000000e+000,5.000000e-001,2,1,8.094788e-003,0,1,0,
1473255173.634,,-4.000000e+004,7.499860e+001,-5.906447e-004,0.000000e+000,1.403376e-002,0.000000e+000,3,9.140456e-001,1.825000e+000,,,,,,,,,,,,,,,,,,0,5.000000e+000,5.000000e-001,2,1,5.386353e-003,0,1,0,
1473255351.795,,-3.000000e+004,7.500129e+001,-5.339892e-004,0.000000e+000,1.698541e-002,0.000000e+000,3,9.062974e-001,1.825000e+000,,,,,,,,,,,,,,,,,,0,5.000000e+000,5.000000e-001,2,1,0.000000e+000,0,1,0,
1473255379.581,,-3.000000e+004,7.499860e+001,-5.332320e-004,0.000000e+000,1.460539e-002,0.000000e+000,3,9.067094e-001,1.825000e+000,,,,,,,,,,,,,,,,,,0,5.000000e+000,5.000000e-001,2,1,0.000000e+000,0,1,0,
1473255553.569,,-2.000000e+004,7.499590e+001,-4.507567e-004,0.000000e+000,1.123453e-002,0.000000e+000,3,8.944304e-001,1.825000e+000,,,,,,,,,,,,,,,,,,0,5.000000e+000,5.000000e-001,2,1,1.618958e-002,0,1,0,
1473255576.430,,-2.000000e+004,7.500398e+001,-4.498412e-004,0.000000e+000,1.011890e-002,0.000000e+000,3,8.926929e-001,1.825000e+000,,,,,,,,,,,,,,,,,,0,5.000000e+000,5.000000e-001,2,1,5.393982e-003,0,1,0,
1473255745.775,,-1.000000e+004,7.498781e+001,-3.107197e-004,0.000000e+000,2.825608e-003,0.000000e+000,3,8.511119e-001,1.825000e+000,,,,,,,,,,,,,,,,,,0,5.000000e+000,5.000000e-001,2,1,2.158356e-002,0,1,0,
1473255773.954,,-1.000000e+004,7.499724e+001,-3.110437e-004,0.000000e+000,2.283605e-003,0.000000e+000,3,8.496278e-001,1.825000e+000,,,,,,,,,,,,,,,,,,0,5.000000e+000,5.000000e-001,2,1,8.102417e-003,0,1,0,
1473255911.644,,-9.000000e+003,7.502289e+001,-2.894070e-004,0.000000e+000,2.911825e-003,0.000000e+000,3,8.394819e-001,1.825000e+000,,,,,,,,,,,,,,,,,,0,5.000000e+000,5.000000e-001,2,1,4.319763e-002,0,1,0,
1473255937.825,,-9.000000e+003,7.499725e+001,-2.894954e-004,0.000000e+000,-3.626925e-004,0.000000e+000,3,8.404486e-001,1.825000e+000,,,,,,,,,,,,,,,,,,0,5.000000e+000,5.000000e-001,2,1,2.693176e-003,0,1,0,
1473256076.558,,-7.000000e+003,7.499860e+001,-2.414636e-004,0.000000e+000,-4.234590e-003,0.000000e+000,3,8.114790e-001,1.825000e+000,,,,,,,,,,,,,,,,,,0,5.000000e+000,5.000000e-001,2,1,1.081085e-002,0,1,0,
1473256104.238,,-7.000000e+003,7.499725e+001,-2.418239e-004,0.000000e+000,-2.853941e-003,0.000000e+000,3,8.129653e-001,1.825000e+000,,,,,,,,,,,,,,,,,,0,5.000000e+000,5.000000e-001,2,1,2.693176e-003,0,1,0,
1473256234.426,,-5.000000e+003,7.499994e+001,-1.811368e-004,0.000000e+000,-1.319811e-002,0.000000e+000,3,7.529207e-001,1.825000e+000,,,,,,,,,,,,,,,,,,0,5.000000e+000,5.000000e-001,2,1,1.349640e-002,0,1,0,
1473256260.878,,-5.000000e+003,7.499455e+001,-1.811276e-004,0.000000e+000,-1.233153e-002,0.000000e+000,3,7.543628e-001,1.825000e+000,,,,,,,,,,,,,,,,,,0,5.000000e+000,5.000000e-001,2,1,1.348114e-002,0,1,0,
1473256396.627,,-3.000000e+003,7.499725e+001,-1.052015e-004,0.000000e+000,-4.587278e-002,0.000000e+000,3,6.007683e-001,1.825000e+000,,,,,,,,,,,,,,,,,,0,5.000000e+000,5.000000e-001,2,1,2.693176e-003,0,1,0,
1473256422.036,,-3.000000e+003,7.500129e+001,-1.053119e-004,0.000000e+000,-4.404772e-002,0.000000e+000,3,6.008485e-001,1.825000e+000,,,,,,,,,,,,,,,,,,0,5.000000e+000,5.000000e-001,2,1,0.000000e+000,0,1,0,
1473256558.876,,-1.000000e+003,7.500130e+001,-3.060958e-005,0.000000e+000,-1.243670e+000,0.000000e+000,3,6.683674e-002,1.825000e+000,,,,,,,,,,,,,,,,,,0,5.000000e+000,5.000000e-001,2,1,5.401611e-003,0,1,0,
1473256585.167,,-1.000000e+003,7.499454e+001,-2.919837e-005,0.000000e+000,-1.251667e+000,0.000000e+000,3,5.585519e-002,1.825000e+000,,,,,,,,,,,,,,,,,,0,5.000000e+000,5.000000e-001,2,1,2.427673e-002,0,1,0,
1473256728.358,,-7.000000e+002,7.500264e+001,-6.474607e-006,0.000000e+000,0.000000e+000,0.000000e+000,3,0.000000e+000,1.825000e+000,,,,,,,,,,,,,,,,,,0,5.000000e+000,5.000000e-001,2,1,2.708435e-003,0,1,0,
1473256754.435,,-7.000000e+002,7.499860e+001,-6.334125e-006,0.000000e+000,0.000000e+000,0.000000e+000,3,0.000000e+000,1.825000e+000,,,,,,,,,,,,,,,,,,0,5.000000e+000,5.000000e-001,2,1,0.000000e+000,0,1,0,
1473256904.386,,-6.000000e+002,7.499051e+001,-3.073346e-006,0.000000e+000,0.000000e+000,0.000000e+000,3,0.000000e+000,1.825000e+000,,,,,,,,,,,,,,,,,,0,5.000000e+000,5.000000e-001,2,1,2.698517e-002,0,1,0,
1473256932.065,,-6.000000e+002,7.499995e+001,-2.899941e-006,0.000000e+000,0.000000e+000,0.000000e+000,3,0.000000e+000,1.825000e+000,,,,,,,,,,,,,,,,,,0,5.000000e+000,5.000000e-001,2,1,8.094788e-003,0,1,0,
1473257071.254,,-5.000000e+002,7.499860e+001,1.822769e-007,0.000000e+000,0.000000e+000,0.000000e+000,3,0.000000e+000,1.825000e+000,,,,,,,,,,,,,,,,,,0,5.000000e+000,5.000000e-001,2,1,1.081085e-002,0,1,0,
1473257101.934,,-5.000000e+002,7.499725e+001,-1.565387e-007,0.000000e+000,0.000000e+000,0.000000e+000,3,0.000000e+000,1.825000e+000,,,,,,,,,,,,,,,,,,0,5.000000e+000,5.000000e-001,2,1,2.693176e-003,0,1,0,
1473257240.377,,-4.000000e+002,7.499725e+001,1.352321e-006,0.000000e+000,0.000000e+000,0.000000e+000,3,0.000000e+000,1.825000e+000,,,,,,,,,,,,,,,,,,0,5.000000e+000,5.000000e-001,2,1,2.693176e-003,0,1,0,
1473257266.617,,-4.000000e+002,7.499725e+001,-2.460950e-005,0.000000e+000,-1.389044e+000,0.000000e+000,3,5.082927e-001,1.825000e+000,,,,,,,,,,,,,,,,,,0,5.000000e+000,5.000000e-001,2,1,2.693176e-003,0,1,0,
1473257401.242,,-3.000000e+002,7.499860e+001,-2.041390e-006,0.000000e+000,-4.113776e-001,0.000000e+000,3,0.000000e+000,1.825000e+000,,,,,,,,,,,,,,,,,,0,5.000000e+000,5.000000e-001,2,1,5.386353e-003,0,1,0,
1473257431.582,,-3.000000e+002,7.499994e+001,-1.480428e-005,0.000000e+000,-1.018299e+000,0.000000e+000,3,1.691139e-001,1.825000e+000,,,,,,,,,,,,,,,,,,0,5.000000e+000,5.000000e-001,2,1,2.693176e-003,0,1,0,
1473257568.775,,-2.000000e+002,7.499725e+001,2.734075e-006,0.000000e+000,-2.940900e-002,0.000000e+000,3,0.000000e+000,1.825000e+000,,,,,,,,,,,,,,,,,,0,5.000000e+000,5.000000e-001,2,1,2.693176e-003,0,1,0,
1473257598.493,,-2.000000e+002,7.499590e+001,2.388351e-006,0.000000e+000,-5.277702e-002,0.000000e+000,3,0.000000e+000,1.825000e+000,,,,,,,,,,,,,,,,,,0,5.000000e+000,5.000000e-001,2,1,5.409241e-003,0,1,0,
1473257721.932,,-1.800000e+002,7.498915e+001,2.752685e-006,0.000000e+000,1.144230e-003,0.000000e+000,3,0.000000e+000,1.825000e+000,,,,,,,,,,,,,,,,,,0,5.000000e+000,5.000000e-001,2,1,2.427673e-002,0,1,0,
1473257749.363,,-1.800000e+002,7.499590e+001,2.531997e-006,0.000000e+000,-4.359609e-002,0.000000e+000,3,0.000000e+000,1.825000e+000,,,,,,,,,,,,,,,,,,0,5.000000e+000,5.000000e-001,2,1,0.000000e+000,0,1,0,
1473257873.072,,-1.600000e+002,7.500938e+001,3.001174e-006,0.000000e+000,-1.181046e-002,0.000000e+000,3,0.000000e+000,1.825000e+000,,,,,,,,,,,,,,,,,,0,5.000000e+000,5.000000e-001,2,1,2.158356e-002,0,1,0,
1473257899.000,,-1.600000e+002,7.499860e+001,1.650950e-006,0.000000e+000,-9.167083e-002,0.000000e+000,3,0.000000e+000,1.825000e+000,,,,,,,,,,,,,,,,,,0,5.000000e+000,5.000000e-001,2,1,5.386353e-003,0,1,0,
1473258022.939,,-1.400000e+002,7.499454e+001,2.659241e-006,0.000000e+000,-5.141543e-002,0.000000e+000,3,0.000000e+000,1.825000e+000,,,,,,,,,,,,,,,,,,0,5.000000e+000,5.000000e-001,2,1,2.716064e-003,0,1,0,
1473258050.307,,-1.400000e+002,7.499454e+001,2.913398e-006,0.000000e+000,-4.546586e-002,0.000000e+000,3,0.000000e+000,1.825000e+000,,,,,,,,,,,,,,,,,,0,5.000000e+000,5.000000e-001,2,1,2.716064e-003,0,1,0,
1473258180.886,,-1.200000e+002,7.500670e+001,2.750988e-006,0.000000e+000,4.169206e-002,0.000000e+000,3,0.000000e+000,1.825000e+000,,,,,,,,,,,,,,,,,,0,5.000000e+000,5.000000e-001,2,1,2.158356e-002,0,1,0,
1473258208.315,,-1.200000e+002,7.499320e+001,2.607557e-006,0.000000e+000,2.156999e-002,0.000000e+000,3,0.000000e+000,1.825000e+000,,,,,,,,,,,,,,,,,,0,5.000000e+000,5.000000e-001,2,1,5.401611e-003,0,1,0,
1473258333.781,,-1.000000e+002,7.500130e+001,2.425990e-006,0.000000e+000,-1.837883e-004,0.000000e+000,3,0.000000e+000,1.825000e+000,,,,,,,,,,,,,,,,,,0,5.000000e+000,5.000000e-001,2,1,5.401611e-003,0,1,0,
1473258364.214,,-1.000000e+002,7.500669e+001,-9.243661e-007,0.000000e+000,-4.489159e-001,0.000000e+000,3,0.000000e+000,1.825000e+000,,,,,,,,,,,,,,,,,,0,5.000000e+000,5.000000e-001,2,1,1.080322e-002,0,1,0,
1473258487.897,,-8.000000e+001,7.500398e+001,1.499100e-006,0.000000e+000,-7.794576e-002,0.000000e+000,3,0.000000e+000,1.825000e+000,,,,,,,,,,,,,,,,,,0,5.000000e+000,5.000000e-001,2,1,5.393982e-003,0,1,0,
1473258524.512,,-8.000000e+001,7.499860e+001,1.845983e-006,0.000000e+000,7.313821e-002,0.000000e+000,3,0.000000e+000,1.825000e+000,,,,,,,,,,,,,,,,,,0,5.000000e+000,5.000000e-001,2,1,5.386353e-003,0,1,0,
1473258648.205,,-6.000000e+001,7.500534e+001,1.521524e-006,0.000000e+000,-3.320295e-002,0.000000e+000,3,0.000000e+000,1.825000e+000,,,,,,,,,,,,,,,,,,0,5.000000e+000,5.000000e-001,2,1,2.429962e-002,0,1,0,
1473258703.970,,-6.000000e+001,7.499995e+001,1.442019e-006,0.000000e+000,0.000000e+000,0.000000e+000,3,0.000000e+000,1.825000e+000,,,,,,,,,,,,,,,,,,0,5.000000e+000,5.000000e-001,2,1,8.094788e-003,0,1,0,
1473258827.158,,-4.000000e+001,7.499590e+001,1.212819e-006,0.000000e+000,2.087146e-001,0.000000e+000,3,0.000000e+000,1.825000e+000,,,,,,,,,,,,,,,,,,0,5.000000e+000,5.000000e-001,2,1,1.078796e-002,0,1,0,
1473258884.314,,-4.000000e+001,7.499320e+001,2.036638e-006,0.000000e+000,4.575794e-002,0.000000e+000,3,0.000000e+000,1.825000e+000,,,,,,,,,,,,,,,,,,0,5.000000e+000,5.000000e-001,2,1,5.401611e-003,0,1,0,
1473259007.756,,-2.000000e+001,7.500804e+001,7.678859e-007,0.000000e+000,2.764021e-001,0.000000e+000,3,0.000000e+000,1.825000e+000,,,,,,,,,,,,,,,,,,0,5.000000e+000,5.000000e-001,2,1,2.427673e-002,0,1,0,
1473259035.936,,-2.000000e+001,7.499860e+001,1.285219e-006,0.000000e+000,2.326303e-001,0.000000e+000,3,0.000000e+000,1.825000e+000,,,,,,,,,,,,,,,,,,0,5.000000e+000,5.000000e-001,2,1,5.386353e-003,0,1,0,
1473259159.678,,0.000000e+000,7.499994e+001,8.953457e-007,0.000000e+000,4.400668e-001,0.000000e+000,3,0.000000e+000,1.825000e+000,,,,,,,,,,,,,,,,,,0,5.000000e+000,5.000000e-001,2,1,2.693176e-003,0,1,0,
1473259189.108,,0.000000e+000,7.499860e+001,7.222732e-007,0.000000e+000,-1.204305e-001,0.000000e+000,3,0.000000e+000,1.825000e+000,,,,,,,,,,,,,,,,,,0,5.000000e+000,5.000000e-001,2,1,5.386353e-003,0,1,0,
1473259309.549,,2.000000e+001,7.500400e+001,1.382444e-006,0.000000e+000,0.000000e+000,0.000000e+000,3,0.000000e+000,1.825000e+000,,,,,,,,,,,,,,,,,,0,5.000000e+000,5.000000e-001,2,1,2.698517e-002,0,1,0,
1473259338.478,,2.000000e+001,7.499860e+001,3.377561e-007,0.000000e+000,0.000000e+000,0.000000e+000,3,0.000000e+000,1.825000e+000,,,,,,,,,,,,,,,,,,0,5.000000e+000,5.000000e-001,2,1,0.000000e+000,0,1,0,
1473259490.267,,4.000000e+001,7.499860e+001,-4.289169e-008,0.000000e+000,0.000000e+000,0.000000e+000,3,0.000000e+000,1.825000e+000,,,,,,,,,,,,,,,,,,0,5.000000e+000,5.000000e-001,2,1,0.000000e+000,0,1,0,
1473259516.446,,4.000000e+001,7.498916e+001,5.725675e-007,0.000000e+000,0.000000e+000,0.000000e+000,3,0.000000e+000,1.825000e+000,,,,,,,,,,,,,,,,,,0,5.000000e+000,5.000000e-001,2,1,1.887512e-002,0,1,0,
1473259641.935,,6.000000e+001,7.500264e+001,4.780043e-008,0.000000e+000,0.000000e+000,0.000000e+000,3,0.000000e+000,1.825000e+000,,,,,,,,,,,,,,,,,,0,5.000000e+000,5.000000e-001,2,1,2.708435e-003,0,1,0,
1473259679.106,,6.000000e+001,7.500130e+001,4.498394e-006,0.000000e+000,-1.442221e+000,0.000000e+000,3,4.272896e-001,1.825000e+000,,,,,,,,,,,,,,,,,,0,5.000000e+000,5.000000e-001,2,1,5.401611e-003,0,1,0,
1473259804.742,,8.000000e+001,7.499455e+001,6.212662e-006,0.000000e+000,-1.435247e+000,0.000000e+000,3,4.692836e-001,1.825000e+000,,,,,,,,,,,,,,,,,,0,5.000000e+000,5.000000e-001,2,1,8.094788e-003,0,1,0,
1473259831.457,,8.000000e+001,7.500264e+001,-1.800300e-007,0.000000e+000,0.000000e+000,0.000000e+000,3,0.000000e+000,1.825000e+000,,,,,,,,,,,,,,,,,,0,5.000000e+000,5.000000e-001,2,1,8.087158e-003,0,1,0,
1473259955.012,,1.000000e+002,7.500130e+001,-3.217475e-007,0.000000e+000,0.000000e+000,0.000000e+000,3,0.000000e+000,1.825000e+000,,,,,,,,,,,,,,,,,,0,5.000000e+000,5.000000e-001,2,1,5.401611e-003,0,1,0,
1473259994.655,,1.000000e+002,7.499994e+001,7.633740e-006,0.000000e+000,-1.376688e+000,0.000000e+000,3,5.306152e-001,1.825000e+000,,,,,,,,,,,,,,,,,,0,5.000000e+000,5.000000e-001,2,1,2.693176e-003,0,1,0,
1473260136.332,,1.200000e+002,7.499724e+001,-8.805650e-007,0.000000e+000,0.000000e+000,0.000000e+000,3,0.000000e+000,1.825000e+000,,,,,,,,,,,,,,,,,,0,5.000000e+000,5.000000e-001,2,1,8.102417e-003,0,1,0,
1473260165.515,,1.200000e+002,7.500130e+001,-9.437053e-007,0.000000e+000,0.000000e+000,0.000000e+000,3,0.000000e+000,1.825000e+000,,,,,,,,,,,,,,,,,,0,5.000000e+000,5.000000e-001,2,1,5.401611e-003,0,1,0,
1473260289.769,,1.400000e+002,7.500129e+001,-2.151490e-006,0.000000e+000,0.000000e+000,0.000000e+000,3,0.000000e+000,1.825000e+000,,,,,,,,,,,,,,,,,,0,5.000000e+000,5.000000e-001,2,1,0.000000e+000,0,1,0,
1473260315.698,,1.400000e+002,7.499860e+001,1.029082e-005,0.000000e+000,-1.348823e+000,0.000000e+000,3,5.628898e-001,1.825000e+000,,,,,,,,,,,,,,,,,,0,5.000000e+000,5.000000e-001,2,1,5.386353e-003,0,1,0,
1473260466.325,,1.600000e+002,7.499725e+001,-8.264626e-007,0.000000e+000,0.000000e+000,0.000000e+000,3,0.000000e+000,1.825000e+000,,,,,,,,,,,,,,,,,,0,5.000000e+000,5.000000e-001,2,1,2.693176e-003,0,1,0,
1473260491.503,,1.600000e+002,7.499590e+001,1.212765e-005,0.000000e+000,-1.376314e+000,0.000000e+000,3,5.406909e-001,1.825000e+000,,,,,,,,,,,,,,,,,,0,5.000000e+000,5.000000e-001,2,1,0.000000e+000,0,1,0,
1473260622.985,,1.800000e+002,7.499590e+001,-1.688261e-006,0.000000e+000,0.000000e+000,0.000000e+000,3,0.000000e+000,1.825000e+000,,,,,,,,,,,,,,,,,,0,5.000000e+000,5.000000e-001,2,1,0.000000e+000,0,1,0,
1473260650.692,,1.800000e+002,7.499725e+001,-7.446852e-007,0.000000e+000,0.000000e+000,0.000000e+000,3,0.000000e+000,1.825000e+000,,,,,,,,,,,,,,,,,,0,5.000000e+000,5.000000e-001,2,1,2.693176e-003,0,1,0,
1473260772.135,,2.000000e+002,7.499860e+001,-1.373067e-006,0.000000e+000,0.000000e+000,0.000000e+000,3,0.000000e+000,1.825000e+000,,,,,,,,,,,,,,,,,,0,5.000000e+000,5.000000e-001,2,1,5.386353e-003,0,1,0,
1473260798.813,,2.000000e+002,7.499320e+001,-7.929997e-007,0.000000e+000,0.000000e+000,0.000000e+000,3,0.000000e+000,1.825000e+000,,,,,,,,,,,,,,,,,,0,5.000000e+000,5.000000e-001,2,1,3.237915e-002,0,1,0,
1473260951.053,,3.000000e+002,7.499454e+001,-1.219057e-006,0.000000e+000,0.000000e+000,0.000000e+000,3,0.000000e+000,1.825000e+000,,,,,,,,,,,,,,,,,,0,5.000000e+000,5.000000e-001,2,1,2.716064e-003,0,1,0,
1473260987.246,,3.000000e+002,7.499994e+001,-5.050048e-007,0.000000e+000,0.000000e+000,0.000000e+000,3,0.000000e+000,1.825000e+000,,,,,,,,,,,,,,,,,,0,5.000000e+000,5.000000e-001,2,1,1.349640e-002,0,1,0,
1473261122.440,,4.000000e+002,7.500400e+001,3.340646e-007,0.000000e+000,0.000000e+000,0.000000e+000,3,0.000000e+000,1.825000e+000,,,,,,,,,,,,,,,,,,0,5.000000e+000,5.000000e-001,2,1,1.079559e-002,0,1,0,
1473261151.409,,4.000000e+002,7.499725e+001,3.901844e-007,0.000000e+000,0.000000e+000,0.000000e+000,3,0.000000e+000,1.825000e+000,,,,,,,,,,,,,,,,,,0,5.000000e+000,5.000000e-001,2,1,1.349640e-002,0,1,0,
1473261288.109,,5.000000e+002,7.499994e+001,2.264155e-006,0.000000e+000,0.000000e+000,0.000000e+000,3,0.000000e+000,1.825000e+000,,,,,,,,,,,,,,,,,,0,5.000000e+000,5.000000e-001,2,1,2.693176e-003,0,1,0,
1473261315.039,,5.000000e+002,7.499860e+001,2.301501e-006,0.000000e+000,0.000000e+000,0.000000e+000,3,0.000000e+000,1.825000e+000,,,,,,,,,,,,,,,,,,0,5.000000e+000,5.000000e-001,2,1,0.000000e+000,0,1,0,
1473261445.293,,6.000000e+002,7.499590e+001,3.836142e-006,0.000000e+000,0.000000e+000,0.000000e+000,3,0.000000e+000,1.825000e+000,,,,,,,,,,,,,,,,,,0,5.000000e+000,5.000000e-001,2,1,1.078796e-002,0,1,0,
1473261471.471,,6.000000e+002,7.499860e+001,4.326163e-006,0.000000e+000,0.000000e+000,0.000000e+000,3,0.000000e+000,1.825000e+000,,,,,,,,,,,,,,,,,,0,5.000000e+000,5.000000e-001,2,1,5.386353e-003,0,1,0,
1473261605.699,,7.000000e+002,7.499051e+001,7.190117e-006,0.000000e+000,0.000000e+000,0.000000e+000,3,0.000000e+000,1.825000e+000,,,,,,,,,,,,,,,,,,0,5.000000e+000,5.000000e-001,2,1,1.079559e-002,0,1,0,
1473261632.634,,7.000000e+002,7.500535e+001,6.880474e-006,0.000000e+000,0.000000e+000,0.000000e+000,3,0.000000e+000,1.825000e+000,,,,,,,,,,,,,,,,,,0,5.000000e+000,5.000000e-001,2,1,1.889038e-002,0,1,0,
1473261762.577,,1.000000e+003,7.500130e+001,2.888835e-005,0.000000e+000,-1.245843e+000,0.000000e+000,3,6.515228e-003,1.825000e+000,,,,,,,,,,,,,,,,,,0,5.000000e+000,5.000000e-001,2,1,5.401611e-003,0,1,0,
1473261789.505,,1.000000e+003,7.499994e+001,2.912903e-005,0.000000e+000,-1.245644e+000,0.000000e+000,3,6.102911e-003,1.825000e+000,,,,,,,,,,,,,,,,,,0,5.000000e+000,5.000000e-001,2,1,2.693176e-003,0,1,0,
1473261939.216,,3.000000e+003,7.499319e+001,1.059850e-004,0.000000e+000,-4.879324e-002,0.000000e+000,3,6.045825e-001,1.825000e+000,,,,,,,,,,,,,,,,,,0,5.000000e+000,5.000000e-001,2,1,0.000000e+000,0,1,0,
1473261965.217,,3.000000e+003,7.499590e+001,1.064976e-004,0.000000e+000,-4.092369e-002,0.000000e+000,3,6.096189e-001,1.825000e+000,,,,,,,,,,,,,,,,,,0,5.000000e+000,5.000000e-001,2,1,5.409241e-003,0,1,0,
1473262104.660,,5.000000e+003,7.499725e+001,1.818223e-004,0.000000e+000,-1.256956e-002,0.000000e+000,3,7.566168e-001,1.825000e+000,,,,,,,,,,,,,,,,,,0,5.000000e+000,5.000000e-001,2,1,2.693176e-003,0,1,0,
1473262129.626,,5.000000e+003,7.499590e+001,1.817693e-004,0.000000e+000,-1.267427e-002,0.000000e+000,3,7.555191e-001,1.825000e+000,,,,,,,,,,,,,,,,,,0,5.000000e+000,5.000000e-001,2,1,1.078796e-002,0,1,0,
1473262267.070,,7.000000e+003,7.499050e+001,2.418791e-004,0.000000e+000,-2.402054e-003,0.000000e+000,3,8.119844e-001,1.825000e+000,,,,,,,,,,,,,,,,,,0,5.000000e+000,5.000000e-001,2,1,1.618958e-002,0,1,0,
1473262296.048,,7.000000e+003,7.499725e+001,2.418987e-004,0.000000e+000,-1.549764e-003,0.000000e+000,3,8.121315e-001,1.825000e+000,,,,,,,,,,,,,,,,,,0,5.000000e+000,5.000000e-001,2,1,2.693176e-003,0,1,0,
1473262432.989,,9.000000e+003,7.500264e+001,2.900412e-004,0.000000e+000,3.212932e-003,0.000000e+000,3,8.421201e-001,1.825000e+000,,,,,,,,,,,,,,,,,,0,5.000000e+000,5.000000e-001,2,1,2.708435e-003,0,1,0,
1473262457.283,,9.000000e+003,7.499454e+001,2.903863e-004,0.000000e+000,2.353516e-003,0.000000e+000,3,8.407115e-001,1.825000e+000,,,,,,,,,,,,,,,,,,0,5.000000e+000,5.000000e-001,2,1,2.716064e-003,0,1,0,
1473262589.745,,1.000000e+004,7.499590e+001,3.111692e-004,0.000000e+000,3.501359e-003,0.000000e+000,3,8.504295e-001,1.825000e+000,,,,,,,,,,,,,,,,,,0,5.000000e+000,5.000000e-001,2,1,1.618958e-002,0,1,0,
1473262618.424,,1.000000e+004,7.499725e+001,3.107665e-004,0.000000e+000,2.273597e-003,0.000000e+000,3,8.518353e-001,1.825000e+000,,,,,,,,,,,,,,,,,,0,5.000000e+000,5.000000e-001,2,1,2.693176e-003,0,1,0,
1473262787.069,,2.000000e+004,7.499994e+001,4.526248e-004,0.000000e+000,1.136917e-002,0.000000e+000,3,8.926014e-001,1.825000e+000,,,,,,,,,,,,,,,,,,0,5.000000e+000,5.000000e-001,2,1,2.693176e-003,0,1,0,
1473262817.130,,2.000000e+004,7.500130e+001,4.525829e-004,0.000000e+000,1.129252e-002,0.000000e+000,3,8.946899e-001,1.825000e+000,,,,,,,,,,,,,,,,,,0,5.000000e+000,5.000000e-001,2,1,5.401611e-003,0,1,0,
1473262999.119,,3.000000e+004,7.500668e+001,5.344116e-004,0.000000e+000,1.602263e-002,0.000000e+000,3,9.087168e-001,1.825000e+000,,,,,,,,,,,,,,,,,,0,5.000000e+000,5.000000e-001,2,1,2.699280e-002,0,1,0,
1473263024.048,,3.000000e+004,7.499860e+001,5.317440e-004,0.000000e+000,1.446570e-002,0.000000e+000,3,9.095175e-001,1.825000e+000,,,,,,,,,,,,,,,,,,0,5.000000e+000,5.000000e-001,2,1,5.386353e-003,0,1,0,
1473263194.996,,4.000000e+004,7.499860e+001,5.888137e-004,0.000000e+000,1.706993e-002,0.000000e+000,3,9.134951e-001,1.825000e+000,,,,,,,,,,,,,,,,,,0,5.000000e+000,5.000000e-001,2,1,0.000000e+000,0,1,0,
1473263221.976,,4.000000e+004,7.499590e+001,5.917833e-004,0.000000e+000,1.766683e-002,0.000000e+000,3,9.128450e-001,1.825000e+000,,,,,,,,,,,,,,,,,,0,5.000000e+000,5.000000e-001,2,1,5.409241e-003,0,1,0,
1473263401.902,,5.000000e+004,7.499994e+001,6.304483e-004,0.000000e+000,2.061932e-002,0.000000e+000,3,9.190358e-001,1.825000e+000,,,,,,,,,,,,,,,,,,0,5.000000e+000,5.000000e-001,2,1,2.693176e-003,0,1,0,
1473263427.387,,5.000000e+004,7.500534e+001,6.303950e-004,0.000000e+000,2.051093e-002,0.000000e+000,3,9.182135e-001,1.825000e+000,,,,,,,,,,,,,,,,,,0,5.000000e+000,5.000000e-001,2,1,1.349640e-002,0,1,0,
1473263609.194,,6.000000e+004,7.499994e+001,6.620055e-004,0.000000e+000,1.934101e-002,0.000000e+000,3,9.220868e-001,1.825000e+000,,,,,,,,,,,,,,,,,,0,5.000000e+000,5.000000e-001,2,1,1.349640e-002,0,1,0,
1473263635.929,,6.000000e+004,7.499860e+001,6.647010e-004,0.000000e+000,2.289199e-002,0.000000e+000,3,9.223489e-001,1.825000e+000,,,,,,,,,,,,,,,,,,0,5.000000e+000,5.000000e-001,2,1,0.000000e+000,0,1,0,
1473264616.264,,7.000000e+004,7.500130e+001,6.911221e-004,0.000000e+000,2.393489e-002,0.000000e+000,3,9.205889e-001,1.825000e+000,,,,,,,,,,,,,,,,,,0,5.000000e+000,5.000000e-001,2,1,5.401611e-003,0,1,0,
1473264642.443,,7.000000e+004,7.499994e+001,6.973869e-004,0.000000e+000,1.869817e-002,0.000000e+000,3,9.215673e-001,1.825000e+000,,,,,,,,,,,,,,,,,,0,5.000000e+000,5.000000e-001,2,1,2.693176e-003,0,1,0,
1473264653.912,,7.000000e+004,7.499994e+001,6.888332e-004,0.000000e+000,2.011934e-002,0.000000e+000,3,9.267600e-001,1.825000e+000,,,,,,,,,,,,,,,,,,0,5.000000e+000,5.000000e-001,2,1,2.693176e-003,0,1,0,