File: data/A344/A344_GdN_FC_050_Oe_160908.rso.dat
[Header]
TITLE,MPMS RSO Measurement
BYAPP,MPMS Measurement,1.1,Summary
FILEOPENTIME, 1473341040.718000 9/9/2016, 1:24:00 AM

INFO, APPNAME, MPMS MultiVu Application, Revision 1.61,  Build 082

INFO, NAME, A344
INFO, WEIGHT, 10.500
INFO, AREA, 1.000
INFO, LENGTH, 1.000
INFO, SHAPE, 0
INFO, COMMENT, m = 0.0105g
INFO, SEQUENCE FILE: FC_120K-5K.seq


INFO, BACKGROUND DATA FILE:, None


STARTUPAXIS,X,4,LINEAR,AUTO,0.000000,0.000000
STARTUPAXIS,Y1,5,LINEAR,AUTO,0.000000,0.000000


STARTUPGROUP,Longitudinal
FIELDGROUP,Longitudinal,1,2,3,4,5,6,7,8,9,10,11,19,20,21,22,23,35
FIELDGROUP,Transverse,1,2,3,4,12,13,14,15,16,17,18,24,25,26,27,28,35

PLOT_APPEARANCE,ALL,HORZ_GRID_ON,VERT_GRID_ON,MARKERS_AND_LINES

[Data]
Time,Comment,Field (Oe),Temperature (K),Long Moment (emu),Long Scan Std Dev,Long Offset (cm),Long Offset Std Dev,Long Algorithm,Long Reg Fit,Long Reg Factor,Trans Moment (emu),Trans Scan Std Dev,Trans Offset (cm),Trans Offset Std Dev,Trans Algorithm,Trans Reg Fit,Trans Reg Factor,Long Moment [w/o ABS] (emu),Long Scan Std Dev [w/o ABS],Long Offset [w/o ABS] (cm),Long Offset Std Dev [w/o ABS],Long Reg Fit [w/o ABS],Trans Moment [w/o ABS] (emu),Trans Scan Std Dev [w/o ABS],Trans Offset [w/o ABS] (cm),Trans Offset Std Dev [w/o ABS],Trans Reg Fit [w/o ABS],RSO Position (deg),Amplitude (cm),Frequency,Cycles to Average,Scans per Measurement,Delta Temp (K),Error,EC Comp. Running,Using ABS,
1473341040.700,,5.000000e+001,1.200089e+002,-4.277318e-006,0.000000e+000,9.325366e-002,0.000000e+000,3,2.364769e-001,1.825000e+000,,,,,,,,,,,,,,,,,,0,5.000000e+000,5.000000e-001,2,1,3.295898e-003,0,1,0,
1473341052.915,,5.000000e+001,1.200106e+002,-4.301953e-006,0.000000e+000,9.608114e-002,0.000000e+000,3,2.414699e-001,1.825000e+000,,,,,,,,,,,,,,,,,,0,5.000000e+000,5.000000e-001,2,1,0.000000e+000,0,1,0,
1473341064.921,,5.000000e+001,1.200089e+002,-4.324157e-006,0.000000e+000,9.341822e-002,0.000000e+000,3,2.474889e-001,1.825000e+000,,,,,,,,,,,,,,,,,,0,5.000000e+000,5.000000e-001,2,1,3.295898e-003,0,1,0,
1473341077.580,,5.000000e+001,1.200073e+002,-4.284359e-006,0.000000e+000,9.596065e-002,0.000000e+000,3,2.392135e-001,1.825000e+000,,,,,,,,,,,,,,,,,,0,5.000000e+000,5.000000e-001,2,1,0.000000e+000,0,1,0,
1473341322.482,,5.000000e+001,1.144583e+002,-4.236188e-006,0.000000e+000,9.300531e-002,0.000000e+000,3,2.353663e-001,1.825000e+000,,,,,,,,,,,,,,,,,,0,5.000000e+000,5.000000e-001,2,1,6.604996e-001,0,1,0,
1473341335.482,,5.000000e+001,1.137167e+002,-4.231358e-006,0.000000e+000,9.513394e-002,0.000000e+000,3,2.297118e-001,1.825000e+000,,,,,,,,,,,,,,,,,,0,5.000000e+000,5.000000e-001,2,1,5.603027e-001,0,1,0,
1473341348.496,,5.000000e+001,1.128647e+002,-4.220564e-006,0.000000e+000,9.432644e-002,0.000000e+000,3,2.235642e-001,1.825000e+000,,,,,,,,,,,,,,,,,,0,5.000000e+000,5.000000e-001,2,1,5.900955e-001,0,1,0,
1473341361.710,,5.000000e+001,1.121391e+002,-4.245043e-006,0.000000e+000,9.449822e-002,0.000000e+000,3,2.336349e-001,1.825000e+000,,,,,,,,,,,,,,,,,,0,5.000000e+000,5.000000e-001,2,1,6.027985e-001,0,1,0,
1473341401.866,,5.000000e+001,1.095602e+002,-4.219946e-006,0.000000e+000,9.070745e-002,0.000000e+000,3,2.274357e-001,1.825000e+000,,,,,,,,,,,,,,,,,,0,5.000000e+000,5.000000e-001,2,1,6.874008e-001,0,0,0,
1473341413.438,,5.000000e+001,1.086998e+002,-4.210553e-006,0.000000e+000,9.108146e-002,0.000000e+000,3,2.273039e-001,1.825000e+000,,,,,,,,,,,,,,,,,,0,5.000000e+000,5.000000e-001,2,1,6.881027e-001,0,0,0,
1473341426.903,,5.000000e+001,1.077933e+002,-4.185186e-006,0.000000e+000,9.184354e-002,0.000000e+000,3,2.213476e-001,1.825000e+000,,,,,,,,,,,,,,,,,,0,5.000000e+000,5.000000e-001,2,1,7.523041e-001,0,0,0,
1473341441.394,,5.000000e+001,1.066929e+002,-4.187331e-006,0.000000e+000,9.020378e-002,0.000000e+000,3,2.234215e-001,1.825000e+000,,,,,,,,,,,,,,,,,,0,5.000000e+000,5.000000e-001,2,1,7.537003e-001,0,0,0,
1473341472.610,,5.000000e+001,1.041920e+002,-4.134799e-006,0.000000e+000,9.028954e-002,0.000000e+000,3,2.127289e-001,1.825000e+000,,,,,,,,,,,,,,,,,,0,5.000000e+000,5.000000e-001,2,1,8.162003e-001,0,0,0,
1473341484.881,,5.000000e+001,1.031781e+002,-4.139619e-006,0.000000e+000,9.074495e-002,0.000000e+000,3,2.162672e-001,1.825000e+000,,,,,,,,,,,,,,,,,,0,5.000000e+000,5.000000e-001,2,1,8.333054e-001,0,0,0,
1473341499.551,,5.000000e+001,1.019266e+002,-4.099026e-006,0.000000e+000,8.851425e-002,0.000000e+000,3,2.066717e-001,1.825000e+000,,,,,,,,,,,,,,,,,,0,5.000000e+000,5.000000e-001,2,1,8.698044e-001,0,0,0,
1473341512.934,,5.000000e+001,1.008920e+002,-4.078616e-006,0.000000e+000,9.129114e-002,0.000000e+000,3,1.996161e-001,1.825000e+000,,,,,,,,,,,,,,,,,,0,5.000000e+000,5.000000e-001,2,1,8.556976e-001,0,0,0,
1473341534.209,,5.000000e+001,9.889280e+001,-4.069303e-006,0.000000e+000,9.005494e-002,0.000000e+000,3,2.009668e-001,1.825000e+000,,,,,,,,,,,,,,,,,,0,5.000000e+000,5.000000e-001,2,1,9.266052e-001,0,0,0,
1473341547.174,,5.000000e+001,9.777899e+001,-4.022328e-006,0.000000e+000,9.039085e-002,0.000000e+000,3,1.915382e-001,1.825000e+000,,,,,,,,,,,,,,,,,,0,5.000000e+000,5.000000e-001,2,1,9.180908e-001,0,0,0,
1473341560.388,,5.000000e+001,9.674353e+001,-4.003374e-006,0.000000e+000,8.992223e-002,0.000000e+000,3,1.864637e-001,1.825000e+000,,,,,,,,,,,,,,,,,,0,5.000000e+000,5.000000e-001,2,1,7.032623e-001,0,0,0,
1473341573.293,,5.000000e+001,9.532858e+001,-3.949824e-006,0.000000e+000,8.798151e-002,0.000000e+000,3,1.753037e-001,1.825000e+000,,,,,,,,,,,,,,,,,,0,5.000000e+000,5.000000e-001,2,1,7.221680e-001,0,0,0,
1473341589.313,,5.000000e+001,9.378204e+001,-3.906290e-006,0.000000e+000,8.976862e-002,0.000000e+000,3,1.701510e-001,1.825000e+000,,,,,,,,,,,,,,,,,,0,5.000000e+000,5.000000e-001,2,1,9.802856e-001,0,0,0,
1473341602.696,,5.000000e+001,9.259267e+001,-3.861422e-006,0.000000e+000,9.090573e-002,0.000000e+000,3,1.587339e-001,1.825000e+000,,,,,,,,,,,,,,,,,,0,5.000000e+000,5.000000e-001,2,1,9.589767e-001,0,0,0,
1473341616.410,,5.000000e+001,9.125318e+001,-3.794417e-006,0.000000e+000,8.831809e-002,0.000000e+000,3,1.426707e-001,1.825000e+000,,,,,,,,,,,,,,,,,,0,5.000000e+000,5.000000e-001,2,1,7.256622e-001,0,0,0,
1473341628.125,,5.000000e+001,9.013010e+001,-3.749867e-006,0.000000e+000,8.870386e-002,0.000000e+000,3,1.342468e-001,1.825000e+000,,,,,,,,,,,,,,,,,,0,5.000000e+000,5.000000e-001,2,1,9.707260e-001,0,0,0,
1473341641.589,,5.000000e+001,8.870704e+001,-3.689754e-006,0.000000e+000,8.941571e-002,0.000000e+000,3,1.174832e-001,1.825000e+000,,,,,,,,,,,,,,,,,,0,5.000000e+000,5.000000e-001,2,1,9.680176e-001,0,0,0,
1473341654.303,,5.000000e+001,8.762622e+001,-3.602766e-006,0.000000e+000,8.971286e-002,0.000000e+000,3,9.524922e-002,1.825000e+000,,,,,,,,,,,,,,,,,,0,5.000000e+000,5.000000e-001,2,1,7.176056e-001,0,0,0,
1473341667.518,,5.000000e+001,8.628981e+001,-3.523110e-006,0.000000e+000,9.095909e-002,0.000000e+000,3,7.464924e-002,1.825000e+000,,,,,,,,,,,,,,,,,,0,5.000000e+000,5.000000e-001,2,1,9.857254e-001,0,0,0,
1473341679.732,,5.000000e+001,8.499239e+001,-3.395871e-006,0.000000e+000,9.050227e-002,0.000000e+000,3,4.035251e-002,1.825000e+000,,,,,,,,,,,,,,,,,,0,5.000000e+000,5.000000e-001,2,1,7.116013e-001,0,0,0,
1473341694.696,,5.000000e+001,8.382482e+001,-3.256810e-006,0.000000e+000,8.859669e-002,0.000000e+000,3,3.539045e-004,1.825000e+000,,,,,,,,,,,,,,,,,,0,5.000000e+000,5.000000e-001,2,1,1.166504e+000,0,0,0,
1473341707.911,,5.000000e+001,8.247093e+001,-3.094237e-006,0.000000e+000,9.350687e-002,0.000000e+000,3,0.000000e+000,1.825000e+000,,,,,,,,,,,,,,,,,,0,5.000000e+000,5.000000e-001,2,1,6.803665e-001,0,0,0,
1473341721.375,,5.000000e+001,8.147705e+001,-2.906960e-006,0.000000e+000,9.362571e-002,0.000000e+000,3,0.000000e+000,1.825000e+000,,,,,,,,,,,,,,,,,,0,5.000000e+000,5.000000e-001,2,1,8.276901e-001,0,0,0,
1473341734.779,,5.000000e+001,8.002347e+001,-2.683406e-006,0.000000e+000,9.684094e-002,0.000000e+000,3,0.000000e+000,1.825000e+000,,,,,,,,,,,,,,,,,,0,5.000000e+000,5.000000e-001,2,1,8.214645e-001,0,0,0,
1473341873.367,,5.000000e+001,8.016296e+001,-2.685577e-006,0.000000e+000,9.648456e-002,0.000000e+000,3,0.000000e+000,1.825000e+000,,,,,,,,,,,,,,,,,,0,5.000000e+000,5.000000e-001,2,1,7.659912e-003,0,1,0,
1473341884.620,,5.000000e+001,8.014229e+001,-2.644973e-006,0.000000e+000,9.116384e-002,0.000000e+000,3,0.000000e+000,1.825000e+000,,,,,,,,,,,,,,,,,,0,5.000000e+000,5.000000e-001,2,1,4.899597e-002,0,1,0,
1473341897.858,,5.000000e+001,8.012621e+001,-2.642664e-006,0.000000e+000,9.382652e-002,0.000000e+000,3,0.000000e+000,1.825000e+000,,,,,,,,,,,,,,,,,,0,5.000000e+000,5.000000e-001,2,1,1.683044e-002,0,1,0,
1473341911.588,,5.000000e+001,8.011549e+001,-2.664610e-006,0.000000e+000,9.115176e-002,0.000000e+000,3,0.000000e+000,1.825000e+000,,,,,,,,,,,,,,,,,,0,5.000000e+000,5.000000e-001,2,1,7.667542e-003,0,1,0,
1473342101.573,,5.000000e+001,8.001385e+001,-2.688534e-006,0.000000e+000,9.434061e-002,0.000000e+000,3,0.000000e+000,1.825000e+000,,,,,,,,,,,,,,,,,,0,5.000000e+000,5.000000e-001,2,1,3.044128e-003,0,1,0,
1473342113.287,,5.000000e+001,8.000927e+001,-2.628713e-006,0.000000e+000,9.183585e-002,0.000000e+000,3,0.000000e+000,1.825000e+000,,,,,,,,,,,,,,,,,,0,5.000000e+000,5.000000e-001,2,1,9.155273e-003,0,1,0,
1473342125.251,,5.000000e+001,8.001003e+001,-2.705925e-006,0.000000e+000,9.427712e-002,0.000000e+000,3,0.000000e+000,1.825000e+000,,,,,,,,,,,,,,,,,,0,5.000000e+000,5.000000e-001,2,1,1.068115e-002,0,1,0,
1473342137.966,,5.000000e+001,8.001385e+001,-2.684900e-006,0.000000e+000,9.170413e-002,0.000000e+000,3,0.000000e+000,1.825000e+000,,,,,,,,,,,,,,,,,,0,5.000000e+000,5.000000e-001,2,1,3.044128e-003,0,0,0,
1473342318.947,,5.000000e+001,7.651761e+001,-1.611471e-006,0.000000e+000,2.268809e-002,0.000000e+000,3,0.000000e+000,1.825000e+000,,,,,,,,,,,,,,,,,,0,5.000000e+000,5.000000e-001,2,1,4.570847e-001,0,0,0,
1473342331.411,,5.000000e+001,7.591319e+001,-1.382108e-006,0.000000e+000,7.099657e-002,0.000000e+000,3,0.000000e+000,1.825000e+000,,,,,,,,,,,,,,,,,,0,5.000000e+000,5.000000e-001,2,1,5.012207e-001,0,0,0,
1473342343.875,,5.000000e+001,7.526088e+001,-9.781980e-007,0.000000e+000,0.000000e+000,0.000000e+000,3,0.000000e+000,1.825000e+000,,,,,,,,,,,,,,,,,,0,5.000000e+000,5.000000e-001,2,1,5.458908e-001,0,0,0,
1473342356.840,,5.000000e+001,7.457723e+001,-5.458399e-007,0.000000e+000,0.000000e+000,0.000000e+000,3,0.000000e+000,1.825000e+000,,,,,,,,,,,,,,,,,,0,5.000000e+000,5.000000e-001,2,1,5.737000e-001,0,0,0,
1473342375.304,,5.000000e+001,7.356869e+001,2.875693e-007,0.000000e+000,0.000000e+000,0.000000e+000,3,0.000000e+000,1.825000e+000,,,,,,,,,,,,,,,,,,0,5.000000e+000,5.000000e-001,2,1,5.874023e-001,0,0,0,
1473342386.800,,5.000000e+001,7.279457e+001,1.033003e-006,0.000000e+000,0.000000e+000,0.000000e+000,3,0.000000e+000,1.825000e+000,,,,,,,,,,,,,,,,,,0,5.000000e+000,5.000000e-001,2,1,6.391678e-001,0,0,0,
1473342398.517,,5.000000e+001,7.224101e+001,3.092913e-006,0.000000e+000,-1.224910e+000,0.000000e+000,3,5.310279e-003,1.825000e+000,,,,,,,,,,,,,,,,,,0,5.000000e+000,5.000000e-001,2,1,4.679642e-001,0,0,0,
1473342412.231,,5.000000e+001,7.130579e+001,3.718533e-006,0.000000e+000,-3.044780e-001,0.000000e+000,3,1.058010e-001,1.825000e+000,,,,,,,,,,,,,,,,,,0,5.000000e+000,5.000000e-001,2,1,7.830658e-001,0,0,0,
1473342425.499,,5.000000e+001,7.045834e+001,6.036046e-006,0.000000e+000,-8.942722e-002,0.000000e+000,3,4.415962e-001,1.825000e+000,,,,,,,,,,,,,,,,,,0,5.000000e+000,5.000000e-001,2,1,6.121750e-001,0,0,0,
1473342438.492,,5.000000e+001,6.966054e+001,9.939326e-006,0.000000e+000,-2.947609e-002,0.000000e+000,3,6.498779e-001,1.825000e+000,,,,,,,,,,,,,,,,,,0,5.000000e+000,5.000000e-001,2,1,6.521912e-001,0,0,0,
1473342452.706,,5.000000e+001,6.871652e+001,1.859720e-005,0.000000e+000,2.835913e-003,0.000000e+000,3,7.975362e-001,1.825000e+000,,,,,,,,,,,,,,,,,,0,5.000000e+000,5.000000e-001,2,1,6.540375e-001,0,0,0,
1473342466.367,,5.000000e+001,6.790974e+001,3.961398e-005,0.000000e+000,1.920390e-002,0.000000e+000,3,8.836748e-001,1.825000e+000,,,,,,,,,,,,,,,,,,0,5.000000e+000,5.000000e-001,2,1,6.305618e-001,0,0,0,
1473342496.279,,5.000000e+001,6.569740e+001,1.662069e-004,0.000000e+000,2.110335e-002,0.000000e+000,3,9.573476e-001,1.825000e+000,,,,,,,,,,,,,,,,,,0,5.000000e+000,5.000000e-001,2,1,4.978943e-001,0,0,0,
1473342509.494,,5.000000e+001,6.488890e+001,2.186969e-004,0.000000e+000,1.974607e-002,0.000000e+000,3,9.660781e-001,1.825000e+000,,,,,,,,,,,,,,,,,,0,5.000000e+000,5.000000e-001,2,1,4.658661e-001,0,0,0,
1473342522.722,,5.000000e+001,6.390430e+001,2.615078e-004,0.000000e+000,1.888612e-002,0.000000e+000,3,9.706562e-001,1.825000e+000,,,,,,,,,,,,,,,,,,0,5.000000e+000,5.000000e-001,2,1,5.041504e-001,0,0,0,
1473342535.881,,5.000000e+001,6.305308e+001,2.957355e-004,0.000000e+000,1.833486e-002,0.000000e+000,3,9.730662e-001,1.825000e+000,,,,,,,,,,,,,,,,,,0,5.000000e+000,5.000000e-001,2,1,5.630379e-001,0,0,0,
1473342569.300,,5.000000e+001,6.080383e+001,3.645360e-004,0.000000e+000,1.716012e-002,0.000000e+000,3,9.761966e-001,1.825000e+000,,,,,,,,,,,,,,,,,,0,5.000000e+000,5.000000e-001,2,1,5.922394e-001,0,1,0,
1473342584.021,,5.000000e+001,5.980267e+001,3.886959e-004,0.000000e+000,1.683173e-002,0.000000e+000,3,9.767365e-001,1.825000e+000,,,,,,,,,,,,,,,,,,0,5.000000e+000,5.000000e-001,2,1,7.729530e-001,0,1,0,
1473342597.486,,5.000000e+001,5.895237e+001,4.091600e-004,0.000000e+000,1.651315e-002,0.000000e+000,3,9.772763e-001,1.825000e+000,,,,,,,,,,,,,,,,,,0,5.000000e+000,5.000000e-001,2,1,6.175308e-001,0,1,0,
1473342609.978,,5.000000e+001,5.821029e+001,4.271143e-004,0.000000e+000,1.621455e-002,0.000000e+000,3,9.776096e-001,1.825000e+000,,,,,,,,,,,,,,,,,,0,5.000000e+000,5.000000e-001,2,1,5.877304e-001,0,1,0,
1473342624.960,,5.000000e+001,5.732120e+001,4.469858e-004,0.000000e+000,1.583359e-002,0.000000e+000,3,9.780173e-001,1.825000e+000,,,,,,,,,,,,,,,,,,0,5.000000e+000,5.000000e-001,2,1,5.753975e-001,0,1,0,
1473342636.482,,5.000000e+001,5.660223e+001,4.614409e-004,0.000000e+000,1.558138e-002,0.000000e+000,3,9.782599e-001,1.825000e+000,,,,,,,,,,,,,,,,,,0,5.000000e+000,5.000000e-001,2,1,5.600319e-001,0,1,0,
1473342649.196,,5.000000e+001,5.589967e+001,4.764557e-004,0.000000e+000,1.527327e-002,0.000000e+000,3,9.784545e-001,1.825000e+000,,,,,,,,,,,,,,,,,,0,5.000000e+000,5.000000e-001,2,1,5.559502e-001,0,1,0,
1473342661.910,,5.000000e+001,5.513231e+001,4.907533e-004,0.000000e+000,1.504793e-002,0.000000e+000,3,9.786606e-001,1.825000e+000,,,,,,,,,,,,,,,,,,0,5.000000e+000,5.000000e-001,2,1,4.307327e-001,0,1,0,
1473342676.374,,5.000000e+001,5.431870e+001,5.063756e-004,0.000000e+000,1.477959e-002,0.000000e+000,3,9.789294e-001,1.825000e+000,,,,,,,,,,,,,,,,,,0,5.000000e+000,5.000000e-001,2,1,4.239311e-001,0,1,0,
1473342689.339,,5.000000e+001,5.357989e+001,5.197463e-004,0.000000e+000,1.450849e-002,0.000000e+000,3,9.790811e-001,1.825000e+000,,,,,,,,,,,,,,,,,,0,5.000000e+000,5.000000e-001,2,1,5.367088e-001,0,1,0,
1473342701.808,,5.000000e+001,5.293242e+001,5.321958e-004,0.000000e+000,1.431216e-002,0.000000e+000,3,9.791581e-001,1.825000e+000,,,,,,,,,,,,,,,,,,0,5.000000e+000,5.000000e-001,2,1,5.230713e-001,0,1,0,
1473342714.522,,5.000000e+001,5.229149e+001,5.442497e-004,0.000000e+000,1.408416e-002,0.000000e+000,3,9.793163e-001,1.825000e+000,,,,,,,,,,,,,,,,,,0,5.000000e+000,5.000000e-001,2,1,5.043602e-001,0,1,0,
1473342727.487,,5.000000e+001,5.164085e+001,5.563620e-004,0.000000e+000,1.381732e-002,0.000000e+000,3,9.793930e-001,1.825000e+000,,,,,,,,,,,,,,,,,,0,5.000000e+000,5.000000e-001,2,1,5.189476e-001,0,1,0,
1473342740.701,,5.000000e+001,5.086694e+001,5.684501e-004,0.000000e+000,1.359074e-002,0.000000e+000,3,9.795045e-001,1.825000e+000,,,,,,,,,,,,,,,,,,0,5.000000e+000,5.000000e-001,2,1,5.030098e-001,0,1,0,
1473342753.969,,5.000000e+001,5.025106e+001,5.801853e-004,0.000000e+000,1.333271e-002,0.000000e+000,3,9.795919e-001,1.825000e+000,,,,,,,,,,,,,,,,,,0,5.000000e+000,5.000000e-001,2,1,4.953079e-001,0,1,0,
1473342765.705,,5.000000e+001,4.962287e+001,5.902438e-004,0.000000e+000,1.312923e-002,0.000000e+000,3,9.796687e-001,1.825000e+000,,,,,,,,,,,,,,,,,,0,5.000000e+000,5.000000e-001,2,1,4.983597e-001,0,1,0,
1473342779.420,,5.000000e+001,4.892884e+001,6.016520e-004,0.000000e+000,1.289370e-002,0.000000e+000,3,9.797896e-001,1.825000e+000,,,,,,,,,,,,,,,,,,0,5.000000e+000,5.000000e-001,2,1,3.803406e-001,0,1,0,
1473342791.634,,5.000000e+001,4.836907e+001,6.117716e-004,0.000000e+000,1.272585e-002,0.000000e+000,3,9.798283e-001,1.825000e+000,,,,,,,,,,,,,,,,,,0,5.000000e+000,5.000000e-001,2,1,5.030174e-001,0,1,0,
1473342804.613,,5.000000e+001,4.769386e+001,6.222429e-004,0.000000e+000,1.249342e-002,0.000000e+000,3,9.799613e-001,1.825000e+000,,,,,,,,,,,,,,,,,,0,5.000000e+000,5.000000e-001,2,1,3.691292e-001,0,1,0,
1473342816.027,,5.000000e+001,4.708249e+001,6.312005e-004,0.000000e+000,1.229706e-002,0.000000e+000,3,9.799566e-001,1.825000e+000,,,,,,,,,,,,,,,,,,0,5.000000e+000,5.000000e-001,2,1,3.645325e-001,0,1,0,
1473342827.645,,5.000000e+001,4.652711e+001,6.403910e-004,0.000000e+000,1.215090e-002,0.000000e+000,3,9.800615e-001,1.825000e+000,,,,,,,,,,,,,,,,,,0,5.000000e+000,5.000000e-001,2,1,4.917297e-001,0,1,0,
1473342840.359,,5.000000e+001,4.597479e+001,6.499974e-004,0.000000e+000,1.198661e-002,0.000000e+000,3,9.801829e-001,1.825000e+000,,,,,,,,,,,,,,,,,,0,5.000000e+000,5.000000e-001,2,1,6.129189e-001,0,1,0,
1473342852.509,,5.000000e+001,4.529015e+001,6.592044e-004,0.000000e+000,1.177365e-002,0.000000e+000,3,9.801891e-001,1.825000e+000,,,,,,,,,,,,,,,,,,0,5.000000e+000,5.000000e-001,2,1,4.978523e-001,0,1,0,
1473342865.331,,5.000000e+001,4.468089e+001,6.687124e-004,0.000000e+000,1.157471e-002,0.000000e+000,3,9.802482e-001,1.825000e+000,,,,,,,,,,,,,,,,,,0,5.000000e+000,5.000000e-001,2,1,4.851189e-001,0,1,0,
1473342880.296,,5.000000e+001,4.394457e+001,6.795969e-004,0.000000e+000,1.139793e-002,0.000000e+000,3,9.803245e-001,1.825000e+000,,,,,,,,,,,,,,,,,,0,5.000000e+000,5.000000e-001,2,1,5.000496e-001,0,1,0,
1473342893.010,,5.000000e+001,4.338999e+001,6.886980e-004,0.000000e+000,1.119631e-002,0.000000e+000,3,9.804444e-001,1.825000e+000,,,,,,,,,,,,,,,,,,0,5.000000e+000,5.000000e-001,2,1,3.658180e-001,0,1,0,
1473342906.724,,5.000000e+001,4.263852e+001,6.983569e-004,0.000000e+000,1.102326e-002,0.000000e+000,3,9.804624e-001,1.825000e+000,,,,,,,,,,,,,,,,,,0,5.000000e+000,5.000000e-001,2,1,3.702927e-001,0,1,0,
1473342918.189,,5.000000e+001,4.209055e+001,7.062452e-004,0.000000e+000,1.079712e-002,0.000000e+000,3,9.805433e-001,1.825000e+000,,,,,,,,,,,,,,,,,,0,5.000000e+000,5.000000e-001,2,1,4.863396e-001,0,1,0,
1473342931.903,,5.000000e+001,4.147152e+001,7.156490e-004,0.000000e+000,1.064973e-002,0.000000e+000,3,9.805599e-001,1.825000e+000,,,,,,,,,,,,,,,,,,0,5.000000e+000,5.000000e-001,2,1,5.013390e-001,0,1,0,
1473342945.117,,5.000000e+001,4.084817e+001,7.245582e-004,0.000000e+000,1.047634e-002,0.000000e+000,3,9.806132e-001,1.825000e+000,,,,,,,,,,,,,,,,,,0,5.000000e+000,5.000000e-001,2,1,5.021400e-001,0,1,0,
1473342959.332,,5.000000e+001,4.016312e+001,7.338883e-004,0.000000e+000,1.027764e-002,0.000000e+000,3,9.806247e-001,1.825000e+000,,,,,,,,,,,,,,,,,,0,5.000000e+000,5.000000e-001,2,1,6.135101e-001,0,1,0,
1473342987.867,,5.000000e+001,3.870856e+001,7.527223e-004,0.000000e+000,9.894412e-003,0.000000e+000,3,9.807325e-001,1.825000e+000,,,,,,,,,,,,,,,,,,0,5.000000e+000,5.000000e-001,2,1,5.091400e-001,0,1,0,
1473343000.950,,5.000000e+001,3.807053e+001,7.612800e-004,0.000000e+000,9.668522e-003,0.000000e+000,3,9.806901e-001,1.825000e+000,,,,,,,,,,,,,,,,,,0,5.000000e+000,5.000000e-001,2,1,5.197105e-001,0,0,0,
1473343013.914,,5.000000e+001,3.733756e+001,7.698655e-004,0.000000e+000,9.573760e-003,0.000000e+000,3,9.807358e-001,1.825000e+000,,,,,,,,,,,,,,,,,,0,5.000000e+000,5.000000e-001,2,1,6.764488e-001,0,0,0,
1473343026.128,,5.000000e+001,3.665247e+001,7.779626e-004,0.000000e+000,9.406878e-003,0.000000e+000,3,9.807568e-001,1.825000e+000,,,,,,,,,,,,,,,,,,0,5.000000e+000,5.000000e-001,2,1,6.937408e-001,0,0,0,
1473343038.593,,5.000000e+001,3.594858e+001,7.864273e-004,0.000000e+000,9.287639e-003,0.000000e+000,3,9.807743e-001,1.825000e+000,,,,,,,,,,,,,,,,,,0,5.000000e+000,5.000000e-001,2,1,4.413185e-001,0,0,0,
1473343052.057,,5.000000e+001,3.521407e+001,7.956176e-004,0.000000e+000,9.036451e-003,0.000000e+000,3,9.807622e-001,1.825000e+000,,,,,,,,,,,,,,,,,,0,5.000000e+000,5.000000e-001,2,1,4.500084e-001,0,0,0,
1473343063.521,,5.000000e+001,3.453585e+001,8.035706e-004,0.000000e+000,8.891199e-003,0.000000e+000,3,9.807926e-001,1.825000e+000,,,,,,,,,,,,,,,,,,0,5.000000e+000,5.000000e-001,2,1,5.995407e-001,0,0,0,
1473343076.986,,5.000000e+001,3.381052e+001,8.127222e-004,0.000000e+000,8.803801e-003,0.000000e+000,3,9.808972e-001,1.825000e+000,,,,,,,,,,,,,,,,,,0,5.000000e+000,5.000000e-001,2,1,5.360909e-001,0,0,0,
1473343088.950,,5.000000e+001,3.302850e+001,8.211565e-004,0.000000e+000,8.550506e-003,0.000000e+000,3,9.809728e-001,1.825000e+000,,,,,,,,,,,,,,,,,,0,5.000000e+000,5.000000e-001,2,1,7.415771e-001,0,0,0,
1473343102.664,,5.000000e+001,3.204404e+001,8.305297e-004,0.000000e+000,8.353350e-003,0.000000e+000,3,9.809342e-001,1.825000e+000,,,,,,,,,,,,,,,,,,0,5.000000e+000,5.000000e-001,2,1,6.147079e-001,0,0,0,
1473343116.879,,5.000000e+001,3.112053e+001,8.402372e-004,0.000000e+000,8.187993e-003,0.000000e+000,3,9.809727e-001,1.825000e+000,,,,,,,,,,,,,,,,,,0,5.000000e+000,5.000000e-001,2,1,6.290798e-001,0,0,0,
1473343129.593,,5.000000e+001,3.034086e+001,8.489405e-004,0.000000e+000,8.026859e-003,0.000000e+000,3,9.810220e-001,1.825000e+000,,,,,,,,,,,,,,,,,,0,5.000000e+000,5.000000e-001,2,1,6.280899e-001,0,0,0,
1473343142.057,,5.000000e+001,2.954665e+001,8.573172e-004,0.000000e+000,7.827551e-003,0.000000e+000,3,9.810814e-001,1.825000e+000,,,,,,,,,,,,,,,,,,0,5.000000e+000,5.000000e-001,2,1,6.391697e-001,0,0,0,
1473343154.827,,5.000000e+001,2.866016e+001,8.658040e-004,0.000000e+000,7.669985e-003,0.000000e+000,3,9.810717e-001,1.825000e+000,,,,,,,,,,,,,,,,,,0,5.000000e+000,5.000000e-001,2,1,4.933491e-001,0,0,0,
1473343167.303,,5.000000e+001,2.776628e+001,8.739661e-004,0.000000e+000,7.531199e-003,0.000000e+000,3,9.810614e-001,1.825000e+000,,,,,,,,,,,,,,,,,,0,5.000000e+000,5.000000e-001,2,1,6.625805e-001,0,0,0,
1473343179.517,,5.000000e+001,2.695076e+001,8.816795e-004,0.000000e+000,7.375506e-003,0.000000e+000,3,9.811030e-001,1.825000e+000,,,,,,,,,,,,,,,,,,0,5.000000e+000,5.000000e-001,2,1,6.557484e-001,0,0,0,
1473343193.981,,5.000000e+001,2.596896e+001,8.905927e-004,0.000000e+000,7.171557e-003,0.000000e+000,3,9.811508e-001,1.825000e+000,,,,,,,,,,,,,,,,,,0,5.000000e+000,5.000000e-001,2,1,6.581707e-001,0,0,0,
1473343208.446,,5.000000e+001,2.506521e+001,8.992049e-004,0.000000e+000,7.054288e-003,0.000000e+000,3,9.812226e-001,1.825000e+000,,,,,,,,,,,,,,,,,,0,5.000000e+000,5.000000e-001,2,1,5.014992e-001,0,0,0,
1473343220.845,,5.000000e+001,2.432820e+001,9.063240e-004,0.000000e+000,6.900546e-003,0.000000e+000,3,9.811995e-001,1.825000e+000,,,,,,,,,,,,,,,,,,0,5.000000e+000,5.000000e-001,2,1,6.378403e-001,0,0,0,
1473343234.167,,5.000000e+001,2.361699e+001,9.109088e-004,0.000000e+000,6.779719e-003,0.000000e+000,3,9.813237e-001,1.825000e+000,,,,,,,,,,,,,,,,,,0,5.000000e+000,5.000000e-001,2,1,2.584209e-001,0,0,0,
1473343247.132,,5.000000e+001,2.323344e+001,9.143010e-004,0.000000e+000,6.784444e-003,0.000000e+000,3,9.812896e-001,1.825000e+000,,,,,,,,,,,,,,,,,,0,5.000000e+000,5.000000e-001,2,1,3.910503e-001,0,0,0,
1473343260.846,,5.000000e+001,2.241193e+001,9.211895e-004,0.000000e+000,6.662716e-003,0.000000e+000,3,9.812400e-001,1.825000e+000,,,,,,,,,,,,,,,,,,0,5.000000e+000,5.000000e-001,2,1,6.769199e-001,0,0,0,
1473343272.810,,5.000000e+001,2.146243e+001,9.275235e-004,0.000000e+000,6.548868e-003,0.000000e+000,3,9.811971e-001,1.825000e+000,,,,,,,,,,,,,,,,,,0,5.000000e+000,5.000000e-001,2,1,5.422096e-001,0,0,0,
1473343285.524,,5.000000e+001,2.084824e+001,9.323563e-004,0.000000e+000,6.419443e-003,0.000000e+000,3,9.812636e-001,1.825000e+000,,,,,,,,,,,,,,,,,,0,5.000000e+000,5.000000e-001,2,1,1.714687e-001,0,0,0,
1473343296.741,,5.000000e+001,2.072225e+001,9.330514e-004,0.000000e+000,6.383724e-003,0.000000e+000,3,9.814318e-001,1.825000e+000,,,,,,,,,,,,,,,,,,0,5.000000e+000,5.000000e-001,2,1,3.644180e-002,0,0,0,
1473343308.755,,5.000000e+001,2.024156e+001,9.363425e-004,0.000000e+000,6.479531e-003,0.000000e+000,3,9.813286e-001,1.825000e+000,,,,,,,,,,,,,,,,,,0,5.000000e+000,5.000000e-001,2,1,6.678391e-001,0,0,0,
1473343324.723,,5.000000e+001,1.919694e+001,9.451145e-004,0.000000e+000,6.321297e-003,0.000000e+000,3,9.813632e-001,1.825000e+000,,,,,,,,,,,,,,,,,,0,5.000000e+000,5.000000e-001,2,1,6.910992e-001,0,0,0,
1473343337.470,,5.000000e+001,1.824574e+001,9.516068e-004,0.000000e+000,6.199930e-003,0.000000e+000,3,9.813091e-001,1.825000e+000,,,,,,,,,,,,,,,,,,0,5.000000e+000,5.000000e-001,2,1,8.724499e-001,0,0,0,
1473343350.434,,5.000000e+001,1.730597e+001,9.576916e-004,0.000000e+000,6.128913e-003,0.000000e+000,3,9.813874e-001,1.825000e+000,,,,,,,,,,,,,,,,,,0,5.000000e+000,5.000000e-001,2,1,6.612396e-001,0,0,0,
1473343364.148,,5.000000e+001,1.644423e+001,9.625913e-004,0.000000e+000,6.040508e-003,0.000000e+000,3,9.814428e-001,1.825000e+000,,,,,,,,,,,,,,,,,,0,5.000000e+000,5.000000e-001,2,1,4.969387e-001,0,0,0,
1473343378.417,,5.000000e+001,1.586341e+001,9.662145e-004,0.000000e+000,5.996994e-003,0.000000e+000,3,9.814756e-001,1.825000e+000,,,,,,,,,,,,,,,,,,0,5.000000e+000,5.000000e-001,2,1,4.285698e-001,0,0,0,
1473343391.381,,5.000000e+001,1.563287e+001,9.665419e-004,0.000000e+000,5.964721e-003,0.000000e+000,3,9.815665e-001,1.825000e+000,,,,,,,,,,,,,,,,,,0,5.000000e+000,5.000000e-001,2,1,2.719975e-002,0,0,0,
1473343403.345,,5.000000e+001,1.563258e+001,9.664276e-004,0.000000e+000,6.007478e-003,0.000000e+000,3,9.815226e-001,1.825000e+000,,,,,,,,,,,,,,,,,,0,5.000000e+000,5.000000e-001,2,1,5.307007e-002,0,0,0,
1473343416.559,,5.000000e+001,1.513146e+001,9.701313e-004,0.000000e+000,5.991322e-003,0.000000e+000,3,9.814598e-001,1.825000e+000,,,,,,,,,,,,,,,,,,0,5.000000e+000,5.000000e-001,2,1,8.227501e-001,0,0,0,
1473343429.473,,5.000000e+001,1.403901e+001,9.755637e-004,0.000000e+000,5.923607e-003,0.000000e+000,3,9.814564e-001,1.825000e+000,,,,,,,,,,,,,,,,,,0,5.000000e+000,5.000000e-001,2,1,1.038590e+000,0,0,0,
1473343442.799,,5.000000e+001,1.286111e+001,9.812794e-004,0.000000e+000,5.856527e-003,0.000000e+000,3,9.814599e-001,1.825000e+000,,,,,,,,,,,,,,,,,,0,5.000000e+000,5.000000e-001,2,1,8.744097e-001,0,0,0,
1473343461.514,,5.000000e+001,1.214349e+001,9.834482e-004,0.000000e+000,5.753389e-003,0.000000e+000,3,9.815679e-001,1.825000e+000,,,,,,,,,,,,,,,,,,0,5.000000e+000,5.000000e-001,2,1,1.415195e-001,0,1,0,
1473343678.753,,5.000000e+001,1.500274e+001,9.701078e-004,0.000000e+000,6.059704e-003,0.000000e+000,3,9.815519e-001,1.825000e+000,,,,,,,,,,,,,,,,,,0,5.000000e+000,5.000000e-001,2,1,0.000000e+000,0,1,0,
1473343691.217,,5.000000e+001,1.500365e+001,9.701314e-004,0.000000e+000,5.983014e-003,0.000000e+000,3,9.815103e-001,1.825000e+000,,,,,,,,,,,,,,,,,,0,5.000000e+000,5.000000e-001,2,1,6.093979e-004,0,1,0,
1473343702.431,,5.000000e+001,1.500243e+001,9.700558e-004,0.000000e+000,6.076987e-003,0.000000e+000,3,9.815609e-001,1.825000e+000,,,,,,,,,,,,,,,,,,0,5.000000e+000,5.000000e-001,2,1,6.103516e-004,0,1,0,
1473343714.645,,5.000000e+001,1.500152e+001,9.701785e-004,0.000000e+000,6.005610e-003,0.000000e+000,3,9.815247e-001,1.825000e+000,,,,,,,,,,,,,,,,,,0,5.000000e+000,5.000000e-001,2,1,1.219749e-003,0,1,0,
1473343807.368,,5.000000e+001,1.499694e+001,9.701707e-004,0.000000e+000,6.050171e-003,0.000000e+000,3,9.815559e-001,1.825000e+000,,,,,,,,,,,,,,,,,,0,5.000000e+000,5.000000e-001,2,1,6.093979e-004,0,0,0,
1473343819.582,,5.000000e+001,1.499573e+001,9.702342e-004,0.000000e+000,6.044202e-003,0.000000e+000,3,9.814947e-001,1.825000e+000,,,,,,,,,,,,,,,,,,0,5.000000e+000,5.000000e-001,2,1,1.830101e-003,0,0,0,
1473343831.046,,5.000000e+001,1.499512e+001,9.701583e-004,0.000000e+000,6.019925e-003,0.000000e+000,3,9.815397e-001,1.825000e+000,,,,,,,,,,,,,,,,,,0,5.000000e+000,5.000000e-001,2,1,1.830101e-003,0,0,0,
1473343843.510,,5.000000e+001,1.499512e+001,9.702350e-004,0.000000e+000,6.070207e-003,0.000000e+000,3,9.815312e-001,1.825000e+000,,,,,,,,,,,,,,,,,,0,5.000000e+000,5.000000e-001,2,1,1.830101e-003,0,0,0,
1473343907.268,,5.000000e+001,1.379224e+001,9.769476e-004,0.000000e+000,5.995365e-003,0.000000e+000,3,9.815921e-001,1.825000e+000,,,,,,,,,,,,,,,,,,0,5.000000e+000,5.000000e-001,2,1,2.824602e-001,0,0,0,
1473343920.982,,5.000000e+001,1.346234e+001,9.784319e-004,0.000000e+000,5.971089e-003,0.000000e+000,3,9.815496e-001,1.825000e+000,,,,,,,,,,,,,,,,,,0,5.000000e+000,5.000000e-001,2,1,2.684393e-001,0,0,0,
1473343933.696,,5.000000e+001,1.317302e+001,9.797121e-004,0.000000e+000,5.984786e-003,0.000000e+000,3,9.815745e-001,1.825000e+000,,,,,,,,,,,,,,,,,,0,5.000000e+000,5.000000e-001,2,1,2.062407e-001,0,0,0,
1473343944.933,,5.000000e+001,1.291953e+001,9.809283e-004,0.000000e+000,5.938751e-003,0.000000e+000,3,9.815689e-001,1.825000e+000,,,,,,,,,,,,,,,,,,0,5.000000e+000,5.000000e-001,2,1,1.997604e-001,0,0,0,
1473343958.698,,5.000000e+001,1.264909e+001,9.821788e-004,0.000000e+000,5.922411e-003,0.000000e+000,3,9.815691e-001,1.825000e+000,,,,,,,,,,,,,,,,,,0,5.000000e+000,5.000000e-001,2,1,2.438507e-001,0,0,0,
1473343971.412,,5.000000e+001,1.238397e+001,9.833236e-004,0.000000e+000,5.878599e-003,0.000000e+000,3,9.815806e-001,1.825000e+000,,,,,,,,,,,,,,,,,,0,5.000000e+000,5.000000e-001,2,1,1.903801e-001,0,0,0,
1473343986.626,,5.000000e+001,1.209858e+001,9.846543e-004,0.000000e+000,5.888770e-003,0.000000e+000,3,9.815613e-001,1.825000e+000,,,,,,,,,,,,,,,,,,0,5.000000e+000,5.000000e-001,2,1,1.909199e-001,0,0,0,
1473344000.282,,5.000000e+001,1.181573e+001,9.857730e-004,0.000000e+000,5.913974e-003,0.000000e+000,3,9.815981e-001,1.825000e+000,,,,,,,,,,,,,,,,,,0,5.000000e+000,5.000000e-001,2,1,1.885500e-001,0,0,0,
1473344014.104,,5.000000e+001,1.153644e+001,9.869090e-004,0.000000e+000,5.867276e-003,0.000000e+000,3,9.814932e-001,1.825000e+000,,,,,,,,,,,,,,,,,,0,5.000000e+000,5.000000e-001,2,1,1.849403e-001,0,0,0,
1473344027.069,,5.000000e+001,1.125933e+001,9.879166e-004,0.000000e+000,5.893571e-003,0.000000e+000,3,9.815207e-001,1.825000e+000,,,,,,,,,,,,,,,,,,0,5.000000e+000,5.000000e-001,2,1,1.841402e-001,0,0,0,
1473344040.294,,5.000000e+001,1.103055e+001,9.889393e-004,0.000000e+000,5.866544e-003,0.000000e+000,3,9.815359e-001,1.825000e+000,,,,,,,,,,,,,,,,,,0,5.000000e+000,5.000000e-001,2,1,1.824303e-001,0,0,0,
1473344053.314,,5.000000e+001,1.080150e+001,9.898462e-004,0.000000e+000,5.898251e-003,0.000000e+000,3,9.815793e-001,1.825000e+000,,,,,,,,,,,,,,,,,,0,5.000000e+000,5.000000e-001,2,1,1.840801e-001,0,0,0,
1473344066.528,,5.000000e+001,1.055209e+001,9.907830e-004,0.000000e+000,5.870720e-003,0.000000e+000,3,9.815723e-001,1.825000e+000,,,,,,,,,,,,,,,,,,0,5.000000e+000,5.000000e-001,2,1,2.257395e-001,0,0,0,
1473344078.743,,5.000000e+001,1.030142e+001,9.915776e-004,0.000000e+000,5.884015e-003,0.000000e+000,3,9.816055e-001,1.825000e+000,,,,,,,,,,,,,,,,,,0,5.000000e+000,5.000000e-001,2,1,1.834698e-001,0,0,0,
1473344092.957,,5.000000e+001,1.002762e+001,9.925583e-004,0.000000e+000,5.826700e-003,0.000000e+000,3,9.816049e-001,1.825000e+000,,,,,,,,,,,,,,,,,,0,5.000000e+000,5.000000e-001,2,1,1.813240e-001,0,0,0,
1473344105.111,,5.000000e+001,9.825136e+000,9.932743e-004,0.000000e+000,5.839756e-003,0.000000e+000,3,9.816012e-001,1.825000e+000,,,,,,,,,,,,,,,,,,0,5.000000e+000,5.000000e-001,2,1,1.356058e-001,0,0,0,
1473344117.684,,5.000000e+001,9.581460e+000,9.940919e-004,0.000000e+000,5.859774e-003,0.000000e+000,3,9.815847e-001,1.825000e+000,,,,,,,,,,,,,,,,,,0,5.000000e+000,5.000000e-001,2,1,1.779289e-001,0,0,0,
1473344140.894,,5.000000e+001,9.146143e+000,9.954642e-004,0.000000e+000,5.800032e-003,0.000000e+000,3,9.815953e-001,1.825000e+000,,,,,,,,,,,,,,,,,,0,5.000000e+000,5.000000e-001,2,1,1.705437e-001,0,1,0,
1473344154.108,,5.000000e+001,8.913544e+000,9.960720e-004,0.000000e+000,5.799992e-003,0.000000e+000,3,9.815726e-001,1.825000e+000,,,,,,,,,,,,,,,,,,0,5.000000e+000,5.000000e-001,2,1,1.235809e-001,0,1,0,
1473344166.822,,5.000000e+001,8.733751e+000,9.967203e-004,0.000000e+000,5.764640e-003,0.000000e+000,3,9.815707e-001,1.825000e+000,,,,,,,,,,,,,,,,,,0,5.000000e+000,5.000000e-001,2,1,1.560354e-001,0,1,0,
1473344178.537,,5.000000e+001,8.545981e+000,9.972518e-004,0.000000e+000,5.790349e-003,0.000000e+000,3,9.816281e-001,1.825000e+000,,,,,,,,,,,,,,,,,,0,5.000000e+000,5.000000e-001,2,1,1.456356e-001,0,1,0,
1473344190.022,,5.000000e+001,8.384010e+000,9.976601e-004,0.000000e+000,5.759308e-003,0.000000e+000,3,9.816350e-001,1.825000e+000,,,,,,,,,,,,,,,,,,0,5.000000e+000,5.000000e-001,2,1,1.072502e-001,0,1,0,
1473344200.988,,5.000000e+001,8.248275e+000,9.981326e-004,0.000000e+000,5.726106e-003,0.000000e+000,3,9.815710e-001,1.825000e+000,,,,,,,,,,,,,,,,,,0,5.000000e+000,5.000000e-001,2,1,1.642208e-001,0,1,0,
1473344212.952,,5.000000e+001,8.103022e+000,9.985182e-004,0.000000e+000,5.759841e-003,0.000000e+000,3,9.816113e-001,1.825000e+000,,,,,,,,,,,,,,,,,,0,5.000000e+000,5.000000e-001,2,1,1.262856e-001,0,1,0,
1473344229.425,,5.000000e+001,7.888063e+000,9.989203e-004,0.000000e+000,5.799281e-003,0.000000e+000,3,9.816489e-001,1.825000e+000,,,,,,,,,,,,,,,,,,0,5.000000e+000,5.000000e-001,2,1,1.192217e-001,0,1,0,
1473344243.139,,5.000000e+001,7.756363e+000,9.993501e-004,0.000000e+000,5.749600e-003,0.000000e+000,3,9.816097e-001,1.825000e+000,,,,,,,,,,,,,,,,,,0,5.000000e+000,5.000000e-001,2,1,8.689785e-002,0,1,0,
1473344254.853,,5.000000e+001,7.608016e+000,9.996681e-004,0.000000e+000,5.779624e-003,0.000000e+000,3,9.816071e-001,1.825000e+000,,,,,,,,,,,,,,,,,,0,5.000000e+000,5.000000e-001,2,1,1.055861e-001,0,1,0,
1473344266.067,,5.000000e+001,7.506244e+000,9.998420e-004,0.000000e+000,5.776722e-003,0.000000e+000,3,9.816395e-001,1.825000e+000,,,,,,,,,,,,,,,,,,0,5.000000e+000,5.000000e-001,2,1,9.795904e-002,0,1,0,
1473344331.787,,5.000000e+001,6.922423e+000,1.001190e-003,0.000000e+000,5.815565e-003,0.000000e+000,3,9.815850e-001,1.825000e+000,,,,,,,,,,,,,,,,,,0,5.000000e+000,5.000000e-001,2,1,7.913399e-002,0,1,0,
1473344343.501,,5.000000e+001,6.832964e+000,1.001438e-003,0.000000e+000,5.810316e-003,0.000000e+000,3,9.816256e-001,1.825000e+000,,,,,,,,,,,,,,,,,,0,5.000000e+000,5.000000e-001,2,1,6.118011e-002,0,1,0,
1473344353.965,,5.000000e+001,6.751618e+000,1.001557e-003,0.000000e+000,5.727378e-003,0.000000e+000,3,9.815354e-001,1.825000e+000,,,,,,,,,,,,,,,,,,0,5.000000e+000,5.000000e-001,2,1,6.338978e-002,0,1,0,
1473344366.429,,5.000000e+001,6.660651e+000,1.013102e-003,0.000000e+000,-1.130606e-002,0.000000e+000,3,9.062085e-001,1.825000e+000,,,,,,,,,,,,,,,,,,0,5.000000e+000,5.000000e-001,2,1,7.541323e-002,0,1,0,
1473344422.398,,5.000000e+001,5.877337e+000,1.003347e-003,0.000000e+000,5.721678e-003,0.000000e+000,3,9.815046e-001,1.825000e+000,,,,,,,,,,,,,,,,,,0,5.000000e+000,5.000000e-001,2,1,1.319489e-001,0,0,0,
1473344434.151,,5.000000e+001,5.745503e+000,1.003544e-003,0.000000e+000,5.762722e-003,0.000000e+000,3,9.816135e-001,1.825000e+000,,,,,,,,,,,,,,,,,,0,5.000000e+000,5.000000e-001,2,1,1.317201e-001,0,0,0,
1473344445.865,,5.000000e+001,5.570114e+000,1.003793e-003,0.000000e+000,5.699399e-003,0.000000e+000,3,9.815937e-001,1.825000e+000,,,,,,,,,,,,,,,,,,0,5.000000e+000,5.000000e-001,2,1,9.799194e-002,0,0,0,
1473344458.262,,5.000000e+001,5.398297e+000,1.003970e-003,0.000000e+000,5.729367e-003,0.000000e+000,3,9.815823e-001,1.825000e+000,,,,,,,,,,,,,,,,,,0,5.000000e+000,5.000000e-001,2,1,1.239319e-001,0,0,0,
1473344563.119,,5.000000e+001,4.996159e+000,1.004569e-003,0.000000e+000,5.699339e-003,0.000000e+000,3,9.816371e-001,1.825000e+000,,,,,,,,,,,,,,,,,,0,5.000000e+000,5.000000e-001,2,1,9.259224e-003,0,0,0,
1473344575.083,,5.000000e+001,5.003574e+000,1.004593e-003,0.000000e+000,5.716229e-003,0.000000e+000,3,9.816778e-001,1.825000e+000,,,,,,,,,,,,,,,,,,0,5.000000e+000,5.000000e-001,2,1,5.572796e-003,0,0,0,
1473344587.298,,5.000000e+001,5.012449e+000,1.004588e-003,0.000000e+000,5.737649e-003,0.000000e+000,3,9.815773e-001,1.825000e+000,,,,,,,,,,,,,,,,,,0,5.000000e+000,5.000000e-001,2,1,5.971432e-003,0,0,0,
1473344598.512,,5.000000e+001,5.017242e+000,1.004588e-003,0.000000e+000,5.704464e-003,0.000000e+000,3,9.816266e-001,1.825000e+000,,,,,,,,,,,,,,,,,,0,5.000000e+000,5.000000e-001,2,1,3.614902e-003,0,0,0,