File: data/A344/A344_GdN_MH_040K_160905.rso.dat
[Header]
TITLE,MPMS RSO Measurement
BYAPP,MPMS Measurement,1.1,Summary
FILEOPENTIME, 1473135559.194000 9/6/2016, 4:19:19 PM

INFO, APPNAME, MPMS MultiVu Application, Revision 1.61,  Build 082

INFO, NAME, A344
INFO, WEIGHT, 10.500
INFO, AREA, 1.000
INFO, LENGTH, 1.000
INFO, SHAPE, 0
INFO, COMMENT, m = 0.0105g
INFO, SEQUENCE FILE: 7T_hysteresis_sweep_hi_res_zero_n4.seq


INFO, BACKGROUND DATA FILE:, None


STARTUPAXIS,X,4,LINEAR,AUTO,0.000000,0.000000
STARTUPAXIS,Y1,5,LINEAR,AUTO,0.000000,0.000000


STARTUPGROUP,Longitudinal
FIELDGROUP,Longitudinal,1,2,3,4,5,6,7,8,9,10,11,19,20,21,22,23,35
FIELDGROUP,Transverse,1,2,3,4,12,13,14,15,16,17,18,24,25,26,27,28,35

PLOT_APPEARANCE,ALL,HORZ_GRID_ON,VERT_GRID_ON,MARKERS_AND_LINES

[Data]
Time,Comment,Field (Oe),Temperature (K),Long Moment (emu),Long Scan Std Dev,Long Offset (cm),Long Offset Std Dev,Long Algorithm,Long Reg Fit,Long Reg Factor,Trans Moment (emu),Trans Scan Std Dev,Trans Offset (cm),Trans Offset Std Dev,Trans Algorithm,Trans Reg Fit,Trans Reg Factor,Long Moment [w/o ABS] (emu),Long Scan Std Dev [w/o ABS],Long Offset [w/o ABS] (cm),Long Offset Std Dev [w/o ABS],Long Reg Fit [w/o ABS],Trans Moment [w/o ABS] (emu),Trans Scan Std Dev [w/o ABS],Trans Offset [w/o ABS] (cm),Trans Offset Std Dev [w/o ABS],Trans Reg Fit [w/o ABS],RSO Position (deg),Amplitude (cm),Frequency,Cycles to Average,Scans per Measurement,Delta Temp (K),Error,EC Comp. Running,Using ABS,
1473135559.187,,7.000000e+004,4.000239e+001,1.071523e-003,0.000000e+000,9.328429e-003,0.000000e+000,3,9.464114e-001,1.825000e+000,,,,,,,,,,,,,,,,,,0,5.000000e+000,5.000000e-001,2,1,2.017975e-003,0,0,0,
1473135585.162,,7.000000e+004,4.000138e+001,1.071669e-003,0.000000e+000,9.254008e-003,0.000000e+000,3,9.463748e-001,1.825000e+000,,,,,,,,,,,,,,,,,,0,5.000000e+000,5.000000e-001,2,1,0.000000e+000,0,0,0,
1473135766.856,,6.000000e+004,3.999935e+001,1.068330e-003,0.000000e+000,7.758887e-003,0.000000e+000,3,9.459325e-001,1.825000e+000,,,,,,,,,,,,,,,,,,0,5.000000e+000,5.000000e-001,2,1,0.000000e+000,0,1,0,
1473135792.292,,6.000000e+004,4.000137e+001,1.067565e-003,0.000000e+000,7.996059e-003,0.000000e+000,3,9.465526e-001,1.825000e+000,,,,,,,,,,,,,,,,,,0,5.000000e+000,5.000000e-001,2,1,4.047394e-003,0,1,0,
1473135978.241,,5.000000e+004,4.000542e+001,1.061908e-003,0.000000e+000,7.122509e-003,0.000000e+000,3,9.465414e-001,1.825000e+000,,,,,,,,,,,,,,,,,,0,5.000000e+000,5.000000e-001,2,1,4.051208e-003,0,1,0,
1473136003.174,,5.000000e+004,4.000138e+001,1.061880e-003,0.000000e+000,7.223172e-003,0.000000e+000,3,9.461458e-001,1.825000e+000,,,,,,,,,,,,,,,,,,0,5.000000e+000,5.000000e-001,2,1,0.000000e+000,0,1,0,
1473136181.622,,4.000000e+004,4.000137e+001,1.056294e-003,0.000000e+000,6.545687e-003,0.000000e+000,3,9.460922e-001,1.825000e+000,,,,,,,,,,,,,,,,,,0,5.000000e+000,5.000000e-001,2,1,4.047394e-003,0,1,0,
1473136204.605,,4.000000e+004,3.999935e+001,1.053665e-003,0.000000e+000,6.823283e-003,0.000000e+000,3,9.478874e-001,1.825000e+000,,,,,,,,,,,,,,,,,,0,5.000000e+000,5.000000e-001,2,1,0.000000e+000,0,1,0,
1473136378.048,,3.000000e+004,4.000340e+001,1.043412e-003,0.000000e+000,3.690775e-003,0.000000e+000,3,9.460731e-001,1.825000e+000,,,,,,,,,,,,,,,,,,0,5.000000e+000,5.000000e-001,2,1,4.047394e-003,0,1,0,
1473136400.995,,3.000000e+004,3.999935e+001,1.041647e-003,0.000000e+000,3.943797e-003,0.000000e+000,3,9.457594e-001,1.825000e+000,,,,,,,,,,,,,,,,,,0,5.000000e+000,5.000000e-001,2,1,0.000000e+000,0,0,0,
1473136575.670,,2.000000e+004,3.999834e+001,1.024829e-003,0.000000e+000,4.327138e-003,0.000000e+000,3,9.466468e-001,1.825000e+000,,,,,,,,,,,,,,,,,,0,5.000000e+000,5.000000e-001,2,1,2.021790e-003,0,0,0,
1473136598.706,,2.000000e+004,3.999935e+001,1.024789e-003,0.000000e+000,4.403013e-003,0.000000e+000,3,9.468566e-001,1.825000e+000,,,,,,,,,,,,,,,,,,0,5.000000e+000,5.000000e-001,2,1,0.000000e+000,0,0,0,
1473136768.903,,1.000000e+004,4.000037e+001,9.984461e-004,0.000000e+000,4.053664e-003,0.000000e+000,3,9.463959e-001,1.825000e+000,,,,,,,,,,,,,,,,,,0,5.000000e+000,5.000000e-001,2,1,6.069183e-003,0,0,0,
1473136792.854,,1.000000e+004,3.999733e+001,9.994878e-004,0.000000e+000,4.087774e-003,0.000000e+000,3,9.461451e-001,1.825000e+000,,,,,,,,,,,,,,,,,,0,5.000000e+000,5.000000e-001,2,1,8.110046e-003,0,0,0,
1473136931.794,,9.000000e+003,3.999733e+001,9.935844e-004,0.000000e+000,3.987288e-003,0.000000e+000,3,9.460683e-001,1.825000e+000,,,,,,,,,,,,,,,,,,0,5.000000e+000,5.000000e-001,2,1,4.051208e-003,0,0,0,
1473136956.473,,9.000000e+003,3.999733e+001,9.934764e-004,0.000000e+000,3.725527e-003,0.000000e+000,3,9.462117e-001,1.825000e+000,,,,,,,,,,,,,,,,,,0,5.000000e+000,5.000000e-001,2,1,0.000000e+000,0,0,0,
1473137087.916,,7.000000e+003,3.999834e+001,9.846084e-004,0.000000e+000,3.694229e-003,0.000000e+000,3,9.460589e-001,1.825000e+000,,,,,,,,,,,,,,,,,,0,5.000000e+000,5.000000e-001,2,1,2.021790e-003,0,0,0,
1473137115.845,,7.000000e+003,3.999733e+001,9.844408e-004,0.000000e+000,3.687717e-003,0.000000e+000,3,9.462973e-001,1.825000e+000,,,,,,,,,,,,,,,,,,0,5.000000e+000,5.000000e-001,2,1,4.051208e-003,0,0,0,
1473137251.284,,5.000000e+003,3.999834e+001,9.722522e-004,0.000000e+000,3.959418e-003,0.000000e+000,3,9.459153e-001,1.825000e+000,,,,,,,,,,,,,,,,,,0,5.000000e+000,5.000000e-001,2,1,2.021790e-003,0,1,0,
1473137279.213,,5.000000e+003,4.000037e+001,9.726544e-004,0.000000e+000,3.922839e-003,0.000000e+000,3,9.461858e-001,1.825000e+000,,,,,,,,,,,,,,,,,,0,5.000000e+000,5.000000e-001,2,1,2.029419e-003,0,1,0,
1473137413.435,,3.000000e+003,4.000239e+001,9.562651e-004,0.000000e+000,4.310365e-003,0.000000e+000,3,9.467577e-001,1.825000e+000,,,,,,,,,,,,,,,,,,0,5.000000e+000,5.000000e-001,2,1,2.017975e-003,0,1,0,
1473137439.950,,3.000000e+003,4.000138e+001,9.561760e-004,0.000000e+000,4.252541e-003,0.000000e+000,3,9.476084e-001,1.825000e+000,,,,,,,,,,,,,,,,,,0,5.000000e+000,5.000000e-001,2,1,0.000000e+000,0,1,0,
1473137575.922,,1.000000e+003,4.000138e+001,9.206429e-004,0.000000e+000,5.944003e-003,0.000000e+000,3,9.563234e-001,1.825000e+000,,,,,,,,,,,,,,,,,,0,5.000000e+000,5.000000e-001,2,1,8.098602e-003,0,1,0,
1473137600.657,,1.000000e+003,4.000441e+001,9.215644e-004,0.000000e+000,6.269720e-003,0.000000e+000,3,9.559450e-001,1.825000e+000,,,,,,,,,,,,,,,,,,0,5.000000e+000,5.000000e-001,2,1,2.029419e-003,0,1,0,
1473137741.614,,7.000000e+002,4.000138e+001,9.096941e-004,0.000000e+000,6.338839e-003,0.000000e+000,3,9.595146e-001,1.825000e+000,,,,,,,,,,,,,,,,,,0,5.000000e+000,5.000000e-001,2,1,8.098602e-003,0,1,0,
1473137765.793,,7.000000e+002,4.000037e+001,9.086957e-004,0.000000e+000,6.188327e-003,0.000000e+000,3,9.604698e-001,1.825000e+000,,,,,,,,,,,,,,,,,,0,5.000000e+000,5.000000e-001,2,1,2.029419e-003,0,1,0,
1473137897.232,,6.000000e+002,4.000239e+001,9.036829e-004,0.000000e+000,6.633868e-003,0.000000e+000,3,9.627668e-001,1.825000e+000,,,,,,,,,,,,,,,,,,0,5.000000e+000,5.000000e-001,2,1,2.017975e-003,0,1,0,
1473137922.660,,6.000000e+002,3.999834e+001,9.037436e-004,0.000000e+000,6.523249e-003,0.000000e+000,3,9.622455e-001,1.825000e+000,,,,,,,,,,,,,,,,,,0,5.000000e+000,5.000000e-001,2,1,2.021790e-003,0,0,0,
1473138055.104,,5.000000e+002,3.999935e+001,8.941964e-004,0.000000e+000,6.734912e-003,0.000000e+000,3,9.658107e-001,1.825000e+000,,,,,,,,,,,,,,,,,,0,5.000000e+000,5.000000e-001,2,1,0.000000e+000,0,0,0,
1473138081.782,,5.000000e+002,3.999935e+001,8.956672e-004,0.000000e+000,7.043762e-003,0.000000e+000,3,9.646006e-001,1.825000e+000,,,,,,,,,,,,,,,,,,0,5.000000e+000,5.000000e-001,2,1,0.000000e+000,0,0,0,
1473138213.221,,4.000000e+002,3.999733e+001,8.873197e-004,0.000000e+000,8.028499e-003,0.000000e+000,3,9.661124e-001,1.825000e+000,,,,,,,,,,,,,,,,,,0,5.000000e+000,5.000000e-001,2,1,4.051208e-003,0,0,0,
1473138238.900,,4.000000e+002,4.000340e+001,8.847148e-004,0.000000e+000,7.684649e-003,0.000000e+000,3,9.672160e-001,1.825000e+000,,,,,,,,,,,,,,,,,,0,5.000000e+000,5.000000e-001,2,1,4.047394e-003,0,0,0,
1473138366.593,,3.000000e+002,4.000037e+001,8.701710e-004,0.000000e+000,7.080390e-003,0.000000e+000,3,9.721660e-001,1.825000e+000,,,,,,,,,,,,,,,,,,0,5.000000e+000,5.000000e-001,2,1,6.069183e-003,0,0,0,
1473138391.547,,3.000000e+002,3.999935e+001,8.691947e-004,0.000000e+000,7.933943e-003,0.000000e+000,3,9.709707e-001,1.825000e+000,,,,,,,,,,,,,,,,,,0,5.000000e+000,5.000000e-001,2,1,0.000000e+000,0,0,0,
1473138522.236,,2.000000e+002,3.999632e+001,8.441721e-004,0.000000e+000,8.089181e-003,0.000000e+000,3,9.741387e-001,1.825000e+000,,,,,,,,,,,,,,,,,,0,5.000000e+000,5.000000e-001,2,1,2.029419e-003,0,0,0,
1473138546.665,,2.000000e+002,3.999936e+001,8.447231e-004,0.000000e+000,8.359350e-003,0.000000e+000,3,9.741499e-001,1.825000e+000,,,,,,,,,,,,,,,,,,0,5.000000e+000,5.000000e-001,2,1,4.051208e-003,0,0,0,
1473138666.291,,1.800000e+002,3.999936e+001,8.369408e-004,0.000000e+000,8.545283e-003,0.000000e+000,3,9.752248e-001,1.825000e+000,,,,,,,,,,,,,,,,,,0,5.000000e+000,5.000000e-001,2,1,4.051208e-003,0,0,0,
1473138693.577,,1.800000e+002,4.000239e+001,8.377768e-004,0.000000e+000,8.451766e-003,0.000000e+000,3,9.753590e-001,1.825000e+000,,,,,,,,,,,,,,,,,,0,5.000000e+000,5.000000e-001,2,1,6.076813e-003,0,0,0,
1473138816.570,,1.600000e+002,3.999834e+001,8.293650e-004,0.000000e+000,9.226484e-003,0.000000e+000,3,9.749410e-001,1.825000e+000,,,,,,,,,,,,,,,,,,0,5.000000e+000,5.000000e-001,2,1,2.021790e-003,0,1,0,
1473138841.997,,1.600000e+002,4.000138e+001,8.297741e-004,0.000000e+000,8.576103e-003,0.000000e+000,3,9.763852e-001,1.825000e+000,,,,,,,,,,,,,,,,,,0,5.000000e+000,5.000000e-001,2,1,0.000000e+000,0,1,0,
1473138962.657,,1.400000e+002,3.999936e+001,8.205850e-004,0.000000e+000,8.823724e-003,0.000000e+000,3,9.762616e-001,1.825000e+000,,,,,,,,,,,,,,,,,,0,5.000000e+000,5.000000e-001,2,1,4.051208e-003,0,1,0,
1473138988.209,,1.400000e+002,4.000037e+001,8.201028e-004,0.000000e+000,8.540696e-003,0.000000e+000,3,9.771021e-001,1.825000e+000,,,,,,,,,,,,,,,,,,0,5.000000e+000,5.000000e-001,2,1,2.029419e-003,0,1,0,
1473139111.709,,1.200000e+002,4.000340e+001,8.098698e-004,0.000000e+000,9.368475e-003,0.000000e+000,3,9.773229e-001,1.825000e+000,,,,,,,,,,,,,,,,,,0,5.000000e+000,5.000000e-001,2,1,4.047394e-003,0,1,0,
1473139136.388,,1.200000e+002,4.000037e+001,8.094255e-004,0.000000e+000,9.090691e-003,0.000000e+000,3,9.775113e-001,1.825000e+000,,,,,,,,,,,,,,,,,,0,5.000000e+000,5.000000e-001,2,1,6.069183e-003,0,1,0,
1473139262.880,,1.000000e+002,3.999530e+001,7.968693e-004,0.000000e+000,9.144004e-003,0.000000e+000,3,9.789514e-001,1.825000e+000,,,,,,,,,,,,,,,,,,0,5.000000e+000,5.000000e-001,2,1,8.102417e-003,0,1,0,
1473139285.243,,1.000000e+002,3.999834e+001,7.965923e-004,0.000000e+000,8.849724e-003,0.000000e+000,3,9.790714e-001,1.825000e+000,,,,,,,,,,,,,,,,,,0,5.000000e+000,5.000000e-001,2,1,2.021790e-003,0,1,0,
1473139407.114,,8.000000e+001,3.999935e+001,7.816905e-004,0.000000e+000,9.539559e-003,0.000000e+000,3,9.793025e-001,1.825000e+000,,,,,,,,,,,,,,,,,,0,5.000000e+000,5.000000e-001,2,1,0.000000e+000,0,1,0,
1473139433.042,,8.000000e+001,4.000037e+001,7.815537e-004,0.000000e+000,9.009110e-003,0.000000e+000,3,9.799321e-001,1.825000e+000,,,,,,,,,,,,,,,,,,0,5.000000e+000,5.000000e-001,2,1,2.029419e-003,0,1,0,
1473139553.734,,6.000000e+001,3.999530e+001,7.628878e-004,0.000000e+000,9.044540e-003,0.000000e+000,3,9.799463e-001,1.825000e+000,,,,,,,,,,,,,,,,,,0,5.000000e+000,5.000000e-001,2,1,4.058838e-003,0,0,0,
1473139577.677,,6.000000e+001,3.999733e+001,7.635447e-004,0.000000e+000,8.820309e-003,0.000000e+000,3,9.811180e-001,1.825000e+000,,,,,,,,,,,,,,,,,,0,5.000000e+000,5.000000e-001,2,1,4.051208e-003,0,0,0,
1473139700.173,,4.000000e+001,3.999631e+001,7.397000e-004,0.000000e+000,9.423099e-003,0.000000e+000,3,9.793414e-001,1.825000e+000,,,,,,,,,,,,,,,,,,0,5.000000e+000,5.000000e-001,2,1,6.080627e-003,0,0,0,
1473139736.566,,4.000000e+001,4.000037e+001,7.399525e-004,0.000000e+000,9.524454e-003,0.000000e+000,3,9.813485e-001,1.825000e+000,,,,,,,,,,,,,,,,,,0,5.000000e+000,5.000000e-001,2,1,2.029419e-003,0,0,0,
1473139852.257,,2.000000e+001,3.999834e+001,7.089442e-004,0.000000e+000,9.616656e-003,0.000000e+000,3,9.831542e-001,1.825000e+000,,,,,,,,,,,,,,,,,,0,5.000000e+000,5.000000e-001,2,1,6.080627e-003,0,0,0,
1473139878.186,,2.000000e+001,3.999834e+001,7.091420e-004,0.000000e+000,9.244500e-003,0.000000e+000,3,9.828685e-001,1.825000e+000,,,,,,,,,,,,,,,,,,0,5.000000e+000,5.000000e-001,2,1,6.080627e-003,0,0,0,
1473139991.622,,0.000000e+000,4.000037e+001,6.663217e-004,0.000000e+000,9.212740e-003,0.000000e+000,3,9.838310e-001,1.825000e+000,,,,,,,,,,,,,,,,,,0,5.000000e+000,5.000000e-001,2,1,2.029419e-003,0,0,0,
1473140016.026,,0.000000e+000,3.999733e+001,6.653967e-004,0.000000e+000,9.762831e-003,0.000000e+000,3,9.833767e-001,1.825000e+000,,,,,,,,,,,,,,,,,,0,5.000000e+000,5.000000e-001,2,1,0.000000e+000,0,0,0,
1473140144.329,,-2.000000e+001,3.999328e+001,5.807977e-004,0.000000e+000,1.008489e-002,0.000000e+000,3,9.842135e-001,1.825000e+000,,,,,,,,,,,,,,,,,,0,5.000000e+000,5.000000e-001,2,1,1.214981e-002,0,0,0,
1473140168.226,,-2.000000e+001,3.999834e+001,5.793804e-004,0.000000e+000,9.274700e-003,0.000000e+000,3,9.846674e-001,1.825000e+000,,,,,,,,,,,,,,,,,,0,5.000000e+000,5.000000e-001,2,1,2.021790e-003,0,0,0,
1473140321.213,,-4.000000e+001,3.999834e+001,-5.054919e-005,0.000000e+000,-5.844152e-003,0.000000e+000,3,9.359616e-001,1.825000e+000,,,,,,,,,,,,,,,,,,0,5.000000e+000,5.000000e-001,2,1,2.021790e-003,0,1,0,
1473140346.878,,-4.000000e+001,4.000037e+001,-7.236245e-005,0.000000e+000,-5.610359e-003,0.000000e+000,3,9.539700e-001,1.825000e+000,,,,,,,,,,,,,,,,,,0,5.000000e+000,5.000000e-001,2,1,2.029419e-003,0,1,0,
1473140485.402,,-6.000000e+001,3.999834e+001,-6.237924e-004,0.000000e+000,8.438532e-003,0.000000e+000,3,9.805586e-001,1.825000e+000,,,,,,,,,,,,,,,,,,0,5.000000e+000,5.000000e-001,2,1,2.021790e-003,0,1,0,
1473140508.829,,-6.000000e+001,4.000037e+001,-6.263737e-004,0.000000e+000,9.020118e-003,0.000000e+000,3,9.799536e-001,1.825000e+000,,,,,,,,,,,,,,,,,,0,5.000000e+000,5.000000e-001,2,1,2.029419e-003,0,1,0,
1473140630.826,,-8.000000e+001,4.000442e+001,-7.052397e-004,0.000000e+000,9.298650e-003,0.000000e+000,3,9.790150e-001,1.825000e+000,,,,,,,,,,,,,,,,,,0,5.000000e+000,5.000000e-001,2,1,6.069183e-003,0,1,0,
1473140655.793,,-8.000000e+001,3.999935e+001,-7.080675e-004,0.000000e+000,8.945665e-003,0.000000e+000,3,9.795406e-001,1.825000e+000,,,,,,,,,,,,,,,,,,0,5.000000e+000,5.000000e-001,2,1,8.098602e-003,0,1,0,
1473140777.522,,-1.000000e+002,4.000138e+001,-7.505740e-004,0.000000e+000,9.088223e-003,0.000000e+000,3,9.786384e-001,1.825000e+000,,,,,,,,,,,,,,,,,,0,5.000000e+000,5.000000e-001,2,1,0.000000e+000,0,1,0,
1473140803.974,,-1.000000e+002,4.000239e+001,-7.513938e-004,0.000000e+000,8.967786e-003,0.000000e+000,3,9.786031e-001,1.825000e+000,,,,,,,,,,,,,,,,,,0,5.000000e+000,5.000000e-001,2,1,2.017975e-003,0,1,0,
1473140926.391,,-1.200000e+002,3.999935e+001,-7.786193e-004,0.000000e+000,8.509250e-003,0.000000e+000,3,9.785493e-001,1.825000e+000,,,,,,,,,,,,,,,,,,0,5.000000e+000,5.000000e-001,2,1,0.000000e+000,0,1,0,
1473140964.530,,-1.200000e+002,3.999834e+001,-7.787607e-004,0.000000e+000,8.856778e-003,0.000000e+000,3,9.778547e-001,1.825000e+000,,,,,,,,,,,,,,,,,,0,5.000000e+000,5.000000e-001,2,1,2.021790e-003,0,1,0,
1473141085.285,,-1.400000e+002,3.999834e+001,-7.992507e-004,0.000000e+000,8.306681e-003,0.000000e+000,3,9.777718e-001,1.825000e+000,,,,,,,,,,,,,,,,,,0,5.000000e+000,5.000000e-001,2,1,2.021790e-003,0,0,0,
1473141110.711,,-1.400000e+002,3.999936e+001,-7.995212e-004,0.000000e+000,8.014826e-003,0.000000e+000,3,9.773495e-001,1.825000e+000,,,,,,,,,,,,,,,,,,0,5.000000e+000,5.000000e-001,2,1,4.051208e-003,0,0,0,
1473141232.637,,-1.600000e+002,3.999733e+001,-8.138124e-004,0.000000e+000,8.478049e-003,0.000000e+000,3,9.768548e-001,1.825000e+000,,,,,,,,,,,,,,,,,,0,5.000000e+000,5.000000e-001,2,1,8.110046e-003,0,0,0,
1473141258.063,,-1.600000e+002,4.000037e+001,-8.137673e-004,0.000000e+000,8.941815e-003,0.000000e+000,3,9.758535e-001,1.825000e+000,,,,,,,,,,,,,,,,,,0,5.000000e+000,5.000000e-001,2,1,2.029419e-003,0,0,0,
1473141384.433,,-1.800000e+002,3.999935e+001,-8.262266e-004,0.000000e+000,8.353095e-003,0.000000e+000,3,9.752484e-001,1.825000e+000,,,,,,,,,,,,,,,,,,0,5.000000e+000,5.000000e-001,2,1,8.098602e-003,0,0,0,
1473141408.717,,-1.800000e+002,3.999935e+001,-8.263683e-004,0.000000e+000,9.052043e-003,0.000000e+000,3,9.751607e-001,1.825000e+000,,,,,,,,,,,,,,,,,,0,5.000000e+000,5.000000e-001,2,1,0.000000e+000,0,0,0,
1473141530.897,,-2.000000e+002,4.000037e+001,-8.363950e-004,0.000000e+000,8.323417e-003,0.000000e+000,3,9.745126e-001,1.825000e+000,,,,,,,,,,,,,,,,,,0,5.000000e+000,5.000000e-001,2,1,2.029419e-003,0,0,0,
1473141556.259,,-2.000000e+002,3.999834e+001,-8.356028e-004,0.000000e+000,8.692336e-003,0.000000e+000,3,9.745017e-001,1.825000e+000,,,,,,,,,,,,,,,,,,0,5.000000e+000,5.000000e-001,2,1,2.021790e-003,0,0,0,
1473141688.582,,-3.000000e+002,4.000340e+001,-8.663412e-004,0.000000e+000,8.192872e-003,0.000000e+000,3,9.712226e-001,1.825000e+000,,,,,,,,,,,,,,,,,,0,5.000000e+000,5.000000e-001,2,1,8.098602e-003,0,0,0,
1473141713.283,,-3.000000e+002,3.999935e+001,-8.669288e-004,0.000000e+000,8.384136e-003,0.000000e+000,3,9.709315e-001,1.825000e+000,,,,,,,,,,,,,,,,,,0,5.000000e+000,5.000000e-001,2,1,0.000000e+000,0,0,0,
1473141849.913,,-4.000000e+002,3.999935e+001,-8.838387e-004,0.000000e+000,7.749410e-003,0.000000e+000,3,9.680657e-001,1.825000e+000,,,,,,,,,,,,,,,,,,0,5.000000e+000,5.000000e-001,2,1,0.000000e+000,0,1,0,
1473141875.954,,-4.000000e+002,4.000037e+001,-8.838624e-004,0.000000e+000,8.113628e-003,0.000000e+000,3,9.674964e-001,1.825000e+000,,,,,,,,,,,,,,,,,,0,5.000000e+000,5.000000e-001,2,1,2.029419e-003,0,1,0,
1473142003.404,,-5.000000e+002,4.000037e+001,-8.952585e-004,0.000000e+000,7.865226e-003,0.000000e+000,3,9.651040e-001,1.825000e+000,,,,,,,,,,,,,,,,,,0,5.000000e+000,5.000000e-001,2,1,2.029419e-003,0,1,0,
1473142027.856,,-5.000000e+002,4.000037e+001,-8.951075e-004,0.000000e+000,7.410803e-003,0.000000e+000,3,9.654155e-001,1.825000e+000,,,,,,,,,,,,,,,,,,0,5.000000e+000,5.000000e-001,2,1,2.029419e-003,0,1,0,
1473142161.309,,-6.000000e+002,4.000239e+001,-9.036963e-004,0.000000e+000,7.329084e-003,0.000000e+000,3,9.622304e-001,1.825000e+000,,,,,,,,,,,,,,,,,,0,5.000000e+000,5.000000e-001,2,1,6.076813e-003,0,1,0,
1473142185.530,,-6.000000e+002,4.000239e+001,-9.029322e-004,0.000000e+000,7.355190e-003,0.000000e+000,3,9.623182e-001,1.825000e+000,,,,,,,,,,,,,,,,,,0,5.000000e+000,5.000000e-001,2,1,2.017975e-003,0,1,0,
1473142308.468,,-7.000000e+002,4.000340e+001,-9.090500e-004,0.000000e+000,6.984800e-003,0.000000e+000,3,9.605055e-001,1.825000e+000,,,,,,,,,,,,,,,,,,0,5.000000e+000,5.000000e-001,2,1,0.000000e+000,0,1,0,
1473142332.146,,-7.000000e+002,4.000137e+001,-9.092184e-004,0.000000e+000,7.088053e-003,0.000000e+000,3,9.600909e-001,1.825000e+000,,,,,,,,,,,,,,,,,,0,5.000000e+000,5.000000e-001,2,1,4.047394e-003,0,1,0,
1473142458.818,,-1.000000e+003,4.000239e+001,-9.215875e-004,0.000000e+000,6.507144e-003,0.000000e+000,3,9.561219e-001,1.825000e+000,,,,,,,,,,,,,,,,,,0,5.000000e+000,5.000000e-001,2,1,2.017975e-003,0,1,0,
1473142484.859,,-1.000000e+003,4.000239e+001,-9.214252e-004,0.000000e+000,6.466992e-003,0.000000e+000,3,9.562483e-001,1.825000e+000,,,,,,,,,,,,,,,,,,0,5.000000e+000,5.000000e-001,2,1,2.017975e-003,0,1,0,
1473142614.105,,-3.000000e+003,4.000037e+001,-9.561446e-004,0.000000e+000,5.302437e-003,0.000000e+000,3,9.457651e-001,1.825000e+000,,,,,,,,,,,,,,,,,,0,5.000000e+000,5.000000e-001,2,1,2.029419e-003,0,0,0,
1473142640.536,,-3.000000e+003,4.000037e+001,-9.558625e-004,0.000000e+000,6.052356e-003,0.000000e+000,3,9.479702e-001,1.825000e+000,,,,,,,,,,,,,,,,,,0,5.000000e+000,5.000000e-001,2,1,2.029419e-003,0,0,0,
1473142777.839,,-5.000000e+003,4.000340e+001,-9.726392e-004,0.000000e+000,4.514650e-003,0.000000e+000,3,9.464068e-001,1.825000e+000,,,,,,,,,,,,,,,,,,0,5.000000e+000,5.000000e-001,2,1,8.098602e-003,0,0,0,
1473142803.518,,-5.000000e+003,4.000239e+001,-9.770544e-004,0.000000e+000,5.567956e-003,0.000000e+000,3,9.439299e-001,1.825000e+000,,,,,,,,,,,,,,,,,,0,5.000000e+000,5.000000e-001,2,1,2.017975e-003,0,0,0,
1473142933.248,,-7.000000e+003,3.999834e+001,-9.846787e-004,0.000000e+000,4.703802e-003,0.000000e+000,3,9.459984e-001,1.825000e+000,,,,,,,,,,,,,,,,,,0,5.000000e+000,5.000000e-001,2,1,2.021790e-003,0,0,0,
1473142961.427,,-7.000000e+003,4.000037e+001,-9.843881e-004,0.000000e+000,4.539827e-003,0.000000e+000,3,9.460174e-001,1.825000e+000,,,,,,,,,,,,,,,,,,0,5.000000e+000,5.000000e-001,2,1,2.029419e-003,0,0,0,
1473143097.871,,-9.000000e+003,3.999834e+001,-9.934871e-004,0.000000e+000,4.764067e-003,0.000000e+000,3,9.460770e-001,1.825000e+000,,,,,,,,,,,,,,,,,,0,5.000000e+000,5.000000e-001,2,1,2.021790e-003,0,0,0,
1473143126.341,,-9.000000e+003,3.999834e+001,-9.934283e-004,0.000000e+000,4.663388e-003,0.000000e+000,3,9.460555e-001,1.825000e+000,,,,,,,,,,,,,,,,,,0,5.000000e+000,5.000000e-001,2,1,2.021790e-003,0,0,0,
1473143260.780,,-1.000000e+004,3.999936e+001,-9.975440e-004,0.000000e+000,4.802962e-003,0.000000e+000,3,9.461526e-001,1.825000e+000,,,,,,,,,,,,,,,,,,0,5.000000e+000,5.000000e-001,2,1,4.051208e-003,0,0,0,
1473143289.459,,-1.000000e+004,4.000037e+001,-9.973078e-004,0.000000e+000,4.728952e-003,0.000000e+000,3,9.461405e-001,1.825000e+000,,,,,,,,,,,,,,,,,,0,5.000000e+000,5.000000e-001,2,1,2.029419e-003,0,1,0,
1473143461.406,,-2.000000e+004,4.000037e+001,-1.024959e-003,0.000000e+000,5.436907e-003,0.000000e+000,3,9.464871e-001,1.825000e+000,,,,,,,,,,,,,,,,,,0,5.000000e+000,5.000000e-001,2,1,2.029419e-003,0,1,0,
1473143487.585,,-2.000000e+004,4.000340e+001,-1.024687e-003,0.000000e+000,5.369047e-003,0.000000e+000,3,9.465252e-001,1.825000e+000,,,,,,,,,,,,,,,,,,0,5.000000e+000,5.000000e-001,2,1,0.000000e+000,0,1,0,
1473143662.076,,-3.000000e+004,4.000137e+001,-1.042724e-003,0.000000e+000,6.202618e-003,0.000000e+000,3,9.468140e-001,1.825000e+000,,,,,,,,,,,,,,,,,,0,5.000000e+000,5.000000e-001,2,1,4.047394e-003,0,1,0,
1473143685.759,,-3.000000e+004,4.000543e+001,-1.044533e-003,0.000000e+000,6.110766e-003,0.000000e+000,3,9.460678e-001,1.825000e+000,,,,,,,,,,,,,,,,,,0,5.000000e+000,5.000000e-001,2,1,8.098602e-003,0,1,0,
1473143860.952,,-4.000000e+004,3.999834e+001,-1.050661e-003,0.000000e+000,6.359535e-003,0.000000e+000,3,9.465892e-001,1.825000e+000,,,,,,,,,,,,,,,,,,0,5.000000e+000,5.000000e-001,2,1,6.080627e-003,0,1,0,
1473143885.182,,-4.000000e+004,4.000037e+001,-1.056560e-003,0.000000e+000,6.596608e-003,0.000000e+000,3,9.463079e-001,1.825000e+000,,,,,,,,,,,,,,,,,,0,5.000000e+000,5.000000e-001,2,1,2.029419e-003,0,1,0,
1473144065.667,,-5.000000e+004,3.999834e+001,-1.063062e-003,0.000000e+000,8.686633e-003,0.000000e+000,3,9.455462e-001,1.825000e+000,,,,,,,,,,,,,,,,,,0,5.000000e+000,5.000000e-001,2,1,2.021790e-003,0,0,0,
1473144091.618,,-5.000000e+004,3.999935e+001,-1.061539e-003,0.000000e+000,7.272544e-003,0.000000e+000,3,9.460510e-001,1.825000e+000,,,,,,,,,,,,,,,,,,0,5.000000e+000,5.000000e-001,2,1,0.000000e+000,0,0,0,
1473144267.575,,-6.000000e+004,3.999936e+001,-1.068485e-003,0.000000e+000,7.211015e-003,0.000000e+000,3,9.456613e-001,1.825000e+000,,,,,,,,,,,,,,,,,,0,5.000000e+000,5.000000e-001,2,1,4.051208e-003,0,0,0,
1473144292.816,,-6.000000e+004,3.999935e+001,-1.069422e-003,0.000000e+000,7.591140e-003,0.000000e+000,3,9.459079e-001,1.825000e+000,,,,,,,,,,,,,,,,,,0,5.000000e+000,5.000000e-001,2,1,0.000000e+000,0,0,0,
1473144470.510,,-7.000000e+004,3.999530e+001,-1.072933e-003,0.000000e+000,7.699037e-003,0.000000e+000,3,9.452173e-001,1.825000e+000,,,,,,,,,,,,,,,,,,0,5.000000e+000,5.000000e-001,2,1,1.216125e-002,0,0,0,
1473144496.230,,-7.000000e+004,3.999733e+001,-1.072646e-003,0.000000e+000,7.596629e-003,0.000000e+000,3,9.452871e-001,1.825000e+000,,,,,,,,,,,,,,,,,,0,5.000000e+000,5.000000e-001,2,1,4.051208e-003,0,0,0,
1473144685.870,,-6.000000e+004,3.999834e+001,-1.068469e-003,0.000000e+000,6.540127e-003,0.000000e+000,3,9.460071e-001,1.825000e+000,,,,,,,,,,,,,,,,,,0,5.000000e+000,5.000000e-001,2,1,2.021790e-003,0,0,0,
1473144712.934,,-6.000000e+004,3.999834e+001,-1.068374e-003,0.000000e+000,6.535439e-003,0.000000e+000,3,9.457980e-001,1.825000e+000,,,,,,,,,,,,,,,,,,0,5.000000e+000,5.000000e-001,2,1,2.021790e-003,0,0,0,
1473144886.976,,-5.000000e+004,4.000543e+001,-1.062727e-003,0.000000e+000,6.080811e-003,0.000000e+000,3,9.462904e-001,1.825000e+000,,,,,,,,,,,,,,,,,,0,5.000000e+000,5.000000e-001,2,1,1.620865e-002,0,1,0,
1473144911.654,,-5.000000e+004,4.000239e+001,-1.062333e-003,0.000000e+000,6.223012e-003,0.000000e+000,3,9.458974e-001,1.825000e+000,,,,,,,,,,,,,,,,,,0,5.000000e+000,5.000000e-001,2,1,6.076813e-003,0,1,0,
1473145089.848,,-4.000000e+004,4.000543e+001,-1.054579e-003,0.000000e+000,5.230891e-003,0.000000e+000,3,9.444539e-001,1.825000e+000,,,,,,,,,,,,,,,,,,0,5.000000e+000,5.000000e-001,2,1,8.098602e-003,0,1,0,
1473145113.777,,-4.000000e+004,4.000138e+001,-1.053165e-003,0.000000e+000,6.336318e-003,0.000000e+000,3,9.463863e-001,1.825000e+000,,,,,,,,,,,,,,,,,,0,5.000000e+000,5.000000e-001,2,1,0.000000e+000,0,1,0,
1473145290.285,,-3.000000e+004,4.000037e+001,-1.041574e-003,0.000000e+000,5.070616e-003,0.000000e+000,3,9.454864e-001,1.825000e+000,,,,,,,,,,,,,,,,,,0,5.000000e+000,5.000000e-001,2,1,2.029419e-003,0,1,0,
1473145315.568,,-3.000000e+004,4.000138e+001,-1.043739e-003,0.000000e+000,3.155807e-003,0.000000e+000,3,9.471695e-001,1.825000e+000,,,,,,,,,,,,,,,,,,0,5.000000e+000,5.000000e-001,2,1,0.000000e+000,0,1,0,
1473145489.047,,-2.000000e+004,3.999733e+001,-1.024869e-003,0.000000e+000,4.226850e-003,0.000000e+000,3,9.454532e-001,1.825000e+000,,,,,,,,,,,,,,,,,,0,5.000000e+000,5.000000e-001,2,1,0.000000e+000,0,0,0,
1473145512.725,,-2.000000e+004,3.999936e+001,-1.025871e-003,0.000000e+000,5.130176e-003,0.000000e+000,3,9.457273e-001,1.825000e+000,,,,,,,,,,,,,,,,,,0,5.000000e+000,5.000000e-001,2,1,4.051208e-003,0,0,0,
1473145683.418,,-1.000000e+004,4.000137e+001,-9.974340e-004,0.000000e+000,3.799689e-003,0.000000e+000,3,9.461846e-001,1.825000e+000,,,,,,,,,,,,,,,,,,0,5.000000e+000,5.000000e-001,2,1,4.047394e-003,0,0,0,
1473145709.584,,-1.000000e+004,4.000137e+001,-9.972225e-004,0.000000e+000,3.973405e-003,0.000000e+000,3,9.461886e-001,1.825000e+000,,,,,,,,,,,,,,,,,,0,5.000000e+000,5.000000e-001,2,1,4.047394e-003,0,0,0,
1473145838.938,,-9.000000e+003,4.000037e+001,-9.935355e-004,0.000000e+000,3.692190e-003,0.000000e+000,3,9.460527e-001,1.825000e+000,,,,,,,,,,,,,,,,,,0,5.000000e+000,5.000000e-001,2,1,2.029419e-003,0,0,0,
1473145864.376,,-9.000000e+003,4.000340e+001,-9.933012e-004,0.000000e+000,3.921755e-003,0.000000e+000,3,9.460221e-001,1.825000e+000,,,,,,,,,,,,,,,,,,0,5.000000e+000,5.000000e-001,2,1,8.098602e-003,0,0,0,
1473145999.065,,-7.000000e+003,4.000037e+001,-9.842794e-004,0.000000e+000,3.964260e-003,0.000000e+000,3,9.459645e-001,1.825000e+000,,,,,,,,,,,,,,,,,,0,5.000000e+000,5.000000e-001,2,1,1.012802e-002,0,0,0,
1473146024.760,,-7.000000e+003,3.999834e+001,-9.842325e-004,0.000000e+000,3.820513e-003,0.000000e+000,3,9.461257e-001,1.825000e+000,,,,,,,,,,,,,,,,,,0,5.000000e+000,5.000000e-001,2,1,2.021790e-003,0,0,0,
1473146157.717,,-5.000000e+003,3.999733e+001,-9.728203e-004,0.000000e+000,3.820983e-003,0.000000e+000,3,9.461458e-001,1.825000e+000,,,,,,,,,,,,,,,,,,0,5.000000e+000,5.000000e-001,2,1,4.051208e-003,0,0,0,
1473146184.084,,-5.000000e+003,3.999935e+001,-9.726509e-004,0.000000e+000,4.119727e-003,0.000000e+000,3,9.459186e-001,1.825000e+000,,,,,,,,,,,,,,,,,,0,5.000000e+000,5.000000e-001,2,1,0.000000e+000,0,0,0,
1473146320.631,,-3.000000e+003,4.000037e+001,-9.565208e-004,0.000000e+000,4.230201e-003,0.000000e+000,3,9.471561e-001,1.825000e+000,,,,,,,,,,,,,,,,,,0,5.000000e+000,5.000000e-001,2,1,2.029419e-003,0,1,0,
1473146345.060,,-3.000000e+003,3.999936e+001,-9.561679e-004,0.000000e+000,4.367698e-003,0.000000e+000,3,9.473979e-001,1.825000e+000,,,,,,,,,,,,,,,,,,0,5.000000e+000,5.000000e-001,2,1,4.051208e-003,0,1,0,
1473146481.806,,-1.000000e+003,4.000138e+001,-9.208299e-004,0.000000e+000,5.777226e-003,0.000000e+000,3,9.564630e-001,1.825000e+000,,,,,,,,,,,,,,,,,,0,5.000000e+000,5.000000e-001,2,1,0.000000e+000,0,1,0,
1473146505.735,,-1.000000e+003,4.000239e+001,-9.209968e-004,0.000000e+000,6.459326e-003,0.000000e+000,3,9.556057e-001,1.825000e+000,,,,,,,,,,,,,,,,,,0,5.000000e+000,5.000000e-001,2,1,2.017975e-003,0,1,0,
1473146644.954,,-7.000000e+002,4.000239e+001,-9.092545e-004,0.000000e+000,6.898668e-003,0.000000e+000,3,9.598226e-001,1.825000e+000,,,,,,,,,,,,,,,,,,0,5.000000e+000,5.000000e-001,2,1,2.017975e-003,0,1,0,
1473146669.180,,-7.000000e+002,4.000137e+001,-9.091584e-004,0.000000e+000,6.562367e-003,0.000000e+000,3,9.597546e-001,1.825000e+000,,,,,,,,,,,,,,,,,,0,5.000000e+000,5.000000e-001,2,1,4.047394e-003,0,1,0,
1473146803.896,,-6.000000e+002,3.999834e+001,-9.026115e-004,0.000000e+000,6.620548e-003,0.000000e+000,3,9.625084e-001,1.825000e+000,,,,,,,,,,,,,,,,,,0,5.000000e+000,5.000000e-001,2,1,2.021790e-003,0,1,0,
1473146827.886,,-6.000000e+002,4.000138e+001,-9.032207e-004,0.000000e+000,6.871261e-003,0.000000e+000,3,9.619976e-001,1.825000e+000,,,,,,,,,,,,,,,,,,0,5.000000e+000,5.000000e-001,2,1,0.000000e+000,0,1,0,
1473146953.324,,-5.000000e+002,3.999834e+001,-8.948226e-004,0.000000e+000,7.731393e-003,0.000000e+000,3,9.640682e-001,1.825000e+000,,,,,,,,,,,,,,,,,,0,5.000000e+000,5.000000e-001,2,1,2.021790e-003,0,0,0,
1473146978.757,,-5.000000e+002,4.000137e+001,-8.959510e-004,0.000000e+000,7.198812e-003,0.000000e+000,3,9.636499e-001,1.825000e+000,,,,,,,,,,,,,,,,,,0,5.000000e+000,5.000000e-001,2,1,4.047394e-003,0,0,0,
1473147114.995,,-4.000000e+002,4.000037e+001,-8.848089e-004,0.000000e+000,7.921571e-003,0.000000e+000,3,9.672837e-001,1.825000e+000,,,,,,,,,,,,,,,,,,0,5.000000e+000,5.000000e-001,2,1,2.029419e-003,0,0,0,
1473147138.972,,-4.000000e+002,3.999834e+001,-8.847748e-004,0.000000e+000,7.234734e-003,0.000000e+000,3,9.677264e-001,1.825000e+000,,,,,,,,,,,,,,,,,,0,5.000000e+000,5.000000e-001,2,1,2.021790e-003,0,0,0,
1473147273.164,,-3.000000e+002,3.999834e+001,-8.690418e-004,0.000000e+000,7.724510e-003,0.000000e+000,3,9.706722e-001,1.825000e+000,,,,,,,,,,,,,,,,,,0,5.000000e+000,5.000000e-001,2,1,2.021790e-003,0,0,0,
1473147298.349,,-3.000000e+002,3.999936e+001,-8.693201e-004,0.000000e+000,8.165482e-003,0.000000e+000,3,9.709076e-001,1.825000e+000,,,,,,,,,,,,,,,,,,0,5.000000e+000,5.000000e-001,2,1,4.051208e-003,0,0,0,
1473147429.346,,-2.000000e+002,3.999834e+001,-8.443251e-004,0.000000e+000,7.955582e-003,0.000000e+000,3,9.752820e-001,1.825000e+000,,,,,,,,,,,,,,,,,,0,5.000000e+000,5.000000e-001,2,1,2.021790e-003,0,0,0,
1473147457.025,,-2.000000e+002,4.000138e+001,-8.443551e-004,0.000000e+000,8.075790e-003,0.000000e+000,3,9.753826e-001,1.825000e+000,,,,,,,,,,,,,,,,,,0,5.000000e+000,5.000000e-001,2,1,0.000000e+000,0,0,0,
1473147581.720,,-1.800000e+002,3.999733e+001,-8.375600e-004,0.000000e+000,8.844602e-003,0.000000e+000,3,9.751087e-001,1.825000e+000,,,,,,,,,,,,,,,,,,0,5.000000e+000,5.000000e-001,2,1,0.000000e+000,0,0,0,
1473147606.956,,-1.800000e+002,3.999834e+001,-8.378410e-004,0.000000e+000,8.707520e-003,0.000000e+000,3,9.749916e-001,1.825000e+000,,,,,,,,,,,,,,,,,,0,5.000000e+000,5.000000e-001,2,1,2.021790e-003,0,0,0,
1473147731.394,,-1.600000e+002,3.999834e+001,-8.288893e-004,0.000000e+000,8.864853e-003,0.000000e+000,3,9.762865e-001,1.825000e+000,,,,,,,,,,,,,,,,,,0,5.000000e+000,5.000000e-001,2,1,2.021790e-003,0,0,0,
1473147761.532,,-1.600000e+002,3.999935e+001,-8.290421e-004,0.000000e+000,9.156181e-003,0.000000e+000,3,9.762989e-001,1.825000e+000,,,,,,,,,,,,,,,,,,0,5.000000e+000,5.000000e-001,2,1,0.000000e+000,0,0,0,
1473147884.877,,-1.400000e+002,4.000239e+001,-8.201789e-004,0.000000e+000,9.198523e-003,0.000000e+000,3,9.759380e-001,1.825000e+000,,,,,,,,,,,,,,,,,,0,5.000000e+000,5.000000e-001,2,1,2.017975e-003,0,1,0,
1473147908.825,,-1.400000e+002,4.000340e+001,-8.202529e-004,0.000000e+000,8.949146e-003,0.000000e+000,3,9.769375e-001,1.825000e+000,,,,,,,,,,,,,,,,,,0,5.000000e+000,5.000000e-001,2,1,8.098602e-003,0,1,0,
1473148035.809,,-1.200000e+002,4.000239e+001,-8.096223e-004,0.000000e+000,8.711332e-003,0.000000e+000,3,9.780169e-001,1.825000e+000,,,,,,,,,,,,,,,,,,0,5.000000e+000,5.000000e-001,2,1,2.017975e-003,0,1,0,
1473148061.240,,-1.200000e+002,4.000239e+001,-8.092530e-004,0.000000e+000,8.858957e-003,0.000000e+000,3,9.782242e-001,1.825000e+000,,,,,,,,,,,,,,,,,,0,5.000000e+000,5.000000e-001,2,1,6.076813e-003,0,1,0,
1473148183.802,,-1.000000e+002,4.000137e+001,-7.950327e-004,0.000000e+000,7.516511e-003,0.000000e+000,3,9.819225e-001,1.825000e+000,,,,,,,,,,,,,,,,,,0,5.000000e+000,5.000000e-001,2,1,4.047394e-003,0,1,0,
1473148209.249,,-1.000000e+002,4.000340e+001,-7.968310e-004,0.000000e+000,9.058304e-003,0.000000e+000,3,9.789330e-001,1.825000e+000,,,,,,,,,,,,,,,,,,0,5.000000e+000,5.000000e-001,2,1,0.000000e+000,0,1,0,
1473148330.437,,-8.000000e+001,3.999935e+001,-7.819310e-004,0.000000e+000,9.660223e-003,0.000000e+000,3,9.793312e-001,1.825000e+000,,,,,,,,,,,,,,,,,,0,5.000000e+000,5.000000e-001,2,1,0.000000e+000,0,1,0,
1473148354.928,,-8.000000e+001,4.000137e+001,-7.818552e-004,0.000000e+000,8.548209e-003,0.000000e+000,3,9.802157e-001,1.825000e+000,,,,,,,,,,,,,,,,,,0,5.000000e+000,5.000000e-001,2,1,4.047394e-003,0,1,0,
1473148474.922,,-6.000000e+001,4.000340e+001,-7.627453e-004,0.000000e+000,9.511708e-003,0.000000e+000,3,9.803174e-001,1.825000e+000,,,,,,,,,,,,,,,,,,0,5.000000e+000,5.000000e-001,2,1,0.000000e+000,0,0,0,
1473148500.850,,-6.000000e+001,4.000037e+001,-7.629804e-004,0.000000e+000,9.434285e-003,0.000000e+000,3,9.815578e-001,1.825000e+000,,,,,,,,,,,,,,,,,,0,5.000000e+000,5.000000e-001,2,1,2.029419e-003,0,0,0,
1473148622.261,,-4.000000e+001,3.999834e+001,-7.402365e-004,0.000000e+000,1.038473e-002,0.000000e+000,3,9.813048e-001,1.825000e+000,,,,,,,,,,,,,,,,,,0,5.000000e+000,5.000000e-001,2,1,2.021790e-003,0,0,0,
1473148646.084,,-4.000000e+001,4.000037e+001,-7.403964e-004,0.000000e+000,9.533180e-003,0.000000e+000,3,9.811165e-001,1.825000e+000,,,,,,,,,,,,,,,,,,0,5.000000e+000,5.000000e-001,2,1,6.069183e-003,0,0,0,
1473148767.093,,-2.000000e+001,3.999834e+001,-7.085685e-004,0.000000e+000,1.034914e-002,0.000000e+000,3,9.824092e-001,1.825000e+000,,,,,,,,,,,,,,,,,,0,5.000000e+000,5.000000e-001,2,1,2.021790e-003,0,0,0,
1473148791.542,,-2.000000e+001,3.999631e+001,-7.084925e-004,0.000000e+000,9.896425e-003,0.000000e+000,3,9.824721e-001,1.825000e+000,,,,,,,,,,,,,,,,,,0,5.000000e+000,5.000000e-001,2,1,6.080627e-003,0,0,0,
1473148912.480,,0.000000e+000,3.999936e+001,-6.639143e-004,0.000000e+000,9.233338e-003,0.000000e+000,3,9.845884e-001,1.825000e+000,,,,,,,,,,,,,,,,,,0,5.000000e+000,5.000000e-001,2,1,4.051208e-003,0,0,0,
1473148935.356,,0.000000e+000,4.000543e+001,-6.636627e-004,0.000000e+000,9.772974e-003,0.000000e+000,3,9.836268e-001,1.825000e+000,,,,,,,,,,,,,,,,,,0,5.000000e+000,5.000000e-001,2,1,1.215744e-002,0,0,0,
1473149064.154,,2.000000e+001,3.999834e+001,-5.799210e-004,0.000000e+000,1.027608e-002,0.000000e+000,3,9.847581e-001,1.825000e+000,,,,,,,,,,,,,,,,,,0,5.000000e+000,5.000000e-001,2,1,2.021790e-003,0,0,0,
1473149089.339,,2.000000e+001,3.999632e+001,-5.786585e-004,0.000000e+000,1.034308e-002,0.000000e+000,3,9.838679e-001,1.825000e+000,,,,,,,,,,,,,,,,,,0,5.000000e+000,5.000000e-001,2,1,2.029419e-003,0,0,0,
1473149209.528,,4.000000e+001,3.999834e+001,5.637459e-006,0.000000e+000,-4.652142e-001,0.000000e+000,3,4.163066e-001,1.825000e+000,,,,,,,,,,,,,,,,,,0,5.000000e+000,5.000000e-001,2,1,2.021790e-003,0,0,0,
1473149245.711,,4.000000e+001,4.000137e+001,5.219629e-005,0.000000e+000,-4.416284e-003,0.000000e+000,3,9.271257e-001,1.825000e+000,,,,,,,,,,,,,,,,,,0,5.000000e+000,5.000000e-001,2,1,4.047394e-003,0,0,0,
1473149385.691,,6.000000e+001,3.999733e+001,6.212567e-004,0.000000e+000,8.954684e-003,0.000000e+000,3,9.802707e-001,1.825000e+000,,,,,,,,,,,,,,,,,,0,5.000000e+000,5.000000e-001,2,1,0.000000e+000,0,1,0,
1473149410.490,,6.000000e+001,4.000543e+001,6.242403e-004,0.000000e+000,9.523141e-003,0.000000e+000,3,9.797339e-001,1.825000e+000,,,,,,,,,,,,,,,,,,0,5.000000e+000,5.000000e-001,2,1,1.215744e-002,0,1,0,
1473149530.113,,8.000000e+001,4.000138e+001,7.052865e-004,0.000000e+000,9.173502e-003,0.000000e+000,3,9.794161e-001,1.825000e+000,,,,,,,,,,,,,,,,,,0,5.000000e+000,5.000000e-001,2,1,0.000000e+000,0,1,0,
1473149554.150,,8.000000e+001,4.000138e+001,7.065118e-004,0.000000e+000,9.390115e-003,0.000000e+000,3,9.792485e-001,1.825000e+000,,,,,,,,,,,,,,,,,,0,5.000000e+000,5.000000e-001,2,1,0.000000e+000,0,1,0,
1473149674.088,,1.000000e+002,4.000239e+001,7.492903e-004,0.000000e+000,8.874935e-003,0.000000e+000,3,9.791805e-001,1.825000e+000,,,,,,,,,,,,,,,,,,0,5.000000e+000,5.000000e-001,2,1,2.017975e-003,0,1,0,
1473149697.797,,1.000000e+002,4.000239e+001,7.508277e-004,0.000000e+000,9.305102e-003,0.000000e+000,3,9.786091e-001,1.825000e+000,,,,,,,,,,,,,,,,,,0,5.000000e+000,5.000000e-001,2,1,2.017975e-003,0,1,0,
1473149818.025,,1.200000e+002,3.999935e+001,7.787629e-004,0.000000e+000,9.289633e-003,0.000000e+000,3,9.772735e-001,1.825000e+000,,,,,,,,,,,,,,,,,,0,5.000000e+000,5.000000e-001,2,1,0.000000e+000,0,1,0,
1473149841.891,,1.200000e+002,3.999936e+001,7.792299e-004,0.000000e+000,9.332366e-003,0.000000e+000,3,9.776487e-001,1.825000e+000,,,,,,,,,,,,,,,,,,0,5.000000e+000,5.000000e-001,2,1,4.051208e-003,0,1,0,
1473149963.187,,1.400000e+002,4.000442e+001,7.991087e-004,0.000000e+000,8.986978e-003,0.000000e+000,3,9.771108e-001,1.825000e+000,,,,,,,,,,,,,,,,,,0,5.000000e+000,5.000000e-001,2,1,1.012802e-002,0,1,0,
1473149988.869,,1.400000e+002,4.000037e+001,7.993717e-004,0.000000e+000,8.974059e-003,0.000000e+000,3,9.770583e-001,1.825000e+000,,,,,,,,,,,,,,,,,,0,5.000000e+000,5.000000e-001,2,1,2.029419e-003,0,0,0,
1473150110.307,,1.600000e+002,3.999632e+001,8.140769e-004,0.000000e+000,9.382438e-003,0.000000e+000,3,9.754635e-001,1.825000e+000,,,,,,,,,,,,,,,,,,0,5.000000e+000,5.000000e-001,2,1,2.029419e-003,0,0,0,
1473150134.008,,1.600000e+002,4.000037e+001,8.142037e-004,0.000000e+000,8.864027e-003,0.000000e+000,3,9.765117e-001,1.825000e+000,,,,,,,,,,,,,,,,,,0,5.000000e+000,5.000000e-001,2,1,2.029419e-003,0,0,0,
1473150260.197,,1.800000e+002,4.000442e+001,8.240615e-004,0.000000e+000,8.066507e-003,0.000000e+000,3,9.717780e-001,1.825000e+000,,,,,,,,,,,,,,,,,,0,5.000000e+000,5.000000e-001,2,1,1.417923e-002,0,0,0,
1473150284.883,,1.800000e+002,4.000037e+001,8.266572e-004,0.000000e+000,8.474000e-003,0.000000e+000,3,9.762028e-001,1.825000e+000,,,,,,,,,,,,,,,,,,0,5.000000e+000,5.000000e-001,2,1,2.029419e-003,0,0,0,
1473150406.321,,2.000000e+002,3.999935e+001,8.357793e-004,0.000000e+000,9.011902e-003,0.000000e+000,3,9.739338e-001,1.825000e+000,,,,,,,,,,,,,,,,,,0,5.000000e+000,5.000000e-001,2,1,0.000000e+000,0,0,0,
1473150432.301,,2.000000e+002,3.999936e+001,8.357284e-004,0.000000e+000,8.913603e-003,0.000000e+000,3,9.747136e-001,1.825000e+000,,,,,,,,,,,,,,,,,,0,5.000000e+000,5.000000e-001,2,1,4.051208e-003,0,0,0,
1473150558.041,,3.000000e+002,3.999834e+001,8.669146e-004,0.000000e+000,8.762113e-003,0.000000e+000,3,9.710721e-001,1.825000e+000,,,,,,,,,,,,,,,,,,0,5.000000e+000,5.000000e-001,2,1,2.021790e-003,0,0,0,
1473150582.797,,3.000000e+002,3.999632e+001,8.669852e-004,0.000000e+000,8.811772e-003,0.000000e+000,3,9.702966e-001,1.825000e+000,,,,,,,,,,,,,,,,,,0,5.000000e+000,5.000000e-001,2,1,2.029419e-003,0,0,0,
1473150719.487,,4.000000e+002,3.999834e+001,8.845814e-004,0.000000e+000,7.831318e-003,0.000000e+000,3,9.682492e-001,1.825000e+000,,,,,,,,,,,,,,,,,,0,5.000000e+000,5.000000e-001,2,1,2.021790e-003,0,0,0,
1473150744.727,,4.000000e+002,4.000137e+001,8.841997e-004,0.000000e+000,7.985968e-003,0.000000e+000,3,9.679629e-001,1.825000e+000,,,,,,,,,,,,,,,,,,0,5.000000e+000,5.000000e-001,2,1,4.047394e-003,0,0,0,
1473150880.170,,5.000000e+002,4.000037e+001,8.947591e-004,0.000000e+000,7.819081e-003,0.000000e+000,3,9.648522e-001,1.825000e+000,,,,,,,,,,,,,,,,,,0,5.000000e+000,5.000000e-001,2,1,2.029419e-003,0,1,0,
1473150904.849,,5.000000e+002,3.999935e+001,8.943666e-004,0.000000e+000,7.303561e-003,0.000000e+000,3,9.654116e-001,1.825000e+000,,,,,,,,,,,,,,,,,,0,5.000000e+000,5.000000e-001,2,1,0.000000e+000,0,1,0,
1473151031.818,,6.000000e+002,4.000037e+001,9.030268e-004,0.000000e+000,6.658203e-003,0.000000e+000,3,9.633223e-001,1.825000e+000,,,,,,,,,,,,,,,,,,0,5.000000e+000,5.000000e-001,2,1,2.029419e-003,0,1,0,
1473151056.188,,6.000000e+002,4.000138e+001,9.033009e-004,0.000000e+000,7.565431e-003,0.000000e+000,3,9.625536e-001,1.825000e+000,,,,,,,,,,,,,,,,,,0,5.000000e+000,5.000000e-001,2,1,0.000000e+000,0,1,0,
1473151189.029,,7.000000e+002,4.000340e+001,9.085846e-004,0.000000e+000,7.818821e-003,0.000000e+000,3,9.611759e-001,1.825000e+000,,,,,,,,,,,,,,,,,,0,5.000000e+000,5.000000e-001,2,1,4.047394e-003,0,1,0,
1473151212.509,,7.000000e+002,4.000340e+001,9.094081e-004,0.000000e+000,7.098678e-003,0.000000e+000,3,9.602819e-001,1.825000e+000,,,,,,,,,,,,,,,,,,0,5.000000e+000,5.000000e-001,2,1,4.047394e-003,0,1,0,
1473151340.698,,1.000000e+003,3.999935e+001,9.214037e-004,0.000000e+000,6.715268e-003,0.000000e+000,3,9.561191e-001,1.825000e+000,,,,,,,,,,,,,,,,,,0,5.000000e+000,5.000000e-001,2,1,0.000000e+000,0,1,0,
1473151365.657,,1.000000e+003,4.000037e+001,9.215609e-004,0.000000e+000,6.673617e-003,0.000000e+000,3,9.562162e-001,1.825000e+000,,,,,,,,,,,,,,,,,,0,5.000000e+000,5.000000e-001,2,1,2.029419e-003,0,1,0,
1473151500.638,,3.000000e+003,3.999936e+001,9.559946e-004,0.000000e+000,5.017082e-003,0.000000e+000,3,9.474137e-001,1.825000e+000,,,,,,,,,,,,,,,,,,0,5.000000e+000,5.000000e-001,2,1,4.051208e-003,0,1,0,
1473151525.131,,3.000000e+003,4.000037e+001,9.564529e-004,0.000000e+000,4.917026e-003,0.000000e+000,3,9.473770e-001,1.825000e+000,,,,,,,,,,,,,,,,,,0,5.000000e+000,5.000000e-001,2,1,2.029419e-003,0,0,0,
1473151661.320,,5.000000e+003,4.000340e+001,9.726125e-004,0.000000e+000,4.757952e-003,0.000000e+000,3,9.461346e-001,1.825000e+000,,,,,,,,,,,,,,,,,,0,5.000000e+000,5.000000e-001,2,1,8.098602e-003,0,0,0,
1473151685.499,,5.000000e+003,3.999935e+001,9.726905e-004,0.000000e+000,4.837074e-003,0.000000e+000,3,9.461123e-001,1.825000e+000,,,,,,,,,,,,,,,,,,0,5.000000e+000,5.000000e-001,2,1,0.000000e+000,0,0,0,
1473151821.286,,7.000000e+003,4.000037e+001,9.844222e-004,0.000000e+000,4.807924e-003,0.000000e+000,3,9.460430e-001,1.825000e+000,,,,,,,,,,,,,,,,,,0,5.000000e+000,5.000000e-001,2,1,6.069183e-003,0,0,0,
1473151847.465,,7.000000e+003,3.999834e+001,9.872639e-004,0.000000e+000,5.149547e-003,0.000000e+000,3,9.456269e-001,1.825000e+000,,,,,,,,,,,,,,,,,,0,5.000000e+000,5.000000e-001,2,1,2.021790e-003,0,0,0,
1473151986.588,,9.000000e+003,3.999935e+001,9.938226e-004,0.000000e+000,4.790031e-003,0.000000e+000,3,9.461203e-001,1.825000e+000,,,,,,,,,,,,,,,,,,0,5.000000e+000,5.000000e-001,2,1,0.000000e+000,0,0,0,
1473152010.916,,9.000000e+003,4.000037e+001,9.936717e-004,0.000000e+000,4.798125e-003,0.000000e+000,3,9.461116e-001,1.825000e+000,,,,,,,,,,,,,,,,,,0,5.000000e+000,5.000000e-001,2,1,2.029419e-003,0,0,0,
1473152143.560,,1.000000e+004,3.999530e+001,9.975962e-004,0.000000e+000,4.879708e-003,0.000000e+000,3,9.461702e-001,1.825000e+000,,,,,,,,,,,,,,,,,,0,5.000000e+000,5.000000e-001,2,1,4.058838e-003,0,0,0,
1473152168.655,,1.000000e+004,3.999834e+001,9.975627e-004,0.000000e+000,4.900334e-003,0.000000e+000,3,9.461578e-001,1.825000e+000,,,,,,,,,,,,,,,,,,0,5.000000e+000,5.000000e-001,2,1,2.021790e-003,0,0,0,
1473152339.348,,2.000000e+004,3.999834e+001,1.025210e-003,0.000000e+000,5.499068e-003,0.000000e+000,3,9.465322e-001,1.825000e+000,,,,,,,,,,,,,,,,,,0,5.000000e+000,5.000000e-001,2,1,2.021790e-003,0,0,0,
1473152366.626,,2.000000e+004,3.999733e+001,1.025136e-003,0.000000e+000,5.477931e-003,0.000000e+000,3,9.465767e-001,1.825000e+000,,,,,,,,,,,,,,,,,,0,5.000000e+000,5.000000e-001,2,1,4.051208e-003,0,0,0,
1473152541.073,,3.000000e+004,4.000138e+001,1.042449e-003,0.000000e+000,6.005140e-003,0.000000e+000,3,9.463555e-001,1.825000e+000,,,,,,,,,,,,,,,,,,0,5.000000e+000,5.000000e-001,2,1,0.000000e+000,0,1,0,
1473152563.504,,3.000000e+004,3.999936e+001,1.041936e-003,0.000000e+000,6.056932e-003,0.000000e+000,3,9.463940e-001,1.825000e+000,,,,,,,,,,,,,,,,,,0,5.000000e+000,5.000000e-001,2,1,4.051208e-003,0,1,0,
1473152736.064,,4.000000e+004,4.000239e+001,1.055141e-003,0.000000e+000,7.203378e-003,0.000000e+000,3,9.454808e-001,1.825000e+000,,,,,,,,,,,,,,,,,,0,5.000000e+000,5.000000e-001,2,1,2.017975e-003,0,1,0,
1473152761.492,,4.000000e+004,4.000441e+001,1.057080e-003,0.000000e+000,5.919300e-003,0.000000e+000,3,9.475234e-001,1.825000e+000,,,,,,,,,,,,,,,,,,0,5.000000e+000,5.000000e-001,2,1,2.029419e-003,0,1,0,
1473152943.974,,5.000000e+004,3.999935e+001,1.062275e-003,0.000000e+000,5.524185e-003,0.000000e+000,3,9.464023e-001,1.825000e+000,,,,,,,,,,,,,,,,,,0,5.000000e+000,5.000000e-001,2,1,0.000000e+000,0,1,0,
1473152971.153,,5.000000e+004,4.000037e+001,1.060882e-003,0.000000e+000,4.941203e-003,0.000000e+000,3,9.483843e-001,1.825000e+000,,,,,,,,,,,,,,,,,,0,5.000000e+000,5.000000e-001,2,1,2.029419e-003,0,1,0,
1473153160.901,,6.000000e+004,3.999935e+001,1.065843e-003,0.000000e+000,6.861633e-003,0.000000e+000,3,9.441677e-001,1.825000e+000,,,,,,,,,,,,,,,,,,0,5.000000e+000,5.000000e-001,2,1,0.000000e+000,0,0,0,
1473153185.330,,6.000000e+004,3.999834e+001,1.065742e-003,0.000000e+000,7.297164e-003,0.000000e+000,3,9.453894e-001,1.825000e+000,,,,,,,,,,,,,,,,,,0,5.000000e+000,5.000000e-001,2,1,2.021790e-003,0,0,0,
1473153364.225,,7.000000e+004,4.000037e+001,1.071916e-003,0.000000e+000,7.120701e-003,0.000000e+000,3,9.456398e-001,1.825000e+000,,,,,,,,,,,,,,,,,,0,5.000000e+000,5.000000e-001,2,1,2.029419e-003,0,0,0,
1473153388.012,,7.000000e+004,4.000037e+001,1.072842e-003,0.000000e+000,7.959312e-003,0.000000e+000,3,9.450681e-001,1.825000e+000,,,,,,,,,,,,,,,,,,0,5.000000e+000,5.000000e-001,2,1,2.029419e-003,0,0,0,
1473153400.411,,7.000000e+004,4.000037e+001,1.072917e-003,0.000000e+000,7.685645e-003,0.000000e+000,3,9.455209e-001,1.825000e+000,,,,,,,,,,,,,,,,,,0,5.000000e+000,5.000000e-001,2,1,2.029419e-003,0,0,0,