File: data/A344/A344_GdN_MH_010K_160908.rso.dat
[Header]
TITLE,MPMS RSO Measurement
BYAPP,MPMS Measurement,1.1,Summary
FILEOPENTIME, 1473271151.107000 9/8/2016, 5:59:11 AM

INFO, APPNAME, MPMS MultiVu Application, Revision 1.61,  Build 082

INFO, NAME, A344
INFO, WEIGHT, 10.500
INFO, AREA, 1.000
INFO, LENGTH, 1.000
INFO, SHAPE, 0
INFO, COMMENT, m = 0.0105g
INFO, SEQUENCE FILE: 7T_hysteresis_sweep_hi_res_zero_n4.seq


INFO, BACKGROUND DATA FILE:, None


STARTUPAXIS,X,4,LINEAR,AUTO,0.000000,0.000000
STARTUPAXIS,Y1,5,LINEAR,AUTO,0.000000,0.000000


STARTUPGROUP,Longitudinal
FIELDGROUP,Longitudinal,1,2,3,4,5,6,7,8,9,10,11,19,20,21,22,23,35
FIELDGROUP,Transverse,1,2,3,4,12,13,14,15,16,17,18,24,25,26,27,28,35

PLOT_APPEARANCE,ALL,HORZ_GRID_ON,VERT_GRID_ON,MARKERS_AND_LINES

[Data]
Time,Comment,Field (Oe),Temperature (K),Long Moment (emu),Long Scan Std Dev,Long Offset (cm),Long Offset Std Dev,Long Algorithm,Long Reg Fit,Long Reg Factor,Trans Moment (emu),Trans Scan Std Dev,Trans Offset (cm),Trans Offset Std Dev,Trans Algorithm,Trans Reg Fit,Trans Reg Factor,Long Moment [w/o ABS] (emu),Long Scan Std Dev [w/o ABS],Long Offset [w/o ABS] (cm),Long Offset Std Dev [w/o ABS],Long Reg Fit [w/o ABS],Trans Moment [w/o ABS] (emu),Trans Scan Std Dev [w/o ABS],Trans Offset [w/o ABS] (cm),Trans Offset Std Dev [w/o ABS],Trans Reg Fit [w/o ABS],RSO Position (deg),Amplitude (cm),Frequency,Cycles to Average,Scans per Measurement,Delta Temp (K),Error,EC Comp. Running,Using ABS,
1473271151.106,,7.000000e+004,9.826284e+000,1.300613e-003,0.000000e+000,7.022396e-003,0.000000e+000,3,9.530002e-001,1.825000e+000,,,,,,,,,,,,,,,,,,0,5.000000e+000,5.000000e-001,2,1,2.953529e-003,0,1,0,
1473271175.759,,7.000000e+004,9.830988e+000,1.297398e-003,0.000000e+000,7.262457e-003,0.000000e+000,3,9.535004e-001,1.825000e+000,,,,,,,,,,,,,,,,,,0,5.000000e+000,5.000000e-001,2,1,1.612663e-003,0,1,0,
1473271360.978,,6.000000e+004,9.827226e+000,1.303248e-003,0.000000e+000,5.185099e-003,0.000000e+000,3,9.554898e-001,1.825000e+000,,,,,,,,,,,,,,,,,,0,5.000000e+000,5.000000e-001,2,1,5.373001e-003,0,1,0,
1473271386.643,,6.000000e+004,9.833005e+000,1.299210e-003,0.000000e+000,6.036378e-003,0.000000e+000,3,9.532618e-001,1.825000e+000,,,,,,,,,,,,,,,,,,0,5.000000e+000,5.000000e-001,2,1,2.708435e-004,0,1,0,
1473271568.500,,5.000000e+004,9.826957e+000,1.303627e-003,0.000000e+000,5.339412e-003,0.000000e+000,3,9.540241e-001,1.825000e+000,,,,,,,,,,,,,,,,,,0,5.000000e+000,5.000000e-001,2,1,4.835129e-003,0,1,0,
1473271592.416,,5.000000e+004,9.832870e+000,1.301247e-003,0.000000e+000,5.669472e-003,0.000000e+000,3,9.546929e-001,1.825000e+000,,,,,,,,,,,,,,,,,,0,5.000000e+000,5.000000e-001,2,1,2.151489e-003,0,1,0,
1473271775.863,,4.000000e+004,9.826016e+000,1.309944e-003,0.000000e+000,5.850181e-003,0.000000e+000,3,9.550846e-001,1.825000e+000,,,,,,,,,,,,,,,,,,0,5.000000e+000,5.000000e-001,2,1,2.416611e-003,0,1,0,
1473271802.324,,4.000000e+004,9.832467e+000,1.301456e-003,0.000000e+000,6.257316e-003,0.000000e+000,3,9.569899e-001,1.825000e+000,,,,,,,,,,,,,,,,,,0,5.000000e+000,5.000000e-001,2,1,1.882553e-003,0,1,0,
1473271981.527,,3.000000e+004,9.826689e+000,1.301209e-003,0.000000e+000,2.528992e-003,0.000000e+000,3,9.556019e-001,1.825000e+000,,,,,,,,,,,,,,,,,,0,5.000000e+000,5.000000e-001,2,1,4.835129e-003,0,1,0,
1473272006.953,,3.000000e+004,9.832735e+000,1.296304e-003,0.000000e+000,2.952761e-003,0.000000e+000,3,9.545922e-001,1.825000e+000,,,,,,,,,,,,,,,,,,0,5.000000e+000,5.000000e-001,2,1,2.679825e-004,0,1,0,
1473272179.883,,2.000000e+004,9.826823e+000,1.292188e-003,0.000000e+000,2.613996e-003,0.000000e+000,3,9.561523e-001,1.825000e+000,,,,,,,,,,,,,,,,,,0,5.000000e+000,5.000000e-001,2,1,2.954483e-003,0,1,0,
1473272206.868,,2.000000e+004,9.832064e+000,1.291440e-003,0.000000e+000,2.805853e-003,0.000000e+000,3,9.546043e-001,1.825000e+000,,,,,,,,,,,,,,,,,,0,5.000000e+000,5.000000e-001,2,1,1.075745e-003,0,1,0,
1473272380.109,,1.000000e+004,9.827494e+000,1.274247e-003,0.000000e+000,2.315872e-003,0.000000e+000,3,9.555532e-001,1.825000e+000,,,,,,,,,,,,,,,,,,0,5.000000e+000,5.000000e-001,2,1,4.836082e-003,0,1,0,
1473272405.346,,1.000000e+004,9.833544e+000,1.274771e-003,0.000000e+000,1.946594e-003,0.000000e+000,3,9.555347e-001,1.825000e+000,,,,,,,,,,,,,,,,,,0,5.000000e+000,5.000000e-001,2,1,8.058548e-004,0,1,0,
1473272541.302,,9.000000e+003,9.826016e+000,1.272232e-003,0.000000e+000,1.482519e-003,0.000000e+000,3,9.551334e-001,1.825000e+000,,,,,,,,,,,,,,,,,,0,5.000000e+000,5.000000e-001,2,1,3.490448e-003,0,1,0,
1473272568.025,,9.000000e+003,9.832870e+000,1.271239e-003,0.000000e+000,1.483680e-003,0.000000e+000,3,9.555504e-001,1.825000e+000,,,,,,,,,,,,,,,,,,0,5.000000e+000,5.000000e-001,2,1,1.614571e-003,0,1,0,
1473272708.215,,7.000000e+003,9.826824e+000,1.265099e-003,0.000000e+000,2.205447e-003,0.000000e+000,3,9.555624e-001,1.825000e+000,,,,,,,,,,,,,,,,,,0,5.000000e+000,5.000000e-001,2,1,6.176949e-003,0,1,0,
1473272734.202,,7.000000e+003,9.832870e+000,1.264804e-003,0.000000e+000,1.857723e-003,0.000000e+000,3,9.556473e-001,1.825000e+000,,,,,,,,,,,,,,,,,,0,5.000000e+000,5.000000e-001,2,1,5.388260e-004,0,1,0,
1473272871.395,,5.000000e+003,9.826555e+000,1.255755e-003,0.000000e+000,2.383114e-003,0.000000e+000,3,9.557072e-001,1.825000e+000,,,,,,,,,,,,,,,,,,0,5.000000e+000,5.000000e-001,2,1,5.103111e-003,0,1,0,
1473272898.824,,5.000000e+003,9.832870e+000,1.256109e-003,0.000000e+000,2.129895e-003,0.000000e+000,3,9.556503e-001,1.825000e+000,,,,,,,,,,,,,,,,,,0,5.000000e+000,5.000000e-001,2,1,1.075745e-003,0,1,0,
1473273028.013,,3.000000e+003,9.823734e+000,1.242056e-003,0.000000e+000,2.481186e-003,0.000000e+000,3,9.567318e-001,1.825000e+000,,,,,,,,,,,,,,,,,,0,5.000000e+000,5.000000e-001,2,1,2.682686e-003,0,1,0,
1473273051.464,,3.000000e+003,9.833677e+000,1.241377e-003,0.000000e+000,2.044504e-003,0.000000e+000,3,9.569302e-001,1.825000e+000,,,,,,,,,,,,,,,,,,0,5.000000e+000,5.000000e-001,2,1,0.000000e+000,0,1,0,
1473273187.946,,1.000000e+003,9.826286e+000,1.207285e-003,0.000000e+000,3.764739e-003,0.000000e+000,3,9.630722e-001,1.825000e+000,,,,,,,,,,,,,,,,,,0,5.000000e+000,5.000000e-001,2,1,5.640030e-003,0,1,0,
1473273214.125,,1.000000e+003,9.833005e+000,1.206106e-003,0.000000e+000,3.942461e-003,0.000000e+000,3,9.632094e-001,1.825000e+000,,,,,,,,,,,,,,,,,,0,5.000000e+000,5.000000e-001,2,1,2.708435e-004,0,1,0,
1473273353.324,,7.000000e+002,9.825480e+000,1.195078e-003,0.000000e+000,3.582729e-003,0.000000e+000,3,9.668093e-001,1.825000e+000,,,,,,,,,,,,,,,,,,0,5.000000e+000,5.000000e-001,2,1,4.026413e-003,0,1,0,
1473273377.762,,7.000000e+002,9.833677e+000,1.194647e-003,0.000000e+000,3.860828e-003,0.000000e+000,3,9.665953e-001,1.825000e+000,,,,,,,,,,,,,,,,,,0,5.000000e+000,5.000000e-001,2,1,1.074791e-003,0,1,0,
1473273506.988,,6.000000e+002,9.825748e+000,1.188397e-003,0.000000e+000,3.960890e-003,0.000000e+000,3,9.681404e-001,1.825000e+000,,,,,,,,,,,,,,,,,,0,5.000000e+000,5.000000e-001,2,1,4.026413e-003,0,1,0,
1473273534.474,,6.000000e+002,9.833408e+000,1.188259e-003,0.000000e+000,4.018930e-003,0.000000e+000,3,9.682201e-001,1.825000e+000,,,,,,,,,,,,,,,,,,0,5.000000e+000,5.000000e-001,2,1,0.000000e+000,0,1,0,
1473273671.667,,5.000000e+002,9.825748e+000,1.181106e-003,0.000000e+000,4.286256e-003,0.000000e+000,3,9.702170e-001,1.825000e+000,,,,,,,,,,,,,,,,,,0,5.000000e+000,5.000000e-001,2,1,4.026413e-003,0,1,0,
1473273698.096,,5.000000e+002,9.833408e+000,1.180897e-003,0.000000e+000,4.361216e-003,0.000000e+000,3,9.701125e-001,1.825000e+000,,,,,,,,,,,,,,,,,,0,5.000000e+000,5.000000e-001,2,1,5.369186e-004,0,1,0,
1473273833.808,,4.000000e+002,9.826286e+000,1.172452e-003,0.000000e+000,4.308358e-003,0.000000e+000,3,9.724675e-001,1.825000e+000,,,,,,,,,,,,,,,,,,0,5.000000e+000,5.000000e-001,2,1,5.640030e-003,0,1,0,
1473273860.285,,4.000000e+002,9.832870e+000,1.172089e-003,0.000000e+000,4.720967e-003,0.000000e+000,3,9.717883e-001,1.825000e+000,,,,,,,,,,,,,,,,,,0,5.000000e+000,5.000000e-001,2,1,2.689362e-003,0,1,0,
1473273996.979,,3.000000e+002,9.825614e+000,1.159437e-003,0.000000e+000,5.112441e-003,0.000000e+000,3,9.747356e-001,1.825000e+000,,,,,,,,,,,,,,,,,,0,5.000000e+000,5.000000e-001,2,1,3.757477e-003,0,1,0,
1473274023.958,,3.000000e+002,9.832602e+000,1.157961e-003,0.000000e+000,4.842747e-003,0.000000e+000,3,9.744670e-001,1.825000e+000,,,,,,,,,,,,,,,,,,0,5.000000e+000,5.000000e-001,2,1,5.369186e-004,0,1,0,
1473274156.397,,2.000000e+002,9.826286e+000,1.139216e-003,0.000000e+000,5.261282e-003,0.000000e+000,3,9.768762e-001,1.825000e+000,,,,,,,,,,,,,,,,,,0,5.000000e+000,5.000000e-001,2,1,5.640030e-003,0,1,0,
1473274182.857,,2.000000e+002,9.833544e+000,1.138497e-003,0.000000e+000,5.161067e-003,0.000000e+000,3,9.774448e-001,1.825000e+000,,,,,,,,,,,,,,,,,,0,5.000000e+000,5.000000e-001,2,1,8.058548e-004,0,1,0,
1473274312.049,,1.800000e+002,9.824943e+000,1.132636e-003,0.000000e+000,5.224767e-003,0.000000e+000,3,9.780293e-001,1.825000e+000,,,,,,,,,,,,,,,,,,0,5.000000e+000,5.000000e-001,2,1,3.488541e-003,0,1,0,
1473274338.527,,1.800000e+002,9.832870e+000,1.133782e-003,0.000000e+000,5.429085e-003,0.000000e+000,3,9.779615e-001,1.825000e+000,,,,,,,,,,,,,,,,,,0,5.000000e+000,5.000000e-001,2,1,1.075745e-003,0,1,0,
1473274459.465,,1.600000e+002,9.825884e+000,1.127111e-003,0.000000e+000,5.481446e-003,0.000000e+000,3,9.785052e-001,1.825000e+000,,,,,,,,,,,,,,,,,,0,5.000000e+000,5.000000e-001,2,1,5.908012e-003,0,1,0,
1473274487.644,,1.600000e+002,9.833139e+000,1.126925e-003,0.000000e+000,5.422022e-003,0.000000e+000,3,9.787194e-001,1.825000e+000,,,,,,,,,,,,,,,,,,0,5.000000e+000,5.000000e-001,2,1,1.075745e-003,0,1,0,
1473274610.586,,1.400000e+002,9.825749e+000,1.120362e-003,0.000000e+000,5.335141e-003,0.000000e+000,3,9.790354e-001,1.825000e+000,,,,,,,,,,,,,,,,,,0,5.000000e+000,5.000000e-001,2,1,5.640030e-003,0,1,0,
1473274635.765,,1.400000e+002,9.832870e+000,1.120998e-003,0.000000e+000,5.698301e-003,0.000000e+000,3,9.790230e-001,1.825000e+000,,,,,,,,,,,,,,,,,,0,5.000000e+000,5.000000e-001,2,1,1.614571e-003,0,1,0,
1473274756.976,,1.200000e+002,9.825347e+000,1.113167e-003,0.000000e+000,5.669157e-003,0.000000e+000,3,9.797236e-001,1.825000e+000,,,,,,,,,,,,,,,,,,0,5.000000e+000,5.000000e-001,2,1,5.907059e-003,0,1,0,
1473274782.405,,1.200000e+002,9.832333e+000,1.112057e-003,0.000000e+000,5.569602e-003,0.000000e+000,3,9.798878e-001,1.825000e+000,,,,,,,,,,,,,,,,,,0,5.000000e+000,5.000000e-001,2,1,1.074791e-003,0,1,0,
1473274912.415,,1.000000e+002,9.825884e+000,1.104023e-003,0.000000e+000,5.466975e-003,0.000000e+000,3,9.804831e-001,1.825000e+000,,,,,,,,,,,,,,,,,,0,5.000000e+000,5.000000e-001,2,1,4.834175e-003,0,1,0,
1473274938.117,,1.000000e+002,9.832870e+000,1.104969e-003,0.000000e+000,5.942503e-003,0.000000e+000,3,9.800009e-001,1.825000e+000,,,,,,,,,,,,,,,,,,0,5.000000e+000,5.000000e-001,2,1,5.388260e-004,0,1,0,
1473275062.090,,8.000000e+001,9.825884e+000,1.094572e-003,0.000000e+000,5.583138e-003,0.000000e+000,3,9.814501e-001,1.825000e+000,,,,,,,,,,,,,,,,,,0,5.000000e+000,5.000000e-001,2,1,5.371094e-003,0,1,0,
1473275086.708,,8.000000e+001,9.833139e+000,1.094198e-003,0.000000e+000,5.634117e-003,0.000000e+000,3,9.810217e-001,1.825000e+000,,,,,,,,,,,,,,,,,,0,5.000000e+000,5.000000e-001,2,1,1.075745e-003,0,1,0,
1473275213.943,,6.000000e+001,9.825615e+000,1.082829e-003,0.000000e+000,6.055215e-003,0.000000e+000,3,9.820193e-001,1.825000e+000,,,,,,,,,,,,,,,,,,0,5.000000e+000,5.000000e-001,2,1,6.443977e-003,0,1,0,
1473275240.522,,6.000000e+001,9.833005e+000,1.082254e-003,0.000000e+000,6.070776e-003,0.000000e+000,3,9.814837e-001,1.825000e+000,,,,,,,,,,,,,,,,,,0,5.000000e+000,5.000000e-001,2,1,8.068085e-004,0,1,0,
1473275369.771,,4.000000e+001,9.825615e+000,1.067530e-003,0.000000e+000,6.033584e-003,0.000000e+000,3,9.826459e-001,1.825000e+000,,,,,,,,,,,,,,,,,,0,5.000000e+000,5.000000e-001,2,1,5.371094e-003,0,1,0,
1473275395.450,,4.000000e+001,9.832870e+000,1.068039e-003,0.000000e+000,6.157801e-003,0.000000e+000,3,9.819483e-001,1.825000e+000,,,,,,,,,,,,,,,,,,0,5.000000e+000,5.000000e-001,2,1,0.000000e+000,0,1,0,
1473275515.642,,2.000000e+001,9.825077e+000,1.050395e-003,0.000000e+000,6.361703e-003,0.000000e+000,3,9.827763e-001,1.825000e+000,,,,,,,,,,,,,,,,,,0,5.000000e+000,5.000000e-001,2,1,5.368233e-003,0,1,0,
1473275542.392,,2.000000e+001,9.832064e+000,1.049998e-003,0.000000e+000,5.707437e-003,0.000000e+000,3,9.815080e-001,1.825000e+000,,,,,,,,,,,,,,,,,,0,5.000000e+000,5.000000e-001,2,1,5.378723e-004,0,1,0,
1473275665.080,,0.000000e+000,9.824944e+000,1.028508e-003,0.000000e+000,6.030394e-003,0.000000e+000,3,9.836363e-001,1.825000e+000,,,,,,,,,,,,,,,,,,0,5.000000e+000,5.000000e-001,2,1,4.563332e-003,0,1,0,
1473275691.062,,0.000000e+000,9.831795e+000,1.027878e-003,0.000000e+000,5.830370e-003,0.000000e+000,3,9.840232e-001,1.825000e+000,,,,,,,,,,,,,,,,,,0,5.000000e+000,5.000000e-001,2,1,0.000000e+000,0,1,0,
1473275813.505,,-2.000000e+001,9.825212e+000,9.969854e-004,0.000000e+000,7.018638e-003,0.000000e+000,3,9.835727e-001,1.825000e+000,,,,,,,,,,,,,,,,,,0,5.000000e+000,5.000000e-001,2,1,5.638123e-003,0,1,0,
1473275838.502,,-2.000000e+001,9.832870e+000,9.974330e-004,0.000000e+000,6.553851e-003,0.000000e+000,3,9.836952e-001,1.825000e+000,,,,,,,,,,,,,,,,,,0,5.000000e+000,5.000000e-001,2,1,1.075745e-003,0,1,0,
1473275959.939,,-4.000000e+001,9.825077e+000,9.544326e-004,0.000000e+000,7.556027e-003,0.000000e+000,3,9.837460e-001,1.825000e+000,,,,,,,,,,,,,,,,,,0,5.000000e+000,5.000000e-001,2,1,4.831314e-003,0,1,0,
1473275986.928,,-4.000000e+001,9.831928e+000,9.543440e-004,0.000000e+000,6.492481e-003,0.000000e+000,3,9.844216e-001,1.825000e+000,,,,,,,,,,,,,,,,,,0,5.000000e+000,5.000000e-001,2,1,2.679825e-004,0,1,0,
1473276108.565,,-6.000000e+001,9.824808e+000,8.792112e-004,0.000000e+000,7.787408e-003,0.000000e+000,3,9.845732e-001,1.825000e+000,,,,,,,,,,,,,,,,,,0,5.000000e+000,5.000000e-001,2,1,5.369186e-003,0,1,0,
1473276134.852,,-6.000000e+001,9.832063e+000,8.765067e-004,0.000000e+000,7.354057e-003,0.000000e+000,3,9.849772e-001,1.825000e+000,,,,,,,,,,,,,,,,,,0,5.000000e+000,5.000000e-001,2,1,0.000000e+000,0,1,0,
1473276268.603,,-8.000000e+001,9.828972e+000,3.954825e-004,0.000000e+000,9.407187e-003,0.000000e+000,3,9.850867e-001,1.825000e+000,,,,,,,,,,,,,,,,,,0,5.000000e+000,5.000000e-001,2,1,1.880646e-003,0,1,0,
1473276295.532,,-8.000000e+001,9.833408e+000,3.700740e-004,0.000000e+000,9.936589e-003,0.000000e+000,3,9.845717e-001,1.825000e+000,,,,,,,,,,,,,,,,,,0,5.000000e+000,5.000000e-001,2,1,5.369186e-004,0,1,0,
1473276420.032,,-1.000000e+002,9.824675e+000,-3.898167e-004,0.000000e+000,1.709182e-003,0.000000e+000,3,9.720345e-001,1.825000e+000,,,,,,,,,,,,,,,,,,0,5.000000e+000,5.000000e-001,2,1,4.563332e-003,0,1,0,
1473276448.211,,-1.000000e+002,9.831795e+000,-3.940563e-004,0.000000e+000,2.338262e-003,0.000000e+000,3,9.739302e-001,1.825000e+000,,,,,,,,,,,,,,,,,,0,5.000000e+000,5.000000e-001,2,1,1.075745e-003,0,1,0,
1473276570.208,,-1.200000e+002,9.825346e+000,-5.218479e-004,0.000000e+000,3.137910e-003,0.000000e+000,3,9.748079e-001,1.825000e+000,,,,,,,,,,,,,,,,,,0,5.000000e+000,5.000000e-001,2,1,6.445885e-003,0,1,0,
1473276594.407,,-1.200000e+002,9.831795e+000,-5.263215e-004,0.000000e+000,3.393792e-003,0.000000e+000,3,9.745526e-001,1.825000e+000,,,,,,,,,,,,,,,,,,0,5.000000e+000,5.000000e-001,2,1,5.369186e-004,0,1,0,
1473276715.599,,-1.400000e+002,9.824808e+000,-6.063355e-004,0.000000e+000,4.015916e-003,0.000000e+000,3,9.755741e-001,1.825000e+000,,,,,,,,,,,,,,,,,,0,5.000000e+000,5.000000e-001,2,1,2.684593e-003,0,1,0,
1473276745.547,,-1.400000e+002,9.832063e+000,-6.099290e-004,0.000000e+000,3.987294e-003,0.000000e+000,3,9.743444e-001,1.825000e+000,,,,,,,,,,,,,,,,,,0,5.000000e+000,5.000000e-001,2,1,0.000000e+000,0,1,0,
1473276868.791,,-1.600000e+002,9.824003e+000,-6.728800e-004,0.000000e+000,3.952999e-003,0.000000e+000,3,9.738882e-001,1.825000e+000,,,,,,,,,,,,,,,,,,0,5.000000e+000,5.000000e-001,2,1,4.295349e-003,0,1,0,
1473276894.470,,-1.600000e+002,9.832064e+000,-6.752412e-004,0.000000e+000,4.748392e-003,0.000000e+000,3,9.744565e-001,1.825000e+000,,,,,,,,,,,,,,,,,,0,5.000000e+000,5.000000e-001,2,1,5.378723e-004,0,1,0,
1473277020.428,,-1.800000e+002,9.825212e+000,-7.302734e-004,0.000000e+000,4.398410e-003,0.000000e+000,3,9.742355e-001,1.825000e+000,,,,,,,,,,,,,,,,,,0,5.000000e+000,5.000000e-001,2,1,5.638123e-003,0,1,0,
1473277045.143,,-1.800000e+002,9.832198e+000,-7.330622e-004,0.000000e+000,4.479309e-003,0.000000e+000,3,9.740720e-001,1.825000e+000,,,,,,,,,,,,,,,,,,0,5.000000e+000,5.000000e-001,2,1,8.068085e-004,0,1,0,
1473277166.331,,-2.000000e+002,9.824675e+000,-7.780110e-004,0.000000e+000,4.146396e-003,0.000000e+000,3,9.746098e-001,1.825000e+000,,,,,,,,,,,,,,,,,,0,5.000000e+000,5.000000e-001,2,1,5.637169e-003,0,1,0,
1473277193.010,,-2.000000e+002,9.831929e+000,-7.808293e-004,0.000000e+000,4.507878e-003,0.000000e+000,3,9.737327e-001,1.825000e+000,,,,,,,,,,,,,,,,,,0,5.000000e+000,5.000000e-001,2,1,8.068085e-004,0,1,0,
1473277342.975,,-3.000000e+002,9.830048e+000,-9.456056e-004,0.000000e+000,4.480266e-003,0.000000e+000,3,9.720066e-001,1.825000e+000,,,,,,,,,,,,,,,,,,0,5.000000e+000,5.000000e-001,2,1,3.494263e-003,0,1,0,
1473277369.153,,-3.000000e+002,9.832333e+000,-9.474409e-004,0.000000e+000,4.376185e-003,0.000000e+000,3,9.722438e-001,1.825000e+000,,,,,,,,,,,,,,,,,,0,5.000000e+000,5.000000e-001,2,1,5.388260e-004,0,1,0,
1473277503.847,,-4.000000e+002,9.825211e+000,-1.031224e-003,0.000000e+000,4.109004e-003,0.000000e+000,3,9.701899e-001,1.825000e+000,,,,,,,,,,,,,,,,,,0,5.000000e+000,5.000000e-001,2,1,4.563332e-003,0,1,0,
1473277530.025,,-4.000000e+002,9.831795e+000,-1.033571e-003,0.000000e+000,4.107616e-003,0.000000e+000,3,9.702945e-001,1.825000e+000,,,,,,,,,,,,,,,,,,0,5.000000e+000,5.000000e-001,2,1,5.369186e-004,0,1,0,
1473277667.219,,-5.000000e+002,9.825212e+000,-1.082517e-003,0.000000e+000,4.197767e-003,0.000000e+000,3,9.684285e-001,1.825000e+000,,,,,,,,,,,,,,,,,,0,5.000000e+000,5.000000e-001,2,1,5.638123e-003,0,1,0,
1473277696.918,,-5.000000e+002,9.831660e+000,-1.083131e-003,0.000000e+000,4.242535e-003,0.000000e+000,3,9.688328e-001,1.825000e+000,,,,,,,,,,,,,,,,,,0,5.000000e+000,5.000000e-001,2,1,2.689362e-004,0,1,0,
1473277826.607,,-6.000000e+002,9.826017e+000,-1.112686e-003,0.000000e+000,4.032106e-003,0.000000e+000,3,9.672663e-001,1.825000e+000,,,,,,,,,,,,,,,,,,0,5.000000e+000,5.000000e-001,2,1,6.176949e-003,0,1,0,
1473277854.076,,-6.000000e+002,9.831391e+000,-1.113853e-003,0.000000e+000,4.006594e-003,0.000000e+000,3,9.671459e-001,1.825000e+000,,,,,,,,,,,,,,,,,,0,5.000000e+000,5.000000e-001,2,1,2.689362e-004,0,1,0,
1473277988.515,,-7.000000e+002,9.825481e+000,-1.134583e-003,0.000000e+000,3.908437e-003,0.000000e+000,3,9.656870e-001,1.825000e+000,,,,,,,,,,,,,,,,,,0,5.000000e+000,5.000000e-001,2,1,5.639076e-003,0,1,0,
1473278014.444,,-7.000000e+002,9.831659e+000,-1.135693e-003,0.000000e+000,3.465598e-003,0.000000e+000,3,9.655771e-001,1.825000e+000,,,,,,,,,,,,,,,,,,0,5.000000e+000,5.000000e-001,2,1,8.058548e-004,0,1,0,
1473278142.410,,-1.000000e+003,9.823734e+000,-1.168576e-003,0.000000e+000,3.562354e-003,0.000000e+000,3,9.629813e-001,1.825000e+000,,,,,,,,,,,,,,,,,,0,5.000000e+000,5.000000e-001,2,1,3.757477e-003,0,1,0,
1473278167.374,,-1.000000e+003,9.831257e+000,-1.169052e-003,0.000000e+000,3.590337e-003,0.000000e+000,3,9.629233e-001,1.825000e+000,,,,,,,,,,,,,,,,,,0,5.000000e+000,5.000000e-001,2,1,5.378723e-004,0,1,0,
1473278298.354,,-3.000000e+003,9.825346e+000,-1.231440e-003,0.000000e+000,1.591398e-003,0.000000e+000,3,9.575382e-001,1.825000e+000,,,,,,,,,,,,,,,,,,0,5.000000e+000,5.000000e-001,2,1,4.832268e-003,0,1,0,
1473278325.534,,-3.000000e+003,9.831257e+000,-1.232399e-003,0.000000e+000,2.268079e-003,0.000000e+000,3,9.570507e-001,1.825000e+000,,,,,,,,,,,,,,,,,,0,5.000000e+000,5.000000e-001,2,1,5.378723e-004,0,1,0,
1473278461.533,,-5.000000e+003,9.825212e+000,-1.251748e-003,0.000000e+000,2.210943e-003,0.000000e+000,3,9.558890e-001,1.825000e+000,,,,,,,,,,,,,,,,,,0,5.000000e+000,5.000000e-001,2,1,6.176949e-003,0,1,0,
1473278488.259,,-5.000000e+003,9.832063e+000,-1.251723e-003,0.000000e+000,2.364460e-003,0.000000e+000,3,9.557869e-001,1.825000e+000,,,,,,,,,,,,,,,,,,0,5.000000e+000,5.000000e-001,2,1,0.000000e+000,0,1,0,
1473278625.449,,-7.000000e+003,9.825077e+000,-1.262614e-003,0.000000e+000,2.434855e-003,0.000000e+000,3,9.555172e-001,1.825000e+000,,,,,,,,,,,,,,,,,,0,5.000000e+000,5.000000e-001,2,1,5.908012e-003,0,1,0,
1473278653.896,,-7.000000e+003,9.831390e+000,-1.262795e-003,0.000000e+000,2.807194e-003,0.000000e+000,3,9.555714e-001,1.825000e+000,,,,,,,,,,,,,,,,,,0,5.000000e+000,5.000000e-001,2,1,1.343727e-003,0,1,0,
1473278794.648,,-9.000000e+003,9.825749e+000,-1.270025e-003,0.000000e+000,2.634498e-003,0.000000e+000,3,9.555997e-001,1.825000e+000,,,,,,,,,,,,,,,,,,0,5.000000e+000,5.000000e-001,2,1,5.102158e-003,0,1,0,
1473278821.076,,-9.000000e+003,9.832197e+000,-1.269762e-003,0.000000e+000,2.653176e-003,0.000000e+000,3,9.551654e-001,1.825000e+000,,,,,,,,,,,,,,,,,,0,5.000000e+000,5.000000e-001,2,1,2.698898e-004,0,1,0,
1473278958.212,,-1.000000e+004,9.825749e+000,-1.273019e-003,0.000000e+000,2.609408e-003,0.000000e+000,3,9.552425e-001,1.825000e+000,,,,,,,,,,,,,,,,,,0,5.000000e+000,5.000000e-001,2,1,5.102158e-003,0,1,0,
1473278983.249,,-1.000000e+004,9.831929e+000,-1.273093e-003,0.000000e+000,2.653684e-003,0.000000e+000,3,9.551039e-001,1.825000e+000,,,,,,,,,,,,,,,,,,0,5.000000e+000,5.000000e-001,2,1,8.068085e-004,0,1,0,
1473279162.476,,-2.000000e+004,9.825211e+000,-1.291001e-003,0.000000e+000,4.057120e-003,0.000000e+000,3,9.558712e-001,1.825000e+000,,,,,,,,,,,,,,,,,,0,5.000000e+000,5.000000e-001,2,1,2.951622e-003,0,1,0,
1473279189.905,,-2.000000e+004,9.832064e+000,-1.290314e-003,0.000000e+000,3.309840e-003,0.000000e+000,3,9.550998e-001,1.825000e+000,,,,,,,,,,,,,,,,,,0,5.000000e+000,5.000000e-001,2,1,2.152443e-003,0,1,0,
1473279365.353,,-3.000000e+004,9.826153e+000,-1.299813e-003,0.000000e+000,3.952815e-003,0.000000e+000,3,9.545164e-001,1.825000e+000,,,,,,,,,,,,,,,,,,0,5.000000e+000,5.000000e-001,2,1,4.834175e-003,0,1,0,
1473279390.804,,-3.000000e+004,9.831795e+000,-1.300042e-003,0.000000e+000,4.028913e-003,0.000000e+000,3,9.539665e-001,1.825000e+000,,,,,,,,,,,,,,,,,,0,5.000000e+000,5.000000e-001,2,1,5.369186e-004,0,1,0,
1473279569.497,,-4.000000e+004,9.825614e+000,-1.304351e-003,0.000000e+000,4.959865e-003,0.000000e+000,3,9.538454e-001,1.825000e+000,,,,,,,,,,,,,,,,,,0,5.000000e+000,5.000000e-001,2,1,3.221512e-003,0,1,0,
1473279592.952,,-4.000000e+004,9.832333e+000,-1.303702e-003,0.000000e+000,4.436895e-003,0.000000e+000,3,9.556727e-001,1.825000e+000,,,,,,,,,,,,,,,,,,0,5.000000e+000,5.000000e-001,2,1,0.000000e+000,0,1,0,
1473279771.457,,-5.000000e+004,9.825346e+000,-1.305462e-003,0.000000e+000,5.792073e-003,0.000000e+000,3,9.541240e-001,1.825000e+000,,,,,,,,,,,,,,,,,,0,5.000000e+000,5.000000e-001,2,1,5.370140e-003,0,1,0,
1473279797.415,,-5.000000e+004,9.832064e+000,-1.305059e-003,0.000000e+000,5.280793e-003,0.000000e+000,3,9.544117e-001,1.825000e+000,,,,,,,,,,,,,,,,,,0,5.000000e+000,5.000000e-001,2,1,1.075745e-003,0,1,0,
1473279979.175,,-6.000000e+004,9.824675e+000,-1.302861e-003,0.000000e+000,6.097802e-003,0.000000e+000,3,9.536594e-001,1.825000e+000,,,,,,,,,,,,,,,,,,0,5.000000e+000,5.000000e-001,2,1,3.489494e-003,0,1,0,
1473280005.382,,-6.000000e+004,9.832736e+000,-1.304363e-003,0.000000e+000,5.360869e-003,0.000000e+000,3,9.542114e-001,1.825000e+000,,,,,,,,,,,,,,,,,,0,5.000000e+000,5.000000e-001,2,1,1.882553e-003,0,1,0,
1473280182.075,,-7.000000e+004,9.825749e+000,-1.298754e-003,0.000000e+000,6.120976e-003,0.000000e+000,3,9.532810e-001,1.825000e+000,,,,,,,,,,,,,,,,,,0,5.000000e+000,5.000000e-001,2,1,6.175995e-003,0,1,0,
1473280209.012,,-7.000000e+004,9.833408e+000,-1.297935e-003,0.000000e+000,6.209991e-003,0.000000e+000,3,9.532511e-001,1.825000e+000,,,,,,,,,,,,,,,,,,0,5.000000e+000,5.000000e-001,2,1,5.369186e-004,0,1,0,
1473280396.254,,-6.000000e+004,9.826420e+000,-1.303438e-003,0.000000e+000,5.377398e-003,0.000000e+000,3,9.534962e-001,1.825000e+000,,,,,,,,,,,,,,,,,,0,5.000000e+000,5.000000e-001,2,1,4.834175e-003,0,1,0,
1473280421.982,,-6.000000e+004,9.833139e+000,-1.302954e-003,0.000000e+000,5.103108e-003,0.000000e+000,3,9.534715e-001,1.825000e+000,,,,,,,,,,,,,,,,,,0,5.000000e+000,5.000000e-001,2,1,5.388260e-004,0,1,0,
1473280596.679,,-5.000000e+004,9.825480e+000,-1.304428e-003,0.000000e+000,4.993394e-003,0.000000e+000,3,9.545245e-001,1.825000e+000,,,,,,,,,,,,,,,,,,0,5.000000e+000,5.000000e-001,2,1,3.489494e-003,0,1,0,
1473280621.857,,-5.000000e+004,9.833005e+000,-1.304009e-003,0.000000e+000,4.408532e-003,0.000000e+000,3,9.536480e-001,1.825000e+000,,,,,,,,,,,,,,,,,,0,5.000000e+000,5.000000e-001,2,1,2.708435e-004,0,1,0,
1473280802.580,,-4.000000e+004,9.826153e+000,-1.303645e-003,0.000000e+000,3.580062e-003,0.000000e+000,3,9.551273e-001,1.825000e+000,,,,,,,,,,,,,,,,,,0,5.000000e+000,5.000000e-001,2,1,4.834175e-003,0,1,0,
1473280830.031,,-4.000000e+004,9.832333e+000,-1.303548e-003,0.000000e+000,3.553456e-003,0.000000e+000,3,9.547260e-001,1.825000e+000,,,,,,,,,,,,,,,,,,0,5.000000e+000,5.000000e-001,2,1,5.388260e-004,0,1,0,
1473281004.979,,-3.000000e+004,9.826421e+000,-1.301003e-003,0.000000e+000,2.796949e-003,0.000000e+000,3,9.546832e-001,1.825000e+000,,,,,,,,,,,,,,,,,,0,5.000000e+000,5.000000e-001,2,1,5.371094e-003,0,1,0,
1473281030.407,,-3.000000e+004,9.832602e+000,-1.299698e-003,0.000000e+000,2.688603e-003,0.000000e+000,3,9.550567e-001,1.825000e+000,,,,,,,,,,,,,,,,,,0,5.000000e+000,5.000000e-001,2,1,0.000000e+000,0,1,0,
1473281203.856,,-2.000000e+004,9.826554e+000,-1.291742e-003,0.000000e+000,2.527254e-003,0.000000e+000,3,9.551659e-001,1.825000e+000,,,,,,,,,,,,,,,,,,0,5.000000e+000,5.000000e-001,2,1,4.566193e-003,0,1,0,
1473281230.218,,-2.000000e+004,9.832333e+000,-1.291636e-003,0.000000e+000,2.146893e-003,0.000000e+000,3,9.559218e-001,1.825000e+000,,,,,,,,,,,,,,,,,,0,5.000000e+000,5.000000e-001,2,1,0.000000e+000,0,1,0,
1473281402.056,,-1.000000e+004,9.826689e+000,-1.273955e-003,0.000000e+000,1.828972e-003,0.000000e+000,3,9.556507e-001,1.825000e+000,,,,,,,,,,,,,,,,,,0,5.000000e+000,5.000000e-001,2,1,5.371094e-003,0,1,0,
1473281427.293,,-1.000000e+004,9.833408e+000,-1.273287e-003,0.000000e+000,1.895013e-003,0.000000e+000,3,9.555477e-001,1.825000e+000,,,,,,,,,,,,,,,,,,0,5.000000e+000,5.000000e-001,2,1,0.000000e+000,0,1,0,
1473281562.919,,-9.000000e+003,9.826153e+000,-1.271169e-003,0.000000e+000,2.064986e-003,0.000000e+000,3,9.549128e-001,1.825000e+000,,,,,,,,,,,,,,,,,,0,5.000000e+000,5.000000e-001,2,1,5.908012e-003,0,1,0,
1473281591.245,,-9.000000e+003,9.832064e+000,-1.270923e-003,0.000000e+000,2.019789e-003,0.000000e+000,3,9.554209e-001,1.825000e+000,,,,,,,,,,,,,,,,,,0,5.000000e+000,5.000000e-001,2,1,5.378723e-004,0,1,0,
1473281730.968,,-7.000000e+003,9.826421e+000,-1.264497e-003,0.000000e+000,1.976003e-003,0.000000e+000,3,9.556329e-001,1.825000e+000,,,,,,,,,,,,,,,,,,0,5.000000e+000,5.000000e-001,2,1,5.371094e-003,0,1,0,
1473281755.444,,-7.000000e+003,9.833275e+000,-1.263406e-003,0.000000e+000,2.023725e-003,0.000000e+000,3,9.556236e-001,1.825000e+000,,,,,,,,,,,,,,,,,,0,5.000000e+000,5.000000e-001,2,1,2.679825e-004,0,1,0,
1473281889.383,,-5.000000e+003,9.826421e+000,-1.255560e-003,0.000000e+000,1.690940e-003,0.000000e+000,3,9.558600e-001,1.825000e+000,,,,,,,,,,,,,,,,,,0,5.000000e+000,5.000000e-001,2,1,5.371094e-003,0,1,0,
1473281915.080,,-5.000000e+003,9.833542e+000,-1.254876e-003,0.000000e+000,1.813201e-003,0.000000e+000,3,9.559953e-001,1.825000e+000,,,,,,,,,,,,,,,,,,0,5.000000e+000,5.000000e-001,2,1,1.345634e-003,0,1,0,
1473282052.269,,-3.000000e+003,9.824406e+000,-1.240652e-003,0.000000e+000,1.897382e-003,0.000000e+000,3,9.570225e-001,1.825000e+000,,,,,,,,,,,,,,,,,,0,5.000000e+000,5.000000e-001,2,1,3.489494e-003,0,1,0,
1473282077.451,,-3.000000e+003,9.831928e+000,-1.240798e-003,0.000000e+000,2.033125e-003,0.000000e+000,3,9.567506e-001,1.825000e+000,,,,,,,,,,,,,,,,,,0,5.000000e+000,5.000000e-001,2,1,2.679825e-004,0,1,0,
1473282215.141,,-1.000000e+003,9.825884e+000,-1.205951e-003,0.000000e+000,3.391261e-003,0.000000e+000,3,9.637071e-001,1.825000e+000,,,,,,,,,,,,,,,,,,0,5.000000e+000,5.000000e-001,2,1,4.296303e-003,0,1,0,
1473282242.069,,-1.000000e+003,9.833677e+000,-1.205777e-003,0.000000e+000,3.340143e-003,0.000000e+000,3,9.636353e-001,1.825000e+000,,,,,,,,,,,,,,,,,,0,5.000000e+000,5.000000e-001,2,1,1.074791e-003,0,1,0,
1473282381.534,,-7.000000e+002,9.826017e+000,-1.194054e-003,0.000000e+000,4.501943e-003,0.000000e+000,3,9.660339e-001,1.825000e+000,,,,,,,,,,,,,,,,,,0,5.000000e+000,5.000000e-001,2,1,5.103111e-003,0,1,0,
1473282409.213,,-7.000000e+002,9.833005e+000,-1.192710e-003,0.000000e+000,4.009178e-003,0.000000e+000,3,9.665139e-001,1.825000e+000,,,,,,,,,,,,,,,,,,0,5.000000e+000,5.000000e-001,2,1,8.068085e-004,0,1,0,
1473282546.212,,-6.000000e+002,9.826017e+000,-1.186832e-003,0.000000e+000,4.732065e-003,0.000000e+000,3,9.681864e-001,1.825000e+000,,,,,,,,,,,,,,,,,,0,5.000000e+000,5.000000e-001,2,1,5.639076e-003,0,1,0,
1473282571.946,,-6.000000e+002,9.832870e+000,-1.186965e-003,0.000000e+000,3.857486e-003,0.000000e+000,3,9.683825e-001,1.825000e+000,,,,,,,,,,,,,,,,,,0,5.000000e+000,5.000000e-001,2,1,5.388260e-004,0,1,0,
1473282707.139,,-5.000000e+002,9.825615e+000,-1.179964e-003,0.000000e+000,4.290039e-003,0.000000e+000,3,9.705954e-001,1.825000e+000,,,,,,,,,,,,,,,,,,0,5.000000e+000,5.000000e-001,2,1,6.443977e-003,0,1,0,
1473282732.067,,-5.000000e+002,9.833005e+000,-1.179991e-003,0.000000e+000,4.271407e-003,0.000000e+000,3,9.704155e-001,1.825000e+000,,,,,,,,,,,,,,,,,,0,5.000000e+000,5.000000e-001,2,1,2.708435e-004,0,1,0,
1473282865.507,,-4.000000e+002,9.825884e+000,-1.170852e-003,0.000000e+000,4.198126e-003,0.000000e+000,3,9.729130e-001,1.825000e+000,,,,,,,,,,,,,,,,,,0,5.000000e+000,5.000000e-001,2,1,5.908012e-003,0,1,0,
1473282892.685,,-4.000000e+002,9.832737e+000,-1.170827e-003,0.000000e+000,4.570768e-003,0.000000e+000,3,9.721509e-001,1.825000e+000,,,,,,,,,,,,,,,,,,0,5.000000e+000,5.000000e-001,2,1,8.077621e-004,0,1,0,
1473283025.379,,-3.000000e+002,9.825077e+000,-1.157666e-003,0.000000e+000,4.913113e-003,0.000000e+000,3,9.748424e-001,1.825000e+000,,,,,,,,,,,,,,,,,,0,5.000000e+000,5.000000e-001,2,1,3.220558e-003,0,1,0,
1473283050.619,,-3.000000e+002,9.833273e+000,-1.157712e-003,0.000000e+000,4.918504e-003,0.000000e+000,3,9.742706e-001,1.825000e+000,,,,,,,,,,,,,,,,,,0,5.000000e+000,5.000000e-001,2,1,8.077621e-004,0,1,0,
1473283184.614,,-2.000000e+002,9.825481e+000,-1.138362e-003,0.000000e+000,4.900227e-003,0.000000e+000,3,9.777335e-001,1.825000e+000,,,,,,,,,,,,,,,,,,0,5.000000e+000,5.000000e-001,2,1,5.639076e-003,0,1,0,
1473283209.301,,-2.000000e+002,9.833542e+000,-1.138539e-003,0.000000e+000,4.961015e-003,0.000000e+000,3,9.773132e-001,1.825000e+000,,,,,,,,,,,,,,,,,,0,5.000000e+000,5.000000e-001,2,1,1.345634e-003,0,1,0,
1473283331.993,,-1.800000e+002,9.825346e+000,-1.132397e-003,0.000000e+000,5.286983e-003,0.000000e+000,3,9.776856e-001,1.825000e+000,,,,,,,,,,,,,,,,,,0,5.000000e+000,5.000000e-001,2,1,4.832268e-003,0,1,0,
1473283355.951,,-1.800000e+002,9.833005e+000,-1.132480e-003,0.000000e+000,5.352324e-003,0.000000e+000,3,9.778706e-001,1.825000e+000,,,,,,,,,,,,,,,,,,0,5.000000e+000,5.000000e-001,2,1,1.344681e-003,0,1,0,
1473283478.944,,-1.600000e+002,9.825347e+000,-1.126762e-003,0.000000e+000,5.169192e-003,0.000000e+000,3,9.781222e-001,1.825000e+000,,,,,,,,,,,,,,,,,,0,5.000000e+000,5.000000e-001,2,1,5.907059e-003,0,1,0,
1473283506.176,,-1.600000e+002,9.832197e+000,-1.126604e-003,0.000000e+000,5.245866e-003,0.000000e+000,3,9.787090e-001,1.825000e+000,,,,,,,,,,,,,,,,,,0,5.000000e+000,5.000000e-001,2,1,1.343727e-003,0,1,0,
1473283627.618,,-1.400000e+002,9.825615e+000,-1.119410e-003,0.000000e+000,5.942611e-003,0.000000e+000,3,9.785715e-001,1.825000e+000,,,,,,,,,,,,,,,,,,0,5.000000e+000,5.000000e-001,2,1,5.908012e-003,0,1,0,
1473283653.350,,-1.400000e+002,9.832870e+000,-1.119692e-003,0.000000e+000,5.601821e-003,0.000000e+000,3,9.785190e-001,1.825000e+000,,,,,,,,,,,,,,,,,,0,5.000000e+000,5.000000e-001,2,1,5.388260e-004,0,1,0,
1473283775.067,,-1.200000e+002,9.824003e+000,-1.112280e-003,0.000000e+000,5.867548e-003,0.000000e+000,3,9.798080e-001,1.825000e+000,,,,,,,,,,,,,,,,,,0,5.000000e+000,5.000000e-001,2,1,4.831314e-003,0,1,0,
1473283801.279,,-1.200000e+002,9.832064e+000,-1.110947e-003,0.000000e+000,6.061442e-003,0.000000e+000,3,9.795474e-001,1.825000e+000,,,,,,,,,,,,,,,,,,0,5.000000e+000,5.000000e-001,2,1,1.612663e-003,0,1,0,
1473283928.777,,-1.000000e+002,9.825615e+000,-1.103869e-003,0.000000e+000,5.699167e-003,0.000000e+000,3,9.802147e-001,1.825000e+000,,,,,,,,,,,,,,,,,,0,5.000000e+000,5.000000e-001,2,1,6.982803e-003,0,1,0,
1473283956.249,,-1.000000e+002,9.833139e+000,-1.103018e-003,0.000000e+000,6.148720e-003,0.000000e+000,3,9.802613e-001,1.825000e+000,,,,,,,,,,,,,,,,,,0,5.000000e+000,5.000000e-001,2,1,5.388260e-004,0,1,0,
1473284075.937,,-8.000000e+001,9.825077e+000,-1.094238e-003,0.000000e+000,5.849045e-003,0.000000e+000,3,9.805461e-001,1.825000e+000,,,,,,,,,,,,,,,,,,0,5.000000e+000,5.000000e-001,2,1,5.908012e-003,0,1,0,
1473284100.365,,-8.000000e+001,9.832198e+000,-1.093613e-003,0.000000e+000,5.680932e-003,0.000000e+000,3,9.812269e-001,1.825000e+000,,,,,,,,,,,,,,,,,,0,5.000000e+000,5.000000e-001,2,1,8.068085e-004,0,1,0,
1473284221.557,,-6.000000e+001,9.825481e+000,-1.082518e-003,0.000000e+000,6.078398e-003,0.000000e+000,3,9.815548e-001,1.825000e+000,,,,,,,,,,,,,,,,,,0,5.000000e+000,5.000000e-001,2,1,5.639076e-003,0,1,0,
1473284247.486,,-6.000000e+001,9.832737e+000,-1.081596e-003,0.000000e+000,5.772310e-003,0.000000e+000,3,9.817742e-001,1.825000e+000,,,,,,,,,,,,,,,,,,0,5.000000e+000,5.000000e-001,2,1,8.077621e-004,0,1,0,
1473284372.674,,-4.000000e+001,9.824406e+000,-1.067193e-003,0.000000e+000,5.690024e-003,0.000000e+000,3,9.828576e-001,1.825000e+000,,,,,,,,,,,,,,,,,,0,5.000000e+000,5.000000e-001,2,1,3.489494e-003,0,1,0,
1473284399.357,,-4.000000e+001,9.831795e+000,-1.067666e-003,0.000000e+000,5.996556e-003,0.000000e+000,3,9.826258e-001,1.825000e+000,,,,,,,,,,,,,,,,,,0,5.000000e+000,5.000000e-001,2,1,5.369186e-004,0,1,0,
1473284522.049,,-2.000000e+001,9.824808e+000,-1.051059e-003,0.000000e+000,5.674044e-003,0.000000e+000,3,9.830012e-001,1.825000e+000,,,,,,,,,,,,,,,,,,0,5.000000e+000,5.000000e-001,2,1,5.906105e-003,0,1,0,
1473284548.536,,-2.000000e+001,9.831391e+000,-1.050698e-003,0.000000e+000,6.431871e-003,0.000000e+000,3,9.825311e-001,1.825000e+000,,,,,,,,,,,,,,,,,,0,5.000000e+000,5.000000e-001,2,1,2.689362e-004,0,1,0,
1473284670.474,,0.000000e+000,9.825077e+000,-1.028208e-003,0.000000e+000,6.306616e-003,0.000000e+000,3,9.835889e-001,1.825000e+000,,,,,,,,,,,,,,,,,,0,5.000000e+000,5.000000e-001,2,1,5.908012e-003,0,1,0,
1473284697.403,,0.000000e+000,9.831929e+000,-1.027564e-003,0.000000e+000,6.449156e-003,0.000000e+000,3,9.831569e-001,1.825000e+000,,,,,,,,,,,,,,,,,,0,5.000000e+000,5.000000e-001,2,1,8.068085e-004,0,1,0,
1473284824.166,,2.000000e+001,9.824944e+000,-9.975376e-004,0.000000e+000,6.468589e-003,0.000000e+000,3,9.843366e-001,1.825000e+000,,,,,,,,,,,,,,,,,,0,5.000000e+000,5.000000e-001,2,1,6.175995e-003,0,1,0,
1473284850.789,,2.000000e+001,9.831795e+000,-9.970582e-004,0.000000e+000,6.324418e-003,0.000000e+000,3,9.839625e-001,1.825000e+000,,,,,,,,,,,,,,,,,,0,5.000000e+000,5.000000e-001,2,1,1.075745e-003,0,1,0,
1473284970.787,,4.000000e+001,9.824540e+000,-9.555711e-004,0.000000e+000,6.212810e-003,0.000000e+000,3,9.845387e-001,1.825000e+000,,,,,,,,,,,,,,,,,,0,5.000000e+000,5.000000e-001,2,1,5.369186e-003,0,1,0,
1473284996.842,,4.000000e+001,9.831391e+000,-9.551618e-004,0.000000e+000,6.699909e-003,0.000000e+000,3,9.843671e-001,1.825000e+000,,,,,,,,,,,,,,,,,,0,5.000000e+000,5.000000e-001,2,1,8.068085e-004,0,1,0,
1473285118.045,,6.000000e+001,9.823734e+000,-8.815256e-004,0.000000e+000,6.894393e-003,0.000000e+000,3,9.851352e-001,1.825000e+000,,,,,,,,,,,,,,,,,,0,5.000000e+000,5.000000e-001,2,1,4.294395e-003,0,1,0,
1473285144.303,,6.000000e+001,9.832064e+000,-8.793629e-004,0.000000e+000,6.661231e-003,0.000000e+000,3,9.851562e-001,1.825000e+000,,,,,,,,,,,,,,,,,,0,5.000000e+000,5.000000e-001,2,1,1.075745e-003,0,1,0,
1473285265.688,,8.000000e+001,9.824675e+000,-4.501391e-004,0.000000e+000,8.202875e-003,0.000000e+000,3,9.858915e-001,1.825000e+000,,,,,,,,,,,,,,,,,,0,5.000000e+000,5.000000e-001,2,1,5.637169e-003,0,1,0,
1473285291.407,,8.000000e+001,9.831795e+000,-4.192685e-004,0.000000e+000,8.315090e-003,0.000000e+000,3,9.856541e-001,1.825000e+000,,,,,,,,,,,,,,,,,,0,5.000000e+000,5.000000e-001,2,1,2.150536e-003,0,1,0,
1473285421.244,,1.000000e+002,9.828972e+000,3.875771e-004,0.000000e+000,2.513481e-003,0.000000e+000,3,9.731026e-001,1.825000e+000,,,,,,,,,,,,,,,,,,0,5.000000e+000,5.000000e-001,2,1,4.031181e-003,0,1,0,
1473285445.173,,1.000000e+002,9.832063e+000,3.923062e-004,0.000000e+000,3.683635e-003,0.000000e+000,3,9.724845e-001,1.825000e+000,,,,,,,,,,,,,,,,,,0,5.000000e+000,5.000000e-001,2,1,0.000000e+000,0,1,0,
1473285566.159,,1.200000e+002,9.824540e+000,5.223667e-004,0.000000e+000,3.888076e-003,0.000000e+000,3,9.732380e-001,1.825000e+000,,,,,,,,,,,,,,,,,,0,5.000000e+000,5.000000e-001,2,1,5.369186e-003,0,1,0,
1473285592.588,,1.200000e+002,9.831659e+000,5.259005e-004,0.000000e+000,4.125454e-003,0.000000e+000,3,9.737738e-001,1.825000e+000,,,,,,,,,,,,,,,,,,0,5.000000e+000,5.000000e-001,2,1,8.058548e-004,0,1,0,
1473285711.601,,1.400000e+002,9.822527e+000,6.075475e-004,0.000000e+000,4.369061e-003,0.000000e+000,3,9.731975e-001,1.825000e+000,,,,,,,,,,,,,,,,,,0,5.000000e+000,5.000000e-001,2,1,5.097389e-003,0,1,0,
1473285737.476,,1.400000e+002,9.832737e+000,6.109736e-004,0.000000e+000,4.431001e-003,0.000000e+000,3,9.738224e-001,1.825000e+000,,,,,,,,,,,,,,,,,,0,5.000000e+000,5.000000e-001,2,1,4.034996e-003,0,1,0,
1473285860.272,,1.600000e+002,9.831123e+000,6.757030e-004,0.000000e+000,5.053462e-003,0.000000e+000,3,9.737934e-001,1.825000e+000,,,,,,,,,,,,,,,,,,0,5.000000e+000,5.000000e-001,2,1,5.645752e-003,0,1,0,
1473285886.701,,1.600000e+002,9.838522e+000,6.794233e-004,0.000000e+000,4.706810e-003,0.000000e+000,3,9.740462e-001,1.825000e+000,,,,,,,,,,,,,,,,,,0,5.000000e+000,5.000000e-001,2,1,1.077652e-003,0,1,0,
1473286016.129,,1.800000e+002,9.832468e+000,7.361017e-004,0.000000e+000,4.931125e-003,0.000000e+000,3,9.740246e-001,1.825000e+000,,,,,,,,,,,,,,,,,,0,5.000000e+000,5.000000e-001,2,1,5.648613e-003,0,1,0,
1473286042.415,,1.800000e+002,9.839734e+000,7.382170e-004,0.000000e+000,5.047362e-003,0.000000e+000,3,9.744540e-001,1.825000e+000,,,,,,,,,,,,,,,,,,0,5.000000e+000,5.000000e-001,2,1,2.689362e-004,0,1,0,
1473286164.856,,2.000000e+002,9.834755e+000,7.852595e-004,0.000000e+000,5.354386e-003,0.000000e+000,3,9.743826e-001,1.825000e+000,,,,,,,,,,,,,,,,,,0,5.000000e+000,5.000000e-001,2,1,5.920410e-003,0,1,0,
1473286190.284,,2.000000e+002,9.842023e+000,7.885233e-004,0.000000e+000,5.306480e-003,0.000000e+000,3,9.741764e-001,1.825000e+000,,,,,,,,,,,,,,,,,,0,5.000000e+000,5.000000e-001,2,1,1.077652e-003,0,1,0,
1473286324.267,,3.000000e+002,9.816359e+000,9.549500e-004,0.000000e+000,5.584916e-003,0.000000e+000,3,9.722457e-001,1.825000e+000,,,,,,,,,,,,,,,,,,0,5.000000e+000,5.000000e-001,2,1,3.485680e-003,0,0,0,
1473286349.445,,3.000000e+002,9.821051e+000,9.568878e-004,0.000000e+000,5.649616e-003,0.000000e+000,3,9.731575e-001,1.825000e+000,,,,,,,,,,,,,,,,,,0,5.000000e+000,5.000000e-001,2,1,0.000000e+000,0,0,0,
1473286492.132,,4.000000e+002,9.812071e+000,1.042188e-003,0.000000e+000,5.402842e-003,0.000000e+000,3,9.706273e-001,1.825000e+000,,,,,,,,,,,,,,,,,,0,5.000000e+000,5.000000e-001,2,1,4.553795e-003,0,0,0,
1473286519.855,,4.000000e+002,9.817832e+000,1.044682e-003,0.000000e+000,5.492949e-003,0.000000e+000,3,9.704989e-001,1.825000e+000,,,,,,,,,,,,,,,,,,0,5.000000e+000,5.000000e-001,2,1,5.378723e-004,0,0,0,
1473286656.106,,5.000000e+002,9.809259e+000,1.092757e-003,0.000000e+000,5.321212e-003,0.000000e+000,3,9.688351e-001,1.825000e+000,,,,,,,,,,,,,,,,,,0,5.000000e+000,5.000000e-001,2,1,5.888939e-003,0,1,0,
1473286681.534,,5.000000e+002,9.831795e+000,1.092794e-003,0.000000e+000,5.553184e-003,0.000000e+000,3,9.690428e-001,1.825000e+000,,,,,,,,,,,,,,,,,,0,5.000000e+000,5.000000e-001,2,1,2.690315e-003,0,1,0,
1473286807.973,,6.000000e+002,9.840273e+000,1.120957e-003,0.000000e+000,6.055875e-003,0.000000e+000,3,9.666316e-001,1.825000e+000,,,,,,,,,,,,,,,,,,0,5.000000e+000,5.000000e-001,2,1,4.578590e-003,0,1,0,
1473286834.671,,6.000000e+002,9.845662e+000,1.105953e-003,0.000000e+000,1.526620e-002,0.000000e+000,3,9.108236e-001,1.825000e+000,,,,,,,,,,,,,,,,,,0,5.000000e+000,5.000000e-001,2,1,2.708435e-004,0,1,0,
1473286967.613,,7.000000e+002,9.816626e+000,1.142472e-003,0.000000e+000,5.541637e-003,0.000000e+000,3,9.665467e-001,1.825000e+000,,,,,,,,,,,,,,,,,,0,5.000000e+000,5.000000e-001,2,1,4.021645e-003,0,0,0,
1473286992.041,,7.000000e+002,9.822661e+000,1.142584e-003,0.000000e+000,5.379917e-003,0.000000e+000,3,9.658789e-001,1.825000e+000,,,,,,,,,,,,,,,,,,0,5.000000e+000,5.000000e-001,2,1,5.359650e-004,0,0,0,
1473287116.730,,1.000000e+003,9.813946e+000,1.174172e-003,0.000000e+000,5.085432e-003,0.000000e+000,3,9.630098e-001,1.825000e+000,,,,,,,,,,,,,,,,,,0,5.000000e+000,5.000000e-001,2,1,5.625725e-003,0,0,0,
1473287141.408,,1.000000e+003,9.819038e+000,1.174311e-003,0.000000e+000,5.155189e-003,0.000000e+000,3,9.630923e-001,1.825000e+000,,,,,,,,,,,,,,,,,,0,5.000000e+000,5.000000e-001,2,1,8.039474e-004,0,0,0,
1473287278.362,,3.000000e+003,9.810999e+000,1.235651e-003,0.000000e+000,4.085191e-003,0.000000e+000,3,9.571347e-001,1.825000e+000,,,,,,,,,,,,,,,,,,0,5.000000e+000,5.000000e-001,2,1,3.480911e-003,0,0,0,
1473287304.791,,3.000000e+003,9.817832e+000,1.234181e-003,0.000000e+000,3.994985e-003,0.000000e+000,3,9.566342e-001,1.825000e+000,,,,,,,,,,,,,,,,,,0,5.000000e+000,5.000000e-001,2,1,0.000000e+000,0,1,0,
1473287443.237,,5.000000e+003,9.843776e+000,1.252797e-003,0.000000e+000,3.929347e-003,0.000000e+000,3,9.557033e-001,1.825000e+000,,,,,,,,,,,,,,,,,,0,5.000000e+000,5.000000e-001,2,1,4.583359e-003,0,1,0,
1473287475.711,,5.000000e+003,9.833036e+000,1.252884e-003,0.000000e+000,4.008332e-003,0.000000e+000,3,9.557825e-001,1.825000e+000,,,,,,,,,,,,,,,,,,0,5.000000e+000,5.000000e-001,2,1,3.523540e-002,0,1,0,
1473287613.149,,7.000000e+003,9.805244e+000,1.263708e-003,0.000000e+000,4.020452e-003,0.000000e+000,3,9.555176e-001,1.825000e+000,,,,,,,,,,,,,,,,,,0,5.000000e+000,5.000000e-001,2,1,4.815102e-003,0,1,0,
1473287638.328,,7.000000e+003,9.812605e+000,1.263491e-003,0.000000e+000,4.049598e-003,0.000000e+000,3,9.555010e-001,1.825000e+000,,,,,,,,,,,,,,,,,,0,5.000000e+000,5.000000e-001,2,1,2.409935e-003,0,0,0,
1473287767.344,,9.000000e+003,9.785492e+000,1.270809e-003,0.000000e+000,4.160254e-003,0.000000e+000,3,9.556811e-001,1.825000e+000,,,,,,,,,,,,,,,,,,0,5.000000e+000,5.000000e-001,2,1,4.263878e-003,0,0,0,
1473287791.309,,9.000000e+003,9.792957e+000,1.270926e-003,0.000000e+000,4.110893e-003,0.000000e+000,3,9.556491e-001,1.825000e+000,,,,,,,,,,,,,,,,,,0,5.000000e+000,5.000000e-001,2,1,1.069069e-003,0,0,0,
1473287924.749,,1.000000e+004,9.782030e+000,1.274637e-003,0.000000e+000,4.588831e-003,0.000000e+000,3,9.551981e-001,1.825000e+000,,,,,,,,,,,,,,,,,,0,5.000000e+000,5.000000e-001,2,1,5.324364e-003,0,0,0,
1473287951.451,,1.000000e+004,9.788289e+000,1.273361e-003,0.000000e+000,4.271653e-003,0.000000e+000,3,9.555020e-001,1.825000e+000,,,,,,,,,,,,,,,,,,0,5.000000e+000,5.000000e-001,2,1,8.010864e-004,0,0,0,
1473288131.954,,2.000000e+004,9.778835e+000,1.291682e-003,0.000000e+000,5.082765e-003,0.000000e+000,3,9.553402e-001,1.825000e+000,,,,,,,,,,,,,,,,,,0,5.000000e+000,5.000000e-001,2,1,4.788399e-003,0,0,0,
1473288159.934,,2.000000e+004,9.785758e+000,1.291473e-003,0.000000e+000,5.164586e-003,0.000000e+000,3,9.548212e-001,1.825000e+000,,,,,,,,,,,,,,,,,,0,5.000000e+000,5.000000e-001,2,1,5.340576e-004,0,1,0,
1473288334.128,,3.000000e+004,9.818502e+000,1.300694e-003,0.000000e+000,5.903659e-003,0.000000e+000,3,9.549094e-001,1.825000e+000,,,,,,,,,,,,,,,,,,0,5.000000e+000,5.000000e-001,2,1,3.486633e-003,0,1,0,
1473288357.358,,3.000000e+004,9.824406e+000,1.301333e-003,0.000000e+000,5.859934e-003,0.000000e+000,3,9.549460e-001,1.825000e+000,,,,,,,,,,,,,,,,,,0,5.000000e+000,5.000000e-001,2,1,8.049011e-004,0,1,0,
1473288536.843,,4.000000e+004,9.793891e+000,1.305025e-003,0.000000e+000,6.687427e-003,0.000000e+000,3,9.544795e-001,1.825000e+000,,,,,,,,,,,,,,,,,,0,5.000000e+000,5.000000e-001,2,1,4.003525e-003,0,0,0,
1473288561.302,,4.000000e+004,9.798830e+000,1.304337e-003,0.000000e+000,6.390912e-003,0.000000e+000,3,9.547068e-001,1.825000e+000,,,,,,,,,,,,,,,,,,0,5.000000e+000,5.000000e-001,2,1,1.067162e-003,0,0,0,
1473288747.940,,5.000000e+004,9.785759e+000,1.304845e-003,0.000000e+000,6.934573e-003,0.000000e+000,3,9.543621e-001,1.825000e+000,,,,,,,,,,,,,,,,,,0,5.000000e+000,5.000000e-001,2,1,2.131462e-003,0,0,0,
1473288771.764,,5.000000e+004,9.792556e+000,1.304814e-003,0.000000e+000,6.879632e-003,0.000000e+000,3,9.543981e-001,1.825000e+000,,,,,,,,,,,,,,,,,,0,5.000000e+000,5.000000e-001,2,1,2.670288e-004,0,0,0,
1473288954.959,,6.000000e+004,9.781364e+000,1.302449e-003,0.000000e+000,7.231405e-003,0.000000e+000,3,9.536666e-001,1.825000e+000,,,,,,,,,,,,,,,,,,0,5.000000e+000,5.000000e-001,2,1,5.057335e-003,0,0,0,
1473288980.640,,6.000000e+004,9.787889e+000,1.302800e-003,0.000000e+000,7.243759e-003,0.000000e+000,3,9.538203e-001,1.825000e+000,,,,,,,,,,,,,,,,,,0,5.000000e+000,5.000000e-001,2,1,0.000000e+000,0,0,0,
1473289157.584,,7.000000e+004,9.767277e+000,1.298231e-003,0.000000e+000,8.023001e-003,0.000000e+000,3,9.530955e-001,1.825000e+000,,,,,,,,,,,,,,,,,,0,5.000000e+000,5.000000e-001,2,1,5.573273e-003,0,1,0,
1473289181.567,,7.000000e+004,9.794159e+000,1.298366e-003,0.000000e+000,8.250740e-003,0.000000e+000,3,9.531094e-001,1.825000e+000,,,,,,,,,,,,,,,,,,0,5.000000e+000,5.000000e-001,2,1,8.805275e-003,0,1,0,
1473289194.032,,7.000000e+004,9.799231e+000,1.299004e-003,0.000000e+000,8.150338e-003,0.000000e+000,3,9.534560e-001,1.825000e+000,,,,,,,,,,,,,,,,,,0,5.000000e+000,5.000000e-001,2,1,2.939224e-003,0,1,0,