File: data/A344/A344_cool_zero_field_050_160908.rso.dat
[Header]
TITLE,MPMS RSO Measurement
BYAPP,MPMS Measurement,1.1,Summary
FILEOPENTIME, 1473327917.195000 9/8/2016, 9:45:17 PM

INFO, APPNAME, MPMS MultiVu Application, Revision 1.61,  Build 082

INFO, NAME, A344
INFO, WEIGHT, 10.500
INFO, AREA, 1.000
INFO, LENGTH, 1.000
INFO, SHAPE, 0
INFO, COMMENT, m = 0.0105g
INFO, SEQUENCE FILE: cool_zero_field_magnet_reset_120K-5K.seq


INFO, BACKGROUND DATA FILE:, None


STARTUPAXIS,X,4,LINEAR,AUTO,0.000000,0.000000
STARTUPAXIS,Y1,5,LINEAR,AUTO,0.000000,0.000000


STARTUPGROUP,Longitudinal
FIELDGROUP,Longitudinal,1,2,3,4,5,6,7,8,9,10,11,19,20,21,22,23,35
FIELDGROUP,Transverse,1,2,3,4,12,13,14,15,16,17,18,24,25,26,27,28,35

PLOT_APPEARANCE,ALL,HORZ_GRID_ON,VERT_GRID_ON,MARKERS_AND_LINES

[Data]
Time,Comment,Field (Oe),Temperature (K),Long Moment (emu),Long Scan Std Dev,Long Offset (cm),Long Offset Std Dev,Long Algorithm,Long Reg Fit,Long Reg Factor,Trans Moment (emu),Trans Scan Std Dev,Trans Offset (cm),Trans Offset Std Dev,Trans Algorithm,Trans Reg Fit,Trans Reg Factor,Long Moment [w/o ABS] (emu),Long Scan Std Dev [w/o ABS],Long Offset [w/o ABS] (cm),Long Offset Std Dev [w/o ABS],Long Reg Fit [w/o ABS],Trans Moment [w/o ABS] (emu),Trans Scan Std Dev [w/o ABS],Trans Offset [w/o ABS] (cm),Trans Offset Std Dev [w/o ABS],Trans Reg Fit [w/o ABS],RSO Position (deg),Amplitude (cm),Frequency,Cycles to Average,Scans per Measurement,Delta Temp (K),Error,EC Comp. Running,Using ABS,
1473327917.176,,0.000000e+000,1.199974e+002,-1.275453e-006,0.000000e+000,1.321306e-001,0.000000e+000,3,2.096789e-001,1.825000e+000,,,,,,,,,,,,,,,,,,0,5.000000e+000,5.000000e-001,2,1,6.599426e-003,0,0,0,
1473327930.890,,0.000000e+000,1.199974e+002,-1.271870e-006,0.000000e+000,1.252706e-001,0.000000e+000,3,1.928894e-001,1.825000e+000,,,,,,,,,,,,,,,,,,0,5.000000e+000,5.000000e-001,2,1,0.000000e+000,0,0,0,
1473327943.854,,0.000000e+000,1.199958e+002,-1.269123e-006,0.000000e+000,1.319368e-001,0.000000e+000,3,2.006404e-001,1.825000e+000,,,,,,,,,,,,,,,,,,0,5.000000e+000,5.000000e-001,2,1,3.295898e-003,0,0,0,
1473327957.319,,0.000000e+000,1.199974e+002,-1.267225e-006,0.000000e+000,1.257770e-001,0.000000e+000,3,1.994243e-001,1.825000e+000,,,,,,,,,,,,,,,,,,0,5.000000e+000,5.000000e-001,2,1,6.599426e-003,0,0,0,
1473328118.302,,0.000000e+000,1.176734e+002,-1.262613e-006,0.000000e+000,1.280283e-001,0.000000e+000,3,1.929045e-001,1.825000e+000,,,,,,,,,,,,,,,,,,0,5.000000e+000,5.000000e-001,2,1,3.391037e-001,0,0,0,
1473328132.016,,0.000000e+000,1.172235e+002,-1.276138e-006,0.000000e+000,1.279138e-001,0.000000e+000,3,2.012239e-001,1.825000e+000,,,,,,,,,,,,,,,,,,0,5.000000e+000,5.000000e-001,2,1,3.837967e-001,0,0,0,
1473328146.484,,0.000000e+000,1.165905e+002,-1.275268e-006,0.000000e+000,1.250266e-001,0.000000e+000,3,2.070634e-001,1.825000e+000,,,,,,,,,,,,,,,,,,0,5.000000e+000,5.000000e-001,2,1,6.567001e-001,0,0,0,
1473328160.448,,0.000000e+000,1.158173e+002,-1.272119e-006,0.000000e+000,1.293782e-001,0.000000e+000,3,1.951074e-001,1.825000e+000,,,,,,,,,,,,,,,,,,0,5.000000e+000,5.000000e-001,2,1,6.360016e-001,0,0,0,
1473328186.342,,0.000000e+000,1.141722e+002,-1.258931e-006,0.000000e+000,1.294106e-001,0.000000e+000,3,1.837500e-001,1.825000e+000,,,,,,,,,,,,,,,,,,0,5.000000e+000,5.000000e-001,2,1,6.424026e-001,0,1,0,
1473328199.354,,0.000000e+000,1.133080e+002,-1.246290e-006,0.000000e+000,1.270657e-001,0.000000e+000,3,1.860500e-001,1.825000e+000,,,,,,,,,,,,,,,,,,0,5.000000e+000,5.000000e-001,2,1,7.299957e-001,0,1,0,
1473328212.176,,0.000000e+000,1.121966e+002,-1.238402e-006,0.000000e+000,1.246580e-001,0.000000e+000,3,1.709659e-001,1.825000e+000,,,,,,,,,,,,,,,,,,0,5.000000e+000,5.000000e-001,2,1,7.810974e-001,0,1,0,
1473328225.140,,0.000000e+000,1.112139e+002,-1.256835e-006,0.000000e+000,1.294758e-001,0.000000e+000,3,1.809484e-001,1.825000e+000,,,,,,,,,,,,,,,,,,0,5.000000e+000,5.000000e-001,2,1,8.236008e-001,0,1,0,
1473328239.105,,0.000000e+000,1.099624e+002,-1.255298e-006,0.000000e+000,1.289826e-001,0.000000e+000,3,1.978470e-001,1.825000e+000,,,,,,,,,,,,,,,,,,0,5.000000e+000,5.000000e-001,2,1,8.701019e-001,0,1,0,
1473328251.069,,0.000000e+000,1.090893e+002,-1.252614e-006,0.000000e+000,1.215541e-001,0.000000e+000,3,1.974328e-001,1.825000e+000,,,,,,,,,,,,,,,,,,0,5.000000e+000,5.000000e-001,2,1,8.761978e-001,0,1,0,
1473328264.283,,0.000000e+000,1.078459e+002,-1.239607e-006,0.000000e+000,1.280244e-001,0.000000e+000,3,1.665184e-001,1.825000e+000,,,,,,,,,,,,,,,,,,0,5.000000e+000,5.000000e-001,2,1,1.160301e+000,0,1,0,
1473328276.998,,0.000000e+000,1.065757e+002,-1.281755e-006,0.000000e+000,1.232817e-001,0.000000e+000,3,2.149508e-001,1.825000e+000,,,,,,,,,,,,,,,,,,0,5.000000e+000,5.000000e-001,2,1,9.722977e-001,0,1,0,
1473328292.465,,0.000000e+000,1.051539e+002,-1.255968e-006,0.000000e+000,1.310162e-001,0.000000e+000,3,1.802732e-001,1.825000e+000,,,,,,,,,,,,,,,,,,0,5.000000e+000,5.000000e-001,2,1,9.709930e-001,0,1,0,
1473328303.189,,0.000000e+000,1.041963e+002,-1.235373e-006,0.000000e+000,1.240471e-001,0.000000e+000,3,1.726341e-001,1.825000e+000,,,,,,,,,,,,,,,,,,0,5.000000e+000,5.000000e-001,2,1,9.443054e-001,0,1,0,
1473328318.693,,0.000000e+000,1.028399e+002,-1.290930e-006,0.000000e+000,1.213223e-001,0.000000e+000,3,2.221798e-001,1.825000e+000,,,,,,,,,,,,,,,,,,0,5.000000e+000,5.000000e-001,2,1,7.621002e-001,0,1,0,
1473328332.935,,0.000000e+000,1.013674e+002,-1.256716e-006,0.000000e+000,1.155873e-001,0.000000e+000,3,1.977222e-001,1.825000e+000,,,,,,,,,,,,,,,,,,0,5.000000e+000,5.000000e-001,2,1,1.232903e+000,0,1,0,
1473328347.650,,0.000000e+000,9.972670e+001,-1.298766e-006,0.000000e+000,1.218359e-001,0.000000e+000,3,2.185228e-001,1.825000e+000,,,,,,,,,,,,,,,,,,0,5.000000e+000,5.000000e-001,2,1,1.034805e+000,0,1,0,
1473328362.114,,0.000000e+000,9.858801e+001,-1.257374e-006,0.000000e+000,1.196570e-001,0.000000e+000,3,1.868365e-001,1.825000e+000,,,,,,,,,,,,,,,,,,0,5.000000e+000,5.000000e-001,2,1,1.242577e+000,0,1,0,
1473328375.328,,0.000000e+000,9.697696e+001,-1.242103e-006,0.000000e+000,1.230708e-001,0.000000e+000,3,1.661528e-001,1.825000e+000,,,,,,,,,,,,,,,,,,0,5.000000e+000,5.000000e-001,2,1,1.035545e+000,0,1,0,
1473328387.293,,0.000000e+000,9.597514e+001,-1.243384e-006,0.000000e+000,1.256074e-001,0.000000e+000,3,1.717004e-001,1.825000e+000,,,,,,,,,,,,,,,,,,0,5.000000e+000,5.000000e-001,2,1,9.680862e-001,0,1,0,
1473328401.007,,0.000000e+000,9.448528e+001,-1.260379e-006,0.000000e+000,1.205966e-001,0.000000e+000,3,2.094497e-001,1.825000e+000,,,,,,,,,,,,,,,,,,0,5.000000e+000,5.000000e-001,2,1,1.019264e+000,0,1,0,
1473328412.971,,0.000000e+000,9.339635e+001,-1.279683e-006,0.000000e+000,1.210733e-001,0.000000e+000,3,2.115735e-001,1.825000e+000,,,,,,,,,,,,,,,,,,0,5.000000e+000,5.000000e-001,2,1,7.336197e-001,0,1,0,
1473328426.435,,0.000000e+000,9.203815e+001,-1.251177e-006,0.000000e+000,1.233092e-001,0.000000e+000,3,1.888975e-001,1.825000e+000,,,,,,,,,,,,,,,,,,0,5.000000e+000,5.000000e-001,2,1,9.978561e-001,0,1,0,
1473328438.900,,0.000000e+000,9.105804e+001,-1.266961e-006,0.000000e+000,1.208341e-001,0.000000e+000,3,2.093002e-001,1.825000e+000,,,,,,,,,,,,,,,,,,0,5.000000e+000,5.000000e-001,2,1,9.623642e-001,0,1,0,
1473328453.661,,0.000000e+000,8.964796e+001,-1.284849e-006,0.000000e+000,1.217157e-001,0.000000e+000,3,2.226711e-001,1.825000e+000,,,,,,,,,,,,,,,,,,0,5.000000e+000,5.000000e-001,2,1,9.287949e-001,0,1,0,
1473328465.625,,0.000000e+000,8.870148e+001,-1.280738e-006,0.000000e+000,1.207552e-001,0.000000e+000,3,2.135664e-001,1.825000e+000,,,,,,,,,,,,,,,,,,0,5.000000e+000,5.000000e-001,2,1,9.641800e-001,0,1,0,
1473328478.350,,0.000000e+000,8.740655e+001,-1.243690e-006,0.000000e+000,1.226224e-001,0.000000e+000,3,1.768474e-001,1.825000e+000,,,,,,,,,,,,,,,,,,0,5.000000e+000,5.000000e-001,2,1,7.124176e-001,0,1,0,
1473328490.756,,0.000000e+000,8.648506e+001,-1.289118e-006,0.000000e+000,1.137685e-001,0.000000e+000,3,2.234547e-001,1.825000e+000,,,,,,,,,,,,,,,,,,0,5.000000e+000,5.000000e-001,2,1,6.699753e-001,0,1,0,
1473328506.579,,0.000000e+000,8.519485e+001,-1.277927e-006,0.000000e+000,1.218589e-001,0.000000e+000,3,2.122604e-001,1.825000e+000,,,,,,,,,,,,,,,,,,0,5.000000e+000,5.000000e-001,2,1,1.089371e+000,0,1,0,
1473328519.335,,0.000000e+000,8.395804e+001,-1.231893e-006,0.000000e+000,1.210742e-001,0.000000e+000,3,1.676370e-001,1.825000e+000,,,,,,,,,,,,,,,,,,0,5.000000e+000,5.000000e-001,2,1,6.067505e-001,0,1,0,
1473328532.549,,0.000000e+000,8.307091e+001,-1.222588e-006,0.000000e+000,1.241542e-001,0.000000e+000,3,1.699443e-001,1.825000e+000,,,,,,,,,,,,,,,,,,0,5.000000e+000,5.000000e-001,2,1,7.732925e-001,0,1,0,
1473328545.523,,0.000000e+000,8.213306e+001,-1.246102e-006,0.000000e+000,1.191830e-001,0.000000e+000,3,1.756382e-001,1.825000e+000,,,,,,,,,,,,,,,,,,0,5.000000e+000,5.000000e-001,2,1,7.264404e-001,0,1,0,
1473328559.533,,0.000000e+000,8.116797e+001,-1.238389e-006,0.000000e+000,1.224644e-001,0.000000e+000,3,1.788905e-001,1.825000e+000,,,,,,,,,,,,,,,,,,0,5.000000e+000,5.000000e-001,2,1,8.672714e-001,0,1,0,
1473328572.033,,0.000000e+000,8.034892e+001,-1.225930e-006,0.000000e+000,1.141020e-001,0.000000e+000,3,1.810766e-001,1.825000e+000,,,,,,,,,,,,,,,,,,0,5.000000e+000,5.000000e-001,2,1,7.708359e-001,0,1,0,
1473328589.751,,0.000000e+000,7.973637e+001,-1.253366e-006,0.000000e+000,1.194789e-001,0.000000e+000,3,1.967752e-001,1.825000e+000,,,,,,,,,,,,,,,,,,0,5.000000e+000,5.000000e-001,2,1,2.744980e-001,0,1,0,
1473328605.258,,0.000000e+000,7.959610e+001,-1.202085e-006,0.000000e+000,1.156655e-001,0.000000e+000,3,1.444046e-001,1.825000e+000,,,,,,,,,,,,,,,,,,0,5.000000e+000,5.000000e-001,2,1,9.071350e-003,0,1,0,
1473328785.489,,0.000000e+000,8.006197e+001,-1.257490e-006,0.000000e+000,1.145674e-001,0.000000e+000,3,1.958105e-001,1.825000e+000,,,,,,,,,,,,,,,,,,0,5.000000e+000,5.000000e-001,2,1,7.637024e-003,0,0,0,
1473328797.454,,0.000000e+000,8.003676e+001,-1.248908e-006,0.000000e+000,1.165867e-001,0.000000e+000,3,1.889887e-001,1.825000e+000,,,,,,,,,,,,,,,,,,0,5.000000e+000,5.000000e-001,2,1,6.095886e-003,0,0,0,
1473328810.211,,0.000000e+000,8.003828e+001,-1.233719e-006,0.000000e+000,1.211463e-001,0.000000e+000,3,1.807332e-001,1.825000e+000,,,,,,,,,,,,,,,,,,0,5.000000e+000,5.000000e-001,2,1,3.044128e-003,0,0,0,
1473328822.222,,0.000000e+000,8.003523e+001,-1.239037e-006,0.000000e+000,1.166439e-001,0.000000e+000,3,1.950162e-001,1.825000e+000,,,,,,,,,,,,,,,,,,0,5.000000e+000,5.000000e-001,2,1,3.051758e-003,0,0,0,
1473328991.456,,0.000000e+000,7.640741e+001,-1.200630e-006,0.000000e+000,1.190061e-001,0.000000e+000,3,1.682421e-001,1.825000e+000,,,,,,,,,,,,,,,,,,0,5.000000e+000,5.000000e-001,2,1,3.453598e-001,0,0,0,
1473329004.670,,0.000000e+000,7.578741e+001,-1.195466e-006,0.000000e+000,1.187789e-001,0.000000e+000,3,1.619436e-001,1.825000e+000,,,,,,,,,,,,,,,,,,0,5.000000e+000,5.000000e-001,2,1,3.839951e-001,0,0,0,
1473329017.135,,0.000000e+000,7.513397e+001,-1.173544e-006,0.000000e+000,1.139330e-001,0.000000e+000,3,1.495070e-001,1.825000e+000,,,,,,,,,,,,,,,,,,0,5.000000e+000,5.000000e-001,2,1,6.767502e-001,0,0,0,
1473329031.349,,0.000000e+000,7.421214e+001,-1.170010e-006,0.000000e+000,1.115222e-001,0.000000e+000,3,1.448292e-001,1.825000e+000,,,,,,,,,,,,,,,,,,0,5.000000e+000,5.000000e-001,2,1,5.894241e-001,0,0,0,
1473329047.121,,0.000000e+000,7.349339e+001,-1.159760e-006,0.000000e+000,1.135404e-001,0.000000e+000,3,1.425294e-001,1.825000e+000,,,,,,,,,,,,,,,,,,0,5.000000e+000,5.000000e-001,2,1,5.836258e-001,0,0,0,
1473329058.393,,0.000000e+000,7.264971e+001,-1.139792e-006,0.000000e+000,1.219429e-001,0.000000e+000,3,1.209981e-001,1.825000e+000,,,,,,,,,,,,,,,,,,0,5.000000e+000,5.000000e-001,2,1,4.680176e-001,0,0,0,
1473329071.857,,0.000000e+000,7.187183e+001,-1.097905e-006,0.000000e+000,1.214870e-001,0.000000e+000,3,9.373960e-002,1.825000e+000,,,,,,,,,,,,,,,,,,0,5.000000e+000,5.000000e-001,2,1,4.676132e-001,0,0,0,
1473329083.821,,0.000000e+000,7.133070e+001,-1.064702e-006,0.000000e+000,1.271370e-001,0.000000e+000,3,6.297928e-002,1.825000e+000,,,,,,,,,,,,,,,,,,0,5.000000e+000,5.000000e-001,2,1,6.146469e-001,0,0,0,
1473329102.036,,0.000000e+000,7.020171e+001,-9.612662e-007,0.000000e+000,1.357070e-001,0.000000e+000,3,0.000000e+000,1.825000e+000,,,,,,,,,,,,,,,,,,0,5.000000e+000,5.000000e-001,2,1,7.645874e-001,0,0,0,
1473329115.500,,0.000000e+000,6.910189e+001,-8.036211e-007,0.000000e+000,1.421172e-001,0.000000e+000,3,0.000000e+000,1.825000e+000,,,,,,,,,,,,,,,,,,0,5.000000e+000,5.000000e-001,2,1,7.987823e-001,0,0,0,
1473329127.977,,0.000000e+000,6.831268e+001,-4.819494e-007,0.000000e+000,1.189627e-001,0.000000e+000,3,0.000000e+000,1.825000e+000,,,,,,,,,,,,,,,,,,0,5.000000e+000,5.000000e-001,2,1,7.796478e-001,0,0,0,
1473329140.691,,0.000000e+000,6.754681e+001,1.089601e-006,0.000000e+000,-1.207343e+000,0.000000e+000,3,1.524927e-001,1.825000e+000,,,,,,,,,,,,,,,,,,0,5.000000e+000,5.000000e-001,2,1,7.520905e-001,0,0,0,
1473329156.155,,0.000000e+000,6.645698e+001,6.616192e-006,0.000000e+000,6.351582e-003,0.000000e+000,3,7.953066e-001,1.825000e+000,,,,,,,,,,,,,,,,,,0,5.000000e+000,5.000000e-001,2,1,7.975616e-001,0,0,0,
1473329167.922,,0.000000e+000,6.574191e+001,1.925150e-005,0.000000e+000,1.994009e-002,0.000000e+000,3,9.067534e-001,1.825000e+000,,,,,,,,,,,,,,,,,,0,5.000000e+000,5.000000e-001,2,1,6.325836e-001,0,1,0,
1473329179.386,,0.000000e+000,6.502354e+001,3.640948e-005,0.000000e+000,2.034486e-002,0.000000e+000,3,9.426628e-001,1.825000e+000,,,,,,,,,,,,,,,,,,0,5.000000e+000,5.000000e-001,2,1,8.041306e-001,0,1,0,
1473329202.608,,0.000000e+000,6.351704e+001,6.713053e-005,0.000000e+000,1.799100e-002,0.000000e+000,3,9.665030e-001,1.825000e+000,,,,,,,,,,,,,,,,,,0,5.000000e+000,5.000000e-001,2,1,6.219482e-001,0,1,0,
1473329217.334,,0.000000e+000,6.272804e+001,8.126628e-005,0.000000e+000,1.760562e-002,0.000000e+000,3,9.710559e-001,1.825000e+000,,,,,,,,,,,,,,,,,,0,5.000000e+000,5.000000e-001,2,1,9.560509e-001,0,1,0,
1473329242.522,,0.000000e+000,6.111919e+001,1.001781e-004,0.000000e+000,1.677568e-002,0.000000e+000,3,9.747016e-001,1.825000e+000,,,,,,,,,,,,,,,,,,0,5.000000e+000,5.000000e-001,2,1,7.164879e-001,0,1,0,
1473329254.986,,0.000000e+000,6.042201e+001,1.077853e-004,0.000000e+000,1.637297e-002,0.000000e+000,3,9.757527e-001,1.825000e+000,,,,,,,,,,,,,,,,,,0,5.000000e+000,5.000000e-001,2,1,6.778603e-001,0,1,0,
1473329268.701,,0.000000e+000,5.952209e+001,1.155714e-004,0.000000e+000,1.614201e-002,0.000000e+000,3,9.764593e-001,1.825000e+000,,,,,,,,,,,,,,,,,,0,5.000000e+000,5.000000e-001,2,1,5.493507e-001,0,1,0,
1473329281.915,,0.000000e+000,5.886953e+001,1.223906e-004,0.000000e+000,1.583478e-002,0.000000e+000,3,9.772630e-001,1.825000e+000,,,,,,,,,,,,,,,,,,0,5.000000e+000,5.000000e-001,2,1,5.191574e-001,0,1,0,
1473329294.629,,0.000000e+000,5.820255e+001,1.285659e-004,0.000000e+000,1.559683e-002,0.000000e+000,3,9.775183e-001,1.825000e+000,,,,,,,,,,,,,,,,,,0,5.000000e+000,5.000000e-001,2,1,5.294800e-001,0,1,0,
1473329308.547,,0.000000e+000,5.743953e+001,1.349348e-004,0.000000e+000,1.530124e-002,0.000000e+000,3,9.778541e-001,1.825000e+000,,,,,,,,,,,,,,,,,,0,5.000000e+000,5.000000e-001,2,1,4.919205e-001,0,1,0,
1473329320.119,,0.000000e+000,5.681585e+001,1.400040e-004,0.000000e+000,1.522082e-002,0.000000e+000,3,9.782549e-001,1.825000e+000,,,,,,,,,,,,,,,,,,0,5.000000e+000,5.000000e-001,2,1,4.927979e-001,0,1,0,
1473329334.333,,0.000000e+000,5.606187e+001,1.459188e-004,0.000000e+000,1.494772e-002,0.000000e+000,3,9.785458e-001,1.825000e+000,,,,,,,,,,,,,,,,,,0,5.000000e+000,5.000000e-001,2,1,4.957504e-001,0,1,0,
1473329349.048,,0.000000e+000,5.532763e+001,1.518345e-004,0.000000e+000,1.471497e-002,0.000000e+000,3,9.788653e-001,1.825000e+000,,,,,,,,,,,,,,,,,,0,5.000000e+000,5.000000e-001,2,1,4.938812e-001,0,1,0,
1473329362.512,,0.000000e+000,5.464779e+001,1.572187e-004,0.000000e+000,1.447928e-002,0.000000e+000,3,9.789352e-001,1.825000e+000,,,,,,,,,,,,,,,,,,0,5.000000e+000,5.000000e-001,2,1,6.185303e-001,0,1,0,
1473329376.476,,0.000000e+000,5.398606e+001,1.624761e-004,0.000000e+000,1.426580e-002,0.000000e+000,3,9.791349e-001,1.825000e+000,,,,,,,,,,,,,,,,,,0,5.000000e+000,5.000000e-001,2,1,4.697495e-001,0,1,0,
1473329392.968,,0.000000e+000,5.327186e+001,1.686109e-004,0.000000e+000,1.390671e-002,0.000000e+000,3,9.795209e-001,1.825000e+000,,,,,,,,,,,,,,,,,,0,5.000000e+000,5.000000e-001,2,1,4.678383e-001,0,1,0,
1473329407.978,,0.000000e+000,5.242823e+001,1.740702e-004,0.000000e+000,1.366129e-002,0.000000e+000,3,9.797087e-001,1.825000e+000,,,,,,,,,,,,,,,,,,0,5.000000e+000,5.000000e-001,2,1,4.661026e-001,0,1,0,
1473329420.942,,0.000000e+000,5.182352e+001,1.787382e-004,0.000000e+000,1.349103e-002,0.000000e+000,3,9.797738e-001,1.825000e+000,,,,,,,,,,,,,,,,,,0,5.000000e+000,5.000000e-001,2,1,4.878693e-001,0,1,0,
1473329434.406,,0.000000e+000,5.111894e+001,1.835262e-004,0.000000e+000,1.330063e-002,0.000000e+000,3,9.797696e-001,1.825000e+000,,,,,,,,,,,,,,,,,,0,5.000000e+000,5.000000e-001,2,1,4.960976e-001,0,1,0,
1473329451.371,,0.000000e+000,5.027670e+001,1.894311e-004,0.000000e+000,1.311635e-002,0.000000e+000,3,9.800090e-001,1.825000e+000,,,,,,,,,,,,,,,,,,0,5.000000e+000,5.000000e-001,2,1,4.794884e-001,0,1,0,
1473329463.878,,0.000000e+000,4.968649e+001,1.936846e-004,0.000000e+000,1.287198e-002,0.000000e+000,3,9.802316e-001,1.825000e+000,,,,,,,,,,,,,,,,,,0,5.000000e+000,5.000000e-001,2,1,4.701080e-001,0,1,0,
1473329476.898,,0.000000e+000,4.910085e+001,1.980790e-004,0.000000e+000,1.259381e-002,0.000000e+000,3,9.802750e-001,1.825000e+000,,,,,,,,,,,,,,,,,,0,5.000000e+000,5.000000e-001,2,1,4.656906e-001,0,1,0,
1473329489.865,,0.000000e+000,4.844614e+001,2.023970e-004,0.000000e+000,1.246872e-002,0.000000e+000,3,9.802897e-001,1.825000e+000,,,,,,,,,,,,,,,,,,0,5.000000e+000,5.000000e-001,2,1,6.039886e-001,0,1,0,
1473329505.579,,0.000000e+000,4.767392e+001,2.075700e-004,0.000000e+000,1.224167e-002,0.000000e+000,3,9.803535e-001,1.825000e+000,,,,,,,,,,,,,,,,,,0,5.000000e+000,5.000000e-001,2,1,4.822998e-001,0,1,0,
1473329529.008,,0.000000e+000,4.661595e+001,2.152286e-004,0.000000e+000,1.192506e-002,0.000000e+000,3,9.805967e-001,1.825000e+000,,,,,,,,,,,,,,,,,,0,5.000000e+000,5.000000e-001,2,1,4.652596e-001,0,1,0,
1473329542.472,,0.000000e+000,4.601644e+001,2.195719e-004,0.000000e+000,1.179194e-002,0.000000e+000,3,9.805860e-001,1.825000e+000,,,,,,,,,,,,,,,,,,0,5.000000e+000,5.000000e-001,2,1,4.846191e-001,0,1,0,
1473329555.186,,0.000000e+000,4.535564e+001,2.236657e-004,0.000000e+000,1.158016e-002,0.000000e+000,3,9.807163e-001,1.825000e+000,,,,,,,,,,,,,,,,,,0,5.000000e+000,5.000000e-001,2,1,6.003075e-001,0,1,0,
1473329568.700,,0.000000e+000,4.470442e+001,2.280035e-004,0.000000e+000,1.132753e-002,0.000000e+000,3,9.806714e-001,1.825000e+000,,,,,,,,,,,,,,,,,,0,5.000000e+000,5.000000e-001,2,1,4.785805e-001,0,1,0,
1473329580.925,,0.000000e+000,4.415984e+001,2.318663e-004,0.000000e+000,1.120153e-002,0.000000e+000,3,9.808138e-001,1.825000e+000,,,,,,,,,,,,,,,,,,0,5.000000e+000,5.000000e-001,2,1,6.105804e-001,0,1,0,
1473329594.389,,0.000000e+000,4.343111e+001,2.361465e-004,0.000000e+000,1.111419e-002,0.000000e+000,3,9.808416e-001,1.825000e+000,,,,,,,,,,,,,,,,,,0,5.000000e+000,5.000000e-001,2,1,6.057205e-001,0,1,0,
1473329606.604,,0.000000e+000,4.288483e+001,2.399984e-004,0.000000e+000,1.084215e-002,0.000000e+000,3,9.808751e-001,1.825000e+000,,,,,,,,,,,,,,,,,,0,5.000000e+000,5.000000e-001,2,1,4.868393e-001,0,1,0,
1473329621.568,,0.000000e+000,4.214697e+001,2.446407e-004,0.000000e+000,1.066117e-002,0.000000e+000,3,9.810103e-001,1.825000e+000,,,,,,,,,,,,,,,,,,0,5.000000e+000,5.000000e-001,2,1,4.911804e-001,0,1,0,
1473329634.282,,0.000000e+000,4.152454e+001,2.486128e-004,0.000000e+000,1.050725e-002,0.000000e+000,3,9.810435e-001,1.825000e+000,,,,,,,,,,,,,,,,,,0,5.000000e+000,5.000000e-001,2,1,4.938698e-001,0,0,0,
1473329646.747,,0.000000e+000,4.088207e+001,2.526521e-004,0.000000e+000,1.031118e-002,0.000000e+000,3,9.810452e-001,1.825000e+000,,,,,,,,,,,,,,,,,,0,5.000000e+000,5.000000e-001,2,1,5.232277e-001,0,0,0,
1473329659.142,,0.000000e+000,4.023321e+001,2.565889e-004,0.000000e+000,1.012962e-002,0.000000e+000,3,9.811540e-001,1.825000e+000,,,,,,,,,,,,,,,,,,0,5.000000e+000,5.000000e-001,2,1,5.098381e-001,0,0,0,
1473329676.715,,0.000000e+000,3.933969e+001,2.619869e-004,0.000000e+000,9.873728e-003,0.000000e+000,3,9.811809e-001,1.825000e+000,,,,,,,,,,,,,,,,,,0,5.000000e+000,5.000000e-001,2,1,5.181389e-001,0,0,0,
1473329690.707,,0.000000e+000,3.861270e+001,2.663848e-004,0.000000e+000,9.731159e-003,0.000000e+000,3,9.812636e-001,1.825000e+000,,,,,,,,,,,,,,,,,,0,5.000000e+000,5.000000e-001,2,1,4.060020e-001,0,0,0,
1473329703.421,,0.000000e+000,3.793221e+001,2.703450e-004,0.000000e+000,9.586708e-003,0.000000e+000,3,9.812802e-001,1.825000e+000,,,,,,,,,,,,,,,,,,0,5.000000e+000,5.000000e-001,2,1,6.859512e-001,0,0,0,
1473329716.080,,0.000000e+000,3.723808e+001,2.744098e-004,0.000000e+000,9.392873e-003,0.000000e+000,3,9.813699e-001,1.825000e+000,,,,,,,,,,,,,,,,,,0,5.000000e+000,5.000000e-001,2,1,4.383507e-001,0,0,0,
1473329738.434,,0.000000e+000,3.598720e+001,2.818005e-004,0.000000e+000,9.177728e-003,0.000000e+000,3,9.814652e-001,1.825000e+000,,,,,,,,,,,,,,,,,,0,5.000000e+000,5.000000e-001,2,1,6.152382e-001,0,0,0,
1473329751.648,,0.000000e+000,3.513767e+001,2.861788e-004,0.000000e+000,8.938297e-003,0.000000e+000,3,9.815108e-001,1.825000e+000,,,,,,,,,,,,,,,,,,0,5.000000e+000,5.000000e-001,2,1,4.716225e-001,0,0,0,
1473329762.612,,0.000000e+000,3.443709e+001,2.898713e-004,0.000000e+000,8.806329e-003,0.000000e+000,3,9.814510e-001,1.825000e+000,,,,,,,,,,,,,,,,,,0,5.000000e+000,5.000000e-001,2,1,3.161888e-001,0,0,0,
1473329775.845,,0.000000e+000,3.375679e+001,2.943414e-004,0.000000e+000,8.620223e-003,0.000000e+000,3,9.815222e-001,1.825000e+000,,,,,,,,,,,,,,,,,,0,5.000000e+000,5.000000e-001,2,1,7.034607e-001,0,0,0,
1473329789.743,,0.000000e+000,3.269956e+001,2.990019e-004,0.000000e+000,8.388170e-003,0.000000e+000,3,9.815449e-001,1.825000e+000,,,,,,,,,,,,,,,,,,0,5.000000e+000,5.000000e-001,2,1,7.883415e-001,0,0,0,
1473329801.815,,0.000000e+000,3.183018e+001,3.030426e-004,0.000000e+000,8.206416e-003,0.000000e+000,3,9.816226e-001,1.825000e+000,,,,,,,,,,,,,,,,,,0,5.000000e+000,5.000000e-001,2,1,6.436691e-001,0,0,0,
1473329814.779,,0.000000e+000,3.102915e+001,3.073518e-004,0.000000e+000,8.074146e-003,0.000000e+000,3,9.816657e-001,1.825000e+000,,,,,,,,,,,,,,,,,,0,5.000000e+000,5.000000e-001,2,1,6.480789e-001,0,0,0,
1473329829.744,,0.000000e+000,2.995887e+001,3.123084e-004,0.000000e+000,7.815077e-003,0.000000e+000,3,9.816724e-001,1.825000e+000,,,,,,,,,,,,,,,,,,0,5.000000e+000,5.000000e-001,2,1,8.321896e-001,0,0,0,
1473329843.491,,0.000000e+000,2.904494e+001,3.168047e-004,0.000000e+000,7.681847e-003,0.000000e+000,3,9.816927e-001,1.825000e+000,,,,,,,,,,,,,,,,,,0,5.000000e+000,5.000000e-001,2,1,6.670589e-001,0,0,0,
1473329855.455,,0.000000e+000,2.812117e+001,3.205746e-004,0.000000e+000,7.516545e-003,0.000000e+000,3,9.816815e-001,1.825000e+000,,,,,,,,,,,,,,,,,,0,5.000000e+000,5.000000e-001,2,1,8.394585e-001,0,0,0,
1473329869.170,,0.000000e+000,2.728036e+001,3.247434e-004,0.000000e+000,7.361741e-003,0.000000e+000,3,9.817701e-001,1.825000e+000,,,,,,,,,,,,,,,,,,0,5.000000e+000,5.000000e-001,2,1,5.037117e-001,0,0,0,
1473329883.635,,0.000000e+000,2.617472e+001,3.290580e-004,0.000000e+000,7.133807e-003,0.000000e+000,3,9.818110e-001,1.825000e+000,,,,,,,,,,,,,,,,,,0,5.000000e+000,5.000000e-001,2,1,6.861305e-001,0,0,0,
1473329898.606,,0.000000e+000,2.514824e+001,3.334135e-004,0.000000e+000,6.932147e-003,0.000000e+000,3,9.818434e-001,1.825000e+000,,,,,,,,,,,,,,,,,,0,5.000000e+000,5.000000e-001,2,1,6.806297e-001,0,0,0,
1473329913.070,,0.000000e+000,2.413807e+001,3.373128e-004,0.000000e+000,6.817113e-003,0.000000e+000,3,9.818315e-001,1.825000e+000,,,,,,,,,,,,,,,,,,0,5.000000e+000,5.000000e-001,2,1,6.494389e-001,0,0,0,
1473329928.285,,0.000000e+000,2.344014e+001,3.397671e-004,0.000000e+000,6.626348e-003,0.000000e+000,3,9.819962e-001,1.825000e+000,,,,,,,,,,,,,,,,,,0,5.000000e+000,5.000000e-001,2,1,2.267990e-001,0,0,0,
1473329941.249,,0.000000e+000,2.306385e+001,3.413512e-004,0.000000e+000,6.617437e-003,0.000000e+000,3,9.819824e-001,1.825000e+000,,,,,,,,,,,,,,,,,,0,5.000000e+000,5.000000e-001,2,1,4.111500e-001,0,0,0,
1473329956.964,,0.000000e+000,2.212868e+001,3.450536e-004,0.000000e+000,6.506597e-003,0.000000e+000,3,9.819770e-001,1.825000e+000,,,,,,,,,,,,,,,,,,0,5.000000e+000,5.000000e-001,2,1,8.599701e-001,0,0,0,
1473329968.928,,0.000000e+000,2.119279e+001,3.478976e-004,0.000000e+000,6.389564e-003,0.000000e+000,3,9.819102e-001,1.825000e+000,,,,,,,,,,,,,,,,,,0,5.000000e+000,5.000000e-001,2,1,6.704712e-001,0,0,0,
1473329981.892,,0.000000e+000,2.050430e+001,3.502076e-004,0.000000e+000,6.311647e-003,0.000000e+000,3,9.820839e-001,1.825000e+000,,,,,,,,,,,,,,,,,,0,5.000000e+000,5.000000e-001,2,1,4.248905e-001,0,0,0,
1473329996.634,,0.000000e+000,2.025750e+001,3.506736e-004,0.000000e+000,6.256348e-003,0.000000e+000,3,9.821345e-001,1.825000e+000,,,,,,,,,,,,,,,,,,0,5.000000e+000,5.000000e-001,2,1,3.098869e-002,0,0,0,
1473330009.098,,0.000000e+000,1.984908e+001,3.521359e-004,0.000000e+000,6.322678e-003,0.000000e+000,3,9.819437e-001,1.825000e+000,,,,,,,,,,,,,,,,,,0,5.000000e+000,5.000000e-001,2,1,7.427902e-001,0,0,0,
1473330022.562,,0.000000e+000,1.886271e+001,3.553664e-004,0.000000e+000,6.164419e-003,0.000000e+000,3,9.820033e-001,1.825000e+000,,,,,,,,,,,,,,,,,,0,5.000000e+000,5.000000e-001,2,1,8.661690e-001,0,0,0,
1473330036.588,,0.000000e+000,1.781886e+001,3.584593e-004,0.000000e+000,6.051580e-003,0.000000e+000,3,9.820700e-001,1.825000e+000,,,,,,,,,,,,,,,,,,0,5.000000e+000,5.000000e-001,2,1,8.841095e-001,0,0,0,
1473330050.303,,0.000000e+000,1.675511e+001,3.613703e-004,0.000000e+000,5.979631e-003,0.000000e+000,3,9.820750e-001,1.825000e+000,,,,,,,,,,,,,,,,,,0,5.000000e+000,5.000000e-001,2,1,5.181007e-001,0,0,0,
1473330064.767,,0.000000e+000,1.588193e+001,3.636730e-004,0.000000e+000,5.861902e-003,0.000000e+000,3,9.821372e-001,1.825000e+000,,,,,,,,,,,,,,,,,,0,5.000000e+000,5.000000e-001,2,1,6.269503e-001,0,0,0,
1473330078.541,,0.000000e+000,1.522017e+001,3.652889e-004,0.000000e+000,5.865742e-003,0.000000e+000,3,9.821578e-001,1.825000e+000,,,,,,,,,,,,,,,,,,0,5.000000e+000,5.000000e-001,2,1,4.745007e-001,0,0,0,
1473330093.509,,0.000000e+000,1.493239e+001,3.657097e-004,0.000000e+000,5.816893e-003,0.000000e+000,3,9.821985e-001,1.825000e+000,,,,,,,,,,,,,,,,,,0,5.000000e+000,5.000000e-001,2,1,1.422024e-002,0,0,0,
1473330109.003,,0.000000e+000,1.497440e+001,3.655587e-004,0.000000e+000,5.825182e-003,0.000000e+000,3,9.821825e-001,1.825000e+000,,,,,,,,,,,,,,,,,,0,5.000000e+000,5.000000e-001,2,1,1.886082e-002,0,0,0,
1473330416.297,,0.000000e+000,1.500457e+001,3.655964e-004,0.000000e+000,5.880249e-003,0.000000e+000,3,9.822701e-001,1.825000e+000,,,,,,,,,,,,,,,,,,0,5.000000e+000,5.000000e-001,2,1,4.890442e-003,0,1,0,
1473330428.807,,0.000000e+000,1.500213e+001,3.656498e-004,0.000000e+000,5.845808e-003,0.000000e+000,3,9.821476e-001,1.825000e+000,,,,,,,,,,,,,,,,,,0,5.000000e+000,5.000000e-001,2,1,0.000000e+000,0,1,0,
1473330442.021,,0.000000e+000,1.500365e+001,3.656536e-004,0.000000e+000,5.852338e-003,0.000000e+000,3,9.821898e-001,1.825000e+000,,,,,,,,,,,,,,,,,,0,5.000000e+000,5.000000e-001,2,1,3.050804e-003,0,1,0,
1473330454.485,,0.000000e+000,1.500488e+001,3.656113e-004,0.000000e+000,5.857966e-003,0.000000e+000,3,9.822891e-001,1.825000e+000,,,,,,,,,,,,,,,,,,0,5.000000e+000,5.000000e-001,2,1,1.830101e-003,0,1,0,
1473330553.208,,0.000000e+000,1.499786e+001,3.656391e-004,0.000000e+000,5.896697e-003,0.000000e+000,3,9.821955e-001,1.825000e+000,,,,,,,,,,,,,,,,,,0,5.000000e+000,5.000000e-001,2,1,1.220703e-003,0,0,0,
1473330567.423,,0.000000e+000,1.499573e+001,3.656542e-004,0.000000e+000,5.881417e-003,0.000000e+000,3,9.822298e-001,1.825000e+000,,,,,,,,,,,,,,,,,,0,5.000000e+000,5.000000e-001,2,1,1.830101e-003,0,0,0,
1473330580.439,,0.000000e+000,1.499542e+001,3.656668e-004,0.000000e+000,5.868470e-003,0.000000e+000,3,9.822589e-001,1.825000e+000,,,,,,,,,,,,,,,,,,0,5.000000e+000,5.000000e-001,2,1,0.000000e+000,0,0,0,
1473330592.903,,0.000000e+000,1.499573e+001,3.656579e-004,0.000000e+000,5.907611e-003,0.000000e+000,3,9.822261e-001,1.825000e+000,,,,,,,,,,,,,,,,,,0,5.000000e+000,5.000000e-001,2,1,6.093979e-004,0,0,0,
1473330657.160,,0.000000e+000,1.376183e+001,3.685465e-004,0.000000e+000,5.848852e-003,0.000000e+000,3,9.822338e-001,1.825000e+000,,,,,,,,,,,,,,,,,,0,5.000000e+000,5.000000e-001,2,1,1.629896e-001,0,0,0,
1473330669.624,,0.000000e+000,1.347359e+001,3.691320e-004,0.000000e+000,5.837699e-003,0.000000e+000,3,9.821761e-001,1.825000e+000,,,,,,,,,,,,,,,,,,0,5.000000e+000,5.000000e-001,2,1,2.049103e-001,0,0,0,
1473330683.588,,0.000000e+000,1.319704e+001,3.697200e-004,0.000000e+000,5.819902e-003,0.000000e+000,3,9.821587e-001,1.825000e+000,,,,,,,,,,,,,,,,,,0,5.000000e+000,5.000000e-001,2,1,2.488699e-001,0,0,0,
1473330696.585,,0.000000e+000,1.292877e+001,3.702860e-004,0.000000e+000,5.823688e-003,0.000000e+000,3,9.822243e-001,1.825000e+000,,,,,,,,,,,,,,,,,,0,5.000000e+000,5.000000e-001,2,1,1.925602e-001,0,0,0,
1473330711.050,,0.000000e+000,1.264297e+001,3.708297e-004,0.000000e+000,5.817842e-003,0.000000e+000,3,9.821916e-001,1.825000e+000,,,,,,,,,,,,,,,,,,0,5.000000e+000,5.000000e-001,2,1,1.881599e-001,0,0,0,
1473330723.764,,0.000000e+000,1.240985e+001,3.713225e-004,0.000000e+000,5.761763e-003,0.000000e+000,3,9.821824e-001,1.825000e+000,,,,,,,,,,,,,,,,,,0,5.000000e+000,5.000000e-001,2,1,1.828098e-001,0,0,0,
1473330735.989,,0.000000e+000,1.218008e+001,3.717467e-004,0.000000e+000,5.770438e-003,0.000000e+000,3,9.821675e-001,1.825000e+000,,,,,,,,,,,,,,,,,,0,5.000000e+000,5.000000e-001,2,1,1.835699e-001,0,0,0,
1473330750.454,,0.000000e+000,1.190731e+001,3.722919e-004,0.000000e+000,5.724234e-003,0.000000e+000,3,9.821239e-001,1.825000e+000,,,,,,,,,,,,,,,,,,0,5.000000e+000,5.000000e-001,2,1,1.835299e-001,0,0,0,
1473330763.668,,0.000000e+000,1.163704e+001,3.727272e-004,0.000000e+000,5.754065e-003,0.000000e+000,3,9.821559e-001,1.825000e+000,,,,,,,,,,,,,,,,,,0,5.000000e+000,5.000000e-001,2,1,1.792793e-001,0,0,0,
1473330776.883,,0.000000e+000,1.139091e+001,3.731431e-004,0.000000e+000,5.731158e-003,0.000000e+000,3,9.821589e-001,1.825000e+000,,,,,,,,,,,,,,,,,,0,5.000000e+000,5.000000e-001,2,1,1.344700e-001,0,0,0,
1473330789.407,,0.000000e+000,1.114798e+001,3.735483e-004,0.000000e+000,5.729387e-003,0.000000e+000,3,9.822155e-001,1.825000e+000,,,,,,,,,,,,,,,,,,0,5.000000e+000,5.000000e-001,2,1,1.767397e-001,0,0,0,
1473330804.378,,0.000000e+000,1.088276e+001,3.740079e-004,0.000000e+000,5.738684e-003,0.000000e+000,3,9.822058e-001,1.825000e+000,,,,,,,,,,,,,,,,,,0,5.000000e+000,5.000000e-001,2,1,1.767197e-001,0,0,0,
1473330818.843,,0.000000e+000,1.061892e+001,3.744514e-004,0.000000e+000,5.711106e-003,0.000000e+000,3,9.822150e-001,1.825000e+000,,,,,,,,,,,,,,,,,,0,5.000000e+000,5.000000e-001,2,1,1.752501e-001,0,0,0,
1473330832.057,,0.000000e+000,1.040024e+001,3.747846e-004,0.000000e+000,5.710245e-003,0.000000e+000,3,9.822733e-001,1.825000e+000,,,,,,,,,,,,,,,,,,0,5.000000e+000,5.000000e-001,2,1,1.755199e-001,0,0,0,
1473330845.271,,0.000000e+000,1.014143e+001,3.751708e-004,0.000000e+000,5.698039e-003,0.000000e+000,3,9.822631e-001,1.825000e+000,,,,,,,,,,,,,,,,,,0,5.000000e+000,5.000000e-001,2,1,1.717300e-001,0,0,0,
1473330859.744,,0.000000e+000,9.907591e+000,3.755289e-004,0.000000e+000,5.694904e-003,0.000000e+000,3,9.822822e-001,1.825000e+000,,,,,,,,,,,,,,,,,,0,5.000000e+000,5.000000e-001,2,1,2.100401e-001,0,0,0,
1473330872.215,,0.000000e+000,9.678035e+000,3.758215e-004,0.000000e+000,5.725475e-003,0.000000e+000,3,9.822532e-001,1.825000e+000,,,,,,,,,,,,,,,,,,0,5.000000e+000,5.000000e-001,2,1,1.665478e-001,0,0,0,
1473330886.236,,0.000000e+000,9.431424e+000,3.761726e-004,0.000000e+000,5.719461e-003,0.000000e+000,3,9.822936e-001,1.825000e+000,,,,,,,,,,,,,,,,,,0,5.000000e+000,5.000000e-001,2,1,1.633778e-001,0,0,0,
1473330898.451,,0.000000e+000,9.229884e+000,3.764161e-004,0.000000e+000,5.716064e-003,0.000000e+000,3,9.822321e-001,1.825000e+000,,,,,,,,,,,,,,,,,,0,5.000000e+000,5.000000e-001,2,1,1.602917e-001,0,0,0,
1473330909.916,,0.000000e+000,9.033730e+000,3.766828e-004,0.000000e+000,5.655350e-003,0.000000e+000,3,9.822475e-001,1.825000e+000,,,,,,,,,,,,,,,,,,0,5.000000e+000,5.000000e-001,2,1,1.551428e-001,0,0,0,
1473330924.129,,0.000000e+000,8.821789e+000,3.769232e-004,0.000000e+000,5.641548e-003,0.000000e+000,3,9.822558e-001,1.825000e+000,,,,,,,,,,,,,,,,,,0,5.000000e+000,5.000000e-001,2,1,1.916580e-001,0,0,0,
1473330938.844,,0.000000e+000,8.576176e+000,3.772183e-004,0.000000e+000,5.627658e-003,0.000000e+000,3,9.822441e-001,1.825000e+000,,,,,,,,,,,,,,,,,,0,5.000000e+000,5.000000e-001,2,1,1.479301e-001,0,0,0,
1473330951.558,,0.000000e+000,8.393326e+000,3.774441e-004,0.000000e+000,5.653649e-003,0.000000e+000,3,9.822399e-001,1.825000e+000,,,,,,,,,,,,,,,,,,0,5.000000e+000,5.000000e-001,2,1,1.442308e-001,0,0,0,
1473330964.772,,0.000000e+000,8.214568e+000,3.776889e-004,0.000000e+000,5.652581e-003,0.000000e+000,3,9.821758e-001,1.825000e+000,,,,,,,,,,,,,,,,,,0,5.000000e+000,5.000000e-001,2,1,1.429424e-001,0,1,0,
1473330990.492,,0.000000e+000,7.850596e+000,3.780254e-004,0.000000e+000,5.664365e-003,0.000000e+000,3,9.823349e-001,1.825000e+000,,,,,,,,,,,,,,,,,,0,5.000000e+000,5.000000e-001,2,1,1.643667e-001,0,1,0,
1473331002.136,,0.000000e+000,7.708196e+000,3.782235e-004,0.000000e+000,5.628466e-003,0.000000e+000,3,9.822093e-001,1.825000e+000,,,,,,,,,,,,,,,,,,0,5.000000e+000,5.000000e-001,2,1,1.204352e-001,0,1,0,
1473331014.958,,0.000000e+000,7.575508e+000,3.783535e-004,0.000000e+000,5.671321e-003,0.000000e+000,3,9.822868e-001,1.825000e+000,,,,,,,,,,,,,,,,,,0,5.000000e+000,5.000000e-001,2,1,8.658314e-002,0,1,0,
1473331027.173,,0.000000e+000,7.440059e+000,3.784606e-004,0.000000e+000,5.623274e-003,0.000000e+000,3,9.822960e-001,1.825000e+000,,,,,,,,,,,,,,,,,,0,5.000000e+000,5.000000e-001,2,1,1.330628e-001,0,1,0,
1473331083.141,,0.000000e+000,6.932363e+000,3.789304e-004,0.000000e+000,5.622269e-003,0.000000e+000,3,9.823450e-001,1.825000e+000,,,,,,,,,,,,,,,,,,0,5.000000e+000,5.000000e-001,2,1,1.048689e-001,0,1,0,
1473331096.355,,0.000000e+000,6.818383e+000,3.790094e-004,0.000000e+000,5.572629e-003,0.000000e+000,3,9.822782e-001,1.825000e+000,,,,,,,,,,,,,,,,,,0,5.000000e+000,5.000000e-001,2,1,8.123636e-002,0,1,0,
1473331108.320,,0.000000e+000,6.723428e+000,3.790985e-004,0.000000e+000,5.603993e-003,0.000000e+000,3,9.822598e-001,1.825000e+000,,,,,,,,,,,,,,,,,,0,5.000000e+000,5.000000e-001,2,1,6.644487e-002,0,1,0,
1473331120.034,,0.000000e+000,6.624825e+000,3.792464e-004,0.000000e+000,5.595892e-003,0.000000e+000,3,9.822431e-001,1.825000e+000,,,,,,,,,,,,,,,,,,0,5.000000e+000,5.000000e-001,2,1,8.495712e-002,0,1,0,
1473331176.753,,0.000000e+000,5.885855e+000,3.797843e-004,0.000000e+000,5.546531e-003,0.000000e+000,3,9.822646e-001,1.825000e+000,,,,,,,,,,,,,,,,,,0,5.000000e+000,5.000000e-001,2,1,1.293120e-001,0,1,0,
1473331189.015,,0.000000e+000,5.727753e+000,3.799055e-004,0.000000e+000,5.525832e-003,0.000000e+000,3,9.822611e-001,1.825000e+000,,,,,,,,,,,,,,,,,,0,5.000000e+000,5.000000e-001,2,1,1.277528e-001,0,1,0,
1473331201.231,,0.000000e+000,5.569361e+000,3.799640e-004,0.000000e+000,5.547777e-003,0.000000e+000,3,9.821868e-001,1.825000e+000,,,,,,,,,,,,,,,,,,0,5.000000e+000,5.000000e-001,2,1,1.288381e-001,0,1,0,
1473331213.695,,0.000000e+000,5.399817e+000,3.800842e-004,0.000000e+000,5.513760e-003,0.000000e+000,3,9.822337e-001,1.825000e+000,,,,,,,,,,,,,,,,,,0,5.000000e+000,5.000000e-001,2,1,1.514091e-001,0,0,0,
1473331337.174,,0.000000e+000,5.002401e+000,3.803357e-004,0.000000e+000,5.469230e-003,0.000000e+000,3,9.822686e-001,1.825000e+000,,,,,,,,,,,,,,,,,,0,5.000000e+000,5.000000e-001,2,1,8.913994e-003,0,0,0,
1473331349.888,,0.000000e+000,5.017994e+000,3.803555e-004,0.000000e+000,5.552396e-003,0.000000e+000,3,9.823084e-001,1.825000e+000,,,,,,,,,,,,,,,,,,0,5.000000e+000,5.000000e-001,2,1,9.102821e-003,0,0,0,
1473331363.400,,0.000000e+000,5.027490e+000,3.803054e-004,0.000000e+000,5.541334e-003,0.000000e+000,3,9.822814e-001,1.825000e+000,,,,,,,,,,,,,,,,,,0,5.000000e+000,5.000000e-001,2,1,6.637096e-003,0,0,0,
1473331375.614,,0.000000e+000,5.034200e+000,3.803329e-004,0.000000e+000,5.502215e-003,0.000000e+000,3,9.822612e-001,1.825000e+000,,,,,,,,,,,,,,,,,,0,5.000000e+000,5.000000e-001,2,1,6.783962e-003,0,0,0,