File: data/A269/A269_GdN_MH_60K_150528.rso.dat
[Header]
TITLE,MPMS RSO Measurement
BYAPP,MPMS Measurement,1.1,Summary
FILEOPENTIME, 1432842693.145000 5/29/2015, 7:51:33 AM

INFO, APPNAME, MPMS MultiVu Application, Revision 1.61,  Build 082

INFO, NAME, A269
INFO, WEIGHT, 22.300
INFO, AREA, 1.000
INFO, LENGTH, 1.000
INFO, SHAPE, 1
INFO, COMMENT, m = 0.0223g
INFO, SEQUENCE FILE: 7T_hysteresis_sweep.seq


INFO, BACKGROUND DATA FILE:, None


STARTUPAXIS,X,4,LINEAR,AUTO,0.000000,0.000000
STARTUPAXIS,Y1,5,LINEAR,AUTO,0.000000,0.000000


STARTUPGROUP,Longitudinal
FIELDGROUP,Longitudinal,1,2,3,4,5,6,7,8,9,10,11,19,20,21,22,23,35
FIELDGROUP,Transverse,1,2,3,4,12,13,14,15,16,17,18,24,25,26,27,28,35

PLOT_APPEARANCE,ALL,HORZ_GRID_ON,VERT_GRID_ON,MARKERS_AND_LINES

[Data]
Time,Comment,Field (Oe),Temperature (K),Long Moment (emu),Long Scan Std Dev,Long Offset (cm),Long Offset Std Dev,Long Algorithm,Long Reg Fit,Long Reg Factor,Trans Moment (emu),Trans Scan Std Dev,Trans Offset (cm),Trans Offset Std Dev,Trans Algorithm,Trans Reg Fit,Trans Reg Factor,Long Moment [w/o ABS] (emu),Long Scan Std Dev [w/o ABS],Long Offset [w/o ABS] (cm),Long Offset Std Dev [w/o ABS],Long Reg Fit [w/o ABS],Trans Moment [w/o ABS] (emu),Trans Scan Std Dev [w/o ABS],Trans Offset [w/o ABS] (cm),Trans Offset Std Dev [w/o ABS],Trans Reg Fit [w/o ABS],RSO Position (deg),Amplitude (cm),Frequency,Cycles to Average,Scans per Measurement,Delta Temp (K),Error,EC Comp. Running,Using ABS,
1432842693.142,,7.000000e+004,6.007670e+001,-1.956285e-003,0.000000e+000,-5.592235e-001,0.000000e+000,3,0.000000e+000,1.825000e+000,,,,,,,,,,,,,,,,,,0,5.000000e+000,5.000000e-001,2,1,2.118301e-002,0,1,0,
1432842703.106,,7.000000e+004,6.006171e+001,-1.948256e-003,0.000000e+000,-5.575523e-001,0.000000e+000,3,0.000000e+000,1.825000e+000,,,,,,,,,,,,,,,,,,0,5.000000e+000,5.000000e-001,2,1,8.808136e-003,0,1,0,
1432842865.821,,6.000000e+004,5.999477e+001,-1.762516e-003,0.000000e+000,-5.604311e-001,0.000000e+000,3,0.000000e+000,1.825000e+000,,,,,,,,,,,,,,,,,,0,5.000000e+000,5.000000e-001,2,1,1.762390e-003,0,0,0,
1432842875.845,,6.000000e+004,5.999564e+001,-1.772346e-003,0.000000e+000,-5.606264e-001,0.000000e+000,3,0.000000e+000,1.825000e+000,,,,,,,,,,,,,,,,,,0,5.000000e+000,5.000000e-001,2,1,3.509521e-003,0,0,0,
1432843037.383,,5.000000e+004,5.999741e+001,-1.561300e-003,0.000000e+000,-5.646023e-001,0.000000e+000,3,0.000000e+000,1.825000e+000,,,,,,,,,,,,,,,,,,0,5.000000e+000,5.000000e-001,2,1,3.509521e-003,0,0,0,
1432843047.206,,5.000000e+004,5.999565e+001,-1.566598e-003,0.000000e+000,-5.610723e-001,0.000000e+000,3,0.000000e+000,1.825000e+000,,,,,,,,,,,,,,,,,,0,5.000000e+000,5.000000e-001,2,1,0.000000e+000,0,0,0,
1432843213.143,,4.000000e+004,6.000092e+001,-1.338969e-003,0.000000e+000,-5.654342e-001,0.000000e+000,3,0.000000e+000,1.825000e+000,,,,,,,,,,,,,,,,,,0,5.000000e+000,5.000000e-001,2,1,0.000000e+000,0,0,0,
1432843223.216,,4.000000e+004,6.000004e+001,-1.339038e-003,0.000000e+000,-5.647757e-001,0.000000e+000,3,0.000000e+000,1.825000e+000,,,,,,,,,,,,,,,,,,0,5.000000e+000,5.000000e-001,2,1,1.758575e-003,0,1,0,
1432843380.398,,3.000000e+004,6.000092e+001,-1.089057e-003,0.000000e+000,-5.662653e-001,0.000000e+000,3,0.000000e+000,1.825000e+000,,,,,,,,,,,,,,,,,,0,5.000000e+000,5.000000e-001,2,1,0.000000e+000,0,1,0,
1432843390.422,,3.000000e+004,5.999741e+001,-1.089340e-003,0.000000e+000,-5.658610e-001,0.000000e+000,3,0.000000e+000,1.825000e+000,,,,,,,,,,,,,,,,,,0,5.000000e+000,5.000000e-001,2,1,7.030487e-003,0,1,0,
1432843546.290,,2.000000e+004,5.999916e+001,-8.022452e-004,0.000000e+000,-5.678336e-001,0.000000e+000,3,0.000000e+000,1.825000e+000,,,,,,,,,,,,,,,,,,0,5.000000e+000,5.000000e-001,2,1,3.520966e-003,0,1,0,
1432843556.553,,2.000000e+004,6.000532e+001,-8.031715e-004,0.000000e+000,-5.679897e-001,0.000000e+000,3,0.000000e+000,1.825000e+000,,,,,,,,,,,,,,,,,,0,5.000000e+000,5.000000e-001,2,1,1.758575e-003,0,1,0,
1432843719.138,,1.000000e+004,5.999741e+001,-4.681062e-004,0.000000e+000,-5.694971e-001,0.000000e+000,3,0.000000e+000,1.825000e+000,,,,,,,,,,,,,,,,,,0,5.000000e+000,5.000000e-001,2,1,1.406860e-002,0,1,0,
1432843729.304,,1.000000e+004,6.000444e+001,-4.666010e-004,0.000000e+000,-5.703519e-001,0.000000e+000,3,0.000000e+000,1.825000e+000,,,,,,,,,,,,,,,,,,0,5.000000e+000,5.000000e-001,2,1,7.041931e-003,0,1,0,
1432843845.887,,9.000000e+003,5.999740e+001,-4.300666e-004,0.000000e+000,-5.702190e-001,0.000000e+000,3,0.000000e+000,1.825000e+000,,,,,,,,,,,,,,,,,,0,5.000000e+000,5.000000e-001,2,1,0.000000e+000,0,1,0,
1432843855.804,,9.000000e+003,5.999652e+001,-4.306631e-004,0.000000e+000,-5.675766e-001,0.000000e+000,3,0.000000e+000,1.825000e+000,,,,,,,,,,,,,,,,,,0,5.000000e+000,5.000000e-001,2,1,1.747131e-003,0,1,0,
1432843976.137,,7.000000e+003,6.000092e+001,-3.513211e-004,0.000000e+000,-5.715809e-001,0.000000e+000,3,0.000000e+000,1.825000e+000,,,,,,,,,,,,,,,,,,0,5.000000e+000,5.000000e-001,2,1,3.528595e-003,0,1,0,
1432843986.352,,7.000000e+003,6.000005e+001,-3.516400e-004,0.000000e+000,-5.697123e-001,0.000000e+000,3,0.000000e+000,1.825000e+000,,,,,,,,,,,,,,,,,,0,5.000000e+000,5.000000e-001,2,1,5.290985e-003,0,1,0,
1432844106.058,,5.000000e+003,5.999652e+001,-2.679632e-004,0.000000e+000,-5.714524e-001,0.000000e+000,3,0.000000e+000,1.825000e+000,,,,,,,,,,,,,,,,,,0,5.000000e+000,5.000000e-001,2,1,8.800507e-003,0,1,0,
1432844116.083,,5.000000e+003,5.999828e+001,-2.684169e-004,0.000000e+000,-5.714624e-001,0.000000e+000,3,0.000000e+000,1.825000e+000,,,,,,,,,,,,,,,,,,0,5.000000e+000,5.000000e-001,2,1,1.762390e-003,0,1,0,
1432844234.915,,3.000000e+003,5.999828e+001,-1.781371e-004,0.000000e+000,-5.810582e-001,0.000000e+000,3,0.000000e+000,1.825000e+000,,,,,,,,,,,,,,,,,,0,5.000000e+000,5.000000e-001,2,1,1.762390e-003,0,0,0,
1432844254.403,,3.000000e+003,5.999213e+001,-1.789876e-004,0.000000e+000,-5.679078e-001,0.000000e+000,3,0.000000e+000,1.825000e+000,,,,,,,,,,,,,,,,,,0,5.000000e+000,5.000000e-001,2,1,3.517151e-003,0,0,0,
1432844373.587,,1.000000e+003,5.999564e+001,-3.233434e-005,0.000000e+000,-1.298648e+000,0.000000e+000,3,0.000000e+000,1.825000e+000,,,,,,,,,,,,,,,,,,0,5.000000e+000,5.000000e-001,2,1,3.509521e-003,0,0,0,
1432844383.611,,1.000000e+003,5.999740e+001,-3.248542e-005,0.000000e+000,-1.293460e+000,0.000000e+000,3,0.000000e+000,1.825000e+000,,,,,,,,,,,,,,,,,,0,5.000000e+000,5.000000e-001,2,1,0.000000e+000,0,0,0,
1432844494.006,,5.000000e+002,5.999741e+001,-1.338046e-005,0.000000e+000,-1.399017e+000,0.000000e+000,3,0.000000e+000,1.825000e+000,,,,,,,,,,,,,,,,,,0,5.000000e+000,5.000000e-001,2,1,7.030487e-003,0,0,0,
1432844503.970,,5.000000e+002,5.999389e+001,-1.689872e-005,0.000000e+000,-1.301840e+000,0.000000e+000,3,0.000000e+000,1.825000e+000,,,,,,,,,,,,,,,,,,0,5.000000e+000,5.000000e-001,2,1,0.000000e+000,0,0,0,
1432844607.643,,4.000000e+002,5.999476e+001,-1.028278e-005,0.000000e+000,-1.406977e+000,0.000000e+000,3,0.000000e+000,1.825000e+000,,,,,,,,,,,,,,,,,,0,5.000000e+000,5.000000e-001,2,1,5.279541e-003,0,0,0,
1432844617.464,,4.000000e+002,5.999300e+001,-1.091315e-005,0.000000e+000,-1.360581e+000,0.000000e+000,3,0.000000e+000,1.825000e+000,,,,,,,,,,,,,,,,,,0,5.000000e+000,5.000000e-001,2,1,1.770020e-003,0,0,0,
1432844721.139,,3.000000e+002,5.999828e+001,-6.346441e-006,0.000000e+000,-1.410244e+000,0.000000e+000,3,0.000000e+000,1.825000e+000,,,,,,,,,,,,,,,,,,0,5.000000e+000,5.000000e-001,2,1,5.268097e-003,0,1,0,
1432844731.211,,3.000000e+002,5.999477e+001,-6.822741e-006,0.000000e+000,-1.399534e+000,0.000000e+000,3,0.000000e+000,1.825000e+000,,,,,,,,,,,,,,,,,,0,5.000000e+000,5.000000e-001,2,1,1.762390e-003,0,1,0,
1432844834.637,,2.000000e+002,6.000092e+001,-4.938203e-006,0.000000e+000,-1.381088e+000,0.000000e+000,3,0.000000e+000,1.825000e+000,,,,,,,,,,,,,,,,,,0,5.000000e+000,5.000000e-001,2,1,3.528595e-003,0,1,0,
1432844844.662,,2.000000e+002,5.999652e+001,-3.967147e-006,0.000000e+000,-1.420008e+000,0.000000e+000,3,0.000000e+000,1.825000e+000,,,,,,,,,,,,,,,,,,0,5.000000e+000,5.000000e-001,2,1,5.271912e-003,0,1,0,
1432844948.451,,1.000000e+002,5.999740e+001,-1.618216e-006,0.000000e+000,-1.451949e+000,0.000000e+000,3,0.000000e+000,1.825000e+000,,,,,,,,,,,,,,,,,,0,5.000000e+000,5.000000e-001,2,1,0.000000e+000,0,1,0,
1432844958.476,,1.000000e+002,6.000180e+001,-2.212702e-006,0.000000e+000,-1.425566e+000,0.000000e+000,3,0.000000e+000,1.825000e+000,,,,,,,,,,,,,,,,,,0,5.000000e+000,5.000000e-001,2,1,1.770020e-003,0,1,0,
1432845089.245,,0.000000e+000,6.000268e+001,3.369697e-006,0.000000e+000,-6.280727e-001,0.000000e+000,3,3.884507e-001,1.825000e+000,,,,,,,,,,,,,,,,,,0,5.000000e+000,5.000000e-001,2,1,3.520966e-003,0,1,0,
1432845099.771,,0.000000e+000,5.999917e+001,2.803478e-006,0.000000e+000,-6.571302e-001,0.000000e+000,3,7.810031e-002,1.825000e+000,,,,,,,,,,,,,,,,,,0,5.000000e+000,5.000000e-001,2,1,7.038116e-003,0,1,0,
1432845198.245,,-1.000000e+002,6.000268e+001,1.483750e-005,0.000000e+000,-5.452041e-001,0.000000e+000,3,0.000000e+000,1.825000e+000,,,,,,,,,,,,,,,,,,0,5.000000e+000,5.000000e-001,2,1,3.520966e-003,0,1,0,
1432845208.709,,-1.000000e+002,6.000269e+001,7.178488e-006,0.000000e+000,-1.188037e+000,0.000000e+000,3,0.000000e+000,1.825000e+000,,,,,,,,,,,,,,,,,,0,5.000000e+000,5.000000e-001,2,1,0.000000e+000,0,1,0,
1432845313.215,,-2.000000e+002,6.000180e+001,1.180480e-005,0.000000e+000,-1.263178e+000,0.000000e+000,3,0.000000e+000,1.825000e+000,,,,,,,,,,,,,,,,,,0,5.000000e+000,5.000000e-001,2,1,5.279541e-003,0,1,0,
1432845323.929,,-2.000000e+002,5.999741e+001,9.603818e-006,0.000000e+000,-1.307598e+000,0.000000e+000,3,0.000000e+000,1.825000e+000,,,,,,,,,,,,,,,,,,0,5.000000e+000,5.000000e-001,2,1,3.509521e-003,0,1,0,
1432845428.423,,-3.000000e+002,6.000092e+001,1.290434e-005,0.000000e+000,-1.338703e+000,0.000000e+000,3,0.000000e+000,1.825000e+000,,,,,,,,,,,,,,,,,,0,5.000000e+000,5.000000e-001,2,1,3.528595e-003,0,1,0,
1432845439.139,,-3.000000e+002,6.000180e+001,3.262343e-005,0.000000e+000,-5.318550e-001,0.000000e+000,3,0.000000e+000,1.825000e+000,,,,,,,,,,,,,,,,,,0,5.000000e+000,5.000000e-001,2,1,1.770020e-003,0,1,0,
1432845543.618,,-4.000000e+002,5.999828e+001,1.548959e-005,0.000000e+000,-1.322250e+000,0.000000e+000,3,0.000000e+000,1.825000e+000,,,,,,,,,,,,,,,,,,0,5.000000e+000,5.000000e-001,2,1,1.762390e-003,0,1,0,
1432845554.082,,-4.000000e+002,5.999652e+001,1.561387e-005,0.000000e+000,-1.323793e+000,0.000000e+000,3,0.000000e+000,1.825000e+000,,,,,,,,,,,,,,,,,,0,5.000000e+000,5.000000e-001,2,1,1.747131e-003,0,1,0,
1432845658.362,,-5.000000e+002,5.999741e+001,1.915258e-005,0.000000e+000,-1.318038e+000,0.000000e+000,3,0.000000e+000,1.825000e+000,,,,,,,,,,,,,,,,,,0,5.000000e+000,5.000000e-001,2,1,7.030487e-003,0,1,0,
1432845668.577,,-5.000000e+002,6.000004e+001,1.809595e-005,0.000000e+000,-1.327008e+000,0.000000e+000,3,0.000000e+000,1.825000e+000,,,,,,,,,,,,,,,,,,0,5.000000e+000,5.000000e-001,2,1,1.758575e-003,0,1,0,
1432845779.803,,-1.000000e+003,5.999564e+001,4.786564e-005,0.000000e+000,-1.152176e+000,0.000000e+000,3,0.000000e+000,1.825000e+000,,,,,,,,,,,,,,,,,,0,5.000000e+000,5.000000e-001,2,1,7.041931e-003,0,0,0,
1432845790.031,,-1.000000e+003,5.999652e+001,4.140047e-005,0.000000e+000,-1.222235e+000,0.000000e+000,3,0.000000e+000,1.825000e+000,,,,,,,,,,,,,,,,,,0,5.000000e+000,5.000000e-001,2,1,8.800507e-003,0,0,0,
1432845924.920,,-3.000000e+003,5.999564e+001,1.840432e-004,0.000000e+000,-5.712006e-001,0.000000e+000,3,0.000000e+000,1.825000e+000,,,,,,,,,,,,,,,,,,0,5.000000e+000,5.000000e-001,2,1,3.509521e-003,0,0,0,
1432845935.134,,-3.000000e+003,5.999652e+001,1.811320e-004,0.000000e+000,-5.715365e-001,0.000000e+000,3,0.000000e+000,1.825000e+000,,,,,,,,,,,,,,,,,,0,5.000000e+000,5.000000e-001,2,1,5.271912e-003,0,0,0,
1432846055.312,,-5.000000e+003,5.999389e+001,2.724191e-004,0.000000e+000,-5.650169e-001,0.000000e+000,3,0.000000e+000,1.825000e+000,,,,,,,,,,,,,,,,,,0,5.000000e+000,5.000000e-001,2,1,3.532410e-003,0,0,0,
1432846065.657,,-5.000000e+003,5.999476e+001,2.714287e-004,0.000000e+000,-5.718848e-001,0.000000e+000,3,0.000000e+000,1.825000e+000,,,,,,,,,,,,,,,,,,0,5.000000e+000,5.000000e-001,2,1,5.279541e-003,0,0,0,
1432846186.138,,-7.000000e+003,5.999564e+001,3.536641e-004,0.000000e+000,-5.711460e-001,0.000000e+000,3,0.000000e+000,1.825000e+000,,,,,,,,,,,,,,,,,,0,5.000000e+000,5.000000e-001,2,1,7.041931e-003,0,0,0,
1432846196.915,,-7.000000e+003,5.999389e+001,3.536000e-004,0.000000e+000,-5.711168e-001,0.000000e+000,3,0.000000e+000,1.825000e+000,,,,,,,,,,,,,,,,,,0,5.000000e+000,5.000000e-001,2,1,3.532410e-003,0,0,0,
1432846310.650,,-9.000000e+003,5.999741e+001,4.319111e-004,0.000000e+000,-5.693476e-001,0.000000e+000,3,0.000000e+000,1.825000e+000,,,,,,,,,,,,,,,,,,0,5.000000e+000,5.000000e-001,2,1,3.509521e-003,0,1,0,
1432846320.816,,-9.000000e+003,5.999564e+001,4.317623e-004,0.000000e+000,-5.694689e-001,0.000000e+000,3,0.000000e+000,1.825000e+000,,,,,,,,,,,,,,,,,,0,5.000000e+000,5.000000e-001,2,1,7.041931e-003,0,1,0,
1432846437.129,,-1.000000e+004,5.999917e+001,4.696139e-004,0.000000e+000,-5.690389e-001,0.000000e+000,3,0.000000e+000,1.825000e+000,,,,,,,,,,,,,,,,,,0,5.000000e+000,5.000000e-001,2,1,7.038116e-003,0,1,0,
1432846447.201,,-1.000000e+004,5.999477e+001,4.695875e-004,0.000000e+000,-5.688107e-001,0.000000e+000,3,0.000000e+000,1.825000e+000,,,,,,,,,,,,,,,,,,0,5.000000e+000,5.000000e-001,2,1,1.762390e-003,0,1,0,
1432846611.202,,-2.000000e+004,5.999916e+001,8.044415e-004,0.000000e+000,-5.640617e-001,0.000000e+000,3,0.000000e+000,1.825000e+000,,,,,,,,,,,,,,,,,,0,5.000000e+000,5.000000e-001,2,1,3.520966e-003,0,1,0,
1432846621.369,,-2.000000e+004,6.000180e+001,8.031342e-004,0.000000e+000,-5.668453e-001,0.000000e+000,3,0.000000e+000,1.825000e+000,,,,,,,,,,,,,,,,,,0,5.000000e+000,5.000000e-001,2,1,1.770020e-003,0,1,0,
1432846784.165,,-3.000000e+004,5.999741e+001,1.091042e-003,0.000000e+000,-5.653636e-001,0.000000e+000,3,0.000000e+000,1.825000e+000,,,,,,,,,,,,,,,,,,0,5.000000e+000,5.000000e-001,2,1,7.030487e-003,0,1,0,
1432846794.236,,-3.000000e+004,5.999564e+001,1.093772e-003,0.000000e+000,-5.624322e-001,0.000000e+000,3,0.000000e+000,1.825000e+000,,,,,,,,,,,,,,,,,,0,5.000000e+000,5.000000e-001,2,1,3.509521e-003,0,1,0,
1432846953.014,,-4.000000e+004,5.999828e+001,1.341070e-003,0.000000e+000,-5.649784e-001,0.000000e+000,3,0.000000e+000,1.825000e+000,,,,,,,,,,,,,,,,,,0,5.000000e+000,5.000000e-001,2,1,1.762390e-003,0,1,0,
1432846963.229,,-4.000000e+004,5.999564e+001,1.337126e-003,0.000000e+000,-5.643349e-001,0.000000e+000,3,0.000000e+000,1.825000e+000,,,,,,,,,,,,,,,,,,0,5.000000e+000,5.000000e-001,2,1,3.509521e-003,0,1,0,
1432847123.941,,-5.000000e+004,6.000268e+001,1.565383e-003,0.000000e+000,-5.641236e-001,0.000000e+000,3,0.000000e+000,1.825000e+000,,,,,,,,,,,,,,,,,,0,5.000000e+000,5.000000e-001,2,1,3.520966e-003,0,1,0,
1432847133.965,,-5.000000e+004,5.999741e+001,1.564780e-003,0.000000e+000,-5.624600e-001,0.000000e+000,3,0.000000e+000,1.825000e+000,,,,,,,,,,,,,,,,,,0,5.000000e+000,5.000000e-001,2,1,3.509521e-003,0,1,0,
1432847297.301,,-6.000000e+004,5.999565e+001,1.771580e-003,0.000000e+000,-5.614881e-001,0.000000e+000,3,0.000000e+000,1.825000e+000,,,,,,,,,,,,,,,,,,0,5.000000e+000,5.000000e-001,2,1,0.000000e+000,0,1,0,
1432847307.468,,-6.000000e+004,6.053540e+001,1.767537e-003,0.000000e+000,-5.612756e-001,0.000000e+000,3,0.000000e+000,1.825000e+000,,,,,,,,,,,,,,,,,,0,5.000000e+000,5.000000e-001,2,1,1.079498e+000,0,1,0,
1432847466.812,,-7.000000e+004,5.999916e+001,1.952584e-003,0.000000e+000,-5.616685e-001,0.000000e+000,3,0.000000e+000,1.825000e+000,,,,,,,,,,,,,,,,,,0,5.000000e+000,5.000000e-001,2,1,1.055145e-002,0,0,0,
1432847476.969,,-7.000000e+004,5.999564e+001,1.946020e-003,0.000000e+000,-5.612643e-001,0.000000e+000,3,0.000000e+000,1.825000e+000,,,,,,,,,,,,,,,,,,0,5.000000e+000,5.000000e-001,2,1,3.509521e-003,0,0,0,
1432847646.290,,-6.000000e+004,5.999476e+001,1.763380e-003,0.000000e+000,-5.653263e-001,0.000000e+000,3,0.000000e+000,1.825000e+000,,,,,,,,,,,,,,,,,,0,5.000000e+000,5.000000e-001,2,1,5.279541e-003,0,0,0,
1432847656.315,,-6.000000e+004,5.999212e+001,1.769401e-003,0.000000e+000,-5.610638e-001,0.000000e+000,3,0.000000e+000,1.825000e+000,,,,,,,,,,,,,,,,,,0,5.000000e+000,5.000000e-001,2,1,0.000000e+000,0,0,0,
1432847810.904,,-5.000000e+004,5.999564e+001,1.563053e-003,0.000000e+000,-5.644398e-001,0.000000e+000,3,0.000000e+000,1.825000e+000,,,,,,,,,,,,,,,,,,0,5.000000e+000,5.000000e-001,2,1,1.054764e-002,0,0,0,
1432847821.059,,-5.000000e+004,5.999477e+001,1.562905e-003,0.000000e+000,-5.644499e-001,0.000000e+000,3,0.000000e+000,1.825000e+000,,,,,,,,,,,,,,,,,,0,5.000000e+000,5.000000e-001,2,1,8.789063e-003,0,0,0,
1432847980.353,,-4.000000e+004,5.999300e+001,1.339515e-003,0.000000e+000,-5.659975e-001,0.000000e+000,3,0.000000e+000,1.825000e+000,,,,,,,,,,,,,,,,,,0,5.000000e+000,5.000000e-001,2,1,8.789063e-003,0,1,0,
1432847990.379,,-4.000000e+004,5.999125e+001,1.339324e-003,0.000000e+000,-5.657206e-001,0.000000e+000,3,0.000000e+000,1.825000e+000,,,,,,,,,,,,,,,,,,0,5.000000e+000,5.000000e-001,2,1,5.279541e-003,0,1,0,