File: data/A269/A269_cool_zero_field_150528.rso.raw
[Header]
TITLE,MPMS RSO Measurement
BYAPP,MPMS Measurement,2.1,Raw with ABS
FILEOPENTIME, 1432763032.747000 5/28/2015, 9:43:52 AM

INFO, APPNAME, MPMS MultiVu Application, Revision 1.61,  Build 082

INFO, NAME, A269
INFO, WEIGHT, 22.300
INFO, AREA, 1.000
INFO, LENGTH, 1.000
INFO, SHAPE, 1
INFO, COMMENT, m = 0.0223g
INFO, SEQUENCE FILE: cool_zero_field.seq


INFO, BACKGROUND DATA FILE:, None


STARTUPAXIS,X,8,LINEAR,AUTO,0.000000,0.000000
STARTUPAXIS,Y1,9,LINEAR,AUTO,0.000000,0.000000


STARTUPGROUP,Longitudinal
FIELDGROUP,Longitudinal,1,2,3,4,5,6,7,8,9,10,11,12,13,14,15,16,17,18,19,20,21,22
FIELDGROUP,Transverse,1,2,3,4,5,6,7,8,23,24,25,26,27,28,29,30,31,32,33,34,35,36

PLOT_APPEARANCE,ALL,HORZ_GRID_ON,VERT_GRID_ON,MARKERS_ONLY

[Data]
Time,Comment,Field (Oe),Start Temperature (K),End Temperature (K),Scan,Rejected,Position (cm),Long Voltage,Long Average Voltage,Long Detrended Voltage,Long Demeaned Voltage,Long Reg Fit,Long Detrended Fit,Long Demeaned Fit,Long Scaled Response,Long Avg. Scaled Response,Long Background Response,Long Response [w/ABS],Long Detrended Resp. [w/ABS],Long Fit [w/ABS],Long Detrended Fit [w/ABS],Trans Voltage,Trans Average Voltage,Trans Detrended Voltage,Trans Demeaned Voltage,Trans Reg Fit,Trans Detrended Fit,Trans Demeaned Fit,Trans Scaled Response,Trans Avg. Scaled Response,Trans Background Response,Trans Response [w/ABS],Trans Detrended Resp. [w/ABS],Trans Adjusted Fit,Trans Detrended Fit [w/ABS],
1432763032.718,,0.000000e+000,2.999944e+002,2.999842e+002,1,0,2.591737e+000,-7.141331e-002,-7.141332e-002,1.733420e-002,1.733420e-002,-7.869500e-002,1.005252e-002,1.005252e-002,-1.797253e-006,-1.797253e-006,,,,,,,,,,,,,,,,,,,,
1432763043.684,,0.000000e+000,2.999842e+002,2.999842e+002,1,0,1.737310e-002,-9.216589e-002,-9.216590e-002,-7.572524e-003,-1.437785e-002,-8.572187e-002,-1.128495e-003,-7.933825e-003,-2.319531e-006,-2.319531e-006,,,,,,,,,,,,,,,,,,,,
1432763204.914,,0.000000e+000,2.948751e+002,2.937642e+002,1,0,1.974750e+000,-2.160710e-001,-2.160711e-001,-1.204013e-003,-4.978529e-002,-2.211859e-001,-6.318881e-003,-5.490015e-002,-5.437842e-006,-5.437842e-006,,,,,,,,,,,,,,,,,,,,
1432763216.379,,0.000000e+000,2.935588e+002,2.922843e+002,1,0,4.870041e+000,-2.546769e-001,-2.546770e-001,-6.597562e-003,-7.063974e-002,-2.566832e-001,-8.603765e-003,-7.264595e-002,-6.409433e-006,-6.409433e-006,,,,,,,,,,,,,,,,,,,,
1432763245.097,,0.000000e+000,2.896764e+002,2.882129e+002,1,0,3.432219e+000,-2.926725e-001,-2.926725e-001,1.005721e-002,-1.007934e-001,-2.871713e-001,1.555839e-002,-9.529226e-002,-7.365664e-006,-7.365664e-006,,,,,,,,,,,,,,,,,,,,
1432763277.078,,0.000000e+000,2.846380e+002,2.827247e+002,1,0,3.642877e-001,-1.138340e-001,-1.138340e-001,-1.420356e-003,-2.713017e-002,-1.139609e-001,-1.547247e-003,-2.725706e-002,-2.864852e-006,-2.864852e-006,,,,,,,,,,,,,,,,,,,,
1432763289.044,,0.000000e+000,2.822127e+002,2.804323e+002,1,0,1.199470e+000,-3.146458e-001,-3.146458e-001,-9.745998e-003,-8.639240e-002,-3.116528e-001,-6.752951e-003,-8.339936e-002,-7.918665e-006,-7.918665e-006,,,,,,,,,,,,,,,,,,,,
1432763304.702,,0.000000e+000,2.792620e+002,2.774100e+002,1,0,4.317239e+000,-2.916044e-001,-2.916044e-001,-4.111853e-003,-8.205843e-002,-2.921156e-001,-4.623082e-003,-8.256966e-002,-7.338782e-006,-7.338782e-006,,,,,,,,,,,,,,,,,,,,
1432763316.524,,0.000000e+000,2.770394e+002,2.751351e+002,1,0,4.141675e+000,-2.771081e-001,-2.771081e-001,6.703580e-003,-8.853687e-002,-2.835124e-001,2.992395e-004,-9.494121e-002,-6.973955e-006,-6.973955e-006,,,,,,,,,,,,,,,,,,,,
1432763340.955,,0.000000e+000,2.719890e+002,2.703398e+002,1,0,1.062170e+000,-2.632221e-001,-2.632222e-001,-7.507753e-003,-2.051479e-002,-2.614840e-001,-5.769592e-003,-1.877663e-002,-6.624489e-006,-6.624489e-006,,,,,,,,,,,,,,,,,,,,
1432763352.669,,0.000000e+000,2.696166e+002,2.675683e+002,1,0,5.486671e-001,-2.587970e-001,-2.587970e-001,-7.664562e-003,-4.717046e-002,-2.540085e-001,-2.876134e-003,-4.238203e-002,-6.513121e-006,-6.513121e-006,,,,,,,,,,,,,,,,,,,,
1432763364.829,,0.000000e+000,2.672422e+002,2.649219e+002,1,0,3.525304e+000,-2.032533e-001,-2.032533e-001,1.654166e-002,-3.657167e-002,-2.076860e-001,1.210892e-002,-4.100440e-002,-5.115258e-006,-5.115258e-006,,,,,,,,,,,,,,,,,,,,
1432763376.426,,0.000000e+000,2.645408e+002,2.625860e+002,1,0,4.718177e+000,-2.772607e-001,-2.772607e-001,-8.279560e-003,-1.115283e-001,-2.770172e-001,-8.036105e-003,-1.112848e-001,-6.977795e-006,-6.977795e-006,,,,,,,,,,,,,,,,,,,,
1432763399.388,,0.000000e+000,2.597473e+002,2.576359e+002,1,0,1.915014e+000,-1.472518e-001,-1.472518e-001,5.522831e-003,3.199860e-003,-1.566910e-001,-3.916399e-003,-6.239370e-003,-3.705874e-006,-3.705874e-006,,,,,,,,,,,,,,,,,,,,
1432763411.352,,0.000000e+000,2.572690e+002,2.551902e+002,1,0,9.007292e-002,-1.889096e-001,-1.889096e-001,-1.005518e-002,-3.415178e-002,-1.800884e-001,-1.233995e-003,-2.533059e-002,-4.754271e-006,-4.754271e-006,,,,,,,,,,,,,,,,,,,,
1432763423.317,,0.000000e+000,2.547871e+002,2.524653e+002,1,0,2.634925e+000,-2.032533e-001,-2.032533e-001,1.515209e-002,-3.128600e-002,-2.072401e-001,1.116528e-002,-3.527281e-002,-5.115258e-006,-5.115258e-006,,,,,,,,,,,,,,,,,,,,
1432763434.782,,0.000000e+000,2.520707e+002,2.499843e+002,1,0,4.991792e+000,-2.990814e-001,-2.990814e-001,-8.128757e-003,-8.121610e-002,-2.979077e-001,-6.955082e-003,-8.004242e-002,-7.526956e-006,-7.526956e-006,,,,,,,,,,,,,,,,,,,,
1432763447.250,,0.000000e+000,2.495836e+002,2.474972e+002,1,0,2.812430e+000,-2.717673e-001,-2.717673e-001,5.698524e-003,-7.448539e-002,-2.645286e-001,1.293724e-002,-6.724668e-002,-6.839545e-006,-6.839545e-006,,,,,,,,,,,,,,,,,,,,
1432763471.701,,0.000000e+000,2.444353e+002,2.423293e+002,1,0,5.768957e-002,-2.211066e-001,-2.211066e-001,-7.307581e-003,-2.631208e-002,-2.152473e-001,-1.448265e-003,-2.045277e-002,-5.564571e-006,-5.564571e-006,,,,,,,,,,,,,,,,,,,,
1432763483.724,,0.000000e+000,2.420045e+002,2.399462e+002,1,0,1.767200e+000,-1.568651e-001,-1.568651e-001,-3.482240e-003,-3.369132e-002,-1.595244e-001,-6.141516e-003,-3.635060e-002,-3.947812e-006,-3.947812e-006,,,,,,,,,,,,,,,,,,,,
1432763495.939,,0.000000e+000,2.395705e+002,2.373221e+002,1,0,4.766805e+000,-1.609851e-001,-1.609851e-001,-4.588260e-003,-3.177543e-002,-1.640424e-001,-7.645517e-003,-3.483269e-002,-4.051499e-006,-4.051499e-006,,,,,,,,,,,,,,,,,,,,
1432763508.404,,0.000000e+000,2.369608e+002,2.349196e+002,1,0,3.621428e+000,-1.882992e-001,-1.882992e-001,8.480190e-003,-4.522216e-002,-1.859089e-001,1.087052e-002,-4.283184e-002,-4.738910e-006,-4.738910e-006,,,,,,,,,,,,,,,,,,,,
1432763533.083,,0.000000e+000,2.320214e+002,2.300465e+002,1,0,5.151789e-001,-3.418073e-002,-3.418073e-002,-6.738499e-003,-1.276738e-002,-2.960997e-002,-2.167743e-003,-8.196622e-003,-8.602236e-007,-8.602236e-007,,,,,,,,,,,,,,,,,,,,
1432763545.049,,0.000000e+000,2.299352e+002,2.281629e+002,1,0,1.026248e+000,-3.952147e-002,-3.952147e-002,-6.717961e-003,-1.923094e-002,-3.734366e-002,-4.540149e-003,-1.705312e-002,-9.946335e-007,-9.946335e-007,,,,,,,,,,,,,,,,,,,,
1432763557.014,,0.000000e+000,2.274387e+002,2.255190e+002,1,0,4.134624e+000,4.119999e-003,4.119999e-003,6.375971e-003,3.431299e-003,-3.622583e-003,-1.366611e-003,-4.311283e-003,1.036877e-007,1.036877e-007,,,,,,,,,,,,,,,,,,,,
1432763571.316,,0.000000e+000,2.247726e+002,2.228814e+002,1,0,4.300864e+000,-4.013184e-002,-4.013184e-002,-4.001507e-003,-2.132895e-002,-4.099734e-002,-4.867003e-003,-2.219444e-002,-1.009995e-006,-1.009995e-006,,,,,,,,,,,,,,,,,,,,
1432763599.497,,0.000000e+000,2.195402e+002,2.177892e+002,1,0,1.265570e+000,2.914518e-002,2.914518e-002,-4.760305e-003,-4.450068e-003,2.599150e-002,-7.913980e-003,-7.603742e-003,7.334942e-007,7.334942e-007,,,,,,,,,,,,,,,,,,,,
1432763611.961,,0.000000e+000,2.173754e+002,2.156334e+002,1,0,4.095545e-001,3.204443e-002,3.204444e-002,-8.372956e-003,-4.461531e-003,3.836244e-002,-2.054957e-003,1.856469e-003,8.064596e-007,8.064596e-007,,,,,,,,,,,,,,,,,,,,
1432763628.676,,0.000000e+000,2.144521e+002,2.128371e+002,1,0,3.308442e+000,4.348888e-002,4.348888e-002,2.188368e-002,2.361441e-002,3.984735e-002,1.824215e-002,1.997289e-002,1.094481e-006,1.094481e-006,,,,,,,,,,,,,,,,,,,,
1432763640.892,,0.000000e+000,2.125570e+002,2.107791e+002,1,0,4.824589e+000,2.133244e-001,2.133244e-001,-6.412541e-003,4.838304e-002,2.119541e-001,-7.782852e-003,4.701273e-002,5.368717e-006,5.368717e-006,,,,,,,,,,,,,,,,,,,,
1432763669.120,,0.000000e+000,2.078692e+002,2.061578e+002,1,0,2.140612e+000,1.356548e-001,1.356548e-001,1.060417e-002,1.259872e-002,1.269971e-001,1.946525e-003,3.941067e-003,3.414012e-006,3.414012e-006,,,,,,,,,,,,,,,,,,,,
1432763688.836,,0.000000e+000,2.047313e+002,2.030097e+002,1,0,3.462998e-002,5.066073e-002,5.066073e-002,-8.474490e-003,4.341073e-003,5.786464e-002,-1.270572e-003,1.154499e-002,1.274974e-006,1.274974e-006,,,,,,,,,,,,,,,,,,,,
1432763700.550,,0.000000e+000,2.027324e+002,2.013077e+002,1,0,2.409781e+000,1.005585e-001,1.005585e-001,5.409978e-003,4.793754e-002,1.033780e-001,8.229464e-003,5.075703e-002,2.530747e-006,2.530747e-006,,,,,,,,,,,,,,,,,,,,
1432763720.516,,0.000000e+000,1.996427e+002,1.980134e+002,1,0,4.984327e+000,1.992859e-001,1.992859e-001,-4.296042e-003,8.720984e-002,1.964300e-001,-7.151924e-003,8.435395e-002,5.015410e-006,5.015410e-006,,,,,,,,,,,,,,,,,,,,
1432763731.002,,0.000000e+000,1.978836e+002,1.964147e+002,1,0,3.026590e+000,2.299570e-001,2.299570e-001,2.570458e-003,9.063441e-002,2.431359e-001,1.574939e-002,1.038133e-001,5.787308e-006,5.787308e-006,,,,,,,,,,,,,,,,,,,,
1432763764.184,,0.000000e+000,1.929221e+002,1.913713e+002,1,0,1.309613e-001,9.765923e-002,9.765923e-002,5.144955e-003,2.112484e-002,9.119153e-002,-1.322745e-003,1.465714e-002,2.457782e-006,2.457782e-006,,,,,,,,,,,,,,,,,,,,
1432763786.399,,0.000000e+000,1.895429e+002,1.880963e+002,1,0,1.568770e+000,1.159703e-001,1.159703e-001,-1.787214e-003,2.136330e-002,1.094773e-001,-8.280201e-003,1.487031e-002,2.918616e-006,2.918616e-006,,,,,,,,,,,,,,,,,,,,
1432763797.113,,0.000000e+000,1.880142e+002,1.864753e+002,1,0,4.637638e+000,1.562548e-001,1.562548e-001,-1.237288e-002,5.205578e-002,1.603674e-001,-8.260247e-003,5.616841e-002,3.932450e-006,3.932450e-006,,,,,,,,,,,,,,,,,,,,
1432763820.093,,0.000000e+000,1.846817e+002,1.831370e+002,1,0,3.801622e+000,2.494888e-001,2.494888e-001,9.289718e-003,9.011757e-002,2.454789e-001,5.279786e-003,8.610764e-002,6.278864e-006,6.278864e-006,,,,,,,,,,,,,,,,,,,,
1432763855.064,,0.000000e+000,1.795019e+002,1.783258e+002,1,0,6.843722e-001,1.539659e-001,1.539659e-001,1.972394e-003,1.784280e-002,1.471097e-001,-4.883779e-003,1.098663e-002,3.874846e-006,3.874846e-006,,,,,,,,,,,,,,,,,,,,
1432763865.305,,0.000000e+000,1.779816e+002,1.766589e+002,1,0,8.595288e-001,2.774132e-001,2.774132e-001,-5.811218e-003,4.764609e-002,2.783115e-001,-4.912976e-003,4.854433e-002,6.981636e-006,6.981636e-006,,,,,,,,,,,,,,,,,,,,
1432763889.286,,0.000000e+000,1.749035e+002,1.733284e+002,1,0,3.939852e+000,2.580340e-001,2.580340e-001,6.102675e-004,8.563225e-002,2.579844e-001,5.606764e-004,8.558266e-002,6.493919e-006,6.493919e-006,,,,,,,,,,,,,,,,,,,,
1432763900.501,,0.000000e+000,1.732353e+002,1.717482e+002,1,0,4.451675e+000,3.976562e-001,3.976562e-001,-8.257479e-003,1.348756e-001,3.983729e-001,-7.540793e-003,1.355923e-001,1.000778e-005,1.000778e-005,,,,,,,,,,,,,,,,,,,,
1432763937.183,,0.000000e+000,1.681583e+002,1.667892e+002,1,0,1.476407e+000,2.841273e-001,2.841273e-001,-1.043668e-002,2.091765e-003,2.876897e-001,-6.874255e-003,5.654186e-003,7.150608e-006,7.150608e-006,,,,,,,,,,,,,,,,,,,,
1432763962.149,,0.000000e+000,1.647609e+002,1.633801e+002,1,0,2.836867e-001,3.196814e-001,3.196814e-001,-2.957243e-003,5.712867e-002,3.207699e-001,-1.868713e-003,5.821720e-002,8.045395e-006,8.045395e-006,,,,,,,,,,,,,,,,,,,,
1432763972.364,,0.000000e+000,1.632912e+002,1.619780e+002,1,0,3.086275e+000,3.704947e-001,3.704947e-001,2.352102e-002,1.097232e-001,3.657754e-001,1.880174e-002,1.050040e-001,9.324209e-006,9.324209e-006,,,,,,,,,,,,,,,,,,,,
1432763999.331,,0.000000e+000,1.597880e+002,1.584369e+002,1,0,4.907856e+000,2.420118e-001,2.420118e-001,-2.214988e-003,8.969676e-002,2.381548e-001,-6.071931e-003,8.583982e-002,6.090690e-006,6.090690e-006,,,,,,,,,,,,,,,,,,,,
1432764037.044,,0.000000e+000,1.548039e+002,1.536225e+002,1,0,2.366298e+000,1.980651e-001,1.980651e-001,1.230701e-002,1.467593e-002,1.935305e-001,7.772352e-003,1.014127e-002,4.984688e-006,4.984688e-006,,,,,,,,,,,,,,,,,,,,
1432764047.819,,0.000000e+000,1.535253e+002,1.521612e+002,1,0,8.768495e-003,1.353496e-001,1.353496e-001,-1.103304e-002,1.971213e-002,1.447655e-001,-1.617134e-003,2.912804e-002,3.406332e-006,3.406332e-006,,,,,,,,,,,,,,,,,,,,
1432764077.785,,0.000000e+000,1.496822e+002,1.483686e+002,1,0,2.189207e+000,2.616962e-001,2.616962e-001,5.278636e-003,7.734886e-002,2.629521e-001,6.534535e-003,7.860476e-002,6.586086e-006,6.586086e-006,,,,,,,,,,,,,,,,,,,,
1432764089.499,,0.000000e+000,1.481478e+002,1.468264e+002,1,0,4.944185e+000,3.532518e-001,3.532518e-001,-3.924997e-003,1.243770e-001,3.514197e-001,-5.757094e-003,1.225449e-001,8.890257e-006,8.890257e-006,,,,,,,,,,,,,,,,,,,,
1432764115.716,,0.000000e+000,1.446243e+002,1.433401e+002,1,0,3.233604e+000,4.394665e-001,4.394665e-001,1.117428e-002,1.967046e-001,4.400262e-001,1.173391e-002,1.972643e-001,1.106002e-005,1.106002e-005,,,,,,,,,,,,,,,,,,,,
1432764151.146,,0.000000e+000,1.398246e+002,1.385193e+002,1,0,2.344378e-001,2.838221e-001,2.838221e-001,-7.151095e-003,3.620237e-002,2.885271e-001,-2.446113e-003,4.090735e-002,7.142928e-006,7.142928e-006,,,,,,,,,,,,,,,,,,,,
1432764161.692,,0.000000e+000,1.382309e+002,1.368599e+002,1,0,1.380659e+000,2.441481e-001,2.441481e-001,-5.054572e-004,5.640249e-002,2.372457e-001,-7.407839e-003,4.950011e-002,6.144454e-006,6.144454e-006,,,,,,,,,,,,,,,,,,,,
1432764185.922,,0.000000e+000,1.347063e+002,1.332781e+002,1,0,4.486898e+000,2.815332e-001,2.815332e-001,1.604866e-003,9.823190e-002,2.727914e-001,-7.136930e-003,8.949010e-002,7.085323e-006,7.085323e-006,,,,,,,,,,,,,,,,,,,,
1432764196.388,,0.000000e+000,1.330174e+002,1.316061e+002,1,0,3.975111e+000,3.221229e-001,3.221229e-001,-5.641338e-003,1.235254e-001,3.236110e-001,-4.153249e-003,1.250135e-001,8.106839e-006,8.106839e-006,,,,,,,,,,,,,,,,,,,,
1432764229.570,,0.000000e+000,1.280610e+002,1.263975e+002,1,0,8.669208e-001,2.316355e-001,2.316355e-001,-1.259452e-002,8.028045e-003,2.367774e-001,-7.452646e-003,1.316991e-002,5.829550e-006,5.829550e-006,,,,,,,,,,,,,,,,,,,,
1432764251.036,,0.000000e+000,1.245118e+002,1.229940e+002,1,0,6.999804e-001,2.095096e-001,2.095096e-001,-7.257094e-003,4.512957e-002,2.112432e-001,-5.523493e-003,4.686317e-002,5.272710e-006,5.272710e-006,,,,,,,,,,,,,,,,,,,,
1432764261.763,,0.000000e+000,1.228559e+002,1.212795e+002,1,0,3.736486e+000,1.927244e-001,1.927244e-001,-3.328547e-004,7.145119e-002,1.915753e-001,-1.481973e-003,7.030207e-002,4.850278e-006,4.850278e-006,,,,,,,,,,,,,,,,,,,,
1432764280.729,,0.000000e+000,1.197488e+002,1.182106e+002,1,0,4.589901e+000,6.500442e-002,6.500442e-002,-7.091025e-003,2.820693e-002,6.404417e-002,-8.051278e-003,2.724667e-002,1.635961e-006,1.635961e-006,,,,,,,,,,,,,,,,,,,,
1432764312.738,,0.000000e+000,1.146507e+002,1.128416e+002,1,0,1.693829e+000,1.295511e-001,1.295511e-001,-1.493268e-003,6.580338e-003,1.314724e-001,4.280433e-004,8.501649e-003,3.260401e-006,3.260401e-006,,,,,,,,,,,,,,,,,,,,
1432764324.454,,0.000000e+000,1.124980e+002,1.106199e+002,1,0,1.786353e-001,1.382488e-001,1.382488e-001,-7.511280e-003,1.309679e-002,1.435664e-001,-2.193771e-003,1.841430e-002,3.479297e-006,3.479297e-006,,,,,,,,,,,,,,,,,,,,
1432764339.919,,0.000000e+000,1.095696e+002,1.076311e+002,1,0,2.861458e+000,1.644948e-001,1.644948e-001,1.578772e-002,5.602928e-002,1.631620e-001,1.445493e-002,5.469649e-002,4.139826e-006,4.139826e-006,,,,,,,,,,,,,,,,,,,,
1432764351.883,,0.000000e+000,1.072558e+002,1.053752e+002,1,0,4.967729e+000,2.032533e-001,2.032533e-001,-3.989011e-003,5.387408e-002,2.037949e-001,-3.447353e-003,5.441573e-002,5.115258e-006,5.115258e-006,,,,,,,,,,,,,,,,,,,,
1432764378.373,,0.000000e+000,1.024959e+002,1.008483e+002,1,0,2.591346e+000,1.748711e-001,1.748711e-001,2.429774e-002,2.429774e-002,1.693728e-001,1.879951e-002,1.879951e-002,4.400965e-006,4.400965e-006,,,,,,,,,,,,,,,,,,,,
1432765709.961,,0.000000e+000,9.998598e+001,9.998133e+001,1,0,1.569226e-002,-1.586962e-002,-1.586962e-002,-4.905290e-003,-1.654634e-003,-1.308049e-002,-2.116150e-003,1.134505e-003,-3.993895e-007,-3.993895e-007,,,,,,,,,,,,,,,,,,,,
1432765720.175,,0.000000e+000,9.997900e+001,9.998830e+001,1,0,1.974496e+000,9.308145e-003,9.308145e-003,1.033372e-002,1.412493e-002,4.830146e-003,5.855721e-003,9.646932e-003,2.342573e-007,2.342573e-007,,,,,,,,,,,,,,,,,,,,
1432765916.659,,0.000000e+000,9.999992e+001,9.999529e+001,1,0,4.870039e+000,1.403851e-002,1.403851e-002,-1.680916e-003,4.587984e-003,1.090208e-002,-4.817346e-003,1.451554e-003,3.533061e-007,3.533061e-007,,,,,,,,,,,,,,,,,,,,
1432765927.411,,0.000000e+000,9.999294e+001,9.999063e+001,1,0,3.431348e+000,-1.998962e-002,-1.998962e-002,4.811700e-003,5.403439e-003,-2.070103e-002,4.100299e-003,4.692037e-003,-5.030772e-007,-5.030772e-007,,,,,,,,,,,,,,,,,,,,
1432766011.228,,0.000000e+000,9.867881e+001,9.837811e+001,1,0,3.631305e-001,-5.630665e-002,-5.630665e-002,-8.140497e-003,-8.172236e-003,-5.176434e-002,-3.598191e-003,-3.629930e-003,-1.417065e-006,-1.417065e-006,,,,,,,,,,,,,,,,,,,,
1432766034.138,,0.000000e+000,9.787556e+001,9.748411e+001,1,0,1.199375e+000,-5.188147e-002,-5.188147e-002,-1.003154e-002,-9.093918e-003,-4.893912e-002,-7.089190e-003,-6.151572e-003,-1.305696e-006,-1.305696e-006,,,,,,,,,,,,,,,,,,,,
1432766044.959,,0.000000e+000,9.745753e+001,9.698356e+001,1,0,4.317334e+000,-6.042665e-002,-6.042665e-002,-9.431235e-003,-5.821325e-003,-5.825417e-002,-7.258757e-003,-3.648847e-003,-1.520752e-006,-1.520752e-006,,,,,,,,,,,,,,,,,,,,
1432766055.697,,0.000000e+000,9.688929e+001,9.644008e+001,1,0,4.140819e+000,-4.730369e-002,-4.730369e-002,-6.553225e-003,-1.490038e-002,-4.839208e-002,-7.641617e-003,-1.598877e-002,-1.190488e-006,-1.190488e-006,,,,,,,,,,,,,,,,,,,,
1432766079.095,,0.000000e+000,9.569650e+001,9.514111e+001,1,0,1.060954e+000,-1.480148e-002,-1.480148e-002,-3.276465e-003,-3.034183e-003,-1.914908e-002,-7.624066e-003,-7.381784e-003,-3.725075e-007,-3.725075e-007,,,,,,,,,,,,,,,,,,,,
1432766089.666,,0.000000e+000,9.509881e+001,9.451859e+001,1,0,5.499150e-001,-3.494369e-002,-3.494369e-002,-4.721090e-003,-5.978355e-003,-3.566135e-002,-5.438745e-003,-6.696010e-003,-8.794249e-007,-8.794249e-007,,,,,,,,,,,,,,,,,,,,
1432766100.880,,0.000000e+000,9.447472e+001,9.386655e+001,1,0,3.525391e+000,-3.433332e-002,-3.433332e-002,2.791916e-003,5.704463e-004,-3.649476e-002,6.304804e-004,-1.590990e-003,-8.640638e-007,-8.640638e-007,,,,,,,,,,,,,,,,,,,,
1432766112.526,,0.000000e+000,9.375323e+001,9.314564e+001,1,0,4.716991e+000,-4.181036e-002,-4.181036e-002,-2.841561e-003,-4.433710e-003,-4.402909e-002,-5.060295e-003,-6.652445e-003,-1.052238e-006,-1.052238e-006,,,,,,,,,,,,,,,,,,,,
1432766134.864,,0.000000e+000,9.232700e+001,9.173471e+001,1,0,1.915399e+000,-2.960295e-002,-2.960295e-002,8.042525e-003,7.785758e-003,-3.089335e-002,6.752125e-003,6.495358e-003,-7.450150e-007,-7.450150e-007,,,,,,,,,,,,,,,,,,,,
1432766146.840,,0.000000e+000,9.153559e+001,9.092365e+001,1,0,9.019231e-002,-3.952147e-002,-3.952147e-002,-6.775064e-003,-8.978043e-003,-3.600565e-002,-3.259247e-003,-5.462226e-003,-9.946335e-007,-9.946335e-007,,,,,,,,,,,,,,,,,,,,
1432766158.055,,0.000000e+000,9.079560e+001,9.017189e+001,1,0,2.634585e+000,-3.601184e-002,-3.601184e-002,1.463552e-002,1.048882e-002,-3.418092e-002,1.646644e-002,1.231974e-002,-9.063069e-007,-9.063069e-007,,,,,,,,,,,,,,,,,,,,
1432766168.771,,0.000000e+000,9.003629e+001,8.938467e+001,1,0,4.992939e+000,-4.455702e-002,-4.455702e-002,-2.448521e-003,-1.185014e-002,-4.604936e-002,-3.940858e-003,-1.334248e-002,-1.121363e-006,-1.121363e-006,,,,,,,,,,,,,,,,,,,,
1432766180.245,,0.000000e+000,8.925505e+001,8.852711e+001,1,0,2.812484e+000,-5.783258e-002,-5.783258e-002,1.721265e-002,4.036248e-003,-5.970202e-002,1.534321e-002,2.166808e-003,-1.455468e-006,-1.455468e-006,,,,,,,,,,,,,,,,,,,,
1432766201.466,,0.000000e+000,8.772483e+001,8.695760e+001,1,0,5.753286e-002,-4.821924e-002,-4.821924e-002,-3.418970e-003,-6.541267e-003,-4.775710e-002,-2.956826e-003,-6.079122e-003,-1.213530e-006,-1.213530e-006,,,,,,,,,,,,,,,,,,,,
1432766212.974,,0.000000e+000,8.688621e+001,8.609238e+001,1,0,1.767867e+000,-3.952147e-002,-3.952147e-002,2.334226e-003,-4.549161e-003,-3.776163e-002,4.094068e-003,-2.789319e-003,-9.946335e-007,-9.946335e-007,,,,,,,,,,,,,,,,,,,,
1432766223.454,,0.000000e+000,8.603809e+001,8.526224e+001,1,0,4.766518e+000,-5.630665e-002,-5.630665e-002,-9.579471e-004,-1.250675e-002,-5.959312e-002,-4.244421e-003,-1.579323e-002,-1.417065e-006,-1.417065e-006,,,,,,,,,,,,,,,,,,,,
1432766234.191,,0.000000e+000,8.526224e+001,8.444876e+001,1,0,3.621764e+000,-5.355999e-002,-5.355999e-002,-4.833634e-003,-1.240040e-002,-5.158880e-002,-2.862445e-003,-1.042921e-002,-1.347940e-006,-1.347940e-006,,,,,,,,,,,,,,,,,,,,
1432766256.907,,0.000000e+000,8.341308e+001,8.266977e+001,1,0,5.155125e-001,-4.104739e-002,-4.104739e-002,-5.838462e-003,-8.657675e-003,-4.267243e-002,-7.463493e-003,-1.028271e-002,-1.033036e-006,-1.033036e-006,,,,,,,,,,,,,,,,,,,,
1432766267.415,,0.000000e+000,8.261948e+001,8.180973e+001,1,0,1.026438e+000,-6.378368e-002,-6.378368e-002,-7.376852e-003,-1.690182e-002,-6.447732e-002,-8.070486e-003,-1.759546e-002,-1.605239e-006,-1.605239e-006,,,,,,,,,,,,,,,,,,,,
1432766279.880,,0.000000e+000,8.162865e+001,8.087439e+001,1,0,4.134352e+000,-7.507553e-002,-7.507554e-002,-1.440062e-002,-2.666239e-002,-6.996698e-002,-9.292062e-003,-2.155384e-002,-1.889420e-006,-1.889420e-006,,,,,,,,,,,,,,,,,,,,
1432766290.596,,0.000000e+000,8.072823e+001,8.011481e+001,1,0,4.300392e+000,-9.796441e-002,-9.796441e-002,-1.477466e-002,-3.452621e-002,-9.109328e-002,-7.903523e-003,-2.765507e-002,-2.465462e-006,-2.465462e-006,,,,,,,,,,,,,,,,,,,,
1432766312.843,,0.000000e+000,7.899877e+001,7.820974e+001,1,0,1.265248e+000,-5.371258e-002,-5.371258e-002,-5.263219e-003,-7.705461e-003,-5.183128e-002,-3.381921e-003,-5.824164e-003,-1.351780e-006,-1.351780e-006,,,,,,,,,,,,,,,,,,,,
1432766324.059,,0.000000e+000,7.815127e+001,7.728000e+001,1,0,4.097098e-001,-5.600147e-002,-5.600147e-002,-4.618031e-003,-1.235530e-002,-5.930527e-002,-7.921834e-003,-1.565910e-002,-1.409384e-006,-1.409384e-006,,,,,,,,,,,,,,,,,,,,
1432766334.525,,0.000000e+000,7.728000e+001,7.640215e+001,1,0,3.307441e+000,-5.951109e-002,-5.951110e-002,-5.758526e-003,-1.982186e-002,-5.311350e-002,6.390718e-004,-1.342426e-002,-1.497711e-006,-1.497711e-006,,,,,,,,,,,,,,,,,,,,
1432766346.425,,0.000000e+000,7.620412e+001,7.539731e+001,1,0,4.826611e+000,-7.965331e-002,-7.965331e-002,3.079197e-003,-2.114021e-002,-8.650152e-002,-3.769019e-003,-2.798843e-002,-2.004628e-006,-2.004628e-006,,,,,,,,,,,,,,,,,,,,
1432766368.000,,0.000000e+000,7.440575e+001,7.354283e+001,1,0,2.140543e+000,-5.371258e-002,-5.371258e-002,2.164266e-002,2.055888e-002,-4.838380e-002,2.697143e-002,2.588765e-002,-1.351780e-006,-1.351780e-006,,,,,,,,,,,,,,,,,,,,
1432766379.646,,0.000000e+000,7.336533e+001,7.249893e+001,1,0,3.587614e-002,-8.392590e-002,-8.392590e-002,-8.164141e-003,-1.708956e-002,-8.295591e-002,-7.194150e-003,-1.611957e-002,-2.112156e-006,-2.112156e-006,,,,,,,,,,,,,,,,,,,,
1432766389.968,,0.000000e+000,7.242826e+001,7.165648e+001,1,0,2.410093e+000,-4.501480e-002,-4.501480e-002,3.116573e-002,1.408884e-002,-4.677604e-002,2.940449e-002,1.232760e-002,-1.132884e-006,-1.132884e-006,,,,,,,,,,,,,,,,,,,,
1432766400.683,,0.000000e+000,7.149377e+001,7.063556e+001,1,0,4.985219e+000,-5.493332e-002,-5.493332e-002,1.971571e-002,-1.846455e-002,-7.818807e-002,-3.539046e-003,-4.171930e-002,-1.382502e-006,-1.382502e-006,,,,,,,,,,,,,,,,,,,,
1432766412.847,,0.000000e+000,7.042472e+001,6.953496e+001,1,0,3.026491e+000,-1.060518e-001,-1.060518e-001,1.374817e-002,-3.828692e-002,-1.148157e-001,4.984316e-003,-4.705077e-002,-2.668997e-006,-2.668997e-006,,,,,,,,,,,,,,,,,,,,
1432766435.674,,0.000000e+000,6.838375e+001,6.746318e+001,1,0,1.309783e-001,-1.016266e-001,-1.016266e-001,-1.156544e-002,-2.433600e-002,-1.072765e-001,-1.721529e-002,-2.998585e-002,-2.557629e-006,-2.557629e-006,,,,,,,,,,,,,,,,,,,,
1432766446.138,,0.000000e+000,6.739504e+001,6.657880e+001,1,0,1.569695e+000,-5.478073e-002,-5.478073e-002,2.345553e-002,-6.207455e-003,-4.849513e-002,2.974113e-002,7.814169e-005,-1.378662e-006,-1.378662e-006,,,,,,,,,,,,,,,,,,,,
1432766457.623,,0.000000e+000,6.638195e+001,6.549713e+001,1,0,4.638090e+000,-1.287881e-001,-1.287881e-001,3.586276e-003,-5.167115e-002,-1.414796e-001,-9.105192e-003,-6.436262e-002,-3.241199e-006,-3.241199e-006,,,,,,,,,,,,,,,,,,,,
1432766468.087,,0.000000e+000,6.540367e+001,6.435777e+001,1,0,3.801504e+000,-2.209540e-001,-2.209540e-001,-9.572163e-002,-1.692013e-001,-1.560959e-001,-3.086353e-002,-1.043431e-001,-5.560731e-006,-5.560731e-006,,,,,,,,,,,,,,,,,,,,
1432766491.137,,0.000000e+000,6.275316e+001,6.163715e+001,1,0,6.841248e-001,-9.750664e-002,-9.750663e-002,-1.800843e-002,-3.424485e-002,-1.146070e-001,-3.510879e-002,-5.134521e-002,-2.453941e-006,-2.453941e-006,,,,,,,,,,,,,,,,,,,,
1432766503.102,,0.000000e+000,6.132748e+001,6.044585e+001,1,0,8.595400e-001,-9.338664e-002,-9.338664e-002,1.423200e-002,-3.666519e-002,-1.304550e-001,-2.283640e-002,-7.373359e-002,-2.350254e-006,-2.350254e-006,,,,,,,,,,,,,,,,,,,,
1432766514.819,,0.000000e+000,6.028736e+001,5.948082e+001,1,0,3.940223e+000,-3.973510e-001,-3.973510e-001,-2.259470e-001,-3.197372e-001,-2.207340e-001,-4.933007e-002,-1.431202e-001,-1.000010e-005,-1.000010e-005,,,,,,,,,,,,,,,,,,,,
1432766682.126,,0.000000e+000,6.004496e+001,6.004319e+001,1,0,4.451530e+000,-1.753288e-001,-1.753288e-001,-2.351428e-002,-1.307436e-001,-1.727110e-001,-2.089647e-002,-1.281258e-001,-4.412486e-006,-4.412486e-006,,,,,,,,,,,,,,,,,,,,
1432766703.056,,0.000000e+000,6.004144e+001,6.002557e+001,1,0,1.475749e+000,-4.882962e-002,-4.882962e-002,1.399345e-002,4.241873e-003,2.003449e-003,6.482651e-002,5.507494e-002,-1.228891e-006,-1.228891e-006,,,,,,,,,,,,,,,,,,,,
1432766713.522,,0.000000e+000,6.002557e+001,6.001677e+001,1,0,2.837673e-001,-9.201331e-002,-9.201331e-002,-4.180428e-003,-4.713852e-002,-1.375653e-001,-4.973244e-002,-9.269053e-002,-2.315691e-006,-2.315691e-006,,,,,,,,,,,,,,,,,,,,
1432766723.987,,0.000000e+000,6.002910e+001,6.003086e+001,1,0,3.085879e+000,-1.629688e-001,-1.629688e-001,-5.911579e-002,-1.276044e-001,-1.171714e-001,-1.331833e-002,-8.180695e-002,-4.101423e-006,-4.101423e-006,,,,,,,,,,,,,,,,,,,,
1432766734.452,,0.000000e+000,6.002910e+001,6.001501e+001,1,0,4.910026e+000,-4.211554e-002,-4.211554e-002,1.067869e-001,1.498528e-003,-1.584494e-001,-9.546954e-003,-1.148353e-001,-1.059918e-006,-1.059918e-006,,,,,,,,,,,,,,,,,,,,
1432766755.381,,0.000000e+000,6.001148e+001,6.000796e+001,1,0,2.367324e+000,-3.509629e-003,-3.509629e-003,5.274538e-002,5.070585e-002,3.297327e-002,8.922828e-002,8.718875e-002,-8.832652e-008,-8.832652e-008,,,,,,,,,,,,,,,,,,,,
1432766765.595,,0.000000e+000,6.000796e+001,6.001325e+001,1,0,7.978286e-003,-1.031526e-001,-1.031526e-001,-1.596228e-002,-5.019141e-002,-1.260012e-001,-3.881089e-002,-7.304002e-002,-2.596032e-006,-2.596032e-006,,,,,,,,,,,,,,,,,,,,
1432766776.060,,0.000000e+000,6.001148e+001,6.000444e+001,1,0,2.189420e+000,2.395703e-002,2.395703e-002,1.277322e-001,6.528224e-002,6.849011e-003,1.106241e-001,4.817422e-002,6.029246e-007,6.029246e-007,,,,,,,,,,,,,,,,,,,,
1432766786.275,,0.000000e+000,6.000444e+001,6.001677e+001,1,0,4.944223e+000,-5.844295e-002,-5.844295e-002,1.066264e-001,1.462871e-002,-1.739012e-001,-8.831779e-003,-1.008295e-001,-1.470829e-006,-1.470829e-006,,,,,,,,,,,,,,,,,,,,
1432766796.740,,0.000000e+000,6.001148e+001,6.000972e+001,1,0,3.234079e+000,-2.117985e-001,-2.117985e-001,-5.303973e-002,-1.776125e-001,-1.888215e-001,-3.006278e-002,-1.546356e-001,-5.330314e-006,-5.330314e-006,,,,,,,,,,,,,,,,,,,,
1432766817.670,,0.000000e+000,6.000796e+001,6.000269e+001,1,0,2.342855e-001,-9.704886e-002,-9.704886e-002,-1.941890e-002,-4.404126e-002,-1.263469e-001,-4.871694e-002,-7.333930e-002,-2.442421e-006,-2.442421e-006,,,,,,,,,,,,,,,,,,,,
1432766828.135,,0.000000e+000,6.000092e+001,6.000620e+001,1,0,1.380532e+000,-5.935850e-002,-5.935850e-002,4.881205e-002,-5.547952e-003,-5.877247e-002,4.939808e-002,-4.961926e-003,-1.493870e-006,-1.493870e-006,,,,,,,,,,,,,,,,,,,,
1432766838.349,,0.000000e+000,6.000620e+001,5.999740e+001,1,0,4.485883e+000,-1.692251e-001,-1.692251e-001,-3.506096e-002,-1.195068e-001,-1.531963e-001,-1.903209e-002,-1.034779e-001,-4.258874e-006,-4.258874e-006,,,,,,,,,,,,,,,,,,,,
1432766848.815,,0.000000e+000,5.999740e+001,5.999740e+001,1,0,3.975578e+000,-3.053377e-001,-3.053377e-001,-1.527188e-001,-2.645841e-001,-1.946418e-001,-4.202294e-002,-1.538882e-001,-7.684408e-006,-7.684408e-006,,,,,,,,,,,,,,,,,,,,
1432766870.035,,0.000000e+000,5.999916e+001,6.000269e+001,1,0,8.676270e-001,-5.294961e-002,-5.294961e-002,-1.694714e-002,-3.266513e-002,-5.810906e-002,-2.210659e-002,-3.782458e-002,-1.332578e-006,-1.332578e-006,,,,,,,,,,,,,,,,,,,,
1432766880.250,,0.000000e+000,6.000444e+001,5.999916e+001,1,0,7.012476e-001,-7.126072e-002,-7.126072e-002,8.166472e-003,-3.725800e-002,-1.175771e-001,-3.814987e-002,-8.357434e-002,-1.793412e-006,-1.793412e-006,,,,,,,,,,,,,,,,,,,,
1432766890.964,,0.000000e+000,6.000620e+001,6.000269e+001,1,0,3.736310e+000,-3.480636e-001,-3.480636e-001,-2.104209e-001,-2.859525e-001,-1.886543e-001,-5.101157e-002,-1.265432e-001,-8.759687e-006,-8.759687e-006,,,,,,,,,,,,,,,,,,,,
1432766901.428,,0.000000e+000,6.000269e+001,6.000444e+001,1,0,4.592699e+000,-1.425214e-001,-1.425214e-001,1.485579e-002,-9.116215e-002,-1.733831e-001,-1.600585e-002,-1.220238e-001,-3.586825e-006,-3.586825e-006,,,,,,,,,,,,,,,,,,,,
1432766922.607,,0.000000e+000,5.999389e+001,5.999565e+001,1,0,1.693147e+000,-1.541185e-002,-1.541185e-002,3.733151e-002,2.948816e-002,4.151984e-002,9.426320e-002,8.641985e-002,-3.878687e-007,-3.878687e-007,,,,,,,,,,,,,,,,,,,,
1432766932.822,,0.000000e+000,5.999565e+001,5.999740e+001,1,0,1.761761e-001,-1.039155e-001,-1.039155e-001,-9.113831e-003,-4.680414e-002,-1.417834e-001,-4.698167e-002,-8.467199e-002,-2.615233e-006,-2.615233e-006,,,,,,,,,,,,,,,,,,,,
1432766943.036,,0.000000e+000,5.999740e+001,5.999389e+001,1,0,2.860438e+000,-1.031526e-001,-1.031526e-001,8.019820e-003,-5.857148e-002,-9.350573e-002,1.766666e-002,-4.892464e-002,-2.596032e-006,-2.596032e-006,,,,,,,,,,,,,,,,,,,,
1432766953.752,,0.000000e+000,6.000269e+001,6.000092e+001,1,0,4.966411e+000,-4.135258e-002,-4.135258e-002,1.154989e-001,1.946992e-002,-1.655080e-001,-8.656464e-003,-1.046855e-001,-1.040717e-006,-1.040717e-006,,,,,,,,,,,,,,,,,,,,
1432766974.933,,0.000000e+000,5.999916e+001,5.999916e+001,1,0,2.591809e+000,-8.392590e-003,-8.392590e-003,2.155242e-002,2.155242e-002,2.813176e-002,5.807678e-002,5.807678e-002,-2.112156e-007,-2.112156e-007,,,,,,,,,,,,,,,,,,,,
1432766985.458,,0.000000e+000,5.999916e+001,5.999389e+001,1,0,1.647206e-002,-8.926664e-002,-8.926664e-002,-1.808870e-002,-4.775557e-002,-1.104084e-001,-3.923048e-002,-6.889735e-002,-2.246566e-006,-2.246566e-006,,,,,,,,,,,,,,,,,,,,
1432766995.923,,0.000000e+000,6.000444e+001,5.999565e+001,1,0,1.974304e+000,9.765923e-003,9.765923e-003,1.186499e-001,6.050201e-002,9.158161e-003,1.180421e-001,5.989425e-002,2.457782e-007,2.457782e-007,,,,,,,,,,,,,,,,,,,,
1432767006.899,,0.000000e+000,6.000972e+001,6.000092e+001,1,0,4.870070e+000,-3.967406e-002,-3.967406e-002,7.853356e-002,-8.579476e-003,-1.284684e-001,-1.026077e-002,-9.737381e-002,-9.984738e-007,-9.984738e-007,,,,,,,,,,,,,,,,,,,,
1432767017.365,,0.000000e+000,6.000269e+001,6.000269e+001,1,0,3.432007e+000,-2.711569e-001,-2.711570e-001,-1.169493e-001,-2.339530e-001,-1.988698e-001,-4.466210e-002,-1.616659e-001,-6.824184e-006,-6.824184e-006,,,,,,,,,,,,,,,,,,,,
1432767160.305,,0.000000e+000,5.999916e+001,5.999037e+001,1,0,3.640344e-001,-7.324442e-002,-7.324442e-002,-2.096491e-002,-4.369395e-002,-1.029284e-001,-5.064885e-002,-7.337789e-002,-1.843336e-006,-1.843336e-006,,,,,,,,,,,,,,,,,,,,
1432767171.380,,0.000000e+000,5.999037e+001,6.000269e+001,1,0,1.199645e+000,-6.347850e-002,-6.347850e-002,3.002466e-002,-1.941611e-002,-7.274775e-002,2.075541e-002,-2.868536e-002,-1.597558e-006,-1.597558e-006,,,,,,,,,,,,,,,,,,,,
1432767231.600,,0.000000e+000,5.894040e+001,5.854670e+001,1,0,4.317213e+000,-2.186651e-001,-2.186651e-001,-1.026117e-001,-2.007858e-001,-1.457568e-001,-2.970336e-002,-1.278775e-001,-5.503126e-006,-5.503126e-006,,,,,,,,,,,,,,,,,,,,
1432767242.815,,0.000000e+000,5.850811e+001,5.809678e+001,1,0,4.140712e+000,-3.308206e-001,-3.308206e-001,-1.413273e-001,-2.851106e-001,-2.306722e-001,-4.117888e-002,-1.849621e-001,-8.325735e-006,-8.325735e-006,,,,,,,,,,,,,,,,,,,,
1432767266.043,,0.000000e+000,5.752984e+001,5.712358e+001,1,0,1.061741e+000,-9.292886e-002,-9.292886e-002,-1.487560e-002,-3.513619e-002,-7.102475e-002,7.028515e-003,-1.323208e-002,-2.338733e-006,-2.338733e-006,,,,,,,,,,,,,,,,,,,,
1432767280.757,,0.000000e+000,5.689868e+001,5.650877e+001,1,0,5.489985e-001,-1.275674e-001,-1.275674e-001,4.999224e-003,-6.171266e-002,-2.025661e-001,-6.999952e-002,-1.367114e-001,-3.210477e-006,-3.210477e-006,,,,,,,,,,,,,,,,,,,,
1432767291.973,,0.000000e+000,5.642577e+001,5.599270e+001,1,0,3.525220e+000,-4.545732e-001,-4.545732e-001,-3.076487e-001,-4.271609e-001,-2.260858e-001,-7.916141e-002,-1.986735e-001,-1.144020e-005,-1.144020e-005,,,,,,,,,,,,,,,,,,,,
1432767302.941,,0.000000e+000,5.594651e+001,5.553714e+001,1,0,4.718783e+000,-1.458785e-001,-1.458785e-001,9.659687e-002,-7.283317e-002,-2.631780e-001,-2.070267e-002,-1.901327e-001,-3.671311e-006,-3.671311e-006,,,,,,,,,,,,,,,,,,,,
1432767326.372,,0.000000e+000,5.495011e+001,5.448919e+001,1,0,1.916095e+000,2.517777e-002,2.517777e-002,1.096683e-001,9.829806e-002,1.314408e-001,2.159314e-001,2.045611e-001,6.336468e-007,6.336468e-007,,,,,,,,,,,,,,,,,,,,
1432767337.034,,0.000000e+000,5.440596e+001,5.393030e+001,1,0,9.094546e-002,-1.470992e-001,-1.470992e-001,-1.745861e-002,-9.054996e-002,-2.174990e-001,-8.785842e-002,-1.609498e-001,-3.702033e-006,-3.702033e-006,,,,,,,,,,,,,,,,,,,,
1432767347.368,,0.000000e+000,5.393030e+001,5.344696e+001,1,0,2.635128e+000,-7.232887e-002,-7.232887e-002,1.214498e-001,-1.672903e-002,-1.047364e-001,8.904223e-002,-4.913659e-002,-1.820294e-006,-1.820294e-006,,,,,,,,,,,,,,,,,,,,
1432767357.867,,0.000000e+000,5.340611e+001,5.291639e+001,1,0,4.991439e+000,-4.425184e-003,-4.425184e-003,2.657329e-001,5.270866e-002,-2.870097e-001,-1.685171e-002,-2.298759e-001,-1.113682e-007,-1.113682e-007,,,,,,,,,,,,,,,,,,,,
1432767369.582,,0.000000e+000,5.285284e+001,5.235504e+001,1,0,2.812331e+000,-1.834162e-001,-1.834162e-001,1.722414e-001,-1.191520e-001,-3.158581e-001,3.979963e-002,-2.515938e-001,-4.616021e-006,-4.616021e-006,,,,,,,,,,,,,,,,,,,,
1432767391.519,,0.000000e+000,5.168294e+001,5.122523e+001,1,0,5.801245e-002,-2.099673e-001,-2.099673e-001,-3.952258e-002,-1.141165e-001,-2.813846e-001,-1.109399e-001,-1.855338e-001,-5.284230e-006,-5.284230e-006,,,,,,,,,,,,,,,,,,,,
1432767401.985,,0.000000e+000,5.117067e+001,5.069853e+001,1,0,1.767699e+000,2.288888e-002,2.288888e-002,2.687229e-001,1.084374e-001,4.171319e-002,2.875472e-001,1.272617e-001,5.760426e-007,5.760426e-007,,,,,,,,,,,,,,,,,,,,
1432767413.952,,0.000000e+000,5.058908e+001,5.004725e+001,1,0,4.766971e+000,-1.647999e-001,-1.648000e-001,1.685079e-001,-8.869215e-002,-3.642534e-001,-3.094548e-002,-2.881456e-001,-4.147506e-006,-4.147506e-006,,,,,,,,,,,,,,,,,,,,
1432767424.167,,0.000000e+000,4.999380e+001,4.954802e+001,1,0,3.621658e+000,-9.691153e-001,-9.691153e-001,-5.104416e-001,-8.815137e-001,-6.112876e-001,-1.526140e-001,-5.236860e-001,-2.438964e-005,-2.438964e-005,,,,,,,,,,,,,,,,,,,,
1432767445.347,,0.000000e+000,4.889211e+001,4.838048e+001,1,0,5.153558e-001,-2.368236e-001,-2.368236e-001,-6.124798e-002,-1.320372e-001,-3.320235e-001,-1.564479e-001,-2.272370e-001,-5.960120e-006,-5.960120e-006,,,,,,,,,,,,,,,,,,,,
1432767457.871,,0.000000e+000,4.825105e+001,4.768266e+001,1,0,1.026125e+000,-1.904355e-001,-1.904355e-001,1.017526e-001,-9.237771e-002,-2.698737e-001,2.231434e-002,-1.718160e-001,-4.792674e-006,-4.792674e-006,,,,,,,,,,,,,,,,,,,,
1432767468.796,,0.000000e+000,4.763729e+001,4.706158e+001,1,0,4.134645e+000,-1.015046e+000,-1.015046e+000,-5.878737e-001,-9.195396e-001,-5.476456e-001,-1.204737e-001,-4.521396e-001,-2.554557e-005,-2.554557e-005,,,,,,,,,,,,,,,,,,,,
1432767479.674,,0.000000e+000,4.699745e+001,4.647309e+001,1,0,4.301085e+000,-8.795434e-001,-8.795434e-001,-2.703741e-001,-7.709346e-001,-7.096525e-001,-1.004832e-001,-6.010438e-001,-2.213539e-005,-2.213539e-005,,,,,,,,,,,,,,,,,,,,
1432767502.127,,0.000000e+000,4.576385e+001,4.522126e+001,1,0,1.265371e+000,-1.620533e-001,-1.620533e-001,1.916424e-002,-4.595023e-002,3.479379e-002,2.160113e-001,1.508968e-001,-4.078381e-006,-4.078381e-006,,,,,,,,,,,,,,,,,,,,
1432767512.591,,0.000000e+000,4.517719e+001,4.462776e+001,1,0,4.100255e-001,-3.431806e-001,-3.431806e-001,1.850903e-002,-2.354641e-001,-6.465019e-001,-2.848122e-001,-5.387853e-001,-8.636798e-006,-8.636798e-006,,,,,,,,,,,,,,,,,,,,
1432767523.608,,0.000000e+000,4.451104e+001,4.397107e+001,1,0,3.308045e+000,-1.559496e+000,-1.559496e+000,-9.417343e-001,-1.430251e+000,-8.875281e-001,-2.697666e-001,-7.582831e-001,-3.924770e-005,-3.924770e-005,,,,,,,,,,,,,,,,,,,,
1432767534.323,,0.000000e+000,4.391185e+001,4.336951e+001,1,0,4.824084e+000,-2.497940e-001,-2.497940e-001,6.707729e-001,-1.003243e-001,-9.892896e-001,-6.872272e-002,-8.398199e-001,-6.286544e-006,-6.286544e-006,,,,,,,,,,,,,,,,,,,,
1432767557.018,,0.000000e+000,4.257656e+001,4.208128e+001,1,0,2.140839e+000,3.683584e-001,3.683584e-001,5.834743e-001,5.451267e-001,7.549275e-001,9.700435e-001,9.316958e-001,9.270445e-006,9.270445e-006,,,,,,,,,,,,,,,,,,,,
1432767567.733,,0.000000e+000,4.203040e+001,4.141074e+001,1,0,3.452846e-002,-6.678976e-001,-6.678976e-001,-8.959764e-002,-4.501556e-001,-1.022247e+000,-4.439473e-001,-8.045052e-001,-1.680892e-005,-1.680892e-005,,,,,,,,,,,,,,,,,,,,
1432767578.949,,0.000000e+000,4.141074e+001,4.077896e+001,1,0,2.409721e+000,1.676992e-001,1.676992e-001,1.117859e+000,3.718498e-001,-1.525552e-001,7.976049e-001,5.159537e-002,4.220472e-006,4.220472e-006,,,,,,,,,,,,,,,,,,,,
1432767590.915,,0.000000e+000,4.063810e+001,4.007170e+001,1,0,4.984648e+000,5.127110e-002,5.127110e-002,1.496105e+000,2.767201e-001,-1.533244e+000,-8.840989e-002,-1.307795e+000,1.290335e-006,1.290335e-006,,,,,,,,,,,,,,,,,,,,
1432767610.909,,0.000000e+000,3.948388e+001,3.891085e+001,1,0,3.026768e+000,-1.006500e+000,-1.006500e+000,2.704212e-002,-8.734328e-001,-1.143352e+000,-1.098093e-001,-1.010284e+000,-5.066102e-005,-5.066102e-005,,,,,,,,,,,,,,,,,,,,
1432767634.141,,0.000000e+000,3.812016e+001,3.752819e+001,1,0,1.315067e-001,-4.686117e-001,-4.686117e-001,-1.217564e-001,-3.328888e-001,-7.144106e-001,-3.675553e-001,-5.786877e-001,-2.358702e-005,-2.358702e-005,,,,,,,,,,,,,,,,,,,,
1432767645.355,,0.000000e+000,3.739235e+001,3.686848e+001,1,0,1.569454e+000,1.236000e-002,1.236000e-002,6.367639e-001,1.595379e-001,9.039148e-002,7.147954e-001,2.375693e-001,6.221260e-007,6.221260e-007,,,,,,,,,,,,,,,,,,,,
1432767655.589,,0.000000e+000,3.680405e+001,3.621616e+001,1,0,4.638060e+000,-7.377849e-001,-7.377850e-001,1.829779e-001,-5.819398e-001,-1.028058e+000,-1.072946e-001,-8.722124e-001,-3.713554e-005,-3.713554e-005,,,,,,,,,,,,,,,,,,,,
1432767667.554,,0.000000e+000,3.614049e+001,3.554177e+001,1,0,3.802283e+000,-2.821284e+000,-2.821284e+000,-1.575610e+000,-2.651100e+000,-1.639168e+000,-3.934944e-001,-1.468984e+000,-1.420060e-004,-1.420060e-004,,,,,,,,,,,,,,,,,,,,
1432767688.985,,0.000000e+000,3.479947e+001,3.427111e+001,1,0,6.845502e-001,-4.954680e-001,-4.954680e-001,-1.438921e-001,-3.228658e-001,-6.471100e-001,-2.955341e-001,-4.745078e-001,-2.493880e-005,-2.493880e-005,,,,,,,,,,,,,,,,,,,,
1432767700.389,,0.000000e+000,3.412350e+001,3.356658e+001,1,0,8.593287e-001,-4.736473e-001,-4.736473e-001,2.045807e-001,-2.899629e-001,-7.966634e-001,-1.184355e-001,-6.129790e-001,-2.384048e-005,-2.384048e-005,,,,,,,,,,,,,,,,,,,,
1432767711.462,,0.000000e+000,3.350126e+001,3.292972e+001,1,0,3.939770e+000,-3.021027e+000,-3.021027e+000,-2.010679e+000,-2.839112e+000,-1.396963e+000,-3.866148e-001,-1.215047e+000,-1.520599e-004,-1.520599e-004,,,,,,,,,,,,,,,,,,,,
1432767721.934,,0.000000e+000,3.279983e+001,3.235352e+001,1,0,4.451475e+000,-1.516465e+000,-1.516465e+000,-1.421876e-001,-1.320936e+000,-1.554373e+000,-1.800958e-001,-1.358845e+000,-7.632948e-005,-7.632948e-005,,,,,,,,,,,,,,,,,,,,
1432767744.304,,0.000000e+000,3.154648e+001,3.106418e+001,1,0,1.476072e+000,-9.567553e-002,-9.567553e-002,2.197097e-001,1.044215e-001,5.126071e-001,8.279923e-001,7.127041e-001,-4.815716e-006,-4.815716e-006,,,,,,,,,,,,,,,,,,,,
1432767755.127,,0.000000e+000,3.106418e+001,3.050468e+001,1,0,2.852849e-001,-6.697286e-001,-6.697287e-001,8.032560e-003,-4.636713e-001,-1.243052e+000,-5.652910e-001,-1.036995e+000,-3.371001e-005,-3.371001e-005,,,,,,,,,,,,,,,,,,,,
1432767766.172,,0.000000e+000,3.038161e+001,2.988432e+001,1,0,3.085959e+000,-1.973937e+000,-1.973937e+000,-9.158532e-001,-1.761128e+000,-1.325508e+000,-2.674239e-001,-1.112699e+000,-9.935582e-005,-9.935582e-005,,,,,,,,,,,,,,,,,,,,
1432767776.637,,0.000000e+000,2.976367e+001,2.928467e+001,1,0,4.910075e+000,-1.037629e-001,-1.037629e-001,1.345925e+000,1.113279e-001,-1.543887e+000,-9.419997e-002,-1.328797e+000,-5.222786e-006,-5.222786e-006,,,,,,,,,,,,,,,,,,,,
1432767800.089,,0.000000e+000,2.862378e+001,2.814786e+001,1,0,2.366527e+000,2.917570e-001,2.917570e-001,5.344266e-001,5.086933e-001,6.850598e-001,9.277294e-001,9.019962e-001,1.468524e-005,1.468524e-005,,,,,,,,,,,,,,,,,,,,
1432767810.608,,0.000000e+000,2.808879e+001,2.754566e+001,1,0,7.779540e-003,-7.721183e-001,-7.721183e-001,-1.288587e-001,-5.482447e-001,-1.177380e+000,-5.341209e-001,-9.535068e-001,-3.886367e-005,-3.886367e-005,,,,,,,,,,,,,,,,,,,,
1432767830.375,,0.000000e+000,2.699346e+001,2.655255e+001,1,0,2.189375e+000,2.008118e-001,2.008118e-001,6.317707e-001,2.954489e-001,7.754358e-002,5.085025e-001,1.721807e-001,2.526907e-005,2.526907e-005,,,,,,,,,,,,,,,,,,,,
1432767841.841,,0.000000e+000,2.636706e+001,2.592853e+001,1,0,4.943857e+000,-2.533036e-002,-2.533036e-002,5.819941e-001,7.442779e-002,-6.470793e-001,-3.975485e-002,-5.473212e-001,-3.187435e-006,-3.187435e-006,,,,,,,,,,,,,,,,,,,,
1432767852.806,,0.000000e+000,2.580914e+001,2.534184e+001,1,0,3.233915e+000,-1.153294e+000,-1.153294e+000,-3.730955e-001,-1.059072e+000,-9.800466e-001,-1.998476e-001,-8.858242e-001,-1.451243e-004,-1.451243e-004,,,,,,,,,,,,,,,,,,,,
1432767875.416,,0.000000e+000,2.463860e+001,2.390021e+001,1,0,2.343436e-001,-3.349406e-001,-3.349406e-001,-9.163523e-002,-2.312510e-001,-5.193477e-001,-2.760423e-001,-4.156580e-001,-4.214711e-005,-4.214711e-005,,,,,,,,,,,,,,,,,,,,
1432767886.987,,0.000000e+000,2.380611e+001,2.299923e+001,1,0,1.380454e+000,-9.048738e-002,-9.048738e-002,3.298366e-001,8.197196e-003,-6.923058e-002,3.510934e-001,2.945400e-002,-1.138644e-005,-1.138644e-005,,,,,,,,,,,,,,,,,,,,
1432767897.901,,0.000000e+000,2.296038e+001,2.266232e+001,1,0,4.486439e+000,-7.650990e-001,-7.650990e-001,-1.543664e-001,-6.600567e-001,-7.036592e-001,-9.292653e-002,-5.986168e-001,-9.627591e-005,-9.627591e-005,,,,,,,,,,,,,,,,,,,,
1432767908.473,,0.000000e+000,2.265613e+001,2.265957e+001,1,0,3.975284e+000,-1.666768e+000,-1.666768e+000,-8.730782e-001,-1.560819e+000,-1.002167e+000,-2.084773e-001,-8.962179e-001,-2.097371e-004,-2.097371e-004,,,,,,,,,,,,,,,,,,,,
1432767929.432,,0.000000e+000,2.252287e+001,2.149654e+001,1,0,8.673350e-001,-2.677999e-001,-2.677999e-001,-6.863382e-002,-1.672590e-001,-2.599505e-001,-6.078440e-002,-1.594096e-001,-3.369849e-005,-3.369849e-005,,,,,,,,,,,,,,,,,,,,
1432767941.666,,0.000000e+000,2.118369e+001,2.040817e+001,1,0,7.010989e-001,-3.106784e-001,-3.106784e-001,8.702259e-002,-2.041561e-001,-5.721081e-001,-1.744071e-001,-4.655858e-001,-3.909409e-005,-3.909409e-005,,,,,,,,,,,,,,,,,,,,
1432767952.631,,0.000000e+000,2.025490e+001,1.976755e+001,1,0,3.736693e+000,-1.954405e+000,-1.954405e+000,-1.361277e+000,-1.849517e+000,-8.787403e-001,-2.856122e-001,-7.738516e-001,-2.459318e-004,-2.459318e-004,,,,,,,,,,,,,,,,,,,,
1432767963.101,,0.000000e+000,1.976755e+001,1.969499e+001,1,0,4.592554e+000,-6.157109e-001,-6.157109e-001,1.766064e-001,-5.076883e-001,-8.755121e-001,-8.319481e-002,-7.674896e-001,-7.747772e-005,-7.747772e-005,,,,,,,,,,,,,,,,,,,,
1432767985.032,,0.000000e+000,1.969133e+001,1.891913e+001,1,0,1.693723e+000,9.216590e-002,9.216590e-002,2.502715e-001,1.981754e-001,4.815717e-001,6.396773e-001,5.875812e-001,1.159766e-005,1.159766e-005,,,,,,,,,,,,,,,,,,,,
1432767997.246,,0.000000e+000,1.860722e+001,1.771294e+001,1,0,1.760686e-001,-3.825495e-001,-3.825495e-001,-1.644292e-002,-2.704783e-001,-6.779487e-001,-3.118421e-001,-5.658775e-001,-4.813795e-005,-4.813795e-005,,,,,,,,,,,,,,,,,,,,
1432768008.734,,0.000000e+000,1.764260e+001,1.698209e+001,1,0,2.860566e+000,-6.460769e-001,-6.460769e-001,-6.847478e-002,-5.318426e-001,-5.538758e-001,2.372627e-002,-4.396415e-001,-8.129881e-005,-8.129881e-005,,,,,,,,,,,,,,,,,,,,
1432768019.450,,0.000000e+000,1.687203e+001,1.654318e+001,1,0,4.966506e+000,2.639851e-002,2.639851e-002,8.173323e-001,1.442313e-001,-8.385612e-001,-4.762744e-002,-7.207284e-001,3.321845e-006,3.321845e-006,,,,,,,,,,,,,,,,,,,,
1432768041.628,,0.000000e+000,1.651092e+001,1.647326e+001,1,0,2.591072e+000,-1.350444e-001,-1.350444e-001,-1.394603e-002,-1.394603e-002,1.542626e-001,2.753610e-001,2.753610e-001,-1.699326e-005,-1.699326e-005,,,,,,,,,,,,,,,,,,,,
1432768052.474,,0.000000e+000,1.645670e+001,1.535472e+001,1,0,1.645150e-002,-4.028443e-001,-4.028443e-001,-8.213986e-002,-2.921146e-001,-6.088114e-001,-2.881069e-001,-4.980816e-001,-5.069174e-005,-5.069174e-005,,,,,,,,,,,,,,,,,,,,
1432768062.939,,0.000000e+000,1.535472e+001,1.416962e+001,1,0,1.974296e+000,2.702414e-001,2.702414e-001,8.204993e-001,3.909866e-001,2.257506e-001,7.760085e-001,3.464958e-001,3.400571e-005,3.400571e-005,,,,,,,,,,,,,,,,,,,,
1432768075.195,,0.000000e+000,1.398533e+001,1.354805e+001,1,0,4.869734e+000,-1.483200e-001,-1.483200e-001,6.363668e-001,-2.002034e-002,-8.433712e-001,-5.868446e-002,-7.150716e-001,-1.866378e-005,-1.866378e-005,,,,,,,,,,,,,,,,,,,,
1432768085.660,,0.000000e+000,1.351076e+001,1.325844e+001,1,0,3.432220e+000,-1.915952e+000,-1.915952e+000,-9.257607e-001,-1.798330e+000,-1.327299e+000,-3.371074e-001,-1.209677e+000,-2.410930e-004,-2.410930e-004,,,,,,,,,,,,,,,,,,,,
1432768107.092,,0.000000e+000,1.340911e+001,1.385558e+001,1,0,3.635399e-001,-3.920102e-001,-3.920102e-001,-1.169160e-001,-2.752350e-001,-6.173629e-001,-3.422687e-001,-5.005877e-001,-4.932844e-005,-4.932844e-005,,,,,,,,,,,,,,,,,,,,
1432768117.868,,0.000000e+000,1.398123e+001,1.450369e+001,1,0,1.199409e+000,-1.893674e-001,-1.893674e-001,2.867603e-001,-8.249941e-002,-2.369052e-001,2.392224e-001,-1.300372e-001,-2.382896e-005,-2.382896e-005,,,,,,,,,,,,,,,,,,,,
1432768132.366,,0.000000e+000,1.463572e+001,1.531961e+001,1,0,4.317616e+000,-1.238746e+000,-1.238746e+000,-5.639037e-001,-1.136224e+000,-8.189035e-001,-1.440609e-001,-7.163814e-001,-1.558771e-004,-1.558771e-004,,,,,,,,,,,,,,,,,,,,
1432768143.331,,0.000000e+000,1.531961e+001,1.537170e+001,1,0,4.141438e+000,-1.598102e+000,-1.598102e+000,-7.193766e-001,-1.496350e+000,-1.069398e+000,-1.906728e-001,-9.676462e-001,-2.010965e-004,-2.010965e-004,,,,,,,,,,,,,,,,,,,,
1432768164.788,,0.000000e+000,1.514365e+001,1.492501e+001,1,0,1.061506e+000,-2.540666e-001,-2.540666e-001,-3.649731e-002,-1.352242e-001,-1.148834e-001,1.026858e-001,3.958948e-003,-3.197036e-005,-3.197036e-005,,,,,,,,,,,,,,,,,,,,
1432768175.253,,0.000000e+000,1.492501e+001,1.491275e+001,1,0,5.495968e-001,-3.785821e-001,-3.785821e-001,6.145614e-002,-2.520236e-001,-7.211719e-001,-2.811337e-001,-5.946134e-001,-4.763872e-005,-4.763872e-005,,,,,,,,,,,,,,,,,,,,
1432768242.006,,0.000000e+000,1.499789e+001,1.500033e+001,1,0,3.524794e+000,-2.021851e+000,-2.021851e+000,-1.380807e+000,-1.906505e+000,-9.800622e-001,-3.390182e-001,-8.647161e-001,-2.544188e-004,-2.544188e-004,,,,,,,,,,,,,,,,,,,,
1432768252.721,,0.000000e+000,1.500125e+001,1.500125e+001,1,0,4.715208e+000,-4.206977e-001,-4.206977e-001,4.347074e-001,-3.030615e-001,-9.294351e-001,-7.403009e-002,-8.117989e-001,-5.293831e-005,-5.293831e-005,,,,,,,,,,,,,,,,,,,,
1432768274.404,,0.000000e+000,1.500064e+001,1.500125e+001,1,0,1.915427e+000,2.458266e-001,2.458266e-001,3.989147e-001,3.564665e-001,6.222289e-001,7.753170e-001,7.328688e-001,3.093348e-005,3.093348e-005,,,,,,,,,,,,,,,,,,,,
1432768285.370,,0.000000e+000,1.500033e+001,1.500003e+001,1,0,9.124696e-002,-4.065065e-001,-4.065065e-001,-3.752986e-002,-2.913758e-001,-6.817752e-001,-3.127985e-001,-5.666444e-001,-5.115258e-005,-5.115258e-005,,,,,,,,,,,,,,,,,,,,
1432768296.335,,0.000000e+000,1.500003e+001,1.499942e+001,1,0,2.634890e+000,-2.346873e-001,-2.346873e-001,3.446240e-001,-1.210938e-001,-3.393824e-001,2.399289e-001,-2.257889e-001,-2.953178e-005,-2.953178e-005,,,,,,,,,,,,,,,,,,,,
1432768364.147,,0.000000e+000,1.500033e+001,1.500308e+001,1,0,4.992860e+000,5.966369e-002,5.966369e-002,8.529292e-001,1.748869e-001,-8.404672e-001,-4.720160e-002,-7.252440e-001,7.507755e-006,7.507755e-006,,,,,,,,,,,,,,,,,,,,
1432768374.362,,0.000000e+000,1.500278e+001,1.500217e+001,1,0,2.812570e+000,-5.499436e-001,-5.499436e-001,4.714969e-001,-4.228998e-001,-9.530242e-001,6.841626e-002,-8.259805e-001,-6.920191e-005,-6.920191e-005,,,,,,,,,,,,,,,,,,,,
1432768497.302,,0.000000e+000,1.283247e+001,1.266984e+001,1,0,5.704001e-002,-4.315317e-001,-4.315317e-001,-9.903216e-002,-3.050766e-001,-6.481240e-001,-3.156244e-001,-5.216689e-001,-5.430161e-005,-5.430161e-005,,,,,,,,,,,,,,,,,,,,
1432768612.036,,0.000000e+000,1.097400e+001,1.084986e+001,1,0,1.767771e+000,1.652577e-001,1.652577e-001,7.366332e-001,2.977625e-001,2.178124e-001,7.891880e-001,3.503172e-001,2.079514e-005,2.079514e-005,,,,,,,,,,,,,,,,,,,,
1432768622.501,,0.000000e+000,1.082132e+001,1.069382e+001,1,0,4.767390e+000,-3.489791e-001,-3.489791e-001,4.485040e-001,-2.184352e-001,-8.701939e-001,-7.271072e-002,-7.396500e-001,-4.391364e-005,-4.391364e-005,,,,,,,,,,,,,,,,,,,,
1432768739.255,,0.000000e+000,8.956869e+000,8.852446e+000,1,0,3.621253e+000,-2.296518e+000,-2.296518e+000,-1.281367e+000,-2.190329e+000,-1.382948e+000,-3.677977e-001,-1.276760e+000,-2.889813e-004,-2.889813e-004,,,,,,,,,,,,,,,,,,,,
1432768858.249,,0.000000e+000,6.994549e+000,6.870017e+000,1,0,5.153501e-001,-4.142888e-001,-4.142888e-001,-1.266640e-001,-2.859546e-001,-6.193312e-001,-3.317064e-001,-4.909970e-001,-5.213185e-005,-5.213185e-005,,,,,,,,,,,,,,,,,,,,
1432768870.499,,0.000000e+000,6.828929e+000,6.677297e+000,1,0,1.025091e+000,-3.015229e-001,-3.015229e-001,2.282597e-001,-1.703858e-001,-4.530767e-001,7.670581e-002,-3.219396e-001,-3.794200e-005,-3.794200e-005,,,,,,,,,,,,,,,,,,,,
1432769133.842,,0.000000e+000,5.000457e+000,5.004790e+000,1,0,4.134298e+000,-1.903287e+000,-1.903287e+000,-1.120226e+000,-1.768839e+000,-1.005571e+000,-2.225101e-001,-8.711226e-001,-2.394993e-004,-2.394993e-004,,,,,,,,,,,,,,,,,,,,
1432769144.057,,0.000000e+000,5.004790e+000,5.003922e+000,1,0,4.300714e+000,-1.481368e+000,-1.481368e+000,-4.543913e-001,-1.346342e+000,-1.197478e+000,-1.705006e-001,-1.062452e+000,-1.864074e-004,-1.864074e-004,,,,,,,,,,,,,,,,,,,,
1432769144.057,,0.000000e+000,5.004790e+000,5.003922e+000,1,0,2.812608e+000,-6.183050e-001,-6.183050e-001,5.384104e-001,-4.832790e-001,-1.077453e+000,7.926233e-002,-9.424272e-001,-7.780414e-005,-7.780414e-005,,,,,,,,,,,,,,,,,,,,