File: data/A269/A269_GdN_MH_35K_150528.rso.raw
[Header]
TITLE,MPMS RSO Measurement
BYAPP,MPMS Measurement,2.1,Raw with ABS
FILEOPENTIME, 1432813180.534000 5/28/2015, 11:39:40 PM

INFO, APPNAME, MPMS MultiVu Application, Revision 1.61,  Build 082

INFO, NAME, A269
INFO, WEIGHT, 22.300
INFO, AREA, 1.000
INFO, LENGTH, 1.000
INFO, SHAPE, 1
INFO, COMMENT, m = 0.0223g
INFO, SEQUENCE FILE: 7T_hysteresis_sweep.seq


INFO, BACKGROUND DATA FILE:, None


STARTUPAXIS,X,8,LINEAR,AUTO,0.000000,0.000000
STARTUPAXIS,Y1,9,LINEAR,AUTO,0.000000,0.000000


STARTUPGROUP,Longitudinal
FIELDGROUP,Longitudinal,1,2,3,4,5,6,7,8,9,10,11,12,13,14,15,16,17,18,19,20,21,22
FIELDGROUP,Transverse,1,2,3,4,5,6,7,8,23,24,25,26,27,28,29,30,31,32,33,34,35,36

PLOT_APPEARANCE,ALL,HORZ_GRID_ON,VERT_GRID_ON,MARKERS_ONLY

[Data]
Time,Comment,Field (Oe),Start Temperature (K),End Temperature (K),Scan,Rejected,Position (cm),Long Voltage,Long Average Voltage,Long Detrended Voltage,Long Demeaned Voltage,Long Reg Fit,Long Detrended Fit,Long Demeaned Fit,Long Scaled Response,Long Avg. Scaled Response,Long Background Response,Long Response [w/ABS],Long Detrended Resp. [w/ABS],Long Fit [w/ABS],Long Detrended Fit [w/ABS],Trans Voltage,Trans Average Voltage,Trans Detrended Voltage,Trans Demeaned Voltage,Trans Reg Fit,Trans Detrended Fit,Trans Demeaned Fit,Trans Scaled Response,Trans Avg. Scaled Response,Trans Background Response,Trans Response [w/ABS],Trans Detrended Resp. [w/ABS],Trans Adjusted Fit,Trans Detrended Fit [w/ABS],
1432813180.493,,7.000000e+004,3.502243e+001,3.501927e+001,1,0,2.591359e+000,2.180547e-001,2.180548e-001,2.736107e-003,2.736107e-003,-1.808012e-001,-3.961198e-001,-3.961198e-001,1.092982e-003,1.092982e-003,,,,,,,,,,,,,,,,,,,,
1432813180.493,,7.000000e+004,3.502243e+001,3.501927e+001,1,0,4.317506e+000,1.790521e+000,1.790521e+000,7.850815e-001,1.575202e+000,1.205682e+000,2.002428e-001,9.903635e-001,8.974841e-003,8.974841e-003,,,,,,,,,,,,,,,,,,,,
1432813190.708,,7.000000e+004,3.502243e+001,3.501770e+001,1,0,9.299193e-002,6.228828e-001,6.228828e-001,5.918734e-002,4.056610e-001,9.901872e-001,4.264917e-001,7.729654e-001,3.122149e-003,3.122149e-003,,,,,,,,,,,,,,,,,,,,
1432813190.708,,7.000000e+004,3.502243e+001,3.501770e+001,1,0,3.621262e+000,2.929624e+000,2.929624e+000,1.576739e+000,2.712403e+000,1.812774e+000,4.598882e-001,1.595552e+000,1.468450e-002,1.468450e-002,,,,,,,,,,,,,,,,,,,,
1432813360.641,,6.000000e+004,3.500039e+001,3.499881e+001,1,0,3.308278e+000,1.997894e+000,1.997894e+000,1.286332e+000,1.906108e+000,1.079860e+000,3.682975e-001,9.880733e-001,1.002027e-002,1.002027e-002,,,,,,,,,,,,,,,,,,,,
1432813370.714,,6.000000e+004,3.499881e+001,3.500353e+001,1,0,1.313636e-001,5.388043e-001,5.388043e-001,1.400340e-001,3.641130e-001,8.100148e-001,4.112445e-001,6.353235e-001,2.702326e-003,2.702326e-003,,,,,,,,,,,,,,,,,,,,
1432813370.714,,6.000000e+004,3.499881e+001,3.500353e+001,1,0,4.450495e+000,1.220588e+000,1.220588e+000,1.151069e-001,1.045896e+000,1.255099e+000,1.496177e-001,1.080407e+000,6.121753e-003,6.121753e-003,,,,,,,,,,,,,,,,,,,,
1432813531.977,,5.000000e+004,3.500039e+001,3.500196e+001,1,0,2.189289e+000,-4.535050e-001,-4.535050e-001,-9.779748e-001,-4.955591e-001,-2.702750e-001,-7.947448e-001,-3.123291e-001,-2.275874e-003,-2.275874e-003,,,,,,,,,,,,,,,,,,,,
1432813542.442,,5.000000e+004,3.500039e+001,3.500196e+001,1,0,8.668551e-001,2.850429e-001,2.850429e-001,9.391252e-002,2.185140e-001,2.779062e-001,8.677582e-002,2.113773e-001,1.430462e-003,1.430462e-003,,,,,,,,,,,,,,,,,,,,
1432813542.442,,5.000000e+004,3.500039e+001,3.500196e+001,1,0,4.967113e+000,-1.567125e-001,-1.567125e-001,-9.864256e-001,-2.232414e-001,8.882895e-001,5.857641e-002,8.217606e-001,-7.864477e-004,-7.864477e-004,,,,,,,,,,,,,,,,,,,,
1432813695.171,,4.000000e+004,3.500039e+001,3.500196e+001,1,0,1.199941e+000,3.738517e-002,3.738517e-002,-3.089702e-001,5.247357e-002,9.161654e-002,-2.547388e-001,1.067049e-001,1.877260e-004,1.877260e-004,,,,,,,,,,,,,,,,,,,,
1432813705.590,,4.000000e+004,3.500196e+001,3.500196e+001,1,0,1.914953e+000,-3.224280e-001,-3.224280e-001,-4.303955e-001,-3.885537e-001,-7.304770e-001,-8.384444e-001,-7.966026e-001,-1.619041e-003,-1.619041e-003,,,,,,,,,,,,,,,,,,,,
1432813705.590,,4.000000e+004,3.500196e+001,3.500196e+001,1,0,4.767283e+000,2.299570e-001,2.299570e-001,-4.498480e-001,1.638314e-001,7.534090e-001,7.360396e-002,6.872833e-001,1.154707e-003,1.154707e-003,,,,,,,,,,,,,,,,,,,,
1432813862.927,,3.000000e+004,3.500039e+001,3.499881e+001,1,0,4.100220e-001,3.012177e-001,3.012177e-001,-4.056238e-002,2.312760e-001,6.545140e-001,3.127339e-001,5.845724e-001,1.513438e-003,1.513438e-003,,,,,,,,,,,,,,,,,,,,
1432813862.927,,3.000000e+004,3.500039e+001,3.499881e+001,1,0,3.026505e+000,8.551286e-001,8.551286e-001,-1.738355e-002,7.851870e-001,9.882165e-001,1.157043e-001,9.182748e-001,4.296507e-003,4.296507e-003,,,,,,,,,,,,,,,,,,,,
1432813873.142,,3.000000e+004,3.499881e+001,3.500039e+001,1,0,3.940157e+000,1.782891e+000,1.782891e+000,1.291450e+000,1.770453e+000,7.389579e-001,2.475164e-001,7.265197e-001,8.957957e-003,8.957957e-003,,,,,,,,,,,,,,,,,,,,
1432814028.154,,2.000000e+004,3.499881e+001,3.500196e+001,1,0,8.705760e-003,1.393170e-001,1.393170e-001,5.846338e-002,2.197848e-001,3.220980e-001,2.412444e-001,4.025658e-001,7.004013e-004,7.004013e-004,,,,,,,,,,,,,,,,,,,,
1432814028.154,,2.000000e+004,3.499881e+001,3.500196e+001,1,0,3.974941e+000,1.345256e+000,1.345256e+000,8.510160e-001,1.425724e+000,6.980813e-001,2.038414e-001,7.785491e-001,6.763130e-003,6.763130e-003,,,,,,,,,,,,,,,,,,,,
1432814038.322,,2.000000e+004,3.500196e+001,3.500039e+001,1,0,2.861585e+000,3.242592e-001,3.242592e-001,5.856986e-002,4.083735e-001,2.443155e-001,-2.137381e-002,3.284298e-001,1.630178e-003,1.630178e-003,,,,,,,,,,,,,,,,,,,,
1432814185.609,,1.000000e+004,3.500039e+001,3.500196e+001,1,0,3.633651e-001,3.250221e-002,3.250221e-002,7.512565e-002,1.566493e-001,1.798217e-001,2.224451e-001,3.039688e-001,1.634987e-004,1.634987e-004,,,,,,,,,,,,,,,,,,,,
1432814185.609,,1.000000e+004,3.500039e+001,3.500196e+001,1,0,4.717539e+000,-3.067110e-002,-3.067110e-002,-2.919084e-001,9.347595e-002,3.103941e-001,4.915681e-002,4.345412e-001,-1.542876e-004,-1.542876e-004,,,,,,,,,,,,,,,,,,,,
1432814195.634,,1.000000e+004,3.500039e+001,3.500039e+001,1,0,1.767969e+000,-3.143407e-001,-3.143407e-001,-4.588527e-001,-2.355050e-001,-3.459851e-001,-4.904972e-001,-2.671495e-001,-1.581255e-003,-1.581255e-003,,,,,,,,,,,,,,,,,,,,
1432814312.675,,9.000000e+003,3.500196e+001,3.499881e+001,1,0,1.264676e+000,5.310221e-002,5.310221e-002,-1.861528e-002,2.898989e-002,-1.211072e-001,-1.928247e-001,-1.452195e-001,2.671406e-004,2.671406e-004,,,,,,,,,,,,,,,,,,,,
1432814312.675,,9.000000e+003,3.500196e+001,3.499881e+001,1,0,4.985667e+000,-1.344340e-001,-1.344340e-001,-5.314535e-001,-1.585464e-001,4.277477e-001,3.072822e-002,4.036354e-001,-6.762956e-004,-6.762956e-004,,,,,,,,,,,,,,,,,,,,
1432814322.747,,9.000000e+003,3.500196e+001,3.499881e+001,1,0,8.596932e-001,1.080355e-001,1.080355e-001,-9.412653e-002,9.428685e-002,2.520406e-001,4.987856e-002,2.382919e-001,5.434930e-004,5.434930e-004,,,,,,,,,,,,,,,,,,,,
1432814442.676,,7.000000e+003,3.499881e+001,3.499724e+001,1,0,2.366678e+000,-2.107303e-001,-2.107303e-001,-1.740112e-001,-1.669165e-001,-3.412917e-001,-3.045726e-001,-2.974779e-001,-1.060245e-003,-1.060245e-003,,,,,,,,,,,,,,,,,,,,
1432814442.676,,7.000000e+003,3.499881e+001,3.499724e+001,1,0,4.487050e+000,3.633229e-001,3.633229e-001,1.091602e-001,4.071367e-001,3.192764e-001,6.511366e-002,3.630902e-001,1.827981e-003,1.827981e-003,,,,,,,,,,,,,,,,,,,,
1432814452.700,,7.000000e+003,3.500039e+001,3.499881e+001,1,0,1.773361e-001,6.637776e-002,6.637776e-002,8.093636e-003,1.455379e-001,2.551291e-001,1.968450e-001,3.342892e-001,3.339655e-004,3.339655e-004,,,,,,,,,,,,,,,,,,,,
1432814452.700,,7.000000e+003,3.500039e+001,3.499881e+001,1,0,3.432127e+000,8.961760e-001,8.961760e-001,5.413017e-001,9.753361e-001,5.503871e-001,1.955129e-001,6.295472e-001,4.508918e-003,4.508918e-003,,,,,,,,,,,,,,,,,,,,
1432814572.485,,5.000000e+003,3.499881e+001,3.499881e+001,1,0,3.525791e+000,9.233375e-001,9.233375e-001,7.510455e-001,9.832614e-001,3.551005e-001,1.828084e-001,4.150244e-001,4.646129e-003,4.646129e-003,,,,,,,,,,,,,,,,,,,,
1432814582.759,,5.000000e+003,3.500039e+001,3.500353e+001,1,0,5.684927e-002,1.629688e-001,1.629688e-001,5.003082e-002,1.406690e-001,2.766952e-001,1.637572e-001,2.543954e-001,8.200406e-004,8.200406e-004,,,,,,,,,,,,,,,,,,,,
1432814582.759,,5.000000e+003,3.500039e+001,3.500353e+001,1,0,4.300593e+000,5.937376e-001,5.937376e-001,2.153592e-001,5.714378e-001,4.589475e-001,8.056908e-002,4.366477e-001,2.987620e-003,2.987620e-003,,,,,,,,,,,,,,,,,,,,
1432814702.374,,3.000000e+003,3.500039e+001,3.499881e+001,1,0,2.409633e+000,-8.194220e-002,-8.194220e-002,-3.087885e-001,-1.299199e-001,1.133703e-002,-2.155093e-001,-3.664073e-002,-4.123728e-004,-4.123728e-004,,,,,,,,,,,,,,,,,,,,
1432814712.838,,3.000000e+003,3.499881e+001,3.500039e+001,1,0,6.836297e-001,1.470992e-001,1.470992e-001,4.703032e-002,9.743907e-002,1.957805e-001,9.571161e-002,1.461204e-001,7.402745e-004,7.402745e-004,,,,,,,,,,,,,,,,,,,,
1432814712.838,,3.000000e+003,3.499881e+001,3.500039e+001,1,0,4.910746e+000,-2.868740e-002,-2.868740e-002,-3.583962e-001,-7.834753e-002,3.545326e-001,2.482386e-002,3.048725e-001,-1.443689e-004,-1.443689e-004,,,,,,,,,,,,,,,,,,,,
1432814832.363,,1.000000e+003,3.500196e+001,3.500196e+001,1,0,1.380521e+000,-6.759850e-002,-6.759850e-002,-1.199954e-001,-3.206317e-002,-7.496451e-002,-1.273614e-001,-3.942918e-002,-3.402289e-004,-3.402289e-004,,,,,,,,,,,,,,,,,,,,
1432814842.828,,1.000000e+003,3.500196e+001,3.500039e+001,1,0,1.692926e+000,-8.743553e-002,-8.743553e-002,-7.992680e-002,-6.483518e-002,-2.200872e-001,-2.125785e-001,-1.974869e-001,-4.400703e-004,-4.400703e-004,,,,,,,,,,,,,,,,,,,,
1432814842.828,,1.000000e+003,3.500196e+001,3.500039e+001,1,0,4.870530e+000,-4.440443e-002,-4.440443e-002,-1.915849e-001,-2.180408e-002,1.648316e-001,1.765112e-002,1.874320e-001,-2.234912e-004,-2.234912e-004,,,,,,,,,,,,,,,,,,,,
1432814961.529,,5.000000e+002,3.500039e+001,3.500039e+001,1,0,5.493484e-001,6.607257e-002,6.607258e-002,-6.068364e-002,1.642925e-001,3.786103e-001,2.518541e-001,4.768302e-001,8.313967e-005,8.313967e-005,,,,,,,,,,,,,,,,,,,,
1432814961.529,,5.000000e+002,3.500039e+001,3.500039e+001,1,0,2.811752e+000,1.118503e-001,1.118503e-001,-4.341795e-001,2.100703e-001,4.811617e-001,-6.486823e-002,5.793816e-001,1.407422e-004,1.407422e-004,,,,,,,,,,,,,,,,,,,,
1432814972.054,,5.000000e+002,3.500196e+001,3.500196e+001,1,0,4.135629e+000,1.403241e+000,1.403241e+000,8.877024e-001,1.353574e+000,6.893389e-001,1.738003e-001,6.396719e-001,1.765710e-003,1.765710e-003,,,,,,,,,,,,,,,,,,,,
1432815075.836,,4.000000e+002,3.499881e+001,3.500196e+001,1,0,3.447017e-002,3.981140e-001,3.981140e-001,3.795176e-002,2.053899e-001,5.979729e-001,2.378107e-001,4.052488e-001,5.009531e-004,5.009531e-004,,,,,,,,,,,,,,,,,,,,
1432815075.836,,4.000000e+002,3.499881e+001,3.500196e+001,1,0,3.801827e+000,1.736503e+000,1.736503e+000,9.725196e-001,1.543779e+000,1.003374e+000,2.393906e-001,8.106502e-001,2.185069e-003,2.185069e-003,,,,,,,,,,,,,,,,,,,,
1432815085.909,,4.000000e+002,3.500039e+001,3.500039e+001,1,0,3.086973e+000,6.825465e-001,6.825464e-001,4.405665e-001,7.818319e-001,3.687268e-001,1.267469e-001,4.680123e-001,8.588590e-004,8.588590e-004,,,,,,,,,,,,,,,,,,,,
1432815190.132,,3.000000e+002,3.500196e+001,3.500039e+001,1,0,2.341321e-001,1.071200e-001,1.071200e-001,7.368328e-002,1.724178e-001,2.665359e-001,2.330992e-001,3.318337e-001,1.347915e-004,1.347915e-004,,,,,,,,,,,,,,,,,,,,
1432815190.132,,3.000000e+002,3.500196e+001,3.500039e+001,1,0,4.591183e+000,2.360607e-001,2.360607e-001,-1.347190e-001,3.013585e-001,4.343400e-001,6.356037e-002,4.996379e-001,2.970406e-004,2.970406e-004,,,,,,,,,,,,,,,,,,,,
1432815200.432,,3.000000e+002,3.500196e+001,3.500196e+001,1,0,1.974882e+000,-3.494369e-001,-3.494369e-001,-5.669872e-001,-3.086099e-001,-3.163604e-001,-5.339106e-001,-2.755333e-001,-4.397046e-004,-4.397046e-004,,,,,,,,,,,,,,,,,,,,
1432815305.608,,2.000000e+002,3.499881e+001,3.500196e+001,1,0,1.061269e+000,-1.060518e-001,-1.060518e-001,2.212230e-002,6.820300e-002,-1.834760e-001,-5.530190e-002,-9.221196e-003,-1.334483e-004,-1.334483e-004,,,,,,,,,,,,,,,,,,,,
1432815305.608,,2.000000e+002,3.499881e+001,3.500196e+001,1,0,4.992708e+000,-3.436384e-001,-3.436384e-001,-4.853655e-001,-1.693836e-001,1.683239e-001,2.659675e-002,3.425787e-001,-4.324108e-004,-4.324108e-004,,,,,,,,,,,,,,,,,,,,
1432815315.931,,2.000000e+002,3.500039e+001,3.500353e+001,1,0,1.027493e+000,-1.297037e-002,-1.297037e-002,-1.141146e-001,6.099665e-002,6.292827e-002,-3.821601e-002,1.368953e-001,-1.632101e-005,-1.632101e-005,,,,,,,,,,,,,,,,,,,,
1432815420.154,,1.000000e+002,3.499724e+001,3.500196e+001,1,0,2.140284e+000,-2.119510e-001,-2.119510e-001,-1.612989e-001,-1.523993e-001,-3.232379e-001,-2.725857e-001,-2.636862e-001,-2.667061e-004,-2.667061e-004,,,,,,,,,,,,,,,,,,,,
1432815420.154,,1.000000e+002,3.499724e+001,3.500196e+001,1,0,4.638086e+000,7.003998e-002,7.003998e-002,-6.174893e-002,1.295917e-001,1.647481e-001,3.295922e-002,2.242999e-001,8.813398e-005,8.813398e-005,,,,,,,,,,,,,,,,,,,,
1432815430.070,,1.000000e+002,3.500196e+001,3.500196e+001,1,0,2.828794e-001,1.689200e-001,1.689200e-001,-5.999682e-003,8.489471e-002,3.073696e-001,1.324500e-001,2.233444e-001,2.125584e-004,2.125584e-004,,,,,,,,,,,,,,,,,,,,
1432815430.070,,1.000000e+002,3.500196e+001,3.500196e+001,1,0,3.233256e+000,5.516220e-001,5.516220e-001,1.903689e-001,4.675968e-001,4.591458e-001,9.789262e-002,3.751205e-001,6.941271e-004,6.941271e-004,,,,,,,,,,,,,,,,,,,,
1432815543.871,,0.000000e+000,3.499881e+001,3.500039e+001,1,0,3.736092e+000,3.883480e-001,3.883480e-001,1.102334e+000,1.160363e+000,-4.838848e-001,2.301015e-001,2.881299e-001,9.773522e-005,9.773522e-005,,,,,,,,,,,,,,,,,,,,
1432815554.140,,0.000000e+000,3.500039e+001,3.499881e+001,1,0,1.730719e-002,-7.539598e-001,-7.539598e-001,4.481448e-002,7.805306e-002,-5.917369e-001,2.070373e-001,2.402759e-001,-1.897484e-004,-1.897484e-004,,,,,,,,,,,,,,,,,,,,
1432815554.140,,0.000000e+000,3.500039e+001,3.499881e+001,1,0,4.140211e+000,-1.835688e-001,-1.835688e-001,5.243533e-001,6.484440e-001,-5.716019e-001,1.363202e-001,2.604109e-001,-4.619861e-005,-4.619861e-005,,,,,,,,,,,,,,,,,,,,
1432815658.915,,-1.000000e+002,3.499881e+001,3.499881e+001,1,0,2.635099e+000,-1.305277e+000,-1.305277e+000,2.821452e-001,-3.332552e-001,-1.387548e+000,1.998736e-001,-4.155267e-001,-3.284959e-004,-3.284959e-004,,,,,,,,,,,,,,,,,,,,
1432815669.629,,-1.000000e+002,3.499881e+001,3.500039e+001,1,0,5.149893e-001,-1.228065e+000,-1.228065e+000,-1.003188e-001,-2.923325e-001,-1.373380e+000,-2.456338e-001,-4.376475e-001,-3.090642e-004,-3.090642e-004,,,,,,,,,,,,,,,,,,,,
1432815669.629,,-1.000000e+002,3.499881e+001,3.500039e+001,1,0,4.825458e+000,-1.398663e+000,-1.398663e+000,5.163388e-001,-4.629310e-001,-1.966527e+000,-5.152475e-002,-1.030795e+000,-3.519983e-004,-3.519983e-004,,,,,,,,,,,,,,,,,,,,
1432815789.192,,-2.000000e+002,3.500039e+001,3.499881e+001,1,0,1.569652e+000,-4.547258e-002,-4.547258e-002,2.239407e-001,4.409425e-002,-1.700660e-002,2.524067e-001,7.256024e-002,-5.721955e-005,-5.721955e-005,,,,,,,,,,,,,,,,,,,,
1432815799.224,,-2.000000e+002,3.499881e+001,3.499881e+001,1,0,1.475897e+000,9.033479e-002,9.033479e-002,5.461878e-002,2.294967e-002,2.517449e-001,2.160289e-001,1.843597e-001,1.136710e-004,1.136710e-004,,,,,,,,,,,,,,,,,,,,
1432815799.224,,-2.000000e+002,3.499881e+001,3.499881e+001,1,0,4.944468e+000,9.598071e-002,9.598071e-002,3.199515e-001,2.859559e-002,-2.458170e-001,-2.184624e-002,-3.132021e-001,1.207755e-004,1.207755e-004,,,,,,,,,,,,,,,,,,,,
1432815897.250,,-3.000000e+002,3.499881e+001,3.499881e+001,1,0,7.030800e-001,-5.313272e-001,-5.313272e-001,5.932020e-002,-1.783149e-001,-7.106113e-001,-1.199638e-001,-3.575989e-001,-6.685814e-004,-6.685814e-004,,,,,,,,,,,,,,,,,,,,
1432815907.214,,-3.000000e+002,3.500039e+001,3.500039e+001,1,0,2.591215e+000,-2.676473e-001,-2.676473e-001,-8.075565e-003,-8.075565e-003,-8.498631e-002,1.745855e-001,1.745855e-001,-3.367868e-004,-3.367868e-004,,,,,,,,,,,,,,,,,,,,
1432815907.214,,-3.000000e+002,3.500039e+001,3.500039e+001,1,0,4.318241e+000,-1.035493e+000,-1.035493e+000,-3.484731e-001,-7.759212e-001,-7.754768e-001,-8.845687e-002,-5.159050e-001,-1.302985e-003,-1.302985e-003,,,,,,,,,,,,,,,,,,,,
1432816011.437,,-4.000000e+002,3.500039e+001,3.499724e+001,1,0,9.154539e-002,-6.561480e-001,-6.561480e-001,-2.449025e-002,-2.547384e-001,-8.657545e-001,-2.340968e-001,-4.643449e-001,-8.256413e-004,-8.256413e-004,,,,,,,,,,,,,,,,,,,,
1432816011.437,,-4.000000e+002,3.500039e+001,3.499724e+001,1,0,3.620591e+000,-2.033296e+000,-2.033296e+000,-8.771839e-001,-1.631886e+000,-1.408088e+000,-2.519763e-001,-1.006678e+000,-2.558528e-003,-2.558528e-003,,,,,,,,,,,,,,,,,,,,
1432816021.588,,-4.000000e+002,3.499724e+001,3.500196e+001,1,0,3.308815e+000,-1.254311e+000,-1.254311e+000,-7.702042e-001,-1.209545e+000,-7.001460e-001,-2.160395e-001,-6.553806e-001,-1.578319e-003,-1.578319e-003,,,,,,,,,,,,,,,,,,,,
1432816125.675,,-5.000000e+002,3.500039e+001,3.500039e+001,1,0,1.307277e-001,-5.670339e-001,-5.670339e-001,-8.761761e-002,-2.773316e-001,-7.568521e-001,-2.774358e-001,-4.671498e-001,-7.135035e-004,-7.135035e-004,,,,,,,,,,,,,,,,,,,,
1432816125.675,,-5.000000e+002,3.500039e+001,3.500039e+001,1,0,4.451160e+000,-1.152226e+000,-1.152226e+000,-7.448134e-002,-8.625240e-001,-1.178137e+000,-1.003923e-001,-8.884350e-001,-1.449856e-003,-1.449856e-003,,,,,,,,,,,,,,,,,,,,
1432816135.593,,-5.000000e+002,3.500039e+001,3.500039e+001,1,0,2.189968e+000,4.181036e-002,4.181036e-002,7.195780e-001,2.966361e-001,-1.007375e-001,5.770301e-001,1.540883e-001,5.261032e-005,5.261032e-005,,,,,,,,,,,,,,,,,,,,
1432816246.621,,-1.000000e+003,3.500196e+001,3.500039e+001,1,0,8.667065e-001,-6.149480e-001,-6.149480e-001,-9.947918e-002,-2.593374e-001,-6.044402e-001,-8.897142e-002,-2.488297e-001,-7.737711e-004,-7.737711e-004,,,,,,,,,,,,,,,,,,,,
1432816246.621,,-1.000000e+003,3.500196e+001,3.500039e+001,1,0,4.967849e+000,-2.935881e-001,-2.935881e-001,1.041154e+000,6.202248e-002,-1.395281e+000,-6.053844e-002,-1.039670e+000,-3.694133e-004,-3.694133e-004,,,,,,,,,,,,,,,,,,,,
1432816256.497,,-1.000000e+003,3.500039e+001,3.500039e+001,1,0,1.199914e+000,-1.335185e-001,-1.335185e-001,3.492742e-001,-1.654816e-001,-1.954660e-001,2.873266e-001,-2.274292e-001,-1.680024e-004,-1.680024e-004,,,,,,,,,,,,,,,,,,,,
1432816390.352,,-3.000000e+003,3.500196e+001,3.500196e+001,1,0,1.915886e+000,1.162755e-001,1.162755e-001,1.812719e-001,1.602271e-001,2.930146e-001,3.580110e-001,3.369661e-001,5.851547e-004,5.851547e-004,,,,,,,,,,,,,,,,,,,,
1432816390.352,,-3.000000e+003,3.500196e+001,3.500196e+001,1,0,4.767224e+000,-1.585437e-001,-1.585437e-001,1.940656e-001,-1.145921e-001,-3.841137e-001,-3.150450e-002,-3.401622e-001,-7.978685e-004,-7.978685e-004,,,,,,,,,,,,,,,,,,,,
1432816400.404,,-3.000000e+003,3.500353e+001,3.500353e+001,1,0,4.103220e-001,-2.224799e-001,-2.224799e-001,1.624780e-002,-1.317001e-001,-3.900922e-001,-1.513645e-001,-2.993124e-001,-1.119627e-003,-1.119627e-003,,,,,,,,,,,,,,,,,,,,
1432816400.404,,-3.000000e+003,3.500353e+001,3.500353e+001,1,0,3.027209e+000,-5.226294e-001,-5.226295e-001,4.948865e-003,-4.318497e-001,-5.798151e-001,-5.223672e-002,-4.890352e-001,-2.630125e-003,-2.630125e-003,,,,,,,,,,,,,,,,,,,,
1432816520.629,,-5.000000e+003,3.500039e+001,3.500039e+001,1,0,3.940057e+000,-1.212958e+000,-1.212958e+000,-7.285465e-001,-1.064625e+000,-6.232276e-001,-1.388159e-001,-4.748943e-001,-6.103467e-003,-6.103467e-003,,,,,,,,,,,,,,,,,,,,
1432816530.796,,-5.000000e+003,3.500353e+001,3.500196e+001,1,0,9.629701e-003,-3.135777e-001,-3.135777e-001,-3.621623e-002,-1.735311e-001,-4.341165e-001,-1.567551e-001,-2.940699e-001,-1.577887e-003,-1.577887e-003,,,,,,,,,,,,,,,,,,,,
1432816530.796,,-5.000000e+003,3.500353e+001,3.500196e+001,1,0,3.974947e+000,-1.186102e+000,-1.186102e+000,-5.568712e-001,-1.046055e+000,-7.617989e-001,-1.325682e-001,-6.217523e-001,-5.968329e-003,-5.968329e-003,,,,,,,,,,,,,,,,,,,,
1432816651.330,,-7.000000e+003,3.499410e+001,3.500196e+001,1,0,2.861010e+000,-5.131687e-001,-5.131688e-001,-4.169004e-002,-3.696637e-001,-4.551722e-001,1.630656e-002,-3.116671e-001,-2.581899e-003,-2.581899e-003,,,,,,,,,,,,,,,,,,,,
1432816661.402,,-7.000000e+003,3.500353e+001,3.500353e+001,1,0,3.633757e-001,-3.622547e-001,-3.622547e-001,-6.780455e-002,-1.729361e-001,-4.948977e-001,-2.004475e-001,-3.055791e-001,-1.822607e-003,-1.822607e-003,,,,,,,,,,,,,,,,,,,,
1432816661.402,,-7.000000e+003,3.500353e+001,3.500353e+001,1,0,4.718403e+000,-4.248177e-001,-4.248177e-001,2.614864e-001,-2.354990e-001,-7.306259e-001,-4.432182e-002,-5.413072e-001,-2.137379e-003,-2.137379e-003,,,,,,,,,,,,,,,,,,,,
1432816781.834,,-9.000000e+003,3.500353e+001,3.500196e+001,1,0,1.767944e+000,4.776147e-002,4.776147e-002,4.439081e-001,1.433189e-001,7.873098e-002,4.748776e-001,1.742884e-001,2.402730e-004,2.402730e-004,,,,,,,,,,,,,,,,,,,,
1432816792.108,,-9.000000e+003,3.500196e+001,3.500353e+001,1,0,1.264186e+000,-2.069155e-001,-2.069155e-001,1.846110e-002,-4.318045e-002,-3.365697e-002,1.917196e-001,1.300781e-001,-1.040927e-003,-1.040927e-003,,,,,,,,,,,,,,,,,,,,
1432816792.108,,-9.000000e+003,3.500196e+001,3.500353e+001,1,0,4.985392e+000,-1.155126e-001,-1.155126e-001,5.310813e-001,4.822249e-002,-6.774720e-001,-3.087814e-002,-5.137370e-001,-5.811076e-004,-5.811076e-004,,,,,,,,,,,,,,,,,,,,
1432816909.394,,-1.000000e+004,3.500039e+001,3.500196e+001,1,0,8.606303e-001,-3.596606e-001,-3.596606e-001,9.751780e-002,-1.552389e-001,-5.085819e-001,-5.140346e-002,-3.041602e-001,-1.809233e-003,-1.809233e-003,,,,,,,,,,,,,,,,,,,,
1432816919.667,,-1.000000e+004,3.500196e+001,3.500196e+001,1,0,2.366560e+000,1.037629e-002,1.037629e-002,1.950061e-001,1.845560e-001,1.561545e-001,3.407843e-001,3.303343e-001,5.219678e-005,5.219678e-005,,,,,,,,,,,,,,,,,,,,
1432816919.667,,-1.000000e+004,3.500196e+001,3.500196e+001,1,0,4.486697e+000,-7.359539e-001,-7.359539e-001,-1.228709e-001,-5.617741e-001,-6.859379e-001,-7.285500e-002,-5.117582e-001,-3.702133e-003,-3.702133e-003,,,,,,,,,,,,,,,,,,,,
1432817068.286,,-2.000000e+004,3.500039e+001,3.500196e+001,1,0,1.748565e-001,-5.484176e-001,-5.484176e-001,-1.422294e-002,-2.741901e-001,-8.081672e-001,-2.739725e-001,-5.339397e-001,-2.757111e-003,-2.757111e-003,,,,,,,,,,,,,,,,,,,,
1432817068.286,,-2.000000e+004,3.500039e+001,3.500196e+001,1,0,3.431187e+000,-1.839808e+000,-1.839808e+000,-7.446318e-001,-1.565581e+000,-1.367321e+000,-2.721440e-001,-1.093093e+000,-9.249440e-003,-9.249440e-003,,,,,,,,,,,,,,,,,,,,
1432817078.502,,-2.000000e+004,3.500196e+001,3.499881e+001,1,0,3.525609e+000,-1.933042e+000,-1.933042e+000,-1.149919e+000,-1.651843e+000,-1.065337e+000,-2.822136e-001,-7.841379e-001,-9.718165e-003,-9.718165e-003,,,,,,,,,,,,,,,,,,,,
1432817242.183,,-3.000000e+004,3.499724e+001,3.499724e+001,1,0,5.741904e-002,-5.867183e-001,-5.867183e-001,-9.399524e-002,-3.126006e-001,-7.855893e-001,-2.928662e-001,-5.114716e-001,-2.947907e-003,-2.947907e-003,,,,,,,,,,,,,,,,,,,,
1432817242.183,,-3.000000e+004,3.499724e+001,3.499724e+001,1,0,4.299161e+000,-1.519822e+000,-1.519822e+000,-3.868972e-001,-1.245704e+000,-1.277999e+000,-1.450744e-001,-1.003881e+000,-7.636190e-003,-7.636190e-003,,,,,,,,,,,,,,,,,,,,
1432817251.957,,-3.000000e+004,3.499881e+001,3.499881e+001,1,0,2.410117e+000,-5.081332e-002,-5.081332e-002,6.456445e-001,1.529412e-001,-2.425506e-001,4.539072e-001,-3.879616e-002,-2.553064e-004,-2.553064e-004,,,,,,,,,,,,,,,,,,,,
1432817411.300,,-4.000000e+004,3.500039e+001,3.500196e+001,1,0,6.835668e-001,-2.815332e-001,-2.815332e-001,-1.109153e-001,-2.351498e-001,-3.971281e-001,-2.265102e-001,-3.507447e-001,-1.413692e-003,-1.413692e-003,,,,,,,,,,,,,,,,,,,,
1432817411.300,,-4.000000e+004,3.500039e+001,3.500196e+001,1,0,4.907791e+000,8.880886e-002,8.880886e-002,8.253838e-001,1.351923e-001,-7.954262e-001,-5.885129e-002,-7.490428e-001,4.459451e-004,4.459451e-004,,,,,,,,,,,,,,,,,,,,
1432817421.467,,-4.000000e+004,3.500196e+001,3.500039e+001,1,0,1.380944e+000,-6.068605e-001,-6.068606e-001,4.234906e-001,-9.741908e-002,-5.825015e-001,4.478498e-001,-7.305998e-002,-3.047292e-003,-3.047292e-003,,,,,,,,,,,,,,,,,,,,
1432817576.256,,-5.000000e+004,3.499567e+001,3.499881e+001,1,0,1.693307e+000,7.599109e-002,7.599109e-002,3.210694e-001,2.492459e-001,5.777719e-001,8.228502e-001,7.510267e-001,3.813544e-004,3.813544e-004,,,,,,,,,,,,,,,,,,,,
1432817576.256,,-5.000000e+004,3.499567e+001,3.499881e+001,1,0,4.870811e+000,-2.565081e-001,-2.565081e-001,7.247613e-001,-8.325325e-002,-1.049924e+000,-6.865428e-002,-8.766688e-001,-1.287262e-003,-1.287262e-003,,,,,,,,,,,,,,,,,,,,
1432817586.328,,-5.000000e+004,3.500196e+001,3.500039e+001,1,0,5.502741e-001,-9.028901e-001,-9.028901e-001,-1.791950e-002,-4.976829e-001,-1.223850e+000,-3.388792e-001,-8.186426e-001,-4.531072e-003,-4.531072e-003,,,,,,,,,,,,,,,,,,,,
1432817586.328,,-5.000000e+004,3.500196e+001,3.500039e+001,1,0,2.811914e+000,-1.140172e+000,-1.140172e+000,6.389036e-001,-7.349644e-001,-1.691389e+000,8.768642e-002,-1.286182e+000,-5.721847e-003,-5.721847e-003,,,,,,,,,,,,,,,,,,,,
1432817749.597,,-6.000000e+004,3.500196e+001,3.500196e+001,1,0,4.134710e+000,-2.287515e+000,-2.287515e+000,-1.255306e+000,-2.022861e+000,-1.283516e+000,-2.513074e-001,-1.018862e+000,-1.147283e-002,-1.147283e-002,,,,,,,,,,,,,,,,,,,,
1432817759.761,,-6.000000e+004,3.500039e+001,3.499724e+001,1,0,3.449930e-002,-9.381390e-001,-9.381390e-001,-1.709328e-001,-5.518627e-001,-1.151176e+000,-3.839698e-001,-7.648997e-001,-4.705155e-003,-4.705155e-003,,,,,,,,,,,,,,,,,,,,
1432817759.761,,-6.000000e+004,3.500039e+001,3.499724e+001,1,0,3.802192e+000,-3.171178e+000,-3.171178e+000,-1.485259e+000,-2.784902e+000,-2.073712e+000,-3.877927e-001,-1.687436e+000,-1.590477e-002,-1.590477e-002,,,,,,,,,,,,,,,,,,,,
1432817918.557,,-7.000000e+004,3.500039e+001,3.500353e+001,1,0,3.086509e+000,-1.500900e+000,-1.500900e+000,-7.332597e-001,-1.443241e+000,-9.805617e-001,-2.129211e-001,-9.229027e-001,-7.523141e-003,-7.523141e-003,,,,,,,,,,,,,,,,,,,,
1432817928.580,,-7.000000e+004,3.500353e+001,3.500353e+001,1,0,2.338846e-001,-4.290903e-001,-4.290902e-001,4.894675e-002,-2.721592e-001,-9.496756e-001,-4.716386e-001,-7.927445e-001,-2.150780e-003,-2.150780e-003,,,,,,,,,,,,,,,,,,,,
1432817928.580,,-7.000000e+004,3.500353e+001,3.500353e+001,1,0,4.591897e+000,-1.274911e+000,-1.274911e+000,3.002383e-001,-1.117980e+000,-1.703247e+000,-1.280977e-001,-1.546316e+000,-6.390387e-003,-6.390387e-003,,,,,,,,,,,,,,,,,,,,
1432818091.618,,-6.000000e+004,3.500196e+001,3.500353e+001,1,0,1.974588e+000,4.947051e-001,4.947051e-001,1.041720e+000,5.258297e-001,4.409142e-001,9.879289e-001,4.720388e-001,2.481150e-003,2.481150e-003,,,,,,,,,,,,,,,,,,,,
1432818101.690,,-6.000000e+004,3.500196e+001,3.500196e+001,1,0,1.061215e+000,-5.827509e-001,-5.827509e-001,7.157125e-002,-8.353055e-002,-5.238979e-001,1.304243e-001,-2.467752e-002,-2.922737e-003,-2.922737e-003,,,,,,,,,,,,,,,,,,,,
1432818101.690,,-6.000000e+004,3.500196e+001,3.500196e+001,1,0,4.992998e+000,-4.727317e-001,-4.727317e-001,1.090044e+000,2.648866e-002,-1.624118e+000,-6.134257e-002,-1.124898e+000,-2.370945e-003,-2.370945e-003,,,,,,,,,,,,,,,,,,,,
1432818262.452,,-5.000000e+004,3.499881e+001,3.500039e+001,1,0,1.025463e+000,-1.869259e-001,-1.869259e-001,2.417102e-001,-1.443643e-001,-3.501213e-001,7.851478e-002,-3.075598e-001,-9.380705e-004,-9.380705e-004,,,,,,,,,,,,,,,,,,,,
1432818272.368,,-5.000000e+004,3.500039e+001,3.500039e+001,1,0,2.140464e+000,5.439924e-001,5.439925e-001,5.546035e-001,5.189645e-001,8.262851e-001,8.368961e-001,8.012571e-001,2.729977e-003,2.729977e-003,,,,,,,,,,,,,,,,,,,,
1432818272.368,,-5.000000e+004,3.500039e+001,3.500039e+001,1,0,4.637811e+000,-5.748161e-001,-5.748161e-001,1.663939e-001,-5.998440e-001,-8.422810e-001,-1.010710e-001,-8.673089e-001,-2.884662e-003,-2.884662e-003,,,,,,,,,,,,,,,,,,,,
1432818425.656,,-4.000000e+004,3.499881e+001,3.500196e+001,1,0,2.835680e-001,-2.247688e-001,-2.247688e-001,2.336945e-003,-2.759452e-001,-5.946233e-001,-3.675176e-001,-6.457996e-001,-1.128655e-003,-1.128655e-003,,,,,,,,,,,,,,,,,,,,
1432818425.656,,-4.000000e+004,3.499881e+001,3.500196e+001,1,0,3.233618e+000,-1.308939e+000,-1.308939e+000,-5.113548e-001,-1.360115e+000,-1.071090e+000,-2.735063e-001,-1.122267e+000,-6.572710e-003,-6.572710e-003,,,,,,,,,,,,,,,,,,,,
1432818435.681,,-4.000000e+004,3.500196e+001,3.499881e+001,1,0,3.736376e+000,-2.381359e+000,-2.381359e+000,-1.630264e+000,-2.220064e+000,-1.094619e+000,-3.435234e-001,-9.333235e-001,-1.195777e-002,-1.195777e-002,,,,,,,,,,,,,,,,,,,,
1432818593.227,,-3.000000e+004,3.500039e+001,3.500039e+001,1,0,1.618543e-002,-1.947081e-001,-1.947081e-001,-8.277196e-002,-2.656813e-001,-3.935420e-001,-2.816059e-001,-4.645153e-001,-9.782910e-004,-9.782910e-004,,,,,,,,,,,,,,,,,,,,
1432818593.227,,-3.000000e+004,3.500039e+001,3.500039e+001,1,0,4.140999e+000,-1.313669e+000,-1.313669e+000,-7.017807e-001,-1.384642e+000,-7.984706e-001,-1.865821e-001,-8.694439e-001,-6.600398e-003,-6.600398e-003,,,,,,,,,,,,,,,,,,,,
1432818603.251,,-3.000000e+004,3.500196e+001,3.500039e+001,1,0,2.635368e+000,5.798517e-002,5.798517e-002,3.365044e-001,-6.898949e-002,-4.552073e-002,2.329985e-001,-1.724954e-001,2.913406e-004,2.913406e-004,,,,,,,,,,,,,,,,,,,,
1432818758.337,,-2.000000e+004,3.500039e+001,3.499881e+001,1,0,5.146362e-001,-1.350444e-001,-1.350444e-001,-9.319453e-002,-1.949173e-001,-2.882362e-001,-2.463863e-001,-3.481091e-001,-6.789214e-004,-6.789214e-004,,,,,,,,,,,,,,,,,,,,
1432818758.337,,-2.000000e+004,3.500039e+001,3.499881e+001,1,0,4.826309e+000,7.263406e-002,7.263406e-002,5.315473e-001,1.276116e-002,-5.103504e-001,-5.143714e-002,-5.702233e-001,3.651599e-004,3.651599e-004,,,,,,,,,,,,,,,,,,,,
1432818768.834,,-2.000000e+004,3.499881e+001,3.499881e+001,1,0,1.569271e+000,2.000488e-001,2.000488e-001,4.414976e-001,1.503262e-001,2.570425e-001,4.984912e-001,2.073199e-001,1.005724e-003,1.005724e-003,,,,,,,,,,,,,,,,,,,,
1432818922.290,,-1.000000e+004,3.499410e+001,3.499724e+001,1,0,1.475914e+000,1.805170e-001,1.805170e-001,8.810727e-002,5.044401e-002,4.325155e-001,3.401058e-001,3.024425e-001,9.080705e-004,9.080705e-004,,,,,,,,,,,,,,,,,,,,
1432818922.290,,-1.000000e+004,3.499410e+001,3.499724e+001,1,0,4.944419e+000,2.821436e-001,2.821436e-001,4.985726e-001,1.520706e-001,-2.503212e-001,-3.389225e-002,-3.803942e-001,1.419292e-003,1.419292e-003,,,,,,,,,,,,,,,,,,,,
1432818932.364,,-1.000000e+004,3.499724e+001,3.499881e+001,1,0,7.027270e-001,8.880886e-002,8.880886e-002,6.727606e-002,-1.097389e-001,-1.079536e-001,-1.294864e-001,-3.065013e-001,4.467430e-004,4.467430e-004,,,,,,,,,,,,,,,,,,,,
1432819048.790,,-9.000000e+003,3.499881e+001,3.499724e+001,1,0,2.591102e+000,4.516739e-002,4.516739e-002,-9.771965e-003,-9.771965e-003,2.383482e-001,1.834089e-001,1.834089e-001,2.272230e-004,2.272230e-004,,,,,,,,,,,,,,,,,,,,
1432819048.790,,-9.000000e+003,3.499881e+001,3.499724e+001,1,0,4.318188e+000,-6.288339e-001,-6.288339e-001,-3.684084e-001,-6.837733e-001,-3.536749e-001,-9.324935e-002,-4.086142e-001,-3.163467e-003,-3.163467e-003,,,,,,,,,,,,,,,,,,,,
1432819058.862,,-9.000000e+003,3.499724e+001,3.499881e+001,1,0,9.233076e-002,-1.046785e-001,-1.046785e-001,-2.165095e-002,-1.722133e-001,-2.839611e-001,-2.009336e-001,-3.514960e-001,-5.266048e-004,-5.266048e-004,,,,,,,,,,,,,,,,,,,,
1432819058.862,,-9.000000e+003,3.499724e+001,3.499881e+001,1,0,3.620774e+000,-1.180151e+000,-1.180151e+000,-7.541755e-001,-1.247686e+000,-6.414772e-001,-2.155020e-001,-7.090121e-001,-5.936970e-003,-5.936970e-003,,,,,,,,,,,,,,,,,,,,
1432819178.842,,-7.000000e+003,3.500039e+001,3.500039e+001,1,0,3.308209e+000,-8.444471e-001,-8.444471e-001,-6.105750e-001,-9.010550e-001,-4.060245e-001,-1.721524e-001,-4.626324e-001,-4.248655e-003,-4.248655e-003,,,,,,,,,,,,,,,,,,,,
1432819188.806,,-7.000000e+003,3.500039e+001,3.500039e+001,1,0,1.305167e-001,-1.866207e-001,-1.866207e-001,-6.143728e-002,-1.632627e-001,-3.167501e-001,-1.915667e-001,-2.933921e-001,-9.389421e-004,-9.389421e-004,,,,,,,,,,,,,,,,,,,,
1432819188.806,,-7.000000e+003,3.500039e+001,3.500039e+001,1,0,4.451370e+000,-4.985198e-001,-4.985198e-001,-5.219477e-002,-4.751619e-001,-5.155295e-001,-6.920444e-002,-4.921715e-001,-2.508196e-003,-2.508196e-003,,,,,,,,,,,,,,,,,,,,
1432819308.031,,-5.000000e+003,3.499881e+001,3.500039e+001,1,0,2.189692e+000,4.058962e-001,4.058962e-001,4.484932e-001,2.483356e-001,3.172968e-001,3.598938e-001,1.597362e-001,2.042423e-003,2.042423e-003,,,,,,,,,,,,,,,,,,,,
1432819318.448,,-5.000000e+003,3.500039e+001,3.500039e+001,1,0,8.661897e-001,2.594073e-003,2.594073e-003,-4.360524e-002,-9.639008e-002,7.266742e-003,-3.893257e-002,-9.171741e-002,1.305308e-005,1.305308e-005,,,,,,,,,,,,,,,,,,,,
1432819318.448,,-5.000000e+003,3.500039e+001,3.500039e+001,1,0,4.965211e+000,2.310251e-001,2.310251e-001,4.553481e-001,1.320410e-001,-2.509712e-001,-2.664823e-002,-3.499554e-001,1.162492e-003,1.162492e-003,,,,,,,,,,,,,,,,,,,,
1432819437.514,,-3.000000e+003,3.500039e+001,3.500196e+001,1,0,1.199955e+000,9.475997e-002,9.475997e-002,1.313243e-001,-3.781430e-003,7.124247e-002,1.078068e-001,-2.729893e-002,4.768780e-004,4.768780e-004,,,,,,,,,,,,,,,,,,,,
1432819447.586,,-3.000000e+003,3.500353e+001,3.500039e+001,1,0,1.915141e+000,2.238533e-001,2.238533e-001,1.802328e-001,1.641346e-001,4.007927e-001,3.571723e-001,3.410741e-001,1.126538e-003,1.126538e-003,,,,,,,,,,,,,,,,,,,,
1432819447.586,,-3.000000e+003,3.500353e+001,3.500039e+001,1,0,4.767594e+000,1.815851e-002,1.815851e-002,1.945462e-001,-4.156012e-002,-2.078195e-001,-3.143177e-002,-2.675381e-001,9.138243e-005,9.138243e-005,,,,,,,,,,,,,,,,,,,,
1432819560.513,,-1.000000e+003,3.499567e+001,3.500039e+001,1,0,4.097372e-001,-8.087405e-003,-8.087405e-003,1.139961e-002,-6.052572e-002,-1.196859e-001,-1.001989e-001,-1.721242e-001,-4.070459e-005,-4.070459e-005,,,,,,,,,,,,,,,,,,,,
1432819560.513,,-1.000000e+003,3.499567e+001,3.500039e+001,1,0,3.027126e+000,-1.573229e-001,-1.573229e-001,2.589750e-003,-2.097612e-001,-1.946179e-001,-3.470519e-002,-2.470562e-001,-7.918194e-004,-7.918194e-004,,,,,,,,,,,,,,,,,,,,
1432819579.550,,-1.000000e+003,3.500196e+001,3.500196e+001,1,0,3.939915e+000,-1.827753e+000,-1.827754e+000,-1.658497e+000,-2.211658e+000,-4.837742e-001,-3.145172e-001,-8.676792e-001,-2.299809e-003,-2.299809e-003,,,,,,,,,,,,,,,,,,,,
1432819689.978,,-5.000000e+002,3.500511e+001,3.500039e+001,1,0,8.883718e-003,-7.263406e-002,-7.263406e-002,-5.713496e-002,-2.097996e-001,-2.744308e-001,-2.589317e-001,-4.115964e-001,-9.139603e-005,-9.139603e-005,,,,,,,,,,,,,,,,,,,,
1432819689.978,,-5.000000e+002,3.500511e+001,3.500039e+001,1,0,3.975449e+000,-1.330607e+000,-1.330607e+000,-9.239047e-001,-1.467773e+000,-6.256545e-001,-2.189521e-001,-7.628201e-001,-1.674314e-003,-1.674314e-003,,,,,,,,,,,,,,,,,,,,
1432819700.001,,-5.000000e+002,3.500039e+001,3.500196e+001,1,0,2.861282e+000,-9.918516e-003,-9.918516e-003,-6.798790e-002,-4.016211e-001,8.276789e-002,2.469851e-002,-3.089347e-001,-1.248055e-005,-1.248055e-005,,,,,,,,,,,,,,,,,,,,
1432819803.555,,-4.000000e+002,3.500039e+001,3.500196e+001,1,0,3.638789e-001,3.022859e-001,3.022859e-001,-8.785652e-002,-1.897420e-001,1.216829e-001,-2.684594e-001,-3.703449e-001,3.803710e-004,3.803710e-004,,,,,,,,,,,,,,,,,,,,
1432819803.555,,-4.000000e+002,3.500039e+001,3.500196e+001,1,0,4.717778e+000,3.698843e-001,3.698843e-001,3.594970e-001,-1.221435e-001,-4.902550e-002,-5.941280e-002,-5.410534e-001,4.654313e-004,4.654313e-004,,,,,,,,,,,,,,,,,,,,
1432819813.578,,-4.000000e+002,3.500196e+001,3.500196e+001,1,0,1.768026e+000,2.201910e-001,2.201910e-001,5.526315e-001,2.567767e-001,2.583733e-001,5.908137e-001,2.949589e-001,2.770699e-004,2.770699e-004,,,,,,,,,,,,,,,,,,,,
1432819917.611,,-3.000000e+002,3.500039e+001,3.500353e+001,1,0,1.264715e+000,1.222266e-001,1.222266e-001,1.479140e-002,-3.760184e-002,3.129714e-001,2.055362e-001,1.531430e-001,1.538006e-004,1.538006e-004,,,,,,,,,,,,,,,,,,,,
1432819917.611,,-3.000000e+002,3.500039e+001,3.500353e+001,1,0,4.985563e+000,3.262429e-001,3.262429e-001,5.768281e-001,1.664144e-001,-2.837600e-001,-3.317476e-002,-4.435884e-001,4.105190e-004,4.105190e-004,,,,,,,,,,,,,,,,,,,,
1432819928.184,,-3.000000e+002,3.500039e+001,3.500353e+001,1,0,8.605075e-001,-1.292459e-001,-1.292459e-001,1.007957e-001,-1.203388e-001,-2.842599e-001,-5.421823e-002,-2.753528e-001,-1.626331e-004,-1.626331e-004,,,,,,,,,,,,,,,,,,,,
1432820032.439,,-2.000000e+002,3.500039e+001,3.500196e+001,1,0,2.366829e+000,1.377911e-001,1.377911e-001,1.662763e-001,1.598472e-001,2.611090e-001,2.895942e-001,2.831652e-001,1.733867e-004,1.733867e-004,,,,,,,,,,,,,,,,,,,,
1432820032.439,,-2.000000e+002,3.500039e+001,3.500196e+001,1,0,4.486543e+000,-3.953673e-001,-3.953673e-001,-1.032917e-001,-3.733111e-001,-3.540054e-001,-6.192977e-002,-3.319492e-001,-4.975028e-004,-4.975028e-004,,,,,,,,,,,,,,,,,,,,
1432820042.355,,-2.000000e+002,3.500039e+001,3.499881e+001,1,0,1.762731e-001,6.393628e-002,6.393628e-002,-5.924538e-003,-1.385497e-001,-1.155121e-001,-1.853729e-001,-3.179981e-001,8.045298e-005,8.045298e-005,,,,,,,,,,,,,,,,,,,,
1432820042.355,,-2.000000e+002,3.500039e+001,3.499881e+001,1,0,3.432133e+000,-7.296976e-001,-7.296976e-001,-5.133672e-001,-9.321836e-001,-4.004574e-001,-1.841270e-001,-6.029434e-001,-9.182009e-004,-9.182009e-004,,,,,,,,,,,,,,,,,,,,
1432820147.140,,-1.000000e+002,3.500039e+001,3.500196e+001,1,0,3.525351e+000,-4.974517e-001,-4.974517e-001,-5.410652e-001,-7.019985e-001,-8.847233e-002,-1.320858e-001,-2.930191e-001,-6.259624e-004,-6.259624e-004,,,,,,,,,,,,,,,,,,,,
1432820157.712,,-1.000000e+002,3.500196e+001,3.500196e+001,1,0,5.779285e-002,-6.607257e-002,-6.607258e-002,-3.446696e-002,-1.018057e-001,-1.494914e-001,-1.178857e-001,-1.852245e-001,-8.314164e-005,-8.314164e-005,,,,,,,,,,,,,,,,,,,,
1432820157.712,,-1.000000e+002,3.500196e+001,3.500196e+001,1,0,4.298645e+000,-3.856014e-001,-3.856014e-001,-1.567895e-001,-4.213345e-001,-2.871759e-001,-5.836400e-002,-3.229091e-001,-4.852169e-004,-4.852169e-004,,,,,,,,,,,,,,,,,,,,
1432820272.088,,0.000000e+000,3.542039e+001,3.500039e+001,1,0,2.410593e+000,9.802545e-001,9.802545e-001,4.830453e-001,3.543169e-001,8.311658e-001,3.339565e-001,2.052281e-001,2.466998e-004,2.466998e-004,,,,,,,,,,,,,,,,,,,,
1432820282.910,,0.000000e+000,3.500196e+001,3.500196e+001,1,0,6.836274e-001,4.359569e-001,4.359569e-001,-6.827438e-002,-9.926343e-002,3.567810e-001,-1.474503e-001,-1.784393e-001,1.097169e-004,1.097169e-004,,,,,,,,,,,,,,,,,,,,
1432820282.910,,0.000000e+000,3.500196e+001,3.500196e+001,1,0,4.910179e+000,9.222693e-001,9.222693e-001,5.592104e-001,3.870490e-001,3.249002e-001,-3.815870e-002,-2.103201e-001,2.321067e-004,2.321067e-004,,,,,,,,,,,,,,,,,,,,
1432820380.658,,1.000000e+002,3.499881e+001,3.499881e+001,1,0,1.380785e+000,1.222266e+000,1.222266e+000,-3.012923e-001,2.044195e-001,1.192296e+000,-3.312626e-001,1.744492e-001,3.076049e-004,3.076049e-004,,,,,,,,,,,,,,,,,,,,
1432820391.373,,1.000000e+002,3.499881e+001,3.499881e+001,1,0,1.693143e+000,7.730339e-001,7.730339e-001,-2.291028e-001,-1.463946e-001,4.549109e-001,-5.472258e-001,-4.645175e-001,1.945476e-004,1.945476e-004,,,,,,,,,,,,,,,,,,,,
1432820391.373,,1.000000e+002,3.499881e+001,3.499881e+001,1,0,4.870925e+000,1.349223e+000,1.349223e+000,-5.006732e-001,4.297948e-001,1.895792e+000,4.589593e-002,9.763640e-001,3.395558e-004,3.395558e-004,,,,,,,,,,,,,,,,,,,,
1432820511.756,,2.000000e+002,3.500039e+001,3.500039e+001,1,0,5.508333e-001,4.681540e-001,4.681539e-001,-2.613810e-002,1.525957e-001,6.141024e-001,1.198103e-001,2.985442e-001,5.890925e-004,5.890925e-004,,,,,,,,,,,,,,,,,,,,
1432820511.756,,2.000000e+002,3.500039e+001,3.500039e+001,1,0,2.811933e+000,6.176946e-001,6.176946e-001,-2.096923e-001,3.021364e-001,7.958004e-001,-3.158649e-002,4.802422e-001,7.772641e-004,7.772641e-004,,,,,,,,,,,,,,,,,,,,
1432820522.169,,2.000000e+002,3.500196e+001,3.499881e+001,1,0,4.134494e+000,-3.614917e-001,-3.614917e-001,4.160351e-001,3.141628e-001,-6.949880e-001,8.253880e-002,-1.933348e-002,-4.548762e-004,-4.548762e-004,,,,,,,,,,,,,,,,,,,,
1432820625.787,,3.000000e+002,3.500039e+001,3.499724e+001,1,0,3.447300e-002,4.635762e-001,4.635762e-001,2.955806e-002,1.969863e-001,6.144139e-001,1.803958e-001,3.478241e-001,5.833286e-004,5.833286e-004,,,,,,,,,,,,,,,,,,,,
1432820625.787,,3.000000e+002,3.500039e+001,3.499724e+001,1,0,3.801565e+000,1.571551e+000,1.571551e+000,7.337349e-001,1.304961e+000,1.019634e+000,1.818184e-001,7.530442e-001,1.977519e-003,1.977519e-003,,,,,,,,,,,,,,,,,,,,
1432820636.001,,3.000000e+002,3.499724e+001,3.500039e+001,1,0,3.086253e+000,1.071810e+000,1.071810e+000,3.329934e-001,6.901648e-001,8.346162e-001,9.579964e-002,4.529710e-001,1.348683e-003,1.348683e-003,,,,,,,,,,,,,,,,,,,,
1432820739.429,,4.000000e+002,3.500039e+001,3.500196e+001,1,0,2.340872e-001,5.296487e-001,5.296487e-001,8.199769e-002,2.316855e-001,7.004201e-001,2.527691e-001,4.024568e-001,6.664653e-004,6.664653e-004,,,,,,,,,,,,,,,,,,,,
1432820739.429,,4.000000e+002,3.500039e+001,3.500196e+001,1,0,4.588867e+000,8.171331e-001,8.171331e-001,-1.419512e-001,5.191698e-001,1.028162e+000,6.907823e-002,7.301992e-001,1.028211e-003,1.028211e-003,,,,,,,,,,,,,,,,,,,,
1432820749.201,,4.000000e+002,3.500039e+001,3.500039e+001,1,0,1.974355e+000,3.006073e-002,3.006073e-002,-6.150343e-001,-2.370632e-001,6.527559e-002,-5.798195e-001,-2.018483e-001,3.782589e-005,3.782589e-005,,,,,,,,,,,,,,,,,,,,
1432820853.485,,5.000000e+002,3.500039e+001,3.503819e+001,1,0,1.060829e+000,4.959258e-001,4.959258e-001,3.530086e-002,1.351990e-001,3.750826e-001,-8.554228e-002,1.435584e-002,6.240275e-004,6.240275e-004,,,,,,,,,,,,,,,,,,,,
1432820853.485,,5.000000e+002,3.500039e+001,3.503819e+001,1,0,4.993025e+000,3.047273e-001,3.047273e-001,-7.410151e-001,-5.599949e-002,1.086692e+000,4.094915e-002,7.259648e-001,3.834409e-004,3.834409e-004,,,,,,,,,,,,,,,,,,,,
1432820863.557,,5.000000e+002,3.500983e+001,3.499567e+001,1,0,1.026179e+000,4.676961e-001,4.676962e-001,-1.787150e-001,1.685654e-001,5.886979e-001,-5.771329e-002,2.895671e-001,5.885060e-004,5.885060e-004,,,,,,,,,,,,,,,,,,,,
1432820973.740,,1.000000e+003,3.499881e+001,3.499881e+001,1,0,2.140324e+000,3.697317e-001,3.697318e-001,-5.267678e-001,-4.854684e-001,3.384679e-002,-8.626528e-001,-8.213534e-001,4.652227e-004,4.652227e-004,,,,,,,,,,,,,,,,,,,,
1432820973.740,,1.000000e+003,3.499881e+001,3.499881e+001,1,0,4.638251e+000,1.557054e+000,1.557054e+000,-1.860830e-001,7.018542e-001,1.847326e+000,1.041886e-001,9.921259e-001,1.959196e-003,1.959196e-003,,,,,,,,,,,,,,,,,,,,
1432820983.763,,1.000000e+003,3.500196e+001,3.500039e+001,1,0,2.825527e-001,6.912442e-001,6.912442e-001,-1.248651e-002,3.846295e-001,1.120987e+000,4.172564e-001,8.143725e-001,8.697725e-004,8.697725e-004,,,,,,,,,,,,,,,,,,,,
1432820983.763,,1.000000e+003,3.500196e+001,3.500039e+001,1,0,3.233274e+000,2.102725e+000,2.102725e+000,5.849066e-001,1.796111e+000,1.827454e+000,3.096358e-001,1.520840e+000,2.645798e-003,2.645798e-003,,,,,,,,,,,,,,,,,,,,
1432821106.311,,3.000000e+003,3.500196e+001,3.500353e+001,1,0,3.736057e+000,2.031159e+000,2.031159e+000,1.398124e+000,1.921673e+000,9.244294e-001,2.913938e-001,8.149431e-001,5.110889e-003,5.110889e-003,,,,,,,,,,,,,,,,,,,,
1432821116.528,,3.000000e+003,3.500196e+001,3.500196e+001,1,0,1.661650e-002,4.824976e-001,4.824976e-001,7.398013e-002,2.882816e-001,6.782233e-001,2.697057e-001,4.840072e-001,1.214081e-003,1.214081e-003,,,,,,,,,,,,,,,,,,,,
1432821116.528,,3.000000e+003,3.500196e+001,3.500196e+001,1,0,4.140490e+000,1.668599e+000,1.668599e+000,6.743248e-001,1.474383e+000,1.172507e+000,1.782319e-001,9.782905e-001,4.198601e-003,4.198601e-003,,,,,,,,,,,,,,,,,,,,
1432821235.737,,5.000000e+003,3.500039e+001,3.500039e+001,1,0,2.634648e+000,8.430738e-001,8.430738e-001,-3.741072e-001,2.400923e-001,9.537272e-001,-2.634538e-001,3.507457e-001,2.121126e-003,2.121126e-003,,,,,,,,,,,,,,,,,,,,
1432821245.810,,5.000000e+003,3.500039e+001,3.500353e+001,1,0,5.150490e-001,4.783776e-001,4.783776e-001,1.204253e-001,2.818462e-001,6.783723e-001,3.204200e-001,4.818408e-001,1.203571e-003,1.203571e-003,,,,,,,,,,,,,,,,,,,,
1432821245.810,,5.000000e+003,3.500039e+001,3.500353e+001,1,0,4.824479e+000,3.248695e-001,3.248695e-001,-6.949081e-001,1.283381e-001,1.086928e+000,6.715037e-002,8.903965e-001,8.173532e-004,8.173532e-004,,,,,,,,,,,,,,,,,,,,
1432821365.572,,7.000000e+003,3.500039e+001,3.499881e+001,1,0,1.569938e+000,2.008118e-001,2.008118e-001,-6.358044e-001,-9.997492e-002,1.211979e-001,-7.154182e-001,-1.795888e-001,5.051708e-004,5.051708e-004,,,,,,,,,,,,,,,,,,,,
1432821376.286,,7.000000e+003,3.499881e+001,3.499881e+001,1,0,1.475965e+000,4.629658e-001,4.629658e-001,-1.590049e-001,-6.392622e-002,1.155917e-002,-6.104115e-001,-5.153328e-001,1.164657e-003,1.164657e-003,,,,,,,,,,,,,,,,,,,,
1432821376.286,,7.000000e+003,3.499881e+001,3.499881e+001,1,0,4.944064e+000,5.040132e-001,5.040132e-001,-8.976024e-001,-2.287883e-002,1.462757e+000,6.114135e-002,9.358650e-001,1.267917e-003,1.267917e-003,,,,,,,,,,,,,,,,,,,,
1432821491.024,,9.000000e+003,3.500511e+001,3.499724e+001,1,0,7.015330e-001,7.405316e-001,7.405316e-001,-1.299739e-001,3.471457e-001,1.124274e+000,2.537689e-001,7.308884e-001,1.862692e-003,1.862692e-003,,,,,,,,,,,,,,,,,,,,
1432821501.489,,9.000000e+003,3.500196e+001,3.500039e+001,1,0,2.590394e+000,5.784783e-001,5.784783e-001,1.688701e-002,1.688701e-002,1.918645e-001,-3.697268e-001,-3.697268e-001,1.455072e-003,1.455072e-003,,,,,,,,,,,,,,,,,,,,
1432821501.489,,9.000000e+003,3.500196e+001,3.500039e+001,1,0,4.317423e+000,2.142094e+000,2.142094e+000,7.356802e-001,1.580503e+000,1.593763e+000,1.873492e-001,1.032172e+000,5.388103e-003,5.388103e-003,,,,,,,,,,,,,,,,,,,,
1432821618.415,,1.000000e+004,3.500039e+001,3.499881e+001,1,0,9.160693e-002,9.939879e-001,9.939879e-001,4.776055e-002,4.289735e-001,1.361462e+000,4.152342e-001,7.964472e-001,2.500072e-003,2.500072e-003,,,,,,,,,,,,,,,,,,,,
1432821618.415,,1.000000e+004,3.500039e+001,3.499881e+001,1,0,3.621046e+000,3.367717e+000,3.367718e+000,1.553172e+000,2.802703e+000,2.261270e+000,4.467239e-001,1.696255e+000,8.470464e-003,8.470464e-003,,,,,,,,,,,,,,,,,,,,
1432821628.191,,1.000000e+004,3.499881e+001,3.500039e+001,1,0,3.308876e+000,2.484207e+000,2.484207e+000,1.354608e+000,2.111142e+000,1.513620e+000,3.840214e-001,1.140556e+000,6.248262e-003,6.248262e-003,,,,,,,,,,,,,,,,,,,,
1432821799.243,,2.000000e+004,3.500039e+001,3.500353e+001,1,0,1.310780e-001,5.032502e-001,5.032502e-001,8.852255e-002,2.624099e-001,6.822390e-001,2.675113e-001,4.413987e-001,2.530037e-003,2.530037e-003,,,,,,,,,,,,,,,,,,,,
1432821799.243,,2.000000e+004,3.500039e+001,3.500353e+001,1,0,4.450253e+000,1.035951e+000,1.035951e+000,7.280903e-002,7.951105e-001,1.060351e+000,9.720926e-002,8.195107e-001,5.208132e-003,5.208132e-003,,,,,,,,,,,,,,,,,,,,
1432821809.079,,2.000000e+004,3.500353e+001,3.500196e+001,1,0,2.189406e+000,8.392590e-003,8.392590e-003,-6.912677e-001,-2.792975e-001,1.428213e-001,-5.568390e-001,-1.448688e-001,4.219285e-005,4.219285e-005,,,,,,,,,,,,,,,,,,,,
1432821971.808,,3.000000e+004,3.499724e+001,3.500196e+001,1,0,8.666332e-001,4.916532e-001,4.916532e-001,7.678854e-002,2.003809e-001,4.860054e-001,7.114080e-002,1.947332e-001,2.470262e-003,2.470262e-003,,,,,,,,,,,,,,,,,,,,
1432821971.808,,3.000000e+004,3.499724e+001,3.500196e+001,1,0,4.967834e+000,2.421644e-001,2.421644e-001,-8.061112e-001,-4.910788e-002,1.095958e+000,4.768267e-002,8.046860e-001,1.216730e-003,1.216730e-003,,,,,,,,,,,,,,,,,,,,
1432821982.022,,3.000000e+004,3.500039e+001,3.500039e+001,1,0,1.199358e+000,4.239021e-001,4.239021e-001,-2.756833e-001,1.282230e-001,4.750262e-001,-2.245592e-001,1.793471e-001,2.129853e-003,2.129853e-003,,,,,,,,,,,,,,,,,,,,
1432822140.711,,4.000000e+004,3.499724e+001,3.500039e+001,1,0,1.915389e+000,5.340739e-003,5.340739e-003,-4.290931e-001,-3.781711e-001,-4.049242e-001,-8.393580e-001,-7.884361e-001,2.681800e-005,2.681800e-005,,,,,,,,,,,,,,,,,,,,
1432822140.711,,4.000000e+004,3.499724e+001,3.500039e+001,1,0,4.766973e+000,6.854457e-001,6.854457e-001,-4.449215e-001,3.019339e-001,1.204546e+000,7.417866e-002,8.210340e-001,3.441899e-003,3.441899e-003,,,,,,,,,,,,,,,,,,,,
1432822150.735,,4.000000e+004,3.500039e+001,3.500039e+001,1,0,4.100878e-001,3.418073e-001,3.418073e-001,-3.385570e-002,3.199137e-001,7.308842e-001,3.552212e-001,7.089906e-001,1.716352e-003,1.716352e-003,,,,,,,,,,,,,,,,,,,,
1432822150.735,,4.000000e+004,3.500039e+001,3.500039e+001,1,0,3.026715e+000,1.051973e+000,1.051973e+000,-1.438271e-002,1.030079e+000,1.187028e+000,1.206720e-001,1.165134e+000,5.282381e-003,5.282381e-003,,,,,,,,,,,,,,,,,,,,
1432822311.333,,5.000000e+004,3.500039e+001,3.500196e+001,1,0,3.939884e+000,2.262948e+000,2.262948e+000,1.576471e+000,2.277871e+000,9.910346e-001,3.045584e-001,1.005958e+000,1.135640e-002,1.135640e-002,,,,,,,,,,,,,,,,,,,,
1432822321.797,,5.000000e+004,3.500196e+001,3.500196e+001,1,0,8.626922e-003,6.714072e-001,6.714072e-001,-2.132613e-001,-3.550452e-002,1.055999e+000,1.713307e-001,3.490874e-001,3.369396e-003,3.369396e-003,,,,,,,,,,,,,,,,,,,,
1432822321.797,,5.000000e+004,3.500196e+001,3.500196e+001,1,0,3.975153e+000,2.563707e+000,2.563707e+000,1.223537e+000,1.856796e+000,1.403885e+000,6.371475e-002,6.969731e-001,1.286573e-002,1.286573e-002,,,,,,,,,,,,,,,,,,,,
1432822484.260,,6.000000e+004,3.499881e+001,3.500039e+001,1,0,2.860784e+000,2.330088e-001,2.330088e-001,-1.193293e-001,2.302906e-001,5.216712e-001,1.693331e-001,5.189530e-001,1.168636e-003,1.168636e-003,,,,,,,,,,,,,,,,,,,,
1432822510.636,,6.000000e+004,3.499881e+001,3.499881e+001,1,0,3.636370e-001,3.025910e-001,3.025910e-001,4.507586e-002,8.107302e-002,3.429053e-001,8.539015e-002,1.213873e-001,7.588095e-003,7.588095e-003,,,,,,,,,,,,,,,,,,,,
1432822510.636,,6.000000e+004,3.499881e+001,3.499881e+001,1,0,4.716681e+000,2.855006e-001,2.855006e-001,-1.061857e-001,6.398264e-002,4.106973e-001,1.901092e-002,1.891793e-001,7.159519e-003,7.159519e-003,,,,,,,,,,,,,,,,,,,,
1432822662.864,,7.000000e+004,3.500039e+001,3.500196e+001,1,0,1.767586e+000,3.665273e-001,3.665273e-001,-9.164671e-002,1.938536e-001,2.340273e-001,-2.241467e-001,6.135355e-002,9.185942e-003,9.185942e-003,,,,,,,,,,,,,,,,,,,,
1432822672.781,,7.000000e+004,3.500353e+001,3.500196e+001,1,0,1.264325e+000,-1.061892e+000,-1.061892e+000,2.838415e-001,2.404366e-001,-1.342111e+000,3.622013e-003,-3.978288e-002,-2.661323e-002,-2.661323e-002,,,,,,,,,,,,,,,,,,,,
1432822672.781,,7.000000e+004,3.500353e+001,3.500196e+001,1,0,4.985642e+000,-1.871853e+000,-1.871853e+000,-2.295196e-001,-5.695246e-001,-1.642052e+000,2.815421e-004,-3.397235e-001,-4.691255e-002,-4.691255e-002,,,,,,,,,,,,,,,,,,,,
1432822672.781,,7.000000e+004,3.500353e+001,3.500196e+001,1,0,2.812073e+000,-1.716819e+000,-1.716819e+000,4.126070e-002,-4.144907e-001,-1.752337e+000,5.742169e-003,-4.500092e-001,-4.302707e-002,-4.302707e-002,,,,,,,,,,,,,,,,,,,,