File: data/A269/A269_GdN_MH_5K_150528.rso.raw
[Header]
TITLE,MPMS RSO Measurement
BYAPP,MPMS Measurement,2.1,Raw with ABS
FILEOPENTIME, 1432783611.910000 5/28/2015, 3:26:51 PM

INFO, APPNAME, MPMS MultiVu Application, Revision 1.61,  Build 082

INFO, NAME, A269
INFO, WEIGHT, 22.300
INFO, AREA, 1.000
INFO, LENGTH, 1.000
INFO, SHAPE, 1
INFO, COMMENT, m = 0.0223g
INFO, SEQUENCE FILE: 7T_hysteresis_sweep.seq


INFO, BACKGROUND DATA FILE:, None


STARTUPAXIS,X,8,LINEAR,AUTO,0.000000,0.000000
STARTUPAXIS,Y1,9,LINEAR,AUTO,0.000000,0.000000


STARTUPGROUP,Longitudinal
FIELDGROUP,Longitudinal,1,2,3,4,5,6,7,8,9,10,11,12,13,14,15,16,17,18,19,20,21,22
FIELDGROUP,Transverse,1,2,3,4,5,6,7,8,23,24,25,26,27,28,29,30,31,32,33,34,35,36

PLOT_APPEARANCE,ALL,HORZ_GRID_ON,VERT_GRID_ON,MARKERS_ONLY

[Data]
Time,Comment,Field (Oe),Start Temperature (K),End Temperature (K),Scan,Rejected,Position (cm),Long Voltage,Long Average Voltage,Long Detrended Voltage,Long Demeaned Voltage,Long Reg Fit,Long Detrended Fit,Long Demeaned Fit,Long Scaled Response,Long Avg. Scaled Response,Long Background Response,Long Response [w/ABS],Long Detrended Resp. [w/ABS],Long Fit [w/ABS],Long Detrended Fit [w/ABS],Trans Voltage,Trans Average Voltage,Trans Detrended Voltage,Trans Demeaned Voltage,Trans Reg Fit,Trans Detrended Fit,Trans Demeaned Fit,Trans Scaled Response,Trans Avg. Scaled Response,Trans Background Response,Trans Response [w/ABS],Trans Detrended Resp. [w/ABS],Trans Adjusted Fit,Trans Detrended Fit [w/ABS],
1432783611.899,,7.000000e+004,5.008015e+000,5.005038e+000,1,0,2.591390e+000,7.095554e-002,7.095554e-002,6.108329e-003,6.108329e-003,-7.843187e-002,-1.432791e-001,-1.432791e-001,1.778294e-003,1.778294e-003,,,,,,,,,,,,,,,,,,,,
1432783611.899,,7.000000e+004,5.008015e+000,5.005038e+000,1,0,4.316816e+000,6.503494e-001,6.503494e-001,2.880483e-001,5.855022e-001,4.357705e-001,7.346938e-002,3.709233e-001,1.629912e-002,1.629912e-002,,,,,,,,,,,,,,,,,,,,
1432783621.815,,7.000000e+004,5.005038e+000,5.002932e+000,1,0,9.003936e-002,2.180548e-001,2.180548e-001,2.017566e-002,1.506229e-001,3.567143e-001,1.588352e-001,2.892825e-001,5.464909e-003,5.464909e-003,,,,,,,,,,,,,,,,,,,,
1432783621.815,,7.000000e+004,5.005038e+000,5.002932e+000,1,0,3.621315e+000,1.085086e+000,1.085086e+000,5.900767e-001,1.017654e+000,6.653993e-001,1.703904e-001,5.979674e-001,2.719452e-002,2.719452e-002,,,,,,,,,,,,,,,,,,,,
1432783785.110,,6.000000e+004,5.000209e+000,5.004666e+000,1,0,3.307703e+000,7.776116e-001,7.776116e-001,4.965991e-001,7.389261e-001,4.222865e-001,1.412740e-001,3.836009e-001,1.950022e-002,1.950022e-002,,,,,,,,,,,,,,,,,,,,
1432783795.135,,6.000000e+004,5.005409e+000,5.003675e+000,1,0,1.315693e-001,1.936399e-001,1.936399e-001,5.186661e-002,1.396177e-001,2.988896e-001,1.571163e-001,2.448674e-001,4.855922e-003,4.855922e-003,,,,,,,,,,,,,,,,,,,,
1432783795.135,,6.000000e+004,5.005409e+000,5.003675e+000,1,0,4.449402e+000,4.605243e-001,4.605243e-001,4.199750e-002,4.065021e-001,4.747416e-001,5.621476e-002,4.207194e-001,1.154860e-002,1.154860e-002,,,,,,,,,,,,,,,,,,,,
1432783950.418,,5.000000e+004,5.000333e+000,5.005781e+000,1,0,2.189042e+000,-1.571703e-001,-1.571703e-001,-3.804246e-001,-1.857709e-001,-8.212389e-002,-3.053782e-001,-1.107245e-001,-3.943725e-003,-3.943725e-003,,,,,,,,,,,,,,,,,,,,
1432783960.528,,5.000000e+004,5.005781e+000,5.003798e+000,1,0,8.675856e-001,1.332133e-001,1.332133e-001,3.569597e-002,8.598553e-002,1.282073e-001,3.068999e-002,8.097954e-002,3.342594e-003,3.342594e-003,,,,,,,,,,,,,,,,,,,,
1432783960.528,,5.000000e+004,5.005781e+000,5.003798e+000,1,0,4.966392e+000,-3.082370e-002,-3.082369e-002,-3.860750e-001,-7.805146e-002,3.777540e-001,2.250273e-002,3.305263e-001,-7.734295e-004,-7.734295e-004,,,,,,,,,,,,,,,,,,,,
1432784113.285,,4.000000e+004,5.000209e+000,5.005161e+000,1,0,1.199351e+000,4.440443e-002,4.440443e-002,-1.223964e-001,2.781188e-002,6.444953e-002,-1.023514e-001,4.785698e-002,1.114863e-003,1.114863e-003,,,,,,,,,,,,,,,,,,,,
1432784123.203,,4.000000e+004,5.005161e+000,5.002065e+000,1,0,1.916074e+000,-1.136815e-001,-1.136815e-001,-1.706832e-001,-1.533490e-001,-2.743397e-001,-3.313414e-001,-3.140073e-001,-2.854202e-003,-2.854202e-003,,,,,,,,,,,,,,,,,,,,
1432784123.203,,4.000000e+004,5.005161e+000,5.002065e+000,1,0,4.767421e+000,1.144444e-001,1.144444e-001,-1.794572e-001,7.477684e-002,3.227200e-001,2.881834e-002,2.830524e-001,2.873358e-003,2.873358e-003,,,,,,,,,,,,,,,,,,,,
1432784280.242,,3.000000e+004,5.000086e+000,5.005161e+000,1,0,4.099381e-001,1.069674e-001,1.069674e-001,-1.271074e-002,9.590282e-002,2.458626e-001,1.261844e-001,2.347980e-001,2.687234e-003,2.687234e-003,,,,,,,,,,,,,,,,,,,,
1432784280.242,,3.000000e+004,5.000086e+000,5.005161e+000,1,0,3.026834e+000,3.323466e-001,3.323466e-001,6.134016e-004,3.212820e-001,3.775366e-001,4.580344e-002,3.664720e-001,8.349208e-003,8.349208e-003,,,,,,,,,,,,,,,,,,,,
1432784290.314,,3.000000e+004,5.005161e+000,5.003180e+000,1,0,3.939948e+000,7.296976e-001,7.296976e-001,5.162126e-001,7.190357e-001,3.119539e-001,9.846899e-002,3.012921e-001,1.833146e-002,1.833146e-002,,,,,,,,,,,,,,,,,,,,
1432784452.497,,2.000000e+004,4.999838e+000,5.003798e+000,1,0,8.956029e-003,9.460738e-002,9.460738e-002,2.335050e-002,9.517901e-002,1.701864e-001,9.892952e-002,1.707580e-001,2.378142e-003,2.378142e-003,,,,,,,,,,,,,,,,,,,,
1432784452.497,,2.000000e+004,4.999838e+000,5.003798e+000,1,0,3.975399e+000,6.021302e-001,6.021302e-001,3.468128e-001,6.027018e-001,3.377339e-001,8.241645e-002,3.383055e-001,1.513573e-002,1.513573e-002,,,,,,,,,,,,,,,,,,,,
1432784462.818,,2.000000e+004,5.005161e+000,5.002189e+000,1,0,2.860580e+000,2.061525e-001,2.061525e-001,2.595170e-002,1.905934e-001,1.728969e-001,-7.303909e-003,1.573378e-001,5.182049e-003,5.182049e-003,,,,,,,,,,,,,,,,,,,,
1432784616.532,,1.000000e+004,5.000333e+000,5.005409e+000,1,0,3.642339e-001,5.951110e-002,5.951110e-002,3.153411e-002,7.144243e-002,1.212745e-001,9.329753e-002,1.332058e-001,1.496820e-003,1.496820e-003,,,,,,,,,,,,,,,,,,,,
1432784616.532,,1.000000e+004,5.000333e+000,5.005409e+000,1,0,4.718096e+000,5.279702e-002,5.279702e-002,-1.239291e-001,6.472835e-002,1.971900e-001,2.046383e-002,2.091213e-001,1.327948e-003,1.327948e-003,,,,,,,,,,,,,,,,,,,,
1432784626.604,,1.000000e+004,5.005409e+000,5.002437e+000,1,0,1.767092e+000,-4.531999e-002,-4.531999e-002,-1.925774e-001,-8.281955e-002,-5.959333e-002,-2.068508e-001,-9.709290e-002,-1.139886e-003,-1.139886e-003,,,,,,,,,,,,,,,,,,,,
1432784737.764,,9.000000e+003,5.000333e+000,5.006153e+000,1,0,1.265394e+000,1.632740e-002,1.632740e-002,-8.874573e-003,1.296220e-002,-5.781809e-002,-8.302007e-002,-6.118330e-002,4.106903e-004,4.106903e-004,,,,,,,,,,,,,,,,,,,,
1432784737.764,,9.000000e+003,5.000333e+000,5.006153e+000,1,0,4.984988e+000,-5.005036e-002,-5.005036e-002,-2.244702e-001,-5.341556e-002,1.873061e-001,1.288622e-002,1.839409e-001,-1.258938e-003,-1.258938e-003,,,,,,,,,,,,,,,,,,,,
1432784747.865,,9.000000e+003,5.006153e+000,5.004294e+000,1,0,8.600062e-001,7.156590e-002,7.156590e-002,-3.967341e-002,4.743656e-002,1.310052e-001,1.976593e-002,1.068759e-001,1.800128e-003,1.800128e-003,,,,,,,,,,,,,,,,,,,,
1432784867.593,,7.000000e+003,5.000086e+000,5.005038e+000,1,0,2.367065e+000,-6.561480e-002,-6.561480e-002,-7.356491e-002,-7.017393e-002,-1.203309e-001,-1.282810e-001,-1.248900e-001,-1.650634e-003,-1.650634e-003,,,,,,,,,,,,,,,,,,,,
1432784867.593,,7.000000e+003,5.000086e+000,5.005038e+000,1,0,4.486504e+000,1.921140e-001,1.921140e-001,4.513414e-002,1.875549e-001,1.744828e-001,2.750291e-002,1.699236e-001,4.832903e-003,4.832903e-003,,,,,,,,,,,,,,,,,,,,
1432784877.830,,7.000000e+003,5.005038e+000,5.003180e+000,1,0,1.776886e-001,8.026368e-002,8.026368e-002,3.781298e-003,6.827737e-002,1.604957e-001,8.401327e-002,1.485093e-001,2.019148e-003,2.019148e-003,,,,,,,,,,,,,,,,,,,,
1432784877.830,,7.000000e+003,5.005038e+000,5.003180e+000,1,0,3.432520e+000,4.469436e-001,4.469436e-001,2.312855e-001,4.349573e-001,2.991554e-001,8.349726e-002,2.871691e-001,1.124351e-002,1.124351e-002,,,,,,,,,,,,,,,,,,,,
1432785006.272,,5.000000e+003,5.006153e+000,5.003551e+000,1,0,3.525053e+000,9.109775e-001,9.109775e-001,6.430765e-001,8.692455e-001,4.247551e-001,1.568541e-001,3.830231e-001,1.145984e-002,1.145984e-002,,,,,,,,,,,,,,,,,,,,
1432785016.487,,5.000000e+003,5.002437e+000,5.001818e+000,1,0,5.766493e-002,1.329081e-001,1.329081e-001,4.306976e-002,1.295578e-001,2.308913e-001,1.410529e-001,2.275409e-001,1.671946e-003,1.671946e-003,,,,,,,,,,,,,,,,,,,,
1432785016.487,,5.000000e+003,5.002437e+000,5.001818e+000,1,0,4.301063e+000,5.236976e-001,5.236976e-001,1.805730e-001,5.203472e-001,4.115231e-001,6.839845e-002,4.081727e-001,6.587967e-003,6.587967e-003,,,,,,,,,,,,,,,,,,,,
1432785135.723,,3.000000e+003,5.000457e+000,5.005038e+000,1,0,2.409979e+000,-1.091037e-001,-1.091037e-001,-2.641537e-001,-1.017901e-001,-2.882994e-002,-1.838800e-001,-2.151633e-002,-1.372656e-003,-1.372656e-003,,,,,,,,,,,,,,,,,,,,
1432785145.639,,3.000000e+003,5.005038e+000,5.002437e+000,1,0,6.841739e-001,8.941923e-002,8.941923e-002,4.003154e-002,8.643629e-002,1.305416e-001,8.115390e-002,1.275586e-001,1.125002e-003,1.125002e-003,,,,,,,,,,,,,,,,,,,,
1432785145.639,,3.000000e+003,5.005038e+000,5.002437e+000,1,0,4.911058e+000,-4.776147e-002,-4.776147e-002,-3.085486e-001,-5.074441e-002,2.820171e-001,2.123003e-002,2.790342e-001,-6.008971e-004,-6.008971e-004,,,,,,,,,,,,,,,,,,,,
1432785264.755,,1.000000e+003,4.999838e+000,5.005906e+000,1,0,1.380309e+000,-3.692740e-002,-3.692740e-002,-1.082625e-001,-1.635531e-002,-4.463141e-002,-1.159665e-001,-2.405932e-002,-4.646467e-004,-4.646467e-004,,,,,,,,,,,,,,,,,,,,
1432785283.935,,1.000000e+003,5.003428e+000,5.001818e+000,1,0,1.693983e+000,-1.736503e-001,-1.736503e-001,-1.855090e-001,-1.506654e-001,-4.695633e-001,-4.814220e-001,-4.465784e-001,-8.739966e-004,-8.739966e-004,,,,,,,,,,,,,,,,,,,,
1432785283.935,,1.000000e+003,5.003428e+000,5.001818e+000,1,0,4.870516e+000,-6.118961e-002,-6.118961e-002,-4.301948e-001,-3.820468e-002,4.083339e-001,3.932877e-002,4.313188e-001,-3.079724e-004,-3.079724e-004,,,,,,,,,,,,,,,,,,,,
1432785387.409,,5.000000e+002,4.999838e+000,5.005781e+000,1,0,5.492378e-001,1.503037e-001,1.503037e-001,-3.552314e-002,1.367140e-001,3.407527e-001,1.549259e-001,3.271630e-001,7.565134e-004,7.565134e-004,,,,,,,,,,,,,,,,,,,,
1432785387.409,,5.000000e+002,4.999838e+000,5.005781e+000,1,0,2.812430e+000,2.456740e-001,2.456740e-001,-2.611402e-001,2.320844e-001,4.694658e-001,-3.734845e-002,4.558762e-001,1.236535e-003,1.236535e-003,,,,,,,,,,,,,,,,,,,,
1432785397.624,,5.000000e+002,5.004914e+000,5.003922e+000,1,0,4.134631e+000,8.780175e-001,8.780175e-001,5.428745e-001,8.496000e-001,4.420536e-001,1.069106e-001,4.136361e-001,4.419267e-003,4.419267e-003,,,,,,,,,,,,,,,,,,,,
1432785501.104,,4.000000e+002,5.000457e+000,5.004542e+000,1,0,3.363986e-002,1.924192e-001,1.924192e-001,2.671819e-002,1.431150e-001,3.203767e-001,1.546757e-001,2.710725e-001,9.684964e-004,9.684964e-004,,,,,,,,,,,,,,,,,,,,
1432785501.104,,4.000000e+002,5.000457e+000,5.004542e+000,1,0,3.802031e+000,1.071200e+000,1.071200e+000,6.247769e-001,1.021896e+000,6.008812e-001,1.544584e-001,5.515770e-001,5.391630e-003,5.391630e-003,,,,,,,,,,,,,,,,,,,,
1432785511.069,,4.000000e+002,5.005906e+000,5.004294e+000,1,0,3.085773e+000,5.298013e-001,5.298013e-001,2.860431e-001,5.273962e-001,3.272613e-001,8.350315e-002,3.248562e-001,2.666629e-003,2.666629e-003,,,,,,,,,,,,,,,,,,,,
1432785615.794,,3.000000e+002,5.000333e+000,5.005781e+000,1,0,2.347292e-001,1.442000e-001,1.442000e-001,5.245721e-002,1.324006e-001,2.541384e-001,1.623957e-001,2.423390e-001,7.258006e-004,7.258006e-004,,,,,,,,,,,,,,,,,,,,
1432785615.794,,3.000000e+002,5.000333e+000,5.005781e+000,1,0,4.591934e+000,2.688681e-001,2.688681e-001,-9.601449e-002,2.570687e-001,4.086555e-001,4.377298e-002,3.968561e-001,1.353292e-003,1.353292e-003,,,,,,,,,,,,,,,,,,,,
1432785625.712,,3.000000e+002,5.005781e+000,5.004046e+000,1,0,1.974965e+000,-7.995849e-002,-7.995850e-002,-3.938098e-001,-2.001765e-001,-5.686833e-002,-3.707196e-001,-1.770863e-001,-4.024545e-004,-4.024545e-004,,,,,,,,,,,,,,,,,,,,
1432785729.582,,2.000000e+002,5.000333e+000,5.005906e+000,1,0,1.061791e+000,5.691702e-002,5.691702e-002,1.672333e-002,5.880241e-002,-5.799712e-003,-4.599340e-002,-3.914319e-003,2.864818e-004,2.864818e-004,,,,,,,,,,,,,,,,,,,,
1432785729.582,,2.000000e+002,5.000333e+000,5.005906e+000,1,0,4.992671e+000,-9.109775e-002,-9.109775e-002,-3.777546e-001,-8.921236e-002,3.074214e-001,2.076452e-002,3.093068e-001,-4.585244e-004,-4.585244e-004,,,,,,,,,,,,,,,,,,,,
1432785739.816,,2.000000e+002,5.005906e+000,5.004170e+000,1,0,1.025740e+000,1.205481e-001,1.205481e-001,-9.012590e-002,6.735475e-002,1.795472e-001,-3.112680e-002,1.263539e-001,6.067576e-004,6.067576e-004,,,,,,,,,,,,,,,,,,,,
1432785843.826,,1.000000e+002,5.000209e+000,5.005534e+000,1,0,2.140358e+000,-1.039155e-001,-1.039155e-001,-1.716282e-001,-1.609472e-001,-2.092230e-001,-2.769357e-001,-2.662548e-001,-5.230435e-004,-5.230435e-004,,,,,,,,,,,,,,,,,,,,
1432785843.826,,1.000000e+002,5.000209e+000,5.005534e+000,1,0,4.637918e+000,2.246162e-001,2.246162e-001,-6.205513e-002,1.675845e-001,3.200355e-001,3.336410e-002,2.630037e-001,1.130573e-003,1.130573e-003,,,,,,,,,,,,,,,,,,,,
1432785853.743,,1.000000e+002,5.005534e+000,5.002561e+000,1,0,2.834861e-001,-1.428266e-001,-1.428266e-001,-3.813643e-003,1.027269e-001,-4.768052e-003,1.342449e-001,2.407855e-001,-7.188967e-004,-7.188967e-004,,,,,,,,,,,,,,,,,,,,
1432785853.743,,1.000000e+002,5.005534e+000,5.002561e+000,1,0,3.233634e+000,2.716147e-001,2.716147e-001,1.922196e-001,5.171683e-001,1.802460e-001,1.008508e-001,4.257995e-001,1.367133e-003,1.367133e-003,,,,,,,,,,,,,,,,,,,,
1432785951.091,,0.000000e+000,4.999838e+000,5.005409e+000,1,0,3.736668e+000,8.113346e-001,8.113346e-001,5.232097e-001,7.034003e-001,3.973235e-001,1.091987e-001,2.893893e-001,4.083758e-003,4.083758e-003,,,,,,,,,,,,,,,,,,,,
1432785961.007,,0.000000e+000,5.005409e+000,5.003675e+000,1,0,1.639093e-002,1.170385e-001,1.170385e-001,2.842655e-002,9.802830e-002,1.902483e-001,1.016364e-001,1.712381e-001,5.890995e-004,5.890995e-004,,,,,,,,,,,,,,,,,,,,
1432785961.007,,0.000000e+000,5.005409e+000,5.003675e+000,1,0,4.141780e+000,5.294961e-001,5.294961e-001,2.506394e-001,5.104859e-001,3.451870e-001,6.633028e-002,3.261768e-001,2.665157e-003,2.665157e-003,,,,,,,,,,,,,,,,,,,,
1432786058.587,,-1.000000e+002,5.000086e+000,5.003922e+000,1,0,2.635160e+000,4.470962e-002,4.470962e-002,-9.961502e-002,1.860354e-002,7.536053e-002,-6.896410e-002,4.925445e-002,2.250393e-004,2.250393e-004,,,,,,,,,,,,,,,,,,,,
1432786068.503,,-1.000000e+002,5.005409e+000,5.003180e+000,1,0,5.152224e-001,1.698355e-001,1.698355e-001,3.266365e-002,7.070621e-002,2.224543e-001,8.528245e-002,1.233250e-001,8.548420e-004,8.548420e-004,,,,,,,,,,,,,,,,,,,,
1432786068.503,,-1.000000e+002,5.005409e+000,5.003180e+000,1,0,4.825858e+000,1.074252e-001,1.074252e-001,-1.857212e-001,8.295856e-003,3.109579e-001,1.781159e-002,2.118286e-001,5.407087e-004,5.407087e-004,,,,,,,,,,,,,,,,,,,,
1432786182.060,,-2.000000e+002,5.005161e+000,5.004170e+000,1,0,1.569962e+000,3.025910e-001,3.025910e-001,-4.705214e-001,-1.298098e-001,2.438235e-001,-5.292889e-001,-1.885772e-001,3.807596e-004,3.807596e-004,,,,,,,,,,,,,,,,,,,,
1432786192.084,,-2.000000e+002,5.004170e+000,5.002561e+000,1,0,1.475501e+000,-4.379406e-002,-4.379406e-002,-1.231072e-001,-6.145138e-002,-3.722379e-001,-4.515510e-001,-3.898952e-001,-5.510741e-005,-5.510741e-005,,,,,,,,,,,,,,,,,,,,
1432786192.084,,-2.000000e+002,5.004170e+000,5.002561e+000,1,0,4.943428e+000,-6.973480e-002,-6.973480e-002,-6.546258e-001,-8.739212e-002,6.296119e-001,4.472090e-002,6.119546e-001,-8.774944e-005,-8.774944e-005,,,,,,,,,,,,,,,,,,,,
1432786296.851,,-3.000000e+002,4.999962e+000,5.006153e+000,1,0,7.018046e-001,4.913480e-002,4.913480e-002,-5.515156e-002,8.519556e-002,2.134705e-001,1.091841e-001,2.495312e-001,6.182746e-005,6.182746e-005,,,,,,,,,,,,,,,,,,,,
1432786306.953,,-3.000000e+002,5.004046e+000,5.004542e+000,1,0,2.590922e+000,5.859554e-002,5.859554e-002,6.999314e-003,6.999314e-003,-1.080469e-001,-1.596432e-001,-1.596432e-001,7.373212e-005,7.373212e-005,,,,,,,,,,,,,,,,,,,,
1432786306.953,,-3.000000e+002,5.004046e+000,5.004542e+000,1,0,4.317018e+000,6.320384e-001,6.320384e-001,3.182333e-001,5.804421e-001,3.952191e-001,8.141397e-002,3.436228e-001,7.953085e-004,7.953085e-004,,,,,,,,,,,,,,,,,,,,
1432786420.234,,-4.000000e+002,5.005657e+000,5.004294e+000,1,0,9.017339e-002,-9.002960e-003,-9.002960e-003,2.194203e-002,9.229827e-002,1.233509e-001,1.542959e-001,2.246522e-001,-4.531427e-006,-4.531427e-006,,,,,,,,,,,,,,,,,,,,
1432786420.234,,-4.000000e+002,5.005657e+000,5.004294e+000,1,0,3.621422e+000,6.933805e-001,6.933805e-001,5.640696e-001,7.946818e-001,2.970185e-001,1.677076e-001,3.983197e-001,3.489967e-004,3.489967e-004,,,,,,,,,,,,,,,,,,,,
1432786430.902,,-4.000000e+002,5.002932e+000,5.001198e+000,1,0,3.307949e+000,3.242592e-001,3.242592e-001,4.847502e-001,6.535653e-001,-1.971997e-002,1.407710e-001,3.095862e-001,1.632082e-004,1.632082e-004,,,,,,,,,,,,,,,,,,,,
1432786534.686,,-5.000000e+002,5.000457e+000,5.005657e+000,1,0,1.313407e-001,-4.565569e-001,-4.565569e-001,-3.224623e-002,-1.569045e-001,-5.556949e-001,-1.313842e-001,-2.560425e-001,-2.297957e-004,-2.297957e-004,,,,,,,,,,,,,,,,,,,,
1432786534.686,,-5.000000e+002,5.000457e+000,5.005657e+000,1,0,4.451431e+000,-8.357494e-001,-8.357494e-001,-1.828556e-002,-5.360970e-001,-8.450364e-001,-2.757256e-002,-5.453840e-001,-4.206522e-004,-4.206522e-004,,,,,,,,,,,,,,,,,,,,
1432786544.758,,-5.000000e+002,5.005657e+000,5.003551e+000,1,0,2.189503e+000,-1.669362e-001,-1.669362e-001,4.370272e-001,1.519512e-001,-5.148290e-001,8.913452e-002,-1.959416e-001,-8.402291e-005,-8.402291e-005,,,,,,,,,,,,,,,,,,,,
1432786670.875,,-1.000000e+003,5.005038e+000,5.003551e+000,1,0,8.673304e-001,-1.727348e-001,-1.727348e-001,-3.826128e-002,-9.603266e-002,-1.668210e-001,-3.234747e-002,-9.011885e-002,-8.693885e-004,-8.693885e-004,,,,,,,,,,,,,,,,,,,,
1432786670.875,,-1.000000e+003,5.005038e+000,5.003551e+000,1,0,4.967049e+000,-1.892148e-002,-1.892148e-002,4.116303e-001,5.778063e-002,-4.542521e-001,-2.370035e-002,-3.775500e-001,-9.523337e-005,-9.523337e-005,,,,,,,,,,,,,,,,,,,,
1432786680.864,,-1.000000e+003,5.002437e+000,5.002313e+000,1,0,1.199946e+000,-1.443526e-001,-1.443526e-001,1.387170e-001,-4.850117e-002,-1.663142e-001,1.167553e-001,-7.046283e-002,-7.265385e-004,-7.265385e-004,,,,,,,,,,,,,,,,,,,,
1432786800.293,,-3.000000e+003,5.000457e+000,5.006402e+000,1,0,1.915540e+000,1.734977e-001,1.734977e-001,3.916124e-001,3.472473e-001,5.466464e-001,7.647610e-001,7.203960e-001,8.731246e-004,8.731246e-004,,,,,,,,,,,,,,,,,,,,
1432786800.293,,-3.000000e+003,5.000457e+000,5.006402e+000,1,0,4.766784e+000,-4.069643e-001,-4.069643e-001,4.174725e-001,-2.332148e-001,-8.912283e-001,-6.679144e-002,-7.174787e-001,-2.048041e-003,-2.048041e-003,,,,,,,,,,,,,,,,,,,,
1432786810.317,,-3.000000e+003,5.006402e+000,5.004418e+000,1,0,4.108160e-001,-4.649495e-001,-4.649495e-001,3.318358e-002,-2.761204e-001,-8.197418e-001,-3.216087e-001,-6.309127e-001,-2.339851e-003,-2.339851e-003,,,,,,,,,,,,,,,,,,,,
1432786810.317,,-3.000000e+003,5.006402e+000,5.004418e+000,1,0,3.026834e+000,-1.098056e+000,-1.098056e+000,3.956206e-003,-9.092268e-001,-1.217869e+000,-1.158565e-001,-1.029040e+000,-5.525949e-003,-5.525949e-003,,,,,,,,,,,,,,,,,,,,
1432786929.400,,-5.000000e+003,5.000209e+000,5.005781e+000,1,0,3.939903e+000,-2.493820e+000,-2.493820e+000,-1.550054e+000,-2.235507e+000,-1.238936e+000,-2.951699e-001,-9.806234e-001,-1.254862e-002,-1.254862e-002,,,,,,,,,,,,,,,,,,,,
1432786939.566,,-5.000000e+003,5.005781e+000,5.003922e+000,1,0,8.204076e-003,-6.033509e-001,-6.033509e-001,-7.835011e-002,-3.591343e-001,-8.620548e-001,-3.370540e-001,-6.178381e-001,-3.035993e-003,-3.035993e-003,,,,,,,,,,,,,,,,,,,,
1432786939.566,,-5.000000e+003,5.005781e+000,5.003922e+000,1,0,3.974742e+000,-2.427747e+000,-2.427747e+000,-1.183237e+000,-2.183531e+000,-1.526487e+000,-2.819763e-001,-1.282270e+000,-1.221615e-002,-1.221615e-002,,,,,,,,,,,,,,,,,,,,
1432787059.386,,-7.000000e+003,5.000086e+000,5.006030e+000,1,0,2.861219e+000,-1.023438e+000,-1.023438e+000,-1.002809e-001,-7.548795e-001,-8.956656e-001,2.749166e-002,-6.271069e-001,-5.149211e-003,-5.149211e-003,,,,,,,,,,,,,,,,,,,,
1432787069.458,,-7.000000e+003,5.005038e+000,5.003675e+000,1,0,3.640434e-001,-5.710013e-001,-5.710013e-001,-1.439822e-001,-3.553270e-001,-8.520166e-001,-4.249975e-001,-6.363422e-001,-2.872871e-003,-2.872871e-003,,,,,,,,,,,,,,,,,,,,
1432787069.458,,-7.000000e+003,5.005038e+000,5.003675e+000,1,0,4.717959e+000,-6.505020e-001,-6.505020e-001,5.642564e-001,-4.348277e-001,-1.308063e+000,-9.330491e-002,-1.092389e+000,-3.272862e-003,-3.272862e-003,,,,,,,,,,,,,,,,,,,,
1432787190.387,,-9.000000e+003,4.999838e+000,5.003798e+000,1,0,1.767633e+000,3.294473e-001,3.294473e-001,9.418253e-001,3.806780e-001,3.947413e-001,1.007119e+000,4.459720e-001,1.657346e-003,1.657346e-003,,,,,,,,,,,,,,,,,,,,
1432787200.409,,-9.000000e+003,5.005286e+000,5.002437e+000,1,0,1.265070e+000,-4.670858e-001,-4.670858e-001,4.605156e-002,-8.522260e-002,-9.798066e-002,4.151567e-001,2.838825e-001,-2.349762e-003,-2.349762e-003,,,,,,,,,,,,,,,,,,,,
1432787200.409,,-9.000000e+003,5.005286e+000,5.002437e+000,1,0,4.984626e+000,-2.903836e-001,-2.903836e-001,1.119794e+000,9.147957e-002,-1.474753e+000,-6.457583e-002,-1.092890e+000,-1.460829e-003,-1.460829e-003,,,,,,,,,,,,,,,,,,,,
1432787316.702,,-1.000000e+004,5.000209e+000,5.005781e+000,1,0,8.613396e-001,-5.763420e-001,-5.763420e-001,2.049530e-001,-2.964030e-001,-8.809630e-001,-9.966798e-002,-6.010239e-001,-2.899224e-003,-2.899224e-003,,,,,,,,,,,,,,,,,,,,
1432787326.773,,-1.000000e+004,5.005781e+000,5.003675e+000,1,0,2.366310e+000,2.096622e-001,2.096622e-001,4.044705e-001,3.835497e-001,5.121395e-001,7.069479e-001,6.860271e-001,1.054682e-003,1.054682e-003,,,,,,,,,,,,,,,,,,,,
1432787326.773,,-1.000000e+004,5.005781e+000,5.003675e+000,1,0,4.485759e+000,-1.301462e+000,-1.301462e+000,-2.489007e-001,-1.127574e+000,-1.204104e+000,-1.515427e-001,-1.030216e+000,-6.546858e-003,-6.546858e-003,,,,,,,,,,,,,,,,,,,,
1432787481.456,,-2.000000e+004,5.000209e+000,5.006278e+000,1,0,1.786761e-001,-8.746605e-001,-8.746605e-001,-2.677006e-002,-5.167260e-001,-1.409824e+000,-5.619337e-001,-1.051890e+000,-4.397262e-003,-4.397262e-003,,,,,,,,,,,,,,,,,,,,
1432787481.456,,-2.000000e+004,5.000209e+000,5.006278e+000,1,0,3.432130e+000,-3.446913e+000,-3.446913e+000,-1.541749e+000,-3.088979e+000,-2.463293e+000,-5.581290e-001,-2.105358e+000,-1.732899e-002,-1.732899e-002,,,,,,,,,,,,,,,,,,,,
1432787491.479,,-2.000000e+004,5.005781e+000,5.004542e+000,1,0,3.524928e+000,-3.664510e+000,-3.664510e+000,-2.352380e+000,-3.301384e+000,-1.887865e+000,-5.757346e-001,-1.524739e+000,-1.842293e-002,-1.842293e-002,,,,,,,,,,,,,,,,,,,,
1432787657.625,,-3.000000e+004,5.005161e+000,5.004666e+000,1,0,5.760435e-002,-3.538621e-001,-3.538621e-001,-7.399728e-002,-2.368995e-001,-5.161284e-001,-2.362636e-001,-3.991658e-001,-4.444861e-003,-4.444861e-003,,,,,,,,,,,,,,,,,,,,
1432787657.625,,-3.000000e+004,5.005161e+000,5.004666e+000,1,0,4.300251e+000,-1.059145e+000,-1.059145e+000,-3.022093e-001,-9.421822e-001,-8.715695e-001,-1.146339e-001,-7.546068e-001,-1.330392e-002,-1.330392e-002,,,,,,,,,,,,,,,,,,,,
1432787667.840,,-3.000000e+004,5.003551e+000,5.003180e+000,1,0,2.410189e+000,-7.934812e-003,-7.934812e-003,5.146986e-001,1.436464e-001,-1.639444e-001,3.586890e-001,-1.236327e-002,-9.966915e-005,-9.966915e-005,,,,,,,,,,,,,,,,,,,,
1432787826.571,,-4.000000e+004,5.000209e+000,5.005657e+000,1,0,6.837536e-001,-3.283792e-001,-3.283792e-001,-8.621845e-002,-2.016485e-001,-4.169610e-001,-1.748003e-001,-2.902303e-001,-4.122310e-003,-4.122310e-003,,,,,,,,,,,,,,,,,,,,
1432787826.571,,-4.000000e+004,5.000209e+000,5.005657e+000,1,0,4.907946e+000,-1.100192e-001,-1.100192e-001,6.579893e-001,1.671147e-002,-8.139535e-001,-4.594497e-002,-6.872228e-001,-1.381127e-003,-1.381127e-003,,,,,,,,,,,,,,,,,,,,
1432787836.785,,-4.000000e+004,5.004666e+000,5.003798e+000,1,0,1.379825e+000,-1.763970e-001,-1.763970e-001,3.370239e-001,-7.271603e-003,-1.533653e-001,3.600556e-001,1.576012e-002,-2.214401e-003,-2.214401e-003,,,,,,,,,,,,,,,,,,,,
1432787997.722,,-5.000000e+004,5.000333e+000,5.006030e+000,1,0,1.693704e+000,2.456740e-002,2.456740e-002,2.529317e-001,1.983434e-001,4.158831e-001,6.442474e-001,5.896591e-001,3.082232e-004,3.082232e-004,,,,,,,,,,,,,,,,,,,,
1432787997.722,,-5.000000e+004,5.000333e+000,5.006030e+000,1,0,4.870277e+000,-2.186651e-001,-2.186651e-001,5.692291e-001,-4.488911e-002,-8.405981e-001,-5.270389e-002,-6.668221e-001,-2.743378e-003,-2.743378e-003,,,,,,,,,,,,,,,,,,,,
1432788007.498,,-5.000000e+004,5.006030e+000,5.003922e+000,1,0,5.502014e-001,-3.650014e-001,-3.650014e-001,5.765297e-002,-2.414301e-001,-6.801377e-001,-2.574833e-001,-5.565664e-001,-4.579315e-003,-4.579315e-003,,,,,,,,,,,,,,,,,,,,
1432788007.498,,-5.000000e+004,5.006030e+000,5.003922e+000,1,0,2.811890e+000,-5.452132e-001,-5.452132e-001,4.348233e-001,-4.216419e-001,-9.181872e-001,6.184927e-002,-7.946159e-001,-6.840257e-003,-6.840257e-003,,,,,,,,,,,,,,,,,,,,
1432788164.537,,-6.000000e+004,4.999715e+000,5.006030e+000,1,0,4.134231e+000,-1.698508e+000,-1.698508e+000,-9.530748e-001,-1.521816e+000,-9.343162e-001,-1.888833e-001,-7.576249e-001,-2.129680e-002,-2.129680e-002,,,,,,,,,,,,,,,,,,,,
1432788174.659,,-6.000000e+004,5.004914e+000,5.003675e+000,1,0,3.531310e-002,-3.363140e-001,-3.363140e-001,-5.460469e-002,-2.865059e-001,-5.729339e-001,-2.912246e-001,-5.231258e-001,-4.216884e-003,-4.216884e-003,,,,,,,,,,,,,,,,,,,,
1432788174.659,,-6.000000e+004,5.004914e+000,5.003675e+000,1,0,3.801466e+000,-2.005829e+000,-2.005829e+000,-1.164829e+000,-1.956021e+000,-1.131009e+000,-2.900090e-001,-1.081201e+000,-2.515016e-002,-2.515016e-002,,,,,,,,,,,,,,,,,,,,
1432788333.172,,-7.000000e+004,5.000086e+000,5.006402e+000,1,0,3.086367e+000,-1.216773e+000,-1.216773e+000,-5.556898e-001,-1.061630e+000,-8.252574e-001,-1.641742e-001,-6.701146e-001,-1.524744e-002,-1.524744e-002,,,,,,,,,,,,,,,,,,,,
1432788343.386,,-7.000000e+004,5.006402e+000,5.004294e+000,1,0,2.343208e-001,-4.225288e-001,-4.225288e-001,-1.145735e-001,-2.882847e-001,-6.505175e-001,-3.425622e-001,-5.162734e-001,-5.294728e-003,-5.294728e-003,,,,,,,,,,,,,,,,,,,,
1432788343.386,,-7.000000e+004,5.006402e+000,5.004294e+000,1,0,4.592407e+000,-7.069613e-001,-7.069613e-001,1.945073e-001,-5.727172e-001,-9.937119e-001,-9.224333e-002,-8.594679e-001,-8.858965e-003,-8.858965e-003,,,,,,,,,,,,,,,,,,,,
1432788506.374,,-6.000000e+004,5.000333e+000,5.005657e+000,1,0,1.974855e+000,3.016755e-001,3.016755e-001,7.945180e-001,3.914071e-001,2.574108e-001,7.502533e-001,3.471424e-001,3.782568e-003,3.782568e-003,,,,,,,,,,,,,,,,,,,,
1432788516.291,,-6.000000e+004,5.005657e+000,5.003428e+000,1,0,1.061285e+000,-2.191229e-001,-2.191229e-001,-3.316420e-002,-1.275914e-001,-8.261988e-002,1.033388e-001,8.911632e-003,-2.747480e-003,-2.747480e-003,,,,,,,,,,,,,,,,,,,,
1432788516.291,,-6.000000e+004,5.005657e+000,5.003428e+000,1,0,4.991348e+000,8.758812e-002,8.758812e-002,8.266203e-001,1.791196e-001,-7.847968e-001,-4.576458e-002,-6.932653e-001,1.098227e-003,1.098227e-003,,,,,,,,,,,,,,,,,,,,
1432788677.079,,-5.000000e+004,5.000209e+000,5.005906e+000,1,0,1.025576e+000,-1.802118e-001,-1.802118e-001,1.906885e-001,-1.231864e-001,-3.037802e-001,6.712005e-002,-2.467548e-001,-2.260941e-003,-2.260941e-003,,,,,,,,,,,,,,,,,,,,
1432788687.152,,-5.000000e+004,5.004914e+000,5.004046e+000,1,0,2.139926e+000,3.563036e-001,3.563036e-001,3.961049e-001,3.709074e-001,6.013771e-001,6.411784e-001,6.159809e-001,4.470193e-003,4.470193e-003,,,,,,,,,,,,,,,,,,,,
1432788687.152,,-5.000000e+004,5.004914e+000,5.004046e+000,1,0,4.638033e+000,-4.130680e-001,-4.130680e-001,1.432830e-001,-3.984642e-001,-6.333387e-001,-7.698774e-002,-6.187350e-001,-5.182361e-003,-5.182361e-003,,,,,,,,,,,,,,,,,,,,
1432788840.362,,-4.000000e+004,5.000209e+000,5.005286e+000,1,0,2.824666e-001,-2.529984e-001,-2.529984e-001,4.804183e-003,-2.270124e-001,-5.477441e-001,-2.899415e-001,-5.217580e-001,-3.176018e-003,-3.176018e-003,,,,,,,,,,,,,,,,,,,,
1432788840.362,,-4.000000e+004,5.000209e+000,5.005286e+000,1,0,3.233500e+000,-1.147496e+000,-1.147496e+000,-4.144695e-001,-1.121510e+000,-9.518474e-001,-2.188208e-001,-9.258613e-001,-1.440510e-002,-1.440510e-002,,,,,,,,,,,,,,,,,,,,
1432788850.466,,-4.000000e+004,5.004418e+000,5.003304e+000,1,0,3.736079e+000,-1.767937e+000,-1.767937e+000,-1.281238e+000,-1.722681e+000,-7.551658e-001,-2.684666e-001,-7.099094e-001,-2.219381e-002,-2.219381e-002,,,,,,,,,,,,,,,,,,,,
1432789007.147,,-3.000000e+004,5.000209e+000,5.006650e+000,1,0,1.626179e-002,-2.545244e-001,-2.545244e-001,-6.458367e-002,-2.203991e-001,-4.175774e-001,-2.276367e-001,-3.834521e-001,-3.197080e-003,-3.197080e-003,,,,,,,,,,,,,,,,,,,,
1432789007.147,,-3.000000e+004,5.000209e+000,5.006650e+000,1,0,4.141387e+000,-1.173742e+000,-1.173742e+000,-5.579057e-001,-1.139616e+000,-7.635478e-001,-1.477117e-001,-7.294225e-001,-1.474337e-002,-1.474337e-002,,,,,,,,,,,,,,,,,,,,
1432789017.173,,-3.000000e+004,5.005534e+000,5.004170e+000,1,0,2.635389e+000,-1.200903e-001,-1.200903e-001,2.642090e-001,-8.039260e-002,-2.031566e-001,1.811428e-001,-1.634589e-001,-1.508454e-003,-1.508454e-003,,,,,,,,,,,,,,,,,,,,
1432789173.265,,-2.000000e+004,4.999962e+000,5.006030e+000,1,0,5.150701e-001,-1.707511e-001,-1.707511e-001,-7.530272e-002,-1.646588e-001,-2.947337e-001,-1.992854e-001,-2.886415e-001,-2.146082e-003,-2.146082e-003,,,,,,,,,,,,,,,,,,,,
1432789173.265,,-2.000000e+004,4.999962e+000,5.006030e+000,1,0,4.825586e+000,-2.426222e-002,-2.426222e-002,4.375461e-001,-1.816996e-002,-5.034100e-001,-4.160174e-002,-4.973178e-001,-3.049393e-004,-3.049393e-004,,,,,,,,,,,,,,,,,,,,
1432789183.481,,-2.000000e+004,5.005534e+000,5.004046e+000,1,0,1.569382e+000,2.868740e-002,2.868740e-002,3.631247e-001,9.012596e-002,7.597135e-002,4.104086e-001,1.374099e-001,3.605571e-004,3.605571e-004,,,,,,,,,,,,,,,,,,,,
1432789336.914,,-1.000000e+004,5.000333e+000,5.006030e+000,1,0,1.475831e+000,2.746666e-002,2.746666e-002,7.594121e-002,3.780862e-002,2.407373e-001,2.892118e-001,2.510793e-001,3.454199e-004,3.454199e-004,,,,,,,,,,,,,,,,,,,,
1432789336.914,,-1.000000e+004,5.000333e+000,5.006030e+000,1,0,4.944246e+000,5.981628e-002,5.981628e-002,4.209780e-001,7.015824e-002,-3.894014e-001,-2.823970e-002,-3.790594e-001,7.522478e-004,7.522478e-004,,,,,,,,,,,,,,,,,,,,
1432789346.986,,-1.000000e+004,5.006030e+000,5.004294e+000,1,0,7.009042e-001,3.662221e-003,3.662221e-003,5.610102e-002,-9.476430e-002,-1.599462e-001,-1.075074e-001,-2.583728e-001,4.605599e-005,4.605599e-005,,,,,,,,,,,,,,,,,,,,
1432789463.491,,-9.000000e+003,5.000333e+000,5.006030e+000,1,0,2.591454e+000,-2.945036e-002,-2.945036e-002,-1.076468e-002,-1.076468e-002,1.327919e-001,1.514776e-001,1.514776e-001,-3.703889e-004,-3.703889e-004,,,,,,,,,,,,,,,,,,,,
1432789463.491,,-9.000000e+003,5.000333e+000,5.006030e+000,1,0,4.317699e+000,-6.212043e-001,-6.212043e-001,-3.060044e-001,-6.025186e-001,-3.932507e-001,-7.805087e-002,-3.745650e-001,-7.812711e-003,-7.812711e-003,,,,,,,,,,,,,,,,,,,,
1432789473.407,,-9.000000e+003,5.006030e+000,5.002932e+000,1,0,9.144550e-002,-1.452681e-001,-1.452681e-001,-1.931813e-002,-1.495407e-001,-2.963616e-001,-1.704116e-001,-3.006341e-001,-1.826996e-003,-1.826996e-003,,,,,,,,,,,,,,,,,,,,
1432789473.407,,-9.000000e+003,5.006030e+000,5.002932e+000,1,0,3.621001e+000,-1.059908e+000,-1.059908e+000,-6.373398e-001,-1.064180e+000,-6.044526e-001,-1.818845e-001,-6.087251e-001,-1.333016e-002,-1.333016e-002,,,,,,,,,,,,,,,,,,,,
1432789592.692,,-7.000000e+003,5.000333e+000,5.005781e+000,1,0,3.308230e+000,-7.715080e-001,-7.715079e-001,-5.217906e-001,-7.650219e-001,-3.976715e-001,-1.479542e-001,-3.911854e-001,-9.704193e-003,-9.704193e-003,,,,,,,,,,,,,,,,,,,,
1432789602.967,,-7.000000e+003,5.005286e+000,5.003922e+000,1,0,1.314669e-001,-1.547288e-001,-1.547288e-001,-5.269510e-002,-1.408476e-001,-2.659614e-001,-1.639277e-001,-2.520802e-001,-1.946213e-003,-1.946213e-003,,,,,,,,,,,,,,,,,,,,
1432789602.967,,-7.000000e+003,5.005286e+000,5.003922e+000,1,0,4.450811e+000,-4.199347e-001,-4.199347e-001,-3.988141e-002,-4.060535e-001,-4.384737e-001,-5.842045e-002,-4.245925e-001,-5.282029e-003,-5.282029e-003,,,,,,,,,,,,,,,,,,,,
1432789722.757,,-5.000000e+003,5.000457e+000,5.005534e+000,1,0,2.189291e+000,2.291940e-001,2.291940e-001,3.832176e-001,1.946809e-001,1.527861e-001,3.068097e-001,1.182729e-001,2.883195e-003,2.883195e-003,,,,,,,,,,,,,,,,,,,,
1432789732.829,,-5.000000e+003,5.005534e+000,5.003675e+000,1,0,8.672186e-001,-5.813776e-002,-5.813776e-002,-3.630527e-002,-8.507983e-002,-5.282501e-002,-3.099252e-002,-7.976707e-002,-7.313564e-004,-7.313564e-004,,,,,,,,,,,,,,,,,,,,
1432789732.829,,-5.000000e+003,5.005534e+000,5.003675e+000,1,0,4.967239e+000,1.193274e-001,1.193274e-001,3.911294e-001,9.238531e-002,-2.943944e-001,-2.259237e-002,-3.213365e-001,1.501104e-003,1.501104e-003,,,,,,,,,,,,,,,,,,,,
1432789845.256,,-3.000000e+003,5.000086e+000,5.004914e+000,1,0,1.198966e+000,2.609333e-002,2.609333e-002,1.133655e-001,-1.991489e-002,7.396928e-003,9.466905e-002,-3.861129e-002,3.282856e-004,3.282856e-004,,,,,,,,,,,,,,,,,,,,
1432789855.328,,-3.000000e+003,5.005286e+000,5.004046e+000,1,0,1.915818e+000,1.823481e-001,1.823481e-001,1.577948e-001,1.422474e-001,3.323165e-001,3.077632e-001,2.922158e-001,2.294160e-003,2.294160e-003,,,,,,,,,,,,,,,,,,,,
1432789855.328,,-3.000000e+003,5.005286e+000,5.004046e+000,1,0,4.766759e+000,-1.907407e-002,-1.907407e-002,1.688532e-001,-5.917475e-002,-2.148021e-001,-2.687481e-002,-2.549028e-001,-2.399749e-004,-2.399749e-004,,,,,,,,,,,,,,,,,,,,
1432789973.803,,-1.000000e+003,4.999962e+000,5.005534e+000,1,0,4.086904e-001,-3.646962e-002,-3.646962e-002,9.752206e-003,-6.142399e-002,-1.362561e-001,-9.003429e-002,-1.612105e-001,-4.588866e-004,-4.588866e-004,,,,,,,,,,,,,,,,,,,,
1432789973.803,,-1.000000e+003,4.999962e+000,5.005534e+000,1,0,3.026510e+000,-1.852473e-001,-1.852473e-001,-6.247126e-005,-2.102017e-001,-2.173374e-001,-3.215253e-002,-2.422918e-001,-2.330914e-003,-2.330914e-003,,,,,,,,,,,,,,,,,,,,
1432789983.603,,-1.000000e+003,5.005534e+000,5.003180e+000,1,0,3.940248e+000,-4.853969e-001,-4.853969e-001,-3.694004e-001,-5.014352e-001,-1.861594e-001,-7.016294e-002,-2.021977e-001,-6.107608e-003,-6.107608e-003,,,,,,,,,,,,,,,,,,,,
1432790109.105,,-5.000000e+002,5.005657e+000,5.003428e+000,1,0,8.873480e-003,-2.465896e-001,-2.465896e-001,-3.649139e-002,-1.669861e-001,-3.706186e-001,-1.605204e-001,-2.910151e-001,-1.241143e-003,-1.241143e-003,,,,,,,,,,,,,,,,,,,,
1432790109.105,,-5.000000e+002,5.005657e+000,5.003428e+000,1,0,3.975535e+000,-1.109806e+000,-1.109806e+000,-5.653147e-001,-1.030202e+000,-6.787798e-001,-1.342888e-001,-5.991763e-001,-5.585910e-003,-5.585910e-003,,,,,,,,,,,,,,,,,,,,
1432790119.570,,-5.000000e+002,5.003428e+000,5.001570e+000,1,0,2.860767e+000,-2.685629e-001,-2.685629e-001,-4.319095e-002,-3.049837e-001,-2.126289e-001,1.274306e-002,-2.490497e-001,-1.351740e-003,-1.351740e-003,,,,,,,,,,,,,,,,,,,,
1432790223.745,,-4.000000e+002,5.000580e+000,5.005161e+000,1,0,3.640756e-001,-1.306192e-001,-1.306192e-001,-5.871154e-002,-1.328602e-001,-2.452053e-001,-1.732976e-001,-2.474463e-001,-6.574409e-004,-6.574409e-004,,,,,,,,,,,,,,,,,,,,
1432790223.745,,-4.000000e+002,5.000580e+000,5.005161e+000,1,0,4.717769e+000,-1.184118e-001,-1.184118e-001,2.298684e-001,-1.206528e-001,-3.863741e-001,-3.809397e-002,-3.886152e-001,-5.959978e-004,-5.959978e-004,,,,,,,,,,,,,,,,,,,,
1432790233.770,,-4.000000e+002,5.005657e+000,5.004294e+000,1,0,1.767720e+000,1.434370e-001,1.434370e-001,3.582308e-001,1.586134e-001,1.688471e-001,3.836409e-001,1.840236e-001,7.219561e-004,7.219561e-004,,,,,,,,,,,,,,,,,,,,
1432790337.644,,-3.000000e+002,5.000333e+000,5.006153e+000,1,0,1.264896e+000,-1.770074e-002,-1.770074e-002,1.424706e-002,-2.355221e-002,1.143790e-001,1.463268e-001,1.085275e-001,-8.909298e-005,-8.909298e-005,,,,,,,,,,,,,,,,,,,,
1432790337.644,,-3.000000e+002,5.000333e+000,5.006153e+000,1,0,4.985313e+000,1.095614e-001,1.095615e-001,3.998042e-001,1.037100e-001,-3.131377e-001,-2.289499e-002,-3.189892e-001,5.514548e-004,5.514548e-004,,,,,,,,,,,,,,,,,,,,
1432790347.880,,-3.000000e+002,5.006153e+000,5.004294e+000,1,0,8.613248e-001,-4.501480e-002,-4.501480e-002,7.155369e-002,-8.085310e-002,-1.513956e-001,-3.482709e-002,-1.872339e-001,-2.265727e-004,-2.265727e-004,,,,,,,,,,,,,,,,,,,,
1432790451.854,,-2.000000e+002,5.000333e+000,5.003922e+000,1,0,2.366635e+000,1.626637e-001,1.626637e-001,1.273900e-001,1.209397e-001,2.588004e-001,2.235267e-001,2.170765e-001,8.187387e-004,8.187387e-004,,,,,,,,,,,,,,,,,,,,
1432790451.854,,-2.000000e+002,5.000333e+000,5.003922e+000,1,0,4.486506e+000,-3.077792e-001,-3.077792e-001,-7.859292e-002,-3.495031e-001,-2.770534e-001,-4.786714e-002,-3.187773e-001,-1.549152e-003,-1.549152e-003,,,,,,,,,,,,,,,,,,,,
1432790461.771,,-2.000000e+002,5.005409e+000,5.003551e+000,1,0,1.776775e-001,-4.394665e-002,-4.394665e-002,-6.397716e-003,-1.188230e-001,-1.833136e-001,-1.457647e-001,-2.581900e-001,-2.211977e-004,-2.211977e-004,,,,,,,,,,,,,,,,,,,,
1432790461.771,,-2.000000e+002,5.005409e+000,5.003551e+000,1,0,3.432348e+000,-6.836146e-001,-6.836146e-001,-4.034637e-001,-7.584910e-001,-4.249724e-001,-1.448215e-001,-4.998488e-001,-3.440853e-003,-3.440853e-003,,,,,,,,,,,,,,,,,,,,
1432790565.602,,-1.000000e+002,5.000333e+000,5.006030e+000,1,0,3.525466e+000,-7.438887e-001,-7.438887e-001,-5.512443e-001,-7.553234e-001,-3.268966e-001,-1.342522e-001,-3.383313e-001,-3.744254e-003,-3.744254e-003,,,,,,,,,,,,,,,,,,,,
1432790575.519,,-1.000000e+002,5.004542e+000,5.004542e+000,1,0,5.747003e-002,-7.736442e-002,-7.736442e-002,-4.450887e-002,-1.120269e-001,-1.528049e-001,-1.199494e-001,-1.874674e-001,-3.894024e-004,-3.894024e-004,,,,,,,,,,,,,,,,,,,,
1432790575.519,,-1.000000e+002,5.004542e+000,5.004542e+000,1,0,4.300105e+000,-3.923154e-001,-3.923154e-001,-1.617285e-001,-4.269779e-001,-2.893018e-001,-5.871492e-002,-3.239643e-001,-1.974662e-003,-1.974662e-003,,,,,,,,,,,,,,,,,,,,
1432790672.884,,0.000000e+000,4.999838e+000,5.005906e+000,1,0,2.410145e+000,8.621479e-002,8.621479e-002,2.300996e-001,8.451793e-002,1.687523e-002,1.607600e-001,1.517837e-002,4.339521e-004,4.339521e-004,,,,,,,,,,,,,,,,,,,,
1432790682.801,,0.000000e+000,5.005906e+000,5.003798e+000,1,0,6.838768e-001,-8.682516e-002,-8.682516e-002,-3.515157e-002,-7.653360e-002,-1.227173e-001,-7.104374e-002,-1.124258e-001,-4.370243e-004,-4.370243e-004,,,,,,,,,,,,,,,,,,,,
1432790682.801,,0.000000e+000,5.005906e+000,5.003798e+000,1,0,4.910100e+000,2.822962e-002,2.822962e-002,2.684214e-001,3.852118e-002,-2.587673e-001,-1.857556e-002,-2.484757e-001,1.420905e-004,1.420905e-004,,,,,,,,,,,,,,,,,,,,
1432790786.334,,1.000000e+002,5.000209e+000,5.004914e+000,1,0,1.380249e+000,6.393628e-002,6.393628e-002,1.143719e-001,1.789274e-002,7.131410e-002,1.217498e-001,2.527057e-002,3.218138e-004,3.218138e-004,,,,,,,,,,,,,,,,,,,,
1432790796.406,,1.000000e+002,5.005409e+000,5.004418e+000,1,0,1.693468e+000,7.522812e-002,7.522812e-002,7.721266e-002,6.203555e-002,1.994155e-001,2.014000e-001,1.862229e-001,3.786497e-004,3.786497e-004,,,,,,,,,,,,,,,,,,,,
1432790796.406,,1.000000e+002,5.005409e+000,5.004418e+000,1,0,4.870215e+000,2.136296e-002,2.136296e-002,1.789129e-001,8.170377e-003,-1.740424e-001,-1.649251e-002,-1.872350e-001,1.075273e-004,1.075273e-004,,,,,,,,,,,,,,,,,,,,
1432790909.150,,2.000000e+002,5.005781e+000,5.003180e+000,1,0,5.489703e-001,-1.608326e-001,-1.608325e-001,5.428625e-002,-1.892286e-001,-4.623530e-001,-2.472342e-001,-4.907490e-001,-2.023805e-004,-2.023805e-004,,,,,,,,,,,,,,,,,,,,
1432790909.150,,2.000000e+002,5.005781e+000,5.003180e+000,1,0,2.812380e+000,-2.508622e-001,-2.508622e-001,4.180797e-001,-2.792582e-001,-6.089250e-001,6.001681e-002,-6.373211e-001,-3.156676e-004,-3.156676e-004,,,,,,,,,,,,,,,,,,,,
1432790919.364,,2.000000e+002,5.003551e+000,5.001570e+000,1,0,4.134172e+000,-1.174657e+000,-1.174657e+000,-8.624359e-001,-1.334673e+000,-4.828471e-001,-1.706255e-001,-6.428629e-001,-1.478108e-003,-1.478108e-003,,,,,,,,,,,,,,,,,,,,
1432791023.588,,3.000000e+002,5.000086e+000,5.005906e+000,1,0,3.453095e-002,-6.057924e-002,-6.057924e-002,-2.782869e-002,-1.427946e-001,-1.986377e-001,-1.658871e-001,-2.808531e-001,-7.622827e-005,-7.622827e-005,,,,,,,,,,,,,,,,,,,,
1432791023.588,,3.000000e+002,5.000086e+000,5.005906e+000,1,0,3.802041e+000,-9.784234e-001,-9.784234e-001,-6.684020e-001,-1.060639e+000,-4.759304e-001,-1.659091e-001,-5.581458e-001,-1.231173e-003,-1.231173e-003,,,,,,,,,,,,,,,,,,,,
1432791033.600,,3.000000e+002,5.005409e+000,5.004294e+000,1,0,3.086856e+000,-4.968413e-001,-4.968413e-001,-3.008894e-001,-5.405962e-001,-2.848486e-001,-8.889674e-002,-3.286035e-001,-6.251869e-004,-6.251869e-004,,,,,,,,,,,,,,,,,,,,
1432791147.849,,4.000000e+002,5.006526e+000,5.004294e+000,1,0,2.346409e-001,5.110325e-001,5.110325e-001,-1.201551e-001,-1.987232e-001,3.018624e-001,-3.293251e-001,-4.078932e-001,1.286080e-004,1.286080e-004,,,,,,,,,,,,,,,,,,,,
1432791147.849,,4.000000e+002,5.006526e+000,5.004294e+000,1,0,4.591418e+000,5.272073e-001,5.272073e-001,1.644608e-001,-1.825484e-001,2.721090e-001,-9.063746e-002,-4.376467e-001,1.326786e-004,1.326786e-004,,,,,,,,,,,,,,,,,,,,
1432791158.314,,4.000000e+002,5.004294e+000,5.003428e+000,1,0,1.974916e+000,9.759820e-001,9.759820e-001,7.787665e-001,5.411652e-001,9.419282e-001,7.447127e-001,5.071115e-001,2.456187e-004,2.456187e-004,,,,,,,,,,,,,,,,,,,,
1432791262.571,,5.000000e+002,5.000333e+000,5.005906e+000,1,0,1.061304e+000,8.368175e-001,8.368175e-001,2.124341e-002,1.683866e-001,3.920769e-001,-4.234972e-001,-2.763540e-001,2.105949e-004,2.105949e-004,,,,,,,,,,,,,,,,,,,,
1432791262.571,,5.000000e+002,5.000333e+000,5.005906e+000,1,0,4.992949e+000,7.307657e-001,7.307657e-001,-9.466473e-001,6.233484e-002,1.694193e+000,1.677954e-002,1.025762e+000,1.839057e-004,1.839057e-004,,,,,,,,,,,,,,,,,,,,
1432791273.535,,5.000000e+002,5.003551e+000,5.004294e+000,1,0,1.026303e+000,6.534013e-001,6.534013e-001,-2.025869e-001,2.019729e-001,7.815331e-001,-7.445514e-002,3.301047e-001,1.644361e-004,1.644361e-004,,,,,,,,,,,,,,,,,,,,
1432791398.241,,1.000000e+003,5.005906e+000,5.003180e+000,1,0,2.140297e+000,-1.207007e-001,-1.207007e-001,-2.089726e-001,-1.946308e-001,-2.505838e-001,-3.388557e-001,-3.245140e-001,-6.074968e-004,-6.074968e-004,,,,,,,,,,,,,,,,,,,,
1432791398.241,,1.000000e+003,5.005906e+000,5.003180e+000,1,0,4.638039e+000,3.047273e-001,3.047273e-001,-7.755023e-002,2.307972e-001,4.230139e-001,4.073638e-002,3.490838e-001,1.533718e-003,1.533718e-003,,,,,,,,,,,,,,,,,,,,
1432791408.206,,1.000000e+003,5.003180e+000,5.001941e+000,1,0,2.838780e-001,2.175970e-001,2.175970e-001,-4.107978e-003,1.394953e-001,3.866653e-001,1.649604e-001,3.085637e-001,1.095184e-003,1.095184e-003,,,,,,,,,,,,,,,,,,,,
1432791408.206,,1.000000e+003,5.003180e+000,5.001941e+000,1,0,3.234126e+000,7.539598e-001,7.539598e-001,2.378681e-001,6.758581e-001,6.405199e-001,1.244282e-001,5.624182e-001,3.794743e-003,3.794743e-003,,,,,,,,,,,,,,,,,,,,
1432791521.187,,3.000000e+003,5.000580e+000,5.005657e+000,1,0,3.736931e+000,2.380596e+000,2.380596e+000,1.486801e+000,2.057190e+000,1.203598e+000,3.098024e-001,8.801917e-001,1.198031e-002,1.198031e-002,,,,,,,,,,,,,,,,,,,,
1432791531.401,,3.000000e+003,5.005657e+000,5.003055e+000,1,0,1.630366e-002,5.923643e-001,5.923643e-001,7.988103e-002,3.052133e-001,8.017767e-001,2.892935e-001,5.146258e-001,2.981064e-003,2.981064e-003,,,,,,,,,,,,,,,,,,,,
1432791531.401,,3.000000e+003,5.005657e+000,5.003055e+000,1,0,4.141684e+000,1.839808e+000,1.839808e+000,7.114170e-001,1.552657e+000,1.316741e+000,1.883497e-001,1.029590e+000,9.258807e-003,9.258807e-003,,,,,,,,,,,,,,,,,,,,
1432791644.626,,5.000000e+003,4.999962e+000,5.005906e+000,1,0,2.635132e+000,5.500962e-001,5.500962e-001,-3.953518e-001,1.905588e-001,6.717566e-001,-2.736914e-001,3.122192e-001,2.768021e-003,2.768021e-003,,,,,,,,,,,,,,,,,,,,
1432791654.794,,5.000000e+003,5.004914e+000,5.004046e+000,1,0,5.150432e-001,6.268502e-001,6.268502e-001,1.286279e-001,3.043765e-001,8.387508e-001,3.405284e-001,5.162771e-001,3.154238e-003,3.154238e-003,,,,,,,,,,,,,,,,,,,,
1432791654.794,,5.000000e+003,5.004914e+000,5.004046e+000,1,0,4.825416e+000,4.716636e-001,4.716636e-001,-7.471282e-001,1.491899e-001,1.289926e+000,7.113419e-002,9.674522e-001,2.373357e-003,2.373357e-003,,,,,,,,,,,,,,,,,,,,
1432791774.376,,7.000000e+003,4.999962e+000,5.005781e+000,1,0,1.569308e+000,2.235481e-001,2.235481e-001,-6.785097e-001,-1.376147e-001,1.353793e-001,-7.666785e-001,-2.257835e-001,1.124734e-003,1.124734e-003,,,,,,,,,,,,,,,,,,,,
1432791784.925,,7.000000e+003,5.005781e+000,5.003922e+000,1,0,1.476396e+000,1.905881e-001,1.905881e-001,-1.742365e-001,-7.815906e-002,-2.924938e-001,-6.573185e-001,-5.612410e-001,9.589032e-004,9.589032e-004,,,,,,,,,,,,,,,,,,,,
1432791784.925,,7.000000e+003,5.005781e+000,5.003922e+000,1,0,4.944098e+000,1.973022e-001,1.973022e-001,-9.553576e-001,-7.144499e-002,1.217084e+000,6.442397e-002,9.483365e-001,9.926837e-004,9.926837e-004,,,,,,,,,,,,,,,,,,,,
1432791899.651,,9.000000e+003,5.000086e+000,5.005286e+000,1,0,7.010118e-001,1.018403e+000,1.018403e+000,-1.331075e-001,3.922651e-001,1.414365e+000,2.628547e-001,7.882273e-001,5.123266e-003,5.123266e-003,,,,,,,,,,,,,,,,,,,,
1432791909.866,,9.000000e+003,5.005286e+000,5.003304e+000,1,0,2.591585e+000,2.398755e-001,2.398755e-001,2.425070e-002,2.425070e-002,-1.642940e-001,-3.799188e-001,-3.799188e-001,1.206739e-003,1.206739e-003,,,,,,,,,,,,,,,,,,,,
1432791909.866,,9.000000e+003,5.005286e+000,5.003304e+000,1,0,4.317758e+000,1.796777e+000,1.796777e+000,7.680433e-001,1.581152e+000,1.224288e+000,1.955538e-001,1.008663e+000,9.039025e-003,9.039025e-003,,,,,,,,,,,,,,,,,,,,
1432792026.294,,1.000000e+004,5.000333e+000,5.005286e+000,1,0,9.240586e-002,6.830043e-001,6.830043e-001,4.973108e-002,4.264503e-001,1.072016e+000,4.387429e-001,8.154621e-001,3.435776e-003,3.435776e-003,,,,,,,,,,,,,,,,,,,,
1432792026.294,,1.000000e+004,5.000333e+000,5.005286e+000,1,0,3.620464e+000,3.127537e+000,3.127537e+000,1.636181e+000,2.870983e+000,1.959605e+000,4.682490e-001,1.703051e+000,1.573272e-002,1.573272e-002,,,,,,,,,,,,,,,,,,,,
1432792036.865,,1.000000e+004,5.005657e+000,5.002561e+000,1,0,3.308367e+000,2.418745e+000,2.418745e+000,1.434397e+000,2.185770e+000,1.391084e+000,4.067365e-001,1.158109e+000,1.216722e-002,1.216722e-002,,,,,,,,,,,,,,,,,,,,
1432792191.099,,2.000000e+004,5.000333e+000,5.005781e+000,1,0,1.310193e-001,9.538560e-001,9.538560e-001,1.769489e-001,5.117550e-001,1.324259e+000,5.473516e-001,8.821577e-001,4.795409e-003,4.795409e-003,,,,,,,,,,,,,,,,,,,,
1432792191.099,,2.000000e+004,5.000333e+000,5.005781e+000,1,0,4.452134e+000,1.973785e+000,1.973785e+000,1.409505e-001,1.531684e+000,2.027894e+000,1.950597e-001,1.585793e+000,9.922992e-003,9.922992e-003,,,,,,,,,,,,,,,,,,,,
1432792201.314,,2.000000e+004,5.005781e+000,5.003922e+000,1,0,2.189718e+000,-2.832118e-001,-2.832118e-001,-1.403726e+000,-6.087246e-001,-4.126457e-003,-1.124641e+000,-3.296393e-001,-1.423817e-003,-1.423817e-003,,,,,,,,,,,,,,,,,,,,
1432792373.508,,3.000000e+004,5.005286e+000,5.002809e+000,1,0,8.667552e-001,3.422651e-001,3.422651e-001,5.989860e-002,1.529157e-001,3.344839e-001,5.211745e-002,1.451345e-001,4.299190e-003,4.299190e-003,,,,,,,,,,,,,,,,,,,,
1432792373.508,,3.000000e+004,5.005286e+000,5.002809e+000,1,0,4.965873e+000,1.083407e-001,1.083407e-001,-6.507382e-001,-8.100869e-002,7.969996e-001,3.792061e-002,6.076502e-001,1.360867e-003,1.360867e-003,,,,,,,,,,,,,,,,,,,,
1432792383.559,,3.000000e+004,5.003304e+000,5.000951e+000,1,0,1.199545e+000,2.653584e-001,2.653584e-001,-2.224371e-001,7.917289e-002,3.024209e-001,-1.853746e-001,1.162354e-001,3.333166e-003,3.333166e-003,,,,,,,,,,,,,,,,,,,,
1432792542.239,,4.000000e+004,4.999962e+000,5.005409e+000,1,0,1.915154e+000,-1.387066e-001,-1.387066e-001,-3.411345e-001,-3.027866e-001,-4.611915e-001,-6.636193e-001,-6.252715e-001,-1.741255e-003,-1.741255e-003,,,,,,,,,,,,,,,,,,,,
1432792542.239,,4.000000e+004,4.999962e+000,5.005409e+000,1,0,4.767170e+000,3.666799e-001,3.666799e-001,-3.598352e-001,2.025999e-001,7.844450e-001,5.792999e-002,6.203650e-001,4.603119e-003,4.603119e-003,,,,,,,,,,,,,,,,,,,,
1432792552.312,,4.000000e+004,5.005286e+000,5.004170e+000,1,0,4.114130e-001,4.437391e-001,4.437391e-001,-2.689898e-002,2.416735e-001,7.491603e-001,2.785222e-001,5.470947e-001,5.570482e-003,5.570482e-003,,,,,,,,,,,,,,,,,,,,
1432792552.312,,4.000000e+004,5.005286e+000,5.004170e+000,1,0,3.027484e+000,9.920042e-001,9.920042e-001,-2.989728e-003,7.899386e-001,1.095569e+000,1.005756e-001,8.935039e-001,1.245313e-002,1.245313e-002,,,,,,,,,,,,,,,,,,,,
1432792713.500,,5.000000e+004,4.999962e+000,5.004046e+000,1,0,3.940325e+000,1.926328e+000,1.926328e+000,1.228237e+000,1.760139e+000,9.330232e-001,2.349314e-001,7.668339e-001,2.416776e-002,2.416776e-002,,,,,,,,,,,,,,,,,,,,
1432792723.524,,5.000000e+004,5.005161e+000,5.002313e+000,1,0,9.460027e-003,4.603717e-001,4.603717e-001,6.587397e-002,2.841805e-001,6.630215e-001,2.685238e-001,4.868303e-001,5.775834e-003,5.775834e-003,,,,,,,,,,,,,,,,,,,,
1432792723.524,,5.000000e+004,5.005161e+000,5.002313e+000,1,0,3.973463e+000,1.894284e+000,1.894284e+000,9.403756e-001,1.718093e+000,1.178880e+000,2.249715e-001,1.002689e+000,2.376573e-002,2.376573e-002,,,,,,,,,,,,,,,,,,,,
1432792886.862,,6.000000e+004,4.999838e+000,5.005781e+000,1,0,2.860782e+000,6.630146e-001,6.630146e-001,7.448591e-002,5.229489e-001,5.659757e-001,-2.255296e-002,4.259100e-001,8.313231e-003,8.313231e-003,,,,,,,,,,,,,,,,,,,,
1432792896.777,,6.000000e+004,5.004914e+000,5.004294e+000,1,0,3.633562e-001,4.745628e-001,4.745628e-001,1.123331e-001,2.779596e-001,6.881679e-001,3.259382e-001,4.915647e-001,5.950322e-003,5.950322e-003,,,,,,,,,,,,,,,,,,,,
1432792896.777,,6.000000e+004,5.004914e+000,5.004294e+000,1,0,4.716223e+000,5.575731e-001,5.575731e-001,-4.219918e-001,3.609699e-001,1.051334e+000,7.176913e-002,8.547308e-001,6.991150e-003,6.991150e-003,,,,,,,,,,,,,,,,,,,,
1432793055.347,,7.000000e+004,5.000333e+000,5.006278e+000,1,0,1.767922e+000,-1.853999e-001,-1.853999e-001,-7.022129e-001,-2.757932e-001,-2.358319e-001,-7.526448e-001,-3.262251e-001,-2.323255e-003,-2.323255e-003,,,,,,,,,,,,,,,,,,,,
1432793065.669,,7.000000e+004,5.005534e+000,5.004294e+000,1,0,1.264623e+000,1.895199e-001,1.895199e-001,-3.579095e-002,5.128357e-002,-8.336158e-002,-3.086725e-001,-2.215980e-001,2.374883e-003,2.374883e-003,,,,,,,,,,,,,,,,,,,,
1432793065.669,,7.000000e+004,5.005534e+000,5.004294e+000,1,0,4.985553e+000,-1.220740e-002,-1.220740e-002,-8.325275e-001,-1.504438e-001,8.685683e-001,4.824820e-002,7.303319e-001,-1.529716e-004,-1.529716e-004,,,,,,,,,,,,,,,,,,,,
1432793065.669,,7.000000e+004,5.005534e+000,5.004294e+000,1,0,2.812060e+000,5.764946e-001,5.764946e-001,-4.760242e-001,4.382583e-001,9.843601e-001,-6.815872e-002,8.461237e-001,7.224082e-003,7.224082e-003,,,,,,,,,,,,,,,,,,,,