File: data/A269/A269_cool_zero_field_150528.rso.dat
[Header]
TITLE,MPMS RSO Measurement
BYAPP,MPMS Measurement,1.1,Summary
FILEOPENTIME, 1432763032.740000 5/28/2015, 9:43:52 AM

INFO, APPNAME, MPMS MultiVu Application, Revision 1.61,  Build 082

INFO, NAME, A269
INFO, WEIGHT, 22.300
INFO, AREA, 1.000
INFO, LENGTH, 1.000
INFO, SHAPE, 1
INFO, COMMENT, m = 0.0223g
INFO, SEQUENCE FILE: cool_zero_field.seq


INFO, BACKGROUND DATA FILE:, None


STARTUPAXIS,X,4,LINEAR,AUTO,0.000000,0.000000
STARTUPAXIS,Y1,5,LINEAR,AUTO,0.000000,0.000000


STARTUPGROUP,Longitudinal
FIELDGROUP,Longitudinal,1,2,3,4,5,6,7,8,9,10,11,19,20,21,22,23,35
FIELDGROUP,Transverse,1,2,3,4,12,13,14,15,16,17,18,24,25,26,27,28,35

PLOT_APPEARANCE,ALL,HORZ_GRID_ON,VERT_GRID_ON,MARKERS_AND_LINES

[Data]
Time,Comment,Field (Oe),Temperature (K),Long Moment (emu),Long Scan Std Dev,Long Offset (cm),Long Offset Std Dev,Long Algorithm,Long Reg Fit,Long Reg Factor,Trans Moment (emu),Trans Scan Std Dev,Trans Offset (cm),Trans Offset Std Dev,Trans Algorithm,Trans Reg Fit,Trans Reg Factor,Long Moment [w/o ABS] (emu),Long Scan Std Dev [w/o ABS],Long Offset [w/o ABS] (cm),Long Offset Std Dev [w/o ABS],Long Reg Fit [w/o ABS],Trans Moment [w/o ABS] (emu),Trans Scan Std Dev [w/o ABS],Trans Offset [w/o ABS] (cm),Trans Offset Std Dev [w/o ABS],Trans Reg Fit [w/o ABS],RSO Position (deg),Amplitude (cm),Frequency,Cycles to Average,Scans per Measurement,Delta Temp (K),Error,EC Comp. Running,Using ABS,
1432763032.718,,0.000000e+000,2.999893e+002,2.728341e-007,0.000000e+000,6.228712e-001,0.000000e+000,3,5.637025e-001,1.825000e+000,,,,,,,,,,,,,,,,,,0,5.000000e+000,5.000000e-001,2,1,1.019287e-002,0,1,0,
1432763204.914,,0.000000e+000,2.943196e+002,2.804143e-007,0.000000e+000,8.023513e-001,0.000000e+000,3,4.965135e-001,1.825000e+000,,,,,,,,,,,,,,,,,,0,5.000000e+000,5.000000e-001,2,1,1.110901e+000,0,1,0,
1432763245.097,,0.000000e+000,2.889446e+002,2.583003e-007,0.000000e+000,7.058296e-001,0.000000e+000,3,5.710783e-001,1.825000e+000,,,,,,,,,,,,,,,,,,0,5.000000e+000,5.000000e-001,2,1,1.463501e+000,0,1,0,
1432763277.078,,0.000000e+000,2.836813e+002,2.914383e-007,0.000000e+000,7.745453e-001,0.000000e+000,3,4.120297e-001,1.825000e+000,,,,,,,,,,,,,,,,,,0,5.000000e+000,5.000000e-001,2,1,1.913300e+000,0,1,0,
1432763304.702,,0.000000e+000,2.783360e+002,3.081488e-007,0.000000e+000,6.308580e-001,0.000000e+000,3,6.439635e-001,1.825000e+000,,,,,,,,,,,,,,,,,,0,5.000000e+000,5.000000e-001,2,1,1.851990e+000,0,1,0,
1432763329.489,,0.000000e+000,2.734606e+002,2.892399e-007,0.000000e+000,6.782331e-001,0.000000e+000,3,5.628803e-001,1.825000e+000,,,,,,,,,,,,,,,,,,0,5.000000e+000,5.000000e-001,2,1,2.165314e+000,0,1,0,
1432763352.669,,0.000000e+000,2.685925e+002,3.100108e-007,0.000000e+000,6.254052e-001,0.000000e+000,3,6.558791e-001,1.825000e+000,,,,,,,,,,,,,,,,,,0,5.000000e+000,5.000000e-001,2,1,2.048309e+000,0,1,0,
1432763376.426,,0.000000e+000,2.635634e+002,2.801019e-007,0.000000e+000,6.839374e-001,0.000000e+000,3,6.190715e-001,1.825000e+000,,,,,,,,,,,,,,,,,,0,5.000000e+000,5.000000e-001,2,1,1.954803e+000,0,1,0,
1432763399.388,,0.000000e+000,2.586916e+002,3.284182e-007,0.000000e+000,5.526643e-001,0.000000e+000,3,5.940966e-001,1.825000e+000,,,,,,,,,,,,,,,,,,0,5.000000e+000,5.000000e-001,2,1,2.111420e+000,0,1,0,
1432763423.317,,0.000000e+000,2.536262e+002,2.621998e-007,0.000000e+000,5.996072e-001,0.000000e+000,3,5.287812e-001,1.825000e+000,,,,,,,,,,,,,,,,,,0,5.000000e+000,5.000000e-001,2,1,2.321793e+000,0,1,0,
1432763447.250,,0.000000e+000,2.485404e+002,2.478270e-007,0.000000e+000,6.584496e-001,0.000000e+000,3,4.878342e-001,1.825000e+000,,,,,,,,,,,,,,,,,,0,5.000000e+000,5.000000e-001,2,1,2.086411e+000,0,1,0,
1432763471.701,,0.000000e+000,2.433823e+002,3.045899e-007,0.000000e+000,5.355824e-001,0.000000e+000,3,5.004520e-001,1.825000e+000,,,,,,,,,,,,,,,,,,0,5.000000e+000,5.000000e-001,2,1,2.106003e+000,0,1,0,
1432763495.939,,0.000000e+000,2.384463e+002,2.605406e-007,0.000000e+000,6.424692e-001,0.000000e+000,3,4.870065e-001,1.825000e+000,,,,,,,,,,,,,,,,,,0,5.000000e+000,5.000000e-001,2,1,2.248398e+000,0,1,0,
1432763520.619,,0.000000e+000,2.335100e+002,3.094125e-007,0.000000e+000,5.895607e-001,0.000000e+000,3,5.459493e-001,1.825000e+000,,,,,,,,,,,,,,,,,,0,5.000000e+000,5.000000e-001,2,1,1.721207e+000,0,1,0,
1432763545.049,,0.000000e+000,2.290490e+002,2.455070e-007,0.000000e+000,6.778513e-001,0.000000e+000,3,6.691540e-001,1.825000e+000,,,,,,,,,,,,,,,,,,0,5.000000e+000,5.000000e-001,2,1,1.772293e+000,0,1,0,
1432763571.316,,0.000000e+000,2.238270e+002,2.805832e-007,0.000000e+000,5.747589e-001,0.000000e+000,3,4.881415e-001,1.825000e+000,,,,,,,,,,,,,,,,,,0,5.000000e+000,5.000000e-001,2,1,1.891205e+000,0,1,0,
1432763599.497,,0.000000e+000,2.186647e+002,2.920685e-007,0.000000e+000,5.908656e-001,0.000000e+000,3,5.336487e-001,1.825000e+000,,,,,,,,,,,,,,,,,,0,5.000000e+000,5.000000e-001,2,1,1.751007e+000,0,1,0,
1432763628.676,,0.000000e+000,2.136446e+002,3.110767e-007,0.000000e+000,5.553209e-001,0.000000e+000,3,5.402805e-001,1.825000e+000,,,,,,,,,,,,,,,,,,0,5.000000e+000,5.000000e-001,2,1,1.615005e+000,0,1,0,
1432763657.905,,0.000000e+000,2.087327e+002,2.463916e-007,0.000000e+000,5.280015e-001,0.000000e+000,3,5.737037e-001,1.825000e+000,,,,,,,,,,,,,,,,,,0,5.000000e+000,5.000000e-001,2,1,1.564606e+000,0,1,0,
1432763688.836,,0.000000e+000,2.038705e+002,2.952450e-007,0.000000e+000,5.744616e-001,0.000000e+000,3,6.064820e-001,1.825000e+000,,,,,,,,,,,,,,,,,,0,5.000000e+000,5.000000e-001,2,1,1.721588e+000,0,1,0,
1432763720.516,,0.000000e+000,1.988280e+002,3.019732e-007,0.000000e+000,5.198027e-001,0.000000e+000,3,5.457379e-001,1.825000e+000,,,,,,,,,,,,,,,,,,0,5.000000e+000,5.000000e-001,2,1,1.629303e+000,0,1,0,
1432763752.717,,0.000000e+000,1.939131e+002,2.995028e-007,0.000000e+000,4.865713e-001,0.000000e+000,3,5.843836e-001,1.825000e+000,,,,,,,,,,,,,,,,,,0,5.000000e+000,5.000000e-001,2,1,1.479507e+000,0,1,0,
1432763786.399,,0.000000e+000,1.888196e+002,3.012937e-007,0.000000e+000,5.392914e-001,0.000000e+000,3,6.262622e-001,1.825000e+000,,,,,,,,,,,,,,,,,,0,5.000000e+000,5.000000e-001,2,1,1.446594e+000,0,1,0,
1432763820.093,,0.000000e+000,1.839093e+002,2.825810e-007,0.000000e+000,5.618990e-001,0.000000e+000,3,6.287178e-001,1.825000e+000,,,,,,,,,,,,,,,,,,0,5.000000e+000,5.000000e-001,2,1,1.544708e+000,0,1,0,
1432763855.064,,0.000000e+000,1.789138e+002,3.092937e-007,0.000000e+000,4.395848e-001,0.000000e+000,3,4.073981e-001,1.825000e+000,,,,,,,,,,,,,,,,,,0,5.000000e+000,5.000000e-001,2,1,1.176102e+000,0,1,0,
1432763889.286,,0.000000e+000,1.741160e+002,2.595574e-007,0.000000e+000,4.979050e-001,0.000000e+000,3,4.169267e-001,1.825000e+000,,,,,,,,,,,,,,,,,,0,5.000000e+000,5.000000e-001,2,1,1.575104e+000,0,1,0,
1432763926.468,,0.000000e+000,1.689347e+002,3.300651e-007,0.000000e+000,4.777305e-001,0.000000e+000,3,6.207532e-001,1.825000e+000,,,,,,,,,,,,,,,,,,0,5.000000e+000,5.000000e-001,2,1,1.383194e+000,0,1,0,
1432763962.149,,0.000000e+000,1.640705e+002,2.519388e-007,0.000000e+000,4.929238e-001,0.000000e+000,3,4.377297e-001,1.825000e+000,,,,,,,,,,,,,,,,,,0,5.000000e+000,5.000000e-001,2,1,1.380798e+000,0,1,0,
1432763999.331,,0.000000e+000,1.591125e+002,2.510723e-007,0.000000e+000,4.619271e-001,0.000000e+000,3,4.329176e-001,1.825000e+000,,,,,,,,,,,,,,,,,,0,5.000000e+000,5.000000e-001,2,1,1.351089e+000,0,1,0,
1432764037.044,,0.000000e+000,1.542132e+002,2.490657e-007,0.000000e+000,4.617893e-001,0.000000e+000,3,4.592948e-001,1.825000e+000,,,,,,,,,,,,,,,,,,0,5.000000e+000,5.000000e-001,2,1,1.181396e+000,0,1,0,
1432764077.785,,0.000000e+000,1.490254e+002,2.858961e-007,0.000000e+000,3.803629e-001,0.000000e+000,3,6.231295e-001,1.825000e+000,,,,,,,,,,,,,,,,,,0,5.000000e+000,5.000000e-001,2,1,1.313599e+000,0,1,0,
1432764115.716,,0.000000e+000,1.439822e+002,2.731867e-007,0.000000e+000,2.732598e-001,0.000000e+000,3,5.734168e-001,1.825000e+000,,,,,,,,,,,,,,,,,,0,5.000000e+000,5.000000e-001,2,1,1.284195e+000,0,1,0,
1432764151.146,,0.000000e+000,1.391720e+002,2.874014e-007,0.000000e+000,3.621529e-001,0.000000e+000,3,6.150633e-001,1.825000e+000,,,,,,,,,,,,,,,,,,0,5.000000e+000,5.000000e-001,2,1,1.305298e+000,0,1,0,
1432764185.922,,0.000000e+000,1.339922e+002,2.527636e-007,0.000000e+000,2.237069e-001,0.000000e+000,3,5.074459e-001,1.825000e+000,,,,,,,,,,,,,,,,,,0,5.000000e+000,5.000000e-001,2,1,1.428192e+000,0,1,0,
1432764218.604,,0.000000e+000,1.289101e+002,2.896158e-007,0.000000e+000,1.553678e-001,0.000000e+000,3,5.454556e-001,1.825000e+000,,,,,,,,,,,,,,,,,,0,5.000000e+000,5.000000e-001,2,1,1.488998e+000,0,1,0,
1432764251.036,,0.000000e+000,1.237529e+002,2.498047e-007,0.000000e+000,2.214745e-001,0.000000e+000,3,6.418099e-001,1.825000e+000,,,,,,,,,,,,,,,,,,0,5.000000e+000,5.000000e-001,2,1,1.517799e+000,0,1,0,
1432764280.729,,0.000000e+000,1.189797e+002,2.941478e-007,0.000000e+000,2.781704e-001,0.000000e+000,3,7.227721e-001,1.825000e+000,,,,,,,,,,,,,,,,,,0,5.000000e+000,5.000000e-001,2,1,1.538200e+000,0,1,0,
1432764312.738,,0.000000e+000,1.137462e+002,2.824071e-007,0.000000e+000,1.441063e-001,0.000000e+000,3,6.411481e-001,1.825000e+000,,,,,,,,,,,,,,,,,,0,5.000000e+000,5.000000e-001,2,1,1.809105e+000,0,1,0,
1432764339.919,,0.000000e+000,1.086004e+002,2.402132e-007,0.000000e+000,1.340478e-001,0.000000e+000,3,5.861160e-001,1.825000e+000,,,,,,,,,,,,,,,,,,0,5.000000e+000,5.000000e-001,2,1,1.938499e+000,0,1,0,
1432764366.653,,0.000000e+000,1.036459e+002,2.862049e-007,0.000000e+000,8.249559e-002,0.000000e+000,3,7.161292e-001,1.825000e+000,,,,,,,,,,,,,,,,,,0,5.000000e+000,5.000000e-001,2,1,1.909599e+000,0,1,0,
1432765709.961,,0.000000e+000,9.998366e+001,2.636853e-007,0.000000e+000,1.781977e-001,0.000000e+000,3,7.586508e-001,1.825000e+000,,,,,,,,,,,,,,,,,,0,5.000000e+000,5.000000e-001,2,1,4.646301e-003,0,1,0,
1432765916.659,,0.000000e+000,9.999760e+001,2.864132e-007,0.000000e+000,1.553973e-001,0.000000e+000,3,6.915647e-001,1.825000e+000,,,,,,,,,,,,,,,,,,0,5.000000e+000,5.000000e-001,2,1,4.631042e-003,0,1,0,
1432766000.157,,0.000000e+000,9.884585e+001,2.505019e-007,0.000000e+000,1.192193e-001,0.000000e+000,3,7.632152e-001,1.825000e+000,,,,,,,,,,,,,,,,,,0,5.000000e+000,5.000000e-001,2,1,2.297363e-001,0,1,0,
1432766034.138,,0.000000e+000,9.767983e+001,2.637216e-007,0.000000e+000,1.465214e-001,0.000000e+000,3,7.765161e-001,1.825000e+000,,,,,,,,,,,,,,,,,,0,5.000000e+000,5.000000e-001,2,1,3.914490e-001,0,1,0,
1432766055.697,,0.000000e+000,9.666469e+001,2.878639e-007,0.000000e+000,2.054784e-001,0.000000e+000,3,7.794504e-001,1.825000e+000,,,,,,,,,,,,,,,,,,0,5.000000e+000,5.000000e-001,2,1,4.492111e-001,0,1,0,
1432766079.095,,0.000000e+000,9.541881e+001,2.610520e-007,0.000000e+000,1.457937e-001,0.000000e+000,3,7.819119e-001,1.825000e+000,,,,,,,,,,,,,,,,,,0,5.000000e+000,5.000000e-001,2,1,5.553894e-001,0,1,0,
1432766100.880,,0.000000e+000,9.417063e+001,2.662838e-007,0.000000e+000,8.611976e-002,0.000000e+000,3,7.636113e-001,1.825000e+000,,,,,,,,,,,,,,,,,,0,5.000000e+000,5.000000e-001,2,1,6.081696e-001,0,1,0,
1432766123.399,,0.000000e+000,9.277397e+001,2.523698e-007,0.000000e+000,1.426734e-001,0.000000e+000,3,7.429730e-001,1.825000e+000,,,,,,,,,,,,,,,,,,0,5.000000e+000,5.000000e-001,2,1,6.376572e-001,0,1,0,
1432766146.840,,0.000000e+000,9.122962e+001,2.984201e-007,0.000000e+000,7.025201e-002,0.000000e+000,3,7.727271e-001,1.825000e+000,,,,,,,,,,,,,,,,,,0,5.000000e+000,5.000000e-001,2,1,6.119385e-001,0,1,0,
1432766168.771,,0.000000e+000,8.971048e+001,3.133376e-007,0.000000e+000,9.735852e-002,0.000000e+000,3,7.509459e-001,1.825000e+000,,,,,,,,,,,,,,,,,,0,5.000000e+000,5.000000e-001,2,1,6.516266e-001,0,1,0,
1432766190.711,,0.000000e+000,8.815323e+001,2.831284e-007,0.000000e+000,9.957906e-002,0.000000e+000,3,7.440616e-001,1.825000e+000,,,,,,,,,,,,,,,,,,0,5.000000e+000,5.000000e-001,2,1,7.477570e-001,0,1,0,
1432766212.974,,0.000000e+000,8.648929e+001,2.732621e-007,0.000000e+000,5.134884e-002,0.000000e+000,3,7.493070e-001,1.825000e+000,,,,,,,,,,,,,,,,,,0,5.000000e+000,5.000000e-001,2,1,7.938309e-001,0,1,0,
1432766234.191,,0.000000e+000,8.485550e+001,2.478841e-007,0.000000e+000,-1.012142e-002,0.000000e+000,3,6.059449e-001,1.825000e+000,,,,,,,,,,,,,,,,,,0,5.000000e+000,5.000000e-001,2,1,8.134766e-001,0,1,0,
1432766256.907,,0.000000e+000,8.304143e+001,3.069626e-007,0.000000e+000,-4.344975e-002,0.000000e+000,3,7.273781e-001,1.825000e+000,,,,,,,,,,,,,,,,,,0,5.000000e+000,5.000000e-001,2,1,7.433090e-001,0,1,0,
1432766279.880,,0.000000e+000,8.125152e+001,3.179997e-007,0.000000e+000,-3.876101e-002,0.000000e+000,3,6.514554e-001,1.825000e+000,,,,,,,,,,,,,,,,,,0,5.000000e+000,5.000000e-001,2,1,7.542572e-001,0,1,0,
1432766301.490,,0.000000e+000,7.953972e+001,2.973297e-007,0.000000e+000,-7.208178e-002,0.000000e+000,3,5.413133e-001,1.825000e+000,,,,,,,,,,,,,,,,,,0,5.000000e+000,5.000000e-001,2,1,7.593307e-001,0,1,0,
1432766324.059,,0.000000e+000,7.771564e+001,3.355385e-007,0.000000e+000,-1.230175e-001,0.000000e+000,3,5.568371e-001,1.825000e+000,,,,,,,,,,,,,,,,,,0,5.000000e+000,5.000000e-001,2,1,8.712692e-001,0,1,0,
1432766346.425,,0.000000e+000,7.580071e+001,3.501401e-007,0.000000e+000,-1.620770e-001,0.000000e+000,3,4.796073e-001,1.825000e+000,,,,,,,,,,,,,,,,,,0,5.000000e+000,5.000000e-001,2,1,8.068085e-001,0,1,0,
1432766368.000,,0.000000e+000,7.397429e+001,4.213287e-007,0.000000e+000,-2.105766e-001,0.000000e+000,3,4.792885e-001,1.825000e+000,,,,,,,,,,,,,,,,,,0,5.000000e+000,5.000000e-001,2,1,8.629150e-001,0,1,0,
1432766389.968,,0.000000e+000,7.204237e+001,4.741933e-007,0.000000e+000,-2.831933e-001,0.000000e+000,3,3.910017e-001,1.825000e+000,,,,,,,,,,,,,,,,,,0,5.000000e+000,5.000000e-001,2,1,7.717819e-001,0,1,0,
1432766412.847,,0.000000e+000,6.997984e+001,5.756161e-007,0.000000e+000,-3.335873e-001,0.000000e+000,3,3.155096e-001,1.825000e+000,,,,,,,,,,,,,,,,,,0,5.000000e+000,5.000000e-001,2,1,8.897629e-001,0,1,0,
1432766435.674,,0.000000e+000,6.792346e+001,7.436424e-007,0.000000e+000,-3.849519e-001,0.000000e+000,3,2.251325e-001,1.825000e+000,,,,,,,,,,,,,,,,,,0,5.000000e+000,5.000000e-001,2,1,9.205704e-001,0,1,0,
1432766457.623,,0.000000e+000,6.593954e+001,9.109295e-007,0.000000e+000,-3.945479e-001,0.000000e+000,3,1.397959e-001,1.825000e+000,,,,,,,,,,,,,,,,,,0,5.000000e+000,5.000000e-001,2,1,8.848190e-001,0,1,0,
1432766480.505,,0.000000e+000,6.343450e+001,1.271595e-006,0.000000e+000,-4.539681e-001,0.000000e+000,3,5.543395e-002,1.825000e+000,,,,,,,,,,,,,,,,,,0,5.000000e+000,5.000000e-001,2,1,1.189899e+000,0,1,0,
1432766503.102,,0.000000e+000,6.088667e+001,1.767364e-006,0.000000e+000,-4.873948e-001,0.000000e+000,3,2.853601e-002,1.825000e+000,,,,,,,,,,,,,,,,,,0,5.000000e+000,5.000000e-001,2,1,8.816299e-001,0,1,0,
1432766682.126,,0.000000e+000,6.004408e+001,1.773579e-006,0.000000e+000,-4.832874e-001,0.000000e+000,3,1.613621e-002,1.825000e+000,,,,,,,,,,,,,,,,,,0,5.000000e+000,5.000000e-001,2,1,1.770020e-003,0,1,0,
1432766703.056,,0.000000e+000,6.003350e+001,1.770491e-006,0.000000e+000,-4.904833e-001,0.000000e+000,3,2.533396e-002,1.825000e+000,,,,,,,,,,,,,,,,,,0,5.000000e+000,5.000000e-001,2,1,1.586914e-002,0,1,0,
1432766723.987,,0.000000e+000,6.002998e+001,1.758090e-006,0.000000e+000,-4.875672e-001,0.000000e+000,3,2.001428e-002,1.825000e+000,,,,,,,,,,,,,,,,,,0,5.000000e+000,5.000000e-001,2,1,1.762390e-003,0,1,0,
1432766744.916,,0.000000e+000,6.001236e+001,1.786704e-006,0.000000e+000,-4.780544e-001,0.000000e+000,3,5.056413e-002,1.825000e+000,,,,,,,,,,,,,,,,,,0,5.000000e+000,5.000000e-001,2,1,1.770020e-003,0,1,0,
1432766765.595,,0.000000e+000,6.001060e+001,1.739971e-006,0.000000e+000,-4.774856e-001,0.000000e+000,3,2.188571e-002,1.825000e+000,,,,,,,,,,,,,,,,,,0,5.000000e+000,5.000000e-001,2,1,5.287170e-003,0,1,0,
1432766786.275,,0.000000e+000,6.001060e+001,1.725939e-006,0.000000e+000,-4.885330e-001,0.000000e+000,3,0.000000e+000,1.825000e+000,,,,,,,,,,,,,,,,,,0,5.000000e+000,5.000000e-001,2,1,1.232910e-002,0,1,0,
1432766807.205,,0.000000e+000,6.000444e+001,1.752735e-006,0.000000e+000,-4.832010e-001,0.000000e+000,3,2.340741e-002,1.825000e+000,,,,,,,,,,,,,,,,,,0,5.000000e+000,5.000000e-001,2,1,1.055908e-002,0,1,0,
1432766828.135,,0.000000e+000,6.000356e+001,1.768720e-006,0.000000e+000,-4.865854e-001,0.000000e+000,3,3.303620e-002,1.825000e+000,,,,,,,,,,,,,,,,,,0,5.000000e+000,5.000000e-001,2,1,5.279541e-003,0,1,0,
1432766848.815,,0.000000e+000,5.999740e+001,1.760314e-006,0.000000e+000,-4.819756e-001,0.000000e+000,3,4.052065e-002,1.825000e+000,,,,,,,,,,,,,,,,,,0,5.000000e+000,5.000000e-001,2,1,0.000000e+000,0,1,0,
1432766870.035,,0.000000e+000,6.000092e+001,1.743683e-006,0.000000e+000,-4.830981e-001,0.000000e+000,3,2.947706e-002,1.825000e+000,,,,,,,,,,,,,,,,,,0,5.000000e+000,5.000000e-001,2,1,3.528595e-003,0,1,0,
1432766890.964,,0.000000e+000,6.000444e+001,1.767735e-006,0.000000e+000,-4.802864e-001,0.000000e+000,3,4.961591e-002,1.825000e+000,,,,,,,,,,,,,,,,,,0,5.000000e+000,5.000000e-001,2,1,3.509521e-003,0,1,0,
1432766912.142,,0.000000e+000,5.999916e+001,1.754370e-006,0.000000e+000,-4.876054e-001,0.000000e+000,3,2.890349e-002,1.825000e+000,,,,,,,,,,,,,,,,,,0,5.000000e+000,5.000000e-001,2,1,1.055145e-002,0,1,0,
1432766932.822,,0.000000e+000,5.999652e+001,1.758782e-006,0.000000e+000,-4.805922e-001,0.000000e+000,3,4.369943e-002,1.825000e+000,,,,,,,,,,,,,,,,,,0,5.000000e+000,5.000000e-001,2,1,1.747131e-003,0,1,0,
1432766953.752,,0.000000e+000,6.000180e+001,1.743066e-006,0.000000e+000,-4.846972e-001,0.000000e+000,3,3.699327e-002,1.825000e+000,,,,,,,,,,,,,,,,,,0,5.000000e+000,5.000000e-001,2,1,1.770020e-003,0,1,0,
1432766974.933,,0.000000e+000,5.999916e+001,1.744937e-006,0.000000e+000,-4.800134e-001,0.000000e+000,3,4.015214e-002,1.825000e+000,,,,,,,,,,,,,,,,,,0,5.000000e+000,5.000000e-001,2,1,0.000000e+000,0,1,0,
1432766995.923,,0.000000e+000,6.000005e+001,1.767714e-006,0.000000e+000,-4.802583e-001,0.000000e+000,3,4.843941e-002,1.825000e+000,,,,,,,,,,,,,,,,,,0,5.000000e+000,5.000000e-001,2,1,8.789063e-003,0,1,0,
1432767017.365,,0.000000e+000,6.000269e+001,1.718720e-006,0.000000e+000,-4.850800e-001,0.000000e+000,3,1.298729e-002,1.825000e+000,,,,,,,,,,,,,,,,,,0,5.000000e+000,5.000000e-001,2,1,0.000000e+000,0,1,0,
1432767160.305,,0.000000e+000,5.999477e+001,1.727651e-006,0.000000e+000,-4.852441e-001,0.000000e+000,3,1.955217e-002,1.825000e+000,,,,,,,,,,,,,,,,,,0,5.000000e+000,5.000000e-001,2,1,8.789063e-003,0,1,0,
1432767231.600,,0.000000e+000,5.874355e+001,2.057626e-006,0.000000e+000,-4.942038e-001,0.000000e+000,3,1.099966e-002,1.825000e+000,,,,,,,,,,,,,,,,,,0,5.000000e+000,5.000000e-001,2,1,3.936996e-001,0,1,0,
1432767255.079,,0.000000e+000,5.778635e+001,2.320862e-006,0.000000e+000,-5.056692e-001,0.000000e+000,3,4.299566e-004,1.825000e+000,,,,,,,,,,,,,,,,,,0,5.000000e+000,5.000000e-001,2,1,3.732491e-001,0,1,0,
1432767280.757,,0.000000e+000,5.670373e+001,2.619012e-006,0.000000e+000,-5.093655e-001,0.000000e+000,3,0.000000e+000,1.825000e+000,,,,,,,,,,,,,,,,,,0,5.000000e+000,5.000000e-001,2,1,3.899117e-001,0,1,0,
1432767302.941,,0.000000e+000,5.574183e+001,2.922584e-006,0.000000e+000,-5.178324e-001,0.000000e+000,3,0.000000e+000,1.825000e+000,,,,,,,,,,,,,,,,,,0,5.000000e+000,5.000000e-001,2,1,4.093704e-001,0,1,0,
1432767326.372,,0.000000e+000,5.471965e+001,3.242856e-006,0.000000e+000,-5.254464e-001,0.000000e+000,3,0.000000e+000,1.825000e+000,,,,,,,,,,,,,,,,,,0,5.000000e+000,5.000000e-001,2,1,4.609222e-001,0,1,0,
1432767347.368,,0.000000e+000,5.368863e+001,3.551991e-006,0.000000e+000,-5.305330e-001,0.000000e+000,3,0.000000e+000,1.825000e+000,,,,,,,,,,,,,,,,,,0,5.000000e+000,5.000000e-001,2,1,4.833412e-001,0,1,0,
1432767369.582,,0.000000e+000,5.260394e+001,3.970988e-006,0.000000e+000,-5.310053e-001,0.000000e+000,3,0.000000e+000,1.825000e+000,,,,,,,,,,,,,,,,,,0,5.000000e+000,5.000000e-001,2,1,4.977989e-001,0,1,0,
1432767391.519,,0.000000e+000,5.145409e+001,4.392199e-006,0.000000e+000,-5.374203e-001,0.000000e+000,3,0.000000e+000,1.825000e+000,,,,,,,,,,,,,,,,,,0,5.000000e+000,5.000000e-001,2,1,4.577103e-001,0,1,0,
1432767413.952,,0.000000e+000,5.031816e+001,4.926408e-006,0.000000e+000,-5.415114e-001,0.000000e+000,3,0.000000e+000,1.825000e+000,,,,,,,,,,,,,,,,,,0,5.000000e+000,5.000000e-001,2,1,5.418320e-001,0,1,0,
1432767435.132,,0.000000e+000,4.919453e+001,5.522647e-006,0.000000e+000,-5.451638e-001,0.000000e+000,3,0.000000e+000,1.825000e+000,,,,,,,,,,,,,,,,,,0,5.000000e+000,5.000000e-001,2,1,5.071182e-001,0,1,0,
1432767457.871,,0.000000e+000,4.796685e+001,6.376060e-006,0.000000e+000,-5.491141e-001,0.000000e+000,3,0.000000e+000,1.825000e+000,,,,,,,,,,,,,,,,,,0,5.000000e+000,5.000000e-001,2,1,5.683899e-001,0,1,0,
1432767479.674,,0.000000e+000,4.673527e+001,7.456300e-006,0.000000e+000,-5.525981e-001,0.000000e+000,3,0.000000e+000,1.825000e+000,,,,,,,,,,,,,,,,,,0,5.000000e+000,5.000000e-001,2,1,5.243607e-001,0,1,0,
1432767502.127,,0.000000e+000,4.549255e+001,9.015531e-006,0.000000e+000,-5.562125e-001,0.000000e+000,3,0.000000e+000,1.825000e+000,,,,,,,,,,,,,,,,,,0,5.000000e+000,5.000000e-001,2,1,5.425911e-001,0,1,0,
1432767523.608,,0.000000e+000,4.424105e+001,1.114457e-005,0.000000e+000,-5.592598e-001,0.000000e+000,3,0.000000e+000,1.825000e+000,,,,,,,,,,,,,,,,,,0,5.000000e+000,5.000000e-001,2,1,5.399704e-001,0,1,0,
1432767546.538,,0.000000e+000,4.290841e+001,1.414331e-005,0.000000e+000,-5.635381e-001,0.000000e+000,3,0.000000e+000,1.825000e+000,,,,,,,,,,,,,,,,,,0,5.000000e+000,5.000000e-001,2,1,5.318794e-001,0,1,0,
1432767567.733,,0.000000e+000,4.172057e+001,1.746293e-005,0.000000e+000,-5.674407e-001,0.000000e+000,3,0.000000e+000,1.825000e+000,,,,,,,,,,,,,,,,,,0,5.000000e+000,5.000000e-001,2,1,6.196594e-001,0,1,0,
1432767590.915,,0.000000e+000,4.035490e+001,2.100778e-005,0.000000e+000,-5.691519e-001,0.000000e+000,3,0.000000e+000,1.825000e+000,,,,,,,,,,,,,,,,,,0,5.000000e+000,5.000000e-001,2,1,5.663986e-001,0,1,0,
1432767623.424,,0.000000e+000,3.847580e+001,2.527814e-005,0.000000e+000,-5.720426e-001,0.000000e+000,3,0.000000e+000,1.825000e+000,,,,,,,,,,,,,,,,,,0,5.000000e+000,5.000000e-001,2,1,5.958176e-001,0,1,0,
1432767645.355,,0.000000e+000,3.713042e+001,2.786162e-005,0.000000e+000,-5.728319e-001,0.000000e+000,3,0.000000e+000,1.825000e+000,,,,,,,,,,,,,,,,,,0,5.000000e+000,5.000000e-001,2,1,5.238686e-001,0,1,0,
1432767667.554,,0.000000e+000,3.584113e+001,3.030540e-005,0.000000e+000,-5.733644e-001,0.000000e+000,3,0.000000e+000,1.825000e+000,,,,,,,,,,,,,,,,,,0,5.000000e+000,5.000000e-001,2,1,5.987206e-001,0,1,0,
1432767688.985,,0.000000e+000,3.453529e+001,3.255731e-005,0.000000e+000,-5.749521e-001,0.000000e+000,3,0.000000e+000,1.825000e+000,,,,,,,,,,,,,,,,,,0,5.000000e+000,5.000000e-001,2,1,5.283585e-001,0,1,0,
1432767711.462,,0.000000e+000,3.321549e+001,3.469813e-005,0.000000e+000,-5.755191e-001,0.000000e+000,3,0.000000e+000,1.825000e+000,,,,,,,,,,,,,,,,,,0,5.000000e+000,5.000000e-001,2,1,5.715370e-001,0,1,0,
1432767732.648,,0.000000e+000,3.198145e+001,3.663463e-005,0.000000e+000,-5.758326e-001,0.000000e+000,3,0.000000e+000,1.825000e+000,,,,,,,,,,,,,,,,,,0,5.000000e+000,5.000000e-001,2,1,5.037384e-001,0,1,0,
1432767755.127,,0.000000e+000,3.078443e+001,3.853071e-005,0.000000e+000,-5.770526e-001,0.000000e+000,3,0.000000e+000,1.825000e+000,,,,,,,,,,,,,,,,,,0,5.000000e+000,5.000000e-001,2,1,5.594997e-001,0,1,0,
1432767776.637,,0.000000e+000,2.952417e+001,4.025456e-005,0.000000e+000,-5.775918e-001,0.000000e+000,3,0.000000e+000,1.825000e+000,,,,,,,,,,,,,,,,,,0,5.000000e+000,5.000000e-001,2,1,4.790001e-001,0,1,0,
1432767800.089,,0.000000e+000,2.838582e+001,4.192769e-005,0.000000e+000,-5.784135e-001,0.000000e+000,3,0.000000e+000,1.825000e+000,,,,,,,,,,,,,,,,,,0,5.000000e+000,5.000000e-001,2,1,4.759197e-001,0,1,0,
1432767830.375,,0.000000e+000,2.677300e+001,4.410136e-005,0.000000e+000,-5.793746e-001,0.000000e+000,3,0.000000e+000,1.825000e+000,,,,,,,,,,,,,,,,,,0,5.000000e+000,5.000000e-001,2,1,4.409103e-001,0,1,0,
1432767852.806,,0.000000e+000,2.557549e+001,4.566036e-005,0.000000e+000,-5.794790e-001,0.000000e+000,3,0.000000e+000,1.825000e+000,,,,,,,,,,,,,,,,,,0,5.000000e+000,5.000000e-001,2,1,4.672985e-001,0,1,0,
1432767875.416,,0.000000e+000,2.426941e+001,4.736277e-005,0.000000e+000,-5.803505e-001,0.000000e+000,3,0.000000e+000,1.825000e+000,,,,,,,,,,,,,,,,,,0,5.000000e+000,5.000000e-001,2,1,7.383900e-001,0,1,0,
1432767897.901,,0.000000e+000,2.281135e+001,4.922201e-005,0.000000e+000,-5.800620e-001,0.000000e+000,3,0.000000e+000,1.825000e+000,,,,,,,,,,,,,,,,,,0,5.000000e+000,5.000000e-001,2,1,2.980614e-001,0,1,0,
1432767918.939,,0.000000e+000,2.262119e+001,4.931989e-005,0.000000e+000,-5.800659e-001,0.000000e+000,3,0.000000e+000,1.825000e+000,,,,,,,,,,,,,,,,,,0,5.000000e+000,5.000000e-001,2,1,6.853104e-002,0,1,0,
1432767941.666,,0.000000e+000,2.079593e+001,5.164774e-005,0.000000e+000,-5.808422e-001,0.000000e+000,3,0.000000e+000,1.825000e+000,,,,,,,,,,,,,,,,,,0,5.000000e+000,5.000000e-001,2,1,7.755184e-001,0,1,0,
1432767963.101,,0.000000e+000,1.973127e+001,5.278701e-005,0.000000e+000,-5.807582e-001,0.000000e+000,3,0.000000e+000,1.825000e+000,,,,,,,,,,,,,,,,,,0,5.000000e+000,5.000000e-001,2,1,7.255936e-002,0,1,0,
1432767985.032,,0.000000e+000,1.930523e+001,5.303451e-005,0.000000e+000,-5.811872e-001,0.000000e+000,3,0.000000e+000,1.825000e+000,,,,,,,,,,,,,,,,,,0,5.000000e+000,5.000000e-001,2,1,7.721996e-001,0,1,0,
1432768008.734,,0.000000e+000,1.731234e+001,5.555309e-005,0.000000e+000,-5.816976e-001,0.000000e+000,3,0.000000e+000,1.825000e+000,,,,,,,,,,,,,,,,,,0,5.000000e+000,5.000000e-001,2,1,6.605091e-001,0,1,0,
1432768030.964,,0.000000e+000,1.649410e+001,5.629826e-005,0.000000e+000,-5.812023e-001,0.000000e+000,3,0.000000e+000,1.825000e+000,,,,,,,,,,,,,,,,,,0,5.000000e+000,5.000000e-001,2,1,2.400970e-002,0,1,0,
1432768052.474,,0.000000e+000,1.590571e+001,5.689794e-005,0.000000e+000,-5.813451e-001,0.000000e+000,3,0.000000e+000,1.825000e+000,,,,,,,,,,,,,,,,,,0,5.000000e+000,5.000000e-001,2,1,1.101979e+000,0,1,0,
1432768075.195,,0.000000e+000,1.376669e+001,5.909026e-005,0.000000e+000,-5.814438e-001,0.000000e+000,3,0.000000e+000,1.825000e+000,,,,,,,,,,,,,,,,,,0,5.000000e+000,5.000000e-001,2,1,4.372797e-001,0,1,0,
1432768096.126,,0.000000e+000,1.331031e+001,5.955665e-005,0.000000e+000,-5.815336e-001,0.000000e+000,3,0.000000e+000,1.825000e+000,,,,,,,,,,,,,,,,,,0,5.000000e+000,5.000000e-001,2,1,1.119394e-001,0,1,0,
1432768117.868,,0.000000e+000,1.424246e+001,5.845267e-005,0.000000e+000,-5.816607e-001,0.000000e+000,3,0.000000e+000,1.825000e+000,,,,,,,,,,,,,,,,,,0,5.000000e+000,5.000000e-001,2,1,5.224600e-001,0,1,0,
1432768143.331,,0.000000e+000,1.534566e+001,5.740451e-005,0.000000e+000,-5.814193e-001,0.000000e+000,3,0.000000e+000,1.825000e+000,,,,,,,,,,,,,,,,,,0,5.000000e+000,5.000000e-001,2,1,5.209064e-002,0,1,0,
1432768164.788,,0.000000e+000,1.503433e+001,5.783989e-005,0.000000e+000,-5.810974e-001,0.000000e+000,3,0.000000e+000,1.825000e+000,,,,,,,,,,,,,,,,,,0,5.000000e+000,5.000000e-001,2,1,2.186403e-001,0,1,0,
1432768242.006,,0.000000e+000,1.499911e+001,5.783867e-005,0.000000e+000,-5.810426e-001,0.000000e+000,3,0.000000e+000,1.825000e+000,,,,,,,,,,,,,,,,,,0,5.000000e+000,5.000000e-001,2,1,2.439499e-003,0,1,0,
1432768263.688,,0.000000e+000,1.500095e+001,5.780557e-005,0.000000e+000,-5.814470e-001,0.000000e+000,3,0.000000e+000,1.825000e+000,,,,,,,,,,,,,,,,,,0,5.000000e+000,5.000000e-001,2,1,6.103516e-004,0,1,0,
1432768285.370,,0.000000e+000,1.500018e+001,5.783093e-005,0.000000e+000,-5.809610e-001,0.000000e+000,3,0.000000e+000,1.825000e+000,,,,,,,,,,,,,,,,,,0,5.000000e+000,5.000000e-001,2,1,3.004074e-004,0,1,0,
1432768364.147,,0.000000e+000,1.500171e+001,5.787439e-005,0.000000e+000,-5.807155e-001,0.000000e+000,3,0.000000e+000,1.825000e+000,,,,,,,,,,,,,,,,,,0,5.000000e+000,5.000000e-001,2,1,2.750397e-003,0,1,0,
1432768486.838,,0.000000e+000,1.291484e+001,5.987814e-005,0.000000e+000,-5.807058e-001,0.000000e+000,3,0.000000e+000,1.825000e+000,,,,,,,,,,,,,,,,,,0,5.000000e+000,5.000000e-001,2,1,1.527996e-001,0,1,0,
1432768612.036,,0.000000e+000,1.091193e+001,6.173144e-005,0.000000e+000,-5.810112e-001,0.000000e+000,3,0.000000e+000,1.825000e+000,,,,,,,,,,,,,,,,,,0,5.000000e+000,5.000000e-001,2,1,1.241398e-001,0,0,0,
1432768739.255,,0.000000e+000,8.904657e+000,6.340776e-005,0.000000e+000,-5.808783e-001,0.000000e+000,3,0.000000e+000,1.825000e+000,,,,,,,,,,,,,,,,,,0,5.000000e+000,5.000000e-001,2,1,1.044235e-001,0,0,0,
1432768858.249,,0.000000e+000,6.932283e+000,6.493359e-005,0.000000e+000,-5.809780e-001,0.000000e+000,3,0.000000e+000,1.825000e+000,,,,,,,,,,,,,,,,,,0,5.000000e+000,5.000000e-001,2,1,1.245317e-001,0,1,0,
1432769133.842,,0.000000e+000,5.002624e+000,6.620801e-005,0.000000e+000,-5.809505e-001,0.000000e+000,3,0.000000e+000,1.825000e+000,,,,,,,,,,,,,,,,,,0,5.000000e+000,5.000000e-001,2,1,4.333019e-003,0,1,0,
1432769144.057,,0.000000e+000,5.004356e+000,6.621373e-005,0.000000e+000,-5.807113e-001,0.000000e+000,3,0.000000e+000,1.825000e+000,,,,,,,,,,,,,,,,,,0,5.000000e+000,5.000000e-001,2,1,8.678436e-004,0,1,0,