File: data/A269/A269_GdN_MH_55K_150528.rso.raw
[Header]
TITLE,MPMS RSO Measurement
BYAPP,MPMS Measurement,2.1,Raw with ABS
FILEOPENTIME, 1432833006.494000 5/29/2015, 5:10:06 AM

INFO, APPNAME, MPMS MultiVu Application, Revision 1.61,  Build 082

INFO, NAME, A269
INFO, WEIGHT, 22.300
INFO, AREA, 1.000
INFO, LENGTH, 1.000
INFO, SHAPE, 1
INFO, COMMENT, m = 0.0223g
INFO, SEQUENCE FILE: 7T_hysteresis_sweep.seq


INFO, BACKGROUND DATA FILE:, None


STARTUPAXIS,X,8,LINEAR,AUTO,0.000000,0.000000
STARTUPAXIS,Y1,9,LINEAR,AUTO,0.000000,0.000000


STARTUPGROUP,Longitudinal
FIELDGROUP,Longitudinal,1,2,3,4,5,6,7,8,9,10,11,12,13,14,15,16,17,18,19,20,21,22
FIELDGROUP,Transverse,1,2,3,4,5,6,7,8,23,24,25,26,27,28,29,30,31,32,33,34,35,36

PLOT_APPEARANCE,ALL,HORZ_GRID_ON,VERT_GRID_ON,MARKERS_ONLY

[Data]
Time,Comment,Field (Oe),Start Temperature (K),End Temperature (K),Scan,Rejected,Position (cm),Long Voltage,Long Average Voltage,Long Detrended Voltage,Long Demeaned Voltage,Long Reg Fit,Long Detrended Fit,Long Demeaned Fit,Long Scaled Response,Long Avg. Scaled Response,Long Background Response,Long Response [w/ABS],Long Detrended Resp. [w/ABS],Long Fit [w/ABS],Long Detrended Fit [w/ABS],Trans Voltage,Trans Average Voltage,Trans Detrended Voltage,Trans Demeaned Voltage,Trans Reg Fit,Trans Detrended Fit,Trans Demeaned Fit,Trans Scaled Response,Trans Avg. Scaled Response,Trans Background Response,Trans Response [w/ABS],Trans Detrended Resp. [w/ABS],Trans Adjusted Fit,Trans Detrended Fit [w/ABS],
1432833006.483,,7.000000e+004,5.506775e+001,5.505283e+001,1,0,2.591314e+000,2.566607e-001,2.566607e-001,-8.507967e-003,-8.507967e-003,-1.754574e-002,-2.827144e-001,-2.827144e-001,1.286491e-003,1.286491e-003,,,,,,,,,,,,,,,,,,,,
1432833006.483,,7.000000e+004,5.506775e+001,5.505283e+001,1,0,4.317335e+000,1.370128e+000,1.370129e+000,5.455550e-001,1.104960e+000,9.644651e-001,1.398916e-001,6.992965e-001,6.867658e-003,6.867658e-003,,,,,,,,,,,,,,,,,,,,
1432833016.739,,7.000000e+004,5.505283e+001,5.504239e+001,1,0,9.149914e-002,4.298532e-001,4.298532e-001,4.284800e-002,2.867591e-001,6.749321e-001,2.879269e-001,5.318381e-001,2.154604e-003,2.154604e-003,,,,,,,,,,,,,,,,,,,,
1432833016.739,,7.000000e+004,5.505283e+001,5.504239e+001,1,0,3.620901e+000,2.006439e+000,2.006439e+000,1.063859e+000,1.863345e+000,1.257447e+000,3.148659e-001,1.114352e+000,1.005711e-002,1.005711e-002,,,,,,,,,,,,,,,,,,,,
1432833174.218,,6.000000e+004,5.499770e+001,5.499622e+001,1,0,3.307982e+000,1.370891e+000,1.370891e+000,8.410569e-001,1.245319e+000,7.708603e-001,2.410258e-001,6.452875e-001,6.875588e-003,6.875588e-003,,,,,,,,,,,,,,,,,,,,
1432833184.135,,6.000000e+004,5.499622e+001,5.499472e+001,1,0,1.304577e-001,2.742088e-001,2.742088e-001,9.534977e-002,2.431199e-001,4.501002e-001,2.712412e-001,4.190114e-001,1.375271e-003,1.375271e-003,,,,,,,,,,,,,,,,,,,,
1432833184.135,,6.000000e+004,5.499622e+001,5.499472e+001,1,0,4.449542e+000,7.321391e-001,7.321391e-001,8.723569e-002,7.010502e-001,7.466005e-001,1.016971e-001,7.155116e-001,3.671980e-003,3.671980e-003,,,,,,,,,,,,,,,,,,,,
1432833339.251,,5.000000e+004,5.500068e+001,5.499472e+001,1,0,2.189544e+000,-2.945036e-001,-2.945036e-001,-6.311551e-001,-3.129905e-001,-1.785403e-001,-5.151918e-001,-1.970272e-001,-1.477940e-003,-1.477940e-003,,,,,,,,,,,,,,,,,,,,
1432833349.215,,5.000000e+004,5.499472e+001,5.499472e+001,1,0,8.670201e-001,2.700888e-001,2.700888e-001,6.036111e-002,1.412783e-001,2.719798e-001,6.225207e-002,1.431693e-001,1.355416e-003,1.355416e-003,,,,,,,,,,,,,,,,,,,,
1432833349.215,,5.000000e+004,5.499472e+001,5.499472e+001,1,0,4.967230e+000,-3.509629e-003,-3.509629e-003,-6.279380e-001,-1.323201e-001,6.627287e-001,3.830029e-002,5.339181e-001,-1.761275e-005,-1.761275e-005,,,,,,,,,,,,,,,,,,,,
1432833508.445,,4.000000e+004,5.500217e+001,5.499770e+001,1,0,1.200367e+000,1.023896e-001,1.023896e-001,-1.871552e-001,2.673664e-002,1.410092e-001,-1.485356e-001,6.535627e-002,5.141395e-004,5.141395e-004,,,,,,,,,,,,,,,,,,,,
1432833518.883,,4.000000e+004,5.499770e+001,5.499920e+001,1,0,1.915310e+000,-2.607807e-001,-2.607807e-001,-2.602876e-001,-2.355284e-001,-5.133584e-001,-5.128652e-001,-4.881061e-001,-1.309485e-003,-1.309485e-003,,,,,,,,,,,,,,,,,,,,
1432833518.883,,4.000000e+004,5.499770e+001,5.499920e+001,1,0,4.767127e+000,6.927702e-002,6.927702e-002,-2.686055e-001,9.452932e-002,3.838818e-001,4.599929e-002,4.091341e-001,3.478678e-004,3.478678e-004,,,,,,,,,,,,,,,,,,,,
1432833675.921,,3.000000e+004,5.499770e+001,5.500068e+001,1,0,4.126049e-001,1.641896e-001,1.641896e-001,-1.767438e-002,1.202776e-001,3.620784e-001,1.802144e-001,3.181664e-001,8.249539e-004,8.249539e-004,,,,,,,,,,,,,,,,,,,,
1432833675.921,,3.000000e+004,5.499770e+001,5.500068e+001,1,0,3.026804e+000,4.358043e-001,4.358043e-001,-1.539441e-002,3.918923e-001,5.092069e-001,5.800817e-002,4.652949e-001,2.189655e-003,2.189655e-003,,,,,,,,,,,,,,,,,,,,
1432833685.992,,3.000000e+004,5.500068e+001,5.499920e+001,1,0,3.940264e+000,9.137241e-001,9.137242e-001,7.325366e-001,9.881834e-001,3.234347e-001,1.422470e-001,3.978939e-001,4.590915e-003,4.590915e-003,,,,,,,,,,,,,,,,,,,,
1432833847.504,,2.000000e+004,5.499920e+001,5.500068e+001,1,0,9.581760e-003,3.753776e-002,3.753777e-002,3.078289e-002,1.003492e-001,1.262195e-001,1.194647e-001,1.890310e-001,1.887171e-004,1.887171e-004,,,,,,,,,,,,,,,,,,,,
1432833847.504,,2.000000e+004,5.499920e+001,5.500068e+001,1,0,3.974894e+000,6.141850e-001,6.141850e-001,4.291664e-001,6.769964e-001,2.881736e-001,1.031550e-001,3.509851e-001,3.087750e-003,3.087750e-003,,,,,,,,,,,,,,,,,,,,
1432833857.718,,2.000000e+004,5.501110e+001,5.499920e+001,1,0,2.861445e+000,9.369183e-002,9.369183e-002,2.407118e-002,1.770692e-001,5.492799e-002,-1.469266e-002,1.383053e-001,4.710256e-004,4.710256e-004,,,,,,,,,,,,,,,,,,,,
1432834019.972,,1.000000e+004,5.499622e+001,5.500217e+001,1,0,3.629518e-001,-4.429762e-001,-4.429762e-001,1.144835e-001,2.003019e-001,-2.164919e-001,3.409678e-001,4.267862e-001,-5.570855e-004,-5.570855e-004,,,,,,,,,,,,,,,,,,,,
1432834019.972,,1.000000e+004,5.499622e+001,5.500217e+001,1,0,4.714735e+000,-6.764427e-001,-6.764427e-001,-4.388514e-001,-3.316468e-002,-1.612444e-001,7.634687e-002,4.820336e-001,-8.506924e-004,-8.506924e-004,,,,,,,,,,,,,,,,,,,,
1432834029.889,,1.000000e+004,5.500217e+001,5.499920e+001,1,0,1.768110e+000,-1.003296e+000,-1.003296e+000,-6.992582e-001,-4.600986e-001,-1.050125e+000,-7.460867e-001,-5.069271e-001,-1.261742e-003,-1.261742e-003,,,,,,,,,,,,,,,,,,,,
1432834140.407,,9.000000e+003,5.500068e+001,5.499770e+001,1,0,1.264581e+000,-4.745628e-001,-4.745628e-001,-2.055322e-002,2.635783e-002,-7.294408e-001,-2.754312e-001,-2.285202e-001,-5.968443e-004,-5.968443e-004,,,,,,,,,,,,,,,,,,,,
1432834140.407,,9.000000e+003,5.500068e+001,5.499770e+001,1,0,4.984670e+000,-9.135715e-001,-9.135716e-001,-7.801208e-001,-4.126509e-001,-8.791837e-002,4.553236e-002,4.130023e-001,-1.148973e-003,-1.148973e-003,,,,,,,,,,,,,,,,,,,,
1432834150.680,,9.000000e+003,5.500068e+001,5.499770e+001,1,0,8.609701e-001,-3.495895e-001,-3.495895e-001,-1.367947e-001,5.712426e-002,-1.342850e-001,7.850977e-002,2.724288e-001,-4.396689e-004,-4.396689e-004,,,,,,,,,,,,,,,,,,,,
1432834270.764,,7.000000e+003,5.500068e+001,5.499472e+001,1,0,2.366054e+000,-4.948576e-001,-4.948576e-001,-2.308810e-001,-2.248089e-001,-6.696606e-001,-4.056840e-001,-3.996119e-001,-6.224426e-004,-6.224426e-004,,,,,,,,,,,,,,,,,,,,
1432834270.764,,7.000000e+003,5.500068e+001,5.499472e+001,1,0,4.487288e+000,1.315348e-001,1.315348e-001,1.465568e-001,4.015835e-001,7.145493e-002,8.647692e-002,3.415037e-001,1.654473e-004,1.654473e-004,,,,,,,,,,,,,,,,,,,,
1432834280.750,,7.000000e+003,5.499472e+001,5.499770e+001,1,0,1.760366e-001,1.101718e-001,1.101718e-001,9.563893e-003,1.280679e-001,3.577864e-001,2.571785e-001,3.756824e-001,1.385765e-004,1.385765e-004,,,,,,,,,,,,,,,,,,,,
1432834280.750,,7.000000e+003,5.499472e+001,5.499770e+001,1,0,3.431872e+000,1.066927e+000,1.066927e+000,7.106000e-001,1.084823e+000,6.116095e-001,2.552825e-001,6.295056e-001,1.342004e-003,1.342004e-003,,,,,,,,,,,,,,,,,,,,
1432834394.475,,5.000000e+003,5.499920e+001,5.499920e+001,1,0,3.525310e+000,5.661184e-001,5.661184e-001,8.597260e-001,9.923073e-001,-8.727191e-002,2.063356e-001,3.389171e-001,7.121607e-004,7.121607e-004,,,,,,,,,,,,,,,,,,,,
1432834404.391,,5.000000e+003,5.499920e+001,5.500068e+001,1,0,5.712985e-002,-2.855006e-001,-2.855006e-001,5.376813e-002,1.145848e-001,-1.552469e-001,1.840219e-001,2.448386e-001,-3.591517e-004,-3.591517e-004,,,,,,,,,,,,,,,,,,,,
1432834404.391,,5.000000e+003,5.499920e+001,5.500068e+001,1,0,4.301160e+000,8.255257e-002,8.255257e-002,2.437153e-001,4.826381e-001,-6.952290e-002,9.163981e-002,3.305626e-001,1.038488e-004,1.038488e-004,,,,,,,,,,,,,,,,,,,,
1432834523.959,,3.000000e+003,5.500068e+001,5.564351e+001,1,0,2.409876e+000,-1.501511e+000,-1.501511e+000,-4.216163e-001,-6.286141e-001,-1.067267e+000,1.262772e-002,-1.943700e-001,-1.889082e-003,-1.889082e-003,,,,,,,,,,,,,,,,,,,,
1432834533.984,,3.000000e+003,5.498729e+001,5.499175e+001,1,0,6.836955e-001,-4.867702e-001,-4.867702e-001,4.088082e-002,5.215031e-002,-4.388992e-001,8.875178e-002,1.000213e-001,-6.124158e-004,-6.124158e-004,,,,,,,,,,,,,,,,,,,,
1432834533.984,,3.000000e+003,5.498729e+001,5.499175e+001,1,0,4.910019e+000,-8.124027e-001,-8.124027e-001,-3.360905e-001,-2.734822e-001,-4.534675e-001,2.284471e-002,8.545300e-002,-1.022101e-003,-1.022101e-003,,,,,,,,,,,,,,,,,,,,
1432834652.268,,1.000000e+003,5.499920e+001,5.499324e+001,1,0,1.379958e+000,-7.187109e-001,-7.187109e-001,-7.025983e-002,-1.430560e-001,-7.230259e-001,-7.457479e-002,-1.473709e-001,-9.043330e-004,-9.043330e-004,,,,,,,,,,,,,,,,,,,,
1432834671.804,,1.000000e+003,5.500366e+001,5.499770e+001,1,0,1.692741e+000,-9.624012e-001,-9.624012e-001,-1.049389e-001,-1.263953e-001,-1.124428e+000,-2.669661e-001,-2.884225e-001,-4.843846e-004,-4.843846e-004,,,,,,,,,,,,,,,,,,,,
1432834671.804,,1.000000e+003,5.500366e+001,5.499770e+001,1,0,4.870692e+000,-1.389203e+000,-1.389203e+000,-3.118125e-001,-5.531967e-001,-1.044188e+000,3.320199e-002,-2.081822e-001,-6.991973e-004,-6.991973e-004,,,,,,,,,,,,,,,,,,,,
1432834782.534,,5.000000e+002,5.499770e+001,5.499175e+001,1,0,5.509766e-001,1.030000e-001,1.030000e-001,-4.126914e-002,-6.623237e-002,1.071430e-001,-3.712611e-002,-6.208933e-002,5.184229e-005,5.184229e-005,,,,,,,,,,,,,,,,,,,,
1432834782.534,,5.000000e+002,5.499770e+001,5.499175e+001,1,0,2.812132e+000,-8.911405e-002,-8.911405e-002,-1.868608e-001,-2.583464e-001,1.317540e-001,3.400729e-002,-3.747831e-002,-4.485318e-005,-4.485318e-005,,,,,,,,,,,,,,,,,,,,
1432834792.999,,5.000000e+002,5.499175e+001,5.499622e+001,1,0,4.134120e+000,-8.148442e-001,-8.148442e-001,2.800801e-001,1.583229e-001,-1.089354e+000,5.570758e-003,-1.161865e-001,-4.101301e-004,-4.101301e-004,,,,,,,,,,,,,,,,,,,,
1432834897.222,,4.000000e+002,5.499770e+001,5.499622e+001,1,0,3.438659e-002,5.676443e-001,5.676443e-001,-1.926447e-003,1.829885e-001,5.791845e-001,9.613787e-003,1.945288e-001,2.857103e-004,2.857103e-004,,,,,,,,,,,,,,,,,,,,
1432834897.222,,4.000000e+002,5.499770e+001,5.499622e+001,1,0,3.802068e+000,1.292611e+000,1.292611e+000,2.770693e-001,9.079557e-001,1.023110e+000,7.567884e-003,6.384543e-001,6.506054e-004,6.506054e-004,,,,,,,,,,,,,,,,,,,,
1432834907.436,,4.000000e+002,5.499622e+001,5.499622e+001,1,0,3.086018e+000,1.590930e+000,1.590930e+000,1.272367e-001,3.581890e-001,1.485838e+000,2.214503e-002,2.530973e-001,8.007569e-004,8.007569e-004,,,,,,,,,,,,,,,,,,,,
1432835020.435,,3.000000e+002,5.499324e+001,5.499324e+001,1,0,2.341691e-001,-2.377697e+000,-2.377697e+000,6.809044e-002,-1.664138e-002,-2.459921e+000,-1.413369e-002,-9.886551e-002,-2.991911e-004,-2.991911e-004,,,,,,,,,,,,,,,,,,,,
1432835020.435,,3.000000e+002,5.499324e+001,5.499324e+001,1,0,4.592274e+000,-2.974639e+000,-2.974639e+000,-2.393514e-001,-6.135836e-001,-2.728698e+000,6.589305e-003,-3.676429e-001,-3.743057e-004,-3.743057e-004,,,,,,,,,,,,,,,,,,,,
1432835030.899,,3.000000e+002,5.500366e+001,5.499770e+001,1,0,1.974504e+000,-3.211463e+000,-3.211463e+000,-6.285727e-001,-9.276335e-001,-2.607601e+000,-2.471112e-002,-3.237720e-001,-4.041058e-004,-4.041058e-004,,,,,,,,,,,,,,,,,,,,
1432835149.473,,2.000000e+002,5.499472e+001,5.500068e+001,1,0,1.060671e+000,-8.415479e-001,-8.415479e-001,3.099221e-002,4.661441e-003,-9.342012e-001,-6.166113e-002,-8.799189e-002,-2.117891e-004,-2.117891e-004,,,,,,,,,,,,,,,,,,,,
1432835149.473,,2.000000e+002,5.499472e+001,5.500068e+001,1,0,4.993206e+000,-1.319010e+000,-1.319010e+000,-2.922468e-001,-4.728007e-001,-1.025548e+000,1.214944e-003,-1.793389e-001,-3.319502e-004,-3.319502e-004,,,,,,,,,,,,,,,,,,,,
1432835160.188,,2.000000e+002,5.500068e+001,5.500068e+001,1,0,1.027323e+000,-8.815271e-001,-8.815271e-001,-6.980135e-002,-1.170837e-001,-8.725737e-001,-6.084790e-002,-1.081303e-001,-2.218505e-004,-2.218505e-004,,,,,,,,,,,,,,,,,,,,
1432835258.666,,1.000000e+002,5.500068e+001,5.499920e+001,1,0,2.140492e+000,-1.503342e+000,-1.503342e+000,-4.528962e-002,-6.155622e-002,-1.455867e+000,2.185363e-003,-1.408124e-002,-3.783425e-004,-3.783425e-004,,,,,,,,,,,,,,,,,,,,
1432835258.666,,1.000000e+002,5.500068e+001,5.499920e+001,1,0,4.638484e+000,-1.825770e+000,-1.825770e+000,-3.425224e-002,-3.839842e-001,-1.791010e+000,5.078744e-004,-3.492241e-001,-4.594872e-004,-4.594872e-004,,,,,,,,,,,,,,,,,,,,
1432835269.141,,1.000000e+002,5.499770e+001,5.500217e+001,1,0,2.839831e-001,-1.368450e+000,-1.368450e+000,-5.301893e-003,-1.620433e-001,-1.367971e+000,-4.822552e-003,-1.615640e-001,-3.443946e-004,-3.443946e-004,,,,,,,,,,,,,,,,,,,,
1432835269.141,,1.000000e+002,5.499770e+001,5.500217e+001,1,0,3.233517e+000,-1.632130e+000,-1.632130e+000,5.233808e-002,-4.257233e-001,-1.676008e+000,8.460477e-003,-4.696009e-001,-4.107543e-004,-4.107543e-004,,,,,,,,,,,,,,,,,,,,
1432835367.618,,0.000000e+000,5.499920e+001,5.499920e+001,1,0,3.736795e+000,-1.713157e+000,-1.713157e+000,-3.465591e-002,-5.136420e-001,-1.692349e+000,-1.384840e-002,-4.928344e-001,-4.311486e-004,-4.311486e-004,,,,,,,,,,,,,,,,,,,,
1432835378.084,,0.000000e+000,5.500068e+001,5.499920e+001,1,0,1.621969e-002,-8.088931e-001,-8.088931e-001,-9.919029e-003,-1.028386e-001,-8.114590e-001,-1.248495e-002,-1.054046e-001,-2.035734e-004,-2.035734e-004,,,,,,,,,,,,,,,,,,,,
1432835378.084,,0.000000e+000,5.500068e+001,5.499920e+001,1,0,4.141147e+000,-1.068148e+000,-1.068148e+000,-1.519347e-002,-3.620933e-001,-1.059364e+000,-6.410006e-003,-3.533099e-001,-2.688199e-004,-2.688199e-004,,,,,,,,,,,,,,,,,,,,
1432835475.556,,-1.000000e+002,5.500068e+001,5.499622e+001,1,0,2.635067e+000,-1.078982e+000,-1.078982e+000,7.730602e-002,-2.256996e-001,-1.104657e+000,5.163084e-002,-2.513748e-001,-2.715448e-004,-2.715448e-004,,,,,,,,,,,,,,,,,,,,
1432835486.304,,-1.000000e+002,5.499472e+001,5.500515e+001,1,0,5.140795e-001,-7.504501e-001,-7.504501e-001,-1.411540e-002,-1.002884e-001,-7.931384e-001,-5.680371e-002,-1.429767e-001,-1.888640e-004,-1.888640e-004,,,,,,,,,,,,,,,,,,,,
1432835486.304,,-1.000000e+002,5.499472e+001,5.500515e+001,1,0,4.823737e+000,-9.688101e-001,-9.688101e-001,1.208339e-001,-3.186483e-001,-1.101714e+000,-1.207016e-002,-4.515524e-001,-2.438181e-004,-2.438181e-004,,,,,,,,,,,,,,,,,,,,
1432835584.073,,-2.000000e+002,5.500366e+001,5.499770e+001,1,0,1.569795e+000,-8.667257e-001,-8.667257e-001,1.556231e-001,-1.765273e-001,-8.479895e-001,1.743593e-001,-1.577911e-001,-2.181255e-004,-2.181255e-004,,,,,,,,,,,,,,,,,,,,
1432835594.560,,-2.000000e+002,5.499920e+001,5.500068e+001,1,0,1.475929e+000,-4.972991e-001,-4.972991e-001,3.624715e-002,-7.853180e-003,-3.571877e-001,1.763586e-001,1.322583e-001,-1.251534e-004,-1.251534e-004,,,,,,,,,,,,,,,,,,,,
1432835594.560,,-2.000000e+002,5.499920e+001,5.500068e+001,1,0,4.944440e+000,-6.540117e-001,-6.540117e-001,2.411573e-001,-1.645657e-001,-9.017119e-001,-6.542969e-003,-4.122660e-001,-1.645926e-004,-1.645926e-004,,,,,,,,,,,,,,,,,,,,
1432835692.565,,-3.000000e+002,5.499920e+001,5.499920e+001,1,0,7.023134e-001,-8.720664e-001,-8.720664e-001,4.103971e-002,-2.244597e-001,-9.956854e-001,-8.257931e-002,-3.480787e-001,-2.194683e-004,-2.194683e-004,,,,,,,,,,,,,,,,,,,,
1432835703.279,,-3.000000e+002,5.499920e+001,5.500217e+001,1,0,2.590889e+000,-5.149999e-001,-5.149999e-001,4.531741e-004,4.531741e-004,-3.940620e-001,1.213910e-001,1.213910e-001,-1.296072e-004,-1.296072e-004,,,,,,,,,,,,,,,,,,,,
1432835703.279,,-3.000000e+002,5.499920e+001,5.500217e+001,1,0,4.316610e+000,-1.157720e+000,-1.157720e+000,-2.378432e-001,-6.422666e-001,-9.804982e-001,-6.062182e-002,-4.650452e-001,-2.913571e-004,-2.913571e-004,,,,,,,,,,,,,,,,,,,,
1432835807.752,,-4.000000e+002,5.499920e+001,5.500217e+001,1,0,9.146918e-002,-7.560961e-001,-7.560961e-001,-1.300741e-002,-2.258297e-001,-9.004206e-001,-1.573319e-001,-3.701542e-001,-1.902815e-004,-1.902815e-004,,,,,,,,,,,,,,,,,,,,
1432835807.752,,-4.000000e+002,5.499920e+001,5.500217e+001,1,0,3.621049e+000,-1.845912e+000,-1.845912e+000,-6.180617e-001,-1.315646e+000,-1.398423e+000,-1.705725e-001,-8.681566e-001,-4.645480e-004,-4.645480e-004,,,,,,,,,,,,,,,,,,,,
1432835817.967,,-4.000000e+002,5.500217e+001,5.499622e+001,1,0,3.308171e+000,-1.195105e+000,-1.195105e+000,-5.135109e-001,-9.053817e-001,-7.376215e-001,-5.602764e-002,-4.478984e-001,-3.007638e-004,-3.007638e-004,,,,,,,,,,,,,,,,,,,,
1432835922.197,,-5.000000e+002,5.499770e+001,5.499920e+001,1,0,1.307948e-001,-8.418531e-001,-8.418531e-001,-4.864824e-002,-2.505126e-001,-9.802473e-001,-1.870425e-001,-3.889068e-001,-2.118621e-004,-2.118621e-004,,,,,,,,,,,,,,,,,,,,
1432835922.197,,-5.000000e+002,5.499770e+001,5.499920e+001,1,0,4.451432e+000,-1.474044e+000,-1.474044e+000,-4.418997e-002,-8.827035e-001,-1.498919e+000,-6.906538e-002,-9.075789e-001,-3.709604e-004,-3.709604e-004,,,,,,,,,,,,,,,,,,,,
1432835932.697,,-5.000000e+002,5.499920e+001,5.499472e+001,1,0,2.189817e+000,-3.295999e-001,-3.295999e-001,4.956664e-001,1.436676e-001,-4.303825e-001,3.948838e-001,4.288498e-002,-8.294766e-005,-8.294766e-005,,,,,,,,,,,,,,,,,,,,
1432836043.612,,-1.000000e+003,5.499770e+001,5.499920e+001,1,0,8.669602e-001,-1.509293e+000,-1.509293e+000,-8.095312e-002,-2.823648e-001,-1.493693e+000,-6.535327e-002,-2.667650e-001,-3.798199e-004,-3.798199e-004,,,,,,,,,,,,,,,,,,,,
1432836043.612,,-1.000000e+003,5.499770e+001,5.499920e+001,1,0,4.966469e+000,-1.608325e+000,-1.608325e+000,8.522493e-001,-3.813975e-001,-2.507401e+000,-4.682595e-002,-1.280473e+000,-4.047418e-004,-4.047418e-004,,,,,,,,,,,,,,,,,,,,
1432836053.933,,-1.000000e+003,5.499920e+001,5.500068e+001,1,0,1.199539e+000,-1.341899e+000,-1.341899e+000,2.616850e-001,-3.298379e-001,-1.384005e+000,2.195793e-001,-3.719436e-001,-3.376945e-004,-3.376945e-004,,,,,,,,,,,,,,,,,,,,
1432836188.498,,-3.000000e+003,5.499770e+001,5.500515e+001,1,0,1.915391e+000,-2.284310e-001,-2.284310e-001,1.600392e-001,1.291840e-001,-6.360282e-002,3.248674e-001,2.940122e-001,-2.873939e-004,-2.873939e-004,,,,,,,,,,,,,,,,,,,,
1432836188.498,,-3.000000e+003,5.499770e+001,5.500515e+001,1,0,4.766942e+000,-6.308176e-001,-6.308176e-001,1.793398e-001,-2.732025e-001,-8.390840e-001,-2.892662e-002,-4.814689e-001,-7.936449e-004,-7.936449e-004,,,,,,,,,,,,,,,,,,,,
1432836198.915,,-3.000000e+003,5.500068e+001,5.499920e+001,1,0,4.101095e-001,-4.640339e-001,-4.640339e-001,1.954560e-002,-1.786098e-001,-6.222779e-001,-1.386984e-001,-3.368538e-001,-5.838108e-004,-5.838108e-004,,,,,,,,,,,,,,,,,,,,
1432836198.915,,-3.000000e+003,5.500068e+001,5.499920e+001,1,0,3.027039e+000,-8.621479e-001,-8.621479e-001,8.306522e-003,-5.767238e-001,-9.169505e-001,-4.649607e-002,-6.315264e-001,-1.084686e-003,-1.084686e-003,,,,,,,,,,,,,,,,,,,,
1432836319.031,,-5.000000e+003,5.499770e+001,5.499472e+001,1,0,3.940140e+000,-2.021241e+000,-2.021241e+000,-8.419077e-001,-1.378890e+000,-1.337850e+000,-1.585169e-001,-6.954989e-001,-2.542663e-003,-2.542663e-003,,,,,,,,,,,,,,,,,,,,
1432836328.995,,-5.000000e+003,5.499472e+001,5.499324e+001,1,0,8.803340e-003,-3.886532e-001,-3.886532e-001,-3.827588e-002,-2.514209e-001,-5.274337e-001,-1.770564e-001,-3.902014e-001,-4.889147e-004,-4.889147e-004,,,,,,,,,,,,,,,,,,,,
1432836328.995,,-5.000000e+003,5.499472e+001,5.499324e+001,1,0,3.974910e+000,-1.538285e+000,-1.538285e+000,-6.417239e-001,-1.401053e+000,-1.048225e+000,-1.516632e-001,-9.109925e-001,-1.935119e-003,-1.935119e-003,,,,,,,,,,,,,,,,,,,,
1432836448.970,,-7.000000e+003,5.499622e+001,5.499472e+001,1,0,2.860523e+000,-1.146580e+000,-1.146580e+000,-4.968718e-002,-5.901241e-001,-1.070465e+000,2.642831e-002,-5.140086e-001,-1.442194e-003,-1.442194e-003,,,,,,,,,,,,,,,,,,,,
1432836459.185,,-7.000000e+003,5.499472e+001,5.499472e+001,1,0,3.635639e-001,-8.296456e-001,-8.296457e-001,-8.706172e-002,-2.543994e-001,-1.006993e+000,-2.644095e-001,-4.317471e-001,-1.043546e-003,-1.043546e-003,,,,,,,,,,,,,,,,,,,,
1432836459.185,,-7.000000e+003,5.499472e+001,5.499472e+001,1,0,4.717561e+000,-1.020386e+000,-1.020386e+000,3.459106e-001,-4.451400e-001,-1.425385e+000,-5.908813e-002,-8.501388e-001,-1.283464e-003,-1.283464e-003,,,,,,,,,,,,,,,,,,,,
1432836579.870,,-9.000000e+003,5.499622e+001,5.499622e+001,1,0,1.768320e+000,6.546220e-002,6.546220e-002,6.484236e-001,2.310086e-001,1.112117e-001,6.941731e-001,2.767580e-001,8.232997e-005,8.232997e-005,,,,,,,,,,,,,,,,,,,,
1432836590.144,,-9.000000e+003,5.499920e+001,5.500068e+001,1,0,1.264780e+000,-3.511154e-001,-3.511155e-001,2.202669e-002,-7.139048e-002,-9.791984e-002,2.752223e-001,1.818051e-001,-4.415880e-004,-4.415880e-004,,,,,,,,,,,,,,,,,,,,
1432836590.144,,-9.000000e+003,5.499920e+001,5.500068e+001,1,0,4.985630e+000,-2.305673e-001,-2.305673e-001,7.809255e-001,4.915765e-002,-1.057277e+000,-4.578426e-002,-7.775521e-001,-2.899781e-004,-2.899781e-004,,,,,,,,,,,,,,,,,,,,
1432836706.928,,-1.000000e+004,5.499472e+001,5.499770e+001,1,0,8.602123e-001,-7.309183e-001,-7.309183e-001,1.497728e-001,-3.140003e-001,-9.664506e-001,-8.575946e-002,-5.495327e-001,-9.192007e-004,-9.192007e-004,,,,,,,,,,,,,,,,,,,,
1432836717.453,,-1.000000e+004,5.499770e+001,5.500217e+001,1,0,2.366378e+000,-2.229377e-001,-2.229377e-001,3.023649e-001,2.834966e-001,4.531863e-003,5.298345e-001,5.109662e-001,-2.803658e-004,-2.803658e-004,,,,,,,,,,,,,,,,,,,,
1432836717.453,,-1.000000e+004,5.499770e+001,5.500217e+001,1,0,4.486969e+000,-1.494186e+000,-1.494186e+000,-1.952831e-001,-9.877520e-001,-1.411932e+000,-1.130289e-001,-9.054978e-001,-1.879084e-003,-1.879084e-003,,,,,,,,,,,,,,,,,,,,
1432836874.785,,-2.000000e+004,5.499324e+001,5.499770e+001,1,0,1.768478e-001,-4.457228e-001,-4.457228e-001,-1.519530e-002,-2.900703e-001,-7.036805e-001,-2.731529e-001,-5.480279e-001,-1.120412e-003,-1.120412e-003,,,,,,,,,,,,,,,,,,,,
1432836874.785,,-2.000000e+004,5.499324e+001,5.499770e+001,1,0,3.431798e+000,-1.761681e+000,-1.761681e+000,-7.380021e-001,-1.606028e+000,-1.294509e+000,-2.708306e-001,-1.138857e+000,-4.428332e-003,-4.428332e-003,,,,,,,,,,,,,,,,,,,,
1432836884.950,,-2.000000e+004,5.499920e+001,5.499770e+001,1,0,3.525396e+000,-1.815851e+000,-1.815851e+000,-1.140527e+000,-1.674987e+000,-9.571676e-001,-2.818428e-001,-8.163030e-001,-4.564499e-003,-4.564499e-003,,,,,,,,,,,,,,,,,,,,
1432837035.787,,-3.000000e+004,5.500217e+001,5.499920e+001,1,0,5.713661e-002,-8.536027e-001,-8.536027e-001,-1.109715e-001,-3.631109e-001,-1.072151e+000,-3.295194e-001,-5.816588e-001,-2.144420e-003,-2.144420e-003,,,,,,,,,,,,,,,,,,,,
1432837035.787,,-3.000000e+004,5.500217e+001,5.499920e+001,1,0,4.301268e+000,-1.928312e+000,-1.928312e+000,-4.472727e-001,-1.437820e+000,-1.648135e+000,-1.670960e-001,-1.157644e+000,-4.844304e-003,-4.844304e-003,,,,,,,,,,,,,,,,,,,,
1432837046.003,,-3.000000e+004,5.499920e+001,5.500217e+001,1,0,2.410457e+000,-1.739555e-001,-1.739555e-001,7.412959e-001,1.581627e-001,-3.892833e-001,5.259681e-001,-5.716509e-002,-4.370109e-004,-4.370109e-004,,,,,,,,,,,,,,,,,,,,
1432837198.490,,-4.000000e+004,5.500068e+001,5.500366e+001,1,0,6.840721e-001,-8.027894e-001,-8.027894e-001,-1.386065e-001,-3.335222e-001,-9.503500e-001,-2.861671e-001,-4.810829e-001,-2.015565e-003,-2.015565e-003,,,,,,,,,,,,,,,,,,,,
1432837198.490,,-4.000000e+004,5.500068e+001,5.500366e+001,1,0,4.909204e+000,-5.516220e-001,-5.516220e-001,1.000511e+000,-8.235487e-002,-1.625334e+000,-7.320143e-002,-1.156067e+000,-1.384958e-003,-1.384958e-003,,,,,,,,,,,,,,,,,,,,
1432837208.407,,-4.000000e+004,5.500515e+001,5.500068e+001,1,0,1.380137e+000,-3.367718e-001,-3.367718e-001,5.130352e-001,-6.894696e-002,-3.161087e-001,5.336983e-001,-4.828387e-002,-8.455334e-004,-8.455334e-004,,,,,,,,,,,,,,,,,,,,
1432837369.948,,-5.000000e+004,5.499770e+001,5.500217e+001,1,0,1.692737e+000,-1.393170e-001,-1.393170e-001,4.081677e-001,3.119579e-001,5.013298e-001,1.048815e+000,9.526047e-001,-3.495748e-004,-3.495748e-004,,,,,,,,,,,,,,,,,,,,
1432837369.948,,-5.000000e+004,5.499770e+001,5.500217e+001,1,0,4.869971e+000,-6.143376e-001,-6.143376e-001,9.192983e-001,-1.630628e-001,-1.623974e+000,-9.033854e-002,-1.172700e+000,-1.541499e-003,-1.541499e-003,,,,,,,,,,,,,,,,,,,,
1432837380.221,,-5.000000e+004,5.500068e+001,5.499770e+001,1,0,5.520409e-001,-8.751183e-001,-8.751183e-001,9.015504e-002,-4.370461e-001,-1.404015e+000,-4.387419e-001,-9.659431e-001,-2.195851e-003,-2.195851e-003,,,,,,,,,,,,,,,,,,,,
1432837380.221,,-5.000000e+004,5.500068e+001,5.499770e+001,1,0,2.812570e+000,-1.194800e+000,-1.194800e+000,7.529849e-001,-7.567276e-001,-1.819834e+000,1.279503e-001,-1.381762e+000,-2.997997e-003,-2.997997e-003,,,,,,,,,,,,,,,,,,,,
1432837552.304,,-6.000000e+004,5.500068e+001,5.499770e+001,1,0,4.135140e+000,-1.594287e+000,-1.594287e+000,-8.446930e-001,-1.368949e+000,-9.203112e-001,-1.707173e-001,-6.949735e-001,-7.996009e-003,-7.996009e-003,,,,,,,,,,,,,,,,,,,,
1432837562.470,,-6.000000e+004,5.500068e+001,5.500068e+001,1,0,3.473668e-002,-4.927213e-001,-4.927213e-001,-5.525940e-002,-2.765880e-001,-6.880955e-001,-2.506335e-001,-4.719621e-001,-2.471201e-003,-2.471201e-003,,,,,,,,,,,,,,,,,,,,
1432837562.470,,-6.000000e+004,5.500068e+001,5.500068e+001,1,0,3.802214e+000,-1.984619e+000,-1.984619e+000,-1.013364e+000,-1.768485e+000,-1.229243e+000,-2.579883e-001,-1.013109e+000,-9.953683e-003,-9.953683e-003,,,,,,,,,,,,,,,,,,,,
1432837721.328,,-7.000000e+004,5.500068e+001,5.500515e+001,1,0,3.086231e+000,-1.204566e+000,-1.204566e+000,-4.763370e-001,-9.682924e-001,-8.650447e-001,-1.368161e-001,-6.287715e-001,-6.037787e-003,-6.037787e-003,,,,,,,,,,,,,,,,,,,,
1432837731.293,,-7.000000e+004,5.500366e+001,5.499472e+001,1,0,2.345464e-001,-5.206457e-001,-5.206458e-001,-1.126829e-001,-2.795960e-001,-7.235656e-001,-3.156027e-001,-4.825158e-001,-2.609695e-003,-2.609695e-003,,,,,,,,,,,,,,,,,,,,
1432837731.293,,-7.000000e+004,5.500366e+001,5.499472e+001,1,0,4.591512e+000,-8.200323e-001,-8.200324e-001,1.582168e-001,-5.789825e-001,-1.066777e+000,-8.852823e-002,-8.257275e-001,-4.110346e-003,-4.110346e-003,,,,,,,,,,,,,,,,,,,,
1432837894.723,,-6.000000e+004,5.500217e+001,5.499920e+001,1,0,1.974514e+000,3.686636e-001,3.686636e-001,6.890548e-001,3.535880e-001,3.366227e-001,6.570140e-001,3.215471e-001,1.849000e-003,1.849000e-003,,,,,,,,,,,,,,,,,,,,
1432837904.796,,-6.000000e+004,5.499770e+001,5.499770e+001,1,0,1.061764e+000,-1.553392e-001,-1.553392e-001,-2.957540e-002,-1.079358e-001,-5.120627e-002,7.455754e-002,-3.802814e-003,-7.790904e-004,-7.790904e-004,,,,,,,,,,,,,,,,,,,,
1432837904.796,,-6.000000e+004,5.499770e+001,5.499770e+001,1,0,4.992419e+000,1.255837e-001,1.255837e-001,7.103152e-001,1.729871e-001,-6.260186e-001,-4.128699e-002,-5.786151e-001,6.298540e-004,6.298540e-004,,,,,,,,,,,,,,,,,,,,
1432838066.513,,-5.000000e+004,5.499622e+001,5.499324e+001,1,0,1.026480e+000,-3.280740e-002,-3.280740e-002,1.533990e-001,-8.656839e-002,-1.434766e-001,4.272977e-002,-1.972376e-001,-1.646409e-004,-1.646409e-004,,,,,,,,,,,,,,,,,,,,
1432838076.835,,-5.000000e+004,5.500068e+001,5.499920e+001,1,0,2.139844e+000,3.987243e-001,3.987243e-001,3.301571e-001,3.108193e-001,6.084397e-001,5.398725e-001,5.205346e-001,2.000962e-003,2.000962e-003,,,,,,,,,,,,,,,,,,,,
1432838076.835,,-5.000000e+004,5.500068e+001,5.499920e+001,1,0,4.638239e+000,-2.229377e-001,-2.229377e-001,1.049210e-001,-3.108428e-001,-3.936100e-001,-6.575131e-002,-4.815150e-001,-1.118793e-003,-1.118793e-003,,,,,,,,,,,,,,,,,,,,
1432838236.767,,-4.000000e+004,5.500217e+001,5.500217e+001,1,0,2.837608e-001,-1.937925e-002,-1.937925e-002,6.058142e-004,-1.594055e-001,-2.443609e-001,-2.243759e-001,-3.843871e-001,-9.731104e-005,-9.731104e-005,,,,,,,,,,,,,,,,,,,,
1432838236.767,,-4.000000e+004,5.500217e+001,5.500217e+001,1,0,3.233920e+000,-6.469924e-001,-6.469924e-001,-2.989842e-001,-7.870186e-001,-5.110571e-001,-1.630489e-001,-6.510834e-001,-3.248810e-003,-3.248810e-003,,,,,,,,,,,,,,,,,,,,
1432838246.792,,-4.000000e+004,5.500068e+001,5.500068e+001,1,0,3.736504e+000,-1.282388e+000,-1.282388e+000,-9.836317e-001,-1.356241e+000,-5.090519e-001,-2.102958e-001,-5.829053e-001,-6.439386e-003,-6.439386e-003,,,,,,,,,,,,,,,,,,,,
1432838403.639,,-3.000000e+004,5.499920e+001,5.499324e+001,1,0,1.638704e-002,-8.728294e-002,-8.728294e-002,-4.866474e-002,-1.543987e-001,-1.969678e-001,-1.583496e-001,-2.640836e-001,-4.385443e-004,-4.385443e-004,,,,,,,,,,,,,,,,,,,,
1432838403.639,,-3.000000e+004,5.499920e+001,5.499324e+001,1,0,4.140398e+000,-7.306131e-001,-7.306131e-001,-4.029886e-001,-7.977289e-001,-4.352040e-001,-1.075795e-001,-5.023198e-001,-3.670892e-003,-3.670892e-003,,,,,,,,,,,,,,,,,,,,
1432838413.556,,-3.000000e+004,5.500217e+001,5.499920e+001,1,0,2.634430e+000,3.677481e-002,3.677480e-002,1.969922e-001,-2.773553e-002,-2.161080e-002,1.386066e-001,-8.612113e-002,1.847713e-004,1.847713e-004,,,,,,,,,,,,,,,,,,,,
1432838569.344,,-2.000000e+004,5.499920e+001,5.499472e+001,1,0,5.147649e-001,7.507553e-002,7.507554e-002,-4.697947e-002,-9.254342e-002,-2.600494e-003,-1.246555e-001,-1.702195e-001,3.774342e-004,3.774342e-004,,,,,,,,,,,,,,,,,,,,
1432838569.344,,-2.000000e+004,5.499920e+001,5.499472e+001,1,0,4.825413e+000,1.985229e-001,1.985229e-001,2.632801e-001,3.090395e-002,-9.091418e-002,-2.615697e-002,-2.585331e-001,9.980528e-004,9.980528e-004,,,,,,,,,,,,,,,,,,,,
1432838579.476,,-2.000000e+004,5.499472e+001,5.500217e+001,1,0,1.569517e+000,1.509140e-001,1.509140e-001,2.193795e-001,8.982061e-002,1.772768e-001,2.457422e-001,1.161833e-001,7.587042e-004,7.587042e-004,,,,,,,,,,,,,,,,,,,,
1432838742.198,,-1.000000e+004,5.499472e+001,5.500217e+001,1,0,1.476141e+000,3.611866e-001,3.611866e-001,1.270267e-001,7.595068e-002,7.466616e-001,5.125017e-001,4.614257e-001,4.542271e-004,4.542271e-004,,,,,,,,,,,,,,,,,,,,
1432838742.198,,-1.000000e+004,5.499472e+001,5.500217e+001,1,0,4.944112e+000,5.815302e-001,5.815302e-001,7.661937e-001,2.962943e-001,-2.372850e-001,-5.262151e-002,-5.225208e-001,7.313307e-004,7.313307e-004,,,,,,,,,,,,,,,,,,,,
1432838752.115,,-1.000000e+004,5.500068e+001,5.500366e+001,1,0,7.014251e-001,2.694784e-001,2.694784e-001,1.046155e-001,-1.192042e-001,-3.946123e-002,-2.043241e-001,-4.281439e-001,3.388953e-004,3.388953e-004,,,,,,,,,,,,,,,,,,,,
1432838868.198,,-9.000000e+003,5.500068e+001,5.499622e+001,1,0,2.591007e+000,8.946501e-001,8.946501e-001,-1.194835e-002,-1.194835e-002,1.181732e+000,2.751338e-001,2.751338e-001,1.125176e-003,1.125176e-003,,,,,,,,,,,,,,,,,,,,
1432838868.198,,-9.000000e+003,5.500068e+001,5.499622e+001,1,0,4.317908e+000,3.006073e-002,3.006073e-002,-5.454872e-001,-8.765377e-001,4.374919e-001,-1.380560e-001,-4.691066e-001,3.780653e-005,3.780653e-005,,,,,,,,,,,,,,,,,,,,
1432838878.115,,-9.000000e+003,5.499622e+001,5.499622e+001,1,0,8.994409e-002,2.760399e-001,2.760399e-001,-3.107443e-002,-1.758286e-001,1.554182e-002,-2.915725e-001,-4.363267e-001,3.471676e-004,3.471676e-004,,,,,,,,,,,,,,,,,,,,
1432838878.115,,-9.000000e+003,5.499622e+001,5.499622e+001,1,0,3.621148e+000,-1.123692e+000,-1.123692e+000,-1.101088e+000,-1.575560e+000,-3.388845e-001,-3.162810e-001,-7.907531e-001,-1.413235e-003,-1.413235e-003,,,,,,,,,,,,,,,,,,,,
1432838998.236,,-7.000000e+003,5.500217e+001,5.499622e+001,1,0,3.308108e+000,-6.094546e-001,-6.094546e-001,-8.016995e-001,-1.028757e+000,-3.160109e-002,-2.238460e-001,-4.509038e-001,-7.665852e-004,-7.665852e-004,,,,,,,,,,,,,,,,,,,,
1432839008.701,,-7.000000e+003,5.499622e+001,5.499770e+001,1,0,1.311937e-001,2.520829e-001,2.520829e-001,-7.904753e-002,-1.653671e-001,8.096761e-002,-2.501628e-001,-3.364824e-001,3.170753e-004,3.170753e-004,,,,,,,,,,,,,,,,,,,,
1432839008.701,,-7.000000e+003,5.499622e+001,5.499770e+001,1,0,4.451138e+000,-1.281777e-002,-1.281777e-002,-7.170945e-002,-4.302678e-001,-3.297548e-002,-9.186716e-002,-4.504255e-001,-1.612247e-005,-1.612247e-005,,,,,,,,,,,,,,,,,,,,
1432839128.427,,-5.000000e+003,5.500068e+001,5.500217e+001,1,0,2.189708e+000,7.368695e-001,7.368694e-001,5.110903e-001,3.827701e-001,6.343519e-001,4.085729e-001,2.802526e-001,9.269607e-004,9.269607e-004,,,,,,,,,,,,,,,,,,,,
1432839138.595,,-5.000000e+003,5.500217e+001,5.499622e+001,1,0,8.665202e-001,7.354961e-001,7.354961e-001,-5.041232e-002,-8.480048e-002,7.391865e-001,-4.672189e-002,-8.111006e-002,9.252331e-004,9.252331e-004,,,,,,,,,,,,,,,,,,,,
1432839138.595,,-5.000000e+003,5.500217e+001,5.499622e+001,1,0,4.965109e+000,1.132694e+000,1.132694e+000,5.230254e-001,3.123979e-001,5.792766e-001,-3.039245e-002,-2.410200e-001,1.424897e-003,1.424897e-003,,,,,,,,,,,,,,,,,,,,
1432839258.407,,-3.000000e+003,5.500068e+001,5.499770e+001,1,0,1.199487e+000,5.653554e-001,5.653554e-001,1.190605e-001,9.810948e-002,5.422272e-001,9.593238e-002,7.498133e-002,7.112855e-004,7.112855e-004,,,,,,,,,,,,,,,,,,,,
1432839268.682,,-3.000000e+003,5.500217e+001,5.500366e+001,1,0,1.915203e+000,5.909909e-001,5.909910e-001,1.558048e-001,1.512400e-001,7.592842e-001,3.240981e-001,3.195332e-001,7.435381e-004,7.435381e-004,,,,,,,,,,,,,,,,,,,,
1432839268.682,,-3.000000e+003,5.500217e+001,5.500366e+001,1,0,4.766632e+000,5.549791e-001,5.549791e-001,1.821791e-001,1.152281e-001,3.439023e-001,-2.889771e-002,-9.584868e-002,6.982309e-004,6.982309e-004,,,,,,,,,,,,,,,,,,,,
1432839387.264,,-1.000000e+003,5.500217e+001,5.499622e+001,1,0,4.102026e-001,6.917020e-001,6.917020e-001,1.713061e-002,5.879432e-002,6.455636e-001,-2.900779e-002,1.265591e-002,8.703485e-004,8.703485e-004,,,,,,,,,,,,,,,,,,,,
1432839387.264,,-1.000000e+003,5.500217e+001,5.499622e+001,1,0,3.026713e+000,7.652516e-001,7.652516e-001,9.336816e-003,1.323439e-001,7.087991e-001,-4.711576e-002,7.589138e-002,9.628939e-004,9.628939e-004,,,,,,,,,,,,,,,,,,,,
1432839397.228,,-1.000000e+003,5.499622e+001,5.500068e+001,1,0,3.940031e+000,1.988281e-001,1.988281e-001,-2.652314e-001,-2.147155e-001,4.155096e-001,-4.854992e-002,1.966029e-003,2.501796e-004,2.501796e-004,,,,,,,,,,,,,,,,,,,,
1432839507.654,,-5.000000e+002,5.500217e+001,5.499026e+001,1,0,8.704796e-003,-4.528947e-001,-4.528947e-001,-1.217719e-003,2.248156e-002,-4.573245e-001,-5.647536e-003,1.805174e-002,-5.698812e-004,-5.698812e-004,,,,,,,,,,,,,,,,,,,,
1432839507.654,,-5.000000e+002,5.500217e+001,5.499026e+001,1,0,3.975296e+000,-5.030977e-001,-5.030977e-001,-1.121501e-001,-2.772141e-002,-3.937603e-001,-2.812730e-003,8.161595e-002,-6.330519e-004,-6.330519e-004,,,,,,,,,,,,,,,,,,,,
1432839517.675,,-5.000000e+002,5.499770e+001,5.499920e+001,1,0,2.861282e+000,7.666250e-001,7.666250e-001,-7.643164e-003,4.620427e-002,7.621633e-001,-1.210487e-002,4.174256e-002,9.646506e-004,9.646506e-004,,,,,,,,,,,,,,,,,,,,
1432839621.065,,-4.000000e+002,5.499920e+001,5.499324e+001,1,0,3.641357e-001,6.659139e-001,6.659139e-001,-9.937593e-003,4.120409e-003,6.440517e-001,-3.179974e-002,-1.774174e-002,8.379299e-004,8.379299e-004,,,,,,,,,,,,,,,,,,,,
1432839621.065,,-4.000000e+002,5.499920e+001,5.499324e+001,1,0,4.717780e+000,7.742546e-001,7.742546e-001,4.600508e-002,1.124611e-001,7.203681e-001,-7.881333e-003,5.857468e-002,9.742567e-004,9.742567e-004,,,,,,,,,,,,,,,,,,,,
1432839631.075,,-4.000000e+002,5.499622e+001,5.499770e+001,1,0,1.767607e+000,5.195776e-001,5.195776e-001,6.772152e-002,1.217089e-001,4.647855e-001,1.292938e-002,6.691676e-002,6.537927e-004,6.537927e-004,,,,,,,,,,,,,,,,,,,,
1432839744.521,,-3.000000e+002,5.499324e+001,5.499472e+001,1,0,1.264507e+000,6.068606e-001,6.068606e-001,-1.855464e-002,-1.798445e-002,7.557717e-001,1.303565e-001,1.309267e-001,1.527253e-004,1.527253e-004,,,,,,,,,,,,,,,,,,,,
1432839744.521,,-3.000000e+002,5.499324e+001,5.499472e+001,1,0,4.985297e+000,9.996338e-001,9.996338e-001,3.703223e-001,3.747888e-001,6.263723e-001,-2.939261e-003,1.527250e-003,2.515725e-004,2.515725e-004,,,,,,,,,,,,,,,,,,,,
1432839754.971,,-3.000000e+002,5.499472e+001,5.500068e+001,1,0,8.597580e-001,9.794915e-001,9.794915e-001,7.268563e-002,8.709967e-002,9.850855e-001,7.827964e-002,9.269369e-002,2.465034e-004,2.465034e-004,,,,,,,,,,,,,,,,,,,,
1432839859.121,,-2.000000e+002,5.500068e+001,5.500217e+001,1,0,2.366506e+000,1.542711e-001,1.542711e-001,2.879635e-002,1.988459e-002,1.068834e-001,-1.859128e-002,-2.750304e-002,3.882480e-005,3.882480e-005,,,,,,,,,,,,,,,,,,,,
1432839859.121,,-2.000000e+002,5.500068e+001,5.500217e+001,1,0,4.486692e+000,-2.562029e-001,-2.562029e-001,-1.629514e-002,-3.905894e-001,-2.425186e-001,-2.610898e-003,-3.769051e-001,-6.447759e-005,-6.447759e-005,,,,,,,,,,,,,,,,,,,,
1432839869.830,,-2.000000e+002,5.500068e+001,5.499472e+001,1,0,1.761531e-001,-5.923643e-001,-5.923643e-001,1.726718e-002,-1.685914e-001,-6.064909e-001,3.140578e-003,-1.827180e-001,-1.490780e-004,-1.490780e-004,,,,,,,,,,,,,,,,,,,,
1432839869.830,,-2.000000e+002,5.500068e+001,5.499472e+001,1,0,3.432213e+000,-1.259957e+000,-1.259957e+000,-2.492621e-001,-8.361838e-001,-1.021576e+000,-1.088106e-002,-5.978028e-001,-3.170884e-004,-3.170884e-004,,,,,,,,,,,,,,,,,,,,
1432839974.003,,-1.000000e+002,5.499770e+001,5.499770e+001,1,0,3.525410e+000,9.764397e-001,9.764397e-001,-2.358273e-001,2.886474e-003,1.207596e+000,-4.670849e-003,2.340429e-001,2.457383e-004,2.457383e-004,,,,,,,,,,,,,,,,,,,,
1432839984.463,,-1.000000e+002,5.499770e+001,5.499920e+001,1,0,5.749157e-002,1.116672e+000,1.116672e+000,-7.046429e-003,9.193480e-002,1.121427e+000,-2.291886e-003,9.668934e-002,2.810303e-004,2.810303e-004,,,,,,,,,,,,,,,,,,,,
1432839984.463,,-1.000000e+002,5.499770e+001,5.499920e+001,1,0,4.300375e+000,1.371654e+000,1.371654e+000,-4.193792e-002,3.469169e-001,1.412199e+000,-1.393168e-003,3.874617e-001,3.452010e-004,3.452010e-004,,,,,,,,,,,,,,,,,,,,
1432840088.634,,0.000000e+000,5.499920e+001,5.499472e+001,1,0,2.409870e+000,1.780755e+000,1.780755e+000,-1.216546e-002,3.147820e-001,1.776994e+000,-1.592603e-002,3.110214e-001,4.481611e-004,4.481611e-004,,,,,,,,,,,,,,,,,,,,
1432840116.376,,0.000000e+000,5.499175e+001,5.499622e+001,1,0,6.840951e-001,1.086917e+000,1.086917e+000,1.674136e-002,1.156579e-001,1.086529e+000,1.635333e-002,1.152698e-001,1.367717e-004,1.367717e-004,,,,,,,,,,,,,,,,,,,,
1432840116.376,,0.000000e+000,5.499175e+001,5.499622e+001,1,0,4.909921e+000,1.489761e+000,1.489761e+000,-3.103398e-002,5.185022e-001,1.524897e+000,4.102485e-003,5.536386e-001,1.874634e-004,1.874634e-004,,,,,,,,,,,,,,,,,,,,
1432840224.279,,1.000000e+002,5.499622e+001,5.499920e+001,1,0,1.380459e+000,9.453108e-001,9.453108e-001,-6.648433e-002,2.126454e-001,9.363686e-001,-7.542658e-002,2.037032e-001,2.379041e-004,2.379041e-004,,,,,,,,,,,,,,,,,,,,
1432840234.849,,1.000000e+002,5.499920e+001,5.499920e+001,1,0,1.693575e+000,5.209510e-001,5.209510e-001,-4.769498e-002,-1.406223e-002,4.445131e-001,-1.241329e-001,-9.050012e-002,1.311065e-004,1.311065e-004,,,,,,,,,,,,,,,,,,,,
1432840234.849,,1.000000e+002,5.499920e+001,5.499920e+001,1,0,4.870347e+000,8.044679e-001,8.044679e-001,-1.089138e-001,2.694547e-001,9.243677e-001,1.098603e-002,3.893545e-001,2.024585e-004,2.024585e-004,,,,,,,,,,,,,,,,,,,,
1432840338.804,,2.000000e+002,5.500217e+001,5.499770e+001,1,0,5.516527e-001,1.287271e+000,1.287271e+000,-3.205767e-002,2.952358e-001,1.406124e+000,8.679590e-002,4.140893e-001,3.239625e-004,3.239625e-004,,,,,,,,,,,,,,,,,,,,
1432840338.804,,2.000000e+002,5.500217e+001,5.499770e+001,1,0,2.812694e+000,1.768090e+000,1.768090e+000,-1.611945e-001,7.760549e-001,1.902719e+000,-2.656584e-002,9.106835e-001,4.449683e-004,4.449683e-004,,,,,,,,,,,,,,,,,,,,
1432840349.267,,2.000000e+002,5.499920e+001,5.499920e+001,1,0,4.135184e+000,1.624195e+000,1.624195e+000,3.061875e-001,8.113402e-001,1.378019e+000,6.001123e-002,5.651639e-001,4.087549e-004,4.087549e-004,,,,,,,,,,,,,,,,,,,,
1432840447.508,,3.000000e+002,5.500217e+001,5.500217e+001,1,0,3.636492e-002,1.331980e+000,1.331980e+000,9.096892e-003,2.495477e-001,1.440799e+000,1.179152e-001,3.583660e-001,3.352124e-004,3.352124e-004,,,,,,,,,,,,,,,,,,,,
1432840447.508,,3.000000e+002,5.500217e+001,5.500217e+001,1,0,3.801339e+000,2.399518e+000,2.399518e+000,4.967235e-001,1.317085e+000,2.025035e+000,1.222406e-001,9.426023e-001,6.038737e-004,6.038737e-004,,,,,,,,,,,,,,,,,,,,
1432840457.971,,3.000000e+002,5.500366e+001,5.500217e+001,1,0,3.085617e+000,1.573534e+000,1.573534e+000,2.390879e-001,7.385034e-001,1.393536e+000,5.908996e-002,5.585055e-001,3.960030e-004,3.960030e-004,,,,,,,,,,,,,,,,,,,,
1432840562.934,,4.000000e+002,5.500217e+001,5.499770e+001,1,0,2.342348e-001,5.360576e-001,5.360576e-001,4.020320e-002,1.791702e-001,5.147445e-001,1.889013e-002,1.578571e-001,1.349059e-004,1.349059e-004,,,,,,,,,,,,,,,,,,,,
1432840562.934,,4.000000e+002,5.500217e+001,5.499770e+001,1,0,4.591292e+000,8.226264e-001,8.226264e-001,-1.480318e-001,4.657390e-001,9.795473e-001,8.889156e-003,6.226599e-001,2.070248e-004,2.070248e-004,,,,,,,,,,,,,,,,,,,,
1432840573.398,,4.000000e+002,5.499770e+001,5.499920e+001,1,0,1.974814e+000,2.206488e-001,2.206488e-001,-4.410857e-001,-7.536191e-002,5.728136e-001,-8.892088e-002,2.768029e-001,5.552918e-005,5.552918e-005,,,,,,,,,,,,,,,,,,,,
1432840677.862,,5.000000e+002,5.500068e+001,5.499622e+001,1,0,1.061076e+000,8.975494e-001,8.975494e-001,3.451495e-002,1.145585e-001,8.008760e-001,-6.215842e-002,1.788509e-002,2.258788e-004,2.258788e-004,,,,,,,,,,,,,,,,,,,,
1432840677.862,,5.000000e+002,5.500068e+001,5.499622e+001,1,0,4.993432e+000,7.988220e-001,7.988220e-001,-5.330387e-001,1.583105e-002,1.359591e+000,2.773054e-002,5.766003e-001,2.010329e-004,2.010329e-004,,,,,,,,,,,,,,,,,,,,
1432840688.325,,5.000000e+002,5.499622e+001,5.500217e+001,1,0,1.025850e+000,6.683554e-002,6.683554e-002,-1.311618e-001,9.305549e-002,1.284558e-003,-1.967128e-001,2.750451e-002,1.681994e-005,1.681994e-005,,,,,,,,,,,,,,,,,,,,
1432840799.053,,1.000000e+003,5.499920e+001,5.499472e+001,1,0,2.140306e+000,6.465346e-001,6.465346e-001,-3.884064e-001,-3.429013e-001,3.608092e-001,-6.741318e-001,-6.286268e-001,1.627031e-004,1.627031e-004,,,,,,,,,,,,,,,,,,,,
1432840799.053,,1.000000e+003,5.499920e+001,5.499472e+001,1,0,4.638297e+000,1.804712e+000,1.804712e+000,-1.630819e-001,8.152761e-001,2.049661e+000,8.186676e-002,1.060225e+000,4.541634e-004,4.541634e-004,,,,,,,,,,,,,,,,,,,,
1432840809.517,,1.000000e+003,5.499472e+001,5.499472e+001,1,0,2.824706e-001,1.155278e+000,1.155278e+000,-3.057469e-002,3.857040e-001,1.510359e+000,3.245058e-001,7.407845e-001,2.907306e-004,2.907306e-004,,,,,,,,,,,,,,,,,,,,
1432840809.517,,1.000000e+003,5.499472e+001,5.499472e+001,1,0,3.233527e+000,2.516709e+000,2.516709e+000,4.774846e-001,1.747135e+000,2.282976e+000,2.437516e-001,1.513402e+000,6.333403e-004,6.333403e-004,,,,,,,,,,,,,,,,,,,,
1432840944.867,,3.000000e+003,5.500217e+001,5.499622e+001,1,0,3.736802e+000,1.477706e+000,1.477706e+000,6.536192e-001,1.020730e+000,9.576573e-001,1.335704e-001,5.006816e-001,1.859133e-003,1.859133e-003,,,,,,,,,,,,,,,,,,,,
1432840955.333,,3.000000e+003,5.499622e+001,5.499770e+001,1,0,1.733767e-002,5.487228e-001,5.487228e-001,2.917590e-002,1.734804e-001,6.425020e-001,1.229551e-001,2.672596e-001,6.903597e-004,6.903597e-004,,,,,,,,,,,,,,,,,,,,
1432840955.333,,3.000000e+003,5.499622e+001,5.499770e+001,1,0,4.141192e+000,1.226234e+000,1.226234e+000,3.122545e-001,8.509913e-001,9.959275e-001,8.194827e-002,6.206850e-001,1.542750e-003,1.542750e-003,,,,,,,,,,,,,,,,,,,,
1432841075.088,,5.000000e+003,5.500217e+001,5.499770e+001,1,0,2.634906e+000,6.413465e-001,6.413465e-001,-2.212409e-001,2.105224e-001,7.114005e-001,-1.511868e-001,2.805765e-001,8.067955e-004,8.067955e-004,,,,,,,,,,,,,,,,,,,,
1432841085.505,,5.000000e+003,5.500068e+001,5.500217e+001,1,0,5.153402e-001,8.554338e-001,8.554338e-001,6.684500e-002,1.969431e-001,9.719021e-001,1.833133e-001,3.134114e-001,1.076111e-003,1.076111e-003,,,,,,,,,,,,,,,,,,,,
1432841085.505,,5.000000e+003,5.500068e+001,5.500217e+001,1,0,4.826689e+000,9.225745e-001,9.225745e-001,-3.994165e-001,2.640838e-001,1.360345e+000,3.835370e-002,7.018541e-001,1.160572e-003,1.160572e-003,,,,,,,,,,,,,,,,,,,,
1432841204.839,,7.000000e+003,5.500068e+001,5.499622e+001,1,0,1.569098e+000,1.026643e+000,1.026643e+000,-4.145102e-001,5.043226e-002,9.753497e-001,-4.658032e-001,-8.607507e-004,1.291333e-003,1.291333e-003,,,,,,,,,,,,,,,,,,,,
1432841214.756,,7.000000e+003,5.499770e+001,5.499770e+001,1,0,1.476297e+000,6.006042e-001,6.006043e-001,-9.863807e-002,-1.804858e-002,3.010383e-001,-3.982040e-001,-3.176146e-001,7.554530e-004,7.554530e-004,,,,,,,,,,,,,,,,,,,,
1432841214.756,,7.000000e+003,5.499770e+001,5.499770e+001,1,0,4.944010e+000,7.660146e-001,7.660146e-001,-5.940616e-001,1.473617e-001,1.400730e+000,4.065412e-002,7.820774e-001,9.635097e-004,9.635097e-004,,,,,,,,,,,,,,,,,,,,
1432841335.345,,9.000000e+003,5.500217e+001,5.499770e+001,1,0,7.002026e-001,8.803064e-001,8.803064e-001,-9.681808e-002,3.208601e-001,1.168438e+000,1.913137e-001,6.089919e-001,1.107137e-003,1.107137e-003,,,,,,,,,,,,,,,,,,,,
1432841345.309,,9.000000e+003,5.499770e+001,5.499770e+001,1,0,2.591524e+000,5.653554e-001,5.653554e-001,9.382188e-003,9.382188e-003,2.789624e-001,-2.770108e-001,-2.770108e-001,7.110315e-004,7.110315e-004,,,,,,,,,,,,,,,,,,,,
1432841345.309,,9.000000e+003,5.499770e+001,5.499770e+001,1,0,4.317714e+000,1.845454e+000,1.845454e+000,5.523654e-001,1.289481e+000,1.432124e+000,1.390356e-001,8.761512e-001,2.320976e-003,2.320976e-003,,,,,,,,,,,,,,,,,,,,
1432841461.736,,1.000000e+004,5.499920e+001,5.499920e+001,1,0,9.015234e-002,1.120335e+000,1.120335e+000,3.794091e-002,3.203894e-001,1.398509e+000,3.161157e-001,5.985641e-001,1.408929e-003,1.408929e-003,,,,,,,,,,,,,,,,,,,,
1432841461.736,,1.000000e+004,5.499920e+001,5.499920e+001,1,0,3.621089e+000,2.911313e+000,2.911313e+000,1.185565e+000,2.111368e+000,2.069380e+000,3.436314e-001,1.269435e+000,3.661259e-003,3.661259e-003,,,,,,,,,,,,,,,,,,,,
1432841472.012,,1.000000e+004,5.499622e+001,5.500366e+001,1,0,3.308435e+000,1.640065e+000,1.640065e+000,1.030181e+000,1.578538e+000,9.005814e-001,2.906972e-001,8.390548e-001,2.062541e-003,2.062541e-003,,,,,,,,,,,,,,,,,,,,
1432841642.594,,2.000000e+004,5.499472e+001,5.499622e+001,1,0,1.308973e-001,5.912961e-001,5.912961e-001,8.931895e-002,2.761879e-001,7.674170e-001,2.654398e-001,4.523087e-001,1.486339e-003,1.486339e-003,,,,,,,,,,,,,,,,,,,,
1432841642.594,,2.000000e+004,5.499472e+001,5.499622e+001,1,0,4.452187e+000,1.172369e+000,1.172369e+000,8.103542e-002,8.572603e-001,1.189809e+000,9.847586e-002,8.747007e-001,2.946979e-003,2.946979e-003,,,,,,,,,,,,,,,,,,,,
1432841652.511,,2.000000e+004,5.499472e+001,5.500515e+001,1,0,2.189595e+000,2.934355e-001,2.934355e-001,-6.928924e-001,-2.448845e-001,4.239162e-001,-5.624117e-001,-1.144038e-001,7.376078e-004,7.376078e-004,,,,,,,,,,,,,,,,,,,,
1432841809.348,,3.000000e+004,5.499472e+001,5.499920e+001,1,0,8.670943e-001,6.396679e-001,6.396680e-001,9.047523e-002,2.386313e-001,6.397667e-001,9.057394e-002,2.387300e-001,1.606973e-003,1.606973e-003,,,,,,,,,,,,,,,,,,,,
1432841809.348,,3.000000e+004,5.499472e+001,5.499920e+001,1,0,4.966309e+000,3.999451e-001,3.999451e-001,-9.085474e-001,-1.091629e-003,1.363818e+000,5.532555e-002,9.627813e-001,1.004742e-003,1.004742e-003,,,,,,,,,,,,,,,,,,,,
1432841819.266,,3.000000e+004,5.500068e+001,5.500068e+001,1,0,1.200030e+000,7.803583e-001,7.803583e-001,-3.097457e-001,1.691928e-001,8.462746e-001,-2.438294e-001,2.351091e-001,1.960416e-003,1.960416e-003,,,,,,,,,,,,,,,,,,,,
1432841978.358,,4.000000e+004,5.499920e+001,5.500515e+001,1,0,1.915509e+000,1.116977e-001,1.116977e-001,-5.201550e-001,-4.574234e-001,-3.949944e-001,-1.026847e+000,-9.641156e-001,2.804397e-004,2.804397e-004,,,,,,,,,,,,,,,,,,,,
1432841978.358,,4.000000e+004,5.499920e+001,5.500515e+001,1,0,4.767346e+000,9.546189e-001,9.546190e-001,-5.345662e-001,3.854979e-001,1.581614e+000,9.242851e-002,1.012493e+000,2.396763e-003,2.396763e-003,,,,,,,,,,,,,,,,,,,,
1432841988.273,,4.000000e+004,5.499920e+001,5.499920e+001,1,0,4.089913e-001,8.386486e-001,8.386486e-001,-3.757953e-002,4.050724e-001,1.314087e+000,4.378588e-001,8.805107e-001,2.105596e-003,2.105596e-003,,,,,,,,,,,,,,,,,,,,
1432841988.273,,4.000000e+004,5.499920e+001,5.499920e+001,1,0,3.026473e+000,1.698202e+000,1.698202e+000,-4.225084e-002,1.264626e+000,1.875930e+000,1.354771e-001,1.442354e+000,4.263679e-003,4.263679e-003,,,,,,,,,,,,,,,,,,,,
1432842155.063,,5.000000e+004,5.500068e+001,5.499920e+001,1,0,3.940501e+000,3.574175e+000,3.574175e+000,2.030513e+000,2.960143e+000,1.943319e+000,3.996565e-001,1.329287e+000,8.968337e-003,8.968337e-003,,,,,,,,,,,,,,,,,,,,
1432842165.087,,5.000000e+004,5.499920e+001,5.499622e+001,1,0,8.644292e-003,9.923094e-001,9.923093e-001,1.190500e-001,4.986498e-001,1.308642e+000,4.353831e-001,8.149829e-001,2.489907e-003,2.489907e-003,,,,,,,,,,,,,,,,,,,,
1432842165.087,,5.000000e+004,5.499920e+001,5.499622e+001,1,0,3.975413e+000,3.402356e+000,3.402356e+000,1.556372e+000,2.908697e+000,2.226835e+000,3.808517e-001,1.733176e+000,8.537207e-003,8.537207e-003,,,,,,,,,,,,,,,,,,,,
1432842330.920,,6.000000e+004,5.500217e+001,5.499472e+001,1,0,2.861380e+000,8.365124e-001,8.365123e-001,4.482364e-002,4.912857e-001,7.586555e-001,-3.303320e-002,4.134288e-001,4.195455e-003,4.195455e-003,,,,,,,,,,,,,,,,,,,,
1432842340.885,,6.000000e+004,5.499472e+001,5.499622e+001,1,0,3.633993e-001,4.577776e-001,4.577776e-001,1.061337e-001,2.490238e-001,6.396998e-001,2.880558e-001,4.309459e-001,2.295944e-003,2.295944e-003,,,,,,,,,,,,,,,,,,,,
1432842340.885,,6.000000e+004,5.499472e+001,5.499622e+001,1,0,4.716599e+000,5.279702e-001,5.279702e-001,-3.562644e-001,3.192164e-001,9.493529e-001,6.511828e-002,7.405990e-001,2.647989e-003,2.647989e-003,,,,,,,,,,,,,,,,,,,,
1432842499.115,,7.000000e+004,5.500068e+001,5.499920e+001,1,0,1.768437e+000,7.919553e-002,7.919553e-002,-6.380890e-001,-2.296756e-001,3.555670e-002,-6.817278e-001,-2.733144e-001,3.969612e-004,3.969612e-004,,,,,,,,,,,,,,,,,,,,
1432842509.783,,7.000000e+004,5.499920e+001,5.500068e+001,1,0,1.264523e+000,2.435377e-001,2.435377e-001,-3.110456e-002,5.264853e-002,9.049908e-003,-2.655924e-001,-1.818393e-001,1.220713e-003,1.220713e-003,,,,,,,,,,,,,,,,,,,,
1432842509.783,,7.000000e+004,5.499920e+001,5.500068e+001,1,0,4.985541e+000,9.567553e-002,9.567553e-002,-7.512795e-001,-9.521365e-002,8.930904e-001,4.613528e-002,7.022012e-001,4.795658e-004,4.795658e-004,,,,,,,,,,,,,,,,,,,,
1432842509.783,,7.000000e+004,5.499920e+001,5.500068e+001,1,0,2.811788e+000,6.080813e-001,6.080813e-001,-4.622154e-001,4.171921e-001,9.888268e-001,-8.146986e-002,7.979376e-001,3.047958e-003,3.047958e-003,,,,,,,,,,,,,,,,,,,,