File: data/A269/A269_GdN_MH_10K_150528.rso.raw
[Header]
TITLE,MPMS RSO Measurement
BYAPP,MPMS Measurement,2.1,Raw with ABS
FILEOPENTIME, 1432793302.936000 5/28/2015, 6:08:22 PM

INFO, APPNAME, MPMS MultiVu Application, Revision 1.61,  Build 082

INFO, NAME, A269
INFO, WEIGHT, 22.300
INFO, AREA, 1.000
INFO, LENGTH, 1.000
INFO, SHAPE, 1
INFO, COMMENT, m = 0.0223g
INFO, SEQUENCE FILE: 7T_hysteresis_sweep.seq


INFO, BACKGROUND DATA FILE:, None


STARTUPAXIS,X,8,LINEAR,AUTO,0.000000,0.000000
STARTUPAXIS,Y1,9,LINEAR,AUTO,0.000000,0.000000


STARTUPGROUP,Longitudinal
FIELDGROUP,Longitudinal,1,2,3,4,5,6,7,8,9,10,11,12,13,14,15,16,17,18,19,20,21,22
FIELDGROUP,Transverse,1,2,3,4,5,6,7,8,23,24,25,26,27,28,29,30,31,32,33,34,35,36

PLOT_APPEARANCE,ALL,HORZ_GRID_ON,VERT_GRID_ON,MARKERS_ONLY

[Data]
Time,Comment,Field (Oe),Start Temperature (K),End Temperature (K),Scan,Rejected,Position (cm),Long Voltage,Long Average Voltage,Long Detrended Voltage,Long Demeaned Voltage,Long Reg Fit,Long Detrended Fit,Long Demeaned Fit,Long Scaled Response,Long Avg. Scaled Response,Long Background Response,Long Response [w/ABS],Long Detrended Resp. [w/ABS],Long Fit [w/ABS],Long Detrended Fit [w/ABS],Trans Voltage,Trans Average Voltage,Trans Detrended Voltage,Trans Demeaned Voltage,Trans Reg Fit,Trans Detrended Fit,Trans Demeaned Fit,Trans Scaled Response,Trans Avg. Scaled Response,Trans Background Response,Trans Response [w/ABS],Trans Detrended Resp. [w/ABS],Trans Adjusted Fit,Trans Detrended Fit [w/ABS],
1432793302.926,,7.000000e+004,1.001477e+001,1.000919e+001,1,0,2.591176e+000,1.141392e-001,1.141392e-001,1.038761e-002,1.038761e-002,-1.513623e-001,-2.551140e-001,-2.551140e-001,1.430284e-003,1.430284e-003,,,,,,,,,,,,,,,,,,,,
1432793302.926,,7.000000e+004,1.001477e+001,1.000919e+001,1,0,4.317183e+000,1.142460e+000,1.142460e+000,5.106446e-001,1.038709e+000,7.625444e-001,1.307286e-001,6.587928e-001,1.431623e-002,1.431623e-002,,,,,,,,,,,,,,,,,,,,
1432793312.890,,7.000000e+004,1.000971e+001,1.001129e+001,1,0,9.020734e-002,4.109317e-001,4.109317e-001,3.630454e-002,2.668496e-001,6.576829e-001,2.830557e-001,5.136008e-001,5.149405e-003,5.149405e-003,,,,,,,,,,,,,,,,,,,,
1432793312.890,,7.000000e+004,1.000971e+001,1.001129e+001,1,0,3.621221e+000,1.952422e+000,1.952422e+000,1.052664e+000,1.808339e+000,1.202979e+000,3.032219e-001,1.058897e+000,2.446589e-002,2.446589e-002,,,,,,,,,,,,,,,,,,,,
1432793469.369,,6.000000e+004,1.000003e+001,1.000484e+001,1,0,3.308167e+000,1.406903e+000,1.406903e+000,8.760008e-001,1.301876e+000,7.805430e-001,2.496405e-001,6.755161e-001,1.764050e-002,1.764050e-002,,,,,,,,,,,,,,,,,,,,
1432793479.584,,6.000000e+004,1.000377e+001,1.000538e+001,1,0,1.312050e-001,3.122044e-001,3.122044e-001,9.135263e-002,2.452938e-001,4.975060e-001,2.766542e-001,4.305954e-001,3.914585e-003,3.914585e-003,,,,,,,,,,,,,,,,,,,,
1432793479.584,,6.000000e+004,1.000377e+001,1.000538e+001,1,0,4.451342e+000,7.792901e-001,7.792901e-001,7.293159e-002,7.123796e-001,8.050706e-001,9.871209e-002,7.381601e-001,9.771156e-003,9.771156e-003,,,,,,,,,,,,,,,,,,,,
1432793640.549,,5.000000e+004,9.998920e+000,1.000381e+001,1,0,2.188902e+000,-1.788385e-001,-1.788385e-001,-6.632395e-001,-3.052022e-001,-5.015128e-002,-5.345523e-001,-1.765150e-001,-2.243711e-003,-2.243711e-003,,,,,,,,,,,,,,,,,,,,
1432793650.622,,5.000000e+004,1.000435e+001,1.000327e+001,1,0,8.672466e-001,1.312296e-001,1.312296e-001,6.234709e-002,1.465829e-001,1.221496e-001,5.326711e-002,1.375030e-001,1.646409e-003,1.646409e-003,,,,,,,,,,,,,,,,,,,,
1432793650.622,,5.000000e+004,1.000435e+001,1.000327e+001,1,0,4.966403e+000,-1.756340e-001,-1.756340e-001,-6.762253e-001,-1.602807e-001,5.399135e-001,3.932224e-002,5.552669e-001,-2.203508e-003,-2.203508e-003,,,,,,,,,,,,,,,,,,,,
1432793810.103,,4.000000e+004,1.000057e+001,1.000490e+001,1,0,1.199179e+000,7.232887e-002,7.232887e-002,-2.141905e-001,4.702076e-002,1.071292e-001,-1.793902e-001,8.182109e-002,9.079810e-004,9.079810e-004,,,,,,,,,,,,,,,,,,,,
1432793820.019,,4.000000e+004,1.000490e+001,1.000327e+001,1,0,1.914927e+000,-1.908933e-001,-1.908933e-001,-2.984268e-001,-2.679067e-001,-4.708318e-001,-5.783653e-001,-5.478451e-001,-2.396380e-003,-2.396380e-003,,,,,,,,,,,,,,,,,,,,
1432793820.019,,4.000000e+004,1.000490e+001,1.000327e+001,1,0,4.766744e+000,2.096622e-001,2.096622e-001,-3.149795e-001,1.326488e-001,5.749772e-001,5.033553e-002,4.979638e-001,2.631996e-003,2.631996e-003,,,,,,,,,,,,,,,,,,,,
1432793977.314,,3.000000e+004,1.000003e+001,1.000544e+001,1,0,4.099672e-001,1.695303e-001,1.695303e-001,-2.181414e-002,1.662773e-001,4.123224e-001,2.209780e-001,4.090694e-001,2.129470e-003,2.129470e-003,,,,,,,,,,,,,,,,,,,,
1432793977.314,,3.000000e+004,1.000003e+001,1.000544e+001,1,0,3.027059e+000,5.603198e-001,5.603198e-001,1.749248e-003,5.570668e-001,6.390410e-001,8.047041e-002,6.357880e-001,7.038176e-003,7.038176e-003,,,,,,,,,,,,,,,,,,,,
1432793987.137,,3.000000e+004,1.000436e+001,1.000545e+001,1,0,3.940806e+000,1.259652e+000,1.259651e+000,9.022633e-001,1.253568e+000,5.293915e-001,1.720034e-001,5.233082e-001,1.582248e-002,1.582248e-002,,,,,,,,,,,,,,,,,,,,
1432794142.569,,2.000000e+004,1.000057e+001,1.000491e+001,1,0,8.862450e-003,1.641896e-001,1.641896e-001,4.118951e-002,1.669894e-001,2.978741e-001,1.748740e-001,3.006739e-001,2.063614e-003,2.063614e-003,,,,,,,,,,,,,,,,,,,,
1432794142.569,,2.000000e+004,1.000057e+001,1.000491e+001,1,0,3.975492e+000,1.057619e+000,1.057619e+000,6.122567e-001,1.060419e+000,5.908876e-001,1.455253e-001,5.936874e-001,1.329267e-002,1.329267e-002,,,,,,,,,,,,,,,,,,,,
1432794152.591,,2.000000e+004,1.000491e+001,1.000383e+001,1,0,2.861175e+000,3.588977e-001,3.588977e-001,4.801529e-002,3.164340e-001,2.986804e-001,-1.220197e-002,2.562168e-001,4.510799e-003,4.510799e-003,,,,,,,,,,,,,,,,,,,,
1432794306.711,,1.000000e+004,1.000057e+001,1.000490e+001,1,0,3.640089e-001,1.266518e-001,1.266518e-001,5.672092e-002,1.276699e-001,2.378902e-001,1.679593e-001,2.389083e-001,1.592769e-003,1.592769e-003,,,,,,,,,,,,,,,,,,,,
1432794306.711,,1.000000e+004,1.000057e+001,1.000490e+001,1,0,4.717749e+000,1.113926e-001,1.113926e-001,-2.229847e-001,1.124107e-001,3.712106e-001,3.683333e-002,3.722287e-001,1.400870e-003,1.400870e-003,,,,,,,,,,,,,,,,,,,,
1432794316.629,,1.000000e+004,1.000490e+001,1.000436e+001,1,0,1.767627e+000,-1.330607e-001,-1.330607e-001,-3.477643e-001,-1.591668e-001,-1.577391e-001,-3.724427e-001,-1.838452e-001,-1.673367e-003,-1.673367e-003,,,,,,,,,,,,,,,,,,,,
1432794432.913,,9.000000e+003,1.000003e+001,1.000382e+001,1,0,1.265330e+000,5.188147e-003,5.188147e-003,-1.609134e-002,2.208065e-002,-1.286583e-001,-1.499378e-001,-1.117658e-001,6.524986e-005,6.524986e-005,,,,,,,,,,,,,,,,,,,,
1432794432.913,,9.000000e+003,1.000003e+001,1.000382e+001,1,0,4.984963e+000,-1.231422e-001,-1.231422e-001,-4.052636e-001,-1.062497e-001,3.053406e-001,2.321915e-002,3.222331e-001,-1.548725e-003,-1.548725e-003,,,,,,,,,,,,,,,,,,,,
1432794442.937,,9.000000e+003,1.000383e+001,1.000436e+001,1,0,8.602817e-001,1.115452e-001,1.115452e-001,-7.118241e-002,8.105423e-002,2.184401e-001,3.571252e-002,1.879492e-001,1.402872e-003,1.402872e-003,,,,,,,,,,,,,,,,,,,,
1432794563.226,,7.000000e+003,9.999475e+000,1.000545e+001,1,0,2.366908e+000,-1.345866e-001,-1.345866e-001,-1.334146e-001,-1.272891e-001,-2.340283e-001,-2.328563e-001,-2.267309e-001,-1.692860e-003,-1.692860e-003,,,,,,,,,,,,,,,,,,,,
1432794563.226,,7.000000e+003,9.999475e+000,1.000545e+001,1,0,4.486488e+000,3.314310e-001,3.314310e-001,8.146005e-002,3.387285e-001,2.998807e-001,4.990976e-002,3.071782e-001,4.168811e-003,4.168811e-003,,,,,,,,,,,,,,,,,,,,
1432794573.299,,7.000000e+003,1.000382e+001,1.000328e+001,1,0,1.772046e-001,1.628163e-001,1.628162e-001,6.915953e-003,1.235306e-001,3.082673e-001,1.523670e-001,2.689816e-001,2.047938e-003,2.047938e-003,,,,,,,,,,,,,,,,,,,,
1432794573.299,,7.000000e+003,1.000382e+001,1.000328e+001,1,0,3.431531e+000,8.259834e-001,8.259835e-001,4.184411e-001,7.866978e-001,5.589286e-001,1.513863e-001,5.196429e-001,1.038940e-002,1.038940e-002,,,,,,,,,,,,,,,,,,,,
1432794692.728,,5.000000e+003,9.999475e+000,1.000328e+001,1,0,3.525338e+000,8.095035e-001,8.095034e-001,5.894791e-001,7.675313e-001,3.634030e-001,1.433787e-001,3.214309e-001,1.018332e-002,1.018332e-002,,,,,,,,,,,,,,,,,,,,
1432794702.753,,5.000000e+003,1.000436e+001,1.000328e+001,1,0,5.793392e-002,1.019318e-001,1.019318e-001,3.934497e-002,1.177033e-001,1.914848e-001,1.288979e-001,2.072562e-001,1.282273e-003,1.282273e-003,,,,,,,,,,,,,,,,,,,,
1432794702.753,,5.000000e+003,1.000436e+001,1.000328e+001,1,0,4.298792e+000,4.593036e-001,4.593036e-001,1.672389e-001,4.750750e-001,3.546303e-001,6.256567e-002,3.704017e-001,5.777908e-003,5.777908e-003,,,,,,,,,,,,,,,,,,,,
1432794822.139,,3.000000e+003,1.000111e+001,1.000598e+001,1,0,2.410325e+000,-1.031526e-001,-1.031526e-001,-2.428519e-001,-8.693371e-002,-2.896979e-002,-1.686692e-001,-1.275093e-002,-1.297784e-003,-1.297784e-003,,,,,,,,,,,,,,,,,,,,
1432794832.307,,3.000000e+003,1.000436e+001,1.000436e+001,1,0,6.840627e-001,9.811701e-002,9.811701e-002,3.690333e-002,8.201830e-002,1.356912e-001,7.447754e-002,1.195925e-001,1.234431e-003,1.234431e-003,,,,,,,,,,,,,,,,,,,,
1432794832.307,,3.000000e+003,1.000436e+001,1.000436e+001,1,0,4.910190e+000,-1.709037e-002,-1.709037e-002,-2.838278e-001,-3.318907e-002,2.862588e-001,1.952131e-002,2.701601e-001,-2.150175e-004,-2.150175e-004,,,,,,,,,,,,,,,,,,,,
1432794944.889,,1.000000e+003,1.000111e+001,1.000598e+001,1,0,1.380189e+000,-4.882962e-003,-4.882962e-003,-9.889056e-002,-1.237577e-002,-1.222672e-002,-1.062343e-001,-1.971954e-002,-6.144089e-005,-6.144089e-005,,,,,,,,,,,,,,,,,,,,
1432794964.076,,1.000000e+003,1.000598e+001,1.000436e+001,1,0,1.693299e+000,-1.220740e-001,-1.220740e-001,-1.706554e-001,-1.379374e-001,-3.922233e-001,-4.408047e-001,-4.080867e-001,-6.144089e-004,-6.144089e-004,,,,,,,,,,,,,,,,,,,,
1432794964.076,,1.000000e+003,1.000598e+001,1.000436e+001,1,0,4.870407e+000,-1.113926e-002,-1.113926e-002,-3.950799e-001,-2.700264e-002,4.199266e-001,3.598602e-002,4.040633e-001,-5.606481e-005,-5.606481e-005,,,,,,,,,,,,,,,,,,,,
1432795074.921,,5.000000e+002,1.000057e+001,1.000598e+001,1,0,5.488380e-001,1.930296e-001,1.930296e-001,-3.172627e-002,1.066537e-001,3.637872e-001,1.390313e-001,2.774113e-001,9.715629e-004,9.715629e-004,,,,,,,,,,,,,,,,,,,,
1432795074.921,,5.000000e+002,1.000057e+001,1.000598e+001,1,0,2.812034e+000,2.487258e-001,2.487258e-001,-2.339199e-001,1.623500e-001,4.491158e-001,-3.352999e-002,3.627399e-001,1.251895e-003,1.251895e-003,,,,,,,,,,,,,,,,,,,,
1432795085.590,,5.000000e+002,1.000544e+001,1.000706e+001,1,0,4.134261e+000,6.941435e-001,6.941435e-001,4.868145e-001,7.361690e-001,3.033793e-001,9.605039e-002,3.454049e-001,3.493786e-003,3.493786e-003,,,,,,,,,,,,,,,,,,,,
1432795190.125,,4.000000e+002,1.000057e+001,1.000598e+001,1,0,3.569836e-002,1.495407e-001,1.495407e-001,2.380865e-002,1.259112e-001,2.638552e-001,1.381232e-001,2.402257e-001,7.526777e-004,7.526777e-004,,,,,,,,,,,,,,,,,,,,
1432795190.125,,4.000000e+002,1.000057e+001,1.000598e+001,1,0,3.802376e+000,9.291360e-001,9.291360e-001,5.571567e-001,9.055066e-001,5.094386e-001,1.374593e-001,4.858091e-001,4.676586e-003,4.676586e-003,,,,,,,,,,,,,,,,,,,,
1432795200.149,,4.000000e+002,1.000598e+001,1.000706e+001,1,0,3.086605e+000,4.622028e-001,4.622028e-001,2.544324e-001,4.698978e-001,2.826526e-001,7.488219e-002,2.903475e-001,2.326388e-003,2.326388e-003,,,,,,,,,,,,,,,,,,,,
1432795304.182,,3.000000e+002,9.998920e+000,1.000327e+001,1,0,2.348833e-001,2.160711e-001,2.160711e-001,4.579879e-002,1.145031e-001,3.130019e-001,1.427296e-001,2.114340e-001,1.087549e-003,1.087549e-003,,,,,,,,,,,,,,,,,,,,
1432795304.182,,3.000000e+002,9.998920e+000,1.000327e+001,1,0,4.590395e+000,3.207496e-001,3.207495e-001,-8.426262e-002,2.191816e-001,4.435274e-001,3.851523e-002,3.419595e-001,1.614426e-003,1.614426e-003,,,,,,,,,,,,,,,,,,,,
1432795314.267,,3.000000e+002,1.000436e+001,1.000382e+001,1,0,1.974113e+000,-9.643849e-002,-9.643849e-002,-3.470430e-001,-1.799368e-001,-7.599182e-002,-3.265963e-001,-1.594901e-001,-4.854031e-004,-4.854031e-004,,,,,,,,,,,,,,,,,,,,
1432795418.775,,2.000000e+002,1.000003e+001,1.000544e+001,1,0,1.061359e+000,5.813776e-002,5.813776e-002,1.398659e-002,4.774855e-002,4.234970e-003,-3.991619e-002,-6.154238e-003,2.926261e-004,2.926261e-004,,,,,,,,,,,,,,,,,,,,
1432795418.775,,2.000000e+002,1.000003e+001,1.000544e+001,1,0,4.992634e+000,-8.590961e-002,-8.590961e-002,-3.278094e-001,-9.629881e-002,2.598562e-001,1.795643e-002,2.494670e-001,-4.324108e-004,-4.324108e-004,,,,,,,,,,,,,,,,,,,,
1432795429.191,,2.000000e+002,1.000436e+001,1.000436e+001,1,0,1.026548e+000,4.837184e-002,4.837184e-002,-7.866136e-002,4.934237e-002,9.964325e-002,-2.738995e-002,1.006138e-001,2.434711e-004,2.434711e-004,,,,,,,,,,,,,,,,,,,,
1432795526.772,,1.000000e+002,9.999475e+000,1.000544e+001,1,0,2.139876e+000,-1.765496e-001,-1.765496e-001,-1.424848e-001,-1.353611e-001,-2.675096e-001,-2.334449e-001,-2.263212e-001,-8.886363e-004,-8.886363e-004,,,,,,,,,,,,,,,,,,,,
1432795526.772,,1.000000e+002,9.999475e+000,1.000544e+001,1,0,4.637474e+000,5.874813e-002,5.874813e-002,-5.322243e-002,9.993659e-002,1.400705e-001,2.809993e-002,1.812589e-001,2.957001e-004,2.957001e-004,,,,,,,,,,,,,,,,,,,,
1432795537.189,,1.000000e+002,1.000490e+001,1.000490e+001,1,0,2.866024e-001,1.289407e-001,1.289407e-001,-3.200451e-003,7.667118e-002,2.453670e-001,1.132258e-001,1.930974e-001,6.490040e-004,6.490040e-004,,,,,,,,,,,,,,,,,,,,
1432795537.189,,1.000000e+002,1.000490e+001,1.000490e+001,1,0,3.234020e+000,4.567095e-001,4.567095e-001,1.608315e-001,4.044400e-001,3.810205e-001,8.514252e-002,3.287510e-001,2.298780e-003,2.298780e-003,,,,,,,,,,,,,,,,,,,,
1432795641.222,,0.000000e+000,1.000436e+001,1.000814e+001,1,0,3.736409e+000,5.481125e-001,5.481125e-001,4.222832e-001,5.599422e-001,2.140162e-001,8.818695e-002,2.258460e-001,2.758860e-003,2.758860e-003,,,,,,,,,,,,,,,,,,,,
1432795651.295,,0.000000e+000,1.000761e+001,1.000598e+001,1,0,1.726222e-002,7.156590e-002,7.156590e-002,2.307550e-002,7.619272e-002,1.307251e-001,8.223467e-002,1.353519e-001,3.602186e-004,3.602186e-004,,,,,,,,,,,,,,,,,,,,
1432795651.295,,0.000000e+000,1.000761e+001,1.000598e+001,1,0,4.141394e+000,3.962829e-001,3.962829e-001,2.026054e-001,4.009097e-001,2.472336e-001,5.355609e-002,2.518604e-001,1.994643e-003,1.994643e-003,,,,,,,,,,,,,,,,,,,,
1432795763.738,,-1.000000e+002,1.000544e+001,1.000652e+001,1,0,2.635352e+000,1.207007e-001,1.207007e-001,-2.967014e-001,7.518633e-002,2.107466e-001,-2.066555e-001,1.652322e-001,1.518823e-004,1.518823e-004,,,,,,,,,,,,,,,,,,,,
1432795774.453,,-1.000000e+002,1.000544e+001,1.000382e+001,1,0,5.151964e-001,1.225318e-001,1.225318e-001,9.546447e-002,2.114297e-001,2.818972e-001,2.548298e-001,3.707951e-001,1.541865e-004,1.541865e-004,,,,,,,,,,,,,,,,,,,,
1432795774.453,,-1.000000e+002,1.000544e+001,1.000382e+001,1,0,4.824626e+000,-5.447554e-002,-5.447554e-002,-5.570006e-001,3.442240e-002,5.558357e-001,5.331069e-002,6.447337e-001,-6.854865e-005,-6.854865e-005,,,,,,,,,,,,,,,,,,,,
1432795878.880,,-2.000000e+002,1.000111e+001,1.000706e+001,1,0,1.569032e+000,4.084902e-001,4.084902e-001,-2.976738e-001,-8.134311e-002,3.648250e-001,-3.413391e-001,-1.250084e-001,5.140158e-004,5.140158e-004,,,,,,,,,,,,,,,,,,,,
1432795888.703,,-2.000000e+002,1.000652e+001,1.000598e+001,1,0,1.476258e+000,-8.392590e-003,-8.392590e-003,-7.879613e-002,-4.150235e-002,-2.213396e-001,-2.917431e-001,-2.544493e-001,-1.056065e-005,-1.056065e-005,,,,,,,,,,,,,,,,,,,,
1432795888.703,,-2.000000e+002,1.000652e+001,1.000598e+001,1,0,4.943913e+000,-4.333628e-002,-4.333628e-002,-4.195489e-001,-7.644604e-002,4.049196e-001,2.870697e-002,3.718098e-001,-5.453138e-005,-5.453138e-005,,,,,,,,,,,,,,,,,,,,
1432796000.981,,-3.000000e+002,1.000598e+001,1.000652e+001,1,0,7.015810e-001,4.390088e-001,4.390088e-001,-5.460525e-002,9.725252e-002,6.030734e-001,1.094593e-001,2.613171e-001,2.209660e-004,2.209660e-004,,,,,,,,,,,,,,,,,,,,
1432796011.148,,-3.000000e+002,1.000598e+001,1.000436e+001,1,0,2.591484e+000,-2.009644e-001,-2.009644e-001,4.054666e-003,4.054666e-003,-3.599379e-001,-1.549189e-001,-1.549189e-001,-1.011513e-004,-1.011513e-004,,,,,,,,,,,,,,,,,,,,
1432796011.148,,-3.000000e+002,1.000598e+001,1.000436e+001,1,0,4.318093e+000,3.767510e-001,3.767510e-001,3.107370e-001,5.817701e-001,1.448051e-001,7.879116e-002,3.498242e-001,1.896298e-004,1.896298e-004,,,,,,,,,,,,,,,,,,,,
1432796114.979,,-4.000000e+002,1.000057e+001,1.000652e+001,1,0,9.242423e-002,-2.873318e-001,-2.873318e-001,-7.618749e-003,-1.376111e-001,-4.115116e-001,-1.317986e-001,-2.617909e-001,-1.446216e-004,-1.446216e-004,,,,,,,,,,,,,,,,,,,,
1432796114.979,,-4.000000e+002,1.000057e+001,1.000652e+001,1,0,3.620567e+000,-1.072268e+000,-1.072268e+000,-4.964613e-001,-9.225472e-001,-7.075279e-001,-1.317213e-001,-5.578072e-001,-5.397006e-004,-5.397006e-004,,,,,,,,,,,,,,,,,,,,
1432796124.896,,-4.000000e+002,1.000652e+001,1.000598e+001,1,0,3.308226e+000,-1.760918e-001,-1.760918e-001,-4.406624e-001,-7.328364e-001,1.317393e-001,-1.328312e-001,-4.250053e-001,-8.863163e-005,-8.863163e-005,,,,,,,,,,,,,,,,,,,,
1432796229.727,,-5.000000e+002,9.999475e+000,1.000436e+001,1,0,1.308369e-001,-1.361126e-001,-1.361126e-001,-1.363046e-001,-4.595752e-001,-4.504375e-001,-4.506295e-001,-7.739000e-001,-6.850862e-005,-6.850862e-005,,,,,,,,,,,,,,,,,,,,
1432796229.727,,-5.000000e+002,9.999475e+000,1.000436e+001,1,0,4.449946e+000,-1.121250e+000,-1.121250e+000,-1.018964e-001,-1.444713e+000,-1.180348e+000,-1.609943e-001,-1.503811e+000,-5.643513e-004,-5.643513e-004,,,,,,,,,,,,,,,,,,,,
1432796239.691,,-5.000000e+002,1.000436e+001,1.000382e+001,1,0,2.189218e+000,3.767510e-001,3.767510e-001,1.173615e+000,4.487163e-001,1.367436e-001,9.336081e-001,2.087089e-001,1.896276e-004,1.896276e-004,,,,,,,,,,,,,,,,,,,,
1432796365.263,,-1.000000e+003,1.000490e+001,1.000436e+001,1,0,8.668283e-001,-6.485184e-002,-6.485184e-002,-3.802297e-002,-8.926024e-002,-6.102674e-002,-3.419787e-002,-8.543514e-002,-3.264047e-004,-3.264047e-004,,,,,,,,,,,,,,,,,,,,
1432796365.263,,-1.000000e+003,1.000490e+001,1.000436e+001,1,0,4.966959e+000,1.350444e-001,1.350444e-001,4.244643e-001,1.106360e-001,-3.139742e-001,-2.455429e-002,-3.383826e-001,6.796898e-004,6.796898e-004,,,,,,,,,,,,,,,,,,,,
1432796375.431,,-1.000000e+003,1.000328e+001,1.000111e+001,1,0,1.200310e+000,-4.300058e-001,-4.300058e-001,1.439863e-001,-1.292259e-001,-4.528789e-001,1.211132e-001,-1.520990e-001,-2.164255e-003,-2.164255e-003,,,,,,,,,,,,,,,,,,,,
1432796489.262,,-3.000000e+003,1.000003e+001,1.000490e+001,1,0,1.915582e+000,-3.530992e-001,-3.530992e-001,3.692152e-001,3.162752e-001,-1.612421e-002,7.061902e-001,6.532502e-001,-1.776966e-003,-1.776966e-003,,,,,,,,,,,,,,,,,,,,
1432796489.262,,-3.000000e+003,1.000003e+001,1.000490e+001,1,0,4.767087e+000,-1.064791e+000,-1.064791e+000,3.810372e-001,-3.954165e-001,-1.507568e+000,-6.174012e-002,-8.381938e-001,-5.358543e-003,-5.358543e-003,,,,,,,,,,,,,,,,,,,,
1432796499.180,,-3.000000e+003,1.000436e+001,1.000328e+001,1,0,4.099861e-001,-3.584399e-001,-3.584399e-001,3.039181e-002,-2.386292e-001,-6.855305e-001,-2.966988e-001,-5.657198e-001,-1.803843e-003,-1.803843e-003,,,,,,,,,,,,,,,,,,,,
1432796499.180,,-3.000000e+003,1.000436e+001,1.000328e+001,1,0,3.026903e+000,-9.157079e-001,-9.157079e-001,-1.644678e-003,-7.958972e-001,-1.021352e+000,-1.072891e-001,-9.015416e-001,-4.608286e-003,-4.608286e-003,,,,,,,,,,,,,,,,,,,,
1432796618.796,,-5.000000e+003,1.000111e+001,1.000652e+001,1,0,3.939745e+000,-2.135533e+000,-2.135533e+000,-1.415837e+000,-2.023721e+000,-9.892437e-001,-2.695485e-001,-8.774319e-001,-1.074576e-002,-1.074576e-002,,,,,,,,,,,,,,,,,,,,
1432796628.761,,-5.000000e+003,1.000598e+001,1.000598e+001,1,0,8.830100e-003,-4.846339e-001,-4.846339e-001,-7.182524e-002,-3.191467e-001,-7.210494e-001,-3.082407e-001,-5.555623e-001,-2.438623e-003,-2.438623e-003,,,,,,,,,,,,,,,,,,,,
1432796628.761,,-5.000000e+003,1.000598e+001,1.000598e+001,1,0,3.976187e+000,-2.125614e+000,-2.125614e+000,-1.079044e+000,-1.960127e+000,-1.303471e+000,-2.569008e-001,-1.137984e+000,-1.069585e-002,-1.069585e-002,,,,,,,,,,,,,,,,,,,,
1432796748.190,,-7.000000e+003,1.000111e+001,1.000544e+001,1,0,2.860826e+000,-8.163701e-001,-8.163701e-001,-9.025860e-002,-6.793025e-001,-7.009213e-001,2.519023e-002,-5.638536e-001,-4.107392e-003,-4.107392e-003,,,,,,,,,,,,,,,,,,,,
1432796758.216,,-7.000000e+003,1.000544e+001,1.000653e+001,1,0,3.639264e-001,-5.320902e-001,-5.320902e-001,-1.305670e-001,-3.208738e-001,-7.871526e-001,-3.856294e-001,-5.759362e-001,-2.677098e-003,-2.677098e-003,,,,,,,,,,,,,,,,,,,,
1432796758.216,,-7.000000e+003,1.000544e+001,1.000653e+001,1,0,4.717797e+000,-5.986205e-001,-5.986205e-001,5.122278e-001,-3.874041e-001,-1.195501e+000,-8.465258e-002,-9.842846e-001,-3.011831e-003,-3.011831e-003,,,,,,,,,,,,,,,,,,,,
1432796872.547,,-9.000000e+003,1.000057e+001,1.000544e+001,1,0,1.767548e+000,4.058962e-002,4.058962e-002,8.492444e-001,3.110582e-001,9.980271e-002,9.084575e-001,3.702713e-001,2.041937e-004,2.041937e-004,,,,,,,,,,,,,,,,,,,,
1432796882.464,,-9.000000e+003,1.000544e+001,1.000599e+001,1,0,1.265230e+000,-3.308206e-001,-3.308206e-001,4.008773e-002,-7.076851e-002,3.697253e-003,3.746056e-001,2.637494e-001,-1.664255e-003,-1.664255e-003,,,,,,,,,,,,,,,,,,,,
1432796882.464,,-9.000000e+003,1.000544e+001,1.000599e+001,1,0,4.985308e+000,-1.167333e-001,-1.167333e-001,1.011693e+000,1.433188e-001,-1.186582e+000,-5.815622e-002,-9.265301e-001,-5.872487e-004,-5.872487e-004,,,,,,,,,,,,,,,,,,,,
1432796998.803,,-1.000000e+004,1.000057e+001,1.000653e+001,1,0,8.599375e-001,-5.215613e-001,-5.215613e-001,1.831490e-001,-2.710586e-001,-7.966380e-001,-9.192769e-002,-5.461353e-001,-2.623656e-003,-2.623656e-003,,,,,,,,,,,,,,,,,,,,
1432797009.719,,-1.000000e+004,1.000707e+001,1.000599e+001,1,0,2.366776e+000,3.067110e-001,3.067110e-001,3.655981e-001,3.467565e-001,5.764372e-001,6.353242e-001,6.164826e-001,1.542875e-003,1.542875e-003,,,,,,,,,,,,,,,,,,,,
1432797009.719,,-1.000000e+004,1.000707e+001,1.000599e+001,1,0,4.486537e+000,-1.055635e+000,-1.055635e+000,-2.242418e-001,-1.015590e+000,-9.675317e-001,-1.361382e-001,-9.274862e-001,-5.310255e-003,-5.310255e-003,,,,,,,,,,,,,,,,,,,,
1432797164.556,,-2.000000e+004,1.000003e+001,1.000383e+001,1,0,1.774133e-001,-7.342753e-001,-7.342753e-001,-2.426119e-002,-4.621857e-001,-1.205927e+000,-4.959126e-001,-9.338371e-001,-3.691491e-003,-3.691491e-003,,,,,,,,,,,,,,,,,,,,
1432797164.556,,-2.000000e+004,1.000003e+001,1.000383e+001,1,0,3.432069e+000,-3.017212e+000,-3.017212e+000,-1.362203e+000,-2.745123e+000,-2.147813e+000,-4.928038e-001,-1.875723e+000,-1.516871e-002,-1.516871e-002,,,,,,,,,,,,,,,,,,,,
1432797174.520,,-2.000000e+004,1.000383e+001,1.000437e+001,1,0,3.525181e+000,-3.265481e+000,-3.265481e+000,-2.078995e+000,-2.929922e+000,-1.694788e+000,-5.083022e-001,-1.359229e+000,-1.641686e-002,-1.641686e-002,,,,,,,,,,,,,,,,,,,,
1432797331.812,,-3.000000e+004,9.999475e+000,1.000491e+001,1,0,5.759737e-002,-9.242531e-001,-9.242530e-001,-1.617937e-001,-5.203875e-001,-1.279503e+000,-5.170434e-001,-8.756372e-001,-4.643816e-003,-4.643816e-003,,,,,,,,,,,,,,,,,,,,
1432797331.812,,-3.000000e+004,9.999475e+000,1.000491e+001,1,0,4.300713e+000,-2.471999e+000,-2.471999e+000,-6.593724e-001,-2.068134e+000,-2.063398e+000,-2.507713e-001,-1.659533e+000,-1.242031e-002,-1.242031e-002,,,,,,,,,,,,,,,,,,,,
1432797342.026,,-3.000000e+004,1.000437e+001,1.000491e+001,1,0,2.410335e+000,1.649525e-001,1.649525e-001,1.122439e+000,3.448967e-001,-1.738401e-001,7.836461e-001,6.104037e-003,8.287873e-004,8.287873e-004,,,,,,,,,,,,,,,,,,,,
1432797509.976,,-4.000000e+004,1.000544e+001,1.000598e+001,1,0,6.838176e-001,-2.780236e-001,-2.780236e-001,-7.533304e-002,-1.736261e-001,-3.551419e-001,-1.524513e-001,-2.507443e-001,-3.490172e-003,-3.490172e-003,,,,,,,,,,,,,,,,,,,,
1432797509.976,,-4.000000e+004,1.000544e+001,1.000598e+001,1,0,4.910064e+000,-7.385480e-002,-7.385480e-002,5.766152e-001,3.054276e-002,-6.904176e-001,-3.994761e-002,-5.860201e-001,-9.271367e-004,-9.271367e-004,,,,,,,,,,,,,,,,,,,,
1432797520.441,,-4.000000e+004,1.000598e+001,1.000490e+001,1,0,1.379966e+000,-1.504562e-001,-1.504562e-001,2.953300e-001,-1.217513e-002,-1.309797e-001,3.148065e-001,7.301375e-003,-1.888754e-003,-1.888754e-003,,,,,,,,,,,,,,,,,,,,
1432797680.927,,-5.000000e+004,1.000057e+001,1.000542e+001,1,0,1.693091e+000,1.968444e-002,1.968444e-002,2.206984e-001,1.730364e-001,3.628309e-001,5.638449e-001,5.161829e-001,2.469614e-004,2.469614e-004,,,,,,,,,,,,,,,,,,,,
1432797680.927,,-5.000000e+004,1.000057e+001,1.000542e+001,1,0,4.870499e+000,-1.925718e-001,-1.925718e-001,4.969772e-001,-3.921980e-002,-7.356493e-001,-4.610028e-002,-5.822973e-001,-2.416010e-003,-2.416010e-003,,,,,,,,,,,,,,,,,,,,
1432797691.391,,-5.000000e+004,1.000597e+001,1.000543e+001,1,0,5.492942e-001,-3.666799e-001,-3.666799e-001,5.021114e-002,-2.120889e-001,-6.425300e-001,-2.256390e-001,-4.879390e-001,-4.600374e-003,-4.600374e-003,,,,,,,,,,,,,,,,,,,,
1432797691.391,,-5.000000e+004,1.000597e+001,1.000543e+001,1,0,2.811929e+000,-5.267494e-001,-5.267495e-001,3.789735e-001,-3.721585e-001,-8.514970e-001,5.422595e-002,-6.969060e-001,-6.608611e-003,-6.608611e-003,,,,,,,,,,,,,,,,,,,,
1432797853.904,,-6.000000e+004,1.000057e+001,1.000595e+001,1,0,4.133689e+000,-1.483200e+000,-1.483200e+000,-8.379223e-001,-1.341310e+000,-8.114109e-001,-1.661336e-001,-6.695209e-001,-1.859715e-002,-1.859715e-002,,,,,,,,,,,,,,,,,,,,
1432797864.071,,-6.000000e+004,1.000595e+001,1.000595e+001,1,0,3.478222e-002,-4.075747e-001,-4.075747e-001,-4.882367e-002,-2.625751e-001,-6.150876e-001,-2.563366e-001,-4.700879e-001,-5.110389e-003,-5.110389e-003,,,,,,,,,,,,,,,,,,,,
1432797864.071,,-6.000000e+004,1.000595e+001,1.000595e+001,1,0,3.802329e+000,-1.900693e+000,-1.900693e+000,-1.026424e+000,-1.755693e+000,-1.129537e+000,-2.552682e-001,-9.845377e-001,-2.383190e-002,-2.383190e-002,,,,,,,,,,,,,,,,,,,,
1432798022.610,,-7.000000e+004,1.000110e+001,1.000486e+001,1,0,3.085876e+000,-1.083407e+000,-1.083407e+000,-4.912772e-001,-9.495386e-001,-7.370921e-001,-1.449622e-001,-6.032236e-001,-1.357623e-002,-1.357623e-002,,,,,,,,,,,,,,,,,,,,
1432798032.632,,-7.000000e+004,1.000432e+001,1.000432e+001,1,0,2.345813e-001,-3.790399e-001,-3.790399e-001,-1.018018e-001,-2.585468e-001,-5.812439e-001,-3.040057e-001,-4.607508e-001,-4.749767e-003,-4.749767e-003,,,,,,,,,,,,,,,,,,,,
1432798032.632,,-7.000000e+004,1.000432e+001,1.000432e+001,1,0,4.592413e+000,-6.387524e-001,-6.387524e-001,1.740314e-001,-5.182593e-001,-8.945517e-001,-8.176794e-002,-7.740586e-001,-8.004236e-003,-8.004236e-003,,,,,,,,,,,,,,,,,,,,
1432798196.169,,-6.000000e+004,1.000003e+001,1.000434e+001,1,0,1.974621e+000,2.888577e-001,2.888577e-001,6.989788e-001,3.451341e-001,2.499855e-001,6.601067e-001,3.062620e-001,3.621852e-003,3.621852e-003,,,,,,,,,,,,,,,,,,,,
1432798205.992,,-6.000000e+004,1.000434e+001,1.000380e+001,1,0,1.060898e+000,-1.838740e-001,-1.838740e-001,-2.944965e-002,-1.124451e-001,-6.360164e-002,9.082274e-002,7.827275e-003,-2.305511e-003,-2.305511e-003,,,,,,,,,,,,,,,,,,,,
1432798205.992,,-6.000000e+004,1.000434e+001,1.000380e+001,1,0,4.991929e+000,8.575701e-002,8.575701e-002,7.262977e-001,1.571859e-001,-6.807445e-001,-4.020384e-002,-6.093156e-001,1.075267e-003,1.075267e-003,,,,,,,,,,,,,,,,,,,,
1432798360.720,,-5.000000e+004,1.000003e+001,1.000489e+001,1,0,1.026430e+000,-2.050844e-001,-2.050844e-001,1.671957e-001,-1.332866e-001,-3.121773e-001,6.010273e-002,-2.403795e-001,-2.572993e-003,-2.572993e-003,,,,,,,,,,,,,,,,,,,,
1432798371.184,,-5.000000e+004,1.000489e+001,1.000381e+001,1,0,2.140664e+000,3.128147e-001,3.128147e-001,3.493895e-001,3.288368e-001,5.248487e-001,5.614235e-001,5.408708e-001,3.924581e-003,3.924581e-003,,,,,,,,,,,,,,,,,,,,
1432798371.184,,-5.000000e+004,1.000489e+001,1.000381e+001,1,0,4.637867e+000,-3.346355e-001,-3.346355e-001,1.232698e-001,-3.186134e-001,-5.253986e-001,-6.749328e-002,-5.093765e-001,-4.198344e-003,-4.198344e-003,,,,,,,,,,,,,,,,,,,,
1432798536.947,,-4.000000e+004,1.000111e+001,1.000598e+001,1,0,2.836137e-001,-2.372814e-001,-2.372814e-001,3.690887e-003,-1.927376e-001,-4.942009e-001,-2.532286e-001,-4.496571e-001,-2.978714e-003,-2.978714e-003,,,,,,,,,,,,,,,,,,,,
1432798536.947,,-4.000000e+004,1.000111e+001,1.000598e+001,1,0,3.233934e+000,-1.006806e+000,-1.006806e+000,-3.631549e-001,-9.622619e-001,-8.351497e-001,-1.914990e-001,-7.906059e-001,-1.263894e-002,-1.263894e-002,,,,,,,,,,,,,,,,,,,,
1432798546.911,,-4.000000e+004,1.000598e+001,1.000544e+001,1,0,3.736483e+000,-1.516770e+000,-1.516770e+000,-1.118304e+000,-1.497802e+000,-6.327057e-001,-2.342403e-001,-6.137374e-001,-1.904078e-002,-1.904078e-002,,,,,,,,,,,,,,,,,,,,
1432798697.396,,-3.000000e+004,1.000111e+001,1.000599e+001,1,0,1.729574e-002,-2.024903e-001,-2.024903e-001,-5.622606e-002,-1.909108e-001,-3.457457e-001,-1.994814e-001,-3.341661e-001,-2.543480e-003,-2.543480e-003,,,,,,,,,,,,,,,,,,,,
1432798697.396,,-3.000000e+004,1.000111e+001,1.000599e+001,1,0,4.141339e+000,-1.000092e+000,-1.000092e+000,-4.856890e-001,-9.885120e-001,-6.434329e-001,-1.290304e-001,-6.318533e-001,-1.256215e-002,-1.256215e-002,,,,,,,,,,,,,,,,,,,,
1432798707.362,,-3.000000e+004,1.000490e+001,1.000599e+001,1,0,2.635003e+000,-8.285775e-002,-8.285775e-002,2.293175e-001,-6.774813e-002,-1.534572e-001,1.587181e-001,-1.383476e-001,-1.040776e-003,-1.040776e-003,,,,,,,,,,,,,,,,,,,,
1432798869.042,,-2.000000e+004,1.000111e+001,1.000599e+001,1,0,5.151775e-001,-1.162755e-001,-1.162755e-001,-6.638727e-002,-1.449760e-001,-2.256581e-001,-1.757699e-001,-2.543586e-001,-1.461407e-003,-1.461407e-003,,,,,,,,,,,,,,,,,,,,
1432798869.042,,-2.000000e+004,1.000111e+001,1.000599e+001,1,0,4.825453e+000,1.495407e-002,1.495407e-002,3.870563e-001,-1.374646e-002,-4.088019e-001,-3.669971e-002,-4.375024e-001,1.879500e-004,1.879500e-004,,,,,,,,,,,,,,,,,,,,
1432798879.114,,-2.000000e+004,1.000545e+001,1.000654e+001,1,0,1.569395e+000,1.063570e-001,1.063570e-001,3.207575e-001,9.934501e-002,1.483163e-001,3.627168e-001,1.413043e-001,1.336746e-003,1.336746e-003,,,,,,,,,,,,,,,,,,,,
1432799032.575,,-1.000000e+004,9.998920e+000,1.000382e+001,1,0,1.475958e+000,5.401776e-002,5.401776e-002,6.904253e-002,3.700045e-002,2.452920e-001,2.603168e-001,2.282747e-001,6.793258e-004,6.793258e-004,,,,,,,,,,,,,,,,,,,,
1432799032.575,,-1.000000e+004,9.998920e+000,1.000382e+001,1,0,4.943547e+000,1.010163e-001,1.010163e-001,3.787860e-001,8.399896e-002,-3.031855e-001,-2.541572e-002,-3.202028e-001,1.270378e-003,1.270378e-003,,,,,,,,,,,,,,,,,,,,
1432799042.646,,-1.000000e+004,1.000382e+001,1.000382e+001,1,0,7.015737e-001,-6.942961e-002,-6.942961e-002,5.034742e-002,-9.834689e-002,-2.162548e-001,-9.647779e-002,-2.451721e-001,-8.731447e-004,-8.731447e-004,,,,,,,,,,,,,,,,,,,,
1432799158.824,,-9.000000e+003,9.999475e+000,1.000382e+001,1,0,2.591229e+000,-5.035554e-003,-5.035554e-003,-9.565338e-003,-9.565338e-003,1.412743e-001,1.367445e-001,1.367445e-001,-6.333074e-005,-6.333074e-005,,,,,,,,,,,,,,,,,,,,
1432799158.824,,-9.000000e+003,9.999475e+000,1.000382e+001,1,0,4.318005e+000,-5.308695e-001,-5.308695e-001,-2.763097e-001,-5.353993e-001,-3.249300e-001,-7.037018e-002,-3.294597e-001,-6.676596e-003,-6.676596e-003,,,,,,,,,,,,,,,,,,,,
1432799168.849,,-9.000000e+003,1.000436e+001,1.000491e+001,1,0,9.370651e-002,-1.272622e-001,-1.272622e-001,-1.711985e-002,-1.321643e-001,-2.641755e-001,-1.540332e-001,-2.690776e-001,-1.600541e-003,-1.600541e-003,,,,,,,,,,,,,,,,,,,,
1432799168.849,,-9.000000e+003,1.000436e+001,1.000491e+001,1,0,3.621088e+000,-9.469894e-001,-9.469894e-001,-5.748013e-001,-9.518915e-001,-5.361586e-001,-1.639705e-001,-5.410607e-001,-1.191002e-002,-1.191002e-002,,,,,,,,,,,,,,,,,,,,
1432799288.635,,-7.000000e+003,9.999475e+000,1.000599e+001,1,0,3.307804e+000,-6.678976e-001,-6.678976e-001,-4.737902e-001,-6.899287e-001,-3.282260e-001,-1.341186e-001,-3.502570e-001,-8.400960e-003,-8.400960e-003,,,,,,,,,,,,,,,,,,,,
1432799298.909,,-7.000000e+003,1.000490e+001,1.000328e+001,1,0,1.314753e-001,-9.369183e-002,-9.369183e-002,-4.741607e-002,-1.285361e-001,-1.948876e-001,-1.486118e-001,-2.297319e-001,-1.178476e-003,-1.178476e-003,,,,,,,,,,,,,,,,,,,,
1432799298.909,,-7.000000e+003,1.000490e+001,1.000328e+001,1,0,4.450666e+000,-3.378399e-001,-3.378399e-001,-3.572401e-002,-3.726842e-001,-3.549867e-001,-5.287084e-002,-3.898310e-001,-4.249423e-003,-4.249423e-003,,,,,,,,,,,,,,,,,,,,
1432799418.193,,-5.000000e+003,1.000382e+001,1.000977e+001,1,0,2.189546e+000,1.210059e-001,1.210059e-001,3.496915e-001,1.667095e-001,5.066194e-002,2.793475e-001,9.636557e-002,1.522220e-003,1.522220e-003,,,,,,,,,,,,,,,,,,,,
1432799428.514,,-5.000000e+003,1.001032e+001,1.000869e+001,1,0,8.668513e-001,-6.500442e-002,-6.500442e-002,-3.294932e-002,-7.919189e-002,-6.036104e-002,-2.830593e-002,-7.454850e-002,-8.177371e-004,-8.177371e-004,,,,,,,,,,,,,,,,,,,,
1432799428.514,,-5.000000e+003,1.001032e+001,1.000869e+001,1,0,4.967224e+000,8.819849e-002,8.819849e-002,3.572468e-001,7.401103e-002,-2.896578e-001,-2.060956e-002,-3.038453e-001,1.109512e-003,1.109512e-003,,,,,,,,,,,,,,,,,,,,
1432799547.941,,-3.000000e+003,1.000111e+001,1.000436e+001,1,0,1.199543e+000,9.918516e-003,9.918516e-003,1.045246e-001,-1.178646e-002,-7.194946e-003,8.741114e-002,-2.889992e-002,1.247869e-004,1.247869e-004,,,,,,,,,,,,,,,,,,,,
1432799558.215,,-3.000000e+003,1.000490e+001,1.000544e+001,1,0,1.915464e+000,1.559496e-001,1.559496e-001,1.446852e-001,1.299821e-001,2.940292e-001,2.827649e-001,2.680618e-001,1.962034e-003,1.962034e-003,,,,,,,,,,,,,,,,,,,,
1432799558.215,,-3.000000e+003,1.000490e+001,1.000544e+001,1,0,4.767067e+000,-3.479110e-002,-3.479110e-002,1.548874e-001,-6.075859e-002,-2.143434e-001,-2.466494e-002,-2.403109e-001,-4.377142e-004,-4.377142e-004,,,,,,,,,,,,,,,,,,,,
1432799686.297,,-1.000000e+003,1.000544e+001,1.000490e+001,1,0,4.103065e-001,-1.174963e-002,-1.174963e-002,2.192556e-002,-1.436798e-001,-2.393748e-001,-2.056997e-001,-3.713050e-001,-5.913685e-005,-5.913685e-005,,,,,,,,,,,,,,,,,,,,
1432799686.297,,-1.000000e+003,1.000544e+001,1.000490e+001,1,0,3.026711e+000,-3.564562e-001,-3.564562e-001,5.436596e-004,-4.883863e-001,-4.309192e-001,-7.391938e-002,-5.628493e-001,-1.794074e-003,-1.794074e-003,,,,,,,,,,,,,,,,,,,,
1432799696.512,,-1.000000e+003,1.000490e+001,1.000436e+001,1,0,3.940465e+000,-1.022065e+000,-1.022065e+000,-8.457161e-001,-1.155973e+000,-3.368088e-001,-1.604599e-001,-4.707168e-001,-5.144138e-003,-5.144138e-003,,,,,,,,,,,,,,,,,,,,
1432799807.259,,-5.000000e+002,1.000057e+001,1.000598e+001,1,0,7.861496e-003,-1.663259e-002,-1.663259e-002,-3.313685e-002,-1.328067e-001,-1.276785e-001,-1.441828e-001,-2.438526e-001,-8.371569e-005,-8.371569e-005,,,,,,,,,,,,,,,,,,,,
1432799807.259,,-5.000000e+002,1.000057e+001,1.000598e+001,1,0,3.975506e+000,-7.475508e-001,-7.475509e-001,-5.086513e-001,-8.637250e-001,-3.597635e-001,-1.208638e-001,-4.759375e-001,-3.762598e-003,-3.762598e-003,,,,,,,,,,,,,,,,,,,,
1432799817.224,,-5.000000e+002,1.000598e+001,1.000598e+001,1,0,2.860914e+000,-2.067629e-001,-2.067629e-001,-3.952248e-002,-2.524677e-001,-1.558854e-001,1.135502e-002,-2.015902e-001,-1.040686e-003,-1.040686e-003,,,,,,,,,,,,,,,,,,,,
1432799921.157,,-4.000000e+002,1.000057e+001,1.000436e+001,1,0,3.636472e-001,-1.100192e-001,-1.100192e-001,-5.234435e-002,-1.177472e-001,-2.120730e-001,-1.543982e-001,-2.198010e-001,-5.537557e-004,-5.537557e-004,,,,,,,,,,,,,,,,,,,,
1432799921.157,,-4.000000e+002,1.000057e+001,1.000436e+001,1,0,4.718837e+000,-9.659109e-002,-9.659109e-002,2.048579e-001,-1.043190e-001,-3.353494e-001,-3.390040e-002,-3.430773e-001,-4.861683e-004,-4.861683e-004,,,,,,,,,,,,,,,,,,,,
1432799930.930,,-4.000000e+002,1.000436e+001,1.000328e+001,1,0,1.767627e+000,1.817377e-001,1.817377e-001,3.187819e-001,1.490978e-001,2.043275e-001,3.413717e-001,1.716876e-001,9.147337e-004,9.147337e-004,,,,,,,,,,,,,,,,,,,,
1432800034.762,,-3.000000e+002,9.999475e+000,1.000490e+001,1,0,1.265324e+000,1.094089e-001,1.094089e-001,1.137094e-002,-2.003482e-002,2.269197e-001,1.288818e-001,9.747605e-002,5.506868e-004,5.506868e-004,,,,,,,,,,,,,,,,,,,,
1432800034.762,,-3.000000e+002,9.999475e+000,1.000490e+001,1,0,4.985102e+000,2.346873e-001,2.346873e-001,3.512554e-001,1.052437e-001,-1.367210e-001,-2.015293e-002,-2.661647e-001,1.181250e-003,1.181250e-003,,,,,,,,,,,,,,,,,,,,
1432800045.431,,-3.000000e+002,1.000436e+001,1.000382e+001,1,0,8.602025e-001,-4.577776e-002,-4.577776e-002,6.207865e-002,-7.064998e-002,-1.391984e-001,-3.134195e-002,-1.640706e-001,-2.304129e-004,-2.304129e-004,,,,,,,,,,,,,,,,,,,,
1432800149.714,,-2.000000e+002,9.998920e+000,1.000436e+001,1,0,2.366410e+000,1.945555e-001,1.945555e-001,1.113687e-001,1.063727e-001,2.771957e-001,1.940089e-001,1.890129e-001,9.792607e-004,9.792607e-004,,,,,,,,,,,,,,,,,,,,
1432800149.714,,-2.000000e+002,9.998920e+000,1.000436e+001,1,0,4.486435e+000,-1.889096e-001,-1.889096e-001,-6.726049e-002,-2.770923e-001,-1.631788e-001,-4.152974e-002,-2.513616e-001,-9.508429e-004,-9.508429e-004,,,,,,,,,,,,,,,,,,,,
1432800159.988,,-2.000000e+002,1.000382e+001,1.000490e+001,1,0,1.759058e-001,-6.332590e-002,-6.332590e-002,-5.506387e-003,-1.030557e-001,-1.839018e-001,-1.260823e-001,-2.236317e-001,-3.187397e-004,-3.187397e-004,,,,,,,,,,,,,,,,,,,,
1432800159.988,,-2.000000e+002,1.000382e+001,1.000490e+001,1,0,3.431747e+000,-6.173894e-001,-6.173894e-001,-3.490687e-001,-6.571193e-001,-3.936488e-001,-1.253281e-001,-4.333787e-001,-3.107521e-003,-3.107521e-003,,,,,,,,,,,,,,,,,,,,
1432800263.352,,-1.000000e+002,1.000003e+001,1.000544e+001,1,0,3.525429e+000,-9.979552e-001,-9.979553e-001,-4.660672e-001,-7.172908e-001,-6.452079e-001,-1.133199e-001,-3.645434e-001,-5.023061e-003,-5.023061e-003,,,,,,,,,,,,,,,,,,,,
1432800273.268,,-1.000000e+002,1.000490e+001,1.000382e+001,1,0,5.821169e-002,-3.299051e-001,-3.299051e-001,-3.065188e-002,-1.184717e-001,-4.008623e-001,-1.016091e-001,-1.894289e-001,-1.660529e-003,-1.660529e-003,,,,,,,,,,,,,,,,,,,,
1432800273.268,,-1.000000e+002,1.000490e+001,1.000382e+001,1,0,4.299990e+000,-6.874294e-001,-6.874294e-001,-1.309895e-001,-4.759961e-001,-6.059977e-001,-4.955782e-002,-3.945644e-001,-3.460075e-003,-3.460075e-003,,,,,,,,,,,,,,,,,,,,
1432800376.800,,0.000000e+000,1.000273e+001,1.000868e+001,1,0,2.410277e+000,7.095553e-002,7.095554e-002,1.858106e-001,6.867140e-002,1.490568e-002,1.297607e-001,1.262154e-002,3.571464e-004,3.571464e-004,,,,,,,,,,,,,,,,,,,,
1432800396.089,,0.000000e+000,1.000598e+001,1.000436e+001,1,0,6.844131e-001,-7.324442e-002,-7.324442e-002,-1.121837e-001,-2.439395e-001,-1.898206e-001,-2.287599e-001,-3.605157e-001,-9.216680e-005,-9.216680e-005,,,,,,,,,,,,,,,,,,,,
1432800396.089,,0.000000e+000,1.000598e+001,1.000436e+001,1,0,4.909338e+000,3.061007e-001,3.061006e-001,8.673823e-001,1.354055e-001,-6.213157e-001,-6.003402e-002,-7.920108e-001,3.851804e-004,3.851804e-004,,,,,,,,,,,,,,,,,,,,
1432800500.022,,1.000000e+002,1.000057e+001,1.000652e+001,1,0,1.380487e+000,5.021821e-001,5.021821e-001,3.426777e-001,4.990578e-002,5.262585e-001,3.667541e-001,7.398224e-002,6.319149e-004,6.319149e-004,,,,,,,,,,,,,,,,,,,,
1432800509.844,,1.000000e+002,1.000598e+001,1.000598e+001,1,0,1.693301e+000,1.483200e-001,1.483200e-001,2.332914e-001,1.874684e-001,5.210118e-001,6.059833e-001,5.601603e-001,1.866367e-004,1.866367e-004,,,,,,,,,,,,,,,,,,,,
1432800509.844,,1.000000e+002,1.000598e+001,1.000598e+001,1,0,4.870416e+000,-1.648000e-002,-1.648000e-002,5.381770e-001,2.266844e-002,-6.041974e-001,-4.954041e-002,-5.650489e-001,-2.073741e-005,-2.073741e-005,,,,,,,,,,,,,,,,,,,,
1432800613.567,,2.000000e+002,1.000057e+001,1.000598e+001,1,0,5.490494e-001,-1.948607e-001,-1.948607e-001,2.736554e-002,-9.114772e-002,-3.816718e-001,-1.594456e-001,-2.779589e-001,-2.451992e-004,-2.451992e-004,,,,,,,,,,,,,,,,,,,,
1432800613.567,,2.000000e+002,1.000057e+001,1.000598e+001,1,0,2.811944e+000,-1.649525e-001,-1.649525e-001,2.781393e-001,-6.123959e-002,-4.028437e-001,4.024815e-002,-2.991307e-001,-2.075649e-004,-2.075649e-004,,,,,,,,,,,,,,,,,,,,
1432800623.734,,2.000000e+002,1.000598e+001,1.000544e+001,1,0,4.134498e+000,-6.192206e-001,-6.192206e-001,-5.501232e-001,-8.296950e-001,-1.776043e-001,-1.085069e-001,-3.880788e-001,-7.791843e-004,-7.791843e-004,,,,,,,,,,,,,,,,,,,,
1432800736.396,,3.000000e+002,1.000598e+001,1.000652e+001,1,0,3.436161e-002,5.340739e-003,5.340739e-003,-6.553545e-002,-2.806988e-001,-2.501492e-001,-3.210254e-001,-5.361887e-001,1.344075e-006,1.344075e-006,,,,,,,,,,,,,,,,,,,,
1432800736.396,,3.000000e+002,1.000598e+001,1.000652e+001,1,0,3.802129e+000,-1.726279e+000,-1.726279e+000,-1.278232e+000,-2.012319e+000,-7.720172e-001,-3.239700e-001,-1.058057e+000,-4.344435e-004,-4.344435e-004,,,,,,,,,,,,,,,,,,,,
1432800747.360,,3.000000e+002,1.000652e+001,1.000598e+001,1,0,3.086129e+000,-6.212043e-001,-6.212043e-001,-5.577367e-001,-8.975824e-001,-2.273708e-001,-1.639033e-001,-5.037489e-001,-1.563351e-004,-1.563351e-004,,,,,,,,,,,,,,,,,,,,
1432800851.618,,4.000000e+002,9.998920e+000,1.000436e+001,1,0,2.343507e-001,7.458724e-001,7.458724e-001,6.968155e-002,2.375225e-001,9.291885e-001,2.529977e-001,4.208387e-001,1.877086e-004,1.877086e-004,,,,,,,,,,,,,,,,,,,,
1432800851.618,,4.000000e+002,9.998920e+000,1.000436e+001,1,0,4.592332e+000,1.058840e+000,1.058840e+000,-1.908079e-001,5.504898e-001,1.301780e+000,5.213278e-002,7.934305e-001,2.664709e-004,2.664709e-004,,,,,,,,,,,,,,,,,,,,
1432800862.082,,4.000000e+002,1.000382e+001,1.000436e+001,1,0,1.974532e+000,9.903257e-002,9.903257e-002,-7.197365e-001,-2.454131e-001,6.694680e-001,-1.493009e-001,3.250224e-001,2.492285e-005,2.492285e-005,,,,,,,,,,,,,,,,,,,,
1432800981.235,,5.000000e+002,1.000490e+001,1.000382e+001,1,0,1.061090e+000,-1.069674e-001,-1.069674e-001,3.708559e-002,9.811245e-002,-1.984533e-001,-5.440034e-002,6.626517e-003,-1.345979e-004,-1.345979e-004,,,,,,,,,,,,,,,,,,,,
1432800981.235,,5.000000e+002,1.000490e+001,1.000382e+001,1,0,4.991824e+000,-2.836695e-001,-2.836695e-001,-4.970596e-001,-7.858971e-002,2.403956e-001,2.700552e-002,4.454754e-001,-3.569438e-004,-3.569438e-004,,,,,,,,,,,,,,,,,,,,
1432800991.700,,5.000000e+002,1.000328e+001,1.000220e+001,1,0,1.026379e+000,1.804865e+000,1.804865e+000,-1.102569e-001,2.845259e-001,1.874102e+000,-4.101993e-002,3.537629e-001,2.271076e-003,2.271076e-003,,,,,,,,,,,,,,,,,,,,
1432801110.950,,1.000000e+003,1.000490e+001,1.000436e+001,1,0,2.140498e+000,-1.236000e-002,-1.236000e-002,-4.302136e-001,-3.995903e-001,-2.806807e-001,-6.985343e-001,-6.679110e-001,-3.110445e-005,-3.110445e-005,,,,,,,,,,,,,,,,,,,,
1432801110.950,,1.000000e+003,1.000490e+001,1.000436e+001,1,0,4.637800e+000,8.876308e-001,8.876308e-001,-1.580014e-001,5.004005e-001,1.129665e+000,8.403259e-002,7.424345e-001,2.233760e-003,2.233760e-003,,,,,,,,,,,,,,,,,,,,
1432801120.867,,1.000000e+003,1.000436e+001,1.000328e+001,1,0,2.855643e-001,5.775628e-001,5.775628e-001,-1.474138e-002,3.185607e-001,9.319562e-001,3.396520e-001,6.729541e-001,1.453461e-003,1.453461e-003,,,,,,,,,,,,,,,,,,,,
1432801120.867,,1.000000e+003,1.000436e+001,1.000328e+001,1,0,3.234028e+000,1.767022e+000,1.767022e+000,4.914482e-001,1.508020e+000,1.530206e+000,2.546329e-001,1.271204e+000,4.446784e-003,4.446784e-003,,,,,,,,,,,,,,,,,,,,
1432801249.415,,3.000000e+003,1.000598e+001,1.000544e+001,1,0,3.736419e+000,2.354656e+000,2.354656e+000,1.371238e+000,1.958566e+000,1.269373e+000,2.859564e-001,8.732840e-001,1.184977e-002,1.184977e-002,,,,,,,,,,,,,,,,,,,,
1432801259.581,,3.000000e+003,1.000544e+001,1.000436e+001,1,0,1.645496e-002,4.890591e-001,4.890591e-001,7.406952e-002,2.808605e-001,6.819554e-001,2.669658e-001,4.737568e-001,2.461182e-003,2.461182e-003,,,,,,,,,,,,,,,,,,,,
1432801259.581,,3.000000e+003,1.000544e+001,1.000436e+001,1,0,4.139237e+000,1.641591e+000,1.641591e+000,6.613722e-001,1.433392e+000,1.154586e+000,1.743679e-001,9.463878e-001,8.261279e-003,8.261279e-003,,,,,,,,,,,,,,,,,,,,
1432801379.165,,5.000000e+003,1.000057e+001,1.000652e+001,1,0,2.635345e+000,3.918577e-001,3.918577e-001,-3.625958e-001,1.673487e-001,5.053491e-001,-2.491044e-001,2.808401e-001,1.971783e-003,1.971783e-003,,,,,,,,,,,,,,,,,,,,
1432801388.964,,5.000000e+003,1.000544e+001,1.000652e+001,1,0,5.150910e-001,5.821406e-001,5.821406e-001,1.175358e-001,2.774254e-001,7.758026e-001,3.111978e-001,4.710874e-001,2.929265e-003,2.929265e-003,,,,,,,,,,,,,,,,,,,,
1432801388.964,,5.000000e+003,1.000544e+001,1.000652e+001,1,0,4.825562e+000,4.368725e-001,4.368725e-001,-6.832796e-001,1.321573e-001,1.185151e+000,6.499875e-002,8.804356e-001,2.198292e-003,2.198292e-003,,,,,,,,,,,,,,,,,,,,
1432801509.392,,7.000000e+003,1.000057e+001,1.000436e+001,1,0,1.569816e+000,1.640370e-001,1.640370e-001,-6.154166e-001,-1.227721e-001,8.342304e-002,-6.960306e-001,-2.033860e-001,8.253171e-004,8.253171e-004,,,,,,,,,,,,,,,,,,,,
1432801520.214,,7.000000e+003,1.000653e+001,1.000545e+001,1,0,1.476244e+000,1.765496e-001,1.765496e-001,-1.581666e-001,-7.083237e-002,-2.611057e-001,-5.958218e-001,-5.084876e-001,8.882715e-004,8.882715e-004,,,,,,,,,,,,,,,,,,,,
1432801520.214,,7.000000e+003,1.000653e+001,1.000545e+001,1,0,4.944140e+000,1.840266e-001,1.840266e-001,-8.668299e-001,-6.335534e-002,1.109346e+000,5.848946e-002,8.619641e-001,9.258906e-004,9.258906e-004,,,,,,,,,,,,,,,,,,,,
1432801640.641,,9.000000e+003,1.000111e+001,1.000599e+001,1,0,7.015231e-001,6.563005e-001,6.563005e-001,-1.229897e-001,3.061382e-001,1.015751e+000,2.364607e-001,6.655886e-001,3.301643e-003,3.301643e-003,,,,,,,,,,,,,,,,,,,,
1432801650.666,,9.000000e+003,1.000599e+001,1.000545e+001,1,0,2.591557e+000,2.522355e-001,2.522355e-001,2.193153e-002,2.193153e-002,-1.131991e-001,-3.435030e-001,-3.435030e-001,1.268918e-003,1.268918e-003,,,,,,,,,,,,,,,,,,,,
1432801650.666,,9.000000e+003,1.000599e+001,1.000545e+001,1,0,4.317927e+000,1.683096e+000,1.683096e+000,6.935201e-001,1.452792e+000,1.166142e+000,1.765663e-001,9.358380e-001,8.467129e-003,8.467129e-003,,,,,,,,,,,,,,,,,,,,
1432801767.254,,1.000000e+004,9.998920e+000,1.000382e+001,1,0,9.086643e-002,7.376324e-001,7.376324e-001,4.511451e-002,3.897910e-001,1.086494e+000,3.939761e-001,7.386526e-001,3.710577e-003,3.710577e-003,,,,,,,,,,,,,,,,,,,,
1432801767.254,,1.000000e+004,9.998920e+000,1.000382e+001,1,0,3.620583e+000,2.948851e+000,2.948851e+000,1.471236e+000,2.601009e+000,1.899011e+000,4.213967e-001,1.551170e+000,1.483386e-002,1.483386e-002,,,,,,,,,,,,,,,,,,,,
1432801777.219,,1.000000e+004,1.000382e+001,1.000383e+001,1,0,3.307997e+000,2.269814e+000,2.269814e+000,1.291562e+000,1.976137e+000,1.343587e+000,3.653345e-001,1.049910e+000,1.141805e-002,1.141805e-002,,,,,,,,,,,,,,,,,,,,
1432801932.199,,2.000000e+004,1.000003e+001,1.000437e+001,1,0,1.310085e-001,7.898190e-001,7.898190e-001,1.568548e-001,4.564297e-001,1.116329e+000,4.833645e-001,7.829394e-001,3.970731e-003,3.970731e-003,,,,,,,,,,,,,,,,,,,,
1432801932.199,,2.000000e+004,1.000003e+001,1.000437e+001,1,0,4.450992e+000,1.704306e+000,1.704306e+000,1.265288e-001,1.370917e+000,1.750502e+000,1.727245e-001,1.417113e+000,8.568217e-003,8.568217e-003,,,,,,,,,,,,,,,,,,,,
1432801942.365,,2.000000e+004,1.000437e+001,1.000274e+001,1,0,2.189512e+000,-2.021851e-001,-2.021851e-001,-1.239960e+000,-5.279486e-001,4.360912e-002,-9.941654e-001,-2.821544e-001,-1.016464e-003,-1.016464e-003,,,,,,,,,,,,,,,,,,,,
1432802099.188,,3.000000e+004,1.000328e+001,1.000816e+001,1,0,8.671196e-001,6.323435e-001,6.323435e-001,1.330280e-001,3.488975e-001,6.136996e-001,1.143841e-001,3.302536e-001,3.177146e-003,3.177146e-003,,,,,,,,,,,,,,,,,,,,
1432802099.188,,3.000000e+004,1.000328e+001,1.000816e+001,1,0,4.966919e+000,1.818903e-001,1.818903e-001,-1.423756e+000,-1.015557e-001,1.688461e+000,8.281413e-002,1.405015e+000,9.138894e-004,9.138894e-004,,,,,,,,,,,,,,,,,,,,
1432802109.510,,3.000000e+004,1.000653e+001,1.000653e+001,1,0,1.199608e+000,6.500443e-001,6.500443e-001,-4.851519e-001,1.875815e-001,7.306404e-001,-4.045558e-001,2.681777e-001,3.266081e-003,3.266081e-003,,,,,,,,,,,,,,,,,,,,
1432802277.206,,4.000000e+004,1.000544e+001,1.000652e+001,1,0,1.915723e+000,-1.168859e-001,-1.168859e-001,-2.972407e-001,-2.638536e-001,-3.983668e-001,-5.787216e-001,-5.453345e-001,-1.467328e-003,-1.467328e-003,,,,,,,,,,,,,,,,,,,,
1432802277.206,,4.000000e+004,1.000544e+001,1.000652e+001,1,0,4.767525e+000,3.233436e-001,3.233436e-001,-3.133017e-001,1.763759e-001,6.871426e-001,5.049725e-002,5.401748e-001,4.059096e-003,4.059096e-003,,,,,,,,,,,,,,,,,,,,
1432802287.171,,4.000000e+004,1.000652e+001,1.000490e+001,1,0,4.116463e-001,3.874325e-001,3.874325e-001,-2.386039e-002,2.092895e-001,6.547557e-001,2.434628e-001,4.766127e-001,4.863637e-003,4.863637e-003,,,,,,,,,,,,,,,,,,,,
1432802287.171,,4.000000e+004,1.000652e+001,1.000490e+001,1,0,3.027429e+000,8.642842e-001,8.642842e-001,-2.206063e-003,6.861413e-001,9.541905e-001,8.770021e-002,7.760475e-001,1.084980e-002,1.084980e-002,,,,,,,,,,,,,,,,,,,,
1432802447.670,,5.000000e+004,1.000003e+001,1.000543e+001,1,0,3.940054e+000,1.693167e+000,1.693167e+000,1.073038e+000,1.540208e+000,8.256580e-001,2.055287e-001,6.726986e-001,2.124251e-002,2.124251e-002,,,,,,,,,,,,,,,,,,,,
1432802457.588,,5.000000e+004,1.000543e+001,1.000489e+001,1,0,8.890446e-003,4.275643e-001,4.275643e-001,5.927314e-002,2.496353e-001,6.033149e-001,2.350237e-001,4.253858e-001,5.364232e-003,5.364232e-003,,,,,,,,,,,,,,,,,,,,
1432802457.588,,5.000000e+004,1.000543e+001,1.000489e+001,1,0,3.974960e+000,1.678518e+000,1.678518e+000,8.224239e-001,1.500589e+000,1.052938e+000,1.968434e-001,8.750085e-001,2.105873e-002,2.105873e-002,,,,,,,,,,,,,,,,,,,,
1432802620.956,,6.000000e+004,1.000111e+001,1.000595e+001,1,0,2.861068e+000,6.344798e-001,6.344798e-001,6.690565e-002,4.955828e-001,5.478549e-001,-1.971926e-002,4.089579e-001,7.955447e-003,7.955447e-003,,,,,,,,,,,,,,,,,,,,
1432802631.368,,6.000000e+004,1.000595e+001,1.000595e+001,1,0,3.638377e-001,4.206977e-001,4.206977e-001,9.952999e-002,2.378704e-001,6.084808e-001,2.873131e-001,4.256535e-001,5.274932e-003,5.274932e-003,,,,,,,,,,,,,,,,,,,,
1432802631.368,,6.000000e+004,1.000595e+001,1.000595e+001,1,0,4.717768e+000,4.626606e-001,4.626606e-001,-3.741394e-001,2.798333e-001,8.999975e-001,6.319749e-002,7.171702e-001,5.801086e-003,5.801086e-003,,,,,,,,,,,,,,,,,,,,
1432802790.205,,7.000000e+004,1.000057e+001,1.000432e+001,1,0,1.767401e+000,-6.408887e-002,-6.408887e-002,-6.223326e-001,-2.419989e-001,-1.088401e-001,-6.670838e-001,-2.867502e-001,-8.031006e-004,-8.031006e-004,,,,,,,,,,,,,,,,,,,,
1432802800.920,,7.000000e+004,1.000432e+001,1.000432e+001,1,0,1.264548e+000,1.815851e-001,1.815851e-001,-3.157178e-002,4.701215e-002,-6.010040e-002,-2.732573e-001,-1.946734e-001,2.275452e-003,2.275452e-003,,,,,,,,,,,,,,,,,,,,
1432802800.920,,7.000000e+004,1.000432e+001,1.000432e+001,1,0,4.984422e+000,1.312296e-002,1.312296e-002,-7.370242e-001,-1.214500e-001,7.930920e-001,4.294481e-002,6.585190e-001,1.644444e-004,1.644444e-004,,,,,,,,,,,,,,,,,,,,
1432802800.920,,7.000000e+004,1.000432e+001,1.000432e+001,1,0,2.811746e+000,5.331584e-001,5.331584e-001,-4.265459e-001,3.985854e-001,8.983817e-001,-6.132259e-002,7.638087e-001,6.681032e-003,6.681032e-003,,,,,,,,,,,,,,,,,,,,