File: data/A269/A269_GdN_MH_60K_150528.rso.raw
[Header]
TITLE,MPMS RSO Measurement
BYAPP,MPMS Measurement,2.1,Raw with ABS
FILEOPENTIME, 1432842693.153000 5/29/2015, 7:51:33 AM

INFO, APPNAME, MPMS MultiVu Application, Revision 1.61,  Build 082

INFO, NAME, A269
INFO, WEIGHT, 22.300
INFO, AREA, 1.000
INFO, LENGTH, 1.000
INFO, SHAPE, 1
INFO, COMMENT, m = 0.0223g
INFO, SEQUENCE FILE: 7T_hysteresis_sweep.seq


INFO, BACKGROUND DATA FILE:, None


STARTUPAXIS,X,8,LINEAR,AUTO,0.000000,0.000000
STARTUPAXIS,Y1,9,LINEAR,AUTO,0.000000,0.000000


STARTUPGROUP,Longitudinal
FIELDGROUP,Longitudinal,1,2,3,4,5,6,7,8,9,10,11,12,13,14,15,16,17,18,19,20,21,22
FIELDGROUP,Transverse,1,2,3,4,5,6,7,8,23,24,25,26,27,28,29,30,31,32,33,34,35,36

PLOT_APPEARANCE,ALL,HORZ_GRID_ON,VERT_GRID_ON,MARKERS_ONLY

[Data]
Time,Comment,Field (Oe),Start Temperature (K),End Temperature (K),Scan,Rejected,Position (cm),Long Voltage,Long Average Voltage,Long Detrended Voltage,Long Demeaned Voltage,Long Reg Fit,Long Detrended Fit,Long Demeaned Fit,Long Scaled Response,Long Avg. Scaled Response,Long Background Response,Long Response [w/ABS],Long Detrended Resp. [w/ABS],Long Fit [w/ABS],Long Detrended Fit [w/ABS],Trans Voltage,Trans Average Voltage,Trans Detrended Voltage,Trans Demeaned Voltage,Trans Reg Fit,Trans Detrended Fit,Trans Demeaned Fit,Trans Scaled Response,Trans Avg. Scaled Response,Trans Background Response,Trans Response [w/ABS],Trans Detrended Resp. [w/ABS],Trans Adjusted Fit,Trans Detrended Fit [w/ABS],
1432842693.142,,7.000000e+004,6.008729e+001,6.006611e+001,1,0,2.591198e+000,1.269570e-001,1.269570e-001,-1.166783e-002,-1.166783e-002,-1.206471e-001,-2.592719e-001,-2.592719e-001,6.363617e-004,6.363617e-004,,,,,,,,,,,,,,,,,,,,
1432842693.142,,7.000000e+004,6.008729e+001,6.006611e+001,1,0,7.014382e-001,3.386028e-001,3.386029e-001,-7.727739e-002,1.999780e-001,5.935701e-001,1.776898e-001,4.549452e-001,1.697219e-003,1.697219e-003,,,,,,,,,,,,,,,,,,,,
1432842693.142,,7.000000e+004,6.008729e+001,6.006611e+001,1,0,4.944427e+000,8.392590e-002,8.392590e-002,-6.092098e-001,-5.469893e-002,7.379352e-001,4.479949e-002,5.993103e-001,4.206718e-004,4.206718e-004,,,,,,,,,,,,,,,,,,,,
1432842703.106,,7.000000e+004,6.006611e+001,6.005730e+001,1,0,1.475923e+000,-5.600147e-002,-5.600147e-002,-1.114587e-001,-5.132603e-002,-3.595568e-001,-4.150140e-001,-3.548813e-001,-2.807028e-004,-2.807028e-004,,,,,,,,,,,,,,,,,,,,
1432842703.106,,7.000000e+004,6.006611e+001,6.005730e+001,1,0,1.569716e+000,-1.106296e-001,-1.106296e-001,-4.426973e-001,-1.059542e-001,-1.584296e-001,-4.904974e-001,-1.537542e-001,-5.545219e-004,-5.545219e-004,,,,,,,,,,,,,,,,,,,,
1432842703.106,,7.000000e+004,6.006611e+001,6.005730e+001,1,0,4.825450e+000,8.819850e-002,8.819849e-002,-5.204797e-001,9.287393e-002,6.629899e-001,5.431166e-002,6.676653e-001,4.420878e-004,4.420878e-004,,,,,,,,,,,,,,,,,,,,
1432842865.821,,6.000000e+004,5.999565e+001,5.999389e+001,1,0,5.148043e-001,2.310251e-001,2.310251e-001,8.742274e-002,1.887196e-001,3.755623e-001,2.319599e-001,3.332567e-001,1.158686e-003,1.158686e-003,,,,,,,,,,,,,,,,,,,,
1432842865.821,,6.000000e+004,5.999565e+001,5.999389e+001,1,0,2.635333e+000,9.689627e-002,9.689627e-002,-2.796889e-001,5.459074e-002,1.779640e-001,-1.986212e-001,1.356584e-001,4.859749e-004,4.859749e-004,,,,,,,,,,,,,,,,,,,,
1432842865.821,,6.000000e+004,5.999565e+001,5.999389e+001,1,0,4.141174e+000,1.171606e+000,1.171606e+000,5.620377e-001,1.129300e+000,7.613227e-001,1.517548e-001,7.190171e-001,5.876087e-003,5.876087e-003,,,,,,,,,,,,,,,,,,,,
1432842875.845,,6.000000e+004,5.999389e+001,5.999740e+001,1,0,1.623143e-002,2.415540e-001,2.415540e-001,7.473653e-002,2.247654e-001,3.872274e-001,2.204099e-001,3.704387e-001,1.211493e-003,1.211493e-003,,,,,,,,,,,,,,,,,,,,
1432842875.845,,6.000000e+004,5.999389e+001,5.999740e+001,1,0,3.737039e+000,1.531266e+000,1.531266e+000,1.134405e+000,1.514478e+000,6.426968e-001,2.458351e-001,6.259081e-001,7.679933e-003,7.679933e-003,,,,,,,,,,,,,,,,,,,,
1432842875.845,,6.000000e+004,5.999389e+001,5.999740e+001,1,0,3.234109e+000,9.668263e-001,9.668264e-001,3.399205e-001,9.500377e-001,8.135887e-001,1.866828e-001,7.968000e-001,4.849034e-003,4.849034e-003,,,,,,,,,,,,,,,,,,,,
1432843037.383,,5.000000e+004,5.999916e+001,5.999565e+001,1,0,2.841835e-001,2.198859e-001,2.198859e-001,-1.394548e-003,2.025113e-001,4.508121e-001,2.295317e-001,4.334375e-001,1.103477e-003,1.103477e-003,,,,,,,,,,,,,,,,,,,,
1432843037.383,,5.000000e+004,5.999916e+001,5.999565e+001,1,0,4.638271e+000,3.636280e-001,3.636280e-001,-9.214403e-002,3.462534e-001,5.144736e-001,5.870149e-002,4.970990e-001,1.824834e-003,1.824834e-003,,,,,,,,,,,,,,,,,,,,
1432843047.206,,5.000000e+004,5.999565e+001,5.999565e+001,1,0,2.139837e+000,-1.277200e-001,-1.277200e-001,-3.003081e-001,-2.846630e-001,-3.115273e-001,-4.841155e-001,-4.684704e-001,-6.409510e-004,-6.409510e-004,,,,,,,,,,,,,,,,,,,,
1432843047.206,,5.000000e+004,5.999565e+001,5.999565e+001,1,0,1.027416e+000,2.194281e-001,2.194281e-001,-1.330784e-001,6.248505e-002,3.168246e-001,-3.568182e-002,1.598816e-001,1.101180e-003,1.101180e-003,,,,,,,,,,,,,,,,,,,,
1432843047.206,,5.000000e+004,5.999565e+001,5.999565e+001,1,0,4.991635e+000,-3.036592e-002,-3.036592e-002,-5.627908e-001,-1.873089e-001,5.655455e-001,3.312066e-002,4.086025e-001,-1.523886e-004,-1.523886e-004,,,,,,,,,,,,,,,,,,,,
1432843213.143,,4.000000e+004,6.000092e+001,6.000092e+001,1,0,1.061636e+000,1.440474e-001,1.440474e-001,2.209211e-002,7.266815e-002,7.081863e-002,-5.113662e-002,-5.605817e-004,7.233199e-004,7.233199e-004,,,,,,,,,,,,,,,,,,,,
1432843213.143,,4.000000e+004,6.000092e+001,6.000092e+001,1,0,1.974134e+000,-1.821955e-001,-1.821955e-001,-4.703292e-001,-2.535747e-001,-1.604635e-001,-4.485971e-001,-2.318427e-001,-9.148770e-004,-9.148770e-004,,,,,,,,,,,,,,,,,,,,
1432843213.143,,4.000000e+004,6.000092e+001,6.000092e+001,1,0,4.592886e+000,3.495895e-001,3.495895e-001,-1.047226e-001,2.782103e-001,5.085503e-001,5.423821e-002,4.371711e-001,1.755430e-003,1.755430e-003,,,,,,,,,,,,,,,,,,,,
1432843223.216,,4.000000e+004,6.000092e+001,5.999916e+001,1,0,2.348647e-001,1.129185e-001,1.129185e-001,6.754403e-002,1.538444e-001,2.401241e-001,1.947497e-001,2.810501e-001,5.670093e-004,5.670093e-004,,,,,,,,,,,,,,,,,,,,
1432843223.216,,4.000000e+004,6.000092e+001,5.999916e+001,1,0,3.086080e+000,5.093539e-001,5.093539e-001,2.985704e-001,5.502799e-001,2.965499e-001,8.576628e-002,3.374758e-001,2.557671e-003,2.557671e-003,,,,,,,,,,,,,,,,,,,,
1432843223.216,,4.000000e+004,6.000092e+001,5.999916e+001,1,0,3.802434e+000,1.064943e+000,1.064943e+000,6.887507e-001,1.105869e+000,5.518104e-001,1.756177e-001,5.927364e-001,5.347510e-003,5.347510e-003,,,,,,,,,,,,,,,,,,,,
1432843380.398,,3.000000e+004,6.000092e+001,6.000092e+001,1,0,3.433307e-002,8.514664e-002,8.514664e-002,2.945034e-002,1.245230e-001,1.941886e-001,1.384923e-001,2.335650e-001,4.278106e-004,4.278106e-004,,,,,,,,,,,,,,,,,,,,
1432843380.398,,3.000000e+004,6.000092e+001,6.000092e+001,1,0,4.133944e+000,6.520280e-001,6.520280e-001,4.677039e-001,6.914043e-001,2.781248e-001,9.380075e-002,3.175012e-001,3.276048e-003,3.276048e-003,,,,,,,,,,,,,,,,,,,,
1432843380.398,,3.000000e+004,6.000092e+001,6.000092e+001,1,0,2.812567e+000,8.102664e-002,8.102664e-002,-2.319252e-001,1.204031e-001,2.739757e-001,-3.897621e-002,3.133521e-001,4.071101e-004,4.071101e-004,,,,,,,,,,,,,,,,,,,,
1432843390.422,,3.000000e+004,6.000092e+001,5.999389e+001,1,0,5.486796e-001,3.906369e-002,3.906369e-002,-2.773729e-002,9.405803e-002,2.026498e-001,1.358488e-001,2.576441e-001,1.962716e-004,1.962716e-004,,,,,,,,,,,,,,,,,,,,
1432843390.422,,3.000000e+004,6.000092e+001,5.999389e+001,1,0,4.869744e+000,-9.125035e-002,-9.125035e-002,-2.853828e-001,-3.625601e-002,2.219239e-001,2.779151e-002,2.769183e-001,-4.584781e-004,-4.584781e-004,,,,,,,,,,,,,,,,,,,,
1432843546.290,,2.000000e+004,6.000092e+001,5.999740e+001,1,0,1.693293e+000,-9.643849e-002,-9.643849e-002,-8.996831e-002,-7.665082e-002,-2.454507e-001,-2.389805e-001,-2.256631e-001,-4.848342e-004,-4.848342e-004,,,,,,,,,,,,,,,,,,,,
1432843546.290,,2.000000e+004,6.000092e+001,5.999740e+001,1,0,1.380564e+000,-6.530961e-002,-6.530961e-002,-1.354150e-001,-4.552194e-002,-7.067712e-002,-1.407825e-001,-5.088945e-002,-3.283371e-004,-3.283371e-004,,,,,,,,,,,,,,,,,,,,
1432843546.290,,2.000000e+004,6.000092e+001,5.999740e+001,1,0,4.910164e+000,-1.190222e-001,-1.190222e-001,-2.657032e-001,-9.923452e-002,1.657732e-001,1.909222e-002,1.855609e-001,-5.983714e-004,-5.983714e-004,,,,,,,,,,,,,,,,,,,,
1432843556.553,,2.000000e+004,6.000444e+001,6.000620e+001,1,0,6.839092e-001,-6.988738e-002,-6.988738e-002,3.613959e-002,6.651111e-002,-3.135243e-002,7.467455e-002,1.050461e-001,-3.513514e-004,-3.513514e-004,,,,,,,,,,,,,,,,,,,,
1432843556.553,,2.000000e+004,6.000444e+001,6.000620e+001,1,0,2.409973e+000,-2.638325e-001,-2.638325e-001,-2.354217e-001,-1.274340e-001,-1.950611e-001,-1.666502e-001,-5.866258e-002,-1.326390e-003,-1.326390e-003,,,,,,,,,,,,,,,,,,,,
1432843556.553,,2.000000e+004,6.000444e+001,6.000620e+001,1,0,4.300526e+000,1.904355e-001,1.904355e-001,1.412302e-001,3.268340e-001,1.020846e-001,5.287939e-002,2.384831e-001,9.573941e-004,9.573941e-004,,,,,,,,,,,,,,,,,,,,
1432843719.138,,1.000000e+004,5.999037e+001,6.000444e+001,1,0,5.709182e-002,-3.871273e-001,-3.871273e-001,7.882137e-002,1.435207e-001,-2.221841e-001,2.437645e-001,3.084639e-001,-4.868501e-004,-4.868501e-004,,,,,,,,,,,,,,,,,,,,
1432843719.138,,1.000000e+004,5.999037e+001,6.000444e+001,1,0,3.525409e+000,7.626575e-001,7.626575e-001,1.122314e+000,1.293306e+000,-8.553849e-002,2.741184e-001,4.451095e-001,9.591159e-004,9.591159e-004,,,,,,,,,,,,,,,,,,,,
1432843719.138,,1.000000e+004,5.999037e+001,6.000444e+001,1,0,3.431231e+000,4.737999e-001,4.737999e-001,7.271649e-001,1.004448e+000,1.017876e-002,2.635438e-001,5.408267e-001,5.958493e-004,5.958493e-004,,,,,,,,,,,,,,,,,,,,
1432843729.304,,1.000000e+004,6.000092e+001,6.000796e+001,1,0,1.768871e-001,-4.063540e-001,-4.063540e-001,8.447664e-003,1.070516e-001,-1.496727e-001,2.651289e-001,3.637329e-001,-5.110295e-004,-5.110295e-004,,,,,,,,,,,,,,,,,,,,
1432843729.304,,1.000000e+004,6.000092e+001,6.000796e+001,1,0,4.486284e+000,-1.417585e-001,-1.417585e-001,1.536805e-001,3.716471e-001,-2.058140e-001,8.962490e-002,3.075915e-001,-1.782750e-004,-1.782750e-004,,,,,,,,,,,,,,,,,,,,
1432843845.887,,9.000000e+003,5.999740e+001,5.999740e+001,1,0,2.366130e+000,-6.704916e-001,-6.704916e-001,-2.198101e-001,-2.149891e-001,-8.377256e-001,-3.870441e-001,-3.822231e-001,-8.432585e-004,-8.432585e-004,,,,,,,,,,,,,,,,,,,,
1432843845.887,,9.000000e+003,5.999740e+001,5.999740e+001,1,0,8.610370e-001,-4.519791e-001,-4.519791e-001,-1.121822e-001,3.523439e-003,-2.774451e-001,6.235183e-002,1.780574e-001,-5.684414e-004,-5.684414e-004,,,,,,,,,,,,,,,,,,,,
1432843845.887,,9.000000e+003,5.999740e+001,5.999740e+001,1,0,4.984693e+000,-8.497879e-001,-8.497879e-001,-6.208755e-001,-3.942853e-001,-1.927591e-001,3.615332e-002,2.627435e-001,-1.068754e-003,-1.068754e-003,,,,,,,,,,,,,,,,,,,,
1432843855.804,,9.000000e+003,5.999740e+001,5.999565e+001,1,0,1.264864e+000,-6.149480e-002,-6.149480e-002,-1.505022e-002,1.781590e-002,-2.610565e-001,-2.146119e-001,-1.817458e-001,-7.734027e-005,-7.734027e-005,,,,,,,,,,,,,,,,,,,,
1432843855.804,,9.000000e+003,5.999740e+001,5.999565e+001,1,0,1.767174e+000,-4.287850e-001,-4.287851e-001,-5.083272e-001,-3.494744e-001,-4.662176e-001,-5.457598e-001,-3.869069e-001,-5.392709e-004,-5.392709e-004,,,,,,,,,,,,,,,,,,,,
1432843855.804,,9.000000e+003,5.999740e+001,5.999565e+001,1,0,4.715219e+000,-1.167333e-001,-1.167333e-001,-3.222623e-001,-3.742260e-002,2.620321e-001,5.650307e-002,3.413427e-001,-1.468122e-004,-1.468122e-004,,,,,,,,,,,,,,,,,,,,
1432843976.137,,7.000000e+003,5.999916e+001,6.000269e+001,1,0,3.636378e-001,-4.037599e-001,-4.037599e-001,6.720919e-002,1.095437e-001,-2.667869e-001,2.041822e-001,2.465166e-001,-5.078579e-004,-5.078579e-004,,,,,,,,,,,,,,,,,,,,
1432843976.137,,7.000000e+003,5.999916e+001,6.000269e+001,1,0,2.861134e+000,-3.450118e-001,-3.450117e-001,3.743982e-002,1.682918e-001,-4.026817e-001,-2.023012e-002,1.106218e-001,-4.339632e-004,-4.339632e-004,,,,,,,,,,,,,,,,,,,,
1432843976.137,,7.000000e+003,5.999916e+001,6.000269e+001,1,0,3.974565e+000,3.434858e-001,3.434858e-001,6.374199e-001,8.567894e-001,-1.433608e-001,1.505732e-001,3.699427e-001,4.320439e-004,4.320439e-004,,,,,,,,,,,,,,,,,,,,
1432843986.352,,7.000000e+003,6.000269e+001,5.999740e+001,1,0,8.730635e-003,-3.317362e-001,-3.317362e-001,3.922807e-002,1.074403e-001,-1.963067e-001,1.746576e-001,2.428698e-001,-4.172649e-004,-4.172649e-004,,,,,,,,,,,,,,,,,,,,
1432843986.352,,7.000000e+003,6.000269e+001,5.999740e+001,1,0,3.940202e+000,5.603198e-001,5.603198e-001,8.332291e-001,9.994963e-001,-1.150676e-001,1.578416e-001,3.241089e-001,7.047824e-004,7.047824e-004,,,,,,,,,,,,,,,,,,,,
1432843986.352,,7.000000e+003,6.000269e+001,5.999740e+001,1,0,3.027010e+000,-1.875362e-001,-1.875362e-001,-1.268212e-002,2.516403e-001,-1.102120e-001,6.464208e-002,3.289645e-001,-2.358871e-004,-2.358871e-004,,,,,,,,,,,,,,,,,,,,
1432844106.058,,5.000000e+003,6.000092e+001,5.999212e+001,1,0,4.103572e-001,-4.882962e-002,-4.882962e-002,-2.379305e-002,9.818830e-003,1.274532e-001,1.524898e-001,1.861016e-001,-6.142626e-005,-6.142626e-005,,,,,,,,,,,,,,,,,,,,
1432844106.058,,5.000000e+003,6.000092e+001,5.999212e+001,1,0,4.767295e+000,-1.886044e-001,-1.886044e-001,-2.003808e-001,-1.299559e-001,4.379936e-002,3.202292e-002,1.024478e-001,-2.372589e-004,-2.372589e-004,,,,,,,,,,,,,,,,,,,,
1432844116.083,,5.000000e+003,5.999916e+001,5.999740e+001,1,0,1.915477e+000,-4.071169e-001,-4.071169e-001,-1.764333e-001,-1.697482e-001,-5.907031e-001,-3.600195e-001,-3.533344e-001,-5.121414e-004,-5.121414e-004,,,,,,,,,,,,,,,,,,,,
1432844116.083,,5.000000e+003,5.999916e+001,5.999740e+001,1,0,1.200035e+000,-3.105258e-001,-3.105258e-001,-1.310946e-001,-7.315707e-002,-2.849107e-001,-1.054794e-001,-4.754192e-002,-3.906326e-004,-3.906326e-004,,,,,,,,,,,,,,,,,,,,
1432844116.083,,5.000000e+003,5.999916e+001,5.999740e+001,1,0,4.966338e+000,-5.316324e-001,-5.316324e-001,-4.034536e-001,-2.942637e-001,-1.049943e-001,2.318452e-002,1.323745e-001,-6.687784e-004,-6.687784e-004,,,,,,,,,,,,,,,,,,,,
1432844234.915,,3.000000e+003,5.999740e+001,5.999916e+001,1,0,8.665554e-001,-3.970458e-001,-3.970458e-001,2.851381e-002,2.429479e-002,-4.038768e-001,2.168285e-002,1.746383e-002,-4.995317e-004,-4.995317e-004,,,,,,,,,,,,,,,,,,,,
1432844234.915,,3.000000e+003,5.999740e+001,5.999916e+001,1,0,2.189160e+000,-7.022309e-001,-7.022309e-001,-2.645416e-001,-2.808903e-001,-6.427842e-001,-2.050949e-001,-2.214436e-001,-8.834915e-004,-8.834915e-004,,,,,,,,,,,,,,,,,,,,
1432844234.915,,3.000000e+003,5.999740e+001,5.999916e+001,1,0,4.451944e+000,-4.243599e-001,-4.243599e-001,2.545907e-002,-3.019273e-003,-4.142231e-001,3.559582e-002,7.117480e-003,-5.338961e-004,-5.338961e-004,,,,,,,,,,,,,,,,,,,,
1432844254.403,,3.000000e+003,5.999389e+001,5.999037e+001,1,0,1.304962e-001,-1.043275e+000,-1.043275e+000,6.835727e-002,7.367456e-002,-8.648708e-001,2.467617e-001,2.520790e-001,-5.250266e-004,-5.250266e-004,,,,,,,,,,,,,,,,,,,,
1432844254.403,,3.000000e+003,5.999389e+001,5.999037e+001,1,0,3.308344e+000,-2.819910e-001,-2.819910e-001,8.202339e-001,8.349588e-001,-8.824562e-001,2.197687e-001,2.344936e-001,-1.419115e-004,-1.419115e-004,,,,,,,,,,,,,,,,,,,,
1432844254.403,,3.000000e+003,5.999389e+001,5.999037e+001,1,0,3.620483e+000,-1.567125e-001,-1.567125e-001,9.361050e-001,9.602373e-001,-8.321795e-001,2.606380e-001,2.847703e-001,-7.886534e-005,-7.886534e-005,,,,,,,,,,,,,,,,,,,,
1432844373.587,,1.000000e+003,5.999740e+001,5.999389e+001,1,0,9.155644e-002,-1.551408e+000,-1.551408e+000,-1.032095e-002,-1.268293e-001,-1.524796e+000,1.629109e-002,-1.002172e-001,-7.808369e-004,-7.808369e-004,,,,,,,,,,,,,,,,,,,,
1432844373.587,,1.000000e+003,5.999740e+001,5.999389e+001,1,0,4.318010e+000,-1.509140e+000,-1.509140e+000,1.808189e-001,-8.456111e-002,-1.683800e+000,6.158728e-003,-2.592213e-001,-7.595629e-004,-7.595629e-004,,,,,,,,,,,,,,,,,,,,
1432844383.611,,1.000000e+003,5.999740e+001,5.999740e+001,1,0,2.591152e+000,-1.380352e+000,-1.380352e+000,3.482151e-002,3.482151e-002,-1.374782e+000,4.039121e-002,4.039121e-002,-6.947428e-004,-6.947428e-004,,,,,,,,,,,,,,,,,,,,
1432844383.611,,1.000000e+003,5.999740e+001,5.999740e+001,1,0,7.006593e-001,-1.610309e+000,-1.610309e+000,-5.242600e-002,-1.951355e-001,-1.621301e+000,-6.341793e-002,-2.061274e-001,-8.104821e-004,-8.104821e-004,,,,,,,,,,,,,,,,,,,,
1432844383.611,,1.000000e+003,5.999740e+001,5.999740e+001,1,0,4.944367e+000,-2.005829e+000,-2.005829e+000,-3.052365e-001,-5.906554e-001,-1.698105e+000,2.487618e-003,-2.829313e-001,-1.009551e-003,-1.009551e-003,,,,,,,,,,,,,,,,,,,,
1432844494.006,,5.000000e+002,6.000092e+001,5.999389e+001,1,0,1.475588e+000,-7.679983e-001,-7.679983e-001,1.523819e-002,3.106934e-002,-8.166856e-001,-3.344909e-002,-1.761794e-002,-3.865515e-004,-3.865515e-004,,,,,,,,,,,,,,,,,,,,
1432844494.006,,5.000000e+002,6.000092e+001,5.999389e+001,1,0,1.569991e+000,-8.227790e-001,-8.227790e-001,-1.123658e-001,-2.371138e-002,-7.386563e-001,-2.824318e-002,6.041127e-002,-4.141239e-004,-4.141239e-004,,,,,,,,,,,,,,,,,,,,
1432844494.006,,5.000000e+002,6.000092e+001,5.999389e+001,1,0,4.825442e+000,-7.986694e-001,-7.986694e-001,-1.610795e-001,3.982186e-004,-6.365464e-001,1.043433e-003,1.625212e-001,-4.019889e-004,-4.019889e-004,,,,,,,,,,,,,,,,,,,,
1432844503.970,,5.000000e+002,5.999389e+001,5.999389e+001,1,0,5.146379e-001,1.001465e+000,1.001465e+000,1.443528e-002,8.328658e-002,9.671584e-001,-1.987113e-002,4.898018e-002,5.040606e-004,5.040606e-004,,,,,,,,,,,,,,,,,,,,
1432844503.970,,5.000000e+002,5.999389e+001,5.999389e+001,1,0,2.634912e+000,1.077456e+000,1.077456e+000,-6.793157e-002,1.592777e-001,1.167853e+000,2.246508e-002,2.496744e-001,5.423087e-004,5.423087e-004,,,,,,,,,,,,,,,,,,,,
1432844503.970,,5.000000e+002,5.999389e+001,5.999389e+001,1,0,4.141099e+000,1.425062e+000,1.425062e+000,1.213163e-001,5.068836e-001,1.307998e+000,4.252497e-003,3.898198e-001,7.172669e-004,7.172669e-004,,,,,,,,,,,,,,,,,,,,
1432844607.643,,4.000000e+002,5.999740e+001,5.999212e+001,1,0,1.694263e-002,-1.012299e+000,-1.012299e+000,9.518350e-005,-7.108748e-002,-1.008404e+000,3.989751e-003,-6.719291e-002,-5.095167e-004,-5.095167e-004,,,,,,,,,,,,,,,,,,,,
1432844607.643,,4.000000e+002,5.999740e+001,5.999212e+001,1,0,3.736875e+000,-8.581805e-001,-8.581805e-001,2.633604e-001,8.303100e-002,-1.117283e+000,4.258246e-003,-1.760712e-001,-4.319448e-004,-4.319448e-004,,,,,,,,,,,,,,,,,,,,
1432844607.643,,4.000000e+002,5.999740e+001,5.999212e+001,1,0,3.233503e+000,-1.169622e+000,-1.169622e+000,6.106580e-002,-2.284104e-001,-1.221024e+000,9.663947e-003,-2.798122e-001,-5.887015e-004,-5.887015e-004,,,,,,,,,,,,,,,,,,,,
1432844617.464,,4.000000e+002,5.999212e+001,5.999389e+001,1,0,2.841636e-001,-7.628102e-001,-7.628102e-001,-7.622654e-003,-9.605843e-002,-7.601262e-001,-4.938716e-003,-9.337449e-002,-3.839424e-004,-3.839424e-004,,,,,,,,,,,,,,,,,,,,
1432844617.464,,4.000000e+002,5.999212e+001,5.999389e+001,1,0,4.637963e+000,-9.036531e-001,-9.036531e-001,-4.676443e-002,-2.369013e-001,-8.557204e-001,1.168257e-003,-1.889687e-001,-4.548324e-004,-4.548324e-004,,,,,,,,,,,,,,,,,,,,
1432844721.139,,3.000000e+002,6.000092e+001,5.999565e+001,1,0,2.140058e+000,-8.366649e-001,-8.366649e-001,-3.914063e-002,-4.656035e-002,-7.956407e-001,1.883575e-003,-5.536139e-003,-4.211180e-004,-4.211180e-004,,,,,,,,,,,,,,,,,,,,
1432844721.139,,3.000000e+002,6.000092e+001,5.999565e+001,1,0,1.026537e+000,-9.033479e-001,-9.033479e-001,-2.049691e-002,-1.132433e-001,-9.039551e-001,-2.110411e-002,-1.138505e-001,-4.546814e-004,-4.546814e-004,,,,,,,,,,,,,,,,,,,,
1432844721.139,,3.000000e+002,6.000092e+001,5.999565e+001,1,0,4.992931e+000,-1.106906e+000,-1.106906e+000,-1.387286e-001,-3.168017e-001,-9.677879e-001,3.898479e-004,-1.776833e-001,-5.571384e-004,-5.571384e-004,,,,,,,,,,,,,,,,,,,,
1432844731.211,,3.000000e+002,5.999565e+001,5.999389e+001,1,0,1.060940e+000,-3.796503e-001,-3.796503e-001,1.251508e-002,-3.408164e-003,-4.149698e-001,-2.280449e-002,-3.872773e-002,-1.910891e-004,-1.910891e-004,,,,,,,,,,,,,,,,,,,,
1432844731.211,,3.000000e+002,5.999565e+001,5.999389e+001,1,0,1.975348e+000,-5.407880e-001,-5.407880e-001,-9.630344e-002,-1.645459e-001,-4.470304e-001,-2.545872e-003,-7.078832e-002,-2.721944e-004,-2.721944e-004,,,,,,,,,,,,,,,,,,,,
1432844731.211,,3.000000e+002,5.999565e+001,5.999389e+001,1,0,4.591463e+000,-5.468917e-001,-5.468917e-001,-5.008792e-002,-1.706496e-001,-4.960654e-001,7.383586e-004,-1.198233e-001,-2.752666e-004,-2.752666e-004,,,,,,,,,,,,,,,,,,,,
1432844834.637,,2.000000e+002,6.000269e+001,5.999916e+001,1,0,2.341188e-001,-5.012665e-001,-5.012665e-001,9.440979e-003,-5.489007e-002,-5.123536e-001,-1.646081e-003,-6.597713e-002,-2.523036e-004,-2.523036e-004,,,,,,,,,,,,,,,,,,,,
1432844834.637,,2.000000e+002,6.000269e+001,5.999916e+001,1,0,3.086495e+000,-5.905331e-001,-5.905331e-001,4.347555e-002,-1.441567e-001,-6.281813e-001,5.827410e-003,-1.818048e-001,-2.972344e-004,-2.972344e-004,,,,,,,,,,,,,,,,,,,,
1432844834.637,,2.000000e+002,6.000269e+001,5.999916e+001,1,0,3.801619e+000,-6.433302e-001,-6.433302e-001,1.139797e-001,-1.969537e-001,-7.553947e-001,1.915161e-003,-3.090182e-001,-3.238089e-004,-3.238089e-004,,,,,,,,,,,,,,,,,,,,
1432844844.662,,2.000000e+002,5.999916e+001,5.999389e+001,1,0,3.582114e-002,-8.171331e-001,-8.171331e-001,-1.716276e-003,-8.352935e-002,-8.143266e-001,1.090149e-003,-8.072293e-002,-4.112895e-004,-4.112895e-004,,,,,,,,,,,,,,,,,,,,
1432844844.662,,2.000000e+002,5.999916e+001,5.999389e+001,1,0,4.135302e+000,-8.343760e-001,-8.343760e-001,9.172904e-002,-1.007723e-001,-9.252723e-001,8.327886e-004,-1.916686e-001,-4.199684e-004,-4.199684e-004,,,,,,,,,,,,,,,,,,,,
1432844844.662,,2.000000e+002,5.999916e+001,5.999389e+001,1,0,2.812173e+000,-1.098209e+000,-1.098209e+000,-6.141519e-002,-3.646048e-001,-1.031106e+000,5.687837e-003,-2.975018e-001,-5.527638e-004,-5.527638e-004,,,,,,,,,,,,,,,,,,,,
1432844948.451,,1.000000e+002,5.999740e+001,5.999740e+001,1,0,5.506329e-001,-6.466872e-001,-6.466872e-001,-9.011740e-003,-1.261597e-001,-6.408936e-001,-3.218168e-003,-1.203662e-001,-3.255005e-004,-3.255005e-004,,,,,,,,,,,,,,,,,,,,
1432844948.451,,1.000000e+002,5.999740e+001,5.999740e+001,1,0,4.870956e+000,-7.998902e-001,-7.998902e-001,-3.974180e-002,-2.793627e-001,-7.600379e-001,1.104670e-004,-2.395104e-001,-4.026129e-004,-4.026129e-004,,,,,,,,,,,,,,,,,,,,
1432844958.476,,1.000000e+002,6.000092e+001,6.000269e+001,1,0,1.692719e+000,-4.622028e-001,-4.622028e-001,4.833424e-003,-1.613638e-002,-4.702676e-001,-3.231322e-003,-2.420112e-002,-2.326430e-004,-2.326430e-004,,,,,,,,,,,,,,,,,,,,
1432844958.476,,1.000000e+002,6.000092e+001,6.000269e+001,1,0,1.380656e+000,-6.074709e-001,-6.074709e-001,-1.985832e-002,-1.614045e-001,-5.937102e-001,-6.097638e-003,-1.476438e-001,-3.057616e-004,-3.057616e-004,,,,,,,,,,,,,,,,,,,,
1432844958.476,,1.000000e+002,6.000092e+001,6.000269e+001,1,0,4.910812e+000,-7.585375e-001,-7.585375e-001,-5.034856e-002,-3.124711e-001,-7.080405e-001,1.484351e-004,-2.619741e-001,-3.817987e-004,-3.817987e-004,,,,,,,,,,,,,,,,,,,,
1432845089.245,,0.000000e+000,6.000092e+001,6.000444e+001,1,0,6.845836e-001,-4.886013e-001,-4.886013e-001,-3.513000e-004,-4.772118e-002,-4.933252e-001,-5.075207e-003,-5.244508e-002,-1.229659e-004,-1.229659e-004,,,,,,,,,,,,,,,,,,,,
1432845089.245,,0.000000e+000,6.000092e+001,6.000444e+001,1,0,2.409215e+000,-5.946531e-001,-5.946531e-001,1.465325e-002,-1.537730e-001,-5.970718e-001,1.223455e-002,-1.561917e-001,-1.496559e-004,-1.496559e-004,,,,,,,,,,,,,,,,,,,,
1432845089.245,,0.000000e+000,6.000092e+001,6.000444e+001,1,0,4.301407e+000,-7.379376e-001,-7.379376e-001,-7.574836e-003,-2.970574e-001,-7.343685e-001,-4.005770e-003,-2.934884e-001,-1.857161e-004,-1.857161e-004,,,,,,,,,,,,,,,,,,,,
1432845099.771,,0.000000e+000,5.999565e+001,6.000269e+001,1,0,5.740146e-002,-3.950621e-001,-3.950621e-001,-3.136408e-003,-7.170948e-002,-3.997373e-001,-7.811587e-003,-7.638466e-002,-9.942494e-005,-9.942494e-005,,,,,,,,,,,,,,,,,,,,
1432845099.771,,0.000000e+000,5.999565e+001,6.000269e+001,1,0,3.524611e+000,-5.247658e-001,-5.247658e-001,-2.018431e-002,-2.014132e-001,-5.127582e-001,-8.176716e-003,-1.894056e-001,-1.320673e-004,-1.320673e-004,,,,,,,,,,,,,,,,,,,,
1432845099.771,,0.000000e+000,5.999565e+001,6.000269e+001,1,0,3.431901e+000,-6.413465e-001,-6.413465e-001,-2.410921e-002,-3.179938e-001,-6.254320e-001,-8.194767e-003,-3.020794e-001,-1.614071e-004,-1.614071e-004,,,,,,,,,,,,,,,,,,,,
1432845198.245,,-1.000000e+002,6.000444e+001,6.000092e+001,1,0,1.757016e-001,-1.027253e+000,-1.027253e+000,-3.586581e-003,-1.789968e-001,-1.065174e+000,-4.150789e-002,-2.169181e-001,-2.585263e-004,-2.585263e-004,,,,,,,,,,,,,,,,,,,,
1432845198.245,,-1.000000e+002,6.000444e+001,6.000092e+001,1,0,4.486088e+000,-1.270943e+000,-1.270943e+000,-3.493815e-002,-4.226871e-001,-1.250870e+000,-1.486473e-002,-4.026136e-001,-3.198553e-004,-3.198553e-004,,,,,,,,,,,,,,,,,,,,
1432845208.709,,-1.000000e+002,6.000269e+001,6.000269e+001,1,0,2.366839e+000,-3.950621e-001,-3.950621e-001,3.781561e-002,3.179279e-002,-4.373734e-001,-4.495668e-003,-1.051849e-002,-9.942435e-005,-9.942435e-005,,,,,,,,,,,,,,,,,,,,
1432845208.709,,-1.000000e+002,6.000269e+001,6.000269e+001,1,0,8.601640e-001,-5.601673e-001,-5.601673e-001,1.123541e-002,-1.333123e-001,-5.400499e-001,3.135275e-002,-1.131950e-001,-1.409760e-004,-1.409760e-004,,,,,,,,,,,,,,,,,,,,
1432845208.709,,-1.000000e+002,6.000269e+001,6.000269e+001,1,0,4.985321e+000,-5.920591e-001,-5.920591e-001,1.178685e-001,-1.652042e-001,-7.111285e-001,-1.200882e-003,-2.842736e-001,-1.490021e-004,-1.490021e-004,,,,,,,,,,,,,,,,,,,,
1432845313.215,,-2.000000e+002,6.000444e+001,5.999916e+001,1,0,1.265198e+000,-2.829066e-001,-2.829066e-001,-1.305741e-002,-7.564399e-002,-1.908104e-001,7.903881e-002,1.645222e-002,-7.119801e-005,-7.119801e-005,,,,,,,,,,,,,,,,,,,,
1432845313.215,,-2.000000e+002,6.000444e+001,5.999916e+001,1,0,1.767491e+000,-3.436384e-001,-3.436384e-001,1.661260e-001,-1.363758e-001,-4.662213e-001,4.354308e-002,-2.589587e-001,-8.648216e-005,-8.648216e-005,,,,,,,,,,,,,,,,,,,,
1432845313.215,,-2.000000e+002,6.000444e+001,5.999916e+001,1,0,4.717840e+000,-6.372265e-001,-6.372265e-001,1.124532e-001,-4.299639e-001,-7.522718e-001,-2.592187e-003,-5.450093e-001,-1.603683e-004,-1.603683e-004,,,,,,,,,,,,,,,,,,,,
1432845323.929,,-2.000000e+002,5.999916e+001,5.999565e+001,1,0,3.634123e-001,-4.303110e-001,-4.303110e-001,-1.692951e-002,-8.477768e-002,-4.026255e-001,1.075595e-002,-5.709222e-002,-1.082947e-004,-1.082947e-004,,,,,,,,,,,,,,,,,,,,
1432845323.929,,-2.000000e+002,5.999916e+001,5.999565e+001,1,0,2.860722e+000,-5.735954e-001,-5.735954e-001,-1.834957e-002,-2.280621e-001,-5.833338e-001,-2.808802e-002,-2.378005e-001,-1.443545e-004,-1.443545e-004,,,,,,,,,,,,,,,,,,,,
1432845323.929,,-2.000000e+002,5.999916e+001,5.999565e+001,1,0,3.974277e+000,-8.882412e-001,-8.882412e-001,-1.911311e-001,-5.427079e-001,-7.034167e-001,-6.306522e-003,-3.578834e-001,-2.235402e-004,-2.235402e-004,,,,,,,,,,,,,,,,,,,,
1432845428.423,,-3.000000e+002,6.000269e+001,5.999916e+001,1,0,7.920474e-003,-6.164739e-001,-6.164739e-001,-1.961887e-003,-1.355039e-001,-6.312119e-001,-1.669991e-002,-1.502419e-001,-1.551447e-004,-1.551447e-004,,,,,,,,,,,,,,,,,,,,
1432845428.423,,-3.000000e+002,6.000269e+001,5.999916e+001,1,0,3.939668e+000,-1.189459e+000,-1.189459e+000,-3.829803e-001,-7.084889e-001,-8.150023e-001,-8.523652e-003,-3.340322e-001,-2.993447e-004,-2.993447e-004,,,,,,,,,,,,,,,,,,,,
1432845428.423,,-3.000000e+002,6.000269e+001,5.999916e+001,1,0,3.026580e+000,-9.663686e-001,-9.663686e-001,3.207658e-002,-4.853986e-001,-1.032272e+000,-3.382667e-002,-5.513018e-001,-2.432008e-004,-2.432008e-004,,,,,,,,,,,,,,,,,,,,
1432845439.139,,-3.000000e+002,6.000092e+001,6.000269e+001,1,0,4.108222e-001,-5.406354e-001,-5.406354e-001,1.254504e-002,-1.493356e-001,-6.477019e-001,-9.452147e-002,-2.564021e-001,-1.360588e-004,-1.360588e-004,,,,,,,,,,,,,,,,,,,,
1432845439.139,,-3.000000e+002,6.000092e+001,6.000269e+001,1,0,4.766702e+000,-5.912961e-001,-5.912961e-001,1.391821e-001,-1.999963e-001,-7.513129e-001,-2.083466e-002,-3.600131e-001,-1.488083e-004,-1.488083e-004,,,,,,,,,,,,,,,,,,,,
1432845543.618,,-4.000000e+002,5.999916e+001,5.999740e+001,1,0,1.915750e+000,-4.982147e-001,-4.982147e-001,1.146097e-001,8.098197e-002,-5.836550e-001,2.916934e-002,-4.458368e-003,-1.253823e-004,-1.253823e-004,,,,,,,,,,,,,,,,,,,,
1432845543.618,,-4.000000e+002,5.999916e+001,5.999740e+001,1,0,1.199822e+000,-7.736442e-001,-7.736442e-001,9.699260e-002,-1.944476e-001,-7.668558e-001,1.037810e-001,-1.876592e-001,-1.946977e-004,-1.946977e-004,,,,,,,,,,,,,,,,,,,,
1432845543.618,,-4.000000e+002,5.999916e+001,5.999740e+001,1,0,4.967671e+000,-7.730339e-001,-7.730339e-001,3.554154e-001,-1.938372e-001,-1.130660e+000,-2.210912e-003,-5.514635e-001,-1.945441e-004,-1.945441e-004,,,,,,,,,,,,,,,,,,,,
1432845554.082,,-4.000000e+002,5.999740e+001,5.999565e+001,1,0,8.663126e-001,-6.112857e-001,-6.112857e-001,-3.874057e-002,-1.212213e-001,-4.868933e-001,8.565191e-002,3.171176e-003,-1.538381e-004,-1.538381e-004,,,,,,,,,,,,,,,,,,,,
1432845554.082,,-4.000000e+002,5.999740e+001,5.999565e+001,1,0,2.189141e+000,-5.001984e-001,-5.001984e-001,3.094789e-001,-1.013392e-002,-8.147014e-001,-5.024084e-003,-3.246369e-001,-1.258815e-004,-1.258815e-004,,,,,,,,,,,,,,,,,,,,
1432845554.082,,-4.000000e+002,5.999740e+001,5.999565e+001,1,0,4.449641e+000,-1.038697e+000,-1.038697e+000,8.111930e-003,-5.486330e-001,-1.051475e+000,-4.665876e-003,-5.614108e-001,-2.614019e-004,-2.614019e-004,,,,,,,,,,,,,,,,,,,,
1432845658.362,,-5.000000e+002,6.000092e+001,5.999389e+001,1,0,1.307343e-001,-9.572130e-001,-9.572130e-001,-2.687193e-002,-1.890743e-001,-9.418369e-001,-1.149578e-002,-1.736981e-001,-2.408938e-004,-2.408938e-004,,,,,,,,,,,,,,,,,,,,
1432845658.362,,-5.000000e+002,6.000092e+001,5.999389e+001,1,0,3.307921e+000,-1.653035e+000,-1.653035e+000,-4.357206e-001,-8.848963e-001,-1.254078e+000,-3.676330e-002,-4.859390e-001,-4.160056e-004,-4.160056e-004,,,,,,,,,,,,,,,,,,,,
1432845658.362,,-5.000000e+002,6.000092e+001,5.999389e+001,1,0,3.621028e+000,-1.961272e+000,-1.961272e+000,-4.569841e-001,-1.193133e+000,-1.526695e+000,-2.240678e-002,-7.585559e-001,-4.935770e-004,-4.935770e-004,,,,,,,,,,,,,,,,,,,,
1432845668.577,,-5.000000e+002,6.000092e+001,5.999916e+001,1,0,9.374964e-002,-7.399213e-001,-7.399213e-001,6.992025e-003,-2.177647e-001,-7.613552e-001,-1.444192e-002,-2.391987e-001,-1.862098e-004,-1.862098e-004,,,,,,,,,,,,,,,,,,,,
1432845668.577,,-5.000000e+002,6.000092e+001,5.999916e+001,1,0,4.318029e+000,-1.245308e+000,-1.245308e+000,-2.112053e-001,-7.231513e-001,-1.040695e+000,-6.592819e-003,-5.185388e-001,-3.133962e-004,-3.133962e-004,,,,,,,,,,,,,,,,,,,,
1432845779.803,,-1.000000e+003,5.999916e+001,5.999212e+001,1,0,2.591235e+000,-1.652425e+000,-1.652425e+000,-1.927555e-002,-1.927555e-002,-1.720824e+000,-8.767438e-002,-8.767438e-002,-4.158396e-004,-4.158396e-004,,,,,,,,,,,,,,,,,,,,
1432845779.803,,-1.000000e+003,5.999916e+001,5.999212e+001,1,0,7.026233e-001,-2.124241e+000,-2.124241e+000,1.017742e-001,-4.910917e-001,-2.097479e+000,1.285362e-001,-4.643297e-001,-5.345741e-004,-5.345741e-004,,,,,,,,,,,,,,,,,,,,
1432845779.803,,-1.000000e+003,5.999916e+001,5.999212e+001,1,0,4.944417e+000,-2.224494e+000,-2.224494e+000,5.943868e-001,-5.913451e-001,-2.827794e+000,-8.912604e-003,-1.194644e+000,-5.598033e-004,-5.598033e-004,,,,,,,,,,,,,,,,,,,,
1432845790.031,,-1.000000e+003,5.999212e+001,6.000092e+001,1,0,1.475644e+000,-1.342814e+000,-1.342814e+000,6.494248e-002,-5.255914e-002,-1.151983e+000,2.557744e-001,1.382728e-001,-3.379249e-004,-3.379249e-004,,,,,,,,,,,,,,,,,,,,
1432845790.031,,-1.000000e+003,5.999212e+001,6.000092e+001,1,0,1.569812e+000,-1.566820e+000,-1.566820e+000,3.814441e-001,-2.765650e-001,-1.715994e+000,2.322700e-001,-4.257390e-001,-3.942969e-004,-3.942969e-004,,,,,,,,,,,,,,,,,,,,
1432845790.031,,-1.000000e+003,5.999212e+001,6.000092e+001,1,0,4.825627e+000,-1.956084e+000,-1.956084e+000,5.326879e-001,-6.658286e-001,-2.497031e+000,-8.259177e-003,-1.206776e+000,-4.922567e-004,-4.922567e-004,,,,,,,,,,,,,,,,,,,,
1432845924.920,,-3.000000e+003,5.999389e+001,5.999740e+001,1,0,5.139262e-001,-3.181555e-001,-3.181555e-001,-3.506933e-002,-1.297702e-001,-3.784902e-001,-9.540410e-002,-1.901050e-001,-4.002781e-004,-4.002781e-004,,,,,,,,,,,,,,,,,,,,
1432845924.920,,-3.000000e+003,5.999389e+001,5.999740e+001,1,0,2.634642e+000,-3.885006e-001,-3.885006e-001,1.123975e-001,-2.001154e-001,-4.214200e-001,7.947812e-002,-2.330347e-001,-4.887808e-004,-4.887808e-004,,,,,,,,,,,,,,,,,,,,
1432845924.920,,-3.000000e+003,5.999389e+001,5.999740e+001,1,0,4.140693e+000,-9.559923e-001,-9.559923e-001,-2.372822e-001,-7.676070e-001,-7.808937e-001,-6.218361e-002,-5.925084e-001,-1.202754e-003,-1.202754e-003,,,,,,,,,,,,,,,,,,,,
1432845935.134,,-3.000000e+003,5.999389e+001,5.999916e+001,1,0,1.612143e-002,-5.383465e-001,-5.383465e-001,-2.080182e-002,-1.506722e-001,-6.083485e-001,-9.080384e-002,-2.206742e-001,-6.773051e-004,-6.773051e-004,,,,,,,,,,,,,,,,,,,,
1432845935.134,,-3.000000e+003,5.999389e+001,5.999916e+001,1,0,3.737069e+000,-1.207770e+000,-1.207770e+000,-4.910907e-001,-8.200957e-001,-8.160770e-001,-9.939766e-002,-4.284027e-001,-1.519521e-003,-1.519521e-003,,,,,,,,,,,,,,,,,,,,
1432845935.134,,-3.000000e+003,5.999389e+001,5.999916e+001,1,0,3.233850e+000,-1.063265e+000,-1.063265e+000,-1.474509e-001,-6.755905e-001,-9.937374e-001,-7.792343e-002,-6.060631e-001,-1.337716e-003,-1.337716e-003,,,,,,,,,,,,,,,,,,,,
1432846055.312,,-5.000000e+003,5.999565e+001,5.999212e+001,1,0,2.850119e-001,-2.374035e+000,-2.374035e+000,8.773804e-004,-5.440164e-001,-2.534699e+000,-1.597869e-001,-7.046807e-001,-2.986468e-003,-2.986468e-003,,,,,,,,,,,,,,,,,,,,
1432846055.312,,-5.000000e+003,5.999565e+001,5.999212e+001,1,0,4.637962e+000,-2.938780e+000,-2.938780e+000,6.276023e-002,-1.108761e+000,-3.042392e+000,-4.085243e-002,-1.212374e+000,-3.696901e-003,-3.696901e-003,,,,,,,,,,,,,,,,,,,,
1432846065.657,,-5.000000e+003,5.999212e+001,5.999740e+001,1,0,2.140189e+000,2.618488e-001,2.618488e-001,2.024428e-001,1.868752e-001,3.908071e-001,3.314011e-001,3.158335e-001,3.293983e-004,3.293983e-004,,,,,,,,,,,,,,,,,,,,
1432846065.657,,-5.000000e+003,5.999212e+001,5.999740e+001,1,0,1.026520e+000,-2.517777e-002,-2.517777e-002,9.444278e-002,-1.001514e-001,-9.069435e-002,2.892620e-002,-1.656679e-001,-3.167292e-005,-3.167292e-005,,,,,,,,,,,,,,,,,,,,
1432846065.657,,-5.000000e+003,5.999212e+001,5.999740e+001,1,0,4.993105e+000,1.087985e-001,1.087985e-001,4.074456e-001,3.382490e-002,-3.210957e-001,-2.244852e-002,-3.960693e-001,1.368654e-004,1.368654e-004,,,,,,,,,,,,,,,,,,,,
1432846186.138,,-7.000000e+003,5.999916e+001,5.999212e+001,1,0,1.060615e+000,-5.520798e-001,-5.520799e-001,-2.691533e-002,-1.143928e-001,-4.685654e-001,5.659909e-002,-3.087839e-002,-6.944179e-004,-6.944179e-004,,,,,,,,,,,,,,,,,,,,
1432846186.138,,-7.000000e+003,5.999916e+001,5.999212e+001,1,0,1.974457e+000,-3.125095e-001,-3.125095e-001,5.000810e-001,1.251775e-001,-3.400785e-001,4.725120e-001,9.760854e-002,-3.930812e-004,-3.930812e-004,,,,,,,,,,,,,,,,,,,,
1432846186.138,,-7.000000e+003,5.999916e+001,5.999212e+001,1,0,4.589634e+000,-9.845271e-001,-9.845271e-001,1.154894e-001,-5.468401e-001,-1.156971e+000,-5.695442e-002,-7.192839e-001,-1.238359e-003,-1.238359e-003,,,,,,,,,,,,,,,,,,,,
1432846196.915,,-7.000000e+003,5.999212e+001,5.999565e+001,1,0,2.344032e-001,-4.516739e-001,-4.516740e-001,-6.569131e-002,-2.126487e-001,-5.916501e-001,-2.056674e-001,-3.526248e-001,-5.681252e-004,-5.681252e-004,,,,,,,,,,,,,,,,,,,,
1432846196.915,,-7.000000e+003,5.999212e+001,5.999565e+001,1,0,3.086992e+000,-9.981078e-001,-9.981079e-001,-3.304569e-001,-7.590826e-001,-7.613420e-001,-9.369101e-002,-5.223168e-001,-1.255442e-003,-1.255442e-003,,,,,,,,,,,,,,,,,,,,
1432846196.915,,-7.000000e+003,5.999212e+001,5.999565e+001,1,0,3.801936e+000,-1.693930e+000,-1.693930e+000,-7.446106e-001,-1.454905e+000,-1.133482e+000,-1.841630e-001,-8.944571e-001,-2.130662e-003,-2.130662e-003,,,,,,,,,,,,,,,,,,,,
1432846310.650,,-9.000000e+003,5.999565e+001,5.999916e+001,1,0,3.432847e-002,-8.967864e-001,-8.967864e-001,-3.847418e-002,-3.120974e-001,-1.078400e+000,-2.200880e-001,-4.937113e-001,-1.127863e-003,-1.127863e-003,,,,,,,,,,,,,,,,,,,,
1432846310.650,,-9.000000e+003,5.999565e+001,5.999916e+001,1,0,4.134640e+000,-1.977752e+000,-1.977752e+000,-7.492436e-001,-1.393063e+000,-1.376271e+000,-1.477624e-001,-7.915818e-001,-2.487363e-003,-2.487363e-003,,,,,,,,,,,,,,,,,,,,
1432846310.650,,-9.000000e+003,5.999565e+001,5.999916e+001,1,0,2.812156e+000,-1.227149e+000,-1.227149e+000,3.715553e-001,-6.424603e-001,-1.538805e+000,5.989907e-002,-9.541165e-001,-1.543351e-003,-1.543351e-003,,,,,,,,,,,,,,,,,,,,
1432846320.816,,-9.000000e+003,5.999916e+001,5.999212e+001,1,0,5.507834e-001,-8.017213e-001,-8.017212e-001,4.912465e-002,-2.906474e-001,-1.064119e+000,-2.132728e-001,-5.530448e-001,-1.008302e-003,-1.008302e-003,,,,,,,,,,,,,,,,,,,,
1432846320.816,,-9.000000e+003,5.999916e+001,5.999212e+001,1,0,4.870775e+000,-7.431257e-001,-7.431257e-001,4.629364e-001,-2.320518e-001,-1.249736e+000,-4.367398e-002,-7.386622e-001,-9.346083e-004,-9.346083e-004,,,,,,,,,,,,,,,,,,,,
1432846437.129,,-1.000000e+004,6.000269e+001,5.999565e+001,1,0,1.692936e+000,-3.990295e-001,-3.990295e-001,2.075143e-001,1.429652e-001,-4.683164e-002,5.597122e-001,4.951631e-001,-5.018183e-004,-5.018183e-004,,,,,,,,,,,,,,,,,,,,
1432846437.129,,-1.000000e+004,6.000269e+001,5.999565e+001,1,0,1.380493e+000,-6.631672e-001,-6.631672e-001,3.145338e-001,-1.211725e-001,-6.473218e-001,3.303792e-001,-1.053271e-001,-8.339971e-004,-8.339971e-004,,,,,,,,,,,,,,,,,,,,
1432846437.129,,-1.000000e+004,6.000269e+001,5.999565e+001,1,0,4.910017e+000,-7.205420e-001,-7.205420e-001,6.283162e-001,-1.785473e-001,-1.393460e+000,-4.460130e-002,-8.514648e-001,-9.061515e-004,-9.061515e-004,,,,,,,,,,,,,,,,,,,,
1432846447.201,,-1.000000e+004,5.999565e+001,5.999389e+001,1,0,6.836206e-001,-7.405316e-001,-7.405316e-001,-8.289083e-002,-2.248400e-001,-8.319024e-001,-1.742616e-001,-3.162108e-001,-9.312904e-004,-9.312904e-004,,,,,,,,,,,,,,,,,,,,
1432846447.201,,-1.000000e+004,5.999565e+001,5.999389e+001,1,0,2.410271e+000,-4.670858e-001,-4.670858e-001,5.533140e-001,4.860586e-002,-6.317942e-001,3.886056e-001,-1.161025e-001,-5.874057e-004,-5.874057e-004,,,,,,,,,,,,,,,,,,,,
1432846447.201,,-1.000000e+004,5.999565e+001,5.999389e+001,1,0,4.299910e+000,-1.714377e+000,-1.714377e+000,-3.312186e-001,-1.198686e+000,-1.506711e+000,-1.235519e-001,-9.910190e-001,-2.155996e-003,-2.155996e-003,,,,,,,,,,,,,,,,,,,,
1432846611.202,,-2.000000e+004,5.999740e+001,6.000092e+001,1,0,5.740395e-002,-6.443983e-001,-6.443983e-001,-6.952707e-002,-2.457266e-001,-7.834659e-001,-2.085946e-001,-3.847941e-001,-1.619822e-003,-1.619822e-003,,,,,,,,,,,,,,,,,,,,
1432846611.202,,-2.000000e+004,5.999740e+001,6.000092e+001,1,0,3.525903e+000,-1.819208e+000,-1.819208e+000,-9.548664e-001,-1.420537e+000,-1.099809e+000,-2.354666e-001,-7.011368e-001,-4.572938e-003,-4.572938e-003,,,,,,,,,,,,,,,,,,,,
1432846611.202,,-2.000000e+004,5.999740e+001,6.000092e+001,1,0,3.431410e+000,-1.762444e+000,-1.762444e+000,-6.086313e-001,-1.363772e+000,-1.379567e+000,-2.257548e-001,-9.808956e-001,-4.430249e-003,-4.430249e-003,,,,,,,,,,,,,,,,,,,,
1432846621.369,,-2.000000e+004,6.000092e+001,6.000269e+001,1,0,1.760845e-001,-3.669851e-001,-3.669851e-001,-1.140667e-002,-2.233519e-001,-5.833749e-001,-2.277964e-001,-4.397417e-001,-9.224892e-004,-9.224892e-004,,,,,,,,,,,,,,,,,,,,
1432846621.369,,-2.000000e+004,6.000092e+001,6.000269e+001,1,0,4.486374e+000,-7.464827e-001,-7.464827e-001,-1.343390e-001,-6.028495e-001,-6.897699e-001,-7.762617e-002,-5.461367e-001,-1.876431e-003,-1.876431e-003,,,,,,,,,,,,,,,,,,,,
1432846784.165,,-3.000000e+004,6.000092e+001,5.999389e+001,1,0,2.367497e+000,-1.007111e-001,-1.007111e-001,2.837492e-001,2.671557e-001,1.102857e-001,4.947459e-001,4.781524e-001,-2.530063e-004,-2.530063e-004,,,,,,,,,,,,,,,,,,,,
1432846784.165,,-3.000000e+004,6.000092e+001,5.999389e+001,1,0,8.606685e-001,-6.286813e-001,-6.286813e-001,1.374290e-001,-2.608145e-001,-8.493090e-001,-8.319874e-002,-4.814423e-001,-1.579373e-003,-1.579373e-003,,,,,,,,,,,,,,,,,,,,
1432846784.165,,-3.000000e+004,6.000092e+001,5.999389e+001,1,0,4.984984e+000,-3.845332e-001,-3.845332e-001,7.632271e-001,-1.666647e-002,-1.194013e+000,-4.625218e-002,-8.261458e-001,-9.660241e-004,-9.660241e-004,,,,,,,,,,,,,,,,,,,,
1432846794.236,,-3.000000e+004,5.999389e+001,5.999740e+001,1,0,1.265459e+000,-4.705954e-001,-4.705954e-001,2.484217e-002,-7.335442e-002,-2.269009e-001,2.685367e-001,1.703401e-001,-1.182229e-003,-1.182229e-003,,,,,,,,,,,,,,,,,,,,
1432846794.236,,-3.000000e+004,5.999389e+001,5.999740e+001,1,0,1.766828e+000,-2.252266e-001,-2.252266e-001,6.466312e-001,1.720144e-001,-1.806236e-001,6.912342e-001,2.166174e-001,-5.658141e-004,-5.658141e-004,,,,,,,,,,,,,,,,,,,,
1432846794.236,,-3.000000e+004,5.999389e+001,5.999740e+001,1,0,4.719269e+000,-8.497879e-001,-8.497879e-001,3.984902e-001,-4.525469e-001,-1.320251e+000,-7.197277e-002,-9.230099e-001,-2.134837e-003,-2.134837e-003,,,,,,,,,,,,,,,,,,,,
1432846953.014,,-4.000000e+004,5.999916e+001,5.999740e+001,1,0,3.637464e-001,-8.577226e-001,-8.577227e-001,-1.362817e-001,-3.498585e-001,-1.112688e+000,-3.912473e-001,-6.048241e-001,-2.153486e-003,-2.153486e-003,,,,,,,,,,,,,,,,,,,,
1432846953.014,,-4.000000e+004,5.999916e+001,5.999740e+001,1,0,2.860631e+000,-1.218757e+000,-1.218757e+000,-5.074614e-002,-7.108924e-001,-1.121858e+000,4.615254e-002,-6.139938e-001,-3.059934e-003,-3.059934e-003,,,,,,,,,,,,,,,,,,,,
1432846953.014,,-4.000000e+004,5.999916e+001,5.999740e+001,1,0,3.974679e+000,-2.804041e+000,-2.804041e+000,-1.189461e+000,-2.296176e+000,-1.904977e+000,-2.903973e-001,-1.397113e+000,-7.040109e-003,-7.040109e-003,,,,,,,,,,,,,,,,,,,,
1432846963.229,,-4.000000e+004,5.999740e+001,5.999389e+001,1,0,8.958004e-003,-8.719138e-001,-8.719138e-001,-9.115484e-002,-3.990663e-001,-1.111692e+000,-3.309329e-001,-6.388444e-001,-2.189115e-003,-2.189115e-003,,,,,,,,,,,,,,,,,,,,
1432846963.229,,-4.000000e+004,5.999740e+001,5.999389e+001,1,0,3.939708e+000,-2.779321e+000,-2.779321e+000,-1.555939e+000,-2.306473e+000,-1.526261e+000,-3.028798e-001,-1.053414e+000,-6.978045e-003,-6.978045e-003,,,,,,,,,,,,,,,,,,,,
1432846963.229,,-4.000000e+004,5.999740e+001,5.999389e+001,1,0,3.027497e+000,-1.629841e+000,-1.629841e+000,3.616350e-002,-1.156994e+000,-1.784651e+000,-1.186466e-001,-1.311804e+000,-4.092044e-003,-4.092044e-003,,,,,,,,,,,,,,,,,,,,
1432847123.941,,-5.000000e+004,6.000444e+001,6.000092e+001,1,0,4.108130e-001,-8.920560e-001,-8.920560e-001,3.617591e-002,-4.205222e-001,-1.376557e+000,-4.483255e-001,-9.050237e-001,-2.238351e-003,-2.238351e-003,,,,,,,,,,,,,,,,,,,,
1432847123.941,,-5.000000e+004,6.000444e+001,6.000092e+001,1,0,4.766465e+000,-8.824427e-001,-8.824427e-001,5.459825e-001,-4.109089e-001,-1.523490e+000,-9.506477e-002,-1.051956e+000,-2.214229e-003,-2.214229e-003,,,,,,,,,,,,,,,,,,,,
1432847133.965,,-5.000000e+004,5.999565e+001,5.999916e+001,1,0,1.915907e+000,2.365184e-002,2.365185e-002,5.326512e-001,4.677497e-001,5.425558e-001,1.051555e+000,9.866537e-001,5.934732e-005,5.934732e-005,,,,,,,,,,,,,,,,,,,,
1432847133.965,,-5.000000e+004,5.999565e+001,5.999916e+001,1,0,1.199920e+000,-6.263924e-001,-6.263924e-001,3.801853e-001,-1.822945e-001,-7.105235e-001,2.960542e-001,-2.664257e-001,-1.571747e-003,-1.571747e-003,,,,,,,,,,,,,,,,,,,,
1432847133.965,,-5.000000e+004,5.999565e+001,5.999916e+001,1,0,4.966304e+000,-3.842281e-001,-3.842280e-001,1.119928e+000,5.986986e-002,-1.572905e+000,-6.874894e-002,-1.128807e+000,-9.641067e-004,-9.641067e-004,,,,,,,,,,,,,,,,,,,,
1432847297.301,,-6.000000e+004,5.999565e+001,5.999565e+001,1,0,8.670516e-001,-6.656087e-001,-6.656087e-001,-1.179039e-001,-3.084989e-001,-6.799144e-001,-1.322096e-001,-3.228046e-001,-1.669151e-003,-1.669151e-003,,,,,,,,,,,,,,,,,,,,
1432847297.301,,-6.000000e+004,5.999565e+001,5.999565e+001,1,0,2.189491e+000,1.788385e-001,1.788385e-001,1.274504e+000,5.359483e-001,-5.069920e-002,1.044966e+000,3.064106e-001,4.484744e-004,4.484744e-004,,,,,,,,,,,,,,,,,,,,
1432847297.301,,-6.000000e+004,5.999565e+001,5.999565e+001,1,0,4.451271e+000,-1.803339e+000,-1.803339e+000,-1.597129e-001,-1.446229e+000,-1.827402e+000,-1.837757e-001,-1.470292e+000,-4.522245e-003,-4.522245e-003,,,,,,,,,,,,,,,,,,,,
1432847307.468,,-6.000000e+004,5.999565e+001,6.107515e+001,1,0,1.309985e-001,-8.740501e-001,-8.740501e-001,-1.821710e-001,-5.065032e-001,-1.178809e+000,-4.869303e-001,-8.112625e-001,-2.191861e-003,-2.191861e-003,,,,,,,,,,,,,,,,,,,,
1432847307.468,,-6.000000e+004,5.999565e+001,6.107515e+001,1,0,3.307985e+000,-2.744987e+000,-2.744987e+000,-1.479290e+000,-2.377440e+000,-1.696443e+000,-4.307451e-001,-1.328896e+000,-6.883624e-003,-6.883624e-003,,,,,,,,,,,,,,,,,,,,
1432847307.468,,-6.000000e+004,5.999565e+001,6.107515e+001,1,0,3.621047e+000,-3.605151e+000,-3.605151e+000,-1.765635e+000,-3.237605e+000,-2.356818e+000,-5.173015e-001,-1.989271e+000,-9.040663e-003,-9.040663e-003,,,,,,,,,,,,,,,,,,,,
1432847466.812,,-7.000000e+004,6.000444e+001,5.999389e+001,1,0,9.151240e-002,-8.314768e-001,-8.314768e-001,-7.809027e-002,-5.506489e-001,-1.275600e+000,-5.222136e-001,-9.947723e-001,-2.083855e-003,-2.083855e-003,,,,,,,,,,,,,,,,,,,,
1432847466.812,,-7.000000e+004,6.000444e+001,5.999389e+001,1,0,4.317583e+000,-2.346110e+000,-2.346110e+000,-9.888989e-001,-2.065282e+000,-1.610566e+000,-2.533548e-001,-1.329738e+000,-5.879844e-003,-5.879844e-003,,,,,,,,,,,,,,,,,,,,
1432847476.969,,-7.000000e+004,5.999389e+001,5.999740e+001,1,0,2.591290e+000,-3.823969e-001,-3.823969e-001,2.443972e-002,2.443972e-002,1.053505e-001,5.121872e-001,5.121872e-001,-9.583668e-004,-9.583668e-004,,,,,,,,,,,,,,,,,,,,
1432847476.969,,-7.000000e+004,5.999389e+001,5.999740e+001,1,0,7.029257e-001,-8.505508e-001,-8.505508e-001,1.623608e-001,-4.437142e-001,-1.362584e+000,-3.496726e-001,-9.557476e-001,-2.131659e-003,-2.131659e-003,,,,,,,,,,,,,,,,,,,,
1432847476.969,,-7.000000e+004,5.999389e+001,5.999740e+001,1,0,4.943704e+000,-3.949095e-001,-3.949095e-001,1.224077e+000,1.192716e-002,-1.707926e+000,-8.893974e-002,-1.301090e+000,-9.897259e-004,-9.897259e-004,,,,,,,,,,,,,,,,,,,,
1432847646.290,,-6.000000e+004,5.999740e+001,5.999212e+001,1,0,1.475614e+000,1.312296e-001,1.312296e-001,1.963610e-001,8.195972e-002,6.969168e-001,7.620482e-001,6.476470e-001,3.290853e-004,3.290853e-004,,,,,,,,,,,,,,,,,,,,
1432847646.290,,-6.000000e+004,5.999740e+001,5.999212e+001,1,0,1.569477e+000,2.215644e-001,2.215644e-001,8.129417e-001,1.722945e-001,3.064180e-001,8.977953e-001,2.571481e-001,5.556185e-004,5.556185e-004,,,,,,,,,,,,,,,,,,,,
1432847646.290,,-6.000000e+004,5.999740e+001,5.999212e+001,1,0,4.826619e+000,-1.686148e-001,-1.686148e-001,9.490084e-001,-2.178846e-001,-1.214445e+000,-9.682156e-002,-1.263715e+000,-4.228364e-004,-4.228364e-004,,,,,,,,,,,,,,,,,,,,
1432847656.315,,-6.000000e+004,5.999212e+001,5.999212e+001,1,0,5.150216e-001,-6.923124e-001,-6.923124e-001,-1.725438e-001,-3.734814e-001,-9.850329e-001,-4.652643e-001,-6.662018e-001,-1.736116e-003,-1.736116e-003,,,,,,,,,,,,,,,,,,,,
1432847656.315,,-6.000000e+004,5.999212e+001,5.999212e+001,1,0,2.634674e+000,-4.358043e-001,-4.358043e-001,5.461207e-001,-1.169733e-001,-5.830899e-001,3.988351e-001,-2.642589e-001,-1.092869e-003,-1.092869e-003,,,,,,,,,,,,,,,,,,,,
1432847656.315,,-6.000000e+004,5.999212e+001,5.999212e+001,1,0,4.141486e+000,-2.554247e+000,-2.554247e+000,-1.110165e+000,-2.235416e+000,-1.748338e+000,-3.042564e-001,-1.429507e+000,-6.405302e-003,-6.405302e-003,,,,,,,,,,,,,,,,,,,,
1432847810.904,,-5.000000e+004,6.000092e+001,5.999037e+001,1,0,1.645503e-002,-3.340251e-001,-3.340251e-001,-1.260115e-001,-3.897582e-001,-5.981820e-001,-3.901684e-001,-6.539151e-001,-8.381372e-004,-8.381372e-004,,,,,,,,,,,,,,,,,,,,
1432847810.904,,-5.000000e+004,6.000092e+001,5.999037e+001,1,0,3.736575e+000,-2.624134e+000,-2.624134e+000,-2.011709e+000,-2.679867e+000,-1.044788e+000,-4.323630e-001,-1.100521e+000,-6.584489e-003,-6.584489e-003,,,,,,,,,,,,,,,,,,,,
1432847810.904,,-5.000000e+004,6.000092e+001,5.999037e+001,1,0,3.233907e+000,-1.622211e+000,-1.622211e+000,-6.053744e-001,-1.677944e+000,-1.348680e+000,-3.318429e-001,-1.404413e+000,-4.070460e-003,-4.070460e-003,,,,,,,,,,,,,,,,,,,,
1432847821.059,,-5.000000e+004,5.999037e+001,5.999916e+001,1,0,2.853300e-001,-3.396710e-001,-3.396710e-001,-1.043295e-003,-3.510957e-001,-7.982075e-001,-4.595797e-001,-8.096322e-001,-8.523040e-004,-8.523040e-004,,,,,,,,,,,,,,,,,,,,
1432847821.059,,-5.000000e+004,5.999037e+001,5.999916e+001,1,0,4.638022e+000,-5.619984e-001,-5.619984e-001,1.791896e-001,-5.734231e-001,-8.587913e-001,-1.176033e-001,-8.702160e-001,-1.410169e-003,-1.410169e-003,,,,,,,,,,,,,,,,,,,,
1432847980.353,,-4.000000e+004,5.999740e+001,5.998861e+001,1,0,2.140360e+000,5.496384e-001,5.496383e-001,5.022118e-001,4.745117e-001,8.709840e-001,8.235575e-001,7.958574e-001,1.379978e-003,1.379978e-003,,,,,,,,,,,,,,,,,,,,
1432847980.353,,-4.000000e+004,5.999740e+001,5.998861e+001,1,0,1.025387e+000,-3.616443e-002,-3.616443e-002,2.349609e-001,-1.112911e-001,-2.070693e-001,6.405600e-002,-2.821960e-001,-9.079810e-005,-9.079810e-005,,,,,,,,,,,,,,,,,,,,
1432847980.353,,-4.000000e+004,5.999740e+001,5.998861e+001,1,0,4.993053e+000,3.810236e-001,3.810236e-001,9.707007e-001,3.058969e-001,-6.457129e-001,-5.603584e-002,-7.208396e-001,9.566366e-004,9.566366e-004,,,,,,,,,,,,,,,,,,,,
1432847990.379,,-4.000000e+004,5.998861e+001,5.999389e+001,1,0,1.061382e+000,-9.491257e-002,-9.491257e-002,-4.295529e-002,-1.408031e-001,5.037745e-002,1.023347e-001,4.486926e-003,-2.382971e-004,-2.382971e-004,,,,,,,,,,,,,,,,,,,,
1432847990.379,,-4.000000e+004,5.998861e+001,5.999389e+001,1,0,1.974741e+000,5.679494e-001,5.679495e-001,9.414066e-001,5.220590e-001,5.238397e-001,8.972968e-001,4.779491e-001,1.425952e-003,1.425952e-003,,,,,,,,,,,,,,,,,,,,
1432847990.379,,-4.000000e+004,5.998861e+001,5.999389e+001,1,0,4.591622e+000,-4.866176e-001,-4.866176e-001,2.083394e-001,-5.325081e-001,-8.036415e-001,-1.086845e-001,-8.495320e-001,-1.221752e-003,-1.221752e-003,,,,,,,,,,,,,,,,,,,,
1432847990.379,,-4.000000e+004,5.998861e+001,5.999389e+001,1,0,2.812175e+000,-2.626118e-001,-2.626118e-001,5.721278e-001,-3.085023e-001,-7.378054e-001,9.693424e-002,-7.836959e-001,-6.593398e-004,-6.593398e-004,,,,,,,,,,,,,,,,,,,,