File: data/A269/A269_GdN_FC_250_Oe_150528.rso.dat
[Header]
TITLE,MPMS RSO Measurement
BYAPP,MPMS Measurement,1.1,Summary
FILEOPENTIME, 1432776391.982000 5/28/2015, 1:26:31 PM

INFO, APPNAME, MPMS MultiVu Application, Revision 1.61,  Build 082

INFO, NAME, A269
INFO, WEIGHT, 22.300
INFO, AREA, 1.000
INFO, LENGTH, 1.000
INFO, SHAPE, 1
INFO, COMMENT, m = 0.0223g
INFO, SEQUENCE FILE: FC_300K-5K.seq


INFO, BACKGROUND DATA FILE:, None


STARTUPAXIS,X,4,LINEAR,AUTO,0.000000,0.000000
STARTUPAXIS,Y1,5,LINEAR,AUTO,0.000000,0.000000


STARTUPGROUP,Longitudinal
FIELDGROUP,Longitudinal,1,2,3,4,5,6,7,8,9,10,11,19,20,21,22,23,35
FIELDGROUP,Transverse,1,2,3,4,12,13,14,15,16,17,18,24,25,26,27,28,35

PLOT_APPEARANCE,ALL,HORZ_GRID_ON,VERT_GRID_ON,MARKERS_AND_LINES

[Data]
Time,Comment,Field (Oe),Temperature (K),Long Moment (emu),Long Scan Std Dev,Long Offset (cm),Long Offset Std Dev,Long Algorithm,Long Reg Fit,Long Reg Factor,Trans Moment (emu),Trans Scan Std Dev,Trans Offset (cm),Trans Offset Std Dev,Trans Algorithm,Trans Reg Fit,Trans Reg Factor,Long Moment [w/o ABS] (emu),Long Scan Std Dev [w/o ABS],Long Offset [w/o ABS] (cm),Long Offset Std Dev [w/o ABS],Long Reg Fit [w/o ABS],Trans Moment [w/o ABS] (emu),Trans Scan Std Dev [w/o ABS],Trans Offset [w/o ABS] (cm),Trans Offset Std Dev [w/o ABS],Trans Reg Fit [w/o ABS],RSO Position (deg),Amplitude (cm),Frequency,Cycles to Average,Scans per Measurement,Delta Temp (K),Error,EC Comp. Running,Using ABS,
1432776391.979,,2.500000e+002,2.999995e+002,1.481564e-006,0.000000e+000,3.739877e-001,0.000000e+000,3,4.684491e-001,1.825000e+000,,,,,,,,,,,,,,,,,,0,5.000000e+000,5.000000e-001,2,1,1.031494e-002,0,0,0,
1432776520.456,,2.500000e+002,2.976877e+002,1.516053e-006,0.000000e+000,3.878365e-001,0.000000e+000,3,4.800152e-001,1.825000e+000,,,,,,,,,,,,,,,,,,0,5.000000e+000,5.000000e-001,2,1,4.837036e-001,0,0,0,
1432776554.886,,2.500000e+002,2.954001e+002,1.512410e-006,0.000000e+000,4.386821e-001,0.000000e+000,3,4.622875e-001,1.825000e+000,,,,,,,,,,,,,,,,,,0,5.000000e+000,5.000000e-001,2,1,9.710999e-001,0,1,0,
1432776578.787,,2.500000e+002,2.927026e+002,1.522465e-006,0.000000e+000,4.345945e-001,0.000000e+000,3,4.744422e-001,1.825000e+000,,,,,,,,,,,,,,,,,,0,5.000000e+000,5.000000e-001,2,1,1.184906e+000,0,1,0,
1432776601.535,,2.500000e+002,2.895696e+002,1.482699e-006,0.000000e+000,4.708681e-001,0.000000e+000,3,4.550097e-001,1.825000e+000,,,,,,,,,,,,,,,,,,0,5.000000e+000,5.000000e-001,2,1,1.584290e+000,0,1,0,
1432776625.079,,2.500000e+002,2.857599e+002,1.508365e-006,0.000000e+000,5.030591e-001,0.000000e+000,3,4.484692e-001,1.825000e+000,,,,,,,,,,,,,,,,,,0,5.000000e+000,5.000000e-001,2,1,1.621704e+000,0,1,0,
1432776649.169,,2.500000e+002,2.814702e+002,1.516764e-006,0.000000e+000,5.137158e-001,0.000000e+000,3,4.486506e-001,1.825000e+000,,,,,,,,,,,,,,,,,,0,5.000000e+000,5.000000e-001,2,1,1.987488e+000,0,1,0,
1432776674.600,,2.500000e+002,2.766862e+002,1.527074e-006,0.000000e+000,5.522259e-001,0.000000e+000,3,4.605608e-001,1.825000e+000,,,,,,,,,,,,,,,,,,0,5.000000e+000,5.000000e-001,2,1,1.827698e+000,0,1,0,
1432776698.336,,2.500000e+002,2.716971e+002,1.510499e-006,0.000000e+000,6.062621e-001,0.000000e+000,3,4.374492e-001,1.825000e+000,,,,,,,,,,,,,,,,,,0,5.000000e+000,5.000000e-001,2,1,2.225098e+000,0,1,0,
1432776722.767,,2.500000e+002,2.667206e+002,1.556914e-006,0.000000e+000,6.404617e-001,0.000000e+000,3,4.361841e-001,1.825000e+000,,,,,,,,,,,,,,,,,,0,5.000000e+000,5.000000e-001,2,1,2.269623e+000,0,1,0,
1432776746.700,,2.500000e+002,2.616397e+002,1.591892e-006,0.000000e+000,6.408493e-001,0.000000e+000,3,4.438405e-001,1.825000e+000,,,,,,,,,,,,,,,,,,0,5.000000e+000,5.000000e-001,2,1,2.106415e+000,0,1,0,
1432776770.908,,2.500000e+002,2.564882e+002,1.622469e-006,0.000000e+000,6.875391e-001,0.000000e+000,3,4.546943e-001,1.825000e+000,,,,,,,,,,,,,,,,,,0,5.000000e+000,5.000000e-001,2,1,2.133911e+000,0,1,0,
1432776795.134,,2.500000e+002,2.513177e+002,1.625325e-006,0.000000e+000,7.416807e-001,0.000000e+000,3,4.522965e-001,1.825000e+000,,,,,,,,,,,,,,,,,,0,5.000000e+000,5.000000e-001,2,1,2.153992e+000,0,1,0,
1432776819.313,,2.500000e+002,2.461927e+002,1.658463e-006,0.000000e+000,7.621207e-001,0.000000e+000,3,4.653256e-001,1.825000e+000,,,,,,,,,,,,,,,,,,0,5.000000e+000,5.000000e-001,2,1,2.121201e+000,0,1,0,
1432776844.032,,2.500000e+002,2.412341e+002,1.703709e-006,0.000000e+000,8.020166e-001,0.000000e+000,3,4.655636e-001,1.825000e+000,,,,,,,,,,,,,,,,,,0,5.000000e+000,5.000000e-001,2,1,2.320404e+000,0,1,0,
1432776868.462,,2.500000e+002,2.361685e+002,1.761858e-006,0.000000e+000,8.191331e-001,0.000000e+000,3,4.923224e-001,1.825000e+000,,,,,,,,,,,,,,,,,,0,5.000000e+000,5.000000e-001,2,1,2.032806e+000,0,1,0,
1432776892.692,,2.500000e+002,2.314934e+002,1.838590e-006,0.000000e+000,8.457713e-001,0.000000e+000,3,4.986957e-001,1.825000e+000,,,,,,,,,,,,,,,,,,0,5.000000e+000,5.000000e-001,2,1,2.036301e+000,0,1,0,
1432776917.170,,2.500000e+002,2.269997e+002,1.848361e-006,0.000000e+000,8.683641e-001,0.000000e+000,3,5.091783e-001,1.825000e+000,,,,,,,,,,,,,,,,,,0,5.000000e+000,5.000000e-001,2,1,1.900192e+000,0,1,0,
1432776941.377,,2.500000e+002,2.226212e+002,1.885288e-006,0.000000e+000,8.800037e-001,0.000000e+000,3,5.241642e-001,1.825000e+000,,,,,,,,,,,,,,,,,,0,5.000000e+000,5.000000e-001,2,1,1.744507e+000,0,1,0,
1432776964.059,,2.500000e+002,2.183855e+002,1.972837e-006,0.000000e+000,8.966022e-001,0.000000e+000,3,5.340950e-001,1.825000e+000,,,,,,,,,,,,,,,,,,0,5.000000e+000,5.000000e-001,2,1,1.925903e+000,0,1,0,
1432776987.796,,2.500000e+002,2.141783e+002,2.041288e-006,0.000000e+000,9.124202e-001,0.000000e+000,3,5.414109e-001,1.825000e+000,,,,,,,,,,,,,,,,,,0,5.000000e+000,5.000000e-001,2,1,1.618103e+000,0,1,0,
1432777012.572,,2.500000e+002,2.100435e+002,2.103983e-006,0.000000e+000,9.280994e-001,0.000000e+000,3,5.601629e-001,1.825000e+000,,,,,,,,,,,,,,,,,,0,5.000000e+000,5.000000e-001,2,1,1.657700e+000,0,1,0,
1432777036.035,,2.500000e+002,2.062491e+002,2.135271e-006,0.000000e+000,9.261551e-001,0.000000e+000,3,5.656236e-001,1.825000e+000,,,,,,,,,,,,,,,,,,0,5.000000e+000,5.000000e-001,2,1,1.623413e+000,0,1,0,
1432777060.774,,2.500000e+002,2.023660e+002,2.262522e-006,0.000000e+000,9.549819e-001,0.000000e+000,3,5.790797e-001,1.825000e+000,,,,,,,,,,,,,,,,,,0,5.000000e+000,5.000000e-001,2,1,1.542603e+000,0,1,0,
1432777083.731,,2.500000e+002,1.987204e+002,2.296265e-006,0.000000e+000,9.635029e-001,0.000000e+000,3,5.860529e-001,1.825000e+000,,,,,,,,,,,,,,,,,,0,5.000000e+000,5.000000e-001,2,1,1.448608e+000,0,1,0,
1432777106.160,,2.500000e+002,1.952919e+002,2.353426e-006,0.000000e+000,9.803732e-001,0.000000e+000,3,5.967059e-001,1.825000e+000,,,,,,,,,,,,,,,,,,0,5.000000e+000,5.000000e-001,2,1,1.437195e+000,0,1,0,
1432777128.849,,2.500000e+002,1.921255e+002,2.435365e-006,0.000000e+000,9.809902e-001,0.000000e+000,3,6.023616e-001,1.825000e+000,,,,,,,,,,,,,,,,,,0,5.000000e+000,5.000000e-001,2,1,1.313705e+000,0,1,0,
1432777151.528,,2.500000e+002,1.886330e+002,2.488307e-006,0.000000e+000,9.932015e-001,0.000000e+000,3,6.187717e-001,1.825000e+000,,,,,,,,,,,,,,,,,,0,5.000000e+000,5.000000e-001,2,1,1.557800e+000,0,1,0,
1432777176.249,,2.500000e+002,1.850858e+002,2.595325e-006,0.000000e+000,1.007574e+000,0.000000e+000,3,6.441449e-001,1.825000e+000,,,,,,,,,,,,,,,,,,0,5.000000e+000,5.000000e-001,2,1,1.606094e+000,0,1,0,
1432777199.360,,2.500000e+002,1.817813e+002,2.653275e-006,0.000000e+000,1.005070e+000,0.000000e+000,3,6.424333e-001,1.825000e+000,,,,,,,,,,,,,,,,,,0,5.000000e+000,5.000000e-001,2,1,1.589798e+000,0,1,0,
1432777222.400,,2.500000e+002,1.784043e+002,2.760006e-006,0.000000e+000,1.015039e+000,0.000000e+000,3,6.573613e-001,1.825000e+000,,,,,,,,,,,,,,,,,,0,5.000000e+000,5.000000e-001,2,1,1.398499e+000,0,1,0,
1432777245.618,,2.500000e+002,1.752362e+002,2.879103e-006,0.000000e+000,1.028137e+000,0.000000e+000,3,6.643171e-001,1.825000e+000,,,,,,,,,,,,,,,,,,0,5.000000e+000,5.000000e-001,2,1,1.550797e+000,0,1,0,
1432777269.246,,2.500000e+002,1.718884e+002,7.590897e-007,0.000000e+000,0.000000e+000,0.000000e+000,3,0.000000e+000,1.825000e+000,,,,,,,,,,,,,,,,,,0,5.000000e+000,5.000000e-001,2,1,1.375305e+000,0,1,0,
1432777292.570,,2.500000e+002,1.686644e+002,7.693473e-007,0.000000e+000,0.000000e+000,0.000000e+000,3,0.000000e+000,1.825000e+000,,,,,,,,,,,,,,,,,,0,5.000000e+000,5.000000e-001,2,1,1.350494e+000,0,1,0,
1432777315.000,,2.500000e+002,1.657159e+002,7.248696e-007,0.000000e+000,0.000000e+000,0.000000e+000,3,0.000000e+000,1.825000e+000,,,,,,,,,,,,,,,,,,0,5.000000e+000,5.000000e-001,2,1,1.487305e+000,0,1,0,
1432777337.682,,2.500000e+002,1.626154e+002,7.408882e-007,0.000000e+000,0.000000e+000,0.000000e+000,3,0.000000e+000,1.825000e+000,,,,,,,,,,,,,,,,,,0,5.000000e+000,5.000000e-001,2,1,1.304108e+000,0,1,0,
1432777360.611,,2.500000e+002,1.596219e+002,6.979000e-007,0.000000e+000,0.000000e+000,0.000000e+000,3,0.000000e+000,1.825000e+000,,,,,,,,,,,,,,,,,,0,5.000000e+000,5.000000e-001,2,1,1.311493e+000,0,1,0,
1432777383.615,,2.500000e+002,1.566625e+002,6.857589e-007,0.000000e+000,0.000000e+000,0.000000e+000,3,0.000000e+000,1.825000e+000,,,,,,,,,,,,,,,,,,0,5.000000e+000,5.000000e-001,2,1,1.286392e+000,0,1,0,
1432777406.045,,2.500000e+002,1.537714e+002,6.513584e-007,0.000000e+000,0.000000e+000,0.000000e+000,3,0.000000e+000,1.825000e+000,,,,,,,,,,,,,,,,,,0,5.000000e+000,5.000000e-001,2,1,1.335495e+000,0,1,0,
1432777428.740,,2.500000e+002,1.507598e+002,6.036528e-007,0.000000e+000,0.000000e+000,0.000000e+000,3,0.000000e+000,1.825000e+000,,,,,,,,,,,,,,,,,,0,5.000000e+000,5.000000e-001,2,1,1.313004e+000,0,1,0,
1432777451.742,,2.500000e+002,1.477065e+002,-1.133263e-006,0.000000e+000,-1.480947e+000,0.000000e+000,3,0.000000e+000,1.825000e+000,,,,,,,,,,,,,,,,,,0,5.000000e+000,5.000000e-001,2,1,1.422607e+000,0,1,0,
1432777474.945,,2.500000e+002,1.444106e+002,-1.163866e-006,0.000000e+000,-1.474699e+000,0.000000e+000,3,0.000000e+000,1.825000e+000,,,,,,,,,,,,,,,,,,0,5.000000e+000,5.000000e-001,2,1,1.440903e+000,0,1,0,
1432777498.680,,2.500000e+002,1.410177e+002,-6.525916e-007,0.000000e+000,-2.301703e+000,0.000000e+000,3,0.000000e+000,1.825000e+000,,,,,,,,,,,,,,,,,,0,5.000000e+000,5.000000e-001,2,1,1.399902e+000,0,1,0,
1432777520.858,,2.500000e+002,1.377001e+002,4.497439e-007,0.000000e+000,0.000000e+000,0.000000e+000,3,0.000000e+000,1.825000e+000,,,,,,,,,,,,,,,,,,0,5.000000e+000,5.000000e-001,2,1,1.190308e+000,0,1,0,
1432777543.080,,2.500000e+002,1.341934e+002,4.595436e-006,0.000000e+000,1.095058e+000,0.000000e+000,3,7.887891e-001,1.825000e+000,,,,,,,,,,,,,,,,,,0,5.000000e+000,5.000000e-001,2,1,1.460602e+000,0,1,0,
1432777565.261,,2.500000e+002,1.306936e+002,4.845735e-006,0.000000e+000,1.110389e+000,0.000000e+000,3,8.055481e-001,1.825000e+000,,,,,,,,,,,,,,,,,,0,5.000000e+000,5.000000e-001,2,1,1.519196e+000,0,1,0,
1432777587.440,,2.500000e+002,1.271089e+002,5.078135e-006,0.000000e+000,1.114629e+000,0.000000e+000,3,8.158159e-001,1.825000e+000,,,,,,,,,,,,,,,,,,0,5.000000e+000,5.000000e-001,2,1,1.561203e+000,0,1,0,
1432777609.869,,2.500000e+002,1.235082e+002,5.394904e-006,0.000000e+000,1.113357e+000,0.000000e+000,3,8.208205e-001,1.825000e+000,,,,,,,,,,,,,,,,,,0,5.000000e+000,5.000000e-001,2,1,1.724396e+000,0,1,0,
1432777632.572,,2.500000e+002,1.196946e+002,5.714536e-006,0.000000e+000,1.128191e+000,0.000000e+000,3,8.290610e-001,1.825000e+000,,,,,,,,,,,,,,,,,,0,5.000000e+000,5.000000e-001,2,1,1.533401e+000,0,1,0,
1432777655.500,,2.500000e+002,1.160191e+002,-1.628076e-008,0.000000e+000,0.000000e+000,0.000000e+000,3,0.000000e+000,1.825000e+000,,,,,,,,,,,,,,,,,,0,5.000000e+000,5.000000e-001,2,1,1.720207e+000,0,1,0,
1432777679.644,,2.500000e+002,1.116302e+002,-1.254622e-007,0.000000e+000,0.000000e+000,0.000000e+000,3,0.000000e+000,1.825000e+000,,,,,,,,,,,,,,,,,,0,5.000000e+000,5.000000e-001,2,1,1.665901e+000,0,1,0,
1432777704.181,,2.500000e+002,1.067935e+002,-3.146739e-007,0.000000e+000,0.000000e+000,0.000000e+000,3,0.000000e+000,1.825000e+000,,,,,,,,,,,,,,,,,,0,5.000000e+000,5.000000e-001,2,1,1.723099e+000,0,1,0,
1432777727.873,,2.500000e+002,1.026050e+002,-4.198333e-007,0.000000e+000,0.000000e+000,0.000000e+000,3,0.000000e+000,1.825000e+000,,,,,,,,,,,,,,,,,,0,5.000000e+000,5.000000e-001,2,1,1.712807e+000,0,1,0,
1432778207.465,,2.500000e+002,1.000034e+002,-4.419177e-007,0.000000e+000,0.000000e+000,0.000000e+000,3,0.000000e+000,1.825000e+000,,,,,,,,,,,,,,,,,,0,5.000000e+000,5.000000e-001,2,1,3.952789e-002,0,1,0,
1432778228.393,,2.500000e+002,1.000022e+002,-4.417819e-007,0.000000e+000,0.000000e+000,0.000000e+000,3,0.000000e+000,1.825000e+000,,,,,,,,,,,,,,,,,,0,5.000000e+000,5.000000e-001,2,1,9.300232e-003,0,1,0,
1432778249.571,,2.500000e+002,9.998946e+001,-4.463133e-007,0.000000e+000,0.000000e+000,0.000000e+000,3,0.000000e+000,1.825000e+000,,,,,,,,,,,,,,,,,,0,5.000000e+000,5.000000e-001,2,1,2.334595e-003,0,1,0,
1432778270.558,,2.500000e+002,1.000266e+002,-4.469923e-007,0.000000e+000,0.000000e+000,0.000000e+000,3,0.000000e+000,1.825000e+000,,,,,,,,,,,,,,,,,,0,5.000000e+000,5.000000e-001,2,1,2.304077e-003,0,1,0,
1432778292.012,,2.500000e+002,1.000092e+002,-4.126343e-007,0.000000e+000,0.000000e+000,0.000000e+000,3,0.000000e+000,1.825000e+000,,,,,,,,,,,,,,,,,,0,5.000000e+000,5.000000e-001,2,1,2.790833e-002,0,1,0,
1432778313.693,,2.500000e+002,1.000092e+002,-4.161135e-007,0.000000e+000,0.000000e+000,0.000000e+000,3,0.000000e+000,1.825000e+000,,,,,,,,,,,,,,,,,,0,5.000000e+000,5.000000e-001,2,1,1.390076e-002,0,1,0,
1432778335.123,,2.500000e+002,1.000092e+002,-4.445857e-007,0.000000e+000,0.000000e+000,0.000000e+000,3,0.000000e+000,1.825000e+000,,,,,,,,,,,,,,,,,,0,5.000000e+000,5.000000e-001,2,1,0.000000e+000,0,1,0,
1432778356.053,,2.500000e+002,1.000069e+002,-4.186124e-007,0.000000e+000,0.000000e+000,0.000000e+000,3,0.000000e+000,1.825000e+000,,,,,,,,,,,,,,,,,,0,5.000000e+000,5.000000e-001,2,1,4.600525e-003,0,1,0,
1432778377.231,,2.500000e+002,1.000208e+002,-4.356692e-007,0.000000e+000,0.000000e+000,0.000000e+000,3,0.000000e+000,1.825000e+000,,,,,,,,,,,,,,,,,,0,5.000000e+000,5.000000e-001,2,1,9.300232e-003,0,1,0,
1432778398.114,,2.500000e+002,1.000127e+002,-4.275977e-007,0.000000e+000,0.000000e+000,0.000000e+000,3,0.000000e+000,1.825000e+000,,,,,,,,,,,,,,,,,,0,5.000000e+000,5.000000e-001,2,1,2.304077e-003,0,1,0,
1432778419.459,,2.500000e+002,1.000197e+002,-4.393535e-007,0.000000e+000,0.000000e+000,0.000000e+000,3,0.000000e+000,1.825000e+000,,,,,,,,,,,,,,,,,,0,5.000000e+000,5.000000e-001,2,1,1.159668e-002,0,1,0,
1432778440.839,,2.500000e+002,1.000255e+002,-4.174763e-007,0.000000e+000,0.000000e+000,0.000000e+000,3,0.000000e+000,1.825000e+000,,,,,,,,,,,,,,,,,,0,5.000000e+000,5.000000e-001,2,1,0.000000e+000,0,1,0,
1432778462.182,,2.500000e+002,1.000116e+002,-4.387645e-007,0.000000e+000,0.000000e+000,0.000000e+000,3,0.000000e+000,1.825000e+000,,,,,,,,,,,,,,,,,,0,5.000000e+000,5.000000e-001,2,1,9.300232e-003,0,1,0,
1432778483.344,,2.500000e+002,1.000163e+002,-4.447491e-007,0.000000e+000,0.000000e+000,0.000000e+000,3,0.000000e+000,1.825000e+000,,,,,,,,,,,,,,,,,,0,5.000000e+000,5.000000e-001,2,1,9.300232e-003,0,1,0,
1432778504.433,,2.500000e+002,1.000034e+002,-4.454065e-007,0.000000e+000,0.000000e+000,0.000000e+000,3,0.000000e+000,1.825000e+000,,,,,,,,,,,,,,,,,,0,5.000000e+000,5.000000e-001,2,1,2.304077e-003,0,1,0,
1432778525.592,,2.500000e+002,9.999995e+001,-4.218621e-007,0.000000e+000,0.000000e+000,0.000000e+000,3,0.000000e+000,1.825000e+000,,,,,,,,,,,,,,,,,,0,5.000000e+000,5.000000e-001,2,1,4.699707e-003,0,1,0,
1432778546.865,,2.500000e+002,1.000150e+002,-4.059725e-007,0.000000e+000,0.000000e+000,0.000000e+000,3,0.000000e+000,1.825000e+000,,,,,,,,,,,,,,,,,,0,5.000000e+000,5.000000e-001,2,1,2.296448e-003,0,1,0,
1432778568.385,,2.500000e+002,1.000069e+002,-4.271607e-007,0.000000e+000,0.000000e+000,0.000000e+000,3,0.000000e+000,1.825000e+000,,,,,,,,,,,,,,,,,,0,5.000000e+000,5.000000e-001,2,1,9.300232e-003,0,1,0,
1432778589.705,,2.500000e+002,1.000034e+002,-4.276108e-007,0.000000e+000,0.000000e+000,0.000000e+000,3,0.000000e+000,1.825000e+000,,,,,,,,,,,,,,,,,,0,5.000000e+000,5.000000e-001,2,1,6.973267e-003,0,1,0,
1432778610.801,,2.500000e+002,1.000080e+002,-4.076861e-007,0.000000e+000,0.000000e+000,0.000000e+000,3,0.000000e+000,1.825000e+000,,,,,,,,,,,,,,,,,,0,5.000000e+000,5.000000e-001,2,1,2.304077e-003,0,1,0,
1432778632.521,,2.500000e+002,9.999760e+001,-3.978477e-007,0.000000e+000,0.000000e+000,0.000000e+000,3,0.000000e+000,1.825000e+000,,,,,,,,,,,,,,,,,,0,5.000000e+000,5.000000e-001,2,1,0.000000e+000,0,1,0,
1432778653.238,,2.500000e+002,9.999062e+001,-4.128191e-007,0.000000e+000,0.000000e+000,0.000000e+000,3,0.000000e+000,1.825000e+000,,,,,,,,,,,,,,,,,,0,5.000000e+000,5.000000e-001,2,1,4.646301e-003,0,1,0,
1432778674.267,,2.500000e+002,9.999995e+001,-4.102895e-007,0.000000e+000,0.000000e+000,0.000000e+000,3,0.000000e+000,1.825000e+000,,,,,,,,,,,,,,,,,,0,5.000000e+000,5.000000e-001,2,1,4.699707e-003,0,1,0,
1432778695.070,,2.500000e+002,9.999876e+001,-4.210727e-007,0.000000e+000,0.000000e+000,0.000000e+000,3,0.000000e+000,1.825000e+000,,,,,,,,,,,,,,,,,,0,5.000000e+000,5.000000e-001,2,1,2.326965e-003,0,1,0,
1432778716.500,,2.500000e+002,9.999297e+001,-4.344334e-007,0.000000e+000,0.000000e+000,0.000000e+000,3,0.000000e+000,1.825000e+000,,,,,,,,,,,,,,,,,,0,5.000000e+000,5.000000e-001,2,1,4.661560e-003,0,1,0,
1432778737.990,,2.500000e+002,1.000034e+002,-4.009858e-007,0.000000e+000,0.000000e+000,0.000000e+000,3,0.000000e+000,1.825000e+000,,,,,,,,,,,,,,,,,,0,5.000000e+000,5.000000e-001,2,1,2.304077e-003,0,1,0,
1432778759.030,,2.500000e+002,9.999992e+001,-4.204799e-007,0.000000e+000,0.000000e+000,0.000000e+000,3,0.000000e+000,1.825000e+000,,,,,,,,,,,,,,,,,,0,5.000000e+000,5.000000e-001,2,1,0.000000e+000,0,1,0,
1432778780.266,,2.500000e+002,9.998598e+001,-4.520199e-007,0.000000e+000,0.000000e+000,0.000000e+000,3,0.000000e+000,1.825000e+000,,,,,,,,,,,,,,,,,,0,5.000000e+000,5.000000e-001,2,1,0.000000e+000,0,1,0,
1432778801.720,,2.500000e+002,9.998830e+001,-3.996178e-007,0.000000e+000,0.000000e+000,0.000000e+000,3,0.000000e+000,1.825000e+000,,,,,,,,,,,,,,,,,,0,5.000000e+000,5.000000e-001,2,1,0.000000e+000,0,1,0,
1432778823.451,,2.500000e+002,9.998483e+001,-4.507959e-007,0.000000e+000,0.000000e+000,0.000000e+000,3,0.000000e+000,1.825000e+000,,,,,,,,,,,,,,,,,,0,5.000000e+000,5.000000e-001,2,1,2.304077e-003,0,1,0,
1432778844.481,,2.500000e+002,9.999762e+001,-3.980193e-007,0.000000e+000,0.000000e+000,0.000000e+000,3,0.000000e+000,1.825000e+000,,,,,,,,,,,,,,,,,,0,5.000000e+000,5.000000e-001,2,1,9.353638e-003,0,1,0,
1432778865.505,,2.500000e+002,9.999294e+001,-4.131303e-007,0.000000e+000,0.000000e+000,0.000000e+000,3,0.000000e+000,1.825000e+000,,,,,,,,,,,,,,,,,,0,5.000000e+000,5.000000e-001,2,1,0.000000e+000,0,1,0,
1432778887.006,,2.500000e+002,9.999877e+001,-4.292123e-007,0.000000e+000,0.000000e+000,0.000000e+000,3,0.000000e+000,1.825000e+000,,,,,,,,,,,,,,,,,,0,5.000000e+000,5.000000e-001,2,1,1.165771e-002,0,1,0,
1432778908.528,,2.500000e+002,9.999643e+001,-4.101255e-007,0.000000e+000,0.000000e+000,0.000000e+000,3,0.000000e+000,1.825000e+000,,,,,,,,,,,,,,,,,,0,5.000000e+000,5.000000e-001,2,1,6.980896e-003,0,1,0,
1432778929.498,,2.500000e+002,9.998946e+001,-4.124491e-007,0.000000e+000,0.000000e+000,0.000000e+000,3,0.000000e+000,1.825000e+000,,,,,,,,,,,,,,,,,,0,5.000000e+000,5.000000e-001,2,1,2.334595e-003,0,1,0,
1432778950.262,,2.500000e+002,9.999063e+001,-4.424122e-007,0.000000e+000,0.000000e+000,0.000000e+000,3,0.000000e+000,1.825000e+000,,,,,,,,,,,,,,,,,,0,5.000000e+000,5.000000e-001,2,1,9.315491e-003,0,1,0,
1432778971.272,,2.500000e+002,9.999529e+001,-4.382194e-007,0.000000e+000,0.000000e+000,0.000000e+000,3,0.000000e+000,1.825000e+000,,,,,,,,,,,,,,,,,,0,5.000000e+000,5.000000e-001,2,1,0.000000e+000,0,1,0,
1432778992.279,,2.500000e+002,9.999179e+001,-4.293990e-007,0.000000e+000,0.000000e+000,0.000000e+000,3,0.000000e+000,1.825000e+000,,,,,,,,,,,,,,,,,,0,5.000000e+000,5.000000e-001,2,1,2.311707e-003,0,1,0,
1432779013.710,,2.500000e+002,9.999643e+001,-3.812117e-007,0.000000e+000,0.000000e+000,0.000000e+000,3,0.000000e+000,1.825000e+000,,,,,,,,,,,,,,,,,,0,5.000000e+000,5.000000e-001,2,1,6.980896e-003,0,1,0,
1432779034.963,,2.500000e+002,9.998714e+001,-4.276939e-007,0.000000e+000,0.000000e+000,0.000000e+000,3,0.000000e+000,1.825000e+000,,,,,,,,,,,,,,,,,,0,5.000000e+000,5.000000e-001,2,1,2.319336e-003,0,1,0,
1432779056.182,,2.500000e+002,9.999414e+001,-4.340139e-007,0.000000e+000,0.000000e+000,0.000000e+000,3,0.000000e+000,1.825000e+000,,,,,,,,,,,,,,,,,,0,5.000000e+000,5.000000e-001,2,1,1.631927e-002,0,1,0,
1432779077.109,,2.500000e+002,9.999992e+001,-4.187543e-007,0.000000e+000,0.000000e+000,0.000000e+000,3,0.000000e+000,1.825000e+000,,,,,,,,,,,,,,,,,,0,5.000000e+000,5.000000e-001,2,1,0.000000e+000,0,1,0,
1432779099.103,,2.500000e+002,9.999179e+001,-4.038111e-007,0.000000e+000,0.000000e+000,0.000000e+000,3,0.000000e+000,1.825000e+000,,,,,,,,,,,,,,,,,,0,5.000000e+000,5.000000e-001,2,1,6.996155e-003,0,1,0,
1432779119.918,,2.500000e+002,9.999529e+001,-3.834616e-007,0.000000e+000,0.000000e+000,0.000000e+000,3,0.000000e+000,1.825000e+000,,,,,,,,,,,,,,,,,,0,5.000000e+000,5.000000e-001,2,1,1.862335e-002,0,1,0,
1432779140.901,,2.500000e+002,9.999879e+001,-3.875405e-007,0.000000e+000,0.000000e+000,0.000000e+000,3,0.000000e+000,1.825000e+000,,,,,,,,,,,,,,,,,,0,5.000000e+000,5.000000e-001,2,1,7.003784e-003,0,1,0,
1432779161.633,,2.500000e+002,1.000011e+002,-3.917588e-007,0.000000e+000,0.000000e+000,0.000000e+000,3,0.000000e+000,1.825000e+000,,,,,,,,,,,,,,,,,,0,5.000000e+000,5.000000e-001,2,1,2.372742e-003,0,1,0,
1432779182.676,,2.500000e+002,9.999295e+001,-3.989527e-007,0.000000e+000,0.000000e+000,0.000000e+000,3,0.000000e+000,1.825000e+000,,,,,,,,,,,,,,,,,,0,5.000000e+000,5.000000e-001,2,1,1.394653e-002,0,1,0,
1432779204.175,,2.500000e+002,9.999530e+001,-4.322220e-007,0.000000e+000,0.000000e+000,0.000000e+000,3,0.000000e+000,1.825000e+000,,,,,,,,,,,,,,,,,,0,5.000000e+000,5.000000e-001,2,1,1.399994e-002,0,1,0,
1432779411.395,,2.500000e+002,9.998831e+001,-3.934995e-007,0.000000e+000,0.000000e+000,0.000000e+000,3,0.000000e+000,1.825000e+000,,,,,,,,,,,,,,,,,,0,5.000000e+000,5.000000e-001,2,1,1.396179e-002,0,1,0,
1432779509.106,,2.500000e+002,9.888335e+001,-4.493718e-007,0.000000e+000,0.000000e+000,0.000000e+000,3,0.000000e+000,1.825000e+000,,,,,,,,,,,,,,,,,,0,5.000000e+000,5.000000e-001,2,1,1.775589e-001,0,1,0,
1432779558.540,,2.500000e+002,9.779207e+001,-4.980929e-007,0.000000e+000,0.000000e+000,0.000000e+000,3,0.000000e+000,1.825000e+000,,,,,,,,,,,,,,,,,,0,5.000000e+000,5.000000e-001,2,1,2.518845e-001,0,1,0,
1432779594.971,,2.500000e+002,9.684348e+001,-5.297118e-007,0.000000e+000,0.000000e+000,0.000000e+000,3,0.000000e+000,1.825000e+000,,,,,,,,,,,,,,,,,,0,5.000000e+000,5.000000e-001,2,1,2.669678e-001,0,1,0,
1432779633.151,,2.500000e+002,9.583167e+001,-5.988277e-007,0.000000e+000,0.000000e+000,0.000000e+000,3,0.000000e+000,1.825000e+000,,,,,,,,,,,,,,,,,,0,5.000000e+000,5.000000e-001,2,1,2.831802e-001,0,1,0,
1432779670.585,,2.500000e+002,9.479861e+001,-6.254569e-007,0.000000e+000,0.000000e+000,0.000000e+000,3,0.000000e+000,1.825000e+000,,,,,,,,,,,,,,,,,,0,5.000000e+000,5.000000e-001,2,1,2.837524e-001,0,1,0,
1432779706.205,,2.500000e+002,9.382039e+001,-6.987232e-007,0.000000e+000,0.000000e+000,0.000000e+000,3,0.000000e+000,1.825000e+000,,,,,,,,,,,,,,,,,,0,5.000000e+000,5.000000e-001,2,1,3.071213e-001,0,1,0,
1432779740.283,,2.500000e+002,9.281256e+001,-7.942562e-007,0.000000e+000,0.000000e+000,0.000000e+000,3,0.000000e+000,1.825000e+000,,,,,,,,,,,,,,,,,,0,5.000000e+000,5.000000e-001,2,1,3.170624e-001,0,1,0,
1432779774.497,,2.500000e+002,9.178438e+001,-8.505626e-007,0.000000e+000,0.000000e+000,0.000000e+000,3,0.000000e+000,1.825000e+000,,,,,,,,,,,,,,,,,,0,5.000000e+000,5.000000e-001,2,1,3.124466e-001,0,1,0,
1432779806.034,,2.500000e+002,9.080746e+001,-8.832326e-007,0.000000e+000,0.000000e+000,0.000000e+000,3,0.000000e+000,1.825000e+000,,,,,,,,,,,,,,,,,,0,5.000000e+000,5.000000e-001,2,1,2.907104e-001,0,1,0,
1432779839.162,,2.500000e+002,8.981112e+001,-9.436059e-007,0.000000e+000,0.000000e+000,0.000000e+000,3,0.000000e+000,1.825000e+000,,,,,,,,,,,,,,,,,,0,5.000000e+000,5.000000e-001,2,1,3.397827e-001,0,1,0,
1432779869.506,,2.500000e+002,8.883227e+001,3.617118e-007,0.000000e+000,-2.284589e+000,0.000000e+000,3,0.000000e+000,1.825000e+000,,,,,,,,,,,,,,,,,,0,5.000000e+000,5.000000e-001,2,1,3.217010e-001,0,1,0,
1432779902.186,,2.500000e+002,8.779506e+001,4.124144e-007,0.000000e+000,-2.284896e+000,0.000000e+000,3,0.000000e+000,1.825000e+000,,,,,,,,,,,,,,,,,,0,5.000000e+000,5.000000e-001,2,1,3.110046e-001,0,1,0,
1432779935.165,,2.500000e+002,8.673424e+001,5.105153e-007,0.000000e+000,-2.283718e+000,0.000000e+000,3,0.000000e+000,1.825000e+000,,,,,,,,,,,,,,,,,,0,5.000000e+000,5.000000e-001,2,1,3.146210e-001,0,1,0,
1432779963.847,,2.500000e+002,8.578955e+001,5.374822e-007,0.000000e+000,-2.283969e+000,0.000000e+000,3,0.000000e+000,1.825000e+000,,,,,,,,,,,,,,,,,,0,5.000000e+000,5.000000e-001,2,1,3.012009e-001,0,1,0,
1432779994.529,,2.500000e+002,8.480797e+001,5.823097e-007,0.000000e+000,-2.282600e+000,0.000000e+000,3,0.000000e+000,1.825000e+000,,,,,,,,,,,,,,,,,,0,5.000000e+000,5.000000e-001,2,1,3.424377e-001,0,1,0,
1432780025.711,,2.500000e+002,8.377227e+001,6.506596e-007,0.000000e+000,-2.281731e+000,0.000000e+000,3,0.000000e+000,1.825000e+000,,,,,,,,,,,,,,,,,,0,5.000000e+000,5.000000e-001,2,1,3.112793e-001,0,1,0,
1432780055.163,,2.500000e+002,8.281158e+001,-4.048368e-006,0.000000e+000,-9.878915e-001,0.000000e+000,3,0.000000e+000,1.825000e+000,,,,,,,,,,,,,,,,,,0,5.000000e+000,5.000000e-001,2,1,3.452835e-001,0,1,0,
1432780085.815,,2.500000e+002,8.177742e+001,-2.286607e-006,0.000000e+000,-1.394013e+000,0.000000e+000,3,0.000000e+000,1.825000e+000,,,,,,,,,,,,,,,,,,0,5.000000e+000,5.000000e-001,2,1,3.292389e-001,0,1,0,
1432780114.604,,2.500000e+002,8.079459e+001,-2.320619e-006,0.000000e+000,-1.402305e+000,0.000000e+000,3,0.000000e+000,1.825000e+000,,,,,,,,,,,,,,,,,,0,5.000000e+000,5.000000e-001,2,1,3.405075e-001,0,1,0,
1432780145.572,,2.500000e+002,7.974042e+001,-2.404820e-006,0.000000e+000,-1.404082e+000,0.000000e+000,3,0.000000e+000,1.825000e+000,,,,,,,,,,,,,,,,,,0,5.000000e+000,5.000000e-001,2,1,3.701019e-001,0,1,0,
1432780173.002,,2.500000e+002,7.878437e+001,-2.449746e-006,0.000000e+000,-1.403371e+000,0.000000e+000,3,0.000000e+000,1.825000e+000,,,,,,,,,,,,,,,,,,0,5.000000e+000,5.000000e-001,2,1,3.662415e-001,0,1,0,
1432780200.486,,2.500000e+002,7.782359e+001,-2.589445e-006,0.000000e+000,-1.401842e+000,0.000000e+000,3,0.000000e+000,1.825000e+000,,,,,,,,,,,,,,,,,,0,5.000000e+000,5.000000e-001,2,1,3.404770e-001,0,1,0,
1432780230.165,,2.500000e+002,7.681644e+001,-2.699654e-006,0.000000e+000,-1.400065e+000,0.000000e+000,3,0.000000e+000,1.825000e+000,,,,,,,,,,,,,,,,,,0,5.000000e+000,5.000000e-001,2,1,3.602600e-001,0,1,0,
1432780259.894,,2.500000e+002,7.580598e+001,-2.910947e-006,0.000000e+000,-1.395373e+000,0.000000e+000,3,0.000000e+000,1.825000e+000,,,,,,,,,,,,,,,,,,0,5.000000e+000,5.000000e-001,2,1,3.773193e-001,0,1,0,
1432780289.074,,2.500000e+002,7.479131e+001,-3.114528e-006,0.000000e+000,-1.390966e+000,0.000000e+000,3,0.000000e+000,1.825000e+000,,,,,,,,,,,,,,,,,,0,5.000000e+000,5.000000e-001,2,1,3.635712e-001,0,1,0,
1432780318.005,,2.500000e+002,7.383910e+001,-3.398286e-006,0.000000e+000,-1.383544e+000,0.000000e+000,3,0.000000e+000,1.825000e+000,,,,,,,,,,,,,,,,,,0,5.000000e+000,5.000000e-001,2,1,3.140869e-001,0,1,0,
1432780348.937,,2.500000e+002,7.273048e+001,-3.693235e-006,0.000000e+000,-1.379635e+000,0.000000e+000,3,0.000000e+000,1.825000e+000,,,,,,,,,,,,,,,,,,0,5.000000e+000,5.000000e-001,2,1,2.936249e-001,0,1,0,
1432780375.522,,2.500000e+002,7.181673e+001,-4.120323e-006,0.000000e+000,-1.367566e+000,0.000000e+000,3,0.000000e+000,1.825000e+000,,,,,,,,,,,,,,,,,,0,5.000000e+000,5.000000e-001,2,1,3.007202e-001,0,1,0,
1432780406.462,,2.500000e+002,7.077191e+001,-4.611827e-006,0.000000e+000,-1.359161e+000,0.000000e+000,3,0.000000e+000,1.825000e+000,,,,,,,,,,,,,,,,,,0,5.000000e+000,5.000000e-001,2,1,3.111496e-001,0,1,0,
1432780433.419,,2.500000e+002,6.980919e+001,-5.103852e-006,0.000000e+000,-1.350110e+000,0.000000e+000,3,0.000000e+000,1.825000e+000,,,,,,,,,,,,,,,,,,0,5.000000e+000,5.000000e-001,2,1,3.523560e-001,0,1,0,
1432780463.861,,2.500000e+002,6.874272e+001,-5.623962e-006,0.000000e+000,-1.343917e+000,0.000000e+000,3,0.000000e+000,1.825000e+000,,,,,,,,,,,,,,,,,,0,5.000000e+000,5.000000e-001,2,1,3.557816e-001,0,1,0,
1432780490.791,,2.500000e+002,6.778632e+001,-6.306902e-006,0.000000e+000,-1.332396e+000,0.000000e+000,3,0.000000e+000,1.825000e+000,,,,,,,,,,,,,,,,,,0,5.000000e+000,5.000000e-001,2,1,3.419571e-001,0,1,0,
1432780520.472,,2.500000e+002,6.674812e+001,-7.406737e-006,0.000000e+000,-1.308522e+000,0.000000e+000,3,0.000000e+000,1.825000e+000,,,,,,,,,,,,,,,,,,0,5.000000e+000,5.000000e-001,2,1,3.600845e-001,0,1,0,
1432780547.878,,2.500000e+002,6.577224e+001,-8.114082e-006,0.000000e+000,-1.304783e+000,0.000000e+000,3,0.000000e+000,1.825000e+000,,,,,,,,,,,,,,,,,,0,5.000000e+000,5.000000e-001,2,1,3.710938e-001,0,1,0,
1432780574.427,,2.500000e+002,6.483621e+001,-9.250827e-006,0.000000e+000,-1.286907e+000,0.000000e+000,3,0.000000e+000,1.825000e+000,,,,,,,,,,,,,,,,,,0,5.000000e+000,5.000000e-001,2,1,2.978745e-001,0,1,0,
1432780607.573,,2.500000e+002,6.360921e+001,-1.104961e-005,0.000000e+000,-1.256613e+000,0.000000e+000,3,0.000000e+000,1.825000e+000,,,,,,,,,,,,,,,,,,0,5.000000e+000,5.000000e-001,2,1,3.521690e-001,0,1,0,
1432780630.194,,2.500000e+002,6.278143e+001,-1.224941e-005,0.000000e+000,-1.241894e+000,0.000000e+000,3,0.000000e+000,1.825000e+000,,,,,,,,,,,,,,,,,,0,5.000000e+000,5.000000e-001,2,1,3.473701e-001,0,1,0,
1432780657.233,,2.500000e+002,6.179930e+001,-1.446524e-005,0.000000e+000,-1.203172e+000,0.000000e+000,3,0.000000e+000,1.825000e+000,,,,,,,,,,,,,,,,,,0,5.000000e+000,5.000000e-001,2,1,3.687897e-001,0,1,0,
1432780684.202,,2.500000e+002,6.080462e+001,-1.755440e-005,0.000000e+000,-1.141896e+000,0.000000e+000,3,0.000000e+000,1.825000e+000,,,,,,,,,,,,,,,,,,0,5.000000e+000,5.000000e-001,2,1,3.810120e-001,0,1,0,
1432780711.182,,2.500000e+002,5.977090e+001,-2.300265e-005,0.000000e+000,-1.002297e+000,0.000000e+000,3,0.000000e+000,1.825000e+000,,,,,,,,,,,,,,,,,,0,5.000000e+000,5.000000e-001,2,1,3.721123e-001,0,1,0,
1432780738.363,,2.500000e+002,5.877744e+001,-3.181939e-005,0.000000e+000,-5.786381e-001,0.000000e+000,3,0.000000e+000,1.825000e+000,,,,,,,,,,,,,,,,,,0,5.000000e+000,5.000000e-001,2,1,4.178200e-001,0,1,0,
1432780764.885,,2.500000e+002,5.775599e+001,-3.429510e-005,0.000000e+000,-5.372003e-001,0.000000e+000,3,0.000000e+000,1.825000e+000,,,,,,,,,,,,,,,,,,0,5.000000e+000,5.000000e-001,2,1,3.450813e-001,0,1,0,
1432780790.995,,2.500000e+002,5.676603e+001,-3.684000e-005,0.000000e+000,-5.843375e-001,0.000000e+000,3,0.000000e+000,1.825000e+000,,,,,,,,,,,,,,,,,,0,5.000000e+000,5.000000e-001,2,1,3.511887e-001,0,1,0,
1432780819.033,,2.500000e+002,5.569047e+001,-3.987205e-005,0.000000e+000,-5.889852e-001,0.000000e+000,3,0.000000e+000,1.825000e+000,,,,,,,,,,,,,,,,,,0,5.000000e+000,5.000000e-001,2,1,3.369789e-001,0,1,0,
1432780853.179,,2.500000e+002,5.442307e+001,-4.396729e-005,0.000000e+000,-5.918992e-001,0.000000e+000,3,0.000000e+000,1.825000e+000,,,,,,,,,,,,,,,,,,0,5.000000e+000,5.000000e-001,2,1,3.627510e-001,0,1,0,
1432780875.863,,2.500000e+002,5.356968e+001,-4.703787e-005,0.000000e+000,-5.914796e-001,0.000000e+000,3,0.000000e+000,1.825000e+000,,,,,,,,,,,,,,,,,,0,5.000000e+000,5.000000e-001,2,1,3.496590e-001,0,1,0,
1432780897.293,,2.500000e+002,5.276328e+001,-5.039059e-005,0.000000e+000,-5.874214e-001,0.000000e+000,3,0.000000e+000,1.825000e+000,,,,,,,,,,,,,,,,,,0,5.000000e+000,5.000000e-001,2,1,3.865013e-001,0,1,0,
1432780923.282,,2.500000e+002,5.180357e+001,-5.483689e-005,0.000000e+000,-5.840234e-001,0.000000e+000,3,0.000000e+000,1.825000e+000,,,,,,,,,,,,,,,,,,0,5.000000e+000,5.000000e-001,2,1,3.865700e-001,0,1,0,
1432780950.712,,2.500000e+002,5.076623e+001,-6.032777e-005,0.000000e+000,-5.822700e-001,0.000000e+000,3,0.000000e+000,1.825000e+000,,,,,,,,,,,,,,,,,,0,5.000000e+000,5.000000e-001,2,1,3.771400e-001,0,1,0,
1432780976.239,,2.500000e+002,4.981432e+001,-6.647840e-005,0.000000e+000,-5.811716e-001,0.000000e+000,3,0.000000e+000,1.825000e+000,,,,,,,,,,,,,,,,,,0,5.000000e+000,5.000000e-001,2,1,3.564720e-001,0,1,0,
1432781003.419,,2.500000e+002,4.880067e+001,-7.411033e-005,0.000000e+000,-5.815195e-001,0.000000e+000,3,0.000000e+000,1.825000e+000,,,,,,,,,,,,,,,,,,0,5.000000e+000,5.000000e-001,2,1,3.737411e-001,0,1,0,
1432781030.796,,2.500000e+002,4.779994e+001,-8.366162e-005,0.000000e+000,-5.819182e-001,0.000000e+000,3,0.000000e+000,1.825000e+000,,,,,,,,,,,,,,,,,,0,5.000000e+000,5.000000e-001,2,1,3.570213e-001,0,1,0,
1432781058.334,,2.500000e+002,4.676731e+001,-9.605127e-005,0.000000e+000,-5.813715e-001,0.000000e+000,3,0.000000e+000,1.825000e+000,,,,,,,,,,,,,,,,,,0,5.000000e+000,5.000000e-001,2,1,3.609695e-001,0,1,0,
1432781094.789,,2.500000e+002,4.540070e+001,-1.174768e-004,0.000000e+000,-5.806648e-001,0.000000e+000,3,0.000000e+000,1.825000e+000,,,,,,,,,,,,,,,,,,0,5.000000e+000,5.000000e-001,2,1,3.916893e-001,0,1,0,
1432781117.026,,2.500000e+002,4.455254e+001,-1.339642e-004,0.000000e+000,-5.806612e-001,0.000000e+000,3,0.000000e+000,1.825000e+000,,,,,,,,,,,,,,,,,,0,5.000000e+000,5.000000e-001,2,1,3.528824e-001,0,1,0,
1432781138.906,,2.500000e+002,4.376337e+001,-1.522026e-004,0.000000e+000,-5.811378e-001,0.000000e+000,3,0.000000e+000,1.825000e+000,,,,,,,,,,,,,,,,,,0,5.000000e+000,5.000000e-001,2,1,3.920822e-001,0,1,0,
1432781164.194,,2.500000e+002,4.281339e+001,-1.757681e-004,0.000000e+000,-5.812300e-001,0.000000e+000,3,0.000000e+000,1.825000e+000,,,,,,,,,,,,,,,,,,0,5.000000e+000,5.000000e-001,2,1,3.070107e-001,0,1,0,
1432781191.739,,2.500000e+002,4.182872e+001,-2.020713e-004,0.000000e+000,-5.809521e-001,0.000000e+000,3,0.000000e+000,1.825000e+000,,,,,,,,,,,,,,,,,,0,5.000000e+000,5.000000e-001,2,1,3.392181e-001,0,1,0,
1432781228.830,,2.500000e+002,4.050410e+001,-2.371950e-004,0.000000e+000,-5.811233e-001,0.000000e+000,3,0.000000e+000,1.825000e+000,,,,,,,,,,,,,,,,,,0,5.000000e+000,5.000000e-001,2,1,2.980995e-001,0,1,0,
1432781251.367,,2.500000e+002,3.970579e+001,-2.579226e-004,0.000000e+000,-5.816047e-001,0.000000e+000,3,0.000000e+000,1.825000e+000,,,,,,,,,,,,,,,,,,0,5.000000e+000,5.000000e-001,2,1,2.980995e-001,0,1,0,
1432781277.075,,2.500000e+002,3.879609e+001,-2.809420e-004,0.000000e+000,-5.816808e-001,0.000000e+000,3,0.000000e+000,1.825000e+000,,,,,,,,,,,,,,,,,,0,5.000000e+000,5.000000e-001,2,1,3.111115e-001,0,1,0,
1432781305.006,,2.500000e+002,3.781004e+001,-3.053542e-004,0.000000e+000,-5.818787e-001,0.000000e+000,3,0.000000e+000,1.825000e+000,,,,,,,,,,,,,,,,,,0,5.000000e+000,5.000000e-001,2,1,3.550797e-001,0,1,0,
1432781332.172,,2.500000e+002,3.681332e+001,-3.279021e-004,0.000000e+000,-5.819638e-001,0.000000e+000,3,0.000000e+000,1.825000e+000,,,,,,,,,,,,,,,,,,0,5.000000e+000,5.000000e-001,2,1,3.106766e-001,0,1,0,
1432781361.661,,2.500000e+002,3.577138e+001,-3.505736e-004,0.000000e+000,-5.819685e-001,0.000000e+000,3,0.000000e+000,1.825000e+000,,,,,,,,,,,,,,,,,,0,5.000000e+000,5.000000e-001,2,1,2.943382e-001,0,1,0,
1432781390.901,,2.500000e+002,3.478159e+001,-3.711853e-004,0.000000e+000,-5.819092e-001,0.000000e+000,3,0.000000e+000,1.825000e+000,,,,,,,,,,,,,,,,,,0,5.000000e+000,5.000000e-001,2,1,2.668114e-001,0,1,0,
1432781429.655,,2.500000e+002,3.341882e+001,-3.984586e-004,0.000000e+000,-5.823653e-001,0.000000e+000,3,0.000000e+000,1.825000e+000,,,,,,,,,,,,,,,,,,0,5.000000e+000,5.000000e-001,2,1,3.071709e-001,0,1,0,
1432781450.395,,2.500000e+002,3.269028e+001,-4.125640e-004,0.000000e+000,-5.825250e-001,0.000000e+000,3,0.000000e+000,1.825000e+000,,,,,,,,,,,,,,,,,,0,5.000000e+000,5.000000e-001,2,1,3.110580e-001,0,1,0,
1432781474.527,,2.500000e+002,3.184033e+001,-4.286075e-004,0.000000e+000,-5.826371e-001,0.000000e+000,3,0.000000e+000,1.825000e+000,,,,,,,,,,,,,,,,,,0,5.000000e+000,5.000000e-001,2,1,3.049583e-001,0,1,0,
1432781504.573,,2.500000e+002,3.083147e+001,-4.469238e-004,0.000000e+000,-5.831251e-001,0.000000e+000,3,0.000000e+000,1.825000e+000,,,,,,,,,,,,,,,,,,0,5.000000e+000,5.000000e-001,2,1,3.052998e-001,0,1,0,
1432781533.755,,2.500000e+002,2.980883e+001,-4.645974e-004,0.000000e+000,-5.833933e-001,0.000000e+000,3,0.000000e+000,1.825000e+000,,,,,,,,,,,,,,,,,,0,5.000000e+000,5.000000e-001,2,1,2.746601e-001,0,1,0,
1432781562.436,,2.500000e+002,2.883623e+001,-4.813279e-004,0.000000e+000,-5.837371e-001,0.000000e+000,3,0.000000e+000,1.825000e+000,,,,,,,,,,,,,,,,,,0,5.000000e+000,5.000000e-001,2,1,3.066902e-001,0,1,0,
1432781593.467,,2.500000e+002,2.781145e+001,-4.985100e-004,0.000000e+000,-5.842127e-001,0.000000e+000,3,0.000000e+000,1.825000e+000,,,,,,,,,,,,,,,,,,0,5.000000e+000,5.000000e-001,2,1,3.095188e-001,0,1,0,
1432781623.852,,2.500000e+002,2.686371e+001,-5.137916e-004,0.000000e+000,-5.840771e-001,0.000000e+000,3,0.000000e+000,1.825000e+000,,,,,,,,,,,,,,,,,,0,5.000000e+000,5.000000e-001,2,1,2.364998e-001,0,1,0,
1432781656.889,,2.500000e+002,2.585838e+001,-5.298438e-004,0.000000e+000,-5.840394e-001,0.000000e+000,3,0.000000e+000,1.825000e+000,,,,,,,,,,,,,,,,,,0,5.000000e+000,5.000000e-001,2,1,2.809811e-001,0,1,0,
1432781691.129,,2.500000e+002,2.470139e+001,-5.471751e-004,0.000000e+000,-5.846468e-001,0.000000e+000,3,0.000000e+000,1.825000e+000,,,,,,,,,,,,,,,,,,0,5.000000e+000,5.000000e-001,2,1,5.178604e-001,0,1,0,
1432781711.762,,2.500000e+002,2.339606e+001,-5.675547e-004,0.000000e+000,-5.844288e-001,0.000000e+000,3,0.000000e+000,1.825000e+000,,,,,,,,,,,,,,,,,,0,5.000000e+000,5.000000e-001,2,1,2.120895e-001,0,1,0,
1432781757.302,,2.500000e+002,2.267064e+001,-5.778158e-004,0.000000e+000,-5.847300e-001,0.000000e+000,3,0.000000e+000,1.825000e+000,,,,,,,,,,,,,,,,,,0,5.000000e+000,5.000000e-001,2,1,5.132904e-001,0,1,0,
1432781779.483,,2.500000e+002,2.163937e+001,-5.919366e-004,0.000000e+000,-5.848998e-001,0.000000e+000,3,0.000000e+000,1.825000e+000,,,,,,,,,,,,,,,,,,0,5.000000e+000,5.000000e-001,2,1,3.711128e-002,0,1,0,
1432781809.867,,2.500000e+002,2.084188e+001,-6.037742e-004,0.000000e+000,-5.846214e-001,0.000000e+000,3,0.000000e+000,1.825000e+000,,,,,,,,,,,,,,,,,,0,5.000000e+000,5.000000e-001,2,1,3.064690e-001,0,1,0,
1432781843.155,,2.500000e+002,1.980226e+001,-6.180168e-004,0.000000e+000,-5.850762e-001,0.000000e+000,3,0.000000e+000,1.825000e+000,,,,,,,,,,,,,,,,,,0,5.000000e+000,5.000000e-001,2,1,2.668304e-001,0,1,0,
1432781874.086,,2.500000e+002,1.881090e+001,-6.313718e-004,0.000000e+000,-5.845073e-001,0.000000e+000,3,0.000000e+000,1.825000e+000,,,,,,,,,,,,,,,,,,0,5.000000e+000,5.000000e-001,2,1,2.727394e-001,0,1,0,
1432781906.542,,2.500000e+002,1.775410e+001,-6.451529e-004,0.000000e+000,-5.851883e-001,0.000000e+000,3,0.000000e+000,1.825000e+000,,,,,,,,,,,,,,,,,,0,5.000000e+000,5.000000e-001,2,1,2.786503e-001,0,1,0,
1432781934.735,,2.500000e+002,1.684218e+001,-6.571867e-004,0.000000e+000,-5.851075e-001,0.000000e+000,3,0.000000e+000,1.825000e+000,,,,,,,,,,,,,,,,,,0,5.000000e+000,5.000000e-001,2,1,3.041000e-001,0,1,0,
1432782287.992,,2.500000e+002,1.600198e+001,-6.675085e-004,0.000000e+000,-5.844696e-001,0.000000e+000,3,0.000000e+000,1.825000e+000,,,,,,,,,,,,,,,,,,0,5.000000e+000,5.000000e-001,2,1,1.380920e-003,0,1,0,
1432782413.099,,2.500000e+002,1.498692e+001,-6.804955e-004,0.000000e+000,-5.842561e-001,0.000000e+000,3,0.000000e+000,1.825000e+000,,,,,,,,,,,,,,,,,,0,5.000000e+000,5.000000e-001,2,1,7.929802e-003,0,0,0,
1432782465.533,,2.500000e+002,1.391262e+001,-6.938486e-004,0.000000e+000,-5.848659e-001,0.000000e+000,3,0.000000e+000,1.825000e+000,,,,,,,,,,,,,,,,,,0,5.000000e+000,5.000000e-001,2,1,1.295404e-001,0,0,0,
1432782527.218,,2.500000e+002,1.292334e+001,-7.060297e-004,0.000000e+000,-5.843262e-001,0.000000e+000,3,0.000000e+000,1.825000e+000,,,,,,,,,,,,,,,,,,0,5.000000e+000,5.000000e-001,2,1,1.507301e-001,0,0,0,
1432782588.656,,2.500000e+002,1.191940e+001,-7.178168e-004,0.000000e+000,-5.844895e-001,0.000000e+000,3,0.000000e+000,1.825000e+000,,,,,,,,,,,,,,,,,,0,5.000000e+000,5.000000e-001,2,1,1.360197e-001,0,0,0,
1432782651.491,,2.500000e+002,1.091749e+001,-7.291618e-004,0.000000e+000,-5.850141e-001,0.000000e+000,3,0.000000e+000,1.825000e+000,,,,,,,,,,,,,,,,,,0,5.000000e+000,5.000000e-001,2,1,1.495209e-001,0,0,0,
1432782714.191,,2.500000e+002,9.897631e+000,-7.409424e-004,0.000000e+000,-5.843831e-001,0.000000e+000,3,0.000000e+000,1.825000e+000,,,,,,,,,,,,,,,,,,0,5.000000e+000,5.000000e-001,2,1,1.465807e-001,0,0,0,
1432782774.309,,2.500000e+002,8.924273e+000,-7.511920e-004,0.000000e+000,-5.852959e-001,0.000000e+000,3,0.000000e+000,1.825000e+000,,,,,,,,,,,,,,,,,,0,5.000000e+000,5.000000e-001,2,1,1.501694e-001,0,1,0,
1432782840.721,,2.500000e+002,7.916393e+000,-7.618540e-004,0.000000e+000,-5.849294e-001,0.000000e+000,3,0.000000e+000,1.825000e+000,,,,,,,,,,,,,,,,,,0,5.000000e+000,5.000000e-001,2,1,1.330266e-001,0,1,0,
1432782904.202,,2.500000e+002,6.916929e+000,-7.716623e-004,0.000000e+000,-5.853825e-001,0.000000e+000,3,0.000000e+000,1.825000e+000,,,,,,,,,,,,,,,,,,0,5.000000e+000,5.000000e-001,2,1,1.312661e-001,0,1,0,
1432782967.904,,2.500000e+002,5.858063e+000,-7.814275e-004,0.000000e+000,-5.852220e-001,0.000000e+000,3,0.000000e+000,1.825000e+000,,,,,,,,,,,,,,,,,,0,5.000000e+000,5.000000e-001,2,1,2.035661e-001,0,1,0,
1432783126.821,,2.500000e+002,5.002438e+000,-7.906898e-004,0.000000e+000,-5.844926e-001,0.000000e+000,3,0.000000e+000,1.825000e+000,,,,,,,,,,,,,,,,,,0,5.000000e+000,5.000000e-001,2,1,4.209042e-003,0,0,0,
1432783136.893,,2.500000e+002,5.003736e+000,-7.905830e-004,0.000000e+000,-5.846058e-001,0.000000e+000,3,0.000000e+000,1.825000e+000,,,,,,,,,,,,,,,,,,0,5.000000e+000,5.000000e-001,2,1,3.709793e-004,0,0,0,