File: data/A269/A269_GdN_MH_5K_150528.rso.dat
[Header]
TITLE,MPMS RSO Measurement
BYAPP,MPMS Measurement,1.1,Summary
FILEOPENTIME, 1432783611.902000 5/28/2015, 3:26:51 PM

INFO, APPNAME, MPMS MultiVu Application, Revision 1.61,  Build 082

INFO, NAME, A269
INFO, WEIGHT, 22.300
INFO, AREA, 1.000
INFO, LENGTH, 1.000
INFO, SHAPE, 1
INFO, COMMENT, m = 0.0223g
INFO, SEQUENCE FILE: 7T_hysteresis_sweep.seq


INFO, BACKGROUND DATA FILE:, None


STARTUPAXIS,X,4,LINEAR,AUTO,0.000000,0.000000
STARTUPAXIS,Y1,5,LINEAR,AUTO,0.000000,0.000000


STARTUPGROUP,Longitudinal
FIELDGROUP,Longitudinal,1,2,3,4,5,6,7,8,9,10,11,19,20,21,22,23,35
FIELDGROUP,Transverse,1,2,3,4,12,13,14,15,16,17,18,24,25,26,27,28,35

PLOT_APPEARANCE,ALL,HORZ_GRID_ON,VERT_GRID_ON,MARKERS_AND_LINES

[Data]
Time,Comment,Field (Oe),Temperature (K),Long Moment (emu),Long Scan Std Dev,Long Offset (cm),Long Offset Std Dev,Long Algorithm,Long Reg Fit,Long Reg Factor,Trans Moment (emu),Trans Scan Std Dev,Trans Offset (cm),Trans Offset Std Dev,Trans Algorithm,Trans Reg Fit,Trans Reg Factor,Long Moment [w/o ABS] (emu),Long Scan Std Dev [w/o ABS],Long Offset [w/o ABS] (cm),Long Offset Std Dev [w/o ABS],Long Reg Fit [w/o ABS],Trans Moment [w/o ABS] (emu),Trans Scan Std Dev [w/o ABS],Trans Offset [w/o ABS] (cm),Trans Offset Std Dev [w/o ABS],Trans Reg Fit [w/o ABS],RSO Position (deg),Amplitude (cm),Frequency,Cycles to Average,Scans per Measurement,Delta Temp (K),Error,EC Comp. Running,Using ABS,
1432783611.899,,7.000000e+004,5.006526e+000,-5.848491e-003,0.000000e+000,-5.819983e-001,0.000000e+000,3,0.000000e+000,1.825000e+000,,,,,,,,,,,,,,,,,,0,5.000000e+000,5.000000e-001,2,1,2.977371e-003,0,1,0,
1432783621.815,,7.000000e+004,5.003985e+000,-5.851795e-003,0.000000e+000,-5.814880e-001,0.000000e+000,3,0.000000e+000,1.825000e+000,,,,,,,,,,,,,,,,,,0,5.000000e+000,5.000000e-001,2,1,2.105713e-003,0,1,0,
1432783785.110,,6.000000e+004,5.002438e+000,-5.609410e-003,0.000000e+000,-5.832120e-001,0.000000e+000,3,0.000000e+000,1.825000e+000,,,,,,,,,,,,,,,,,,0,5.000000e+000,5.000000e-001,2,1,4.456997e-003,0,1,0,
1432783795.135,,6.000000e+004,5.004542e+000,-5.613872e-003,0.000000e+000,-5.842852e-001,0.000000e+000,3,0.000000e+000,1.825000e+000,,,,,,,,,,,,,,,,,,0,5.000000e+000,5.000000e-001,2,1,1.733780e-003,0,1,0,
1432783950.418,,5.000000e+004,5.003057e+000,-5.306873e-003,0.000000e+000,-5.839928e-001,0.000000e+000,3,0.000000e+000,1.825000e+000,,,,,,,,,,,,,,,,,,0,5.000000e+000,5.000000e-001,2,1,5.448341e-003,0,1,0,
1432783960.528,,5.000000e+004,5.004789e+000,-5.306235e-003,0.000000e+000,-5.844740e-001,0.000000e+000,3,0.000000e+000,1.825000e+000,,,,,,,,,,,,,,,,,,0,5.000000e+000,5.000000e-001,2,1,1.983166e-003,0,1,0,
1432784113.285,,4.000000e+004,5.002685e+000,-4.926644e-003,0.000000e+000,-5.847779e-001,0.000000e+000,3,0.000000e+000,1.825000e+000,,,,,,,,,,,,,,,,,,0,5.000000e+000,5.000000e-001,2,1,4.951954e-003,0,0,0,
1432784123.203,,4.000000e+004,5.003613e+000,-4.928682e-003,0.000000e+000,-5.856785e-001,0.000000e+000,3,0.000000e+000,1.825000e+000,,,,,,,,,,,,,,,,,,0,5.000000e+000,5.000000e-001,2,1,3.095627e-003,0,0,0,
1432784280.242,,3.000000e+004,5.002624e+000,-4.465378e-003,0.000000e+000,-5.853817e-001,0.000000e+000,3,0.000000e+000,1.825000e+000,,,,,,,,,,,,,,,,,,0,5.000000e+000,5.000000e-001,2,1,5.074978e-003,0,0,0,
1432784290.314,,3.000000e+004,5.004170e+000,-4.466504e-003,0.000000e+000,-5.852822e-001,0.000000e+000,3,0.000000e+000,1.825000e+000,,,,,,,,,,,,,,,,,,0,5.000000e+000,5.000000e-001,2,1,1.980782e-003,0,0,0,
1432784452.497,,2.000000e+004,5.001818e+000,-3.917059e-003,0.000000e+000,-5.851938e-001,0.000000e+000,3,0.000000e+000,1.825000e+000,,,,,,,,,,,,,,,,,,0,5.000000e+000,5.000000e-001,2,1,3.960133e-003,0,0,0,
1432784462.818,,2.000000e+004,5.003675e+000,-3.917058e-003,0.000000e+000,-5.852093e-001,0.000000e+000,3,0.000000e+000,1.825000e+000,,,,,,,,,,,,,,,,,,0,5.000000e+000,5.000000e-001,2,1,2.971649e-003,0,0,0,
1432784616.532,,1.000000e+004,5.002871e+000,-3.226124e-003,0.000000e+000,-5.848831e-001,0.000000e+000,3,0.000000e+000,1.825000e+000,,,,,,,,,,,,,,,,,,0,5.000000e+000,5.000000e-001,2,1,5.075932e-003,0,1,0,
1432784626.604,,1.000000e+004,5.003923e+000,-3.228431e-003,0.000000e+000,-5.844870e-001,0.000000e+000,3,0.000000e+000,1.825000e+000,,,,,,,,,,,,,,,,,,0,5.000000e+000,5.000000e-001,2,1,2.971649e-003,0,1,0,
1432784737.764,,9.000000e+003,5.003243e+000,-3.138602e-003,0.000000e+000,-5.846541e-001,0.000000e+000,3,0.000000e+000,1.825000e+000,,,,,,,,,,,,,,,,,,0,5.000000e+000,5.000000e-001,2,1,5.820274e-003,0,1,0,
1432784747.865,,9.000000e+003,5.005223e+000,-3.137751e-003,0.000000e+000,-5.846495e-001,0.000000e+000,3,0.000000e+000,1.825000e+000,,,,,,,,,,,,,,,,,,0,5.000000e+000,5.000000e-001,2,1,1.859188e-003,0,1,0,
1432784867.593,,7.000000e+003,5.002562e+000,-2.935038e-003,0.000000e+000,-5.845810e-001,0.000000e+000,3,0.000000e+000,1.825000e+000,,,,,,,,,,,,,,,,,,0,5.000000e+000,5.000000e-001,2,1,4.951954e-003,0,1,0,
1432784877.830,,7.000000e+003,5.004109e+000,-2.935929e-003,0.000000e+000,-5.846407e-001,0.000000e+000,3,0.000000e+000,1.825000e+000,,,,,,,,,,,,,,,,,,0,5.000000e+000,5.000000e-001,2,1,1.857758e-003,0,1,0,
1432785006.272,,5.000000e+003,5.004852e+000,-2.674305e-003,0.000000e+000,-5.840626e-001,0.000000e+000,3,0.000000e+000,1.825000e+000,,,,,,,,,,,,,,,,,,0,5.000000e+000,5.000000e-001,2,1,2.602100e-003,0,0,0,
1432785016.487,,5.000000e+003,5.002128e+000,-2.672694e-003,0.000000e+000,-5.842793e-001,0.000000e+000,3,0.000000e+000,1.825000e+000,,,,,,,,,,,,,,,,,,0,5.000000e+000,5.000000e-001,2,1,6.189346e-004,0,0,0,
1432785135.723,,3.000000e+003,5.002748e+000,-2.294324e-003,0.000000e+000,-5.840619e-001,0.000000e+000,3,0.000000e+000,1.825000e+000,,,,,,,,,,,,,,,,,,0,5.000000e+000,5.000000e-001,2,1,4.580975e-003,0,0,0,
1432785145.639,,3.000000e+003,5.003737e+000,-2.293828e-003,0.000000e+000,-5.837101e-001,0.000000e+000,3,0.000000e+000,1.825000e+000,,,,,,,,,,,,,,,,,,0,5.000000e+000,5.000000e-001,2,1,2.600670e-003,0,0,0,
1432785264.755,,1.000000e+003,5.002872e+000,-1.593662e-003,0.000000e+000,-5.832494e-001,0.000000e+000,3,0.000000e+000,1.825000e+000,,,,,,,,,,,,,,,,,,0,5.000000e+000,5.000000e-001,2,1,6.068230e-003,0,0,0,
1432785283.935,,1.000000e+003,5.002623e+000,-1.592129e-003,0.000000e+000,-5.838320e-001,0.000000e+000,3,0.000000e+000,1.825000e+000,,,,,,,,,,,,,,,,,,0,5.000000e+000,5.000000e-001,2,1,1.609802e-003,0,0,0,
1432785387.409,,5.000000e+002,5.002810e+000,-1.278401e-003,0.000000e+000,-5.826779e-001,0.000000e+000,3,0.000000e+000,1.825000e+000,,,,,,,,,,,,,,,,,,0,5.000000e+000,5.000000e-001,2,1,5.943298e-003,0,0,0,
1432785397.624,,5.000000e+002,5.004418e+000,-1.278385e-003,0.000000e+000,-5.836567e-001,0.000000e+000,3,0.000000e+000,1.825000e+000,,,,,,,,,,,,,,,,,,0,5.000000e+000,5.000000e-001,2,1,9.918213e-004,0,0,0,
1432785501.104,,4.000000e+002,5.002500e+000,-1.199896e-003,0.000000e+000,-5.829099e-001,0.000000e+000,3,0.000000e+000,1.825000e+000,,,,,,,,,,,,,,,,,,0,5.000000e+000,5.000000e-001,2,1,4.085064e-003,0,1,0,
1432785511.069,,4.000000e+002,5.005100e+000,-1.198249e-003,0.000000e+000,-5.833532e-001,0.000000e+000,3,0.000000e+000,1.825000e+000,,,,,,,,,,,,,,,,,,0,5.000000e+000,5.000000e-001,2,1,1.612186e-003,0,1,0,
1432785615.794,,3.000000e+002,5.003057e+000,-1.113737e-003,0.000000e+000,-5.828708e-001,0.000000e+000,3,0.000000e+000,1.825000e+000,,,,,,,,,,,,,,,,,,0,5.000000e+000,5.000000e-001,2,1,5.448341e-003,0,1,0,
1432785625.712,,3.000000e+002,5.004913e+000,-1.113469e-003,0.000000e+000,-5.834778e-001,0.000000e+000,3,0.000000e+000,1.825000e+000,,,,,,,,,,,,,,,,,,0,5.000000e+000,5.000000e-001,2,1,1.735210e-003,0,1,0,
1432785729.582,,2.000000e+002,5.003119e+000,-1.020887e-003,0.000000e+000,-5.824569e-001,0.000000e+000,3,0.000000e+000,1.825000e+000,,,,,,,,,,,,,,,,,,0,5.000000e+000,5.000000e-001,2,1,5.573273e-003,0,1,0,
1432785739.816,,2.000000e+002,5.005038e+000,-1.020989e-003,0.000000e+000,-5.823438e-001,0.000000e+000,3,0.000000e+000,1.825000e+000,,,,,,,,,,,,,,,,,,0,5.000000e+000,5.000000e-001,2,1,1.736164e-003,0,1,0,
1432785843.826,,1.000000e+002,5.002872e+000,-9.162212e-004,0.000000e+000,-5.821877e-001,0.000000e+000,3,0.000000e+000,1.825000e+000,,,,,,,,,,,,,,,,,,0,5.000000e+000,5.000000e-001,2,1,5.325317e-003,0,1,0,
1432785853.743,,1.000000e+002,5.004047e+000,-9.149101e-004,0.000000e+000,-5.832431e-001,0.000000e+000,3,0.000000e+000,1.825000e+000,,,,,,,,,,,,,,,,,,0,5.000000e+000,5.000000e-001,2,1,2.973080e-003,0,1,0,
1432785951.091,,0.000000e+000,5.002624e+000,-8.024077e-004,0.000000e+000,-5.827233e-001,0.000000e+000,3,0.000000e+000,1.825000e+000,,,,,,,,,,,,,,,,,,0,5.000000e+000,5.000000e-001,2,1,5.570889e-003,0,0,0,
1432785961.007,,0.000000e+000,5.004542e+000,-8.014402e-004,0.000000e+000,-5.832232e-001,0.000000e+000,3,0.000000e+000,1.825000e+000,,,,,,,,,,,,,,,,,,0,5.000000e+000,5.000000e-001,2,1,1.733780e-003,0,0,0,
1432786058.587,,-1.000000e+002,5.002004e+000,-6.707843e-004,0.000000e+000,-5.826148e-001,0.000000e+000,3,0.000000e+000,1.825000e+000,,,,,,,,,,,,,,,,,,0,5.000000e+000,5.000000e-001,2,1,3.836155e-003,0,0,0,
1432786068.503,,-1.000000e+002,5.004294e+000,-6.695911e-004,0.000000e+000,-5.831258e-001,0.000000e+000,3,0.000000e+000,1.825000e+000,,,,,,,,,,,,,,,,,,0,5.000000e+000,5.000000e-001,2,1,2.228737e-003,0,0,0,
1432786182.060,,-2.000000e+002,5.004665e+000,-5.080964e-004,0.000000e+000,-5.824606e-001,0.000000e+000,3,0.000000e+000,1.825000e+000,,,,,,,,,,,,,,,,,,0,5.000000e+000,5.000000e-001,2,1,9.908676e-004,0,0,0,
1432786192.084,,-2.000000e+002,5.003366e+000,-5.077721e-004,0.000000e+000,-5.820537e-001,0.000000e+000,3,0.000000e+000,1.825000e+000,,,,,,,,,,,,,,,,,,0,5.000000e+000,5.000000e-001,2,1,1.608849e-003,0,0,0,
1432786296.851,,-3.000000e+002,5.003057e+000,-3.250901e-004,0.000000e+000,-5.817205e-001,0.000000e+000,3,0.000000e+000,1.825000e+000,,,,,,,,,,,,,,,,,,0,5.000000e+000,5.000000e-001,2,1,6.191254e-003,0,1,0,
1432786306.953,,-3.000000e+002,5.004294e+000,-3.245133e-004,0.000000e+000,-5.801601e-001,0.000000e+000,3,0.000000e+000,1.825000e+000,,,,,,,,,,,,,,,,,,0,5.000000e+000,5.000000e-001,2,1,4.959106e-004,0,1,0,
1432786420.234,,-4.000000e+002,5.004975e+000,-1.152604e-004,0.000000e+000,-5.693441e-001,0.000000e+000,3,0.000000e+000,1.825000e+000,,,,,,,,,,,,,,,,,,0,5.000000e+000,5.000000e-001,2,1,1.363277e-003,0,1,0,
1432786430.902,,-4.000000e+002,5.002065e+000,-1.139949e-004,0.000000e+000,-5.721315e-001,0.000000e+000,3,0.000000e+000,1.825000e+000,,,,,,,,,,,,,,,,,,0,5.000000e+000,5.000000e-001,2,1,1.734257e-003,0,1,0,
1432786534.686,,-5.000000e+002,5.003057e+000,9.785226e-005,0.000000e+000,-9.225481e-001,0.000000e+000,3,0.000000e+000,1.825000e+000,,,,,,,,,,,,,,,,,,0,5.000000e+000,5.000000e-001,2,1,5.200386e-003,0,1,0,
1432786544.758,,-5.000000e+002,5.004604e+000,8.807411e-005,0.000000e+000,-1.032023e+000,0.000000e+000,3,0.000000e+000,1.825000e+000,,,,,,,,,,,,,,,,,,0,5.000000e+000,5.000000e-001,2,1,2.106190e-003,0,1,0,
1432786670.875,,-1.000000e+003,5.004294e+000,1.122746e-003,0.000000e+000,-5.847946e-001,0.000000e+000,3,0.000000e+000,1.825000e+000,,,,,,,,,,,,,,,,,,0,5.000000e+000,5.000000e-001,2,1,1.486778e-003,0,1,0,
1432786680.864,,-1.000000e+003,5.002375e+000,1.123973e-003,0.000000e+000,-5.847492e-001,0.000000e+000,3,0.000000e+000,1.825000e+000,,,,,,,,,,,,,,,,,,0,5.000000e+000,5.000000e-001,2,1,1.239777e-004,0,1,0,
1432786800.293,,-3.000000e+003,5.003429e+000,2.280162e-003,0.000000e+000,-5.838048e-001,0.000000e+000,3,0.000000e+000,1.825000e+000,,,,,,,,,,,,,,,,,,0,5.000000e+000,5.000000e-001,2,1,5.945206e-003,0,1,0,
1432786810.317,,-3.000000e+003,5.005410e+000,2.279490e-003,0.000000e+000,-5.842559e-001,0.000000e+000,3,0.000000e+000,1.825000e+000,,,,,,,,,,,,,,,,,,0,5.000000e+000,5.000000e-001,2,1,1.984119e-003,0,0,0,
1432786929.400,,-5.000000e+003,5.002995e+000,2.677343e-003,0.000000e+000,-5.840342e-001,0.000000e+000,3,0.000000e+000,1.825000e+000,,,,,,,,,,,,,,,,,,0,5.000000e+000,5.000000e-001,2,1,5.572319e-003,0,0,0,
1432786939.566,,-5.000000e+003,5.004851e+000,2.676449e-003,0.000000e+000,-5.840933e-001,0.000000e+000,3,0.000000e+000,1.825000e+000,,,,,,,,,,,,,,,,,,0,5.000000e+000,5.000000e-001,2,1,1.859188e-003,0,0,0,
1432787059.386,,-7.000000e+003,5.003058e+000,2.939425e-003,0.000000e+000,-5.844749e-001,0.000000e+000,3,0.000000e+000,1.825000e+000,,,,,,,,,,,,,,,,,,0,5.000000e+000,5.000000e-001,2,1,5.944252e-003,0,0,0,
1432787069.458,,-7.000000e+003,5.004356e+000,2.938786e-003,0.000000e+000,-5.842757e-001,0.000000e+000,3,0.000000e+000,1.825000e+000,,,,,,,,,,,,,,,,,,0,5.000000e+000,5.000000e-001,2,1,1.362801e-003,0,0,0,
1432787190.387,,-9.000000e+003,5.001818e+000,3.142522e-003,0.000000e+000,-5.846598e-001,0.000000e+000,3,0.000000e+000,1.825000e+000,,,,,,,,,,,,,,,,,,0,5.000000e+000,5.000000e-001,2,1,3.960133e-003,0,0,0,
1432787200.409,,-9.000000e+003,5.003861e+000,3.143365e-003,0.000000e+000,-5.845598e-001,0.000000e+000,3,0.000000e+000,1.825000e+000,,,,,,,,,,,,,,,,,,0,5.000000e+000,5.000000e-001,2,1,2.849102e-003,0,0,0,
1432787316.702,,-1.000000e+004,5.002995e+000,3.231367e-003,0.000000e+000,-5.851512e-001,0.000000e+000,3,0.000000e+000,1.825000e+000,,,,,,,,,,,,,,,,,,0,5.000000e+000,5.000000e-001,2,1,5.572319e-003,0,1,0,
1432787326.773,,-1.000000e+004,5.004728e+000,3.230742e-003,0.000000e+000,-5.847535e-001,0.000000e+000,3,0.000000e+000,1.825000e+000,,,,,,,,,,,,,,,,,,0,5.000000e+000,5.000000e-001,2,1,2.106190e-003,0,1,0,
1432787481.456,,-2.000000e+004,5.003243e+000,3.922004e-003,0.000000e+000,-5.850065e-001,0.000000e+000,3,0.000000e+000,1.825000e+000,,,,,,,,,,,,,,,,,,0,5.000000e+000,5.000000e-001,2,1,6.069183e-003,0,1,0,
1432787491.479,,-2.000000e+004,5.005161e+000,3.922893e-003,0.000000e+000,-5.842574e-001,0.000000e+000,3,0.000000e+000,1.825000e+000,,,,,,,,,,,,,,,,,,0,5.000000e+000,5.000000e-001,2,1,1.239300e-003,0,1,0,
1432787657.625,,-3.000000e+004,5.004913e+000,4.469083e-003,0.000000e+000,-5.846024e-001,0.000000e+000,3,0.000000e+000,1.825000e+000,,,,,,,,,,,,,,,,,,0,5.000000e+000,5.000000e-001,2,1,4.949570e-004,0,1,0,
1432787667.840,,-3.000000e+004,5.003366e+000,4.472650e-003,0.000000e+000,-5.843057e-001,0.000000e+000,3,0.000000e+000,1.825000e+000,,,,,,,,,,,,,,,,,,0,5.000000e+000,5.000000e-001,2,1,3.709793e-004,0,1,0,
1432787826.571,,-4.000000e+004,5.002933e+000,4.933717e-003,0.000000e+000,-5.843745e-001,0.000000e+000,3,0.000000e+000,1.825000e+000,,,,,,,,,,,,,,,,,,0,5.000000e+000,5.000000e-001,2,1,5.448341e-003,0,0,0,
1432787836.785,,-4.000000e+004,5.004232e+000,4.928419e-003,0.000000e+000,-5.844222e-001,0.000000e+000,3,0.000000e+000,1.825000e+000,,,,,,,,,,,,,,,,,,0,5.000000e+000,5.000000e-001,2,1,8.678436e-004,0,0,0,
1432787997.722,,-5.000000e+004,5.003181e+000,5.313828e-003,0.000000e+000,-5.835409e-001,0.000000e+000,3,0.000000e+000,1.825000e+000,,,,,,,,,,,,,,,,,,0,5.000000e+000,5.000000e-001,2,1,5.697250e-003,0,0,0,
1432788007.498,,-5.000000e+004,5.004976e+000,5.313353e-003,0.000000e+000,-5.837193e-001,0.000000e+000,3,0.000000e+000,1.825000e+000,,,,,,,,,,,,,,,,,,0,5.000000e+000,5.000000e-001,2,1,2.108097e-003,0,0,0,
1432788164.537,,-6.000000e+004,5.002872e+000,5.618972e-003,0.000000e+000,-5.831946e-001,0.000000e+000,3,0.000000e+000,1.825000e+000,,,,,,,,,,,,,,,,,,0,5.000000e+000,5.000000e-001,2,1,6.315231e-003,0,0,0,
1432788174.659,,-6.000000e+004,5.004294e+000,5.614215e-003,0.000000e+000,-5.838360e-001,0.000000e+000,3,0.000000e+000,1.825000e+000,,,,,,,,,,,,,,,,,,0,5.000000e+000,5.000000e-001,2,1,1.238823e-003,0,0,0,
1432788333.172,,-7.000000e+004,5.003244e+000,5.852789e-003,0.000000e+000,-5.832339e-001,0.000000e+000,3,0.000000e+000,1.825000e+000,,,,,,,,,,,,,,,,,,0,5.000000e+000,5.000000e-001,2,1,6.316185e-003,0,1,0,
1432788343.386,,-7.000000e+004,5.005348e+000,5.849363e-003,0.000000e+000,-5.830280e-001,0.000000e+000,3,0.000000e+000,1.825000e+000,,,,,,,,,,,,,,,,,,0,5.000000e+000,5.000000e-001,2,1,2.108097e-003,0,1,0,
1432788506.374,,-6.000000e+004,5.002995e+000,5.614859e-003,0.000000e+000,-5.845526e-001,0.000000e+000,3,0.000000e+000,1.825000e+000,,,,,,,,,,,,,,,,,,0,5.000000e+000,5.000000e-001,2,1,5.324364e-003,0,1,0,
1432788516.291,,-6.000000e+004,5.004542e+000,5.615128e-003,0.000000e+000,-5.849136e-001,0.000000e+000,3,0.000000e+000,1.825000e+000,,,,,,,,,,,,,,,,,,0,5.000000e+000,5.000000e-001,2,1,2.229214e-003,0,1,0,
1432788677.079,,-5.000000e+004,5.003057e+000,5.309639e-003,0.000000e+000,-5.850682e-001,0.000000e+000,3,0.000000e+000,1.825000e+000,,,,,,,,,,,,,,,,,,0,5.000000e+000,5.000000e-001,2,1,5.697250e-003,0,1,0,
1432788687.152,,-5.000000e+004,5.004480e+000,5.303739e-003,0.000000e+000,-5.858950e-001,0.000000e+000,3,0.000000e+000,1.825000e+000,,,,,,,,,,,,,,,,,,0,5.000000e+000,5.000000e-001,2,1,8.678436e-004,0,1,0,
1432788840.362,,-4.000000e+004,5.002748e+000,4.928226e-003,0.000000e+000,-5.855907e-001,0.000000e+000,3,0.000000e+000,1.825000e+000,,,,,,,,,,,,,,,,,,0,5.000000e+000,5.000000e-001,2,1,5.077362e-003,0,0,0,
1432788850.466,,-4.000000e+004,5.003861e+000,4.928562e-003,0.000000e+000,-5.856017e-001,0.000000e+000,3,0.000000e+000,1.825000e+000,,,,,,,,,,,,,,,,,,0,5.000000e+000,5.000000e-001,2,1,1.113892e-003,0,0,0,
1432789007.147,,-3.000000e+004,5.003429e+000,4.468814e-003,0.000000e+000,-5.857778e-001,0.000000e+000,3,0.000000e+000,1.825000e+000,,,,,,,,,,,,,,,,,,0,5.000000e+000,5.000000e-001,2,1,6.441116e-003,0,0,0,
1432789017.173,,-3.000000e+004,5.004852e+000,4.466422e-003,0.000000e+000,-5.861154e-001,0.000000e+000,3,0.000000e+000,1.825000e+000,,,,,,,,,,,,,,,,,,0,5.000000e+000,5.000000e-001,2,1,1.364231e-003,0,0,0,
1432789173.265,,-2.000000e+004,5.002996e+000,3.919774e-003,0.000000e+000,-5.856679e-001,0.000000e+000,3,0.000000e+000,1.825000e+000,,,,,,,,,,,,,,,,,,0,5.000000e+000,5.000000e-001,2,1,6.068230e-003,0,0,0,
1432789183.481,,-2.000000e+004,5.004790e+000,3.918363e-003,0.000000e+000,-5.859851e-001,0.000000e+000,3,0.000000e+000,1.825000e+000,,,,,,,,,,,,,,,,,,0,5.000000e+000,5.000000e-001,2,1,1.488209e-003,0,0,0,
1432789336.914,,-1.000000e+004,5.003181e+000,3.226904e-003,0.000000e+000,-5.855708e-001,0.000000e+000,3,0.000000e+000,1.825000e+000,,,,,,,,,,,,,,,,,,0,5.000000e+000,5.000000e-001,2,1,5.697250e-003,0,1,0,
1432789346.986,,-1.000000e+004,5.005162e+000,3.227560e-003,0.000000e+000,-5.851669e-001,0.000000e+000,3,0.000000e+000,1.825000e+000,,,,,,,,,,,,,,,,,,0,5.000000e+000,5.000000e-001,2,1,1.736164e-003,0,1,0,
1432789463.491,,-9.000000e+003,5.003181e+000,3.138945e-003,0.000000e+000,-5.851664e-001,0.000000e+000,3,0.000000e+000,1.825000e+000,,,,,,,,,,,,,,,,,,0,5.000000e+000,5.000000e-001,2,1,5.697250e-003,0,1,0,
1432789473.407,,-9.000000e+003,5.004481e+000,3.138170e-003,0.000000e+000,-5.852180e-001,0.000000e+000,3,0.000000e+000,1.825000e+000,,,,,,,,,,,,,,,,,,0,5.000000e+000,5.000000e-001,2,1,3.098011e-003,0,1,0,
1432789592.692,,-7.000000e+003,5.003057e+000,2.934790e-003,0.000000e+000,-5.855151e-001,0.000000e+000,3,0.000000e+000,1.825000e+000,,,,,,,,,,,,,,,,,,0,5.000000e+000,5.000000e-001,2,1,5.448341e-003,0,1,0,
1432789602.967,,-7.000000e+003,5.004604e+000,2.936776e-003,0.000000e+000,-5.849916e-001,0.000000e+000,3,0.000000e+000,1.825000e+000,,,,,,,,,,,,,,,,,,0,5.000000e+000,5.000000e-001,2,1,1.364231e-003,0,1,0,
1432789722.757,,-5.000000e+003,5.002995e+000,2.674639e-003,0.000000e+000,-5.842703e-001,0.000000e+000,3,0.000000e+000,1.825000e+000,,,,,,,,,,,,,,,,,,0,5.000000e+000,5.000000e-001,2,1,5.077362e-003,0,1,0,
1432789732.829,,-5.000000e+003,5.004604e+000,2.674482e-003,0.000000e+000,-5.844808e-001,0.000000e+000,3,0.000000e+000,1.825000e+000,,,,,,,,,,,,,,,,,,0,5.000000e+000,5.000000e-001,2,1,1.859188e-003,0,1,0,
1432789845.256,,-3.000000e+003,5.002500e+000,2.294831e-003,0.000000e+000,-5.839674e-001,0.000000e+000,3,0.000000e+000,1.825000e+000,,,,,,,,,,,,,,,,,,0,5.000000e+000,5.000000e-001,2,1,4.827976e-003,0,0,0,
1432789855.328,,-3.000000e+003,5.004666e+000,2.294015e-003,0.000000e+000,-5.839211e-001,0.000000e+000,3,0.000000e+000,1.825000e+000,,,,,,,,,,,,,,,,,,0,5.000000e+000,5.000000e-001,2,1,1.240253e-003,0,0,0,
1432789973.803,,-1.000000e+003,5.002748e+000,1.592612e-003,0.000000e+000,-5.835460e-001,0.000000e+000,3,0.000000e+000,1.825000e+000,,,,,,,,,,,,,,,,,,0,5.000000e+000,5.000000e-001,2,1,5.572319e-003,0,0,0,
1432789983.603,,-1.000000e+003,5.004357e+000,1.591712e-003,0.000000e+000,-5.838361e-001,0.000000e+000,3,0.000000e+000,1.825000e+000,,,,,,,,,,,,,,,,,,0,5.000000e+000,5.000000e-001,2,1,2.354145e-003,0,0,0,
1432790109.105,,-5.000000e+002,5.004542e+000,1.275074e-003,0.000000e+000,-5.833567e-001,0.000000e+000,3,0.000000e+000,1.825000e+000,,,,,,,,,,,,,,,,,,0,5.000000e+000,5.000000e-001,2,1,2.229214e-003,0,0,0,
1432790119.570,,-5.000000e+002,5.002499e+000,1.275503e-003,0.000000e+000,-5.832694e-001,0.000000e+000,3,0.000000e+000,1.825000e+000,,,,,,,,,,,,,,,,,,0,5.000000e+000,5.000000e-001,2,1,1.857758e-003,0,0,0,
1432790223.745,,-4.000000e+002,5.002871e+000,1.198470e-003,0.000000e+000,-5.835501e-001,0.000000e+000,3,0.000000e+000,1.825000e+000,,,,,,,,,,,,,,,,,,0,5.000000e+000,5.000000e-001,2,1,4.580975e-003,0,1,0,
1432790233.770,,-4.000000e+002,5.004975e+000,1.198604e-003,0.000000e+000,-5.833489e-001,0.000000e+000,3,0.000000e+000,1.825000e+000,,,,,,,,,,,,,,,,,,0,5.000000e+000,5.000000e-001,2,1,1.363277e-003,0,1,0,
1432790337.644,,-3.000000e+002,5.003243e+000,1.113941e-003,0.000000e+000,-5.832528e-001,0.000000e+000,3,0.000000e+000,1.825000e+000,,,,,,,,,,,,,,,,,,0,5.000000e+000,5.000000e-001,2,1,5.820274e-003,0,1,0,
1432790347.880,,-3.000000e+002,5.005223e+000,1.113203e-003,0.000000e+000,-5.838783e-001,0.000000e+000,3,0.000000e+000,1.825000e+000,,,,,,,,,,,,,,,,,,0,5.000000e+000,5.000000e-001,2,1,1.859188e-003,0,1,0,
1432790451.854,,-2.000000e+002,5.002128e+000,1.019624e-003,0.000000e+000,-5.831652e-001,0.000000e+000,3,0.000000e+000,1.825000e+000,,,,,,,,,,,,,,,,,,0,5.000000e+000,5.000000e-001,2,1,3.589153e-003,0,1,0,
1432790461.771,,-2.000000e+002,5.004480e+000,1.020053e-003,0.000000e+000,-5.828254e-001,0.000000e+000,3,0.000000e+000,1.825000e+000,,,,,,,,,,,,,,,,,,0,5.000000e+000,5.000000e-001,2,1,1.857758e-003,0,1,0,
1432790565.602,,-1.000000e+002,5.003181e+000,9.159395e-004,0.000000e+000,-5.826488e-001,0.000000e+000,3,0.000000e+000,1.825000e+000,,,,,,,,,,,,,,,,,,0,5.000000e+000,5.000000e-001,2,1,5.697250e-003,0,1,0,
1432790575.519,,-1.000000e+002,5.004542e+000,9.119578e-004,0.000000e+000,-5.812465e-001,0.000000e+000,3,0.000000e+000,1.825000e+000,,,,,,,,,,,,,,,,,,0,5.000000e+000,5.000000e-001,2,1,0.000000e+000,0,1,0,
1432790672.884,,0.000000e+000,5.002872e+000,8.009708e-004,0.000000e+000,-5.830192e-001,0.000000e+000,3,0.000000e+000,1.825000e+000,,,,,,,,,,,,,,,,,,0,5.000000e+000,5.000000e-001,2,1,6.068230e-003,0,0,0,
1432790682.801,,0.000000e+000,5.004852e+000,8.007821e-004,0.000000e+000,-5.829918e-001,0.000000e+000,3,0.000000e+000,1.825000e+000,,,,,,,,,,,,,,,,,,0,5.000000e+000,5.000000e-001,2,1,2.108097e-003,0,0,0,
1432790786.334,,1.000000e+002,5.002562e+000,6.693289e-004,0.000000e+000,-5.832861e-001,0.000000e+000,3,0.000000e+000,1.825000e+000,,,,,,,,,,,,,,,,,,0,5.000000e+000,5.000000e-001,2,1,4.704952e-003,0,0,0,
1432790796.406,,1.000000e+002,5.004913e+000,6.667604e-004,0.000000e+000,-5.832728e-001,0.000000e+000,3,0.000000e+000,1.825000e+000,,,,,,,,,,,,,,,,,,0,5.000000e+000,5.000000e-001,2,1,9.908676e-004,0,0,0,
1432790909.150,,2.000000e+002,5.004480e+000,5.093534e-004,0.000000e+000,-5.821183e-001,0.000000e+000,3,0.000000e+000,1.825000e+000,,,,,,,,,,,,,,,,,,0,5.000000e+000,5.000000e-001,2,1,2.601147e-003,0,0,0,
1432790919.364,,2.000000e+002,5.002561e+000,5.085265e-004,0.000000e+000,-5.821438e-001,0.000000e+000,3,0.000000e+000,1.825000e+000,,,,,,,,,,,,,,,,,,0,5.000000e+000,5.000000e-001,2,1,1.980782e-003,0,0,0,
1432791023.588,,3.000000e+002,5.002996e+000,3.218327e-004,0.000000e+000,-5.816441e-001,0.000000e+000,3,0.000000e+000,1.825000e+000,,,,,,,,,,,,,,,,,,0,5.000000e+000,5.000000e-001,2,1,5.820274e-003,0,1,0,
1432791033.600,,3.000000e+002,5.004851e+000,3.221627e-004,0.000000e+000,-5.800263e-001,0.000000e+000,3,0.000000e+000,1.825000e+000,,,,,,,,,,,,,,,,,,0,5.000000e+000,5.000000e-001,2,1,1.114845e-003,0,1,0,
1432791147.849,,4.000000e+002,5.005410e+000,1.132292e-004,0.000000e+000,-5.726173e-001,0.000000e+000,3,0.000000e+000,1.825000e+000,,,,,,,,,,,,,,,,,,0,5.000000e+000,5.000000e-001,2,1,2.232075e-003,0,1,0,
1432791158.314,,4.000000e+002,5.003861e+000,1.115382e-004,0.000000e+000,-5.713589e-001,0.000000e+000,3,0.000000e+000,1.825000e+000,,,,,,,,,,,,,,,,,,0,5.000000e+000,5.000000e-001,2,1,8.659363e-004,0,1,0,
1432791262.571,,5.000000e+002,5.003119e+000,-8.497372e-005,0.000000e+000,-1.062081e+000,0.000000e+000,3,0.000000e+000,1.825000e+000,,,,,,,,,,,,,,,,,,0,5.000000e+000,5.000000e-001,2,1,5.573273e-003,0,1,0,
1432791273.535,,5.000000e+002,5.003922e+000,-1.196200e-004,0.000000e+000,-5.833697e-001,0.000000e+000,3,0.000000e+000,1.825000e+000,,,,,,,,,,,,,,,,,,0,5.000000e+000,5.000000e-001,2,1,7.429123e-004,0,1,0,
1432791398.241,,1.000000e+003,5.004543e+000,-1.123614e-003,0.000000e+000,-5.847204e-001,0.000000e+000,3,0.000000e+000,1.825000e+000,,,,,,,,,,,,,,,,,,0,5.000000e+000,5.000000e-001,2,1,2.726078e-003,0,1,0,
1432791408.206,,1.000000e+003,5.002561e+000,-1.124157e-003,0.000000e+000,-5.847014e-001,0.000000e+000,3,0.000000e+000,1.825000e+000,,,,,,,,,,,,,,,,,,0,5.000000e+000,5.000000e-001,2,1,1.238823e-003,0,1,0,
1432791521.187,,3.000000e+003,5.003119e+000,-2.278188e-003,0.000000e+000,-5.837028e-001,0.000000e+000,3,0.000000e+000,1.825000e+000,,,,,,,,,,,,,,,,,,0,5.000000e+000,5.000000e-001,2,1,5.077362e-003,0,0,0,
1432791531.401,,3.000000e+003,5.004356e+000,-2.278649e-003,0.000000e+000,-5.842580e-001,0.000000e+000,3,0.000000e+000,1.825000e+000,,,,,,,,,,,,,,,,,,0,5.000000e+000,5.000000e-001,2,1,2.602100e-003,0,0,0,
1432791644.626,,5.000000e+003,5.002934e+000,-2.676676e-003,0.000000e+000,-5.840188e-001,0.000000e+000,3,0.000000e+000,1.825000e+000,,,,,,,,,,,,,,,,,,0,5.000000e+000,5.000000e-001,2,1,5.944252e-003,0,0,0,
1432791654.794,,5.000000e+003,5.004480e+000,-2.675898e-003,0.000000e+000,-5.841438e-001,0.000000e+000,3,0.000000e+000,1.825000e+000,,,,,,,,,,,,,,,,,,0,5.000000e+000,5.000000e-001,2,1,8.678436e-004,0,0,0,
1432791774.376,,7.000000e+003,5.002872e+000,-2.939397e-003,0.000000e+000,-5.838954e-001,0.000000e+000,3,0.000000e+000,1.825000e+000,,,,,,,,,,,,,,,,,,0,5.000000e+000,5.000000e-001,2,1,5.819321e-003,0,0,0,
1432791784.925,,7.000000e+003,5.004851e+000,-2.938269e-003,0.000000e+000,-5.842568e-001,0.000000e+000,3,0.000000e+000,1.825000e+000,,,,,,,,,,,,,,,,,,0,5.000000e+000,5.000000e-001,2,1,1.859188e-003,0,0,0,
1432791899.651,,9.000000e+003,5.002686e+000,-3.144850e-003,0.000000e+000,-5.839784e-001,0.000000e+000,3,0.000000e+000,1.825000e+000,,,,,,,,,,,,,,,,,,0,5.000000e+000,5.000000e-001,2,1,5.200386e-003,0,0,0,
1432791909.866,,9.000000e+003,5.004295e+000,-3.142293e-003,0.000000e+000,-5.844339e-001,0.000000e+000,3,0.000000e+000,1.825000e+000,,,,,,,,,,,,,,,,,,0,5.000000e+000,5.000000e-001,2,1,1.982212e-003,0,0,0,
1432792026.294,,1.000000e+004,5.002810e+000,-3.230355e-003,0.000000e+000,-5.847770e-001,0.000000e+000,3,0.000000e+000,1.825000e+000,,,,,,,,,,,,,,,,,,0,5.000000e+000,5.000000e-001,2,1,4.953384e-003,0,1,0,
1432792036.865,,1.000000e+004,5.004109e+000,-3.231314e-003,0.000000e+000,-5.843462e-001,0.000000e+000,3,0.000000e+000,1.825000e+000,,,,,,,,,,,,,,,,,,0,5.000000e+000,5.000000e-001,2,1,3.096104e-003,0,1,0,
1432792191.099,,2.000000e+004,5.003057e+000,-3.922458e-003,0.000000e+000,-5.841610e-001,0.000000e+000,3,0.000000e+000,1.825000e+000,,,,,,,,,,,,,,,,,,0,5.000000e+000,5.000000e-001,2,1,5.448341e-003,0,1,0,
1432792201.314,,2.000000e+004,5.004851e+000,-3.920834e-003,0.000000e+000,-5.844398e-001,0.000000e+000,3,0.000000e+000,1.825000e+000,,,,,,,,,,,,,,,,,,0,5.000000e+000,5.000000e-001,2,1,1.859188e-003,0,1,0,
1432792373.508,,3.000000e+004,5.004047e+000,-4.473703e-003,0.000000e+000,-5.846363e-001,0.000000e+000,3,0.000000e+000,1.825000e+000,,,,,,,,,,,,,,,,,,0,5.000000e+000,5.000000e-001,2,1,2.477169e-003,0,1,0,
1432792383.559,,3.000000e+004,5.002128e+000,-4.473474e-003,0.000000e+000,-5.840802e-001,0.000000e+000,3,0.000000e+000,1.825000e+000,,,,,,,,,,,,,,,,,,0,5.000000e+000,5.000000e-001,2,1,2.353191e-003,0,1,0,
1432792542.239,,4.000000e+004,5.002686e+000,-4.935628e-003,0.000000e+000,-5.837122e-001,0.000000e+000,3,0.000000e+000,1.825000e+000,,,,,,,,,,,,,,,,,,0,5.000000e+000,5.000000e-001,2,1,5.446911e-003,0,0,0,
1432792552.312,,4.000000e+004,5.004728e+000,-4.925298e-003,0.000000e+000,-5.839392e-001,0.000000e+000,3,0.000000e+000,1.825000e+000,,,,,,,,,,,,,,,,,,0,5.000000e+000,5.000000e-001,2,1,1.116276e-003,0,0,0,
1432792713.500,,5.000000e+004,5.002004e+000,-5.312443e-003,0.000000e+000,-5.835140e-001,0.000000e+000,3,0.000000e+000,1.825000e+000,,,,,,,,,,,,,,,,,,0,5.000000e+000,5.000000e-001,2,1,4.084110e-003,0,0,0,
1432792723.524,,5.000000e+004,5.003737e+000,-5.312013e-003,0.000000e+000,-5.836586e-001,0.000000e+000,3,0.000000e+000,1.825000e+000,,,,,,,,,,,,,,,,,,0,5.000000e+000,5.000000e-001,2,1,2.847672e-003,0,0,0,
1432792886.862,,6.000000e+004,5.002810e+000,-5.618792e-003,0.000000e+000,-5.832332e-001,0.000000e+000,3,0.000000e+000,1.825000e+000,,,,,,,,,,,,,,,,,,0,5.000000e+000,5.000000e-001,2,1,5.943298e-003,0,0,0,
1432792896.777,,6.000000e+004,5.004604e+000,-5.614667e-003,0.000000e+000,-5.840161e-001,0.000000e+000,3,0.000000e+000,1.825000e+000,,,,,,,,,,,,,,,,,,0,5.000000e+000,5.000000e-001,2,1,6.198883e-004,0,0,0,
1432793055.347,,7.000000e+004,5.003305e+000,-5.852643e-003,0.000000e+000,-5.836133e-001,0.000000e+000,3,0.000000e+000,1.825000e+000,,,,,,,,,,,,,,,,,,0,5.000000e+000,5.000000e-001,2,1,5.945206e-003,0,1,0,
1432793065.669,,7.000000e+004,5.004914e+000,-5.849486e-003,0.000000e+000,-5.835627e-001,0.000000e+000,3,0.000000e+000,1.825000e+000,,,,,,,,,,,,,,,,,,0,5.000000e+000,5.000000e-001,2,1,1.240253e-003,0,1,0,