File: data/A269/A269_GdN_MH_50K_150528.rso.raw
[Header]
TITLE,MPMS RSO Measurement
BYAPP,MPMS Measurement,2.1,Raw with ABS
FILEOPENTIME, 1432823279.233000 5/29/2015, 2:27:59 AM

INFO, APPNAME, MPMS MultiVu Application, Revision 1.61,  Build 082

INFO, NAME, A269
INFO, WEIGHT, 22.300
INFO, AREA, 1.000
INFO, LENGTH, 1.000
INFO, SHAPE, 1
INFO, COMMENT, m = 0.0223g
INFO, SEQUENCE FILE: 7T_hysteresis_sweep.seq


INFO, BACKGROUND DATA FILE:, None


STARTUPAXIS,X,8,LINEAR,AUTO,0.000000,0.000000
STARTUPAXIS,Y1,9,LINEAR,AUTO,0.000000,0.000000


STARTUPGROUP,Longitudinal
FIELDGROUP,Longitudinal,1,2,3,4,5,6,7,8,9,10,11,12,13,14,15,16,17,18,19,20,21,22
FIELDGROUP,Transverse,1,2,3,4,5,6,7,8,23,24,25,26,27,28,29,30,31,32,33,34,35,36

PLOT_APPEARANCE,ALL,HORZ_GRID_ON,VERT_GRID_ON,MARKERS_ONLY

[Data]
Time,Comment,Field (Oe),Start Temperature (K),End Temperature (K),Scan,Rejected,Position (cm),Long Voltage,Long Average Voltage,Long Detrended Voltage,Long Demeaned Voltage,Long Reg Fit,Long Detrended Fit,Long Demeaned Fit,Long Scaled Response,Long Avg. Scaled Response,Long Background Response,Long Response [w/ABS],Long Detrended Resp. [w/ABS],Long Fit [w/ABS],Long Detrended Fit [w/ABS],Trans Voltage,Trans Average Voltage,Trans Detrended Voltage,Trans Demeaned Voltage,Trans Reg Fit,Trans Detrended Fit,Trans Demeaned Fit,Trans Scaled Response,Trans Avg. Scaled Response,Trans Background Response,Trans Response [w/ABS],Trans Detrended Resp. [w/ABS],Trans Adjusted Fit,Trans Detrended Fit [w/ABS],
1432823279.222,,7.000000e+004,5.002487e+001,5.001616e+001,1,0,2.591046e+000,4.806665e-002,4.806665e-002,-2.050471e-003,-2.050471e-003,-7.266126e-002,-1.227784e-001,-1.227784e-001,6.023255e-004,6.023255e-004,,,,,,,,,,,,,,,,,,,,
1432823279.222,,7.000000e+004,5.002487e+001,5.001616e+001,1,0,4.317264e+000,5.296487e-001,5.296487e-001,2.390584e-001,4.795316e-001,3.517074e-001,6.111703e-002,3.015902e-001,6.637053e-003,6.637053e-003,,,,,,,,,,,,,,,,,,,,
1432823289.686,,7.000000e+004,5.001616e+001,5.001243e+001,1,0,9.152445e-002,2.156133e-001,2.156133e-001,1.988394e-002,1.250779e-001,3.232355e-001,1.275062e-001,2.327001e-001,2.701860e-003,2.701860e-003,,,,,,,,,,,,,,,,,,,,
1432823289.686,,7.000000e+004,5.001616e+001,5.001243e+001,1,0,3.621332e+000,9.063998e-001,9.063997e-001,4.710620e-001,8.158643e-001,5.743246e-001,1.389869e-001,4.837892e-001,1.135814e-002,1.135814e-002,,,,,,,,,,,,,,,,,,,,
1432823459.375,,6.000000e+004,4.999752e+001,4.999877e+001,1,0,3.308413e+000,5.751213e-001,5.751213e-001,3.763703e-001,5.596070e-001,3.064408e-001,1.076898e-001,2.909265e-001,7.211178e-003,7.211178e-003,,,,,,,,,,,,,,,,,,,,
1432823469.401,,6.000000e+004,4.999877e+001,5.000001e+001,1,0,1.310800e-001,1.464888e-001,1.464888e-001,4.190741e-002,1.079663e-001,2.255965e-001,1.210151e-001,1.870740e-001,1.836755e-003,1.836755e-003,,,,,,,,,,,,,,,,,,,,
1432823469.401,,6.000000e+004,4.999877e+001,5.000001e+001,1,0,4.451227e+000,3.508103e-001,3.508103e-001,3.788912e-002,3.122877e-001,3.578296e-001,4.490843e-002,3.193071e-001,4.398646e-003,4.398646e-003,,,,,,,,,,,,,,,,,,,,
1432823630.532,,5.000000e+004,5.000001e+001,4.999877e+001,1,0,2.189170e+000,-1.692251e-001,-1.692251e-001,-2.842087e-001,-1.509523e-001,-1.156489e-001,-2.306325e-001,-9.737603e-002,-2.123102e-003,-2.123102e-003,,,,,,,,,,,,,,,,,,,,
1432823640.699,,5.000000e+004,4.999877e+001,5.000125e+001,1,0,8.672947e-001,8.850367e-002,8.850368e-002,2.681060e-002,6.390396e-002,8.887566e-002,2.718258e-002,6.427594e-002,1.110369e-003,1.110369e-003,,,,,,,,,,,,,,,,,,,,
1432823640.699,,5.000000e+004,4.999877e+001,5.000125e+001,1,0,4.966683e+000,-3.128147e-002,-3.128147e-002,-2.830780e-001,-5.588119e-002,2.689491e-001,1.715256e-002,2.443494e-001,-3.924581e-004,-3.924581e-004,,,,,,,,,,,,,,,,,,,,
1432823800.238,,4.000000e+004,4.999877e+001,4.999628e+001,1,0,1.199459e+000,4.577776e-003,4.577776e-003,-8.566305e-002,1.401770e-002,2.209292e-002,-6.814791e-002,3.153285e-002,5.746715e-005,5.746715e-005,,,,,,,,,,,,,,,,,,,,
1432823810.059,,4.000000e+004,4.999628e+001,4.999752e+001,1,0,1.914607e+000,-1.173437e-001,-1.173437e-001,-1.185585e-001,-1.070535e-001,-2.324394e-001,-2.336542e-001,-2.221492e-001,-1.473075e-003,-1.473075e-003,,,,,,,,,,,,,,,,,,,,
1432823810.059,,4.000000e+004,4.999628e+001,4.999752e+001,1,0,4.767249e+000,3.479110e-002,3.479110e-002,-1.236587e-001,4.508126e-002,1.793015e-001,2.085174e-002,1.895917e-001,4.367504e-004,4.367504e-004,,,,,,,,,,,,,,,,,,,,
1432823976.499,,3.000000e+004,5.000125e+001,4.999752e+001,1,0,4.099928e-001,1.455733e-001,1.455733e-001,-1.935406e-002,1.466193e-001,3.750516e-001,2.101243e-001,3.760976e-001,7.314183e-004,7.314183e-004,,,,,,,,,,,,,,,,,,,,
1432823976.499,,3.000000e+004,5.000125e+001,4.999752e+001,1,0,3.027119e+000,4.753258e-001,4.753258e-001,-1.364469e-002,4.763718e-001,5.578485e-001,6.887797e-002,5.588944e-001,2.388226e-003,2.388226e-003,,,,,,,,,,,,,,,,,,,,
1432823986.570,,3.000000e+004,4.999752e+001,4.999877e+001,1,0,3.940154e+000,1.131016e+000,1.131016e+000,8.548562e-001,1.163079e+000,4.414559e-001,1.652961e-001,4.735193e-001,5.682675e-003,5.682675e-003,,,,,,,,,,,,,,,,,,,,
1432824141.502,,2.000000e+004,5.000125e+001,5.000001e+001,1,0,9.088381e-003,5.844294e-002,5.844295e-002,3.739179e-002,1.259526e-001,1.654225e-001,1.443714e-001,2.329322e-001,2.938157e-004,2.938157e-004,,,,,,,,,,,,,,,,,,,,
1432824141.502,,2.000000e+004,5.000125e+001,5.000001e+001,1,0,3.974153e+000,7.612842e-001,7.612842e-001,5.132960e-001,8.287939e-001,3.725918e-001,1.246036e-001,4.401014e-001,3.827275e-003,3.827275e-003,,,,,,,,,,,,,,,,,,,,
1432824151.527,,2.000000e+004,5.000373e+001,5.000498e+001,1,0,2.861632e+000,1.451155e-001,1.451155e-001,3.031819e-002,2.149797e-001,9.913874e-002,-1.565858e-002,1.690029e-001,7.295528e-004,7.295528e-004,,,,,,,,,,,,,,,,,,,,
1432824313.861,,1.000000e+004,5.000125e+001,5.000249e+001,1,0,3.637149e-001,1.188696e-001,1.188696e-001,1.484932e-001,2.807871e-001,4.099338e-001,4.395574e-001,5.718513e-001,1.494900e-004,1.494900e-004,,,,,,,,,,,,,,,,,,,,
1432824313.861,,1.000000e+004,5.000125e+001,5.000249e+001,1,0,4.717797e+000,-1.087985e-001,-1.087985e-001,-5.722703e-001,5.311897e-002,5.612608e-001,9.778895e-002,7.231783e-001,-1.368247e-004,-1.368247e-004,,,,,,,,,,,,,,,,,,,,
1432824324.076,,1.000000e+004,5.000249e+001,5.000001e+001,1,0,1.767939e+000,-6.474501e-001,-6.474501e-001,-8.970010e-001,-5.386333e-001,-7.123193e-001,-9.618701e-001,-6.035024e-001,-8.142314e-004,-8.142314e-004,,,,,,,,,,,,,,,,,,,,
1432824440.302,,9.000000e+003,5.000746e+001,5.000249e+001,1,0,1.265055e+000,-4.281747e-001,-4.281747e-001,-3.206512e-002,3.796056e-002,-7.576870e-001,-3.615775e-001,-2.915518e-001,-5.385032e-004,-5.385032e-004,,,,,,,,,,,,,,,,,,,,
1432824440.302,,9.000000e+003,5.000746e+001,5.000249e+001,1,0,4.985109e+000,-9.315775e-001,-9.315775e-001,-1.013977e+000,-4.654423e-001,1.414388e-001,5.903947e-002,6.075740e-001,-1.171619e-003,-1.171619e-003,,,,,,,,,,,,,,,,,,,,
1432824450.780,,9.000000e+003,5.000249e+001,5.000125e+001,1,0,8.604339e-001,-3.323466e-001,-3.323466e-001,-1.805322e-001,1.112075e-001,-5.235601e-002,9.945829e-002,3.911980e-001,-4.179829e-004,-4.179829e-004,,,,,,,,,,,,,,,,,,,,
1432824571.261,,7.000000e+003,5.000001e+001,4.999877e+001,1,0,2.366443e+000,-3.486740e-001,-3.486740e-001,-3.062845e-001,-2.964278e-001,-5.805427e-001,-5.381533e-001,-5.282965e-001,-4.385696e-004,-4.385696e-004,,,,,,,,,,,,,,,,,,,,
1432824571.261,,7.000000e+003,5.000001e+001,4.999877e+001,1,0,4.487081e+000,5.578784e-001,5.578784e-001,1.961394e-001,6.101246e-001,4.766256e-001,1.148865e-001,5.288718e-001,7.017114e-004,7.017114e-004,,,,,,,,,,,,,,,,,,,,
1432824581.725,,7.000000e+003,4.999752e+001,5.000001e+001,1,0,1.774002e-001,-2.345347e-001,-2.345347e-001,1.252784e-002,2.047504e-001,9.688425e-002,3.439468e-001,5.361694e-001,-2.950029e-004,-2.950029e-004,,,,,,,,,,,,,,,,,,,,
1432824581.725,,7.000000e+003,4.999752e+001,5.000001e+001,1,0,3.431567e+000,1.111026e+000,1.111026e+000,9.432927e-001,1.550311e+000,5.089712e-001,3.412376e-001,9.482564e-001,1.397473e-003,1.397473e-003,,,,,,,,,,,,,,,,,,,,
1432824701.452,,5.000000e+003,4.999877e+001,4.999380e+001,1,0,3.526334e+000,1.179235e+000,1.179235e+000,1.179964e+000,1.438094e+000,2.842632e-001,2.849923e-001,5.431224e-001,1.483444e-003,1.483444e-003,,,,,,,,,,,,,,,,,,,,
1432824711.666,,5.000000e+003,4.999380e+001,4.999628e+001,1,0,5.722933e-002,1.850948e-001,1.850948e-001,7.529135e-002,1.838307e-001,3.640104e-001,2.542070e-001,3.627463e-001,2.328439e-004,2.328439e-004,,,,,,,,,,,,,,,,,,,,
1432824711.666,,5.000000e+003,4.999380e+001,4.999628e+001,1,0,4.299902e+000,7.683035e-001,7.683035e-001,3.406349e-001,7.670394e-001,5.545372e-001,1.268687e-001,5.532731e-001,9.665039e-004,9.665039e-004,,,,,,,,,,,,,,,,,,,,
1432824830.626,,3.000000e+003,4.999877e+001,4.999877e+001,1,0,2.410530e+000,-6.678976e-001,-6.678976e-001,-4.075059e-001,-2.820239e-001,-5.438968e-001,-2.835051e-001,-1.580231e-001,-8.402960e-004,-8.402960e-004,,,,,,,,,,,,,,,,,,,,
1432824840.697,,3.000000e+003,4.999752e+001,5.000249e+001,1,0,6.833031e-001,9.079257e-002,9.079257e-002,6.068824e-002,9.681089e-002,1.572452e-001,1.271409e-001,1.632635e-001,1.142280e-004,1.142280e-004,,,,,,,,,,,,,,,,,,,,
1432824840.697,,3.000000e+003,4.999752e+001,5.000249e+001,1,0,4.910780e+000,-2.819910e-001,-2.819910e-001,-4.766541e-001,-2.759727e-001,2.273770e-001,3.271393e-002,2.333953e-001,-3.547788e-004,-3.547788e-004,,,,,,,,,,,,,,,,,,,,
1432824959.422,,1.000000e+003,4.999877e+001,5.000125e+001,1,0,1.380999e+000,-6.711020e-001,-6.711020e-001,-1.111991e-001,-1.579852e-001,-6.765971e-001,-1.166941e-001,-1.634803e-001,-8.444281e-004,-8.444281e-004,,,,,,,,,,,,,,,,,,,,
1432824979.616,,1.000000e+003,5.000125e+001,5.000125e+001,1,0,1.693249e+000,-2.642598e+000,-2.642598e+000,-3.250132e-001,-3.304787e-001,-3.287700e+000,-9.701152e-001,-9.755807e-001,-6.650208e-004,-6.650208e-004,,,,,,,,,,,,,,,,,,,,
1432824979.616,,1.000000e+003,5.000125e+001,5.000125e+001,1,0,4.870892e+000,-3.308054e+000,-3.308054e+000,-9.344484e-001,-9.959347e-001,-2.290920e+000,8.268559e-002,2.119923e-002,-8.324856e-004,-8.324856e-004,,,,,,,,,,,,,,,,,,,,
1432825091.091,,5.000000e+002,4.999877e+001,4.999628e+001,1,0,5.500448e-001,-2.449110e+000,-2.449110e+000,-7.294035e-002,-2.572799e-001,-2.485236e+000,-1.090662e-001,-2.934058e-001,-6.163472e-004,-6.163472e-004,,,,,,,,,,,,,,,,,,,,
1432825091.091,,5.000000e+002,4.999877e+001,4.999628e+001,1,0,2.812581e+000,-3.265633e+000,-3.265633e+000,-5.459213e-001,-1.073803e+000,-2.599284e+000,1.204276e-001,-4.074538e-001,-8.218347e-004,-8.218347e-004,,,,,,,,,,,,,,,,,,,,
1432825101.805,,5.000000e+002,4.999628e+001,4.999628e+001,1,0,4.134144e+000,-1.030457e+000,-1.030457e+000,8.589629e-001,7.513398e-001,-1.865482e+000,2.393841e-002,-8.368468e-002,-2.593267e-004,-2.593267e-004,,,,,,,,,,,,,,,,,,,,
1432825206.040,,4.000000e+002,5.000125e+001,5.000125e+001,1,0,3.455570e-002,-1.533250e+000,-1.533250e+000,2.161144e-002,-6.059718e-002,-1.335789e+000,2.190720e-001,1.368634e-001,-3.858625e-004,-3.858625e-004,,,,,,,,,,,,,,,,,,,,
1432825206.040,,4.000000e+002,5.000125e+001,5.000125e+001,1,0,3.802101e+000,-8.317820e-001,-8.317820e-001,9.213473e-001,6.408708e-001,-1.532295e+000,2.208346e-001,-5.964184e-002,-2.093289e-004,-2.093289e-004,,,,,,,,,,,,,,,,,,,,
1432825216.504,,4.000000e+002,5.000001e+001,4.999628e+001,1,0,3.085839e+000,-5.325480e-002,-5.325480e-002,3.447824e-001,9.191341e-001,-3.081435e-001,8.989374e-002,6.642455e-001,-1.340227e-005,-1.340227e-005,,,,,,,,,,,,,,,,,,,,
1432825334.942,,3.000000e+002,4.999752e+001,4.999752e+001,1,0,2.344471e-001,-5.851924e-001,-5.851924e-001,9.222925e-003,-3.751850e-002,-5.554851e-001,3.893024e-002,-7.811189e-003,-7.363612e-004,-7.363612e-004,,,,,,,,,,,,,,,,,,,,
1432825334.942,,3.000000e+002,4.999752e+001,4.999752e+001,1,0,4.591656e+000,-7.806635e-001,-7.806635e-001,-2.654825e-002,-2.329895e-001,-7.450448e-001,9.070471e-003,-1.973708e-001,-9.823269e-004,-9.823269e-004,,,,,,,,,,,,,,,,,,,,
1432825344.967,,3.000000e+002,5.000125e+001,4.999877e+001,1,0,1.974985e+000,-6.907865e-001,-6.907865e-001,-1.031443e-001,-1.706918e-001,-6.102445e-001,-2.260229e-002,-9.014982e-002,-8.692326e-004,-8.692326e-004,,,,,,,,,,,,,,,,,,,,
1432825458.354,,2.000000e+002,4.999877e+001,4.999752e+001,1,0,1.060955e+000,-2.383953e+000,-2.383953e+000,4.455296e-002,-1.030684e-002,-2.507405e+000,-7.889875e-002,-1.337585e-001,-2.999802e-004,-2.999802e-004,,,,,,,,,,,,,,,,,,,,
1432825458.354,,2.000000e+002,4.999877e+001,4.999752e+001,1,0,4.993369e+000,-3.559832e+000,-3.559832e+000,-8.100036e-001,-1.186185e+000,-2.708391e+000,4.143725e-002,-3.347442e-001,-4.479445e-004,-4.479445e-004,,,,,,,,,,,,,,,,,,,,
1432825468.818,,2.000000e+002,4.999877e+001,4.999877e+001,1,0,1.026601e+000,-1.338847e+000,-1.338847e+000,-1.790417e-001,-1.025865e-001,-1.211925e+000,-5.212007e-002,2.433515e-002,-1.684712e-004,-1.684712e-004,,,,,,,,,,,,,,,,,,,,
1432825567.048,,1.000000e+002,4.999380e+001,4.999504e+001,1,0,2.139651e+000,-2.942442e+000,-2.942442e+000,-1.612556e-001,-1.882081e-001,-2.775417e+000,5.769482e-003,-2.118301e-002,-3.702587e-004,-3.702587e-004,,,,,,,,,,,,,,,,,,,,
1432825567.048,,1.000000e+002,4.999380e+001,4.999504e+001,1,0,4.637990e+000,-3.473769e+000,-3.473769e+000,-1.400567e-001,-7.195354e-001,-3.329927e+000,3.786006e-003,-5.756927e-001,-4.371176e-004,-4.371176e-004,,,,,,,,,,,,,,,,,,,,
1432825577.513,,1.000000e+002,4.999504e+001,4.999504e+001,1,0,2.846228e-001,-2.745750e+000,-2.745750e+000,-1.740330e-002,-2.667897e-001,-2.743568e+000,-1.522129e-002,-2.646077e-001,-3.455082e-004,-3.455082e-004,,,,,,,,,,,,,,,,,,,,
1432825577.513,,1.000000e+002,4.999504e+001,4.999504e+001,1,0,3.233608e+000,-3.085269e+000,-3.085269e+000,1.543202e-001,-6.063082e-001,-3.202375e+000,3.721378e-002,-7.234147e-001,-3.882311e-004,-3.882311e-004,,,,,,,,,,,,,,,,,,,,
1432825675.485,,0.000000e+000,5.000001e+001,4.999877e+001,1,0,3.736378e+000,-2.640309e+000,-2.640309e+000,-5.246365e-002,-7.810024e-001,-2.588073e+000,-2.275705e-004,-7.287663e-001,-3.322421e-004,-3.322421e-004,,,,,,,,,,,,,,,,,,,,
1432825685.993,,0.000000e+000,4.999877e+001,4.999504e+001,1,0,1.621029e-002,-1.413770e+000,-1.413770e+000,7.142835e-003,-1.653472e-001,-1.427480e+000,-6.566710e-003,-1.790568e-001,-1.779011e-004,-1.779011e-004,,,,,,,,,,,,,,,,,,,,
1432825685.993,,0.000000e+000,4.999877e+001,4.999504e+001,1,0,4.141462e+000,-1.912595e+000,-1.912595e+000,-2.020942e-002,-6.641723e-001,-1.898581e+000,-6.195061e-003,-6.501579e-001,-2.406706e-004,-2.406706e-004,,,,,,,,,,,,,,,,,,,,
1432825801.520,,-1.000000e+002,5.000001e+001,5.000498e+001,1,0,2.635352e+000,-2.267678e+000,-2.267678e+000,2.041300e-001,-6.481407e-001,-2.338307e+000,1.335012e-001,-7.187696e-001,-2.853505e-004,-2.853505e-004,,,,,,,,,,,,,,,,,,,,
1432825811.784,,-1.000000e+002,5.000498e+001,5.000125e+001,1,0,5.144348e-001,-1.840114e+000,-1.840114e+000,-6.111559e-002,-2.737269e-001,-1.945279e+000,-1.662807e-001,-3.788921e-001,-2.315485e-004,-2.315485e-004,,,,,,,,,,,,,,,,,,,,
1432825811.784,,-1.000000e+002,5.000498e+001,5.000125e+001,1,0,4.825214e+000,-2.301401e+000,-2.301401e+000,3.493036e-001,-7.350143e-001,-2.685714e+000,-3.500906e-002,-1.119327e+000,-2.895941e-004,-2.895941e-004,,,,,,,,,,,,,,,,,,,,
1432825916.007,,-2.000000e+002,5.000249e+001,5.000001e+001,1,0,1.569237e+000,-1.309549e+000,-1.309549e+000,4.976518e-001,-2.438428e-001,-1.275834e+000,5.313668e-001,-2.101278e-001,-1.647846e-004,-1.647846e-004,,,,,,,,,,,,,,,,,,,,
1432825936.436,,-2.000000e+002,5.000373e+001,5.000498e+001,1,0,1.475224e+000,-7.199317e-001,-7.199317e-001,4.200479e-002,-1.708251e-002,-5.354244e-001,2.265120e-001,1.674247e-001,-1.811824e-004,-1.811824e-004,,,,,,,,,,,,,,,,,,,,
1432825936.436,,-2.000000e+002,5.000373e+001,5.000498e+001,1,0,4.943830e+000,-8.893093e-001,-8.893093e-001,3.571430e-001,-1.864602e-001,-1.270025e+000,-2.357243e-002,-5.671756e-001,-2.238091e-004,-2.238091e-004,,,,,,,,,,,,,,,,,,,,
1432826034.230,,-3.000000e+002,5.000001e+001,4.999628e+001,1,0,7.027084e-001,-9.004486e-001,-9.004486e-001,5.753364e-002,-2.693572e-001,-1.081764e+000,-1.237815e-001,-4.506723e-001,-2.266111e-004,-2.266111e-004,,,,,,,,,,,,,,,,,,,,
1432826044.944,,-3.000000e+002,4.999628e+001,5.000373e+001,1,0,2.590950e+000,-2.246162e-001,-2.246162e-001,-8.475550e-002,-8.475550e-002,-1.422066e-001,-2.345890e-003,-2.345890e-003,-5.652796e-005,-5.652796e-005,,,,,,,,,,,,,,,,,,,,
1432826044.944,,-3.000000e+002,4.999628e+001,5.000373e+001,1,0,4.318371e+000,-1.488693e+000,-1.488693e+000,-4.254084e-001,-1.348832e+000,-1.063521e+000,-2.365801e-004,-9.236603e-001,-3.746513e-004,-3.746513e-004,,,,,,,,,,,,,,,,,,,,
1432826149.168,,-4.000000e+002,4.999877e+001,4.999628e+001,1,0,9.002712e-002,-4.080325e-001,-4.080325e-001,-1.727662e-002,-2.356789e-001,-6.287307e-001,-2.379748e-001,-4.563771e-001,-1.026867e-004,-1.026867e-004,,,,,,,,,,,,,,,,,,,,
1432826149.168,,-4.000000e+002,4.999877e+001,4.999628e+001,1,0,3.620568e+000,-1.820887e+000,-1.820887e+000,-9.326591e-001,-1.648533e+000,-1.146093e+000,-2.578654e-001,-9.737396e-001,-4.582501e-004,-4.582501e-004,,,,,,,,,,,,,,,,,,,,
1432826159.657,,-4.000000e+002,4.999628e+001,4.999877e+001,1,0,3.308610e+000,-1.543168e+000,-1.543168e+000,-8.073156e-001,-1.302964e+000,-9.568852e-001,-2.210324e-001,-7.166805e-001,-3.883586e-004,-3.883586e-004,,,,,,,,,,,,,,,,,,,,
1432826263.881,,-5.000000e+002,4.999877e+001,5.000001e+001,1,0,1.305442e-001,-9.289834e-001,-9.289834e-001,-8.284539e-002,-3.307586e-001,-1.133728e+000,-2.875902e-001,-5.355034e-001,-2.337895e-004,-2.337895e-004,,,,,,,,,,,,,,,,,,,,
1432826263.881,,-5.000000e+002,4.999877e+001,5.000001e+001,1,0,4.451766e+000,-1.704916e+000,-1.704916e+000,-7.689821e-002,-1.106692e+000,-1.733364e+000,-1.053455e-001,-1.135139e+000,-4.290621e-004,-4.290621e-004,,,,,,,,,,,,,,,,,,,,
1432826274.596,,-5.000000e+002,5.000001e+001,5.000125e+001,1,0,2.189871e+000,-2.136296e-001,-2.136296e-001,7.560785e-001,2.305478e-001,-3.777061e-001,5.920020e-001,6.647131e-002,-5.376237e-005,-5.376237e-005,,,,,,,,,,,,,,,,,,,,
1432826393.879,,-1.000000e+003,4.999628e+001,5.000249e+001,1,0,8.668289e-001,3.341777e-001,3.341777e-001,-6.175497e-002,-1.750467e-001,3.403452e-001,-5.558744e-002,-1.688792e-001,1.681944e-004,1.681944e-004,,,,,,,,,,,,,,,,,,,,
1432826393.879,,-1.000000e+003,4.999628e+001,5.000249e+001,1,0,4.966928e+000,4.493850e-001,4.493850e-001,6.340727e-001,-5.983937e-002,-2.207981e-001,-3.611044e-002,-7.300225e-001,2.261793e-004,2.261793e-004,,,,,,,,,,,,,,,,,,,,
1432826404.093,,-1.000000e+003,5.000249e+001,5.000125e+001,1,0,1.199266e+000,-6.630146e-001,-6.630146e-001,2.041781e-001,-1.585118e-001,-7.022873e-001,1.649053e-001,-1.977845e-001,-3.337008e-004,-3.337008e-004,,,,,,,,,,,,,,,,,,,,
1432826532.310,,-3.000000e+003,5.000249e+001,5.000249e+001,1,0,1.915214e+000,1.641896e-001,1.641896e-001,2.333028e-001,1.961982e-001,4.002073e-001,4.693205e-001,4.322159e-001,2.065704e-004,2.065704e-004,,,,,,,,,,,,,,,,,,,,
1432826532.310,,-3.000000e+003,5.000249e+001,5.000249e+001,1,0,4.767578e+000,-3.176977e-001,-3.176977e-001,2.585117e-001,-2.856891e-001,-6.176703e-001,-4.146094e-002,-5.856616e-001,-3.997021e-004,-3.997021e-004,,,,,,,,,,,,,,,,,,,,
1432826542.476,,-3.000000e+003,5.000249e+001,5.000001e+001,1,0,4.111714e-001,-4.637288e-001,-4.637288e-001,2.612223e-002,-2.375431e-001,-6.891328e-001,-1.992818e-001,-4.629471e-001,-5.834269e-004,-5.834269e-004,,,,,,,,,,,,,,,,,,,,
1432826542.476,,-3.000000e+003,5.000249e+001,5.000001e+001,1,0,3.026147e+000,-9.935301e-001,-9.935301e-001,1.109611e-002,-7.673445e-001,-1.071844e+000,-6.721766e-002,-8.456582e-001,-1.249981e-003,-1.249981e-003,,,,,,,,,,,,,,,,,,,,
1432826662.296,,-5.000000e+003,4.999628e+001,4.999504e+001,1,0,3.939350e+000,-2.388836e+000,-2.388836e+000,-1.151270e+000,-1.820516e+000,-1.455700e+000,-2.181336e-001,-8.873798e-001,-3.005088e-003,-3.005088e-003,,,,,,,,,,,,,,,,,,,,
1432826672.320,,-5.000000e+003,4.999628e+001,4.999504e+001,1,0,9.194463e-003,-7.046724e-001,-7.046724e-001,-5.479532e-002,-3.200219e-001,-8.944395e-001,-2.445624e-001,-5.097890e-001,-8.864577e-004,-8.864577e-004,,,,,,,,,,,,,,,,,,,,
1432826672.320,,-5.000000e+003,4.999628e+001,4.999504e+001,1,0,3.975797e+000,-2.203436e+000,-2.203436e+000,-8.739162e-001,-1.818786e+000,-1.537302e+000,-2.077815e-001,-1.152651e+000,-2.771860e-003,-2.771860e-003,,,,,,,,,,,,,,,,,,,,
1432826792.605,,-7.000000e+003,5.000001e+001,5.000125e+001,1,0,2.861109e+000,-1.311075e+000,-1.311075e+000,-6.591766e-002,-7.366731e-001,-1.213730e+000,3.142782e-002,-6.393276e-001,-1.649099e-003,-1.649099e-003,,,,,,,,,,,,,,,,,,,,
1432826802.379,,-7.000000e+003,5.000001e+001,5.000125e+001,1,0,3.640899e-001,-8.732871e-001,-8.732871e-001,-1.175114e-001,-3.297944e-001,-1.107929e+000,-3.521532e-001,-5.644363e-001,-1.098439e-003,-1.098439e-003,,,,,,,,,,,,,,,,,,,,
1432826802.379,,-7.000000e+003,5.000001e+001,5.000125e+001,1,0,4.718176e+000,-1.084628e+000,-1.084628e+000,4.623846e-001,-5.411351e-001,-1.625253e+000,-7.824096e-002,-1.081761e+000,-1.364268e-003,-1.364268e-003,,,,,,,,,,,,,,,,,,,,
1432826922.516,,-9.000000e+003,4.999877e+001,4.999380e+001,1,0,1.767999e+000,1.329081e-001,1.329081e-001,8.463424e-001,3.113963e-001,1.913159e-001,9.047503e-001,3.698041e-001,1.671548e-004,1.671548e-004,,,,,,,,,,,,,,,,,,,,
1432826932.731,,-9.000000e+003,4.999380e+001,4.999628e+001,1,0,1.265451e+000,-3.544725e-001,-3.544725e-001,3.138391e-002,-8.629981e-002,-2.358313e-002,3.622733e-001,2.445896e-001,-4.458101e-004,-4.458101e-004,,,,,,,,,,,,,,,,,,,,
1432826932.731,,-9.000000e+003,4.999380e+001,4.999628e+001,1,0,4.984994e+000,-1.747185e-001,-1.747185e-001,1.015310e+000,9.345421e-002,-1.249381e+000,-5.935222e-002,-9.812080e-001,-2.197385e-004,-2.197385e-004,,,,,,,,,,,,,,,,,,,,
1432827048.956,,-1.000000e+004,5.000001e+001,4.999628e+001,1,0,8.593061e-001,-9.961241e-001,-9.961241e-001,1.922221e-001,-3.733982e-001,-1.297338e+000,-1.089914e-001,-6.746117e-001,-1.252723e-003,-1.252723e-003,,,,,,,,,,,,,,,,,,,,
1432827058.920,,-1.000000e+004,4.999877e+001,5.000249e+001,1,0,2.366750e+000,-2.957244e-001,-2.957244e-001,3.869570e-001,3.638335e-001,-4.477059e-003,6.782044e-001,6.550808e-001,-3.719021e-004,-3.719021e-004,,,,,,,,,,,,,,,,,,,,
1432827058.920,,-1.000000e+004,4.999877e+001,5.000249e+001,1,0,4.486467e+000,-1.879483e+000,-1.879482e+000,-2.487368e-001,-1.219924e+000,-1.775724e+000,-1.449780e-001,-1.116166e+000,-2.363632e-003,-2.363632e-003,,,,,,,,,,,,,,,,,,,,
1432827229.703,,-2.000000e+004,5.000249e+001,5.000249e+001,1,0,1.760526e-001,-3.723258e-001,-3.723258e-001,-8.671460e-003,-1.687357e-001,-5.284767e-001,-1.648224e-001,-3.248866e-001,-1.871828e-003,-1.871828e-003,,,,,,,,,,,,,,,,,,,,
1432827229.703,,-2.000000e+004,5.000249e+001,5.000249e+001,1,0,3.431997e+000,-1.155278e+000,-1.155278e+000,-4.462222e-001,-9.516881e-001,-8.726133e-001,-1.635572e-001,-6.690232e-001,-5.808038e-003,-5.808038e-003,,,,,,,,,,,,,,,,,,,,
1432827240.168,,-2.000000e+004,5.000249e+001,5.000249e+001,1,0,3.525661e+000,-1.200903e+000,-1.200903e+000,-6.900278e-001,-1.001124e+000,-6.808041e-001,-1.699285e-001,-4.810250e-001,-6.037414e-003,-6.037414e-003,,,,,,,,,,,,,,,,,,,,
1432827396.396,,-3.000000e+004,5.000001e+001,5.000001e+001,1,0,5.707615e-002,-4.641865e-001,-4.641865e-001,-6.367861e-002,-2.136675e-001,-5.927107e-001,-1.922028e-001,-3.421917e-001,-2.332258e-003,-2.332258e-003,,,,,,,,,,,,,,,,,,,,
1432827396.396,,-3.000000e+004,5.000001e+001,5.000001e+001,1,0,4.300241e+000,-1.098514e+000,-1.098514e+000,-2.587526e-001,-8.479947e-001,-9.367625e-001,-9.700142e-002,-6.862435e-001,-5.519371e-003,-5.519371e-003,,,,,,,,,,,,,,,,,,,,
1432827406.422,,-3.000000e+004,5.000373e+001,5.000249e+001,1,0,2.410377e+000,-2.883999e-002,-2.883999e-002,4.303015e-001,1.158419e-001,-1.536800e-001,3.054615e-001,-8.998126e-003,-1.449036e-004,-1.449036e-004,,,,,,,,,,,,,,,,,,,,
1432827564.861,,-4.000000e+004,5.000001e+001,4.999628e+001,1,0,6.836146e-001,-3.561510e-001,-3.561510e-001,-7.599517e-002,-1.864794e-001,-4.428203e-001,-1.626644e-001,-2.731487e-001,-1.788378e-003,-1.788378e-003,,,,,,,,,,,,,,,,,,,,
1432827564.861,,-4.000000e+004,5.000001e+001,4.999628e+001,1,0,4.910067e+000,-2.107303e-001,-2.107303e-001,5.727425e-001,-4.105869e-002,-8.250546e-001,-4.158179e-002,-6.553830e-001,-1.058162e-003,-1.058162e-003,,,,,,,,,,,,,,,,,,,,
1432827574.684,,-4.000000e+004,4.999628e+001,4.999877e+001,1,0,1.380794e+000,-1.858577e-001,-1.858577e-001,2.955755e-001,-3.148311e-002,-1.741835e-001,3.072497e-001,-1.980889e-002,-9.332665e-004,-9.332665e-004,,,,,,,,,,,,,,,,,,,,
1432827735.725,,-5.000000e+004,4.999877e+001,4.999628e+001,1,0,1.693464e+000,1.281777e-002,1.281777e-002,2.255959e-001,1.714793e-001,3.766240e-001,5.894021e-001,5.352855e-001,6.432483e-005,6.432483e-005,,,,,,,,,,,,,,,,,,,,
1432827735.725,,-5.000000e+004,4.999877e+001,4.999628e+001,1,0,4.870933e+000,-2.493362e-001,-2.493362e-001,5.181376e-001,-9.067473e-002,-8.173267e-001,-4.985290e-002,-6.586652e-001,-1.251271e-003,-1.251271e-003,,,,,,,,,,,,,,,,,,,,
1432827745.939,,-5.000000e+004,4.999628e+001,4.999628e+001,1,0,5.503754e-001,-3.968932e-001,-3.968932e-001,5.204074e-002,-2.406563e-001,-6.961197e-001,-2.471858e-001,-5.398828e-001,-1.991773e-003,-1.991773e-003,,,,,,,,,,,,,,,,,,,,
1432827745.939,,-5.000000e+004,4.999628e+001,4.999628e+001,1,0,2.812419e+000,-5.720695e-001,-5.720695e-001,4.223453e-001,-4.158325e-001,-9.228618e-001,7.155296e-002,-7.666249e-001,-2.870878e-003,-2.870878e-003,,,,,,,,,,,,,,,,,,,,
1432827902.653,,-6.000000e+004,5.000125e+001,5.000001e+001,1,0,4.134956e+000,-1.675924e+000,-1.675924e+000,-9.349918e-001,-1.517970e+000,-9.285403e-001,-1.876082e-001,-7.705867e-001,-8.405452e-003,-8.405452e-003,,,,,,,,,,,,,,,,,,,,
1432827912.677,,-6.000000e+004,5.000001e+001,5.000125e+001,1,0,3.580451e-002,-5.520798e-001,-5.520799e-001,-5.708053e-002,-3.027729e-001,-7.736543e-001,-2.786550e-001,-5.243474e-001,-2.768909e-003,-2.768909e-003,,,,,,,,,,,,,,,,,,,,
1432827912.677,,-6.000000e+004,5.000001e+001,5.000125e+001,1,0,3.801876e+000,-2.218085e+000,-2.218085e+000,-1.130534e+000,-1.968778e+000,-1.373932e+000,-2.863807e-001,-1.124625e+000,-1.112461e-002,-1.112461e-002,,,,,,,,,,,,,,,,,,,,
1432828090.217,,-7.000000e+004,4.999628e+001,4.999628e+001,1,0,3.086895e+000,-1.253243e+000,-1.253243e+000,-5.353428e-001,-1.054937e+000,-8.739373e-001,-1.560375e-001,-6.756318e-001,-6.281777e-003,-6.281777e-003,,,,,,,,,,,,,,,,,,,,
1432828100.241,,-7.000000e+004,4.999628e+001,4.999877e+001,1,0,2.341186e-001,-4.838710e-001,-4.838710e-001,-1.214457e-001,-3.004032e-001,-7.090782e-001,-3.466529e-001,-5.256104e-001,-2.425364e-003,-2.425364e-003,,,,,,,,,,,,,,,,,,,,
1432828100.241,,-7.000000e+004,4.999628e+001,4.999877e+001,1,0,4.591244e+000,-7.885983e-001,-7.885983e-001,1.852651e-001,-6.051306e-001,-1.070442e+000,-9.657834e-002,-8.869740e-001,-3.952785e-003,-3.952785e-003,,,,,,,,,,,,,,,,,,,,
1432828263.286,,-6.000000e+004,4.999752e+001,4.999628e+001,1,0,1.974856e+000,3.399762e-001,3.399762e-001,7.667834e-001,3.944082e-001,3.052110e-001,7.320182e-001,3.596430e-001,1.705121e-003,1.705121e-003,,,,,,,,,,,,,,,,,,,,
1432828273.811,,-6.000000e+004,4.999752e+001,4.999504e+001,1,0,1.061195e+000,-1.901303e-001,-1.901303e-001,-3.498419e-002,-1.239720e-001,-6.933635e-002,8.580976e-002,-3.178053e-003,-9.535822e-004,-9.535822e-004,,,,,,,,,,,,,,,,,,,,
1432828273.811,,-6.000000e+004,4.999752e+001,4.999504e+001,1,0,4.992962e+000,1.170385e-001,1.170385e-001,7.933989e-001,1.831968e-001,-7.218915e-001,-4.553107e-002,-6.557332e-001,5.869964e-004,5.869964e-004,,,,,,,,,,,,,,,,,,,,
1432828429.132,,-5.000000e+004,4.999504e+001,4.999256e+001,1,0,1.026073e+000,-2.655110e-002,-2.655110e-002,1.747698e-001,-1.100304e-001,-1.501132e-001,5.120775e-002,-2.335925e-001,-1.332443e-004,-1.332443e-004,,,,,,,,,,,,,,,,,,,,
1432828439.455,,-5.000000e+004,5.000001e+001,5.000249e+001,1,0,2.141404e+000,4.409925e-002,4.409925e-002,3.740810e-001,3.473375e-001,2.752235e-001,6.052054e-001,5.784618e-001,2.213081e-004,2.213081e-004,,,,,,,,,,,,,,,,,,,,
1432828439.455,,-5.000000e+004,5.000001e+001,5.000249e+001,1,0,4.637786e+000,-7.623523e-001,-7.623523e-001,1.158733e-001,-4.591141e-001,-9.519457e-001,-7.372010e-002,-6.487075e-001,-3.825796e-003,-3.825796e-003,,,,,,,,,,,,,,,,,,,,
1432828598.701,,-4.000000e+004,5.000001e+001,4.999256e+001,1,0,2.820577e-001,-2.150029e-001,-2.150029e-001,1.307216e-003,-1.934031e-001,-4.720050e-001,-2.556949e-001,-4.504052e-001,-1.079616e-003,-1.079616e-003,,,,,,,,,,,,,,,,,,,,
1432828598.701,,-4.000000e+004,5.000001e+001,4.999256e+001,1,0,3.233781e+000,-9.622486e-001,-9.622486e-001,-3.467824e-001,-9.406488e-001,-8.027086e-001,-1.872425e-001,-7.811088e-001,-4.831838e-003,-4.831838e-003,,,,,,,,,,,,,,,,,,,,
1432828608.615,,-4.000000e+004,4.999256e+001,4.999877e+001,1,0,3.736721e+000,-1.485488e+000,-1.485488e+000,-1.124263e+000,-1.492912e+000,-6.004996e-001,-2.392738e-001,-6.079228e-001,-7.459236e-003,-7.459236e-003,,,,,,,,,,,,,,,,,,,,
1432828765.957,,-3.000000e+004,5.000001e+001,4.999877e+001,1,0,1.588288e-002,-1.176489e-001,-1.176489e-001,-5.570901e-002,-1.726559e-001,-2.468598e-001,-1.849200e-001,-3.018669e-001,-5.911147e-004,-5.911147e-004,,,,,,,,,,,,,,,,,,,,
1432828765.957,,-3.000000e+004,5.000001e+001,4.999877e+001,1,0,4.141723e+000,-8.467361e-001,-8.467361e-001,-4.651413e-001,-9.017432e-001,-5.057236e-001,-1.241288e-001,-5.607307e-001,-4.254339e-003,-4.254339e-003,,,,,,,,,,,,,,,,,,,,
1432828776.173,,-3.000000e+004,5.000373e+001,5.000125e+001,1,0,2.634962e+000,1.373333e-002,1.373333e-002,2.276072e-001,-3.078100e-002,-5.548855e-002,1.583853e-001,-1.000029e-001,6.900172e-005,6.900172e-005,,,,,,,,,,,,,,,,,,,,
1432828925.102,,-2.000000e+004,5.000249e+001,5.000125e+001,1,0,5.149860e-001,6.668294e-002,6.668294e-002,-5.673198e-002,-1.117881e-001,-2.599883e-002,-1.494137e-001,-2.044699e-001,3.352414e-004,3.352414e-004,,,,,,,,,,,,,,,,,,,,
1432828925.102,,-2.000000e+004,5.000249e+001,5.000125e+001,1,0,4.825495e+000,2.156133e-001,2.156133e-001,3.179286e-001,3.714220e-002,-1.336289e-001,-3.131365e-002,-3.121000e-001,1.083973e-003,1.083973e-003,,,,,,,,,,,,,,,,,,,,
1432828935.174,,-2.000000e+004,5.000249e+001,5.000373e+001,1,0,1.569967e+000,1.652577e-001,1.652577e-001,2.644255e-001,9.244568e-002,1.982534e-001,2.974212e-001,1.254414e-001,8.308156e-004,8.308156e-004,,,,,,,,,,,,,,,,,,,,
1432829098.513,,-1.000000e+004,5.000249e+001,5.000001e+001,1,0,1.475855e+000,1.011994e+000,1.011994e+000,1.687849e-001,1.090234e-001,1.506375e+000,6.631665e-001,6.034051e-001,1.272680e-003,1.272680e-003,,,,,,,,,,,,,,,,,,,,
1432829098.513,,-1.000000e+004,5.000249e+001,5.000001e+001,1,0,4.943971e+000,1.336863e+000,1.336863e+000,9.836985e-001,4.338929e-001,2.856528e-001,-6.751190e-002,-6.173176e-001,1.681235e-003,1.681235e-003,,,,,,,,,,,,,,,,,,,,
1432829108.478,,-1.000000e+004,5.000373e+001,5.000249e+001,1,0,7.023036e-001,3.982666e-001,3.982666e-001,1.333258e-001,-1.506374e-001,5.014409e-003,-2.599263e-001,-5.438896e-001,5.008588e-004,5.008588e-004,,,,,,,,,,,,,,,,,,,,
1432829225.203,,-9.000000e+003,4.999877e+001,5.000125e+001,1,0,2.590894e+000,5.111851e-001,5.111851e-001,-1.347041e-002,-1.347041e-002,8.802400e-001,3.555845e-001,3.555845e-001,6.429030e-004,6.429030e-004,,,,,,,,,,,,,,,,,,,,
1432829225.203,,-9.000000e+003,4.999877e+001,5.000125e+001,1,0,4.317231e+000,-6.495865e-001,-6.495865e-001,-7.106323e-001,-1.174242e+000,-1.181841e-001,-1.792299e-001,-6.428396e-001,-8.169666e-004,-8.169666e-004,,,,,,,,,,,,,,,,,,,,
1432829235.167,,-9.000000e+003,5.000125e+001,4.999877e+001,1,0,9.159422e-002,5.502487e-001,5.502487e-001,-4.073254e-002,-2.519988e-001,2.099252e-001,-3.810561e-001,-5.923224e-001,6.920323e-004,6.920323e-004,,,,,,,,,,,,,,,,,,,,
1432829235.167,,-9.000000e+003,5.000125e+001,4.999877e+001,1,0,3.621268e+000,-1.326792e+000,-1.326792e+000,-1.436556e+000,-2.129040e+000,-3.018500e-001,-4.116136e-001,-1.104098e+000,-1.668669e-003,-1.668669e-003,,,,,,,,,,,,,,,,,,,,
1432829349.649,,-7.000000e+003,4.999877e+001,4.999752e+001,1,0,3.308528e+000,-8.508560e-001,-8.508561e-001,-1.064608e+000,-1.415371e+000,-8.624142e-002,-2.999928e-001,-6.507562e-001,-1.070225e-003,-1.070225e-003,,,,,,,,,,,,,,,,,,,,
1432829360.127,,-7.000000e+003,5.000125e+001,5.000125e+001,1,0,1.305927e-001,1.835688e-001,1.835688e-001,-1.068312e-001,-2.372722e-001,-4.368271e-002,-3.340828e-001,-4.645238e-001,2.308968e-004,2.308968e-004,,,,,,,,,,,,,,,,,,,,
1432829360.127,,-7.000000e+003,5.000125e+001,5.000125e+001,1,0,4.451874e+000,-2.148503e-001,-2.148503e-001,-9.385964e-002,-6.356913e-001,-2.429583e-001,-1.219677e-001,-6.637993e-001,-2.702434e-004,-2.702434e-004,,,,,,,,,,,,,,,,,,,,
1432829480.535,,-5.000000e+003,5.000001e+001,4.999504e+001,1,0,2.189831e+000,1.266976e+000,1.266976e+000,7.038519e-001,4.761699e-001,1.126182e+000,5.630580e-001,3.353760e-001,1.593820e-003,1.593820e-003,,,,,,,,,,,,,,,,,,,,
1432829490.640,,-5.000000e+003,4.999504e+001,4.999752e+001,1,0,8.672298e-001,5.841243e-001,5.841243e-001,-6.800055e-002,-1.305479e-001,5.891219e-001,-6.300294e-002,-1.255503e-001,7.348116e-004,7.348116e-004,,,,,,,,,,,,,,,,,,,,
1432829490.640,,-5.000000e+003,4.999504e+001,4.999752e+001,1,0,4.967130e+000,1.049837e+000,1.049837e+000,7.182670e-001,3.351646e-001,2.898028e-001,-4.176691e-002,-4.248693e-001,1.320665e-003,1.320665e-003,,,,,,,,,,,,,,,,,,,,
1432829609.954,,-3.000000e+003,5.000125e+001,5.000373e+001,1,0,1.199133e+000,7.838680e-001,7.838679e-001,1.687764e-001,5.414414e-002,7.528000e-001,1.377085e-001,2.307624e-002,9.862008e-004,9.862008e-004,,,,,,,,,,,,,,,,,,,,
1432829620.121,,-3.000000e+003,5.000001e+001,5.000249e+001,1,0,1.915523e+000,1.031068e+000,1.031068e+000,2.308263e-001,2.178028e-001,1.266278e+000,4.660361e-001,4.530126e-001,1.297208e-003,1.297208e-003,,,,,,,,,,,,,,,,,,,,
1432829620.121,,-3.000000e+003,5.000001e+001,5.000249e+001,1,0,4.767227e+000,8.796961e-001,8.796960e-001,2.574416e-001,6.643099e-002,5.809440e-001,-4.131038e-002,-2.323210e-001,1.106764e-003,1.106764e-003,,,,,,,,,,,,,,,,,,,,
1432829738.655,,-1.000000e+003,4.999752e+001,5.000001e+001,1,0,4.109126e-001,5.830561e-001,5.830562e-001,1.444802e-002,3.853333e-002,4.753758e-001,-9.323233e-002,-6.914702e-002,7.336425e-004,7.336425e-004,,,,,,,,,,,,,,,,,,,,
1432829738.655,,-1.000000e+003,4.999752e+001,5.000001e+001,1,0,3.026888e+000,6.253242e-001,6.253242e-001,9.692415e-003,8.080143e-002,5.864418e-001,-2.919008e-002,4.191893e-002,7.868274e-004,7.868274e-004,,,,,,,,,,,,,,,,,,,,
1432829748.727,,-1.000000e+003,5.000001e+001,4.999504e+001,1,0,3.940393e+000,3.431806e-001,3.431806e-001,-3.970940e-001,-3.362081e-001,6.665564e-001,-7.371823e-002,-1.283228e-002,4.318142e-004,4.318142e-004,,,,,,,,,,,,,,,,,,,,
1432829868.725,,-5.000000e+002,4.999877e+001,5.000249e+001,1,0,9.180456e-003,2.058168e+000,2.058168e+000,-2.120803e-002,3.426623e-002,1.954908e+000,-1.244684e-001,-6.899416e-002,1.035924e-003,1.035924e-003,,,,,,,,,,,,,,,,,,,,
1432829868.725,,-5.000000e+002,4.999877e+001,5.000249e+001,1,0,3.974171e+000,1.749931e+000,1.749931e+000,-4.715977e-001,-2.739706e-001,2.116241e+000,-1.052883e-001,9.233880e-002,8.807813e-004,8.807813e-004,,,,,,,,,,,,,,,,,,,,
1432829878.718,,-5.000000e+002,5.000001e+001,5.000125e+001,1,0,2.861392e+000,9.950560e-001,9.950560e-001,-3.426973e-002,7.208478e-002,1.047203e+000,1.787701e-002,1.242315e-001,5.008349e-004,5.008349e-004,,,,,,,,,,,,,,,,,,,,
1432829982.446,,-4.000000e+002,5.000001e+001,4.999752e+001,1,0,3.635494e-001,-3.804132e-001,-3.804132e-001,-3.716811e-002,-1.364839e-001,-4.675013e-001,-1.242561e-001,-2.235719e-001,-1.914720e-004,-1.914720e-004,,,,,,,,,,,,,,,,,,,,
1432829982.446,,-4.000000e+002,5.000001e+001,4.999752e+001,1,0,4.718485e+000,-5.363628e-001,-5.363628e-001,1.770592e-001,-2.924334e-001,-7.414601e-001,-2.803812e-002,-4.975308e-001,-2.699655e-004,-2.699655e-004,,,,,,,,,,,,,,,,,,,,
1432829992.863,,-4.000000e+002,4.999877e+001,4.999752e+001,1,0,1.767492e+000,-3.604236e-001,-3.604236e-001,2.511624e-001,6.399459e-002,-3.412773e-001,2.703086e-001,8.314088e-002,-1.814107e-004,-1.814107e-004,,,,,,,,,,,,,,,,,,,,
1432830096.396,,-3.000000e+002,5.000001e+001,4.999752e+001,1,0,1.264397e+000,4.960784e-001,4.960784e-001,6.831898e-004,1.388073e-002,5.733758e-001,7.798058e-002,9.117812e-002,2.496908e-004,2.496908e-004,,,,,,,,,,,,,,,,,,,,
1432830096.396,,-3.000000e+002,5.000001e+001,4.999752e+001,1,0,4.984751e+000,8.478042e-001,8.478042e-001,2.622258e-001,3.656065e-001,5.706678e-001,-1.491057e-002,8.847016e-002,4.267247e-004,4.267247e-004,,,,,,,,,,,,,,,,,,,,
1432830106.468,,-3.000000e+002,4.999752e+001,5.000001e+001,1,0,8.598227e-001,8.418531e-001,8.418531e-001,6.067125e-002,1.096125e-001,8.634874e-001,8.230560e-002,1.312469e-001,4.237293e-004,4.237293e-004,,,,,,,,,,,,,,,,,,,,
1432830210.753,,-2.000000e+002,5.000001e+001,5.070618e+001,1,0,2.366589e+000,1.733757e+000,1.733757e+000,-1.790136e-001,-1.994644e-001,1.863008e+000,-4.976261e-002,-7.021344e-002,8.726557e-004,8.726557e-004,,,,,,,,,,,,,,,,,,,,
1432830210.753,,-2.000000e+002,5.000001e+001,5.070618e+001,1,0,4.487405e+000,7.251198e-001,7.251198e-001,-3.491662e-001,-1.208101e+000,1.068733e+000,-5.552690e-003,-8.644876e-001,3.649762e-004,3.649762e-004,,,,,,,,,,,,,,,,,,,,
1432830220.718,,-2.000000e+002,5.070618e+001,4.999628e+001,1,0,1.761395e-001,1.424604e+000,1.424604e+000,1.009589e-002,3.373432e-002,1.406371e+000,-8.137047e-003,1.550138e-002,7.170492e-004,7.170492e-004,,,,,,,,,,,,,,,,,,,,
1432830220.718,,-2.000000e+002,5.070618e+001,4.999628e+001,1,0,3.431676e+000,1.268807e+000,1.268807e+000,-1.967103e-001,-1.220627e-001,1.444641e+000,-2.087593e-002,5.377173e-002,6.386316e-004,6.386316e-004,,,,,,,,,,,,,,,,,,,,
1432830324.642,,-1.000000e+002,5.000001e+001,5.000001e+001,1,0,3.525831e+000,7.902768e-001,7.902768e-001,-1.820597e-001,-7.752001e-003,9.651058e-001,-7.230770e-003,1.670769e-001,3.977742e-004,3.977742e-004,,,,,,,,,,,,,,,,,,,,
1432830334.714,,-1.000000e+002,5.000001e+001,4.999628e+001,1,0,5.664106e-002,5.429243e-001,5.429243e-001,-6.001880e-003,1.717150e-002,5.126601e-001,-3.626608e-002,-1.309270e-002,2.732729e-004,2.732729e-004,,,,,,,,,,,,,,,,,,,,
1432830334.714,,-1.000000e+002,5.000001e+001,4.999628e+001,1,0,4.300484e+000,5.664235e-001,5.664235e-001,-5.036753e-002,4.067075e-002,5.967891e-001,-2.000201e-002,7.103628e-002,2.851009e-004,2.851009e-004,,,,,,,,,,,,,,,,,,,,
1432830432.192,,0.000000e+000,5.000622e+001,5.000249e+001,1,0,2.410411e+000,6.506546e-001,6.506546e-001,-6.261021e-004,1.874243e-001,6.513736e-001,9.290874e-005,1.881433e-001,3.274994e-004,3.274994e-004,,,,,,,,,,,,,,,,,,,,
1432830442.406,,0.000000e+000,5.000249e+001,5.000125e+001,1,0,6.834908e-001,5.645924e-001,5.645924e-001,3.355854e-003,3.931367e-002,5.621495e-001,9.128982e-004,3.687072e-002,2.841810e-004,2.841810e-004,,,,,,,,,,,,,,,,,,,,
1432830442.406,,0.000000e+000,5.000249e+001,5.000125e+001,1,0,4.910783e+000,7.248146e-001,7.248146e-001,-2.298187e-004,1.995358e-001,7.254454e-001,4.010368e-004,2.001667e-001,3.648269e-004,3.648269e-004,,,,,,,,,,,,,,,,,,,,
1432830540.135,,1.000000e+002,5.000249e+001,4.999752e+001,1,0,1.380564e+000,9.146397e-001,9.146397e-001,-5.578942e-002,9.995985e-002,9.123486e-001,-5.808056e-002,9.766871e-002,4.603704e-004,4.603704e-004,,,,,,,,,,,,,,,,,,,,
1432830550.599,,1.000000e+002,4.999752e+001,5.000125e+001,1,0,1.692863e+000,1.307260e+000,1.307260e+000,-3.279017e-002,-7.958889e-003,1.243714e+000,-9.633635e-002,-7.150507e-002,6.579902e-004,6.579902e-004,,,,,,,,,,,,,,,,,,,,
1432830550.599,,1.000000e+002,4.999752e+001,5.000125e+001,1,0,4.870914e+000,1.510056e+000,1.510056e+000,-8.451529e-002,1.948366e-001,1.602629e+000,8.058239e-003,2.874101e-001,7.600643e-004,7.600643e-004,,,,,,,,,,,,,,,,,,,,
1432830654.822,,2.000000e+002,5.000125e+001,5.000125e+001,1,0,5.507917e-001,4.264962e-001,4.264962e-001,-1.792010e-002,1.059262e-001,5.097376e-001,6.532127e-002,1.891676e-001,2.146693e-004,2.146693e-004,,,,,,,,,,,,,,,,,,,,
1432830654.822,,2.000000e+002,5.000125e+001,5.000125e+001,1,0,2.811898e+000,5.618458e-001,5.618458e-001,-1.133749e-001,2.412758e-001,6.581818e-001,-1.703893e-002,3.376118e-001,2.827951e-004,2.827951e-004,,,,,,,,,,,,,,,,,,,,
1432830664.988,,2.000000e+002,5.000498e+001,5.000125e+001,1,0,4.134916e+000,9.068575e-001,9.068575e-001,2.336288e-001,5.004578e-001,7.182788e-001,4.505006e-002,3.118791e-001,4.564507e-004,4.564507e-004,,,,,,,,,,,,,,,,,,,,
1432830768.523,,3.000000e+002,5.000373e+001,4.999877e+001,1,0,3.579492e-002,6.134220e-001,6.134220e-001,-5.970298e-003,1.984747e-001,7.007717e-001,8.137941e-002,2.858244e-001,3.087533e-004,3.087533e-004,,,,,,,,,,,,,,,,,,,,
1432830768.523,,3.000000e+002,5.000373e+001,4.999877e+001,1,0,3.801842e+000,1.485336e+000,1.485336e+000,3.728703e-001,1.070388e+000,1.158213e+000,4.574739e-002,7.432655e-001,7.476130e-004,7.476130e-004,,,,,,,,,,,,,,,,,,,,
1432830778.595,,3.000000e+002,4.999877e+001,5.000125e+001,1,0,3.086735e+000,7.321391e-001,7.321391e-001,1.730633e-001,3.797329e-001,6.079890e-001,4.891326e-002,2.555829e-001,3.685070e-004,3.685070e-004,,,,,,,,,,,,,,,,,,,,
1432830881.800,,4.000000e+002,4.999752e+001,5.000001e+001,1,0,2.339688e-001,9.334086e-001,9.334086e-001,3.718669e-002,1.436827e-001,1.024863e+000,1.286416e-001,2.351376e-001,4.698091e-004,4.698091e-004,,,,,,,,,,,,,,,,,,,,
1432830881.800,,4.000000e+002,4.999752e+001,5.000001e+001,1,0,4.589900e+000,1.175726e+000,1.175726e+000,-8.435776e-002,3.859997e-001,1.295566e+000,3.548298e-002,5.058404e-001,5.917736e-004,5.917736e-004,,,,,,,,,,,,,,,,,,,,
1432830891.825,,4.000000e+002,5.000001e+001,5.000001e+001,1,0,1.974320e+000,2.070681e-001,2.070681e-001,-3.174169e-001,-8.358416e-002,2.302314e-001,-2.942536e-001,-6.042083e-002,1.042228e-004,1.042228e-004,,,,,,,,,,,,,,,,,,,,
1432830995.609,,5.000000e+002,4.999877e+001,4.999504e+001,1,0,1.061664e+000,1.237373e+000,1.237373e+000,2.382518e-002,8.246529e-002,1.170253e+000,-4.329514e-002,1.534498e-002,6.227987e-004,6.227987e-004,,,,,,,,,,,,,,,,,,,,
1432830995.609,,5.000000e+002,4.999877e+001,4.999504e+001,1,0,4.993095e+000,1.159398e+000,1.159398e+000,-3.976131e-001,4.490495e-003,1.578377e+000,2.136591e-002,4.234695e-001,5.835522e-004,5.835522e-004,,,,,,,,,,,,,,,,,,,,
1432831005.384,,5.000000e+002,4.999504e+001,4.999504e+001,1,0,1.025773e+000,4.289376e-001,4.289376e-001,-9.007260e-002,1.147469e-001,4.919719e-001,-2.703840e-002,1.777811e-001,2.158943e-004,2.158943e-004,,,,,,,,,,,,,,,,,,,,
1432831115.669,,1.000000e+003,5.000249e+001,4.999752e+001,1,0,2.140768e+000,4.051332e-001,4.051332e-001,-3.000121e-001,-2.691089e-001,1.966460e-001,-5.084993e-001,-4.775961e-001,2.039069e-004,2.039069e-004,,,,,,,,,,,,,,,,,,,,
1432831115.669,,1.000000e+003,5.000249e+001,4.999752e+001,1,0,4.637702e+000,1.221351e+000,1.221351e+000,-1.173111e-001,5.471087e-001,1.400256e+000,6.159389e-002,7.260137e-001,6.147160e-004,6.147160e-004,,,,,,,,,,,,,,,,,,,,
1432831125.694,,1.000000e+003,5.000125e+001,4.999877e+001,1,0,2.839989e-001,9.303567e-001,9.303567e-001,-1.664736e-002,2.765025e-001,1.193113e+000,2.461090e-001,5.392588e-001,4.682564e-004,4.682564e-004,,,,,,,,,,,,,,,,,,,,
1432831125.694,,1.000000e+003,5.000125e+001,4.999877e+001,1,0,3.234290e+000,1.903897e+000,1.903897e+000,3.559359e-001,1.250043e+000,1.729410e+000,1.814489e-001,1.075556e+000,9.582474e-004,9.582474e-004,,,,,,,,,,,,,,,,,,,,
1432831247.239,,3.000000e+003,5.000125e+001,4.999504e+001,1,0,3.736664e+000,1.730705e+000,1.730705e+000,9.292974e-001,1.391147e+000,9.929727e-001,1.915655e-001,6.534151e-001,2.177436e-003,2.177436e-003,,,,,,,,,,,,,,,,,,,,
1432831257.203,,3.000000e+003,4.999504e+001,4.999504e+001,1,0,1.613952e-002,7.893612e-001,7.893612e-001,4.522052e-002,2.268076e-001,9.203397e-001,1.761990e-001,3.577861e-001,9.931120e-004,9.931120e-004,,,,,,,,,,,,,,,,,,,,
1432831257.203,,3.000000e+003,4.999504e+001,4.999504e+001,1,0,4.141530e+000,1.690268e+000,1.690268e+000,4.497890e-001,1.127714e+000,1.357420e+000,1.169417e-001,7.948668e-001,2.126561e-003,2.126561e-003,,,,,,,,,,,,,,,,,,,,
1432831376.210,,5.000000e+003,4.998883e+001,4.999752e+001,1,0,2.635355e+000,7.969909e-001,7.969909e-001,-2.992971e-001,2.641671e-001,8.892024e-001,-2.070856e-001,3.563786e-001,1.002592e-003,1.002592e-003,,,,,,,,,,,,,,,,,,,,
1432831386.425,,5.000000e+003,4.999752e+001,4.999628e+001,1,0,5.151177e-001,1.158788e+000,1.158788e+000,9.227762e-002,2.584295e-001,1.318398e+000,2.518879e-001,4.180398e-001,1.457722e-003,1.457722e-003,,,,,,,,,,,,,,,,,,,,
1432831386.425,,5.000000e+003,4.999752e+001,4.999628e+001,1,0,4.824538e+000,1.200293e+000,1.200293e+000,-5.474401e-001,2.999346e-001,1.800591e+000,5.285767e-002,9.002324e-001,1.509934e-003,1.509934e-003,,,,,,,,,,,,,,,,,,,,
1432831506.183,,7.000000e+003,4.999877e+001,4.999752e+001,1,0,1.570247e+000,5.229347e-001,5.229347e-001,-5.558072e-001,1.516581e-003,4.541277e-001,-6.246141e-001,-6.729040e-002,6.577585e-004,6.577585e-004,,,,,,,,,,,,,,,,,,,,
1432831516.100,,7.000000e+003,4.999752e+001,4.999877e+001,1,0,1.475857e+000,5.565050e-001,5.565050e-001,-1.329560e-001,-3.471661e-002,1.574508e-001,-5.320102e-001,-4.337708e-001,6.999840e-004,6.999840e-004,,,,,,,,,,,,,,,,,,,,
1432831516.100,,7.000000e+003,4.999752e+001,4.999877e+001,1,0,4.943909e+000,7.054353e-001,7.054353e-001,-7.895887e-001,1.142137e-001,1.549072e+000,5.404838e-002,9.578508e-001,8.873118e-004,8.873118e-004,,,,,,,,,,,,,,,,,,,,
1432831653.558,,9.000000e+003,4.999752e+001,4.999504e+001,1,0,7.015854e-001,4.937895e-001,4.937895e-001,-6.294890e-002,1.617891e-001,6.795717e-001,1.228333e-001,3.475713e-001,1.242050e-003,1.242050e-003,,,,,,,,,,,,,,,,,,,,
1432831664.022,,9.000000e+003,5.000125e+001,5.000001e+001,1,0,2.590576e+000,2.822962e-001,2.822962e-001,7.024258e-003,7.024258e-003,9.618369e-002,-1.790883e-001,-1.790883e-001,7.100720e-004,7.100720e-004,,,,,,,,,,,,,,,,,,,,
1432831664.022,,9.000000e+003,5.000125e+001,5.000001e+001,1,0,4.317781e+000,1.049837e+000,1.049837e+000,3.562424e-001,7.745648e-001,7.835991e-001,9.000473e-002,5.083271e-001,2.640700e-003,2.640700e-003,,,,,,,,,,,,,,,,,,,,
1432831781.517,,1.000000e+004,4.999877e+001,5.000001e+001,1,0,9.025321e-002,5.763420e-001,5.763420e-001,2.351861e-002,2.351109e-001,7.567627e-001,2.039393e-001,4.155316e-001,1.449612e-003,1.449612e-003,,,,,,,,,,,,,,,,,,,,
1432831781.517,,1.000000e+004,4.999877e+001,5.000001e+001,1,0,3.620708e+000,1.800287e+000,1.800287e+000,7.655032e-001,1.459056e+000,1.255711e+000,2.209277e-001,9.144803e-001,4.528071e-003,4.528071e-003,,,,,,,,,,,,,,,,,,,,
1432831791.731,,1.000000e+004,5.000001e+001,5.000125e+001,1,0,3.308591e+000,1.562243e+000,1.562243e+000,6.664916e-001,1.080062e+000,1.083743e+000,1.879922e-001,6.015621e-001,3.929343e-003,3.929343e-003,,,,,,,,,,,,,,,,,,,,
1432831953.412,,2.000000e+004,4.999504e+001,5.000125e+001,1,0,1.308229e-001,6.674398e-001,6.674398e-001,1.080256e-001,3.273465e-001,8.802645e-001,3.208503e-001,5.401713e-001,1.677741e-003,1.677741e-003,,,,,,,,,,,,,,,,,,,,
1432831953.412,,2.000000e+004,4.999504e+001,5.000125e+001,1,0,4.451279e+000,1.344340e+000,1.344340e+000,9.322181e-002,1.004247e+000,1.369192e+000,1.180740e-001,1.029099e+000,3.379264e-003,3.379264e-003,,,,,,,,,,,,,,,,,,,,
1432831963.486,,2.000000e+004,5.000125e+001,5.000125e+001,1,0,2.189245e+000,1.335185e-001,1.335185e-001,-8.339604e-001,-3.124016e-001,2.923839e-001,-6.750949e-001,-1.535361e-001,3.356250e-004,3.356250e-004,,,,,,,,,,,,,,,,,,,,
1432832120.247,,3.000000e+004,5.000125e+001,5.000125e+001,1,0,8.672194e-001,6.038087e-001,6.038087e-001,1.034200e-001,2.657225e-001,6.009169e-001,1.005282e-001,2.628307e-001,1.516888e-003,1.516888e-003,,,,,,,,,,,,,,,,,,,,
1432832120.247,,3.000000e+004,5.000125e+001,5.000125e+001,1,0,4.967046e+000,2.708518e-001,2.708518e-001,-1.061337e+000,-6.723440e-002,1.396034e+000,6.384534e-002,1.057948e+000,6.804336e-004,6.804336e-004,,,,,,,,,,,,,,,,,,,,
1432832130.711,,3.000000e+004,5.000125e+001,4.999877e+001,1,0,1.199092e+000,5.751213e-001,5.751213e-001,-3.604170e-001,1.752825e-001,6.486381e-001,-2.869002e-001,2.487993e-001,1.444819e-003,1.444819e-003,,,,,,,,,,,,,,,,,,,,
1432832295.892,,4.000000e+004,4.999877e+001,5.000249e+001,1,0,1.915627e+000,-5.188147e-003,-5.188147e-003,-5.932037e-001,-5.203648e-001,-5.811346e-001,-1.169150e+000,-1.096311e+000,-1.302589e-005,-1.302589e-005,,,,,,,,,,,,,,,,,,,,
1432832295.892,,4.000000e+004,4.999877e+001,5.000249e+001,1,0,4.767466e+000,9.741508e-001,9.741508e-001,-6.093296e-001,4.589742e-001,1.688187e+000,1.047070e-001,1.173011e+000,2.445802e-003,2.445802e-003,,,,,,,,,,,,,,,,,,,,
1432832305.916,,4.000000e+004,5.000373e+001,5.000249e+001,1,0,4.102920e-001,9.025849e-001,9.025849e-001,-4.141145e-002,4.640153e-001,1.440888e+000,4.968913e-001,1.002318e+000,2.266121e-003,2.266121e-003,,,,,,,,,,,,,,,,,,,,
1432832305.916,,4.000000e+004,5.000373e+001,5.000249e+001,1,0,3.027045e+000,1.887570e+000,1.887570e+000,-4.321220e-002,1.449000e+000,2.090294e+000,1.595119e-001,1.651724e+000,4.739124e-003,4.739124e-003,,,,,,,,,,,,,,,,,,,,
1432832475.976,,5.000000e+004,5.000125e+001,4.999877e+001,1,0,3.940694e+000,1.971190e+000,1.971191e+000,1.141703e+000,1.661814e+000,1.052344e+000,2.228560e-001,7.429674e-001,9.892240e-003,9.892240e-003,,,,,,,,,,,,,,,,,,,,
1432832485.893,,5.000000e+004,4.999877e+001,4.999504e+001,1,0,8.448529e-003,5.435346e-001,5.435346e-001,6.675866e-002,2.794049e-001,7.225233e-001,2.457474e-001,4.583936e-001,2.727679e-003,2.727679e-003,,,,,,,,,,,,,,,,,,,,
1432832485.893,,5.000000e+004,4.999877e+001,4.999504e+001,1,0,3.975125e+000,1.896878e+000,1.896878e+000,8.751959e-001,1.632748e+000,1.234509e+000,2.128265e-001,9.703788e-001,9.519310e-003,9.519310e-003,,,,,,,,,,,,,,,,,,,,
1432832648.264,,6.000000e+004,5.000001e+001,5.000125e+001,1,0,2.861540e+000,7.875301e-001,7.875301e-001,4.899216e-002,5.433807e-001,7.030764e-001,-3.546160e-002,4.589270e-001,3.949789e-003,3.949789e-003,,,,,,,,,,,,,,,,,,,,
1432832658.229,,6.000000e+004,5.000125e+001,5.000125e+001,1,0,3.634162e-001,5.377361e-001,5.377361e-001,1.154198e-001,2.748125e-001,7.418364e-001,3.195200e-001,4.789127e-001,2.696969e-003,2.696969e-003,,,,,,,,,,,,,,,,,,,,
1432832658.229,,6.000000e+004,5.000125e+001,5.000125e+001,1,0,4.716584e+000,6.169317e-001,6.169317e-001,-3.994847e-001,3.540080e-001,1.088255e+000,7.183865e-002,8.253314e-001,3.094167e-003,3.094167e-003,,,,,,,,,,,,,,,,,,,,
1432832816.458,,7.000000e+004,4.999380e+001,5.000001e+001,1,0,1.767995e+000,5.355998e-002,5.355999e-002,-7.014012e-001,-2.559112e-001,-5.164408e-004,-7.554776e-001,-3.099876e-001,2.684651e-004,2.684651e-004,,,,,,,,,,,,,,,,,,,,
1432832826.624,,7.000000e+004,5.000001e+001,5.000001e+001,1,0,1.264935e+000,2.870266e-001,2.870266e-001,-3.154553e-002,5.961326e-002,2.347835e-002,-2.950938e-001,-2.039350e-001,1.438697e-003,1.438697e-003,,,,,,,,,,,,,,,,,,,,
1432832826.624,,7.000000e+004,5.000001e+001,5.000001e+001,1,0,4.985166e+000,1.107822e-001,1.107822e-001,-8.307083e-001,-1.166311e-001,9.920520e-001,5.056144e-002,7.646387e-001,5.552867e-004,5.552867e-004,,,,,,,,,,,,,,,,,,,,
1432832826.624,,7.000000e+004,5.000001e+001,5.000001e+001,1,0,2.812137e+000,6.791894e-001,6.791894e-001,-5.053912e-001,4.517761e-001,1.097734e+000,-8.684677e-002,8.703206e-001,3.404382e-003,3.404382e-003,,,,,,,,,,,,,,,,,,,,