File: data/A269/A269_GdN_ZFC_250_Oe_150528.rso.dat
[Header]
TITLE,MPMS RSO Measurement
BYAPP,MPMS Measurement,1.1,Summary
FILEOPENTIME, 1432769701.348000 5/28/2015, 11:35:01 AM

INFO, APPNAME, MPMS MultiVu Application, Revision 1.61,  Build 082

INFO, NAME, A269
INFO, WEIGHT, 22.300
INFO, AREA, 1.000
INFO, LENGTH, 1.000
INFO, SHAPE, 1
INFO, COMMENT, m = 0.0223g
INFO, SEQUENCE FILE: ZFC_5K-300K.seq


INFO, BACKGROUND DATA FILE:, None


STARTUPAXIS,X,4,LINEAR,AUTO,0.000000,0.000000
STARTUPAXIS,Y1,5,LINEAR,AUTO,0.000000,0.000000


STARTUPGROUP,Longitudinal
FIELDGROUP,Longitudinal,1,2,3,4,5,6,7,8,9,10,11,19,20,21,22,23,35
FIELDGROUP,Transverse,1,2,3,4,12,13,14,15,16,17,18,24,25,26,27,28,35

PLOT_APPEARANCE,ALL,HORZ_GRID_ON,VERT_GRID_ON,MARKERS_AND_LINES

[Data]
Time,Comment,Field (Oe),Temperature (K),Long Moment (emu),Long Scan Std Dev,Long Offset (cm),Long Offset Std Dev,Long Algorithm,Long Reg Fit,Long Reg Factor,Trans Moment (emu),Trans Scan Std Dev,Trans Offset (cm),Trans Offset Std Dev,Trans Algorithm,Trans Reg Fit,Trans Reg Factor,Long Moment [w/o ABS] (emu),Long Scan Std Dev [w/o ABS],Long Offset [w/o ABS] (cm),Long Offset Std Dev [w/o ABS],Long Reg Fit [w/o ABS],Trans Moment [w/o ABS] (emu),Trans Scan Std Dev [w/o ABS],Trans Offset [w/o ABS] (cm),Trans Offset Std Dev [w/o ABS],Trans Reg Fit [w/o ABS],RSO Position (deg),Amplitude (cm),Frequency,Cycles to Average,Scans per Measurement,Delta Temp (K),Error,EC Comp. Running,Using ABS,
1432769701.345,,2.500000e+002,5.004294e+000,-1.637875e-004,0.000000e+000,-5.870957e-001,0.000000e+000,3,0.000000e+000,1.825000e+000,,,,,,,,,,,,,,,,,,0,5.000000e+000,5.000000e-001,2,1,1.732826e-003,0,1,0,
1432769789.531,,2.500000e+002,6.078001e+000,-1.645544e-004,0.000000e+000,-5.869956e-001,0.000000e+000,3,0.000000e+000,1.825000e+000,,,,,,,,,,,,,,,,,,0,5.000000e+000,5.000000e-001,2,1,1.484070e-001,0,1,0,
1432769851.971,,2.500000e+002,7.092040e+000,-1.690553e-004,0.000000e+000,-5.868409e-001,0.000000e+000,3,0.000000e+000,1.825000e+000,,,,,,,,,,,,,,,,,,0,5.000000e+000,5.000000e-001,2,1,1.550102e-001,0,1,0,
1432769912.220,,2.500000e+002,8.079260e+000,-1.736523e-004,0.000000e+000,-5.867887e-001,0.000000e+000,3,0.000000e+000,1.825000e+000,,,,,,,,,,,,,,,,,,0,5.000000e+000,5.000000e-001,2,1,1.353951e-001,0,1,0,
1432769972.904,,2.500000e+002,9.102503e+000,-1.782328e-004,0.000000e+000,-5.865070e-001,0.000000e+000,3,0.000000e+000,1.825000e+000,,,,,,,,,,,,,,,,,,0,5.000000e+000,5.000000e-001,2,1,1.449471e-001,0,0,0,
1432770036.338,,2.500000e+002,1.006289e+001,-1.831272e-004,0.000000e+000,-5.864275e-001,0.000000e+000,3,0.000000e+000,1.825000e+000,,,,,,,,,,,,,,,,,,0,5.000000e+000,5.000000e-001,2,1,1.132698e-001,0,0,0,
1432770105.076,,2.500000e+002,1.109020e+001,-1.885237e-004,0.000000e+000,-5.862530e-001,0.000000e+000,3,0.000000e+000,1.825000e+000,,,,,,,,,,,,,,,,,,0,5.000000e+000,5.000000e-001,2,1,1.202192e-001,0,0,0,
1432770175.903,,2.500000e+002,1.212247e+001,-1.943286e-004,0.000000e+000,-5.865715e-001,0.000000e+000,3,0.000000e+000,1.825000e+000,,,,,,,,,,,,,,,,,,0,5.000000e+000,5.000000e-001,2,1,1.644096e-001,0,0,0,
1432770235.624,,2.500000e+002,1.311563e+001,-1.997373e-004,0.000000e+000,-5.860285e-001,0.000000e+000,3,0.000000e+000,1.825000e+000,,,,,,,,,,,,,,,,,,0,5.000000e+000,5.000000e-001,2,1,1.458397e-001,0,0,0,
1432770294.550,,2.500000e+002,1.410262e+001,-2.051376e-004,0.000000e+000,-5.857350e-001,0.000000e+000,3,0.000000e+000,1.825000e+000,,,,,,,,,,,,,,,,,,0,5.000000e+000,5.000000e-001,2,1,1.403999e-001,0,0,0,
1432770419.300,,2.500000e+002,1.499759e+001,-2.154109e-004,0.000000e+000,-5.863205e-001,0.000000e+000,3,0.000000e+000,1.825000e+000,,,,,,,,,,,,,,,,,,0,5.000000e+000,5.000000e-001,2,1,4.879951e-003,0,1,0,
1432770521.679,,2.500000e+002,1.599920e+001,-2.210517e-004,0.000000e+000,-5.864606e-001,0.000000e+000,3,0.000000e+000,1.825000e+000,,,,,,,,,,,,,,,,,,0,5.000000e+000,5.000000e-001,2,1,5.559921e-003,0,1,0,
1432770576.862,,2.500000e+002,1.718085e+001,-2.216521e-004,0.000000e+000,-5.855935e-001,0.000000e+000,3,0.000000e+000,1.825000e+000,,,,,,,,,,,,,,,,,,0,5.000000e+000,5.000000e-001,2,1,3.340111e-001,0,1,0,
1432770607.579,,2.500000e+002,1.819112e+001,-2.269381e-004,0.000000e+000,-5.853682e-001,0.000000e+000,3,0.000000e+000,1.825000e+000,,,,,,,,,,,,,,,,,,0,5.000000e+000,5.000000e-001,2,1,2.977695e-001,0,1,0,
1432770637.262,,2.500000e+002,1.916694e+001,-2.331033e-004,0.000000e+000,-5.850239e-001,0.000000e+000,3,0.000000e+000,1.825000e+000,,,,,,,,,,,,,,,,,,0,5.000000e+000,5.000000e-001,2,1,2.832203e-001,0,1,0,
1432770669.453,,2.500000e+002,2.021840e+001,-2.400241e-004,0.000000e+000,-5.850140e-001,0.000000e+000,3,0.000000e+000,1.825000e+000,,,,,,,,,,,,,,,,,,0,5.000000e+000,5.000000e-001,2,1,2.541409e-001,0,1,0,
1432770700.181,,2.500000e+002,2.118848e+001,-2.466391e-004,0.000000e+000,-5.848790e-001,0.000000e+000,3,0.000000e+000,1.825000e+000,,,,,,,,,,,,,,,,,,0,5.000000e+000,5.000000e-001,2,1,2.808609e-001,0,1,0,
1432770730.527,,2.500000e+002,2.217387e+001,-2.536160e-004,0.000000e+000,-5.847819e-001,0.000000e+000,3,0.000000e+000,1.825000e+000,,,,,,,,,,,,,,,,,,0,5.000000e+000,5.000000e-001,2,1,2.551384e-001,0,1,0,
1432770761.484,,2.500000e+002,2.317772e+001,-2.608761e-004,0.000000e+000,-5.844943e-001,0.000000e+000,3,0.000000e+000,1.825000e+000,,,,,,,,,,,,,,,,,,0,5.000000e+000,5.000000e-001,2,1,3.088207e-001,0,0,0,
1432770792.008,,2.500000e+002,2.416047e+001,-2.678447e-004,0.000000e+000,-5.842246e-001,0.000000e+000,3,0.000000e+000,1.825000e+000,,,,,,,,,,,,,,,,,,0,5.000000e+000,5.000000e-001,2,1,2.371101e-001,0,0,0,
1432770822.689,,2.500000e+002,2.517155e+001,-2.753911e-004,0.000000e+000,-5.837325e-001,0.000000e+000,3,0.000000e+000,1.825000e+000,,,,,,,,,,,,,,,,,,0,5.000000e+000,5.000000e-001,2,1,3.014908e-001,0,0,0,
1432770852.370,,2.500000e+002,2.615798e+001,-2.826280e-004,0.000000e+000,-5.835621e-001,0.000000e+000,3,0.000000e+000,1.825000e+000,,,,,,,,,,,,,,,,,,0,5.000000e+000,5.000000e-001,2,1,2.663994e-001,0,0,0,
1432770883.078,,2.500000e+002,2.715914e+001,-2.900852e-004,0.000000e+000,-5.832939e-001,0.000000e+000,3,0.000000e+000,1.825000e+000,,,,,,,,,,,,,,,,,,0,5.000000e+000,5.000000e-001,2,1,3.006592e-001,0,0,0,
1432770914.106,,2.500000e+002,2.819630e+001,-2.969647e-004,0.000000e+000,-5.831990e-001,0.000000e+000,3,0.000000e+000,1.825000e+000,,,,,,,,,,,,,,,,,,0,5.000000e+000,5.000000e-001,2,1,2.646408e-001,0,0,0,
1432770943.485,,2.500000e+002,2.917121e+001,-3.032598e-004,0.000000e+000,-5.828124e-001,0.000000e+000,3,0.000000e+000,1.825000e+000,,,,,,,,,,,,,,,,,,0,5.000000e+000,5.000000e-001,2,1,3.369007e-001,0,0,0,
1432770973.273,,2.500000e+002,3.012137e+001,-3.089176e-004,0.000000e+000,-5.825013e-001,0.000000e+000,3,0.000000e+000,1.825000e+000,,,,,,,,,,,,,,,,,,0,5.000000e+000,5.000000e-001,2,1,2.285995e-001,0,0,0,
1432771005.956,,2.500000e+002,3.120193e+001,-3.133053e-004,0.000000e+000,-5.818827e-001,0.000000e+000,3,0.000000e+000,1.825000e+000,,,,,,,,,,,,,,,,,,0,5.000000e+000,5.000000e-001,2,1,2.554512e-001,0,0,0,
1432771034.636,,2.500000e+002,3.217014e+001,-3.158833e-004,0.000000e+000,-5.812362e-001,0.000000e+000,3,0.000000e+000,1.825000e+000,,,,,,,,,,,,,,,,,,0,5.000000e+000,5.000000e-001,2,1,2.909279e-001,0,0,0,
1432771065.318,,2.500000e+002,3.318384e+001,-3.165353e-004,0.000000e+000,-5.804362e-001,0.000000e+000,3,0.000000e+000,1.825000e+000,,,,,,,,,,,,,,,,,,0,5.000000e+000,5.000000e-001,2,1,2.888298e-001,0,0,0,
1432771095.834,,2.500000e+002,3.418381e+001,-3.144940e-004,0.000000e+000,-5.800381e-001,0.000000e+000,3,0.000000e+000,1.825000e+000,,,,,,,,,,,,,,,,,,0,5.000000e+000,5.000000e-001,2,1,2.709084e-001,0,0,0,
1432771128.014,,2.500000e+002,3.524334e+001,-3.091876e-004,0.000000e+000,-5.797756e-001,0.000000e+000,3,0.000000e+000,1.825000e+000,,,,,,,,,,,,,,,,,,0,5.000000e+000,5.000000e-001,2,1,3.187485e-001,0,0,0,
1432771155.313,,2.500000e+002,3.616255e+001,-3.013838e-004,0.000000e+000,-5.795334e-001,0.000000e+000,3,0.000000e+000,1.825000e+000,,,,,,,,,,,,,,,,,,0,5.000000e+000,5.000000e-001,2,1,3.178215e-001,0,0,0,
1432771197.194,,2.500000e+002,3.748788e+001,-2.842304e-004,0.000000e+000,-5.791446e-001,0.000000e+000,3,0.000000e+000,1.825000e+000,,,,,,,,,,,,,,,,,,0,5.000000e+000,5.000000e-001,2,1,2.935486e-001,0,0,0,
1432771218.272,,2.500000e+002,3.816940e+001,-2.734171e-004,0.000000e+000,-5.784627e-001,0.000000e+000,3,0.000000e+000,1.825000e+000,,,,,,,,,,,,,,,,,,0,5.000000e+000,5.000000e-001,2,1,2.533913e-001,0,0,0,
1432771250.702,,2.500000e+002,3.918279e+001,-2.539348e-004,0.000000e+000,-5.788094e-001,0.000000e+000,3,0.000000e+000,1.825000e+000,,,,,,,,,,,,,,,,,,0,5.000000e+000,5.000000e-001,2,1,3.349991e-001,0,0,0,
1432771281.633,,2.500000e+002,4.016705e+001,-2.321615e-004,0.000000e+000,-5.781353e-001,0.000000e+000,3,0.000000e+000,1.825000e+000,,,,,,,,,,,,,,,,,,0,5.000000e+000,5.000000e-001,2,1,3.084717e-001,0,0,0,
1432771311.247,,2.500000e+002,4.116211e+001,-2.085694e-004,0.000000e+000,-5.783455e-001,0.000000e+000,3,0.000000e+000,1.825000e+000,,,,,,,,,,,,,,,,,,0,5.000000e+000,5.000000e-001,2,1,3.053398e-001,0,0,0,
1432771342.299,,2.500000e+002,4.215566e+001,-1.831230e-004,0.000000e+000,-5.782855e-001,0.000000e+000,3,0.000000e+000,1.825000e+000,,,,,,,,,,,,,,,,,,0,5.000000e+000,5.000000e-001,2,1,3.039818e-001,0,0,0,
1432771373.308,,2.500000e+002,4.319267e+001,-1.579066e-004,0.000000e+000,-5.786397e-001,0.000000e+000,3,0.000000e+000,1.825000e+000,,,,,,,,,,,,,,,,,,0,5.000000e+000,5.000000e-001,2,1,2.931328e-001,0,0,0,
1432771414.202,,2.500000e+002,4.447128e+001,-1.292678e-004,0.000000e+000,-5.789914e-001,0.000000e+000,3,0.000000e+000,1.825000e+000,,,,,,,,,,,,,,,,,,0,5.000000e+000,5.000000e-001,2,1,3.069496e-001,0,0,0,
1432771434.880,,2.500000e+002,4.515975e+001,-1.163470e-004,0.000000e+000,-5.791885e-001,0.000000e+000,3,0.000000e+000,1.825000e+000,,,,,,,,,,,,,,,,,,0,5.000000e+000,5.000000e-001,2,1,2.956581e-001,0,0,0,
1432771467.810,,2.500000e+002,4.624488e+001,-9.896116e-005,0.000000e+000,-5.797107e-001,0.000000e+000,3,0.000000e+000,1.825000e+000,,,,,,,,,,,,,,,,,,0,5.000000e+000,5.000000e-001,2,1,2.644196e-001,0,1,0,
1432771496.240,,2.500000e+002,4.717857e+001,-8.708849e-005,0.000000e+000,-5.800130e-001,0.000000e+000,3,0.000000e+000,1.825000e+000,,,,,,,,,,,,,,,,,,0,5.000000e+000,5.000000e-001,2,1,3.025703e-001,0,1,0,
1432771525.919,,2.500000e+002,4.820216e+001,-7.697796e-005,0.000000e+000,-5.803857e-001,0.000000e+000,3,0.000000e+000,1.825000e+000,,,,,,,,,,,,,,,,,,0,5.000000e+000,5.000000e-001,2,1,2.932587e-001,0,1,0,
1432771556.605,,2.500000e+002,4.913945e+001,-6.902828e-005,0.000000e+000,-5.804856e-001,0.000000e+000,3,0.000000e+000,1.825000e+000,,,,,,,,,,,,,,,,,,0,5.000000e+000,5.000000e-001,2,1,2.512207e-001,0,1,0,
1432771587.785,,2.500000e+002,5.018253e+001,-6.205054e-005,0.000000e+000,-5.804144e-001,0.000000e+000,3,0.000000e+000,1.825000e+000,,,,,,,,,,,,,,,,,,0,5.000000e+000,5.000000e-001,2,1,3.376999e-001,0,1,0,
1432771617.966,,2.500000e+002,5.118655e+001,-5.636208e-005,0.000000e+000,-5.814602e-001,0.000000e+000,3,0.000000e+000,1.825000e+000,,,,,,,,,,,,,,,,,,0,5.000000e+000,5.000000e-001,2,1,2.545280e-001,0,1,0,
1432771649.169,,2.500000e+002,5.221619e+001,-5.157744e-005,0.000000e+000,-5.806754e-001,0.000000e+000,3,0.000000e+000,1.825000e+000,,,,,,,,,,,,,,,,,,0,5.000000e+000,5.000000e-001,2,1,2.966805e-001,0,1,0,
1432771678.897,,2.500000e+002,5.318978e+001,-4.752329e-005,0.000000e+000,-5.805635e-001,0.000000e+000,3,0.000000e+000,1.825000e+000,,,,,,,,,,,,,,,,,,0,5.000000e+000,5.000000e-001,2,1,2.527809e-001,0,1,0,
1432771708.078,,2.500000e+002,5.415664e+001,-4.398879e-005,0.000000e+000,-5.821650e-001,0.000000e+000,3,0.000000e+000,1.825000e+000,,,,,,,,,,,,,,,,,,0,5.000000e+000,5.000000e-001,2,1,2.774887e-001,0,1,0,
1432771741.797,,2.500000e+002,5.521181e+001,-4.056527e-005,0.000000e+000,-5.826499e-001,0.000000e+000,3,0.000000e+000,1.825000e+000,,,,,,,,,,,,,,,,,,0,5.000000e+000,5.000000e-001,2,1,3.179512e-001,0,1,0,
1432771770.477,,2.500000e+002,5.616302e+001,-3.782509e-005,0.000000e+000,-5.856897e-001,0.000000e+000,3,0.000000e+000,1.825000e+000,,,,,,,,,,,,,,,,,,0,5.000000e+000,5.000000e-001,2,1,2.820587e-001,0,1,0,
1432771812.910,,2.500000e+002,5.750586e+001,-3.430061e-005,0.000000e+000,-5.912766e-001,0.000000e+000,3,0.000000e+000,1.825000e+000,,,,,,,,,,,,,,,,,,0,5.000000e+000,5.000000e-001,2,1,2.919388e-001,0,1,0,
1432771834.840,,2.500000e+002,5.817750e+001,-3.264351e-005,0.000000e+000,-5.909480e-001,0.000000e+000,3,0.000000e+000,1.825000e+000,,,,,,,,,,,,,,,,,,0,5.000000e+000,5.000000e-001,2,1,3.101387e-001,0,1,0,
1432771866.528,,2.500000e+002,5.916856e+001,-3.030529e-005,0.000000e+000,-5.809820e-001,0.000000e+000,3,0.000000e+000,1.825000e+000,,,,,,,,,,,,,,,,,,0,5.000000e+000,5.000000e-001,2,1,2.655678e-001,0,1,0,
1432771898.248,,2.500000e+002,6.019450e+001,-2.814252e-005,0.000000e+000,-5.291317e-001,0.000000e+000,3,0.000000e+000,1.825000e+000,,,,,,,,,,,,,,,,,,0,5.000000e+000,5.000000e-001,2,1,2.532501e-001,0,1,0,
1432771929.205,,2.500000e+002,6.116029e+001,-2.306158e-005,0.000000e+000,-8.638304e-001,0.000000e+000,3,0.000000e+000,1.825000e+000,,,,,,,,,,,,,,,,,,0,5.000000e+000,5.000000e-001,2,1,2.903519e-001,0,1,0,
1432771963.634,,2.500000e+002,6.223689e+001,-1.664203e-005,0.000000e+000,-1.089851e+000,0.000000e+000,3,0.000000e+000,1.825000e+000,,,,,,,,,,,,,,,,,,0,5.000000e+000,5.000000e-001,2,1,2.661667e-001,0,1,0,
1432771994.147,,2.500000e+002,6.318581e+001,-1.281747e-005,0.000000e+000,-1.194805e+000,0.000000e+000,3,0.000000e+000,1.825000e+000,,,,,,,,,,,,,,,,,,0,5.000000e+000,5.000000e-001,2,1,2.952919e-001,0,1,0,
1432772025.114,,2.500000e+002,6.417152e+001,-1.046842e-005,0.000000e+000,-1.247084e+000,0.000000e+000,3,0.000000e+000,1.825000e+000,,,,,,,,,,,,,,,,,,0,5.000000e+000,5.000000e-001,2,1,2.960892e-001,0,1,0,
1432772055.601,,2.500000e+002,6.516930e+001,-8.959183e-006,0.000000e+000,-1.274133e+000,0.000000e+000,3,0.000000e+000,1.825000e+000,,,,,,,,,,,,,,,,,,0,5.000000e+000,5.000000e-001,2,1,2.657471e-001,0,1,0,
1432772086.299,,2.500000e+002,6.614937e+001,-7.765990e-006,0.000000e+000,-1.295896e+000,0.000000e+000,3,0.000000e+000,1.825000e+000,,,,,,,,,,,,,,,,,,0,5.000000e+000,5.000000e-001,2,1,2.861099e-001,0,1,0,
1432772135.373,,2.500000e+002,6.769423e+001,-6.370347e-006,0.000000e+000,-1.317754e+000,0.000000e+000,3,0.000000e+000,1.825000e+000,,,,,,,,,,,,,,,,,,0,5.000000e+000,5.000000e-001,2,1,3.211365e-001,0,0,0,
1432772157.052,,2.500000e+002,6.842699e+001,-5.748806e-006,0.000000e+000,-1.330544e+000,0.000000e+000,3,0.000000e+000,1.825000e+000,,,,,,,,,,,,,,,,,,0,5.000000e+000,5.000000e-001,2,1,2.984009e-001,0,0,0,
1432772179.731,,2.500000e+002,6.917392e+001,-5.219920e-006,0.000000e+000,-1.341989e+000,0.000000e+000,3,0.000000e+000,1.825000e+000,,,,,,,,,,,,,,,,,,0,5.000000e+000,5.000000e-001,2,1,3.092651e-001,0,0,0,
1432772211.845,,2.500000e+002,7.019267e+001,-4.711864e-006,0.000000e+000,-1.346825e+000,0.000000e+000,3,0.000000e+000,1.825000e+000,,,,,,,,,,,,,,,,,,0,5.000000e+000,5.000000e-001,2,1,2.255325e-001,0,0,0,
1432772241.383,,2.500000e+002,7.116472e+001,-4.196569e-006,0.000000e+000,-1.360935e+000,0.000000e+000,3,0.000000e+000,1.825000e+000,,,,,,,,,,,,,,,,,,0,5.000000e+000,5.000000e-001,2,1,2.998581e-001,0,0,0,
1432772273.627,,2.500000e+002,7.223559e+001,-3.741725e-006,0.000000e+000,-1.370572e+000,0.000000e+000,3,0.000000e+000,1.825000e+000,,,,,,,,,,,,,,,,,,0,5.000000e+000,5.000000e-001,2,1,2.684784e-001,0,0,0,
1432772302.115,,2.500000e+002,7.318996e+001,-3.401502e-006,0.000000e+000,-1.378946e+000,0.000000e+000,3,0.000000e+000,1.825000e+000,,,,,,,,,,,,,,,,,,0,5.000000e+000,5.000000e-001,2,1,3.345795e-001,0,0,0,
1432772332.574,,2.500000e+002,7.415818e+001,-3.155572e-006,0.000000e+000,-1.382114e+000,0.000000e+000,3,0.000000e+000,1.825000e+000,,,,,,,,,,,,,,,,,,0,5.000000e+000,5.000000e-001,2,1,2.824860e-001,0,0,0,
1432772363.798,,2.500000e+002,7.519627e+001,-2.890074e-006,0.000000e+000,-1.390066e+000,0.000000e+000,3,0.000000e+000,1.825000e+000,,,,,,,,,,,,,,,,,,0,5.000000e+000,5.000000e-001,2,1,2.684860e-001,0,0,0,
1432772392.784,,2.500000e+002,7.614465e+001,-2.719787e-006,0.000000e+000,-1.393986e+000,0.000000e+000,3,0.000000e+000,1.825000e+000,,,,,,,,,,,,,,,,,,0,5.000000e+000,5.000000e-001,2,1,2.889557e-001,0,0,0,
1432772435.503,,2.500000e+002,7.753282e+001,-2.498824e-006,0.000000e+000,-1.399499e+000,0.000000e+000,3,0.000000e+000,1.825000e+000,,,,,,,,,,,,,,,,,,0,5.000000e+000,5.000000e-001,2,1,2.877121e-001,0,0,0,
1432772456.711,,2.500000e+002,7.823470e+001,-2.386198e-006,0.000000e+000,-1.401476e+000,0.000000e+000,3,0.000000e+000,1.825000e+000,,,,,,,,,,,,,,,,,,0,5.000000e+000,5.000000e-001,2,1,2.509308e-001,0,0,0,
1432772488.141,,2.500000e+002,7.917271e+001,-2.310916e-006,0.000000e+000,-1.404860e+000,0.000000e+000,3,0.000000e+000,1.825000e+000,,,,,,,,,,,,,,,,,,0,5.000000e+000,5.000000e-001,2,1,2.933502e-001,0,0,0,
1432772520.828,,2.500000e+002,8.021214e+001,-2.193942e-006,0.000000e+000,-1.406781e+000,0.000000e+000,3,0.000000e+000,1.825000e+000,,,,,,,,,,,,,,,,,,0,5.000000e+000,5.000000e-001,2,1,2.822342e-001,0,0,0,
1432772550.765,,2.500000e+002,8.116930e+001,-2.132120e-006,0.000000e+000,-1.405872e+000,0.000000e+000,3,0.000000e+000,1.825000e+000,,,,,,,,,,,,,,,,,,0,5.000000e+000,5.000000e-001,2,1,3.293991e-001,0,0,0,
1432772582.043,,2.500000e+002,8.222023e+001,-2.079107e-006,0.000000e+000,-1.404509e+000,0.000000e+000,3,0.000000e+000,1.825000e+000,,,,,,,,,,,,,,,,,,0,5.000000e+000,5.000000e-001,2,1,2.539139e-001,0,0,0,
1432772612.228,,2.500000e+002,8.321338e+001,-2.031940e-006,0.000000e+000,-1.398071e+000,0.000000e+000,3,0.000000e+000,1.825000e+000,,,,,,,,,,,,,,,,,,0,5.000000e+000,5.000000e-001,2,1,2.827530e-001,0,0,0,
1432772643.208,,2.500000e+002,8.423274e+001,-4.201252e-006,0.000000e+000,-7.601129e-001,0.000000e+000,3,0.000000e+000,1.825000e+000,,,,,,,,,,,,,,,,,,0,5.000000e+000,5.000000e-001,2,1,2.926788e-001,0,0,0,
1432772675.465,,2.500000e+002,8.530861e+001,5.830841e-007,0.000000e+000,-2.284290e+000,0.000000e+000,3,0.000000e+000,1.825000e+000,,,,,,,,,,,,,,,,,,0,5.000000e+000,5.000000e-001,2,1,2.791061e-001,0,0,0,
1432772701.396,,2.500000e+002,8.615025e+001,5.458465e-007,0.000000e+000,-2.283765e+000,0.000000e+000,3,0.000000e+000,1.825000e+000,,,,,,,,,,,,,,,,,,0,5.000000e+000,5.000000e-001,2,1,2.843399e-001,0,0,0,
1432772732.375,,2.500000e+002,8.714743e+001,4.841976e-007,0.000000e+000,-2.284037e+000,0.000000e+000,3,0.000000e+000,1.825000e+000,,,,,,,,,,,,,,,,,,0,5.000000e+000,5.000000e-001,2,1,2.905655e-001,0,0,0,
1432772764.599,,2.500000e+002,8.816209e+001,4.514838e-007,0.000000e+000,-2.284142e+000,0.000000e+000,3,0.000000e+000,1.825000e+000,,,,,,,,,,,,,,,,,,0,5.000000e+000,5.000000e-001,2,1,3.025055e-001,0,0,0,
1432772797.783,,2.500000e+002,8.921046e+001,3.720409e-007,0.000000e+000,-2.284067e+000,0.000000e+000,3,0.000000e+000,1.825000e+000,,,,,,,,,,,,,,,,,,0,5.000000e+000,5.000000e-001,2,1,2.961884e-001,0,1,0,
1432772826.962,,2.500000e+002,9.018011e+001,3.497924e-007,0.000000e+000,-2.284098e+000,0.000000e+000,3,0.000000e+000,1.825000e+000,,,,,,,,,,,,,,,,,,0,5.000000e+000,5.000000e-001,2,1,3.099442e-001,0,1,0,
1432772856.892,,2.500000e+002,9.115999e+001,-9.152931e-007,0.000000e+000,0.000000e+000,0.000000e+000,3,0.000000e+000,1.825000e+000,,,,,,,,,,,,,,,,,,0,5.000000e+000,5.000000e-001,2,1,3.045883e-001,0,1,0,
1432772888.618,,2.500000e+002,9.220398e+001,-8.284597e-007,0.000000e+000,0.000000e+000,0.000000e+000,3,0.000000e+000,1.825000e+000,,,,,,,,,,,,,,,,,,0,5.000000e+000,5.000000e-001,2,1,2.832718e-001,0,1,0,
1432772918.549,,2.500000e+002,9.319542e+001,-7.905709e-007,0.000000e+000,0.000000e+000,0.000000e+000,3,0.000000e+000,1.825000e+000,,,,,,,,,,,,,,,,,,0,5.000000e+000,5.000000e-001,2,1,2.809067e-001,0,1,0,
1432772948.230,,2.500000e+002,9.420296e+001,-7.432755e-007,0.000000e+000,0.000000e+000,0.000000e+000,3,0.000000e+000,1.825000e+000,,,,,,,,,,,,,,,,,,0,5.000000e+000,5.000000e-001,2,1,2.617188e-001,0,1,0,
1432772978.197,,2.500000e+002,9.518893e+001,-6.780364e-007,0.000000e+000,0.000000e+000,0.000000e+000,3,0.000000e+000,1.825000e+000,,,,,,,,,,,,,,,,,,0,5.000000e+000,5.000000e-001,2,1,2.838821e-001,0,1,0,
1432773009.658,,2.500000e+002,9.622054e+001,-6.070383e-007,0.000000e+000,0.000000e+000,0.000000e+000,3,0.000000e+000,1.825000e+000,,,,,,,,,,,,,,,,,,0,5.000000e+000,5.000000e-001,2,1,2.983780e-001,0,1,0,
1432773052.090,,2.500000e+002,9.757669e+001,-5.833837e-007,0.000000e+000,0.000000e+000,0.000000e+000,3,0.000000e+000,1.825000e+000,,,,,,,,,,,,,,,,,,0,5.000000e+000,5.000000e-001,2,1,3.019257e-001,0,1,0,
1432773075.211,,2.500000e+002,9.830106e+001,-5.681634e-007,0.000000e+000,0.000000e+000,0.000000e+000,3,0.000000e+000,1.825000e+000,,,,,,,,,,,,,,,,,,0,5.000000e+000,5.000000e-001,2,1,3.241882e-001,0,1,0,
1432773101.311,,2.500000e+002,9.917509e+001,-4.968334e-007,0.000000e+000,0.000000e+000,0.000000e+000,3,0.000000e+000,1.825000e+000,,,,,,,,,,,,,,,,,,0,5.000000e+000,5.000000e-001,2,1,3.067856e-001,0,1,0,
1432773321.117,,2.500000e+002,9.999480e+001,-4.759544e-007,0.000000e+000,0.000000e+000,0.000000e+000,3,0.000000e+000,1.825000e+000,,,,,,,,,,,,,,,,,,0,5.000000e+000,5.000000e-001,2,1,1.400757e-002,0,1,0,
1432773527.841,,2.500000e+002,9.999710e+001,-5.024744e-007,0.000000e+000,0.000000e+000,0.000000e+000,3,0.000000e+000,1.825000e+000,,,,,,,,,,,,,,,,,,0,5.000000e+000,5.000000e-001,2,1,1.860809e-002,0,0,0,
1432773587.275,,2.500000e+002,1.026816e+002,-3.890012e-007,0.000000e+000,0.000000e+000,0.000000e+000,3,0.000000e+000,1.825000e+000,,,,,,,,,,,,,,,,,,0,5.000000e+000,5.000000e-001,2,1,1.128998e+000,0,0,0,
1432773609.500,,2.500000e+002,1.057261e+002,-2.837068e-007,0.000000e+000,0.000000e+000,0.000000e+000,3,0.000000e+000,1.825000e+000,,,,,,,,,,,,,,,,,,0,5.000000e+000,5.000000e-001,2,1,1.213402e+000,0,0,0,
1432773632.179,,2.500000e+002,1.093880e+002,-1.627545e-007,0.000000e+000,0.000000e+000,0.000000e+000,3,0.000000e+000,1.825000e+000,,,,,,,,,,,,,,,,,,0,5.000000e+000,5.000000e-001,2,1,1.530495e+000,0,0,0,
1432773654.911,,2.500000e+002,1.131113e+002,-4.414498e-008,0.000000e+000,0.000000e+000,0.000000e+000,3,0.000000e+000,1.825000e+000,,,,,,,,,,,,,,,,,,0,5.000000e+000,5.000000e-001,2,1,1.606102e+000,0,0,0,
1432773678.650,,2.500000e+002,1.175247e+002,2.562805e-008,0.000000e+000,0.000000e+000,0.000000e+000,3,0.000000e+000,1.825000e+000,,,,,,,,,,,,,,,,,,0,5.000000e+000,5.000000e-001,2,1,1.858902e+000,0,0,0,
1432773703.026,,2.500000e+002,1.219858e+002,1.095953e-007,0.000000e+000,0.000000e+000,0.000000e+000,3,0.000000e+000,1.825000e+000,,,,,,,,,,,,,,,,,,0,5.000000e+000,5.000000e-001,2,1,1.788498e+000,0,0,0,
1432773727.604,,2.500000e+002,1.263652e+002,4.861821e-006,0.000000e+000,1.107814e+000,0.000000e+000,3,8.175820e-001,1.825000e+000,,,,,,,,,,,,,,,,,,0,5.000000e+000,5.000000e-001,2,1,1.802605e+000,0,0,0,
1432773751.533,,2.500000e+002,1.308518e+002,4.577456e-006,0.000000e+000,1.105063e+000,0.000000e+000,3,8.087243e-001,1.825000e+000,,,,,,,,,,,,,,,,,,0,5.000000e+000,5.000000e-001,2,1,1.712997e+000,0,0,0,
1432773775.828,,2.500000e+002,1.350417e+002,3.762965e-007,0.000000e+000,0.000000e+000,0.000000e+000,3,0.000000e+000,1.825000e+000,,,,,,,,,,,,,,,,,,0,5.000000e+000,5.000000e-001,2,1,1.699890e+000,0,0,0,
1432773800.066,,2.500000e+002,1.392956e+002,-1.111252e-006,0.000000e+000,-1.463494e+000,0.000000e+000,3,0.000000e+000,1.825000e+000,,,,,,,,,,,,,,,,,,0,5.000000e+000,5.000000e-001,2,1,1.647400e+000,0,0,0,
1432773825.248,,2.500000e+002,1.435830e+002,3.921307e-006,0.000000e+000,1.153897e+000,0.000000e+000,3,7.579715e-001,1.825000e+000,,,,,,,,,,,,,,,,,,0,5.000000e+000,5.000000e-001,2,1,1.783798e+000,0,0,0,
1432773847.428,,2.500000e+002,1.473363e+002,-1.060690e-006,0.000000e+000,-1.479385e+000,0.000000e+000,3,0.000000e+000,1.825000e+000,,,,,,,,,,,,,,,,,,0,5.000000e+000,5.000000e-001,2,1,1.241196e+000,0,0,0,
1432773870.107,,2.500000e+002,1.507026e+002,-6.408874e-007,0.000000e+000,-2.301551e+000,0.000000e+000,3,0.000000e+000,1.825000e+000,,,,,,,,,,,,,,,,,,0,5.000000e+000,5.000000e-001,2,1,1.550201e+000,0,0,0,
1432773893.036,,2.500000e+002,1.540108e+002,6.180319e-007,0.000000e+000,0.000000e+000,0.000000e+000,3,0.000000e+000,1.825000e+000,,,,,,,,,,,,,,,,,,0,5.000000e+000,5.000000e-001,2,1,1.495392e+000,0,0,0,
1432773915.467,,2.500000e+002,1.573604e+002,6.368383e-007,0.000000e+000,0.000000e+000,0.000000e+000,3,0.000000e+000,1.825000e+000,,,,,,,,,,,,,,,,,,0,5.000000e+000,5.000000e-001,2,1,1.228699e+000,0,0,0,
1432773938.147,,2.500000e+002,1.607999e+002,6.590443e-007,0.000000e+000,0.000000e+000,0.000000e+000,3,0.000000e+000,1.825000e+000,,,,,,,,,,,,,,,,,,0,5.000000e+000,5.000000e-001,2,1,1.591797e+000,0,0,0,
1432773960.826,,2.500000e+002,1.643199e+002,7.102179e-007,0.000000e+000,0.000000e+000,0.000000e+000,3,0.000000e+000,1.825000e+000,,,,,,,,,,,,,,,,,,0,5.000000e+000,5.000000e-001,2,1,1.594788e+000,0,0,0,
1432773985.007,,2.500000e+002,1.682271e+002,7.522432e-007,0.000000e+000,0.000000e+000,0.000000e+000,3,0.000000e+000,1.825000e+000,,,,,,,,,,,,,,,,,,0,5.000000e+000,5.000000e-001,2,1,1.418900e+000,0,0,0,
1432774008.151,,2.500000e+002,1.718238e+002,7.862630e-007,0.000000e+000,0.000000e+000,0.000000e+000,3,0.000000e+000,1.825000e+000,,,,,,,,,,,,,,,,,,0,5.000000e+000,5.000000e-001,2,1,1.583694e+000,0,0,0,
1432774031.543,,2.500000e+002,1.755970e+002,2.674007e-006,0.000000e+000,1.019321e+000,0.000000e+000,3,6.731510e-001,1.825000e+000,,,,,,,,,,,,,,,,,,0,5.000000e+000,5.000000e-001,2,1,1.468307e+000,0,0,0,
1432774056.684,,2.500000e+002,1.796618e+002,2.539042e-006,0.000000e+000,1.001446e+000,0.000000e+000,3,6.573436e-001,1.825000e+000,,,,,,,,,,,,,,,,,,0,5.000000e+000,5.000000e-001,2,1,1.435806e+000,0,0,0,
1432774080.293,,2.500000e+002,1.834966e+002,2.449048e-006,0.000000e+000,9.826204e-001,0.000000e+000,3,6.491442e-001,1.825000e+000,,,,,,,,,,,,,,,,,,0,5.000000e+000,5.000000e-001,2,1,1.452209e+000,0,0,0,
1432774103.042,,2.500000e+002,1.871229e+002,2.370660e-006,0.000000e+000,9.701210e-001,0.000000e+000,3,6.388107e-001,1.825000e+000,,,,,,,,,,,,,,,,,,0,5.000000e+000,5.000000e-001,2,1,1.579605e+000,0,0,0,
1432774125.684,,2.500000e+002,1.908546e+002,2.282195e-006,0.000000e+000,9.614099e-001,0.000000e+000,3,6.178260e-001,1.825000e+000,,,,,,,,,,,,,,,,,,0,5.000000e+000,5.000000e-001,2,1,1.747498e+000,0,0,0,
1432774148.106,,2.500000e+002,1.945723e+002,2.206075e-006,0.000000e+000,9.514176e-001,0.000000e+000,3,6.112719e-001,1.825000e+000,,,,,,,,,,,,,,,,,,0,5.000000e+000,5.000000e-001,2,1,1.581604e+000,0,0,0,
1432774172.555,,2.500000e+002,1.985771e+002,2.129771e-006,0.000000e+000,9.341685e-001,0.000000e+000,3,5.980555e-001,1.825000e+000,,,,,,,,,,,,,,,,,,0,5.000000e+000,5.000000e-001,2,1,1.594604e+000,0,1,0,
1432774195.965,,2.500000e+002,2.022860e+002,2.073674e-006,0.000000e+000,9.206519e-001,0.000000e+000,3,5.798691e-001,1.825000e+000,,,,,,,,,,,,,,,,,,0,5.000000e+000,5.000000e-001,2,1,1.292801e+000,0,1,0,
1432774219.109,,2.500000e+002,2.061195e+002,2.007637e-006,0.000000e+000,9.023609e-001,0.000000e+000,3,5.681148e-001,1.825000e+000,,,,,,,,,,,,,,,,,,0,5.000000e+000,5.000000e-001,2,1,1.513504e+000,0,1,0,
1432774242.502,,2.500000e+002,2.101946e+002,1.942250e-006,0.000000e+000,8.956317e-001,0.000000e+000,3,5.632665e-001,1.825000e+000,,,,,,,,,,,,,,,,,,0,5.000000e+000,5.000000e-001,2,1,1.601608e+000,0,1,0,
1432774265.187,,2.500000e+002,2.141147e+002,1.893086e-006,0.000000e+000,8.809267e-001,0.000000e+000,3,5.448920e-001,1.825000e+000,,,,,,,,,,,,,,,,,,0,5.000000e+000,5.000000e-001,2,1,1.561295e+000,0,1,0,
1432774289.341,,2.500000e+002,2.178806e+002,1.848273e-006,0.000000e+000,8.708140e-001,0.000000e+000,3,5.450577e-001,1.825000e+000,,,,,,,,,,,,,,,,,,0,5.000000e+000,5.000000e-001,2,1,1.386505e+000,0,1,0,
1432774311.757,,2.500000e+002,2.217518e+002,1.824114e-006,0.000000e+000,8.505946e-001,0.000000e+000,3,5.278426e-001,1.825000e+000,,,,,,,,,,,,,,,,,,0,5.000000e+000,5.000000e-001,2,1,1.567505e+000,0,1,0,
1432774335.424,,2.500000e+002,2.256395e+002,1.756232e-006,0.000000e+000,8.262972e-001,0.000000e+000,3,5.182285e-001,1.825000e+000,,,,,,,,,,,,,,,,,,0,5.000000e+000,5.000000e-001,2,1,1.375488e+000,0,1,0,
1432774359.091,,2.500000e+002,2.294642e+002,1.732907e-006,0.000000e+000,7.955300e-001,0.000000e+000,3,5.053449e-001,1.825000e+000,,,,,,,,,,,,,,,,,,0,5.000000e+000,5.000000e-001,2,1,1.504700e+000,0,1,0,
1432774382.930,,2.500000e+002,2.332949e+002,1.700621e-006,0.000000e+000,7.818196e-001,0.000000e+000,3,5.002992e-001,1.825000e+000,,,,,,,,,,,,,,,,,,0,5.000000e+000,5.000000e-001,2,1,1.482803e+000,0,1,0,
1432774405.599,,2.500000e+002,2.367586e+002,1.685921e-006,0.000000e+000,7.723562e-001,0.000000e+000,3,4.892933e-001,1.825000e+000,,,,,,,,,,,,,,,,,,0,5.000000e+000,5.000000e-001,2,1,1.676590e+000,0,1,0,
1432774428.281,,2.500000e+002,2.405559e+002,1.637420e-006,0.000000e+000,7.274679e-001,0.000000e+000,3,4.965552e-001,1.825000e+000,,,,,,,,,,,,,,,,,,0,5.000000e+000,5.000000e-001,2,1,1.474197e+000,0,1,0,
1432774452.198,,2.500000e+002,2.445441e+002,1.590168e-006,0.000000e+000,7.186991e-001,0.000000e+000,3,4.783731e-001,1.825000e+000,,,,,,,,,,,,,,,,,,0,5.000000e+000,5.000000e-001,2,1,1.669098e+000,0,1,0,
1432774475.614,,2.500000e+002,2.483571e+002,1.603438e-006,0.000000e+000,7.030452e-001,0.000000e+000,3,4.711501e-001,1.825000e+000,,,,,,,,,,,,,,,,,,0,5.000000e+000,5.000000e-001,2,1,1.489105e+000,0,1,0,
1432774498.279,,2.500000e+002,2.519982e+002,1.545045e-006,0.000000e+000,6.826712e-001,0.000000e+000,3,4.621938e-001,1.825000e+000,,,,,,,,,,,,,,,,,,0,5.000000e+000,5.000000e-001,2,1,1.188400e+000,0,1,0,
1432774520.969,,2.500000e+002,2.554632e+002,1.534117e-006,0.000000e+000,6.656752e-001,0.000000e+000,3,4.519254e-001,1.825000e+000,,,,,,,,,,,,,,,,,,0,5.000000e+000,5.000000e-001,2,1,1.553497e+000,0,1,0,
1432774543.681,,2.500000e+002,2.590193e+002,1.570324e-006,0.000000e+000,6.130137e-001,0.000000e+000,3,4.601345e-001,1.825000e+000,,,,,,,,,,,,,,,,,,0,5.000000e+000,5.000000e-001,2,1,1.411224e+000,0,1,0,
1432774566.597,,2.500000e+002,2.627445e+002,1.547796e-006,0.000000e+000,6.072093e-001,0.000000e+000,3,4.561854e-001,1.825000e+000,,,,,,,,,,,,,,,,,,0,5.000000e+000,5.000000e-001,2,1,1.474609e+000,0,1,0,
1432774590.042,,2.500000e+002,2.665197e+002,1.487756e-006,0.000000e+000,5.842660e-001,0.000000e+000,3,4.618573e-001,1.825000e+000,,,,,,,,,,,,,,,,,,0,5.000000e+000,5.000000e-001,2,1,1.397400e+000,0,1,0,
1432774612.404,,2.500000e+002,2.700243e+002,1.497879e-006,0.000000e+000,5.524319e-001,0.000000e+000,3,4.643190e-001,1.825000e+000,,,,,,,,,,,,,,,,,,0,5.000000e+000,5.000000e-001,2,1,1.381805e+000,0,1,0,
1432774635.238,,2.500000e+002,2.736047e+002,1.488788e-006,0.000000e+000,5.368183e-001,0.000000e+000,3,4.728861e-001,1.825000e+000,,,,,,,,,,,,,,,,,,0,5.000000e+000,5.000000e-001,2,1,1.573608e+000,0,1,0,
1432774658.164,,2.500000e+002,2.773527e+002,1.461750e-006,0.000000e+000,5.257385e-001,0.000000e+000,3,4.577413e-001,1.825000e+000,,,,,,,,,,,,,,,,,,0,5.000000e+000,5.000000e-001,2,1,1.759918e+000,0,1,0,
1432774681.364,,2.500000e+002,2.811172e+002,1.495137e-006,0.000000e+000,4.866569e-001,0.000000e+000,3,4.664796e-001,1.825000e+000,,,,,,,,,,,,,,,,,,0,5.000000e+000,5.000000e-001,2,1,1.546509e+000,0,1,0,
1432774704.093,,2.500000e+002,2.847084e+002,1.485001e-006,0.000000e+000,4.689424e-001,0.000000e+000,3,4.698837e-001,1.825000e+000,,,,,,,,,,,,,,,,,,0,5.000000e+000,5.000000e-001,2,1,1.398529e+000,0,1,0,
1432774728.020,,2.500000e+002,2.886904e+002,1.436349e-006,0.000000e+000,4.420404e-001,0.000000e+000,3,4.702260e-001,1.825000e+000,,,,,,,,,,,,,,,,,,0,5.000000e+000,5.000000e-001,2,1,1.611389e+000,0,1,0,
1432774750.278,,2.500000e+002,2.924127e+002,1.447708e-006,0.000000e+000,4.175968e-001,0.000000e+000,3,4.703937e-001,1.825000e+000,,,,,,,,,,,,,,,,,,0,5.000000e+000,5.000000e-001,2,1,1.608917e+000,0,1,0,
1432774772.716,,2.500000e+002,2.961568e+002,1.463944e-006,0.000000e+000,4.009487e-001,0.000000e+000,3,4.738578e-001,1.825000e+000,,,,,,,,,,,,,,,,,,0,5.000000e+000,5.000000e-001,2,1,1.594421e+000,0,1,0,
1432774795.426,,2.500000e+002,2.998018e+002,1.631631e-006,0.000000e+000,2.895632e-001,0.000000e+000,3,4.777541e-001,1.825000e+000,,,,,,,,,,,,,,,,,,0,5.000000e+000,5.000000e-001,2,1,1.453217e+000,0,1,0,
1432775141.940,,2.500000e+002,3.000457e+002,1.480465e-006,0.000000e+000,4.061423e-001,0.000000e+000,3,4.846171e-001,1.825000e+000,,,,,,,,,,,,,,,,,,0,5.000000e+000,5.000000e-001,2,1,2.041626e-002,0,0,0,
1432775162.868,,2.500000e+002,3.000201e+002,1.492154e-006,0.000000e+000,4.068062e-001,0.000000e+000,3,4.862367e-001,1.825000e+000,,,,,,,,,,,,,,,,,,0,5.000000e+000,5.000000e-001,2,1,1.019287e-002,0,0,0,
1432775183.545,,2.500000e+002,3.000201e+002,1.494966e-006,0.000000e+000,3.974024e-001,0.000000e+000,3,4.876897e-001,1.825000e+000,,,,,,,,,,,,,,,,,,0,5.000000e+000,5.000000e-001,2,1,1.019287e-002,0,0,0,
1432775204.971,,2.500000e+002,3.000252e+002,1.483980e-006,0.000000e+000,4.124160e-001,0.000000e+000,3,4.864287e-001,1.825000e+000,,,,,,,,,,,,,,,,,,0,5.000000e+000,5.000000e-001,2,1,0.000000e+000,0,0,0,
1432775226.188,,2.500000e+002,3.000303e+002,1.499307e-006,0.000000e+000,4.129746e-001,0.000000e+000,3,4.854512e-001,1.825000e+000,,,,,,,,,,,,,,,,,,0,5.000000e+000,5.000000e-001,2,1,1.028442e-002,0,0,0,
1432775247.365,,2.500000e+002,3.000303e+002,1.495040e-006,0.000000e+000,3.986431e-001,0.000000e+000,3,4.895378e-001,1.825000e+000,,,,,,,,,,,,,,,,,,0,5.000000e+000,5.000000e-001,2,1,1.028442e-002,0,0,0,
1432775268.042,,2.500000e+002,3.000303e+002,1.486805e-006,0.000000e+000,4.137876e-001,0.000000e+000,3,4.751967e-001,1.825000e+000,,,,,,,,,,,,,,,,,,0,5.000000e+000,5.000000e-001,2,1,1.028442e-002,0,0,0,
1432775288.745,,2.500000e+002,3.000303e+002,1.500231e-006,0.000000e+000,4.100855e-001,0.000000e+000,3,4.831835e-001,1.825000e+000,,,,,,,,,,,,,,,,,,0,5.000000e+000,5.000000e-001,2,1,1.028442e-002,0,0,0,
1432775309.671,,2.500000e+002,3.000150e+002,1.501418e-006,0.000000e+000,4.220184e-001,0.000000e+000,3,4.887692e-001,1.825000e+000,,,,,,,,,,,,,,,,,,0,5.000000e+000,5.000000e-001,2,1,0.000000e+000,0,0,0,
1432775330.850,,2.500000e+002,3.000099e+002,1.495749e-006,0.000000e+000,4.210420e-001,0.000000e+000,3,4.859619e-001,1.825000e+000,,,,,,,,,,,,,,,,,,0,5.000000e+000,5.000000e-001,2,1,1.031494e-002,0,0,0,
1432775352.302,,2.500000e+002,3.000201e+002,1.485174e-006,0.000000e+000,4.080459e-001,0.000000e+000,3,4.797098e-001,1.825000e+000,,,,,,,,,,,,,,,,,,0,5.000000e+000,5.000000e-001,2,1,1.019287e-002,0,0,0,
1432775373.231,,2.500000e+002,3.000150e+002,1.479553e-006,0.000000e+000,3.935875e-001,0.000000e+000,3,4.787310e-001,1.825000e+000,,,,,,,,,,,,,,,,,,0,5.000000e+000,5.000000e-001,2,1,0.000000e+000,0,0,0,
1432775393.907,,2.500000e+002,3.000047e+002,1.486966e-006,0.000000e+000,3.969395e-001,0.000000e+000,3,4.797725e-001,1.825000e+000,,,,,,,,,,,,,,,,,,0,5.000000e+000,5.000000e-001,2,1,2.062988e-002,0,0,0,
1432775414.834,,2.500000e+002,3.000150e+002,1.479814e-006,0.000000e+000,4.165488e-001,0.000000e+000,3,4.813029e-001,1.825000e+000,,,,,,,,,,,,,,,,,,0,5.000000e+000,5.000000e-001,2,1,0.000000e+000,0,0,0,
1432775435.784,,2.500000e+002,3.000201e+002,1.477731e-006,0.000000e+000,4.008601e-001,0.000000e+000,3,4.802812e-001,1.825000e+000,,,,,,,,,,,,,,,,,,0,5.000000e+000,5.000000e-001,2,1,1.019287e-002,0,0,0,
1432775456.463,,2.500000e+002,3.000047e+002,1.484027e-006,0.000000e+000,4.022532e-001,0.000000e+000,3,4.737740e-001,1.825000e+000,,,,,,,,,,,,,,,,,,0,5.000000e+000,5.000000e-001,2,1,2.062988e-002,0,0,0,
1432775477.891,,2.500000e+002,3.000150e+002,1.489086e-006,0.000000e+000,4.094566e-001,0.000000e+000,3,4.800912e-001,1.825000e+000,,,,,,,,,,,,,,,,,,0,5.000000e+000,5.000000e-001,2,1,2.050781e-002,0,0,0,
1432775524.027,,2.500000e+002,3.000099e+002,1.477779e-006,0.000000e+000,4.119044e-001,0.000000e+000,3,4.803344e-001,1.825000e+000,,,,,,,,,,,,,,,,,,0,5.000000e+000,5.000000e-001,2,1,1.031494e-002,0,1,0,
1432775545.564,,2.500000e+002,2.999996e+002,1.472999e-006,0.000000e+000,3.983454e-001,0.000000e+000,3,4.753880e-001,1.825000e+000,,,,,,,,,,,,,,,,,,0,5.000000e+000,5.000000e-001,2,1,3.082275e-002,0,1,0,
1432775566.495,,2.500000e+002,3.000047e+002,1.500270e-006,0.000000e+000,4.205897e-001,0.000000e+000,3,4.753207e-001,1.825000e+000,,,,,,,,,,,,,,,,,,0,5.000000e+000,5.000000e-001,2,1,0.000000e+000,0,1,0,
1432775587.502,,2.500000e+002,2.999995e+002,1.497507e-006,0.000000e+000,4.147170e-001,0.000000e+000,3,4.747024e-001,1.825000e+000,,,,,,,,,,,,,,,,,,0,5.000000e+000,5.000000e-001,2,1,1.031494e-002,0,1,0,
1432775608.182,,2.500000e+002,3.000047e+002,1.494476e-006,0.000000e+000,4.173036e-001,0.000000e+000,3,4.852875e-001,1.825000e+000,,,,,,,,,,,,,,,,,,0,5.000000e+000,5.000000e-001,2,1,0.000000e+000,0,1,0,
1432775629.611,,2.500000e+002,3.000047e+002,1.471339e-006,0.000000e+000,4.010879e-001,0.000000e+000,3,4.722340e-001,1.825000e+000,,,,,,,,,,,,,,,,,,0,5.000000e+000,5.000000e-001,2,1,0.000000e+000,0,1,0,
1432775650.838,,2.500000e+002,3.000150e+002,1.457296e-006,0.000000e+000,4.198805e-001,0.000000e+000,3,4.730209e-001,1.825000e+000,,,,,,,,,,,,,,,,,,0,5.000000e+000,5.000000e-001,2,1,2.050781e-002,0,1,0,
1432775672.019,,2.500000e+002,2.999995e+002,1.496892e-006,0.000000e+000,4.078849e-001,0.000000e+000,3,4.845639e-001,1.825000e+000,,,,,,,,,,,,,,,,,,0,5.000000e+000,5.000000e-001,2,1,1.031494e-002,0,1,0,
1432775692.698,,2.500000e+002,3.000150e+002,1.468029e-006,0.000000e+000,4.010456e-001,0.000000e+000,3,4.836684e-001,1.825000e+000,,,,,,,,,,,,,,,,,,0,5.000000e+000,5.000000e-001,2,1,2.050781e-002,0,1,0,
1432775714.129,,2.500000e+002,3.000047e+002,1.484394e-006,0.000000e+000,4.214757e-001,0.000000e+000,3,4.717321e-001,1.825000e+000,,,,,,,,,,,,,,,,,,0,5.000000e+000,5.000000e-001,2,1,0.000000e+000,0,1,0,
1432775734.828,,2.500000e+002,3.000047e+002,1.491710e-006,0.000000e+000,4.118332e-001,0.000000e+000,3,4.899608e-001,1.825000e+000,,,,,,,,,,,,,,,,,,0,5.000000e+000,5.000000e-001,2,1,0.000000e+000,0,1,0,
1432775756.303,,2.500000e+002,3.000047e+002,1.512287e-006,0.000000e+000,4.048921e-001,0.000000e+000,3,4.777572e-001,1.825000e+000,,,,,,,,,,,,,,,,,,0,5.000000e+000,5.000000e-001,2,1,0.000000e+000,0,1,0,
1432775777.517,,2.500000e+002,3.000047e+002,1.516150e-006,0.000000e+000,4.167500e-001,0.000000e+000,3,4.850127e-001,1.825000e+000,,,,,,,,,,,,,,,,,,0,5.000000e+000,5.000000e-001,2,1,0.000000e+000,0,1,0,
1432775798.446,,2.500000e+002,2.999944e+002,1.502555e-006,0.000000e+000,4.240788e-001,0.000000e+000,3,4.816852e-001,1.825000e+000,,,,,,,,,,,,,,,,,,0,5.000000e+000,5.000000e-001,2,1,0.000000e+000,0,1,0,
1432775819.375,,2.500000e+002,2.999996e+002,1.505878e-006,0.000000e+000,4.083067e-001,0.000000e+000,3,4.772415e-001,1.825000e+000,,,,,,,,,,,,,,,,,,0,5.000000e+000,5.000000e-001,2,1,3.082275e-002,0,1,0,
1432775840.305,,2.500000e+002,3.000098e+002,1.494146e-006,0.000000e+000,4.202668e-001,0.000000e+000,3,4.769205e-001,1.825000e+000,,,,,,,,,,,,,,,,,,0,5.000000e+000,5.000000e-001,2,1,3.082275e-002,0,1,0,
1432775860.985,,2.500000e+002,3.000047e+002,1.475544e-006,0.000000e+000,4.129360e-001,0.000000e+000,3,4.816316e-001,1.825000e+000,,,,,,,,,,,,,,,,,,0,5.000000e+000,5.000000e-001,2,1,0.000000e+000,0,1,0,
1432775882.439,,2.500000e+002,3.000047e+002,1.502962e-006,0.000000e+000,4.291243e-001,0.000000e+000,3,4.737511e-001,1.825000e+000,,,,,,,,,,,,,,,,,,0,5.000000e+000,5.000000e-001,2,1,0.000000e+000,0,1,0,
1432775903.674,,2.500000e+002,3.000099e+002,1.491293e-006,0.000000e+000,4.156024e-001,0.000000e+000,3,4.896716e-001,1.825000e+000,,,,,,,,,,,,,,,,,,0,5.000000e+000,5.000000e-001,2,1,1.031494e-002,0,1,0,
1432775924.861,,2.500000e+002,2.999995e+002,1.472555e-006,0.000000e+000,4.098232e-001,0.000000e+000,3,4.729033e-001,1.825000e+000,,,,,,,,,,,,,,,,,,0,5.000000e+000,5.000000e-001,2,1,1.031494e-002,0,1,0,
1432775945.570,,2.500000e+002,3.000047e+002,1.470578e-006,0.000000e+000,4.218468e-001,0.000000e+000,3,4.795704e-001,1.825000e+000,,,,,,,,,,,,,,,,,,0,5.000000e+000,5.000000e-001,2,1,2.062988e-002,0,1,0,
1432775966.998,,2.500000e+002,3.000047e+002,1.477910e-006,0.000000e+000,4.223866e-001,0.000000e+000,3,4.842303e-001,1.825000e+000,,,,,,,,,,,,,,,,,,0,5.000000e+000,5.000000e-001,2,1,0.000000e+000,0,1,0,
1432775987.677,,2.500000e+002,3.000099e+002,1.465036e-006,0.000000e+000,4.140700e-001,0.000000e+000,3,4.800236e-001,1.825000e+000,,,,,,,,,,,,,,,,,,0,5.000000e+000,5.000000e-001,2,1,1.031494e-002,0,1,0,
1432776009.156,,2.500000e+002,3.000047e+002,1.494247e-006,0.000000e+000,4.024553e-001,0.000000e+000,3,4.919218e-001,1.825000e+000,,,,,,,,,,,,,,,,,,0,5.000000e+000,5.000000e-001,2,1,2.062988e-002,0,1,0,
1432776030.341,,2.500000e+002,2.999995e+002,1.518301e-006,0.000000e+000,4.150987e-001,0.000000e+000,3,4.878787e-001,1.825000e+000,,,,,,,,,,,,,,,,,,0,5.000000e+000,5.000000e-001,2,1,1.031494e-002,0,1,0,
1432776051.079,,2.500000e+002,2.999944e+002,1.506172e-006,0.000000e+000,4.028717e-001,0.000000e+000,3,4.698343e-001,1.825000e+000,,,,,,,,,,,,,,,,,,0,5.000000e+000,5.000000e-001,2,1,0.000000e+000,0,1,0,
1432776071.764,,2.500000e+002,3.000047e+002,1.478927e-006,0.000000e+000,4.221455e-001,0.000000e+000,3,4.802563e-001,1.825000e+000,,,,,,,,,,,,,,,,,,0,5.000000e+000,5.000000e-001,2,1,2.062988e-002,0,1,0,
1432776092.692,,2.500000e+002,3.000099e+002,1.459343e-006,0.000000e+000,4.107167e-001,0.000000e+000,3,4.782293e-001,1.825000e+000,,,,,,,,,,,,,,,,,,0,5.000000e+000,5.000000e-001,2,1,1.031494e-002,0,1,0,
1432776113.868,,2.500000e+002,3.000099e+002,1.488265e-006,0.000000e+000,4.057394e-001,0.000000e+000,3,4.808372e-001,1.825000e+000,,,,,,,,,,,,,,,,,,0,5.000000e+000,5.000000e-001,2,1,1.031494e-002,0,1,0,
1432776134.655,,2.500000e+002,2.999995e+002,1.479194e-006,0.000000e+000,4.058934e-001,0.000000e+000,3,4.761159e-001,1.825000e+000,,,,,,,,,,,,,,,,,,0,5.000000e+000,5.000000e-001,2,1,1.031494e-002,0,1,0,
1432776145.409,,2.500000e+002,3.000098e+002,1.524161e-006,0.000000e+000,3.955593e-001,0.000000e+000,3,4.890062e-001,1.825000e+000,,,,,,,,,,,,,,,,,,0,5.000000e+000,5.000000e-001,2,1,3.082275e-002,0,1,0,