File: data/A269/A269_GdN_MH_25K_150528.rso.raw
[Header]
TITLE,MPMS RSO Measurement
BYAPP,MPMS Measurement,2.1,Raw with ABS
FILEOPENTIME, 1432803388.306000 5/28/2015, 8:56:28 PM

INFO, APPNAME, MPMS MultiVu Application, Revision 1.61,  Build 082

INFO, NAME, A269
INFO, WEIGHT, 22.300
INFO, AREA, 1.000
INFO, LENGTH, 1.000
INFO, SHAPE, 1
INFO, COMMENT, m = 0.0223g
INFO, SEQUENCE FILE: 7T_hysteresis_sweep.seq


INFO, BACKGROUND DATA FILE:, None


STARTUPAXIS,X,8,LINEAR,AUTO,0.000000,0.000000
STARTUPAXIS,Y1,9,LINEAR,AUTO,0.000000,0.000000


STARTUPGROUP,Longitudinal
FIELDGROUP,Longitudinal,1,2,3,4,5,6,7,8,9,10,11,12,13,14,15,16,17,18,19,20,21,22
FIELDGROUP,Transverse,1,2,3,4,5,6,7,8,23,24,25,26,27,28,29,30,31,32,33,34,35,36

PLOT_APPEARANCE,ALL,HORZ_GRID_ON,VERT_GRID_ON,MARKERS_ONLY

[Data]
Time,Comment,Field (Oe),Start Temperature (K),End Temperature (K),Scan,Rejected,Position (cm),Long Voltage,Long Average Voltage,Long Detrended Voltage,Long Demeaned Voltage,Long Reg Fit,Long Detrended Fit,Long Demeaned Fit,Long Scaled Response,Long Avg. Scaled Response,Long Background Response,Long Response [w/ABS],Long Detrended Resp. [w/ABS],Long Fit [w/ABS],Long Detrended Fit [w/ABS],Trans Voltage,Trans Average Voltage,Trans Detrended Voltage,Trans Demeaned Voltage,Trans Reg Fit,Trans Detrended Fit,Trans Demeaned Fit,Trans Scaled Response,Trans Avg. Scaled Response,Trans Background Response,Trans Response [w/ABS],Trans Detrended Resp. [w/ABS],Trans Adjusted Fit,Trans Detrended Fit [w/ABS],
1432803388.294,,7.000000e+004,2.498597e+001,2.498846e+001,1,0,2.591319e+000,2.258370e-002,2.258370e-002,3.863379e-003,3.863379e-003,-1.695635e-001,-1.882838e-001,-1.882838e-001,2.829974e-004,2.829974e-004,,,,,,,,,,,,,,,,,,,,
1432803388.294,,7.000000e+004,2.498597e+001,2.498846e+001,1,0,4.317243e+000,7.779168e-001,7.779168e-001,3.757696e-001,7.591965e-001,4.980147e-001,9.586757e-002,4.792944e-001,9.748112e-003,9.748112e-003,,,,,,,,,,,,,,,,,,,,
1432803398.213,,7.000000e+004,2.498928e+001,2.499426e+001,1,0,9.314627e-002,3.160192e-001,3.160192e-001,2.728949e-002,1.955766e-001,4.949464e-001,2.062168e-001,3.745039e-001,3.960051e-003,3.960051e-003,,,,,,,,,,,,,,,,,,,,
1432803398.213,,7.000000e+004,2.498928e+001,2.499426e+001,1,0,3.621369e+000,1.434828e+000,1.434828e+000,7.627773e-001,1.314385e+000,8.933585e-001,2.213081e-001,7.729159e-001,1.797989e-002,1.797989e-002,,,,,,,,,,,,,,,,,,,,
1432803567.758,,6.000000e+004,2.499923e+001,2.500006e+001,1,0,3.308862e+000,9.727775e-001,9.727775e-001,6.293779e-001,9.320099e-001,5.234686e-001,1.800690e-001,4.827009e-001,1.219720e-002,1.219720e-002,,,,,,,,,,,,,,,,,,,,
1432803577.829,,6.000000e+004,2.500089e+001,2.500006e+001,1,0,1.309578e-001,2.211066e-001,2.211066e-001,6.701229e-002,1.766929e-001,3.539809e-001,1.998866e-001,3.095672e-001,2.772353e-003,2.772353e-003,,,,,,,,,,,,,,,,,,,,
1432803577.829,,6.000000e+004,2.500089e+001,2.500006e+001,1,0,4.451795e+000,5.536058e-001,5.536057e-001,5.359555e-002,5.091920e-001,5.718589e-001,7.184871e-002,5.274452e-001,6.941405e-003,6.941405e-003,,,,,,,,,,,,,,,,,,,,
1432803733.307,,5.000000e+004,2.500421e+001,2.500752e+001,1,0,2.189413e+000,-1.951659e-001,-1.951659e-001,-4.785215e-001,-2.406180e-001,-1.018023e-001,-3.851579e-001,-1.472544e-001,-2.448555e-003,-2.448555e-003,,,,,,,,,,,,,,,,,,,,
1432803743.959,,5.000000e+004,2.500918e+001,2.500918e+001,1,0,8.663871e-001,1.264992e-001,1.264992e-001,4.539084e-002,1.072399e-001,1.216036e-001,4.049524e-002,1.023443e-001,1.587062e-003,1.587062e-003,,,,,,,,,,,,,,,,,,,,
1432803743.959,,5.000000e+004,2.500918e+001,2.500918e+001,1,0,4.965860e+000,-8.545182e-002,-8.545183e-002,-4.835367e-001,-1.047111e-001,4.265843e-001,2.849941e-002,4.073250e-001,-1.072081e-003,-1.072081e-003,,,,,,,,,,,,,,,,,,,,
1432803897.033,,4.000000e+004,2.500669e+001,2.500586e+001,1,0,1.199671e+000,5.661183e-002,5.661184e-002,-1.532475e-001,3.306405e-002,8.256651e-002,-1.272928e-001,5.901873e-002,7.106771e-004,7.106771e-004,,,,,,,,,,,,,,,,,,,,
1432803907.055,,4.000000e+004,2.500835e+001,2.500752e+001,1,0,1.914608e+000,-1.338237e-001,-1.338237e-001,-2.130578e-001,-1.916194e-001,-3.354556e-001,-4.146897e-001,-3.932513e-001,-1.679956e-003,-1.679956e-003,,,,,,,,,,,,,,,,,,,,
1432803907.055,,4.000000e+004,2.500835e+001,2.500752e+001,1,0,4.767017e+000,1.486252e-001,1.486251e-001,-2.236006e-001,9.082939e-002,4.084970e-001,3.627133e-002,3.507013e-001,1.865767e-003,1.865767e-003,,,,,,,,,,,,,,,,,,,,
1432804064.641,,3.000000e+004,2.500254e+001,2.500171e+001,1,0,4.104432e-001,1.290933e-001,1.290933e-001,-1.547136e-002,1.162709e-001,3.030862e-001,1.585215e-001,2.902637e-001,1.621540e-003,1.621540e-003,,,,,,,,,,,,,,,,,,,,
1432804064.641,,3.000000e+004,2.500254e+001,2.500171e+001,1,0,3.026992e+000,4.008606e-001,4.008606e-001,-9.150878e-004,3.880382e-001,4.585578e-001,5.678215e-002,4.457354e-001,5.035209e-003,5.035209e-003,,,,,,,,,,,,,,,,,,,,
1432804075.105,,3.000000e+004,2.500337e+001,2.500421e+001,1,0,3.940055e+000,9.076205e-001,9.076205e-001,6.468438e-001,8.930471e-001,3.845736e-001,1.237969e-001,3.700002e-001,1.140062e-002,1.140062e-002,,,,,,,,,,,,,,,,,,,,
1432804231.590,,2.000000e+004,2.500089e+001,2.500337e+001,1,0,7.983513e-003,1.326029e-001,1.326029e-001,2.970498e-002,1.166928e-001,2.277804e-001,1.248825e-001,2.118703e-001,1.666618e-003,1.666618e-003,,,,,,,,,,,,,,,,,,,,
1432804231.590,,2.000000e+004,2.500089e+001,2.500337e+001,1,0,3.975114e+000,7.644887e-001,7.644886e-001,4.386845e-001,7.485785e-001,4.305744e-001,1.047702e-001,4.146642e-001,9.608463e-003,9.608463e-003,,,,,,,,,,,,,,,,,,,,
1432804241.805,,2.000000e+004,2.500337e+001,2.500503e+001,1,0,2.861084e+000,2.223274e-001,2.223273e-001,3.282560e-002,2.196723e-001,1.800672e-001,-9.434529e-003,1.774122e-001,2.794317e-003,2.794317e-003,,,,,,,,,,,,,,,,,,,,
1432804395.872,,1.000000e+004,2.500006e+001,2.500171e+001,1,0,3.637364e-001,4.898221e-002,4.898221e-002,4.061917e-002,8.928003e-002,1.288291e-001,1.204661e-001,1.691270e-001,6.159988e-004,6.159988e-004,,,,,,,,,,,,,,,,,,,,
1432804395.872,,1.000000e+004,2.500006e+001,2.500171e+001,1,0,4.717576e+000,3.021332e-002,3.021332e-002,-1.595220e-001,7.051115e-002,2.162208e-001,2.648541e-002,2.565186e-001,3.799619e-004,3.799619e-004,,,,,,,,,,,,,,,,,,,,
1432804406.088,,1.000000e+004,2.500171e+001,2.500421e+001,1,0,1.767876e+000,-1.142918e-001,-1.142918e-001,-2.493094e-001,-1.202648e-001,-1.315620e-001,-2.665796e-001,-1.375350e-001,-1.437331e-003,-1.437331e-003,,,,,,,,,,,,,,,,,,,,
1432804521.765,,9.000000e+003,2.499923e+001,2.499923e+001,1,0,1.264543e+000,-1.266518e-002,-1.266518e-002,-1.085039e-002,1.583304e-002,-1.085310e-001,-1.067162e-001,-8.003274e-002,-1.592864e-004,-1.592864e-004,,,,,,,,,,,,,,,,,,,,
1432804521.765,,9.000000e+003,2.499923e+001,2.499923e+001,1,0,4.985439e+000,-1.097140e-001,-1.097140e-001,-2.902359e-001,-8.121582e-002,1.972376e-001,1.671569e-002,2.257358e-001,-1.379843e-003,-1.379843e-003,,,,,,,,,,,,,,,,,,,,
1432804531.789,,9.000000e+003,2.499923e+001,2.499840e+001,1,0,8.603188e-001,4.440443e-002,4.440443e-002,-5.186387e-002,5.652679e-002,1.221191e-001,2.585082e-002,1.342415e-001,5.584621e-004,5.584621e-004,,,,,,,,,,,,,,,,,,,,
1432804651.873,,7.000000e+003,2.500006e+001,2.500006e+001,1,0,2.366924e+000,-7.721183e-002,-7.721183e-002,-9.616110e-002,-9.202176e-002,-1.487415e-001,-1.676908e-001,-1.635514e-001,-9.711870e-004,-9.711870e-004,,,,,,,,,,,,,,,,,,,,
1432804651.873,,7.000000e+003,2.500006e+001,2.500006e+001,1,0,4.486836e+000,2.487258e-001,2.487258e-001,6.006368e-002,2.339159e-001,2.245739e-001,3.591175e-002,2.097640e-001,3.128527e-003,3.128527e-003,,,,,,,,,,,,,,,,,,,,
1432804662.088,,7.000000e+003,2.500006e+001,2.500089e+001,1,0,1.762337e-001,6.515702e-002,6.515702e-002,4.948613e-003,8.538912e-002,1.696073e-001,1.093989e-001,1.898394e-001,8.195590e-004,8.195590e-004,,,,,,,,,,,,,,,,,,,,
1432804662.088,,7.000000e+003,2.500006e+001,2.500089e+001,1,0,3.431829e+000,5.346843e-001,5.346843e-001,3.008938e-001,5.549164e-001,3.425204e-001,1.087298e-001,3.627525e-001,6.725374e-003,6.725374e-003,,,,,,,,,,,,,,,,,,,,
1432804781.772,,5.000000e+003,2.499757e+001,2.499923e+001,1,0,3.525764e+000,5.507065e-001,5.507065e-001,4.238708e-001,5.675516e-001,2.301407e-001,1.033049e-001,2.469858e-001,6.927731e-003,6.927731e-003,,,,,,,,,,,,,,,,,,,,
1432804791.797,,5.000000e+003,2.499923e+001,2.500171e+001,1,0,5.750715e-002,1.065096e-001,1.065096e-001,2.840503e-002,8.298556e-002,1.709358e-001,9.283128e-002,1.474118e-001,1.339860e-003,1.339860e-003,,,,,,,,,,,,,,,,,,,,
1432804791.797,,5.000000e+003,2.499923e+001,2.500171e+001,1,0,4.300146e+000,3.581347e-001,3.581347e-001,1.201872e-001,3.346107e-001,2.832206e-001,4.527304e-002,2.596965e-001,4.505232e-003,4.505232e-003,,,,,,,,,,,,,,,,,,,,
1432804911.183,,3.000000e+003,2.499923e+001,2.500006e+001,1,0,2.410194e+000,1.129185e-002,1.129185e-002,-1.764254e-001,-5.434705e-002,6.478421e-002,-1.229330e-001,-8.546859e-004,1.420651e-004,1.420651e-004,,,,,,,,,,,,,,,,,,,,
1432804921.397,,3.000000e+003,2.500006e+001,2.500089e+001,1,0,6.837747e-001,1.077303e-001,1.077303e-001,2.674391e-002,5.944878e-002,1.354599e-001,5.447347e-002,8.717835e-002,1.355378e-003,1.355378e-003,,,,,,,,,,,,,,,,,,,,
1432804921.397,,3.000000e+003,2.500006e+001,2.500089e+001,1,0,4.910079e+000,2.410962e-002,2.410962e-002,-2.058657e-001,-2.417193e-002,2.441868e-001,1.421154e-002,1.959053e-001,3.033282e-004,3.033282e-004,,,,,,,,,,,,,,,,,,,,
1432805048.960,,1.000000e+003,2.500089e+001,2.500171e+001,1,0,1.379631e+000,-1.384014e-001,-1.384014e-001,-3.530734e-001,-4.760291e-002,-1.619057e-001,-3.765777e-001,-7.110716e-002,-3.482930e-004,-3.482930e-004,,,,,,,,,,,,,,,,,,,,
1432805058.925,,1.000000e+003,2.500171e+001,2.500337e+001,1,0,1.693376e+000,-3.080843e-001,-3.080843e-001,-2.410818e-001,-1.964794e-001,-6.949651e-001,-6.279625e-001,-5.833601e-001,-7.753072e-004,-7.753072e-004,,,,,,,,,,,,,,,,,,,,
1432805058.925,,1.000000e+003,2.500171e+001,2.500337e+001,1,0,4.870521e+000,-1.750236e-001,-1.750236e-001,-5.651961e-001,-6.341870e-002,4.417853e-001,5.161285e-002,5.533903e-001,-4.404543e-004,-4.404543e-004,,,,,,,,,,,,,,,,,,,,
1432805174.900,,5.000000e+002,2.500337e+001,2.500421e+001,1,0,5.500126e-001,8.865627e-002,8.865627e-002,-4.486955e-002,1.284243e-001,3.227362e-001,1.892104e-001,3.625043e-001,2.231138e-004,2.231138e-004,,,,,,,,,,,,,,,,,,,,
1432805174.900,,5.000000e+002,2.500337e+001,2.500421e+001,1,0,2.812499e+000,1.339763e-001,1.339763e-001,-3.225063e-001,1.737443e-001,4.102260e-001,-4.625653e-002,4.499941e-001,3.371669e-004,3.371669e-004,,,,,,,,,,,,,,,,,,,,
1432805185.065,,5.000000e+002,2.500421e+001,2.500586e+001,1,0,4.134713e+000,9.379864e-001,9.379864e-001,6.670673e-001,9.920437e-001,4.018945e-001,1.309755e-001,4.559518e-001,2.360552e-003,2.360552e-003,,,,,,,,,,,,,,,,,,,,
1432805288.350,,4.000000e+002,2.500421e+001,2.500503e+001,1,0,3.461671e-002,-1.220740e-003,-1.220740e-003,3.008213e-002,1.536544e-001,1.511535e-001,1.824564e-001,3.060287e-001,-3.072154e-006,-3.072154e-006,,,,,,,,,,,,,,,,,,,,
1432805288.350,,4.000000e+002,2.500421e+001,2.500503e+001,1,0,3.801678e+000,1.008484e+000,1.008484e+000,7.417598e-001,1.163359e+000,4.493583e-001,1.826340e-001,6.042335e-001,2.537983e-003,2.537983e-003,,,,,,,,,,,,,,,,,,,,
1432805298.375,,4.000000e+002,2.500586e+001,2.500835e+001,1,0,3.085865e+000,5.262917e-001,5.262917e-001,3.407178e-001,6.071939e-001,2.832561e-001,9.768213e-002,3.641583e-001,1.324482e-003,1.324482e-003,,,,,,,,,,,,,,,,,,,,
1432805402.660,,3.000000e+002,2.500503e+001,2.500752e+001,1,0,2.340444e-001,1.103244e-001,1.103244e-001,5.837537e-002,1.431950e-001,2.346671e-001,1.827181e-001,2.675377e-001,2.776475e-004,2.776475e-004,,,,,,,,,,,,,,,,,,,,
1432805402.660,,3.000000e+002,2.500503e+001,2.500752e+001,1,0,4.588872e+000,2.345347e-001,2.345347e-001,-1.072148e-001,2.674054e-001,3.913314e-001,4.958182e-002,4.242020e-001,5.902410e-004,5.902410e-004,,,,,,,,,,,,,,,,,,,,
1432805412.683,,3.000000e+002,2.500752e+001,2.500835e+001,1,0,1.975092e+000,-2.578814e-001,-2.578814e-001,-4.431334e-001,-2.356069e-001,-2.322712e-001,-4.175232e-001,-2.099967e-001,-6.489963e-004,-6.489963e-004,,,,,,,,,,,,,,,,,,,,
1432805516.216,,2.000000e+002,2.500254e+001,2.500337e+001,1,0,1.061281e+000,-2.029481e-002,-2.029481e-002,1.967025e-002,6.098355e-002,-8.717379e-002,-4.720873e-002,-5.895436e-003,-5.107516e-005,-5.107516e-005,,,,,,,,,,,,,,,,,,,,
1432805516.216,,2.000000e+002,2.500254e+001,2.500337e+001,1,0,4.992880e+000,-1.928770e-001,-1.928770e-001,-3.948898e-001,-1.115986e-001,2.236879e-001,2.167507e-002,3.049662e-001,-4.854061e-004,-4.854061e-004,,,,,,,,,,,,,,,,,,,,
1432805526.288,,2.000000e+002,2.500503e+001,2.500586e+001,1,0,1.026667e+000,4.074221e-002,4.074221e-002,-9.506533e-002,5.264296e-002,1.035754e-001,-3.223216e-002,1.154761e-001,1.025344e-004,1.025344e-004,,,,,,,,,,,,,,,,,,,,
1432805630.745,,1.000000e+002,2.500006e+001,2.500254e+001,1,0,2.140056e+000,-1.802118e-001,-1.802118e-001,-1.559018e-001,-1.472205e-001,-2.776920e-001,-2.533820e-001,-2.447007e-001,-4.535348e-004,-4.535348e-004,,,,,,,,,,,,,,,,,,,,
1432805630.745,,1.000000e+002,2.500006e+001,2.500254e+001,1,0,4.637450e+000,9.857479e-002,9.857479e-002,-5.508234e-002,1.315660e-001,1.842350e-001,3.057790e-002,2.172263e-001,2.480808e-004,2.480808e-004,,,,,,,,,,,,,,,,,,,,
1432805640.520,,1.000000e+002,2.500254e+001,2.500421e+001,1,0,2.864778e-001,6.790368e-002,6.790368e-002,-4.113231e-003,8.673547e-002,1.945785e-001,1.225616e-001,2.134103e-001,1.708916e-004,1.708916e-004,,,,,,,,,,,,,,,,,,,,
1432805640.520,,1.000000e+002,2.500254e+001,2.500421e+001,1,0,3.233546e+000,4.338206e-001,4.338206e-001,1.755639e-001,4.526524e-001,3.501263e-001,9.186958e-002,3.689581e-001,1.091786e-003,1.091786e-003,,,,,,,,,,,,,,,,,,,,
1432805744.623,,0.000000e+000,2.499923e+001,2.500337e+001,1,0,3.736364e+000,5.267495e-001,5.267495e-001,3.662035e-001,4.713975e-001,2.367300e-001,7.618392e-002,1.813779e-001,1.325666e-003,1.325666e-003,,,,,,,,,,,,,,,,,,,,
1432805754.838,,0.000000e+000,2.500337e+001,2.500669e+001,1,0,1.696506e-002,8.957183e-002,8.957183e-002,1.933758e-002,6.615056e-002,1.408270e-001,7.059278e-002,1.174058e-001,2.254247e-004,2.254247e-004,,,,,,,,,,,,,,,,,,,,
1432805754.838,,0.000000e+000,2.500337e+001,2.500669e+001,1,0,4.140985e+000,3.741569e-001,3.741569e-001,1.759672e-001,3.507357e-001,2.443942e-001,4.620446e-002,2.209729e-001,9.416376e-004,9.416376e-004,,,,,,,,,,,,,,,,,,,,
1432805862.030,,-1.000000e+002,2.500421e+001,2.500669e+001,1,0,2.635153e+000,2.577288e-001,2.577288e-001,-1.794534e-001,-2.482888e-002,3.165750e-001,-1.206071e-001,3.401732e-002,1.297240e-004,1.297240e-004,,,,,,,,,,,,,,,,,,,,
1432805872.299,,-1.000000e+002,2.500669e+001,2.500752e+001,1,0,5.144053e-001,1.205481e-002,1.205481e-002,5.464801e-002,1.089688e-001,1.028770e-001,1.454702e-001,1.997911e-001,6.067612e-006,6.067612e-006,,,,,,,,,,,,,,,,,,,,
1432805872.299,,-1.000000e+002,2.500669e+001,2.500752e+001,1,0,4.825022e+000,-1.338237e-001,-1.338237e-001,-3.139459e-001,-3.690962e-002,2.105036e-001,3.038139e-002,3.074177e-001,-6.735817e-005,-6.735817e-005,,,,,,,,,,,,,,,,,,,,
1432805975.981,,-2.000000e+002,2.500337e+001,2.500337e+001,1,0,1.570236e+000,-4.094058e-001,-4.094058e-001,1.823176e-001,-3.588271e-002,-3.786434e-001,2.130800e-001,-5.120337e-003,-2.060672e-004,-2.060672e-004,,,,,,,,,,,,,,,,,,,,
1432805985.755,,-2.000000e+002,2.500337e+001,2.500503e+001,1,0,1.475315e+000,1.635792e-001,1.635792e-001,4.083128e-002,-5.922914e-004,3.051217e-001,1.823737e-001,1.409502e-001,8.233470e-005,8.233470e-005,,,,,,,,,,,,,,,,,,,,
1432805985.755,,-2.000000e+002,2.500337e+001,2.500503e+001,1,0,4.943453e+000,5.966369e-002,5.966369e-002,2.765890e-001,-1.045078e-001,-2.351750e-001,-1.824974e-002,-3.993465e-001,3.003066e-005,3.003066e-005,,,,,,,,,,,,,,,,,,,,
1432806090.087,,-3.000000e+002,2.499674e+001,2.499840e+001,1,0,7.012932e-001,-8.818323e-001,-8.818323e-001,1.115781e-001,-3.970836e-001,-1.230943e+000,-2.375331e-001,-7.461948e-001,-4.438520e-004,-4.438520e-004,,,,,,,,,,,,,,,,,,,,
1432806100.094,,-3.000000e+002,2.499840e+001,2.500006e+001,1,0,2.591210e+000,-6.839198e-001,-6.839198e-001,-2.226669e-002,-2.226669e-002,-3.180365e-001,3.436166e-001,3.436166e-001,-3.442368e-004,-3.442368e-004,,,,,,,,,,,,,,,,,,,,
1432806100.094,,-3.000000e+002,2.499840e+001,2.500006e+001,1,0,4.317386e+000,-2.268441e+000,-2.268441e+000,-6.909500e-001,-1.606788e+000,-1.752986e+000,-1.754953e-001,-1.091333e+000,-1.141773e-003,-1.141773e-003,,,,,,,,,,,,,,,,,,,,
1432806222.090,,-4.000000e+002,2.500337e+001,2.500171e+001,1,0,9.166785e-002,-4.124576e-001,-4.124576e-001,-2.638523e-002,-2.553822e-001,-6.303071e-001,-2.442347e-001,-4.732316e-001,-5.190020e-004,-5.190020e-004,,,,,,,,,,,,,,,,,,,,
1432806222.090,,-4.000000e+002,2.500337e+001,2.500171e+001,1,0,3.621380e+000,-1.825465e+000,-1.825465e+000,-9.177880e-001,-1.668389e+000,-1.169362e+000,-2.616858e-001,-1.012287e+000,-2.297011e-003,-2.297011e-003,,,,,,,,,,,,,,,,,,,,
1432806232.307,,-4.000000e+002,2.500171e+001,2.500171e+001,1,0,3.308790e+000,-7.083346e-001,-7.083346e-001,-8.064487e-001,-9.780303e-001,-1.294435e-001,-2.275576e-001,-3.991392e-001,-8.913086e-004,-8.913086e-004,,,,,,,,,,,,,,,,,,,,
1432806336.984,,-5.000000e+002,2.499757e+001,2.499840e+001,1,0,1.310704e-001,-3.549303e-001,-3.549303e-001,-1.017571e-001,-3.047660e-001,-5.802320e-001,-3.270589e-001,-5.300677e-001,-4.466117e-004,-4.466117e-004,,,,,,,,,,,,,,,,,,,,
1432806336.984,,-5.000000e+002,2.499757e+001,2.499840e+001,1,0,4.450982e+000,-9.772027e-001,-9.772027e-001,-8.377074e-002,-9.270384e-001,-1.010946e+000,-1.175139e-001,-9.607815e-001,-1.229622e-003,-1.229622e-003,,,,,,,,,,,,,,,,,,,,
1432806347.055,,-5.000000e+002,2.499923e+001,2.500006e+001,1,0,2.189703e+000,2.674947e-001,2.674947e-001,8.457426e-001,3.552631e-001,9.888720e-002,6.771350e-001,1.866555e-001,3.365909e-004,3.365909e-004,,,,,,,,,,,,,,,,,,,,
1432806466.993,,-1.000000e+003,2.500006e+001,2.500006e+001,1,0,8.667184e-001,-3.643910e-001,-3.643910e-001,-6.875279e-002,-1.765673e-001,-3.559754e-001,-6.033715e-002,-1.681516e-001,-9.170052e-004,-9.170052e-004,,,,,,,,,,,,,,,,,,,,
1432806466.993,,-1.000000e+003,2.500006e+001,2.500006e+001,1,0,4.967620e+000,-1.191748e-001,-1.191748e-001,7.290126e-001,6.864896e-002,-8.904116e-001,-4.222425e-002,-7.025878e-001,-2.999083e-004,-2.999083e-004,,,,,,,,,,,,,,,,,,,,
1432806477.158,,-1.000000e+003,2.500254e+001,2.500254e+001,1,0,1.199350e+000,-3.257851e-001,-3.257851e-001,2.457546e-001,-9.905683e-002,-3.680720e-001,2.034676e-001,-1.413438e-001,-8.198518e-004,-8.198518e-004,,,,,,,,,,,,,,,,,,,,
1432806596.451,,-3.000000e+003,2.499094e+001,2.499674e+001,1,0,1.915496e+000,3.282266e-001,3.282266e-001,5.239115e-001,4.640431e-001,8.322569e-001,1.027942e+000,9.680735e-001,8.258975e-004,8.258975e-004,,,,,,,,,,,,,,,,,,,,
1432806596.451,,-3.000000e+003,2.499094e+001,2.499674e+001,1,0,4.767183e+000,-4.533525e-001,-4.533525e-001,5.605332e-001,-3.175359e-001,-1.103907e+000,-9.002127e-002,-9.680903e-001,-1.140745e-003,-1.140745e-003,,,,,,,,,,,,,,,,,,,,
1432806606.475,,-3.000000e+003,2.499674e+001,2.500171e+001,1,0,4.096237e-001,-6.279184e-001,-6.279183e-001,4.740778e-002,-3.720088e-001,-1.108841e+000,-4.335145e-001,-8.529311e-001,-1.579995e-003,-1.579995e-003,,,,,,,,,,,,,,,,,,,,
1432806606.475,,-3.000000e+003,2.499674e+001,2.500171e+001,1,0,3.026233e+000,-1.483810e+000,-1.483810e+000,1.037708e-002,-1.227901e+000,-1.646731e+000,-1.525445e-001,-1.390822e+000,-3.733625e-003,-3.733625e-003,,,,,,,,,,,,,,,,,,,,
1432806726.009,,-5.000000e+003,2.500254e+001,2.500337e+001,1,0,3.940131e+000,-3.165990e+000,-3.165990e+000,-2.051386e+000,-2.950741e+000,-1.504837e+000,-3.902332e-001,-1.289588e+000,-7.965450e-003,-7.965450e-003,,,,,,,,,,,,,,,,,,,,
1432806736.332,,-5.000000e+003,2.500503e+001,2.500503e+001,1,0,7.893632e-003,-7.977539e-001,-7.977538e-001,-1.036439e-001,-4.728291e-001,-1.137339e+000,-4.432293e-001,-8.124145e-001,-2.007103e-003,-2.007103e-003,,,,,,,,,,,,,,,,,,,,
1432806736.332,,-5.000000e+003,2.500503e+001,2.500503e+001,1,0,3.975472e+000,-3.207190e+000,-3.207190e+000,-1.567043e+000,-2.882266e+000,-2.013073e+000,-3.729258e-001,-1.688148e+000,-8.069107e-003,-8.069107e-003,,,,,,,,,,,,,,,,,,,,
1432806857.425,,-7.000000e+003,2.500503e+001,2.500669e+001,1,0,2.861971e+000,-1.319468e+000,-1.319468e+000,-1.271489e-001,-9.896370e-001,-1.153954e+000,3.836496e-002,-8.241231e-001,-3.319310e-003,-3.319310e-003,,,,,,,,,,,,,,,,,,,,
1432806868.076,,-7.000000e+003,2.500752e+001,2.500752e+001,1,0,3.630350e-001,-7.936338e-001,-7.936338e-001,-1.883544e-001,-4.672150e-001,-1.160374e+000,-5.550950e-001,-8.339556e-001,-1.996499e-003,-1.996499e-003,,,,,,,,,,,,,,,,,,,,
1432806868.076,,-7.000000e+003,2.500752e+001,2.500752e+001,1,0,4.715744e+000,-9.221168e-001,-9.221168e-001,7.225521e-001,-5.956980e-001,-1.767297e+000,-1.226282e-001,-1.440878e+000,-2.319717e-003,-2.319717e-003,,,,,,,,,,,,,,,,,,,,
1432806991.938,,-9.000000e+003,2.500254e+001,2.500503e+001,1,0,1.768136e+000,1.348918e-001,1.348918e-001,6.079997e-001,2.210727e-001,1.778235e-001,6.509313e-001,2.640044e-001,6.785985e-004,6.785985e-004,,,,,,,,,,,,,,,,,,,,
1432807002.137,,-9.000000e+003,2.500586e+001,2.500669e+001,1,0,1.264850e+000,-2.226325e-001,-2.226325e-001,2.701009e-002,-5.231392e-002,1.636793e-002,2.660106e-001,1.866865e-001,-1.119995e-003,-1.119995e-003,,,,,,,,,,,,,,,,,,,,
1432807002.137,,-9.000000e+003,2.500586e+001,2.500669e+001,1,0,4.985423e+000,-6.515702e-002,-6.515702e-002,7.265330e-001,1.051616e-001,-8.336036e-001,-4.191352e-002,-6.632850e-001,-3.277846e-004,-3.277846e-004,,,,,,,,,,,,,,,,,,,,
1432807118.710,,-1.000000e+004,2.500171e+001,2.500337e+001,1,0,8.609724e-001,-2.851955e-001,-2.851955e-001,1.328275e-001,-1.953463e-001,-4.847449e-001,-6.672195e-002,-3.948957e-001,-1.434644e-003,-1.434644e-003,,,,,,,,,,,,,,,,,,,,
1432807128.730,,-1.000000e+004,2.500337e+001,2.500503e+001,1,0,2.366931e+000,6.439406e-002,6.439406e-002,2.627198e-001,2.491429e-001,2.591818e-001,4.575076e-001,4.439307e-001,3.239271e-004,3.239271e-004,,,,,,,,,,,,,,,,,,,,
1432807128.730,,-1.000000e+004,2.500337e+001,2.500503e+001,1,0,4.486928e+000,-9.189123e-001,-9.189123e-001,-1.639345e-001,-7.341634e-001,-8.529258e-001,-9.794801e-002,-6.681770e-001,-4.622485e-003,-4.622485e-003,,,,,,,,,,,,,,,,,,,,
1432807283.722,,-2.000000e+004,2.500254e+001,2.500421e+001,1,0,1.743846e-001,-5.912961e-001,-5.912961e-001,-1.715274e-002,-3.383720e-001,-9.282597e-001,-3.541163e-001,-6.753355e-001,-2.972678e-003,-2.972678e-003,,,,,,,,,,,,,,,,,,,,
1432807283.722,,-2.000000e+004,2.500254e+001,2.500421e+001,1,0,3.432178e+000,-2.242958e+000,-2.242958e+000,-9.756571e-001,-1.990034e+000,-1.619597e+000,-3.522961e-001,-1.366673e+000,-1.127623e-002,-1.127623e-002,,,,,,,,,,,,,,,,,,,,
1432807294.382,,-2.000000e+004,2.500421e+001,2.500421e+001,1,0,3.525355e+000,-2.402570e+000,-2.402570e+000,-1.485733e+000,-2.106690e+000,-1.281021e+000,-3.641838e-001,-9.851416e-001,-1.207866e-002,-1.207866e-002,,,,,,,,,,,,,,,,,,,,
1432807445.698,,-3.000000e+004,2.500171e+001,2.500503e+001,1,0,5.701895e-002,-6.161687e-001,-6.161687e-001,-1.155116e-001,-3.825070e-001,-8.695902e-001,-3.689331e-001,-6.359285e-001,-3.095877e-003,-3.095877e-003,,,,,,,,,,,,,,,,,,,,
1432807445.698,,-3.000000e+004,2.500171e+001,2.500503e+001,1,0,4.300606e+000,-1.762291e+000,-1.762291e+000,-4.797192e-001,-1.528630e+000,-1.463245e+000,-1.806727e-001,-1.229583e+000,-8.854454e-003,-8.854454e-003,,,,,,,,,,,,,,,,,,,,
1432807456.161,,-3.000000e+004,2.500421e+001,2.500669e+001,1,0,2.410345e+000,-1.263466e-001,-1.263466e-001,8.065292e-001,2.037222e-001,-3.670278e-001,5.658480e-001,-3.695893e-002,-6.348158e-004,-6.348158e-004,,,,,,,,,,,,,,,,,,,,
1432807615.109,,-4.000000e+004,2.500171e+001,2.500337e+001,1,0,6.838434e-001,-6.401258e-001,-6.401258e-001,-1.396812e-001,-2.871416e-001,-8.104972e-001,-3.100526e-001,-4.575130e-001,-3.214329e-003,-3.214329e-003,,,,,,,,,,,,,,,,,,,,
1432807615.109,,-4.000000e+004,2.500171e+001,2.500337e+001,1,0,4.910940e+000,-1.519822e-001,-1.519822e-001,1.020227e+000,2.010020e-001,-1.250496e+000,-7.828758e-002,-8.975123e-001,-7.631638e-004,-7.631638e-004,,,,,,,,,,,,,,,,,,,,
1432807625.571,,-4.000000e+004,2.500337e+001,2.500421e+001,1,0,1.380104e+000,-2.597125e-001,-2.597125e-001,5.246373e-001,-2.843887e-002,-2.264463e-001,5.579036e-001,4.827380e-003,-1.304121e-003,-1.304121e-003,,,,,,,,,,,,,,,,,,,,
1432807786.289,,-5.000000e+004,2.499923e+001,2.500171e+001,1,0,1.693186e+000,1.739555e-002,1.739555e-002,3.960097e-001,3.080410e-001,6.303666e-001,1.008981e+000,9.210121e-001,8.729799e-005,8.729799e-005,,,,,,,,,,,,,,,,,,,,
1432807786.289,,-5.000000e+004,2.499923e+001,2.500171e+001,1,0,4.870539e+000,-3.891110e-001,-3.891110e-001,8.911815e-001,-9.846550e-002,-1.363832e+000,-8.353949e-002,-1.073187e+000,-1.952718e-003,-1.952718e-003,,,,,,,,,,,,,,,,,,,,
1432807796.502,,-5.000000e+004,2.500171e+001,2.500337e+001,1,0,5.496021e-001,-6.669821e-001,-6.669820e-001,8.952701e-002,-3.923038e-001,-1.165058e+000,-4.085490e-001,-8.903798e-001,-3.347189e-003,-3.347189e-003,,,,,,,,,,,,,,,,,,,,
1432807796.502,,-5.000000e+004,2.500171e+001,2.500337e+001,1,0,2.811979e+000,-9.639271e-001,-9.639271e-001,6.905392e-001,-6.892489e-001,-1.551418e+000,1.030479e-001,-1.276740e+000,-4.837381e-003,-4.837381e-003,,,,,,,,,,,,,,,,,,,,
1432807958.965,,-6.000000e+004,2.499923e+001,2.500171e+001,1,0,4.134872e+000,-2.507096e+000,-2.507096e+000,-1.518757e+000,-2.331125e+000,-1.291119e+000,-3.027804e-001,-1.115148e+000,-1.257412e-002,-1.257412e-002,,,,,,,,,,,,,,,,,,,,
1432807969.205,,-6.000000e+004,2.500089e+001,2.500254e+001,1,0,3.580590e-002,-8.764915e-001,-8.764916e-001,-9.039509e-002,-5.195177e-001,-1.248542e+000,-4.624456e-001,-8.915682e-001,-4.395968e-003,-4.395968e-003,,,,,,,,,,,,,,,,,,,,
1432807969.205,,-6.000000e+004,2.500089e+001,2.500254e+001,1,0,3.802540e+000,-3.674428e+000,-3.674428e+000,-1.853389e+000,-3.317455e+000,-2.284433e+000,-4.633941e-001,-1.927459e+000,-1.842878e-002,-1.842878e-002,,,,,,,,,,,,,,,,,,,,
1432808127.655,,-7.000000e+004,2.500006e+001,2.499757e+001,1,0,3.085682e+000,-1.899625e+000,-1.899625e+000,-8.881570e-001,-1.723617e+000,-1.271868e+000,-2.603999e-001,-1.095860e+000,-9.521714e-003,-9.521714e-003,,,,,,,,,,,,,,,,,,,,
1432808137.726,,-7.000000e+004,2.500171e+001,2.500089e+001,1,0,2.341230e-001,-6.549272e-001,-6.549272e-001,-1.884999e-001,-4.753024e-001,-1.021641e+000,-5.552140e-001,-8.420165e-001,-3.282770e-003,-3.282770e-003,,,,,,,,,,,,,,,,,,,,
1432808137.726,,-7.000000e+004,2.500171e+001,2.500089e+001,1,0,4.591346e+000,-1.137120e+000,-1.137120e+000,3.092160e-001,-9.574949e-001,-1.597281e+000,-1.509449e-001,-1.417656e+000,-5.699720e-003,-5.699720e-003,,,,,,,,,,,,,,,,,,,,
1432808301.218,,-6.000000e+004,2.500337e+001,2.500421e+001,1,0,1.975088e+000,5.114902e-001,5.114902e-001,1.264286e+000,6.355368e-001,4.432668e-001,1.196062e+000,5.673134e-001,2.565335e-003,2.565335e-003,,,,,,,,,,,,,,,,,,,,
1432808311.242,,-6.000000e+004,2.500421e+001,2.500752e+001,1,0,1.061690e+000,-3.115940e-001,-3.115940e-001,-5.296373e-002,-2.001457e-001,-9.844059e-002,1.601897e-001,1.300770e-002,-1.562773e-003,-1.562773e-003,,,,,,,,,,,,,,,,,,,,
1432808311.242,,-6.000000e+004,2.500421e+001,2.500752e+001,1,0,4.992504e+000,1.884518e-001,1.884518e-001,1.309148e+000,2.999001e-001,-1.193863e+000,-7.316696e-002,-1.082415e+000,9.451637e-004,9.451637e-004,,,,,,,,,,,,,,,,,,,,
1432808465.722,,-5.000000e+004,2.500254e+001,2.500171e+001,1,0,1.027310e+000,-2.203436e-001,-2.203436e-001,2.985579e-001,-1.853335e-001,-4.136295e-001,1.052720e-001,-3.786194e-001,-1.105775e-003,-1.105775e-003,,,,,,,,,,,,,,,,,,,,
1432808475.937,,-5.000000e+004,2.500171e+001,2.500337e+001,1,0,2.140896e+000,4.716636e-001,4.716636e-001,6.262586e-001,5.872401e-001,8.575331e-001,1.012128e+000,9.731097e-001,2.367001e-003,2.367001e-003,,,,,,,,,,,,,,,,,,,,
1432808475.937,,-5.000000e+004,2.500171e+001,2.500337e+001,1,0,4.637664e+000,-7.374798e-001,-7.374798e-001,2.169928e-001,-6.219032e-001,-1.076468e+000,-1.219954e-001,-9.608914e-001,-3.700975e-003,-3.700975e-003,,,,,,,,,,,,,,,,,,,,
1432808635.653,,-4.000000e+004,2.500254e+001,2.500006e+001,1,0,2.857299e-001,-3.849910e-001,-3.849910e-001,5.349226e-003,-3.450418e-001,-8.443289e-001,-4.539887e-001,-8.043797e-001,-1.933195e-003,-1.933195e-003,,,,,,,,,,,,,,,,,,,,
1432808635.653,,-4.000000e+004,2.500254e+001,2.500006e+001,1,0,3.234156e+000,-1.751762e+000,-1.751762e+000,-6.431206e-001,-1.711813e+000,-1.450158e+000,-3.415167e-001,-1.410209e+000,-8.796305e-003,-8.796305e-003,,,,,,,,,,,,,,,,,,,,
1432808645.678,,-4.000000e+004,2.500337e+001,2.500337e+001,1,0,3.736936e+000,-2.615741e+000,-2.615741e+000,-1.997820e+000,-2.667158e+000,-1.038054e+000,-4.201328e-001,-1.089471e+000,-1.313469e-002,-1.313469e-002,,,,,,,,,,,,,,,,,,,,
1432808802.965,,-3.000000e+004,2.500089e+001,2.500171e+001,1,0,1.574590e-002,-2.336192e-001,-2.336192e-001,-1.019418e-001,-3.375216e-001,-4.871662e-001,-3.554888e-001,-5.910686e-001,-1.173796e-003,-1.173796e-003,,,,,,,,,,,,,,,,,,,,
1432808802.965,,-3.000000e+004,2.500089e+001,2.500171e+001,1,0,4.140526e+000,-1.652119e+000,-1.652120e+000,-8.765242e-001,-1.756022e+000,-1.007832e+000,-2.322364e-001,-1.111734e+000,-8.300907e-003,-8.300907e-003,,,,,,,,,,,,,,,,,,,,
1432808813.240,,-3.000000e+004,2.500421e+001,2.500337e+001,1,0,2.635487e+000,-7.461776e-002,-7.461776e-002,4.158147e-001,-1.047067e-001,-2.041999e-001,2.862325e-001,-2.342888e-001,-3.749093e-004,-3.749093e-004,,,,,,,,,,,,,,,,,,,,
1432808969.332,,-2.000000e+004,2.500089e+001,2.500337e+001,1,0,5.148861e-001,-2.085940e-001,-2.085940e-001,-1.194736e-001,-2.556898e-001,-4.052426e-001,-3.161221e-001,-4.523384e-001,-1.048684e-003,-1.048684e-003,,,,,,,,,,,,,,,,,,,,
1432808969.332,,-2.000000e+004,2.500089e+001,2.500337e+001,1,0,4.825548e+000,4.272591e-002,4.272591e-002,6.903331e-001,-4.369907e-003,-7.136330e-001,-6.602588e-002,-7.607288e-001,2.148000e-004,2.148000e-004,,,,,,,,,,,,,,,,,,,,
1432808979.547,,-2.000000e+004,2.500337e+001,2.500503e+001,1,0,1.570323e+000,2.191229e-001,2.191229e-001,5.747444e-001,1.920367e-001,2.935707e-001,6.491922e-001,2.664845e-001,1.101617e-003,1.101617e-003,,,,,,,,,,,,,,,,,,,,
1432809132.480,,-1.000000e+004,2.500171e+001,2.500254e+001,1,0,1.476267e+000,1.609851e-001,1.609851e-001,1.215110e-001,6.655917e-002,5.042365e-001,4.647623e-001,4.098105e-001,8.098177e-004,8.098177e-004,,,,,,,,,,,,,,,,,,,,
1432809132.480,,-1.000000e+004,2.500171e+001,2.500254e+001,1,0,4.944333e+000,2.665792e-001,2.665792e-001,6.777099e-001,1.721532e-001,-4.568686e-001,-4.573787e-002,-5.512946e-001,1.340997e-003,1.340997e-003,,,,,,,,,,,,,,,,,,,,
1432809142.552,,-1.000000e+004,2.500171e+001,2.500254e+001,1,0,7.029890e-001,-1.139866e-001,-1.139866e-001,9.085855e-002,-1.667211e-001,-3.782622e-001,-1.734170e-001,-4.309967e-001,-5.733970e-004,-5.733970e-004,,,,,,,,,,,,,,,,,,,,
1432809258.811,,-9.000000e+003,2.500171e+001,2.500089e+001,1,0,2.591535e+000,3.250221e-002,3.250221e-002,-1.524634e-002,-1.524634e-002,2.950905e-001,2.473419e-001,2.473419e-001,1.635085e-004,1.635085e-004,,,,,,,,,,,,,,,,,,,,
1432809258.811,,-9.000000e+003,2.500171e+001,2.500089e+001,1,0,4.318056e+000,-9.022797e-001,-9.022797e-001,-4.998883e-001,-9.500283e-001,-5.291669e-001,-1.267755e-001,-5.769155e-001,-4.539087e-003,-4.539087e-003,,,,,,,,,,,,,,,,,,,,
1432809269.025,,-9.000000e+003,2.500089e+001,2.500254e+001,1,0,9.234815e-002,-8.987701e-002,-8.987701e-002,-3.083982e-002,-2.295771e-001,-3.344662e-001,-2.754290e-001,-4.741663e-001,-4.521431e-004,-4.521431e-004,,,,,,,,,,,,,,,,,,,,
1432809269.025,,-9.000000e+003,2.500089e+001,2.500254e+001,1,0,3.620980e+000,-1.541948e+000,-1.541948e+000,-1.030231e+000,-1.681648e+000,-8.063331e-001,-2.946165e-001,-9.460332e-001,-7.757057e-003,-7.757057e-003,,,,,,,,,,,,,,,,,,,,
1432809388.452,,-7.000000e+003,2.500089e+001,2.499840e+001,1,0,3.307969e+000,-1.225318e+000,-1.225318e+000,-8.488197e-001,-1.234392e+000,-6.165542e-001,-2.400558e-001,-6.256282e-001,-6.164927e-003,-6.164927e-003,,,,,,,,,,,,,,,,,,,,
1432809398.227,,-7.000000e+003,2.499840e+001,2.500006e+001,1,0,1.310861e-001,-1.239051e-001,-1.239052e-001,-8.549472e-002,-2.257383e-001,-3.051049e-001,-2.666945e-001,-4.069381e-001,-6.234022e-004,-6.234022e-004,,,,,,,,,,,,,,,,,,,,
1432809398.227,,-7.000000e+003,2.499840e+001,2.500006e+001,1,0,4.450854e+000,-5.520798e-001,-5.520799e-001,-7.136260e-002,-6.539130e-001,-5.763764e-001,-9.565912e-002,-6.782095e-001,-2.777672e-003,-2.777672e-003,,,,,,,,,,,,,,,,,,,,
1432809517.841,,-5.000000e+003,2.499840e+001,2.500089e+001,1,0,2.189411e+000,7.103183e-001,7.103183e-001,6.351797e-001,3.581931e-001,5.802605e-001,5.051219e-001,2.281353e-001,3.574241e-003,3.574241e-003,,,,,,,,,,,,,,,,,,,,
1432809528.348,,-5.000000e+003,2.500171e+001,2.500337e+001,1,0,8.672795e-001,-1.496933e-001,-1.496933e-001,-6.022872e-002,-1.442847e-001,-1.419674e-001,-5.250287e-002,-1.365589e-001,-7.532396e-004,-7.532396e-004,,,,,,,,,,,,,,,,,,,,
1432809528.348,,-5.000000e+003,2.500171e+001,2.500337e+001,1,0,4.967157e+000,1.242103e-001,1.242103e-001,6.444619e-001,1.296189e-001,-5.575960e-001,-3.734441e-002,-5.521874e-001,6.250122e-004,6.250122e-004,,,,,,,,,,,,,,,,,,,,
1432809647.775,,-3.000000e+003,2.499674e+001,2.499923e+001,1,0,1.199930e+000,8.377331e-002,8.377331e-002,1.891199e-001,-3.066974e-002,5.132438e-002,1.566710e-001,-6.311867e-002,4.215878e-004,4.215878e-004,,,,,,,,,,,,,,,,,,,,
1432809657.550,,-3.000000e+003,2.500089e+001,2.500006e+001,1,0,1.915111e+000,2.633747e-001,2.633747e-001,2.606484e-001,2.353061e-001,5.156139e-001,5.128875e-001,4.875453e-001,1.325429e-003,1.325429e-003,,,,,,,,,,,,,,,,,,,,
1432809657.550,,-3.000000e+003,2.500089e+001,2.500006e+001,1,0,4.767171e+000,-6.347850e-002,-6.347850e-002,2.801394e-001,-9.154713e-002,-3.885435e-001,-4.492556e-002,-4.166121e-001,-3.194546e-004,-3.194546e-004,,,,,,,,,,,,,,,,,,,,
1432809770.334,,-1.000000e+003,2.500171e+001,2.500669e+001,1,0,4.092157e-001,1.373333e-002,1.373333e-002,1.622548e-002,-8.802279e-002,-1.498865e-001,-1.473944e-001,-2.516426e-001,6.912099e-005,6.912099e-005,,,,,,,,,,,,,,,,,,,,
1432809770.334,,-1.000000e+003,2.500171e+001,2.500669e+001,1,0,3.026316e+000,-2.029481e-001,-2.029481e-001,3.076381e-003,-3.047042e-001,-2.577303e-001,-5.170580e-002,-3.594864e-001,-1.021455e-003,-1.021455e-003,,,,,,,,,,,,,,,,,,,,
1432809780.359,,-1.000000e+003,2.500669e+001,2.500752e+001,1,0,3.940405e+000,-7.405316e-001,-7.405316e-001,-6.067601e-001,-8.095472e-001,-2.487719e-001,-1.150004e-001,-3.177875e-001,-3.727158e-003,-3.727158e-003,,,,,,,,,,,,,,,,,,,,
1432809899.462,,-5.000000e+002,2.500503e+001,2.500669e+001,1,0,7.633129e-003,2.288888e-002,2.288888e-002,-8.848928e-002,-3.297366e-001,-2.807194e-001,-3.920975e-001,-6.333448e-001,2.880127e-005,2.880127e-005,,,,,,,,,,,,,,,,,,,,
1432809899.462,,-5.000000e+002,2.500503e+001,2.500669e+001,1,0,3.974991e+000,-1.897031e+000,-1.897031e+000,-1.390213e+000,-2.249656e+000,-8.372698e-001,-3.304518e-001,-1.189895e+000,-2.387049e-003,-2.387049e-003,,,,,,,,,,,,,,,,,,,,
1432809910.177,,-5.000000e+002,2.500669e+001,2.500669e+001,1,0,2.861279e+000,-3.701895e-001,-3.701895e-001,-1.042881e-001,-6.544017e-001,-2.329838e-001,3.291764e-002,-5.171959e-001,-4.658126e-004,-4.658126e-004,,,,,,,,,,,,,,,,,,,,
1432810008.602,,-4.000000e+002,2.500503e+001,2.500669e+001,1,0,3.633362e-001,2.337718e-001,2.337718e-001,-1.386043e-001,-2.984200e-001,-3.879723e-002,-4.111733e-001,-5.709890e-001,2.941587e-004,2.941587e-004,,,,,,,,,,,,,,,,,,,,
1432810008.602,,-4.000000e+002,2.500503e+001,2.500669e+001,1,0,4.715098e+000,3.154088e-001,3.154088e-001,5.387095e-001,-2.167830e-001,-3.143784e-001,-9.107780e-002,-8.465703e-001,3.968838e-004,3.968838e-004,,,,,,,,,,,,,,,,,,,,
1432810018.624,,-4.000000e+002,2.500752e+001,2.500835e+001,1,0,1.767855e+000,5.418562e-001,5.418561e-001,8.472481e-001,4.206423e-001,6.015744e-001,9.069664e-001,4.803606e-001,6.818261e-004,6.818261e-004,,,,,,,,,,,,,,,,,,,,
1432810123.461,,-3.000000e+002,2.500337e+001,2.500337e+001,1,0,1.265304e+000,4.127628e-001,4.127629e-001,3.020008e-002,-5.311519e-002,7.095793e-001,3.270166e-001,2.437013e-001,5.193891e-004,5.193891e-004,,,,,,,,,,,,,,,,,,,,
1432810123.461,,-3.000000e+002,2.500337e+001,2.500337e+001,1,0,4.985310e+000,7.152013e-001,7.152013e-001,9.019595e-001,2.493232e-001,-2.384728e-001,-5.171455e-002,-7.043508e-001,8.999543e-004,8.999543e-004,,,,,,,,,,,,,,,,,,,,
1432810133.628,,-3.000000e+002,2.500421e+001,2.500421e+001,1,0,8.602041e-001,-2.258370e-001,-2.258370e-001,1.574527e-001,-1.786459e-001,-4.657513e-001,-8.246157e-002,-4.185602e-001,-2.841759e-004,-2.841759e-004,,,,,,,,,,,,,,,,,,,,
1432810237.912,,-2.000000e+002,2.500337e+001,2.500503e+001,1,0,2.366491e+000,3.373821e-001,3.373821e-001,2.644190e-001,2.524096e-001,5.415248e-001,4.685616e-001,4.565523e-001,4.245383e-004,4.245383e-004,,,,,,,,,,,,,,,,,,,,
1432810237.912,,-2.000000e+002,2.500337e+001,2.500503e+001,1,0,4.486882e+000,-5.865657e-001,-5.865657e-001,-1.671461e-001,-6.715382e-001,-5.196061e-001,-1.001864e-001,-6.045786e-001,-7.380937e-004,-7.380937e-004,,,,,,,,,,,,,,,,,,,,
1432810247.937,,-2.000000e+002,2.500586e+001,2.500669e+001,1,0,1.748357e-001,-5.447554e-002,-5.447554e-002,-1.219357e-002,-2.402965e-001,-3.456479e-001,-3.033659e-001,-5.314689e-001,-6.854824e-005,-6.854824e-005,,,,,,,,,,,,,,,,,,,,
1432810247.937,,-2.000000e+002,2.500586e+001,2.500669e+001,1,0,3.430989e+000,-1.370434e+000,-1.370434e+000,-8.359296e-001,-1.556255e+000,-8.359558e-001,-3.014517e-001,-1.021777e+000,-1.724459e-003,-1.724459e-003,,,,,,,,,,,,,,,,,,,,
1432810352.518,,-1.000000e+002,2.500006e+001,2.499923e+001,1,0,3.526029e+000,-9.874264e-001,-9.874264e-001,-1.010306e+000,-1.370044e+000,-2.224560e-001,-2.453357e-001,-6.050740e-001,-1.242516e-003,-1.242516e-003,,,,,,,,,,,,,,,,,,,,
1432810362.982,,-1.000000e+002,2.500171e+001,2.500337e+001,1,0,5.733505e-002,2.357555e-001,2.357555e-001,-6.507722e-002,-2.010186e-001,8.185311e-002,-2.189796e-001,-3.549209e-001,2.966601e-004,2.966601e-004,,,,,,,,,,,,,,,,,,,,
1432810362.982,,-1.000000e+002,2.500171e+001,2.500337e+001,1,0,4.299881e+000,-3.827021e-001,-3.827021e-001,-2.854209e-001,-8.194761e-001,-2.049344e-001,-1.076532e-001,-6.417085e-001,-4.815687e-004,-4.815687e-004,,,,,,,,,,,,,,,,,,,,
1432810467.789,,0.000000e+000,2.500089e+001,2.500337e+001,1,0,2.409429e+000,6.195257e-002,6.195258e-002,3.227470e-001,1.325100e-001,-3.373477e-002,2.270596e-001,3.682264e-002,7.795776e-005,7.795776e-005,,,,,,,,,,,,,,,,,,,,
1432810478.296,,0.000000e+000,2.500337e+001,2.500669e+001,1,0,6.836079e-001,-4.867702e-002,-4.867702e-002,-4.697097e-002,-1.007425e-001,-1.016159e-001,-9.990986e-002,-1.536814e-001,-6.125253e-005,-6.125253e-005,,,,,,,,,,,,,,,,,,,,
1432810478.296,,0.000000e+000,2.500337e+001,2.500669e+001,1,0,4.908623e+000,1.280251e-001,1.280251e-001,3.746902e-001,7.595970e-002,-2.727269e-001,-2.606177e-002,-3.247923e-001,1.610999e-004,1.610999e-004,,,,,,,,,,,,,,,,,,,,
1432810585.543,,1.000000e+002,2.500337e+001,2.500669e+001,1,0,1.380497e+000,3.534043e-001,3.534043e-001,3.838941e-001,9.843919e-002,3.821724e-001,4.126621e-001,1.272072e-001,8.894043e-005,8.894043e-005,,,,,,,,,,,,,,,,,,,,
1432810596.312,,1.000000e+002,2.500752e+001,2.500752e+001,1,0,1.693023e+000,3.521836e-001,3.521836e-001,2.758244e-001,2.254196e-001,7.579759e-001,6.816167e-001,6.312119e-001,8.863321e-005,8.863321e-005,,,,,,,,,,,,,,,,,,,,
1432810596.312,,1.000000e+002,2.500752e+001,2.500752e+001,1,0,4.870429e+000,1.528977e-001,1.528977e-001,5.931876e-001,2.613372e-002,-4.968291e-001,-5.653920e-002,-6.235932e-001,3.847941e-005,3.847941e-005,,,,,,,,,,,,,,,,,,,,
1432810700.058,,2.000000e+002,2.500089e+001,2.500421e+001,1,0,5.504881e-001,-4.573199e-001,-4.573199e-001,-5.972903e-002,3.128699e-001,-1.995725e-001,1.980184e-001,5.706173e-001,-1.150919e-004,-1.150919e-004,,,,,,,,,,,,,,,,,,,,
1432810700.058,,2.000000e+002,2.500089e+001,2.500421e+001,1,0,2.812106e+000,-3.997925e-002,-3.997925e-002,-3.367774e-001,7.302105e-001,2.500015e-001,-4.679655e-002,1.020191e+000,-1.006142e-005,-1.006142e-005,,,,,,,,,,,,,,,,,,,,
1432810710.522,,2.000000e+002,2.500421e+001,2.500503e+001,1,0,4.134451e+000,2.208014e+000,2.208014e+000,7.240187e-001,1.427866e+000,1.628003e+000,1.440079e-001,8.478550e-001,5.556824e-004,5.556824e-004,,,,,,,,,,,,,,,,,,,,
1432810830.112,,3.000000e+002,2.500089e+001,2.500337e+001,1,0,3.522875e-002,3.357036e-001,3.357036e-001,2.438062e-002,1.617901e-001,4.573403e-001,1.460173e-001,2.834268e-001,4.224236e-004,4.224236e-004,,,,,,,,,,,,,,,,,,,,
1432810830.112,,3.000000e+002,2.500089e+001,2.500337e+001,1,0,3.801239e+000,1.236305e+000,1.236305e+000,5.935825e-001,1.062391e+000,7.886215e-001,1.458992e-001,6.147079e-001,1.555671e-003,1.555671e-003,,,,,,,,,,,,,,,,,,,,
1432810840.278,,3.000000e+002,2.500337e+001,2.500254e+001,1,0,3.086705e+000,8.616902e-001,8.616901e-001,2.735053e-001,5.787296e-001,6.673009e-001,7.911618e-002,3.843404e-001,1.084285e-003,1.084285e-003,,,,,,,,,,,,,,,,,,,,
1432810943.560,,4.000000e+002,2.499757e+001,2.500089e+001,1,0,2.339191e-001,1.013825e+000,1.013825e+000,8.434132e-002,2.525058e-001,1.191944e+000,2.624601e-001,4.306247e-001,1.275712e-003,1.275712e-003,,,,,,,,,,,,,,,,,,,,
1432810943.560,,4.000000e+002,2.499757e+001,2.500089e+001,1,0,4.589797e+000,1.351665e+000,1.351665e+000,-1.523810e-001,5.903457e-001,1.575091e+000,7.104561e-002,8.137723e-001,1.700821e-003,1.700821e-003,,,,,,,,,,,,,,,,,,,,
1432810953.633,,4.000000e+002,2.500089e+001,2.500254e+001,1,0,1.974896e+000,-2.059999e-002,-2.059999e-002,-6.263642e-001,-4.316734e-001,2.604818e-003,-6.031594e-001,-4.084686e-001,-2.592130e-005,-2.592130e-005,,,,,,,,,,,,,,,,,,,,
1432811057.596,,5.000000e+002,2.499840e+001,2.500006e+001,1,0,1.061539e+000,3.770562e-001,3.770562e-001,4.107709e-002,1.527763e-001,2.300621e-001,-1.059170e-001,5.782142e-003,4.744529e-004,4.744529e-004,,,,,,,,,,,,,,,,,,,,
1432811057.596,,5.000000e+002,2.499840e+001,2.500006e+001,1,0,4.992298e+000,1.141392e-001,1.141392e-001,-8.760778e-001,-1.101407e-001,1.038201e+000,4.798414e-002,8.139213e-001,1.436223e-004,1.436223e-004,,,,,,,,,,,,,,,,,,,,
1432811068.369,,5.000000e+002,2.500006e+001,2.500006e+001,1,0,1.026580e+000,8.706931e-001,8.706931e-001,-2.099573e-001,1.937566e-001,1.008624e+000,-7.202676e-002,3.316871e-001,1.095600e-003,1.095600e-003,,,,,,,,,,,,,,,,,,,,
1432811188.975,,1.000000e+003,2.500089e+001,2.500171e+001,1,0,2.140061e+000,-1.626637e-001,-1.626637e-001,-3.690880e-001,-3.420216e-001,-3.959187e-001,-6.023431e-001,-5.752766e-001,-4.093499e-004,-4.093499e-004,,,,,,,,,,,,,,,,,,,,
1432811188.975,,1.000000e+003,2.500089e+001,2.500171e+001,1,0,4.637953e+000,6.294442e-001,6.294442e-001,-1.318425e-001,4.500864e-001,8.338553e-001,7.256857e-002,6.544974e-001,1.584023e-003,1.584023e-003,,,,,,,,,,,,,,,,,,,,
1432811199.190,,1.000000e+003,2.500171e+001,2.500254e+001,1,0,2.864322e-001,4.892117e-001,4.892117e-001,-8.509494e-003,2.579249e-001,7.898943e-001,2.921731e-001,5.586075e-001,1.231122e-003,1.231122e-003,,,,,,,,,,,,,,,,,,,,
1432811199.190,,1.000000e+003,2.500171e+001,2.500254e+001,1,0,3.233306e+000,1.456648e+000,1.456648e+000,4.127368e-001,1.225362e+000,1.262616e+000,2.187040e-001,1.031329e+000,3.665717e-003,3.665717e-003,,,,,,,,,,,,,,,,,,,,
1432811318.622,,3.000000e+003,2.499094e+001,2.499591e+001,1,0,3.737069e+000,3.110141e+000,3.110141e+000,2.004742e+000,2.772618e+000,1.523385e+000,4.179858e-001,1.185862e+000,7.825868e-003,7.825868e-003,,,,,,,,,,,,,,,,,,,,
1432811328.395,,3.000000e+003,2.499591e+001,2.500006e+001,1,0,1.616719e-002,6.543168e-001,6.543168e-001,1.066640e-001,4.073786e-001,9.355928e-001,3.879400e-001,6.886545e-001,1.646420e-003,1.646420e-003,,,,,,,,,,,,,,,,,,,,
1432811328.395,,3.000000e+003,2.499591e+001,2.500006e+001,1,0,4.141543e+000,2.330698e+000,2.330698e+000,9.610927e-001,2.083760e+000,1.624120e+000,2.545146e-001,1.377182e+000,5.864602e-003,5.864602e-003,,,,,,,,,,,,,,,,,,,,
1432811447.993,,5.000000e+003,2.500171e+001,2.500503e+001,1,0,2.635791e+000,5.305643e-001,5.305643e-001,-5.271146e-001,2.426392e-001,6.942791e-001,-3.633998e-001,4.063540e-001,1.334869e-003,1.334869e-003,,,,,,,,,,,,,,,,,,,,
1432811458.490,,5.000000e+003,2.500503e+001,2.500669e+001,1,0,5.144747e-001,7.388531e-001,7.388531e-001,1.696196e-001,4.015090e-001,1.020407e+000,4.511733e-001,6.830627e-001,1.858912e-003,1.858912e-003,,,,,,,,,,,,,,,,,,,,
1432811458.490,,5.000000e+003,2.500503e+001,2.500669e+001,1,0,4.825310e+000,5.368206e-001,5.368206e-001,-9.831594e-001,1.994765e-001,1.614250e+000,9.426975e-002,1.276906e+000,1.350610e-003,1.350610e-003,,,,,,,,,,,,,,,,,,,,
1432811578.166,,7.000000e+003,2.500503e+001,2.500669e+001,1,0,1.569762e+000,1.445051e-001,1.445051e-001,-8.859096e-001,-1.752657e-001,3.247685e-002,-9.979379e-001,-2.872940e-001,3.635234e-004,3.635234e-004,,,,,,,,,,,,,,,,,,,,
1432811588.190,,7.000000e+003,2.500669e+001,2.500669e+001,1,0,1.476343e+000,4.403821e-001,4.403821e-001,-2.230304e-001,-9.684095e-002,-1.900553e-001,-8.534678e-001,-7.272784e-001,1.107844e-003,1.107844e-003,,,,,,,,,,,,,,,,,,,,
1432811588.190,,7.000000e+003,2.500669e+001,2.500669e+001,1,0,4.944311e+000,4.521317e-001,4.521317e-001,-1.246035e+000,-8.509132e-002,1.782463e+000,8.429690e-002,1.245240e+000,1.137402e-003,1.137402e-003,,,,,,,,,,,,,,,,,,,,
1432811712.518,,9.000000e+003,2.500337e+001,2.500586e+001,1,0,7.033162e-001,5.166784e-001,5.166784e-001,-8.857141e-002,2.211132e-001,7.752181e-001,1.699683e-001,4.796529e-001,2.599247e-003,2.599247e-003,,,,,,,,,,,,,,,,,,,,
1432811722.742,,9.000000e+003,2.500586e+001,2.500586e+001,1,0,2.591393e+000,2.844325e-001,2.844325e-001,1.440498e-002,1.440498e-002,2.133141e-002,-2.486961e-001,-2.486961e-001,1.430891e-003,1.430891e-003,,,,,,,,,,,,,,,,,,,,
1432811722.742,,9.000000e+003,2.500586e+001,2.500586e+001,1,0,4.318061e+000,1.316416e+000,1.316416e+000,5.010791e-001,1.046388e+000,9.424884e-001,1.271516e-001,6.724609e-001,6.622477e-003,6.622477e-003,,,,,,,,,,,,,,,,,,,,
1432811839.718,,1.000000e+004,2.500337e+001,2.500503e+001,1,0,9.370920e-002,5.552843e-001,5.552843e-001,3.246781e-002,2.793061e-001,8.056761e-001,2.828597e-001,5.296980e-001,2.793296e-003,2.793296e-003,,,,,,,,,,,,,,,,,,,,
1432811839.718,,1.000000e+004,2.500337e+001,2.500503e+001,1,0,3.620810e+000,2.139500e+000,2.139500e+000,1.054441e+000,1.863522e+000,1.387577e+000,3.025174e-001,1.111599e+000,1.076252e-002,1.076252e-002,,,,,,,,,,,,,,,,,,,,
1432811849.980,,1.000000e+004,2.500503e+001,2.500586e+001,1,0,3.307809e+000,1.603748e+000,1.603748e+000,9.220625e-001,1.413530e+000,9.430226e-001,2.613373e-001,7.528046e-001,8.067473e-003,8.067473e-003,,,,,,,,,,,,,,,,,,,,
1432812006.007,,2.000000e+004,2.500171e+001,2.500254e+001,1,0,1.312202e-001,6.985687e-001,6.985687e-001,1.124207e-001,3.321336e-001,9.320838e-001,3.459358e-001,5.656487e-001,3.511979e-003,3.511979e-003,,,,,,,,,,,,,,,,,,,,
1432812006.007,,2.000000e+004,2.500171e+001,2.500254e+001,1,0,4.449168e+000,1.371807e+000,1.371807e+000,9.271840e-002,1.005372e+000,1.403653e+000,1.245644e-001,1.037218e+000,6.896613e-003,6.896613e-003,,,,,,,,,,,,,,,,,,,,
1432812016.221,,2.000000e+004,2.500254e+001,2.500421e+001,1,0,2.188971e+000,-5.325480e-002,-5.325480e-002,-8.904192e-001,-3.686337e-001,1.225453e-001,-7.146190e-001,-1.928336e-001,-2.677328e-004,-2.677328e-004,,,,,,,,,,,,,,,,,,,,
1432812172.902,,3.000000e+004,2.500337e+001,2.500421e+001,1,0,8.663235e-001,5.722221e-001,5.722221e-001,9.552991e-002,2.466849e-001,5.624065e-001,8.571434e-002,2.368693e-001,2.875072e-003,2.875072e-003,,,,,,,,,,,,,,,,,,,,
1432812172.902,,3.000000e+004,2.500337e+001,2.500421e+001,1,0,4.966451e+000,2.357555e-001,2.357555e-001,-1.015606e+000,-8.978166e-002,1.310986e+000,5.962491e-002,9.854493e-001,1.184530e-003,1.184530e-003,,,,,,,,,,,,,,,,,,,,
1432812182.926,,3.000000e+004,2.500254e+001,2.500586e+001,1,0,1.198966e+000,4.304636e-001,4.304636e-001,-3.468682e-001,1.422304e-001,4.922278e-001,-2.851039e-001,2.039946e-001,2.162821e-003,2.162821e-003,,,,,,,,,,,,,,,,,,,,
1432812342.042,,4.000000e+004,2.500089e+001,2.500337e+001,1,0,1.914718e+000,-2.531510e-001,-2.531510e-001,-5.327512e-001,-4.711578e-001,-7.572018e-001,-1.036802e+000,-9.752085e-001,-1.271173e-003,-1.271173e-003,,,,,,,,,,,,,,,,,,,,
1432812342.042,,4.000000e+004,2.500089e+001,2.500337e+001,1,0,4.767020e+000,5.658132e-001,5.658132e-001,-5.555634e-001,3.478064e-001,1.212515e+000,9.113792e-002,9.945078e-001,2.841176e-003,2.841176e-003,,,,,,,,,,,,,,,,,,,,
1432812352.257,,4.000000e+004,2.500337e+001,2.500503e+001,1,0,4.127429e-001,6.851405e-001,6.851406e-001,-4.309928e-002,3.885417e-001,1.164792e+000,4.365517e-001,8.681927e-001,3.440367e-003,3.440367e-003,,,,,,,,,,,,,,,,,,,,
1432812352.257,,4.000000e+004,2.500337e+001,2.500503e+001,1,0,3.026420e+000,1.552629e+000,1.552629e+000,-1.833833e-002,1.256030e+000,1.723012e+000,1.520443e-001,1.426413e+000,7.796377e-003,7.796377e-003,,,,,,,,,,,,,,,,,,,,
1432812512.945,,5.000000e+004,2.499923e+001,2.500171e+001,1,0,3.940567e+000,3.157292e+000,3.157292e+000,1.931120e+000,2.787744e+000,1.597247e+000,3.710749e-001,1.227699e+000,1.584459e-002,1.584459e-002,,,,,,,,,,,,,,,,,,,,
1432812522.969,,5.000000e+004,2.500171e+001,2.500254e+001,1,0,7.686481e-003,8.651997e-001,8.651997e-001,1.064886e-001,4.570698e-001,1.178507e+000,4.197962e-001,7.703773e-001,4.341926e-003,4.341926e-003,,,,,,,,,,,,,,,,,,,,
1432812522.969,,5.000000e+004,2.500171e+001,2.500254e+001,1,0,3.975350e+000,3.133946e+000,3.133946e+000,1.476870e+000,2.725816e+000,2.012340e+000,3.552644e-001,1.604210e+000,1.572742e-002,1.572742e-002,,,,,,,,,,,,,,,,,,,,
1432812679.509,,6.000000e+004,2.499840e+001,2.499840e+001,1,0,2.861535e+000,1.190832e+000,1.190832e+000,1.129531e-001,8.404222e-001,1.035753e+000,-4.212568e-002,6.853434e-001,5.972516e-003,5.972516e-003,,,,,,,,,,,,,,,,,,,,
1432812689.632,,6.000000e+004,2.499840e+001,2.500006e+001,1,0,3.627872e-001,7.374798e-001,7.374798e-001,1.812975e-001,4.444257e-001,1.076224e+000,5.200418e-001,7.831700e-001,3.698766e-003,3.698766e-003,,,,,,,,,,,,,,,,,,,,
1432812689.632,,6.000000e+004,2.499840e+001,2.500006e+001,1,0,4.715869e+000,8.749657e-001,8.749657e-001,-6.619672e-001,5.819116e-001,1.652095e+000,1.151622e-001,1.359041e+000,4.388315e-003,4.388315e-003,,,,,,,,,,,,,,,,,,,,
1432812848.097,,7.000000e+004,2.499840e+001,2.500006e+001,1,0,1.767093e+000,-2.043214e-001,-2.043214e-001,-1.134348e+000,-4.437565e-001,-2.859310e-001,-1.215957e+000,-5.253660e-001,-1.024145e-003,-1.024145e-003,,,,,,,,,,,,,,,,,,,,
1432812858.121,,7.000000e+004,2.500171e+001,2.500171e+001,1,0,1.264891e+000,4.469436e-001,4.469436e-001,-5.721353e-002,8.594912e-002,9.511404e-003,-4.946457e-001,-3.514830e-001,2.240268e-003,2.240268e-003,,,,,,,,,,,,,,,,,,,,
1432812858.121,,7.000000e+004,2.500171e+001,2.500171e+001,1,0,4.985267e+000,1.403851e-001,1.403852e-001,-1.342050e+000,-2.206093e-001,1.561231e+000,7.879557e-002,1.200236e+000,7.036692e-004,7.036692e-004,,,,,,,,,,,,,,,,,,,,
1432812858.121,,7.000000e+004,2.500171e+001,2.500171e+001,1,0,2.812305e+000,1.081423e+000,1.081423e+000,-7.827789e-001,7.204289e-001,1.748037e+000,-1.161651e-001,1.387043e+000,5.420547e-003,5.420547e-003,,,,,,,,,,,,,,,,,,,,